Workbook

Sheet Links
A1: Links e IMPORTRANGE
A2: Pegar en B el link de cada Google Sheet. La primera vez, tocar la primera celda de cada bloque y «Permitir acceso». Todos los IMPORTRANGE del libro están en esta hoja.
A3: Archivo | B3: Link | G3: Qué se importa | L3: Estado
A4: Proyecciones | B4: https://docs.google.com/spreadsheets/d/1xc4xDAwSYT3l-RulPYtcePxiCninrbQGzaBUsgO0YEs/edit?gid=1764491891#gid=1764491891 | G4: Indexado Dim Técnico B3:K10 y B15:K22 → Demanda | L4: =IF(ISERROR(C11),"Falta el link o «Permitir acceso»","OK") -> OK
A5: Aprovechamiento Recargas Planta Comercial | B5: PEGAR ACÁ EL LINK DEL GOOGLE SHEET | G5: sobrestock_sustitutos B73:K76 y B86:K89 → Demanda | L5: =IF(ISERROR(C44),"Falta el link o «Permitir acceso»","OK") -> OK
A6: Aprovechamiento Recargas Planta Industrial | B6: PEGAR ACÁ EL LINK DEL GOOGLE SHEET | G6: sobrestock_sustitutos B73:K76 y B86:K89 → Demanda | L6: =IF(ISERROR(C33),"Falta el link o «Permitir acceso»","OK") -> OK
A7: Sin link, esa fuente suma 0 en Demanda (la columna Estado lo avisa).
A9: Proyecciones · Indexado Dim Técnico B3:K10: matafuegos terminados
A10: Formato | B10: Qué es | C10: 2026 | D10: 2027 | E10: 2028 | F10: 2029 | G10: 2030 | H10: 2031 | I10: 2032 | J10: 2033 | K10: 2034 | L10: 2035
A11: 1 kg | B11: Terminados | C11: =IFERROR(__xludf.DUMMYFUNCTION("IMPORTRANGE(Links!$B$4,""Indexado Dim Técnico!B3:K10"")"),4178.736543) -> 4178.7365
A12: 2,5 kg | B12: Terminados
A13: 5 kg | B13: Terminados
A14: 10 kg | B14: Terminados
A15: 25 kg | B15: Terminados
A16: 50 kg | B16: Terminados
A17: 70 kg | B17: Terminados
A18: 100 kg | B18: Terminados
A20: Proyecciones · Indexado Dim Técnico B15:K22: cilindros vendidos vacíos
A21: Formato | B21: Qué es | C21: 2026 | D21: 2027 | E21: 2028 | F21: 2029 | G21: 2030 | H21: 2031 | I21: 2032 | J21: 2033 | K21: 2034 | L21: 2035
A22: 1 kg | B22: Cilindros | C22: =IFERROR(__xludf.DUMMYFUNCTION("IMPORTRANGE(Links!$B$4,""Indexado Dim Técnico!B15:K22"")"),0) -> 0
A23: 2,5 kg | B23: Cilindros
A24: 5 kg | B24: Cilindros
A25: 10 kg | B25: Cilindros
A26: 25 kg | B26: Cilindros
A27: 50 kg | B27: Cilindros
A28: 70 kg | B28: Cilindros
A29: 100 kg | B29: Cilindros
A31: Recargas Planta Industrial · sobrestock_sustitutos B73:K76 y B86:K89: sustitutos ABC terminados
A32: Formato | B32: Qué es | C32: 2026 | D32: 2027 | E32: 2028 | F32: 2029 | G32: 2030 | H32: 2031 | I32: 2032 | J32: 2033 | K32: 2034 | L32: 2035
A33: 1 kg | B33: Sustitutos | C33: =IFERROR(__xludf.DUMMYFUNCTION("IMPORTRANGE(Links!$B$6,""sobrestock_sustitutos!B73:K76"")"),0) -> 0
A34: 2,5 kg | B34: Sustitutos
A35: 5 kg | B35: Sustitutos
A36: 10 kg | B36: Sustitutos
A37: 25 kg | B37: Sustitutos | C37: =IFERROR(__xludf.DUMMYFUNCTION("IMPORTRANGE(Links!$B$6,""sobrestock_sustitutos!B86:K89"")"),1) -> 1
A38: 50 kg | B38: Sustitutos
A39: 70 kg | B39: Sustitutos
A40: 100 kg | B40: Sustitutos
A42: Recargas Planta Comercial · sobrestock_sustitutos B73:K76 y B86:K89: sustitutos ABC cilindros vacíos
A43: Formato | B43: Qué es | C43: 2026 | D43: 2027 | E43: 2028 | F43: 2029 | G43: 2030 | H43: 2031 | I43: 2032 | J43: 2033 | K43: 2034 | L43: 2035
A44: 1 kg | B44: Sustitutos | C44: =IFERROR(__xludf.DUMMYFUNCTION("IMPORTRANGE(Links!$B$5,""sobrestock_sustitutos!B73:K76"")"),0) -> 0
...

Sheet Resumen
A1: Corte de chapa: comparación de alternativas 2026-2035
A2: Cuerpos de 1 a 100 kg, cúpulas y fondos de 1 a 10 kg. Valor actual = inversión + costos de 10 años descontados. Menor es mejor.
A4: Indicador | B4: A: bobina por formato + fleje | C4: B: hojas para todo | D4: C: bobina madre propia | E4: D: hojas + fleje | F4: Referencia: cuerpos a medida
A5: Cuerpos: se compra | B5: Bobina de ancho estándar por formato, línea de corte transversal | C5: Hojas estándar, dos guillotinas en serie | D5: Bobina madre por espesor, cortada en flejes propios | E5: Hojas estándar, dos guillotinas en serie | F5: Cuerpos comprados cortados a medida
A6: Cúpulas y fondos: se compra | B6: Fleje a medida por disco | C6: Tiras de hoja cargadas a mano | D6: Flejes propios de la bobina madre | E6: Fleje a medida por disco | F6: Fleje a medida por disco
A7: Inversión en equipos (USD) | B7: =Datos!$C$117 -> 160806.26 | C7: =Datos!$D$117 -> 72506.259 | D7: =Datos!$E$117 -> 191000 | E7: =Datos!$F$117 -> 86006.259 | F7: =Datos!$G$117 -> 15000
A8: Acero comprado 2026-2035 (t) | B8: =SUM(Cálculo!$C$32:$L$32) -> 1817.5432 | C8: =SUM(Cálculo!$C$61:$L$61) -> 1924.7473 | D8: =SUM(Cálculo!$C$85:$L$85) -> 1833.9308 | E8: =SUM(Cálculo!$C$99:$L$99) -> 1877.59 | F8: =SUM(Cálculo!$C$113:$L$113) -> 1760.2126
A9: Aprovechamiento de chapa 2026-2035 | B9: =SUM(Cálculo!$C$25:$L$25)/B8 -> 0.90524497 | C9: =SUM(Cálculo!$C$25:$L$25)/C8 -> 0.85482487 | D9: =SUM(Cálculo!$C$25:$L$25)/D8 -> 0.89715591 | E9: =SUM(Cálculo!$C$25:$L$25)/E8 -> 0.87629452 | F9: =SUM(Cálculo!$C$25:$L$25)/F8 -> 0.93472906
A10: Horas-hombre de corte en el año de referencia | B10: =INDEX(Cálculo!$C$41:$L$41,Datos!$B$6-2025) -> 318.27451 | C10: =INDEX(Cálculo!$C$67:$L$67,Datos!$B$6-2025) -> 399.38628 | D10: =INDEX(Cálculo!$C$93:$L$93,Datos!$B$6-2025) -> 406.03852 | E10: =INDEX(Cálculo!$C$105:$L$105,Datos!$B$6-2025) -> 113.60639 | F10: =INDEX(Cálculo!$C$119:$L$119,Datos!$B$6-2025) -> 20.146699
A11: Costo anual en el año de referencia (USD) | B11: =INDEX(Cálculo!$C$44:$L$44,Datos!$B$6-2025) -> 510842.2 | C11: =INDEX(Cálculo!$C$70:$L$70,Datos!$B$6-2025) -> 565521.55 | D11: =INDEX(Cálculo!$C$96:$L$96,Datos!$B$6-2025) -> 523443.22 | E11: =INDEX(Cálculo!$C$108:$L$108,Datos!$B$6-2025) -> 539731.1 | F11: =INDEX(Cálculo!$C$122:$L$122,Datos!$B$6-2025) -> 539193.47
A12: Valor actual a 10 años (USD) | B12: =B7+SUMPRODUCT(Cálculo!$C$44:$L$44,Cálculo!$C$6:$L$6) -> 1139875.8 | C12: =C7+SUMPRODUCT(Cálculo!$C$70:$L$70,Cálculo!$C$6:$L$6) -> 1140454.4 | D12: =D7+SUMPRODUCT(Cálculo!$C$96:$L$96,Cálculo!$C$6:$L$6) -> 1202188.3 | E12: =E7+SUMPRODUCT(Cálculo!$C$108:$L$108,Cálculo!$C$6:$L$6) -> 1107926.9 | F12: =F7+SUMPRODUCT(Cálculo!$C$122:$L$122,Cálculo!$C$6:$L$6) -> 1028430.1
A13: Ranking (1 = conviene; la referencia no corta en planta) | B13: =RANK(B12,$B$12:$E$12,1) -> 2 | C13: =RANK(C12,$B$12:$E$12,1) -> 3 | D13: =RANK(D12,$B$12:$E$12,1) -> 4 | E13: =RANK(E12,$B$12:$E$12,1) -> 1 | F13: —
A14: Diferencia contra la que conviene (USD) | B14: =B12-MIN($B$12:$E$12) -> 31948.883 | C14: =C12-MIN($B$12:$E$12) -> 32527.491 | D14: =D12-MIN($B$12:$E$12) -> 94261.32 | E14: =E12-MIN($B$12:$E$12) -> 0 | F14: =F12-MIN($B$12:$E$12) -> -79496.897
A16: Conviene (de las que cortan en planta) | B16: =INDEX({"A: bobina por formato + fleje","B: hojas para todo","C: bobina madre propia","D: hojas + fleje"},MATCH(MIN($B$12:$E$12),$B$12:$E$12,0)) -> D: hojas + fleje
A17: Margen de D: suba del precio de la hoja que la iguala con A | B17: =($B$12-$E$12)/SUMPRODUCT(Cálculo!$C$55:$L$55,Cálculo!$C$6:$L$6) -> 0.040192118
A18: Margen de D: suba del precio del fleje que la iguala con B | B18: =($C$12-$E$12)/SUMPRODUCT(Cálculo!$C$31:$L$31,Cálculo!$C$6:$L$6) -> 0.14427753
A20: Datos editables en la hoja Datos (gris claro). Demanda por IMPORTRANGE (hoja Links). Medidas de cuerpos y discos del plano (hoja Piezas).

Sheet Datos
A1: Datos
A2: Gris claro: dato editable. Todo lo demás del libro sale de acá, de Demanda y de Piezas.
A4: 1. Generales
A5: Concepto | B5: Valor | C5: Unidad | D5: Fuente o criterio
A6: Año de referencia | B6: 2035 | C6: año | D6: Año de diseño del proyecto (Proyecciones).
A7: Tasa de descuento anual en USD | B7: 0.12 | C7: % | D7: Evaluación económica del Excel V2 (12 % real).
A8: Mantenimiento anual de equipos | B8: 0.03 | C8: % de la inversión | D8: Criterio del grupo.
A9: Precio de venta del scrap | B9: 250 | C9: USD/t | D9: Reaquila (mar-2026): acero reciclado $300-1.200/kg con dólar ~$1.480.
A10: Densidad del acero SAE 1010 | B10: 7.87 | C10: g/cm³ | D10: Planilla «Dimensiones de chapa».
A11: Costo mensual de un operario con cargas | B11: 1337922 | C11: ARS/mes | D11: Planilla «Costo oportunidad operario-máquina», CCT 260/75, ago-2026.
A12: Horas por mes | B12: 150 | C12: h/mes | D12: Excel V2.
A13: Horas productivas por operario y año | B13: 1800 | C13: h/año | D13: Excel V2 (150 h × 12).
A14: Tipo de cambio | B14: 1420 | C14: ARS/USD | D14: Valor fijo del proyecto (criterio del grupo).
A15: Costo hora de operario | B15: =Datos!$B$11/Datos!$B$12/Datos!$B$14 -> 6.2813239 | C15: USD/h | D15: Cálculo.
A17: 2. Corte y puentes
A18: Concepto | B18: Valor | C18: Unidad | D18: Fuente o criterio
A19: Margen mínimo de borde a lo ancho de una bobina | B19: 10 | C19: mm | D19: Criterio del grupo: bordes de laminación y tolerancia de ancho.
A20: Despunte de cabeza y cola de bobina | B20: 0.005 | C20: % | D20: Criterio del grupo.
A21: Puente de avance entre discos | B21: 1.5 | C21: × espesor | D21: MISUMI, Press Dies Tutorial: 1,5 veces el espesor, mínimo 0,7 mm.
A22: Puente mínimo entre discos | B22: 0.7 | C22: mm | D22: MISUMI.
A23: Puente al borde del fleje | B23: 1.5 | C23: × puente de avance | D23: MISUMI: 1,5 veces el de avance (la guía del fleje deja juego).
A24: ¿Mezclar 70 y 100 kg en la misma hoja? | B24: SI | C24: SI/NO | D24: Proceso de carros: la hoja mixta lleva 1 cuerpo de 100 kg y 3 de 70 kg.
A25: Cuerpos de 100 kg por hoja mixta | B25: 1 | C25: u | D25: Proceso de carros.
A26: Cuerpos de 70 kg por hoja mixta | B26: 3 | C26: u | D26: Proceso de carros.
A27: ¿Combinar 25 y 50 kg en la hoja de 3,2 mm (corte en tres etapas)? | B27: SI | C27: SI/NO | D27: Hoja Nesting: el aprovechamiento de la chapa de 3,2 mm sube del 85 % al 90 %.
A28: ¿Discos en fleje de dos filas al tresbolillo? | B28: NO | C28: SI/NO | D28: Corte, sección C: necesita matriz de dos discos o alimentador en zigzag (sin cotización).
A30: 3. Máquinas
A31: Concepto | B31: Valor | C31: Unidad | D31: Fuente o criterio
A32: Guillotina 1 (franjas) Ermaksan CNC HGS 2600-6: golpes por minuto | B32: 20 | C32: golpes/min | D32: Aprovechamiento Manuales del grupo. La ficha de la máquina (resale.info, 2018) da 24.
A33: Guillotina 1: largo de corte | B33: 2600 | C33: mm | D33: Ficha Ermaksan CNC HGS 2600-6: 2.600 × 6 mm.
A34: Guillotina 1: recorrido del tope trasero | B34: 1000 | C34: mm | D34: Ficha Ermaksan CNC HGS 2600-6: tope trasero motorizado de 1.000 mm.
A35: Guillotina 2 (piezas) QC12Y 6 × 2500: golpes por minuto | B35: 20 | C35: golpes/min | D35: Confirmado por el grupo (igual que la HG 6 × 2500 de la ficha Molinari Panther).
A36: Guillotina 2: largo de corte para franjas en paralelo | B36: 2500 | C36: mm | D36: Publicación Alibaba 1600900259147: 6 × 2500, cuchilla de 2.550 mm.
A37: Guillotina 2: recorrido del tope trasero | B37: 800 | C37: mm | D37: Publicación Alibaba 1600900259147: 20 a 800 mm.
A38: Hojas por ciclo como máximo (franjas de hojas enteras en paralelo en G2) | B38: 4 | C38: hojas | D38: Criterio del grupo (comentarios del corte de 5 y 10 kg): sin franjas sueltas en el pulmón.
A39: Guillotina 1 Ermaksan CNC HGS 2600-6 usada (2018) | B39: 26000 | C39: EUR | D39: Anuncio resale.info N.° 165879844 (nov-2024), sin flete ni nacionalización.
A40: Tipo de cambio euro / dólar | B40: =1/0.8723 -> 1.1463946 | C40: USD/EUR | D40: Pound Sterling Live: USD/EUR 0,8723 al cierre del 21/09/2026.
A41: Línea de corte transversal (A y C): golpes por hora | B41: 1200 | C41: golpes/h | D41: Criterio del grupo: 20 golpes por minuto.
A42: Cortadora longitudinal (C): velocidad efectiva | B42: 40 | C42: m/min | D42: Criterio del grupo (máquinas de 60 a 120 m/min nominales).
A43: Cortadora: armado de cuchillas por bobina madre | B43: 45 | C43: min | D43: Criterio del grupo.
...

Sheet Demanda
A1: Demanda: cuerpos a fabricar por formato
A2: Terminados + cilindros vacíos + sustitutos de las dos plantas de recargas, todo desde la hoja Links. Cada unidad lleva un cuerpo; las de 1 a 10 kg, además, cúpula y fondo.
A4: Unidades a fabricar = terminados + cilindros + sustitutos
A5: Formato | B5: Línea | C5: 2026 | D5: 2027 | E5: 2028 | F5: 2029 | G5: 2030 | H5: 2031 | I5: 2032 | J5: 2033 | K5: 2034 | L5: 2035
A6: 1 kg | B6: Manual | C6: =IFERROR(Links!C11,0)+IFERROR(Links!C22,0)+IFERROR(Links!C33,0)+IFERROR(Links!C44,0) -> 4178.7365 | D6: =IFERROR(Links!D11,0)+IFERROR(Links!D22,0)+IFERROR(Links!D33,0)+IFERROR(Links!D44,0) -> 5997.304 | E6: =IFERROR(Links!E11,0)+IFERROR(Links!E22,0)+IFERROR(Links!E33,0)+IFERROR(Links!E44,0) -> 14514.148 | F6: =IFERROR(Links!F11,0)+IFERROR(Links!F22,0)+IFERROR(Links!F33,0)+IFERROR(Links!F44,0) -> 35161.936 | G6: =IFERROR(Links!G11,0)+IFERROR(Links!G22,0)+IFERROR(Links!G33,0)+IFERROR(Links!G44,0) -> 62115.433 | H6: =IFERROR(Links!H11,0)+IFERROR(Links!H22,0)+IFERROR(Links!H33,0)+IFERROR(Links!H44,0) -> 87300.453 | I6: =IFERROR(Links!I11,0)+IFERROR(Links!I22,0)+IFERROR(Links!I33,0)+IFERROR(Links!I44,0) -> 121673.15 | J6: =IFERROR(Links!J11,0)+IFERROR(Links!J22,0)+IFERROR(Links!J33,0)+IFERROR(Links!J44,0) -> 156133.08 | ... L6: =IFERROR(Links!L11,0)+IFERROR(Links!L22,0)+IFERROR(Links!L33,0)+IFERROR(Links!L44,0) -> 202620.64
A7: 2,5 kg | B7: Manual | C7: =IFERROR(Links!C12,0)+IFERROR(Links!C23,0)+IFERROR(Links!C34,0)+IFERROR(Links!C45,0) -> 300.03036 | D7: =IFERROR(Links!D12,0)+IFERROR(Links!D23,0)+IFERROR(Links!D34,0)+IFERROR(Links!D45,0) -> 724.12745 | E7: =IFERROR(Links!E12,0)+IFERROR(Links!E23,0)+IFERROR(Links!E34,0)+IFERROR(Links!E45,0) -> 1309.9881 | F7: =IFERROR(Links!F12,0)+IFERROR(Links!F23,0)+IFERROR(Links!F34,0)+IFERROR(Links!F45,0) -> 2581.7182 | G7: =IFERROR(Links!G12,0)+IFERROR(Links!G23,0)+IFERROR(Links!G34,0)+IFERROR(Links!G45,0) -> 4284.6277 | H7: =IFERROR(Links!H12,0)+IFERROR(Links!H23,0)+IFERROR(Links!H34,0)+IFERROR(Links!H45,0) -> 6099.5099 | I7: =IFERROR(Links!I12,0)+IFERROR(Links!I23,0)+IFERROR(Links!I34,0)+IFERROR(Links!I45,0) -> 8105.7555 | J7: =IFERROR(Links!J12,0)+IFERROR(Links!J23,0)+IFERROR(Links!J34,0)+IFERROR(Links!J45,0) -> 10259.067 | ... L7: =IFERROR(Links!L12,0)+IFERROR(Links!L23,0)+IFERROR(Links!L34,0)+IFERROR(Links!L45,0) -> 14126.338
A8: 5 kg | B8: Manual | C8: =IFERROR(Links!C13,0)+IFERROR(Links!C24,0)+IFERROR(Links!C35,0)+IFERROR(Links!C46,0) -> 2281.773 | D8: =IFERROR(Links!D13,0)+IFERROR(Links!D24,0)+IFERROR(Links!D35,0)+IFERROR(Links!D46,0) -> 3928.0589 | E8: =IFERROR(Links!E13,0)+IFERROR(Links!E24,0)+IFERROR(Links!E35,0)+IFERROR(Links!E46,0) -> 6711.7376 | F8: =IFERROR(Links!F13,0)+IFERROR(Links!F24,0)+IFERROR(Links!F35,0)+IFERROR(Links!F46,0) -> 12203.995 | G8: =IFERROR(Links!G13,0)+IFERROR(Links!G24,0)+IFERROR(Links!G35,0)+IFERROR(Links!G46,0) -> 20592.787 | H8: =IFERROR(Links!H13,0)+IFERROR(Links!H24,0)+IFERROR(Links!H35,0)+IFERROR(Links!H46,0) -> 28701.604 | I8: =IFERROR(Links!I13,0)+IFERROR(Links!I24,0)+IFERROR(Links!I35,0)+IFERROR(Links!I46,0) -> 38664.6 | J8: =IFERROR(Links!J13,0)+IFERROR(Links!J24,0)+IFERROR(Links!J35,0)+IFERROR(Links!J46,0) -> 48842.226 | ... L8: =IFERROR(Links!L13,0)+IFERROR(Links!L24,0)+IFERROR(Links!L35,0)+IFERROR(Links!L46,0) -> 63852.659
A9: 10 kg | B9: Manual | C9: =IFERROR(Links!C14,0)+IFERROR(Links!C25,0)+IFERROR(Links!C36,0)+IFERROR(Links!C47,0) -> 94.833182 | D9: =IFERROR(Links!D14,0)+IFERROR(Links!D25,0)+IFERROR(Links!D36,0)+IFERROR(Links!D47,0) -> 182.4873 | E9: =IFERROR(Links!E14,0)+IFERROR(Links!E25,0)+IFERROR(Links!E36,0)+IFERROR(Links!E47,0) -> 352.01878 | F9: =IFERROR(Links!F14,0)+IFERROR(Links!F25,0)+IFERROR(Links!F36,0)+IFERROR(Links!F47,0) -> 687.30049 | G9: =IFERROR(Links!G14,0)+IFERROR(Links!G25,0)+IFERROR(Links!G36,0)+IFERROR(Links!G47,0) -> 1200.4382 | H9: =IFERROR(Links!H14,0)+IFERROR(Links!H25,0)+IFERROR(Links!H36,0)+IFERROR(Links!H47,0) -> 1735.685 | I9: =IFERROR(Links!I14,0)+IFERROR(Links!I25,0)+IFERROR(Links!I36,0)+IFERROR(Links!I47,0) -> 2335.9605 | J9: =IFERROR(Links!J14,0)+IFERROR(Links!J25,0)+IFERROR(Links!J36,0)+IFERROR(Links!J47,0) -> 2951.5648 | ... L9: =IFERROR(Links!L14,0)+IFERROR(Links!L25,0)+IFERROR(Links!L36,0)+IFERROR(Links!L47,0) -> 3862.9281
A10: 25 kg | B10: Rodante | C10: =IFERROR(Links!C15,0)+IFERROR(Links!C26,0)+IFERROR(Links!C37,0)+IFERROR(Links!C48,0) -> 36.051791 | D10: =IFERROR(Links!D15,0)+IFERROR(Links!D26,0)+IFERROR(Links!D37,0)+IFERROR(Links!D48,0) -> 58.622147 | E10: =IFERROR(Links!E15,0)+IFERROR(Links!E26,0)+IFERROR(Links!E37,0)+IFERROR(Links!E48,0) -> 90.76854 | F10: =IFERROR(Links!F15,0)+IFERROR(Links!F26,0)+IFERROR(Links!F37,0)+IFERROR(Links!F48,0) -> 152.96985 | G10: =IFERROR(Links!G15,0)+IFERROR(Links!G26,0)+IFERROR(Links!G37,0)+IFERROR(Links!G48,0) -> 252.276 | H10: =IFERROR(Links!H15,0)+IFERROR(Links!H26,0)+IFERROR(Links!H37,0)+IFERROR(Links!H48,0) -> 349.57448 | I10: =IFERROR(Links!I15,0)+IFERROR(Links!I26,0)+IFERROR(Links!I37,0)+IFERROR(Links!I48,0) -> 465.46823 | J10: =IFERROR(Links!J15,0)+IFERROR(Links!J26,0)+IFERROR(Links!J37,0)+IFERROR(Links!J48,0) -> 586.72867 | ... L10: =IFERROR(Links!L15,0)+IFERROR(Links!L26,0)+IFERROR(Links!L37,0)+IFERROR(Links!L48,0) -> 777.31053
A11: 50 kg | B11: Rodante | C11: =IFERROR(Links!C16,0)+IFERROR(Links!C27,0)+IFERROR(Links!C38,0)+IFERROR(Links!C49,0) -> 76.913941 | D11: =IFERROR(Links!D16,0)+IFERROR(Links!D27,0)+IFERROR(Links!D38,0)+IFERROR(Links!D49,0) -> 129.77672 | E11: =IFERROR(Links!E16,0)+IFERROR(Links!E27,0)+IFERROR(Links!E38,0)+IFERROR(Links!E49,0) -> 200.49879 | F11: =IFERROR(Links!F16,0)+IFERROR(Links!F27,0)+IFERROR(Links!F38,0)+IFERROR(Links!F49,0) -> 337.44568 | G11: =IFERROR(Links!G16,0)+IFERROR(Links!G27,0)+IFERROR(Links!G38,0)+IFERROR(Links!G49,0) -> 554.00721 | H11: =IFERROR(Links!H16,0)+IFERROR(Links!H27,0)+IFERROR(Links!H38,0)+IFERROR(Links!H49,0) -> 769.13586 | I11: =IFERROR(Links!I16,0)+IFERROR(Links!I27,0)+IFERROR(Links!I38,0)+IFERROR(Links!I49,0) -> 1025.2701 | J11: =IFERROR(Links!J16,0)+IFERROR(Links!J27,0)+IFERROR(Links!J38,0)+IFERROR(Links!J49,0) -> 1292.1071 | ... L11: =IFERROR(Links!L16,0)+IFERROR(Links!L27,0)+IFERROR(Links!L38,0)+IFERROR(Links!L49,0) -> 1708.4352
A12: 70 kg | B12: Rodante | C12: =IFERROR(Links!C17,0)+IFERROR(Links!C28,0)+IFERROR(Links!C39,0)+IFERROR(Links!C50,0) -> 18.34486 | D12: =IFERROR(Links!D17,0)+IFERROR(Links!D28,0)+IFERROR(Links!D39,0)+IFERROR(Links!D50,0) -> 28.221831 | E12: =IFERROR(Links!E17,0)+IFERROR(Links!E28,0)+IFERROR(Links!E39,0)+IFERROR(Links!E50,0) -> 43.260099 | F12: =IFERROR(Links!F17,0)+IFERROR(Links!F28,0)+IFERROR(Links!F39,0)+IFERROR(Links!F50,0) -> 73.814329 | G12: =IFERROR(Links!G17,0)+IFERROR(Links!G28,0)+IFERROR(Links!G39,0)+IFERROR(Links!G50,0) -> 122.26048 | H12: =IFERROR(Links!H17,0)+IFERROR(Links!H28,0)+IFERROR(Links!H39,0)+IFERROR(Links!H50,0) -> 167.52855 | I12: =IFERROR(Links!I17,0)+IFERROR(Links!I28,0)+IFERROR(Links!I39,0)+IFERROR(Links!I50,0) -> 224.48075 | J12: =IFERROR(Links!J17,0)+IFERROR(Links!J28,0)+IFERROR(Links!J39,0)+IFERROR(Links!J50,0) -> 281.64736 | ... L12: =IFERROR(Links!L17,0)+IFERROR(Links!L28,0)+IFERROR(Links!L39,0)+IFERROR(Links!L50,0) -> 374.12986
A13: 100 kg | B13: Rodante | C13: =IFERROR(Links!C18,0)+IFERROR(Links!C29,0)+IFERROR(Links!C40,0)+IFERROR(Links!C51,0) -> 12.896573 | D13: =IFERROR(Links!D18,0)+IFERROR(Links!D29,0)+IFERROR(Links!D40,0)+IFERROR(Links!D51,0) -> 18.867887 | E13: =IFERROR(Links!E18,0)+IFERROR(Links!E29,0)+IFERROR(Links!E40,0)+IFERROR(Links!E51,0) -> 28.826733 | F13: =IFERROR(Links!F18,0)+IFERROR(Links!F29,0)+IFERROR(Links!F40,0)+IFERROR(Links!F51,0) -> 48.329553 | G13: =IFERROR(Links!G18,0)+IFERROR(Links!G29,0)+IFERROR(Links!G40,0)+IFERROR(Links!G51,0) -> 80.640321 | H13: =IFERROR(Links!H18,0)+IFERROR(Links!H29,0)+IFERROR(Links!H40,0)+IFERROR(Links!H51,0) -> 110.85903 | I13: =IFERROR(Links!I18,0)+IFERROR(Links!I29,0)+IFERROR(Links!I40,0)+IFERROR(Links!I51,0) -> 149.89383 | J13: =IFERROR(Links!J18,0)+IFERROR(Links!J29,0)+IFERROR(Links!J40,0)+IFERROR(Links!J51,0) -> 186.51157 | ... L13: =IFERROR(Links!L18,0)+IFERROR(Links!L29,0)+IFERROR(Links!L40,0)+IFERROR(Links!L51,0) -> 247.44657
A14: Total | C14: =SUM(C6:C13) -> 6999.5803 | D14: =SUM(D6:D13) -> 11067.466 | E14: =SUM(E6:E13) -> 23251.246 | F14: =SUM(F6:F13) -> 51247.509 | G14: =SUM(G6:G13) -> 89202.47 | H14: =SUM(H6:H13) -> 125234.35 | I14: =SUM(I6:I13) -> 172644.58 | J14: =SUM(J6:J13) -> 220532.93 | ... L14: =SUM(L6:L13) -> 287569.89
A16: Discos de rodantes (25 a 100 kg): se compran embutidos, no entran en este análisis.

Sheet Piezas
A1: Piezas del plano: cuerpos y discos de cúpula y fondo
A2: Medidas de los planos de recipiente (modelo 3D). El disco sale de la pieza embutida por igualdad de superficie, con su relación de embutido.
A4: A) Cuerpos (desarrollo = π·(Ø − e), fibra media)
A5: Formato | B5: Línea | C5: Plano | D5: Ø ext. (mm) | E5: Espesor (mm) | F5: Alto (mm) | G5: Desarrollo (mm) | H5: Masa (kg) | I5: Acero
A6: 1 kg | B6: Manual | C6: Plano recipiente 1 kg 3" R1 | D6: 76.2 | E6: 0.9 | F6: 263.5 | G6: =ROUND(PI()*(D6-E6)*2,0)/2 -> 236.5 | H6: =F6*G6*E6*Datos!$B$10/1000000 -> 0.44139662 | I6: LAF
A7: 2,5 kg | B7: Manual | C7: Plano recipiente 2,5 kg R2 | D7: 124 | E7: 1.25 | F7: 267.5 | G7: =ROUND(PI()*(D7-E7)*2,0)/2 -> 385.5 | H7: =F7*G7*E7*Datos!$B$10/1000000 -> 1.0144553 | I7: LAF
A8: 5 kg | B8: Manual | C8: Plano recipiente 5 kg R2 | D8: 153 | E8: 1.6 | F8: 327.5 | G8: =ROUND(PI()*(D8-E8)*2,0)/2 -> 475.5 | H8: =F8*G8*E8*Datos!$B$10/1000000 -> 1.9609049 | I8: LAF
A9: 10 kg | B9: Manual | C9: Plano recipiente 10 kg R2 | D9: 181.5 | E9: 2 | F9: 493 | G9: =ROUND(PI()*(D9-E9)*2,0)/2 -> 564 | H9: =F9*G9*E9*Datos!$B$10/1000000 -> 4.3765385 | I9: LAF
A10: 25 kg | B10: Rodante | C10: Plano recipiente 25 kg R3 | D10: 276.5 | E10: 3.2 | F10: 493 | G10: =ROUND(PI()*(D10-E10)*2,0)/2 -> 858.5 | H10: =F10*G10*E10*Datos!$B$10/1000000 -> 10.658889 | I10: LAC
A11: 50 kg | B11: Rodante | C11: Plano recipiente 50 kg R2 | D11: 320 | E11: 3.2 | F11: 640 | G11: =ROUND(PI()*(D11-E11)*2,0)/2 -> 995.5 | H11: =F11*G11*E11*Datos!$B$10/1000000 -> 16.04523 | I11: LAC
A12: 70 kg | B12: Rodante | C12: Plano extintor rodante 70 kg (Ø390) | D12: 390 | E12: 4.75 | F12: 680 | G12: =ROUND(PI()*(D12-E12)*2,0)/2 -> 1210.5 | H12: =F12*G12*E12*Datos!$B$10/1000000 -> 30.771031 | I12: LAC
A13: 100 kg | B13: Rodante | C13: Plano extintor rodante 100 kg R1 (Ø390) | D13: 390 | E13: 4.75 | F13: 900 | G13: =ROUND(PI()*(D13-E13)*2,0)/2 -> 1210.5 | H13: =F13*G13*E13*Datos!$B$10/1000000 -> 40.726365 | I13: LAC
A14: Alto: cuerpo del modelo 3D del plano (incluye el labio del encastre). 1 kg en chapa de 0,9 mm por decisión del grupo.
A16: B) Discos: igual superficie que la pieza embutida (sin sobremedida de recorte)
A17: Formato | B17: Pieza | C17: Perfil del plano | D17: Espesor e (mm) | E17: Ø ext. (mm) | F17: Altura h (mm) | G17: Pollera o pestaña p (mm) | H17: a = Ø/2 − e/2 (mm) | I17: b o profundidad (mm) | J17: Área media (mm²) | K17: D0 = √(4A/π) (mm) | L17: D0 adoptado (mm) | M17: d = 2a (mm) | N17: m = d/D0 | O17: e/D0 × 100 | P17: m1 mínimo | Q17: ¿Un solo embutido? | R17: h/d | S17: Masa del disco (kg) | T17: Plano | V17: e/D0 × 100 desde | W17: hasta | X17: m1 (1.er embutido)
A18: 1 kg | B18: Cúpula | C18: Semielipsoide + pollera | D18: 0.9 | E18: 76.2 | F18: 12.5 | G18: 6 | H18: =E18/2-D18/2 -> 37.65 | I18: =F18-G18-D18/2 -> 6.05 | J18: =PI()*H18^2+PI()*I18^2/(2*SQRT(1-(I18/H18)^2))*LN((1+SQRT(1-(I18/H18)^2))/(1-SQRT(1-(I18/H18)^2)))+2*PI()*H18*G18 -> 6165.6464 | K18: =SQRT(4*J18/PI()) -> 88.602172 | L18: =CEILING(K18,0.5) -> 89 | M18: =2*H18 -> 75.3 | N18: =M18/L18 -> 0.84606742 | O18: =D18/L18*100 -> 1.011236 | P18: =INDEX($X$18:$X$23,MATCH(O18,$V$18:$V$23,1)) -> 0.53 | Q18: =IF(N18>=P18,"Sí","No: dos embutidos") -> Sí | R18: =F18/E18 -> 0.16404199 | S18: =PI()*L18^2/4*D18*Datos!$B$10/1000000 -> 0.044064326 | T18: Plano recipiente 1 kg 3" R1 | V18: 0.08 | W18: 0.15 | X18: 0.63
A19: 1 kg | B19: Fondo | C19: Semielipsoide + pollera | D19: 1.25 | E19: 76.2 | F19: 22 | G19: 6 | H19: =E19/2-D19/2 -> 37.475 | I19: =F19-G19-D19/2 -> 15.375 | J19: =PI()*H19^2+PI()*I19^2/(2*SQRT(1-(I19/H19)^2))*LN((1+SQRT(1-(I19/H19)^2))/(1-SQRT(1-(I19/H19)^2)))+2*PI()*H19*G19 -> 7078.062 | K19: =SQRT(4*J19/PI()) -> 94.931915 | L19: =CEILING(K19,0.5) -> 95 | M19: =2*H19 -> 74.95 | N19: =M19/L19 -> 0.78894737 | O19: =D19/L19*100 -> 1.3157895 | P19: =INDEX($X$18:$X$23,MATCH(O19,$V$18:$V$23,1)) -> 0.53 | Q19: =IF(N19>=P19,"Sí","No: dos embutidos") -> Sí | R19: =F19/E19 -> 0.28871391 | S19: =PI()*L19^2/4*D19*Datos!$B$10/1000000 -> 0.069730349 | T19: Plano recipiente 1 kg 3" R1 | V19: 0.15 | W19: 0.3 | X19: 0.6
A20: 2,5 kg | B20: Cúpula | C20: Semielipsoide + pollera | D20: 1.25 | E20: 124 | F20: 39.5 | G20: 6 | H20: =E20/2-D20/2 -> 61.375 | I20: =F20-G20-D20/2 -> 32.875 | J20: =PI()*H20^2+PI()*I20^2/(2*SQRT(1-(I20/H20)^2))*LN((1+SQRT(1-(I20/H20)^2))/(1-SQRT(1-(I20/H20)^2)))+2*PI()*H20*G20 -> 19119.382 | K20: =SQRT(4*J20/PI()) -> 156.02421 | L20: =CEILING(K20,0.5) -> 156.5 | M20: =2*H20 -> 122.75 | N20: =M20/L20 -> 0.78434505 | O20: =D20/L20*100 -> 0.79872204 | P20: =INDEX($X$18:$X$23,MATCH(O20,$V$18:$V$23,1)) -> 0.55 | Q20: =IF(N20>=P20,"Sí","No: dos embutidos") -> Sí | R20: =F20/E20 -> 0.31854839 | S20: =PI()*L20^2/4*D20*Datos!$B$10/1000000 -> 0.1892358 | T20: Plano recipiente 2,5 kg R2 | V20: 0.3 | W20: 0.6 | X20: 0.58
A21: 2,5 kg | B21: Fondo | C21: Paraboloide + pestaña | D21: 1.25 | E21: 121.5 | F21: 10.5 | G21: 10 | H21: =E21/2-D21/2 -> 60.125 | I21: =F21 -> 10.5 | J21: =PI()*H21^4/(6*I21^2)*((1+4*I21^2/H21^2)^1.5-1)+2*PI()*H21*G21 -> 15474.294 | K21: =SQRT(4*J21/PI()) -> 140.36553 | L21: =CEILING(K21,0.5) -> 140.5 | M21: =2*H21 -> 120.25 | N21: =M21/L21 -> 0.85587189 | O21: =D21/L21*100 -> 0.88967972 | P21: =INDEX($X$18:$X$23,MATCH(O21,$V$18:$V$23,1)) -> 0.55 | Q21: =IF(N21>=P21,"Sí","No: dos embutidos") -> Sí | R21: =(F21+G21)/E21 -> 0.16872428 | S21: =PI()*L21^2/4*D21*Datos!$B$10/1000000 -> 0.15252017 | T21: Plano recipiente 2,5 kg R2; Ø del fondo = Ø del cuerpo − 2 e | V21: 0.6 | W21: 1 | X21: 0.55
A22: 5 kg | B22: Cúpula | C22: Semielipsoide + pollera | D22: 1.6 | E22: 153 | F22: 54.5 | G22: 6 | H22: =E22/2-D22/2 -> 75.7 | I22: =F22-G22-D22/2 -> 47.7 | J22: =PI()*H22^2+PI()*I22^2/(2*SQRT(1-(I22/H22)^2))*LN((1+SQRT(1-(I22/H22)^2))/(1-SQRT(1-(I22/H22)^2)))+2*PI()*H22*G22 -> 30398.075 | K22: =SQRT(4*J22/PI()) -> 196.7334 | L22: =CEILING(K22,0.5) -> 197 | M22: =2*H22 -> 151.4 | N22: =M22/L22 -> 0.76852792 | O22: =D22/L22*100 -> 0.81218274 | P22: =INDEX($X$18:$X$23,MATCH(O22,$V$18:$V$23,1)) -> 0.55 | Q22: =IF(N22>=P22,"Sí","No: dos embutidos") -> Sí | R22: =F22/E22 -> 0.35620915 | S22: =PI()*L22^2/4*D22*Datos!$B$10/1000000 -> 0.38381067 | T22: Plano recipiente 5 kg R2 | V22: 1 | W22: 1.5 | X22: 0.53
A23: 5 kg | B23: Fondo | C23: Paraboloide + pestaña | D23: 1.6 | E23: 149.8 | F23: 16 | G23: 10 | H23: =E23/2-D23/2 -> 74.1 | I23: =F23 -> 16 | J23: =PI()*H23^4/(6*I23^2)*((1+4*I23^2/H23^2)^1.5-1)+2*PI()*H23*G23 -> 22686.58 | K23: =SQRT(4*J23/PI()) -> 169.9572 | L23: =CEILING(K23,0.5) -> 170 | M23: =2*H23 -> 148.2 | N23: =M23/L23 -> 0.87176471 | O23: =D23/L23*100 -> 0.94117647 | P23: =INDEX($X$18:$X$23,MATCH(O23,$V$18:$V$23,1)) -> 0.55 | Q23: =IF(N23>=P23,"Sí","No: dos embutidos") -> Sí | R23: =(F23+G23)/E23 -> 0.17356475 | S23: =PI()*L23^2/4*D23*Datos!$B$10/1000000 -> 0.2858133 | T23: Plano recipiente 5 kg R2; Ø del fondo = Ø del cuerpo − 2 e | V23: 1.5 | W23: 2 | X23: 0.5
A24: 10 kg | B24: Cúpula | C24: Semielipsoide + pollera | D24: 1.6 | E24: 181.5 | F24: 62.5 | G24: 6 | H24: =E24/2-D24/2 -> 89.95 | I24: =F24-G24-D24/2 -> 55.7 | J24: =PI()*H24^2+PI()*I24^2/(2*SQRT(1-(I24/H24)^2))*LN((1+SQRT(1-(I24/H24)^2))/(1-SQRT(1-(I24/H24)^2)))+2*PI()*H24*G24 -> 41952.632 | K24: =SQRT(4*J24/PI()) -> 231.11848 | L24: =CEILING(K24,0.5) -> 231.5 | M24: =2*H24 -> 179.9 | N24: =M24/L24 -> 0.77710583 | O24: =D24/L24*100 -> 0.69114471 | P24: =INDEX($X$18:$X$23,MATCH(O24,$V$18:$V$23,1)) -> 0.55 | Q24: =IF(N24>=P24,"Sí","No: dos embutidos") -> Sí | R24: =F24/E24 -> 0.34435262 | S24: =PI()*L24^2/4*D24*Datos!$B$10/1000000 -> 0.53001308 | T24: Plano recipiente 10 kg R2 | V24: Valor alto de cada rango (lado seguro).
A25: 10 kg | B25: Fondo | C25: Paraboloide + pestaña | D25: 2 | E25: 177.5 | F25: 11.7 | G25: 10 | H25: =E25/2-D25/2 -> 87.75 | I25: =F25 -> 11.7 | J25: =PI()*H25^4/(6*I25^2)*((1+4*I25^2/H25^2)^1.5-1)+2*PI()*H25*G25 -> 30129.042 | K25: =SQRT(4*J25/PI()) -> 195.86089 | L25: =CEILING(K25,0.5) -> 196 | M25: =2*H25 -> 175.5 | N25: =M25/L25 -> 0.89540816 | O25: =D25/L25*100 -> 1.0204082 | P25: =INDEX($X$18:$X$23,MATCH(O25,$V$18:$V$23,1)) -> 0.53 | Q25: =IF(N25>=P25,"Sí","No: dos embutidos") -> Sí | R25: =(F25+G25)/E25 -> 0.12225352 | S25: =PI()*L25^2/4*D25*Datos!$B$10/1000000 -> 0.47490501 | T25: Plano recipiente 10 kg R2; Ø del fondo = Ø del cuerpo − 2 e
A27: Fuentes
A28: Disco y pieza tienen la misma superficie (el espesor no cambia): Harsle, «How to Calculate Deep Drawing Parts» (harslepress.com).
A29: Superficie del semielipsoide achatado y del paraboloide de revolución: fórmulas de geometría (MathWorld, «Oblate Spheroid» y «Paraboloid»).
A30: m1: relación de embutido del primer paso, copa sin brida, con prensachapas (EasyChair, preprint Vxvp, tabla 2). Límite general D0/d ≤ 2 (Univ. Mustansiriyah, apunte de embutido).
A31: Sin sobremedida de recorte: la prensa corta y embute en el mismo golpe, sin recorte después (W-MAN, puesto 4), y la tabla de recorte de Harsle arranca en h/d = 0,5 (estas piezas tienen h/d de 0,12 a 0,36).
A32: Geometría (Ø, alturas, pollera de 6 mm, pestaña de 10 mm, espesores): planos de recipiente (modelo 3D).

Sheet Corte
A1: Corte: cómo sale cada pieza de la hoja, la bobina, el fleje y la bobina madre
A2: Medidas de la hoja Piezas. G1 corta franjas por el lado corto de la hoja; pasan por un pulmón y G2 apoya las franjas de hojas enteras una al lado de la otra y corta una pieza de cada una por golpe.
A4: A) Cuerpos en hoja estándar con dos guillotinas en serie (B y D)
A5: Formato | B5: Hoja: lado corto (mm) | C5: Hoja: lado largo (mm) | D5: Orientación (1 alto, 2 desarrollo a lo largo) | E5: Franja = 1.er corte y tope de G1 (mm) | F5: Franjas por hoja | G5: Pieza = 2.º corte (mm) | H5: Piezas por franja | I5: Piezas por hoja | J5: Aprovech. | K5: Masa de la franja (kg) | L5: Tope de G2 (pieza u orilla, mm) | M5: Franjas que entran en G2 | N5: Hojas por ciclo | O5: Tandas de G2 por ciclo | P5: Golpes G1 por hoja | Q5: Golpes G2 por tanda | R5: Golpes G2 por hoja | S5: Min G1 por hoja | T5: Min G2 por hoja | U5: Manda | V5: Cuerpos por hora | W5: Masa de la hoja (kg) | X5: USD por hoja | Y5: Control | AA5: Tandas por hoja con ciclo de 1 hoja | AB5: 2 hojas | AC5: 3 hojas | AD5: 4 hojas | AE5: Piezas por hoja, orientación 1 | AF5: orientación 2
A6: 1 kg | B6: 1220 | C6: 2440 | D6: =IF(AE6>AF6,1,IF(AF6>AE6,2,IF(INT(C6/Piezas!$F$6)<=INT(C6/Piezas!$G$6),1,2))) -> 1 | E6: =IF(D6=1,Piezas!$F$6,Piezas!$G$6) -> 263.5 | F6: =INT(C6/E6) -> 9 | G6: =IF(D6=1,Piezas!$G$6,Piezas!$F$6) -> 236.5 | H6: =INT(B6/G6) -> 5 | I6: =F6*H6 -> 45 | J6: =I6*Piezas!$F$6*Piezas!$G$6/(B6*C6) -> 0.94205145 | K6: =E6*B6*Piezas!$E$6*Datos!$B$10/1000000 -> 2.276972 | L6: =IF(G6<=Datos!$B$37,G6,B6-H6*G6) -> 236.5 | M6: =INT(Datos!$B$36/E6) -> 9 | N6: =MATCH(MIN(AA6:AD6),AA6:AD6,0) -> 1 | O6: =ROUND(INDEX(AA6:AD6,N6)*N6,0) -> 1 | P6: =IF(C6-F6*E6>0.001,F6,F6-1) -> 9 | Q6: =IF(G6<=Datos!$B$37,IF(B6-H6*G6>0.001,H6,H6-1),1) -> 5 | R6: =Q6*O6/N6 -> 5 | S6: =P6/Datos!$B$32 -> 0.45 | T6: =R6/Datos!$B$35 -> 0.25 | U6: =IF(S6>=T6,"G1","G2") -> G1 | V6: =I6*60/MAX(S6,T6) -> 6000 | W6: =B6*C6*Piezas!$E$6*Datos!$B$10/1000000 -> 21.084674 | X6: =W6*INDEX(Datos!$C$95:$C$100,MATCH(Piezas!$E$6,Datos!$A$95:$A$100,0)) -> 28.592927 | Y6: =IF(I6=0,"No entra ninguna pieza",IF(B6>Datos!$B$33,"Hoja más ancha que la cuchilla de G1",IF(E6>Datos!$B$34,"Franja mayor que el tope de G1",IF(L6>Datos!$B$37,"2.º corte mayor que el tope de G2",IF(M6<1,"La franja no entra en G2","OK"))))) -> OK | AA6: =IFERROR(IF(1>Datos!$B$38,1000000000,CEILING(1*F6/M6,1)/1),1000000000) -> 1 | AB6: =IFERROR(IF(2>Datos!$B$38,1000000000,CEILING(2*F6/M6,1)/2),1000000000) -> 1 | AC6: =IFERROR(IF(3>Datos!$B$38,1000000000,CEILING(3*F6/M6,1)/3),1000000000) -> 1 | AD6: =IFERROR(IF(4>Datos!$B$38,1000000000,CEILING(4*F6/M6,1)/4),1000000000) -> 1 | AE6: =IF(AND(Piezas!$F$6<=Datos!$B$34,Piezas!$F$6<=Datos!$B$36,B6<=Datos!$B$33,OR(Piezas!$G$6<=Datos!$B$37,AND(INT(B6/Piezas!$G$6)=1,B6-Piezas!$G$6<=Datos!$B$37))),INT(C6/Piezas!$F$6)*INT(B6/Piezas!$G$6),0) -> 45 | AF6: =IF(AND(Piezas!$G$6<=Datos!$B$34,Piezas!$G$6<=Datos!$B$36,B6<=Datos!$B$33,OR(Piezas!$F$6<=Datos!$B$37,AND(INT(B6/Piezas!$F$6)=1,B6-Piezas!$F$6<=Datos!$B$37))),INT(C6/Piezas!$G$6)*INT(B6/Piezas!$F$6),0) -> 40
A7: 2,5 kg | B7: 1220 | C7: 2440 | D7: =IF(AE7>AF7,1,IF(AF7>AE7,2,IF(INT(C7/Piezas!$F$7)<=INT(C7/Piezas!$G$7),1,2))) -> 1 | E7: =IF(D7=1,Piezas!$F$7,Piezas!$G$7) -> 267.5 | F7: =INT(C7/E7) -> 9 | G7: =IF(D7=1,Piezas!$G$7,Piezas!$F$7) -> 385.5 | H7: =INT(B7/G7) -> 3 | I7: =F7*H7 -> 27 | J7: =I7*Piezas!$F$7*Piezas!$G$7/(B7*C7) -> 0.93532443 | K7: =E7*B7*Piezas!$E$7*Datos!$B$10/1000000 -> 3.2104681 | L7: =IF(G7<=Datos!$B$37,G7,B7-H7*G7) -> 385.5 | M7: =INT(Datos!$B$36/E7) -> 9 | N7: =MATCH(MIN(AA7:AD7),AA7:AD7,0) -> 1 | O7: =ROUND(INDEX(AA7:AD7,N7)*N7,0) -> 1 | P7: =IF(C7-F7*E7>0.001,F7,F7-1) -> 9 | Q7: =IF(G7<=Datos!$B$37,IF(B7-H7*G7>0.001,H7,H7-1),1) -> 3 | R7: =Q7*O7/N7 -> 3 | S7: =P7/Datos!$B$32 -> 0.45 | T7: =R7/Datos!$B$35 -> 0.15 | U7: =IF(S7>=T7,"G1","G2") -> G1 | V7: =I7*60/MAX(S7,T7) -> 3600 | W7: =B7*C7*Piezas!$E$7*Datos!$B$10/1000000 -> 29.28427 | X7: =W7*INDEX(Datos!$C$95:$C$100,MATCH(Piezas!$E$7,Datos!$A$95:$A$100,0)) -> 37.785427 | Y7: =IF(I7=0,"No entra ninguna pieza",IF(B7>Datos!$B$33,"Hoja más ancha que la cuchilla de G1",IF(E7>Datos!$B$34,"Franja mayor que el tope de G1",IF(L7>Datos!$B$37,"2.º corte mayor que el tope de G2",IF(M7<1,"La franja no entra en G2","OK"))))) -> OK | AA7: =IFERROR(IF(1>Datos!$B$38,1000000000,CEILING(1*F7/M7,1)/1),1000000000) -> 1 | AB7: =IFERROR(IF(2>Datos!$B$38,1000000000,CEILING(2*F7/M7,1)/2),1000000000) -> 1 | AC7: =IFERROR(IF(3>Datos!$B$38,1000000000,CEILING(3*F7/M7,1)/3),1000000000) -> 1 | AD7: =IFERROR(IF(4>Datos!$B$38,1000000000,CEILING(4*F7/M7,1)/4),1000000000) -> 1 | AE7: =IF(AND(Piezas!$F$7<=Datos!$B$34,Piezas!$F$7<=Datos!$B$36,B7<=Datos!$B$33,OR(Piezas!$G$7<=Datos!$B$37,AND(INT(B7/Piezas!$G$7)=1,B7-Piezas!$G$7<=Datos!$B$37))),INT(C7/Piezas!$F$7)*INT(B7/Piezas!$G$7),0) -> 27 | AF7: =IF(AND(Piezas!$G$7<=Datos!$B$34,Piezas!$G$7<=Datos!$B$36,B7<=Datos!$B$33,OR(Piezas!$F$7<=Datos!$B$37,AND(INT(B7/Piezas!$F$7)=1,B7-Piezas!$F$7<=Datos!$B$37))),INT(C7/Piezas!$G$7)*INT(B7/Piezas!$F$7),0) -> 24
A8: 5 kg | B8: 1000 | C8: 2000 | D8: =IF(AE8>AF8,1,IF(AF8>AE8,2,IF(INT(C8/Piezas!$F$8)<=INT(C8/Piezas!$G$8),1,2))) -> 2 | E8: =IF(D8=1,Piezas!$F$8,Piezas!$G$8) -> 475.5 | F8: =INT(C8/E8) -> 4 | G8: =IF(D8=1,Piezas!$G$8,Piezas!$F$8) -> 327.5 | H8: =INT(B8/G8) -> 3 | I8: =F8*H8 -> 12 | J8: =I8*Piezas!$F$8*Piezas!$G$8/(B8*C8) -> 0.9343575 | K8: =E8*B8*Piezas!$E$8*Datos!$B$10/1000000 -> 5.987496 | L8: =IF(G8<=Datos!$B$37,G8,B8-H8*G8) -> 327.5 | M8: =INT(Datos!$B$36/E8) -> 5 | N8: =MATCH(MIN(AA8:AD8),AA8:AD8,0) -> 1 | O8: =ROUND(INDEX(AA8:AD8,N8)*N8,0) -> 1 | P8: =IF(C8-F8*E8>0.001,F8,F8-1) -> 4 | Q8: =IF(G8<=Datos!$B$37,IF(B8-H8*G8>0.001,H8,H8-1),1) -> 3 | R8: =Q8*O8/N8 -> 3 | S8: =P8/Datos!$B$32 -> 0.2 | T8: =R8/Datos!$B$35 -> 0.15 | U8: =IF(S8>=T8,"G1","G2") -> G1 | V8: =I8*60/MAX(S8,T8) -> 3600 | W8: =B8*C8*Piezas!$E$8*Datos!$B$10/1000000 -> 25.184 | X8: =W8*INDEX(Datos!$C$95:$C$100,MATCH(Piezas!$E$8,Datos!$A$95:$A$100,0)) -> 33.43229 | Y8: =IF(I8=0,"No entra ninguna pieza",IF(B8>Datos!$B$33,"Hoja más ancha que la cuchilla de G1",IF(E8>Datos!$B$34,"Franja mayor que el tope de G1",IF(L8>Datos!$B$37,"2.º corte mayor que el tope de G2",IF(M8<1,"La franja no entra en G2","OK"))))) -> OK | AA8: =IFERROR(IF(1>Datos!$B$38,1000000000,CEILING(1*F8/M8,1)/1),1000000000) -> 1 | AB8: =IFERROR(IF(2>Datos!$B$38,1000000000,CEILING(2*F8/M8,1)/2),1000000000) -> 1 | AC8: =IFERROR(IF(3>Datos!$B$38,1000000000,CEILING(3*F8/M8,1)/3),1000000000) -> 1 | AD8: =IFERROR(IF(4>Datos!$B$38,1000000000,CEILING(4*F8/M8,1)/4),1000000000) -> 1 | AE8: =IF(AND(Piezas!$F$8<=Datos!$B$34,Piezas!$F$8<=Datos!$B$36,B8<=Datos!$B$33,OR(Piezas!$G$8<=Datos!$B$37,AND(INT(B8/Piezas!$G$8)=1,B8-Piezas!$G$8<=Datos!$B$37))),INT(C8/Piezas!$F$8)*INT(B8/Piezas!$G$8),0) -> 12 | AF8: =IF(AND(Piezas!$G$8<=Datos!$B$34,Piezas!$G$8<=Datos!$B$36,B8<=Datos!$B$33,OR(Piezas!$F$8<=Datos!$B$37,AND(INT(B8/Piezas!$F$8)=1,B8-Piezas!$F$8<=Datos!$B$37))),INT(C8/Piezas!$G$8)*INT(B8/Piezas!$F$8),0) -> 12
A9: 10 kg | B9: 1500 | C9: 3000 | D9: =IF(AE9>AF9,1,IF(AF9>AE9,2,IF(INT(C9/Piezas!$F$9)<=INT(C9/Piezas!$G$9),1,2))) -> 2 | E9: =IF(D9=1,Piezas!$F$9,Piezas!$G$9) -> 564 | F9: =INT(C9/E9) -> 5 | G9: =IF(D9=1,Piezas!$G$9,Piezas!$F$9) -> 493 | H9: =INT(B9/G9) -> 3 | I9: =F9*H9 -> 15 | J9: =I9*Piezas!$F$9*Piezas!$G$9/(B9*C9) -> 0.92684 | K9: =E9*B9*Piezas!$E$9*Datos!$B$10/1000000 -> 13.31604 | L9: =IF(G9<=Datos!$B$37,G9,B9-H9*G9) -> 493 | M9: =INT(Datos!$B$36/E9) -> 4 | N9: =MATCH(MIN(AA9:AD9),AA9:AD9,0) -> 4 | O9: =ROUND(INDEX(AA9:AD9,N9)*N9,0) -> 5 | P9: =IF(C9-F9*E9>0.001,F9,F9-1) -> 5 | Q9: =IF(G9<=Datos!$B$37,IF(B9-H9*G9>0.001,H9,H9-1),1) -> 3 | R9: =Q9*O9/N9 -> 3.75 | S9: =P9/Datos!$B$32 -> 0.25 | T9: =R9/Datos!$B$35 -> 0.1875 | U9: =IF(S9>=T9,"G1","G2") -> G1 | V9: =I9*60/MAX(S9,T9) -> 3600 | W9: =B9*C9*Piezas!$E$9*Datos!$B$10/1000000 -> 70.83 | X9: =W9*INDEX(Datos!$C$95:$C$100,MATCH(Piezas!$E$9,Datos!$A$95:$A$100,0)) -> 90.690824 | Y9: =IF(I9=0,"No entra ninguna pieza",IF(B9>Datos!$B$33,"Hoja más ancha que la cuchilla de G1",IF(E9>Datos!$B$34,"Franja mayor que el tope de G1",IF(L9>Datos!$B$37,"2.º corte mayor que el tope de G2",IF(M9<1,"La franja no entra en G2","OK"))))) -> OK | AA9: =IFERROR(IF(1>Datos!$B$38,1000000000,CEILING(1*F9/M9,1)/1),1000000000) -> 2 | AB9: =IFERROR(IF(2>Datos!$B$38,1000000000,CEILING(2*F9/M9,1)/2),1000000000) -> 1.5 | AC9: =IFERROR(IF(3>Datos!$B$38,1000000000,CEILING(3*F9/M9,1)/3),1000000000) -> 1.3333333 | AD9: =IFERROR(IF(4>Datos!$B$38,1000000000,CEILING(4*F9/M9,1)/4),1000000000) -> 1.25 | AE9: =IF(AND(Piezas!$F$9<=Datos!$B$34,Piezas!$F$9<=Datos!$B$36,B9<=Datos!$B$33,OR(Piezas!$G$9<=Datos!$B$37,AND(INT(B9/Piezas!$G$9)=1,B9-Piezas!$G$9<=Datos!$B$37))),INT(C9/Piezas!$F$9)*INT(B9/Piezas!$G$9),0) -> 12 | AF9: =IF(AND(Piezas!$G$9<=Datos!$B$34,Piezas!$G$9<=Datos!$B$36,B9<=Datos!$B$33,OR(Piezas!$F$9<=Datos!$B$37,AND(INT(B9/Piezas!$F$9)=1,B9-Piezas!$F$9<=Datos!$B$37))),INT(C9/Piezas!$G$9)*INT(B9/Piezas!$F$9),0) -> 15
A10: 25 kg | B10: 1500 | C10: 3000 | D10: =IF(AE10>AF10,1,IF(AF10>AE10,2,IF(INT(C10/Piezas!$F$10)<=INT(C10/Piezas!$G$10),1,2))) -> 2 | E10: =IF(D10=1,Piezas!$F$10,Piezas!$G$10) -> 858.5 | F10: =INT(C10/E10) -> 3 | G10: =IF(D10=1,Piezas!$G$10,Piezas!$F$10) -> 493 | H10: =INT(B10/G10) -> 3 | I10: =F10*H10 -> 9 | J10: =I10*Piezas!$F$10*Piezas!$G$10/(B10*C10) -> 0.846481 | K10: =E10*B10*Piezas!$E$10*Datos!$B$10/1000000 -> 32.430696 | L10: =IF(G10<=Datos!$B$37,G10,B10-H10*G10) -> 493 | M10: =INT(Datos!$B$36/E10) -> 2 | N10: =MATCH(MIN(AA10:AD10),AA10:AD10,0) -> 2 | O10: =ROUND(INDEX(AA10:AD10,N10)*N10,0) -> 3 | P10: =IF(C10-F10*E10>0.001,F10,F10-1) -> 3 | Q10: =IF(G10<=Datos!$B$37,IF(B10-H10*G10>0.001,H10,H10-1),1) -> 3 | R10: =Q10*O10/N10 -> 4.5 | S10: =P10/Datos!$B$32 -> 0.15 | T10: =R10/Datos!$B$35 -> 0.225 | U10: =IF(S10>=T10,"G1","G2") -> G2 | V10: =I10*60/MAX(S10,T10) -> 2400 | W10: =B10*C10*Piezas!$E$10*Datos!$B$10/1000000 -> 113.328 | X10: =W10*INDEX(Datos!$C$95:$C$100,MATCH(Piezas!$E$10,Datos!$A$95:$A$100,0)) -> 124.88012 | Y10: =IF(I10=0,"No entra ninguna pieza",IF(B10>Datos!$B$33,"Hoja más ancha que la cuchilla de G1",IF(E10>Datos!$B$34,"Franja mayor que el tope de G1",IF(L10>Datos!$B$37,"2.º corte mayor que el tope de G2",IF(M10<1,"La franja no entra en G2","OK"))))) -> OK | AA10: =IFERROR(IF(1>Datos!$B$38,1000000000,CEILING(1*F10/M10,1)/1),1000000000) -> 2 | AB10: =IFERROR(IF(2>Datos!$B$38,1000000000,CEILING(2*F10/M10,1)/2),1000000000) -> 1.5 | AC10: =IFERROR(IF(3>Datos!$B$38,1000000000,CEILING(3*F10/M10,1)/3),1000000000) -> 1.6666667 | AD10: =IFERROR(IF(4>Datos!$B$38,1000000000,CEILING(4*F10/M10,1)/4),1000000000) -> 1.5 | AE10: =IF(AND(Piezas!$F$10<=Datos!$B$34,Piezas!$F$10<=Datos!$B$36,B10<=Datos!$B$33,OR(Piezas!$G$10<=Datos!$B$37,AND(INT(B10/Piezas!$G$10)=1,B10-Piezas!$G$10<=Datos!$B$37))),INT(C10/Piezas!$F$10)*INT(B10/Piezas!$G$10),0) -> 6 | AF10: =IF(AND(Piezas!$G$10<=Datos!$B$34,Piezas!$G$10<=Datos!$B$36,B10<=Datos!$B$33,OR(Piezas!$F$10<=Datos!$B$37,AND(INT(B10/Piezas!$F$10)=1,B10-Piezas!$F$10<=Datos!$B$37))),INT(C10/Piezas!$G$10)*INT(B10/Piezas!$F$10),0) -> 9
A11: 50 kg | B11: 1500 | C11: 3000 | D11: =IF(AE11>AF11,1,IF(AF11>AE11,2,IF(INT(C11/Piezas!$F$11)<=INT(C11/Piezas!$G$11),1,2))) -> 2 | E11: =IF(D11=1,Piezas!$F$11,Piezas!$G$11) -> 995.5 | F11: =INT(C11/E11) -> 3 | G11: =IF(D11=1,Piezas!$G$11,Piezas!$F$11) -> 640 | H11: =INT(B11/G11) -> 2 | I11: =F11*H11 -> 6 | J11: =I11*Piezas!$F$11*Piezas!$G$11/(B11*C11) -> 0.84949333 | K11: =E11*B11*Piezas!$E$11*Datos!$B$10/1000000 -> 37.606008 | L11: =IF(G11<=Datos!$B$37,G11,B11-H11*G11) -> 640 | M11: =INT(Datos!$B$36/E11) -> 2 | N11: =MATCH(MIN(AA11:AD11),AA11:AD11,0) -> 2 | O11: =ROUND(INDEX(AA11:AD11,N11)*N11,0) -> 3 | P11: =IF(C11-F11*E11>0.001,F11,F11-1) -> 3 | Q11: =IF(G11<=Datos!$B$37,IF(B11-H11*G11>0.001,H11,H11-1),1) -> 2 | R11: =Q11*O11/N11 -> 3 | S11: =P11/Datos!$B$32 -> 0.15 | T11: =R11/Datos!$B$35 -> 0.15 | U11: =IF(S11>=T11,"G1","G2") -> G1 | V11: =I11*60/MAX(S11,T11) -> 2400 | W11: =B11*C11*Piezas!$E$11*Datos!$B$10/1000000 -> 113.328 | X11: =W11*INDEX(Datos!$C$95:$C$100,MATCH(Piezas!$E$11,Datos!$A$95:$A$100,0)) -> 124.88012 | Y11: =IF(I11=0,"No entra ninguna pieza",IF(B11>Datos!$B$33,"Hoja más ancha que la cuchilla de G1",IF(E11>Datos!$B$34,"Franja mayor que el tope de G1",IF(L11>Datos!$B$37,"2.º corte mayor que el tope de G2",IF(M11<1,"La franja no entra en G2","OK"))))) -> OK | AA11: =IFERROR(IF(1>Datos!$B$38,1000000000,CEILING(1*F11/M11,1)/1),1000000000) -> 2 | AB11: =IFERROR(IF(2>Datos!$B$38,1000000000,CEILING(2*F11/M11,1)/2),1000000000) -> 1.5 | AC11: =IFERROR(IF(3>Datos!$B$38,1000000000,CEILING(3*F11/M11,1)/3),1000000000) -> 1.6666667 | AD11: =IFERROR(IF(4>Datos!$B$38,1000000000,CEILING(4*F11/M11,1)/4),1000000000) -> 1.5 | AE11: =IF(AND(Piezas!$F$11<=Datos!$B$34,Piezas!$F$11<=Datos!$B$36,B11<=Datos!$B$33,OR(Piezas!$G$11<=Datos!$B$37,AND(INT(B11/Piezas!$G$11)=1,B11-Piezas!$G$11<=Datos!$B$37))),INT(C11/Piezas!$F$11)*INT(B11/Piezas!$G$11),0) -> 4 | AF11: =IF(AND(Piezas!$G$11<=Datos!$B$34,Piezas!$G$11<=Datos!$B$36,B11<=Datos!$B$33,OR(Piezas!$F$11<=Datos!$B$37,AND(INT(B11/Piezas!$F$11)=1,B11-Piezas!$F$11<=Datos!$B$37))),INT(C11/Piezas!$G$11)*INT(B11/Piezas!$F$11),0) -> 6
A12: 70 kg | B12: 1500 | C12: 3000 | D12: =IF(AE12>AF12,1,IF(AF12>AE12,2,IF(INT(C12/Piezas!$F$12)<=INT(C12/Piezas!$G$12),1,2))) -> 1 | E12: =IF(D12=1,Piezas!$F$12,Piezas!$G$12) -> 680 | F12: =INT(C12/E12) -> 4 | G12: =IF(D12=1,Piezas!$G$12,Piezas!$F$12) -> 1210.5 | H12: =INT(B12/G12) -> 1 | I12: =F12*H12 -> 4 | J12: =I12*Piezas!$F$12*Piezas!$G$12/(B12*C12) -> 0.73168 | K12: =E12*B12*Piezas!$E$12*Datos!$B$10/1000000 -> 38.13015 | L12: =IF(G12<=Datos!$B$37,G12,B12-H12*G12) -> 289.5 | M12: =INT(Datos!$B$36/E12) -> 3 | N12: =MATCH(MIN(AA12:AD12),AA12:AD12,0) -> 3 | O12: =ROUND(INDEX(AA12:AD12,N12)*N12,0) -> 4 | P12: =IF(C12-F12*E12>0.001,F12,F12-1) -> 4 | Q12: =IF(G12<=Datos!$B$37,IF(B12-H12*G12>0.001,H12,H12-1),1) -> 1 | R12: =Q12*O12/N12 -> 1.3333333 | S12: =P12/Datos!$B$32 -> 0.2 | T12: =R12/Datos!$B$35 -> 0.066666667 | U12: =IF(S12>=T12,"G1","G2") -> G1 | V12: =I12*60/MAX(S12,T12) -> 1200 | W12: =B12*C12*Piezas!$E$12*Datos!$B$10/1000000 -> 168.22125 | X12: =W12*INDEX(Datos!$C$95:$C$100,MATCH(Piezas!$E$12,Datos!$A$95:$A$100,0)) -> 183.52557 | Y12: =IF(IF(I12=0,"No entra ninguna pieza",IF(B12>Datos!$B$33,"Hoja más ancha que la cuchilla de G1",IF(E12>Datos!$B$34,"Franja mayor que el tope de G1",IF(L12>Datos!$B$37,"2.º corte mayor que el tope de G2",IF(M12<1,"La franja no entra en G2","OK")))))="OK",IF(Datos!$B$24="SI","OK; con mezcla va en la hoja mixta","OK"),IF(I12=0,"No entra ninguna pieza",IF(B12>Datos!$B$33,"Hoja más ancha que la cuchilla de G1",IF(E12>Datos!$B$34,"Franja mayor que el tope de G1",IF(L12>Datos!$B$37,"2.º corte mayor que el tope de G2",IF(M12<1,"La franja no entra en G2","OK")))))) -> OK; con mezcla va en la hoja mixta | AA12: =IFERROR(IF(1>Datos!$B$38,1000000000,CEILING(1*F12/M12,1)/1),1000000000) -> 2 | AB12: =IFERROR(IF(2>Datos!$B$38,1000000000,CEILING(2*F12/M12,1)/2),1000000000) -> 1.5 | AC12: =IFERROR(IF(3>Datos!$B$38,1000000000,CEILING(3*F12/M12,1)/3),1000000000) -> 1.3333333 | AD12: =IFERROR(IF(4>Datos!$B$38,1000000000,CEILING(4*F12/M12,1)/4),1000000000) -> 1.5 | AE12: =IF(AND(Piezas!$F$12<=Datos!$B$34,Piezas!$F$12<=Datos!$B$36,B12<=Datos!$B$33,OR(Piezas!$G$12<=Datos!$B$37,AND(INT(B12/Piezas!$G$12)=1,B12-Piezas!$G$12<=Datos!$B$37))),INT(C12/Piezas!$F$12)*INT(B12/Piezas!$G$12),0) -> 4 | AF12: =IF(AND(Piezas!$G$12<=Datos!$B$34,Piezas!$G$12<=Datos!$B$36,B12<=Datos!$B$33,OR(Piezas!$F$12<=Datos!$B$37,AND(INT(B12/Piezas!$F$12)=1,B12-Piezas!$F$12<=Datos!$B$37))),INT(C12/Piezas!$G$12)*INT(B12/Piezas!$F$12),0) -> 0
A13: 100 kg | B13: 1500 | C13: 3000 | D13: =IF(AE13>AF13,1,IF(AF13>AE13,2,IF(INT(C13/Piezas!$F$13)<=INT(C13/Piezas!$G$13),1,2))) -> 1 | E13: =IF(D13=1,Piezas!$F$13,Piezas!$G$13) -> 900 | F13: =INT(C13/E13) -> 3 | G13: =IF(D13=1,Piezas!$G$13,Piezas!$F$13) -> 1210.5 | H13: =INT(B13/G13) -> 1 | I13: =F13*H13 -> 3 | J13: =I13*Piezas!$F$13*Piezas!$G$13/(B13*C13) -> 0.7263 | K13: =E13*B13*Piezas!$E$13*Datos!$B$10/1000000 -> 50.466375 | L13: =IF(G13<=Datos!$B$37,G13,B13-H13*G13) -> 289.5 | M13: =INT(Datos!$B$36/E13) -> 2 | N13: =MATCH(MIN(AA13:AD13),AA13:AD13,0) -> 2 | O13: =ROUND(INDEX(AA13:AD13,N13)*N13,0) -> 3 | P13: =IF(C13-F13*E13>0.001,F13,F13-1) -> 3 | Q13: =IF(G13<=Datos!$B$37,IF(B13-H13*G13>0.001,H13,H13-1),1) -> 1 | R13: =Q13*O13/N13 -> 1.5 | S13: =P13/Datos!$B$32 -> 0.15 | T13: =R13/Datos!$B$35 -> 0.075 | U13: =IF(S13>=T13,"G1","G2") -> G1 | V13: =I13*60/MAX(S13,T13) -> 1200 | W13: =B13*C13*Piezas!$E$13*Datos!$B$10/1000000 -> 168.22125 | X13: =W13*INDEX(Datos!$C$95:$C$100,MATCH(Piezas!$E$13,Datos!$A$95:$A$100,0)) -> 183.52557 | Y13: =IF(I13=0,"No entra ninguna pieza",IF(B13>Datos!$B$33,"Hoja más ancha que la cuchilla de G1",IF(E13>Datos!$B$34,"Franja mayor que el tope de G1",IF(L13>Datos!$B$37,"2.º corte mayor que el tope de G2",IF(M13<1,"La franja no entra en G2","OK"))))) -> OK | AA13: =IFERROR(IF(1>Datos!$B$38,1000000000,CEILING(1*F13/M13,1)/1),1000000000) -> 2 | AB13: =IFERROR(IF(2>Datos!$B$38,1000000000,CEILING(2*F13/M13,1)/2),1000000000) -> 1.5 | AC13: =IFERROR(IF(3>Datos!$B$38,1000000000,CEILING(3*F13/M13,1)/3),1000000000) -> 1.6666667 | AD13: =IFERROR(IF(4>Datos!$B$38,1000000000,CEILING(4*F13/M13,1)/4),1000000000) -> 1.5 | AE13: =IF(AND(Piezas!$F$13<=Datos!$B$34,Piezas!$F$13<=Datos!$B$36,B13<=Datos!$B$33,OR(Piezas!$G$13<=Datos!$B$37,AND(INT(B13/Piezas!$G$13)=1,B13-Piezas!$G$13<=Datos!$B$37))),INT(C13/Piezas!$F$13)*INT(B13/Piezas!$G$13),0) -> 3 | AF13: =IF(AND(Piezas!$G$13<=Datos!$B$34,Piezas!$G$13<=Datos!$B$36,B13<=Datos!$B$33,OR(Piezas!$F$13<=Datos!$B$37,AND(INT(B13/Piezas!$F$13)=1,B13-Piezas!$F$13<=Datos!$B$37))),INT(C13/Piezas!$G$13)*INT(B13/Piezas!$F$13),0) -> 0
A14: Hoja mixta 70 + 100 kg | B14: =B13 -> 1500 | C14: =C13 -> 3000 | D14: 1 | E14: =MAX(Piezas!$F$13,Piezas!$F$12) -> 900 | F14: =Datos!$B$25+Datos!$B$26 -> 4 | G14: =MAX(Piezas!$G$13,Piezas!$G$12) -> 1210.5 | H14: =INT(B14/G14) -> 1 | I14: =F14*H14 -> 4 | J14: =(Datos!$B$25*Piezas!$F$13*Piezas!$G$13+Datos!$B$26*Piezas!$F$12*Piezas!$G$12)/(B14*C14) -> 0.79086 | K14: =E14*B14*Piezas!$E$13*Datos!$B$10/1000000 -> 50.466375 | L14: =IF(G14<=Datos!$B$37,G14,B14-H14*G14) -> 289.5 | M14: =INT(Datos!$B$36/MIN(Piezas!$F$13,Piezas!$F$12)) -> 3 | N14: =MATCH(MIN(AA14:AD14),AA14:AD14,0) -> 3 | O14: =ROUND(INDEX(AA14:AD14,N14)*N14,0) -> 4 | P14: =IF(C14-(Datos!$B$25*Piezas!$F$13+Datos!$B$26*Piezas!$F$12)>0.001,F14,F14-1) -> 4 | Q14: =IF(G14<=Datos!$B$37,IF(B14-H14*G14>0.001,H14,H14-1),1) -> 1 | R14: =Q14*O14/N14 -> 1.3333333 | S14: =P14/Datos!$B$32 -> 0.2 | T14: =R14/Datos!$B$35 -> 0.066666667 | U14: =IF(S14>=T14,"G1","G2") -> G1 | V14: =I14*60/MAX(S14,T14) -> 1200 | W14: =B14*C14*Piezas!$E$13*Datos!$B$10/1000000 -> 168.22125 | X14: =W14*INDEX(Datos!$C$95:$C$100,MATCH(Piezas!$E$13,Datos!$A$95:$A$100,0)) -> 183.52557 | Y14: =IF(AND(Piezas!$G$12<=B14,Piezas!$G$13<=B14,(Datos!$B$25*Piezas!$F$13+Datos!$B$26*Piezas!$F$12)<=C14,E14<=Datos!$B$34,L14<=Datos!$B$37),"OK: "&Datos!$B$25&" de 100 kg y "&Datos!$B$26&" de 70 kg","No entra") -> OK: 1 de 100 kg y 3 de 70 kg | AA14: =IFERROR(IF(1>Datos!$B$38,1000000000,MAX(CEILING(1*F14/M14,1),CEILING(1*(Datos!$B$25*Piezas!$F$13+Datos!$B$26*Piezas!$F$12)/Datos!$B$36,1))/1),1000000000) -> 2 | AB14: =IFERROR(IF(2>Datos!$B$38,1000000000,MAX(CEILING(2*F14/M14,1),CEILING(2*(Datos!$B$25*Piezas!$F$13+Datos!$B$26*Piezas!$F$12)/Datos!$B$36,1))/2),1000000000) -> 1.5 | AC14: =IFERROR(IF(3>Datos!$B$38,1000000000,MAX(CEILING(3*F14/M14,1),CEILING(3*(Datos!$B$25*Piezas!$F$13+Datos!$B$26*Piezas!$F$12)/Datos!$B$36,1))/3),1000000000) -> 1.3333333 | AD14: =IFERROR(IF(4>Datos!$B$38,1000000000,MAX(CEILING(4*F14/M14,1),CEILING(4*(Datos!$B$25*Piezas!$F$13+Datos!$B$26*Piezas!$F$12)/Datos!$B$36,1))/4),1000000000) -> 1.5
A15: 1.er corte por el lado corto (franjas de hasta 1.500 mm de largo). G1 hace solo el 1.er corte y G2 solo el 2.º: la pieza, o la orilla si la pieza supera el tope. Franjas en paralelo: hojas enteras, con el ciclo que da menos tandas por hoja (Datos, «Hojas por ciclo»).
A17: Para los Aprovechamientos de Manuales (1 a 10 kg) y Carros (25 a 100 kg): IMPORTRANGE
A18: Formato | B18: Piezas por hoja | C18: Golpes G1 por hoja | D18: Golpes G2 por hoja | E18: Tandas de G2 por hoja | F18: Golpes por minuto G1 | G18: Golpes por minuto G2
A19: =A6 -> 1 kg | B19: =I6 -> 45 | C19: =P6 -> 9 | D19: =R6 -> 5 | E19: =O6/N6 -> 1 | F19: =Datos!$B$32 -> 20 | G19: =Datos!$B$35 -> 20
A20: =A7 -> 2,5 kg | B20: =I7 -> 27 | C20: =P7 -> 9 | D20: =R7 -> 3 | E20: =O7/N7 -> 1 | F20: =Datos!$B$32 -> 20 | G20: =Datos!$B$35 -> 20
A21: =A8 -> 5 kg | B21: =I8 -> 12 | C21: =P8 -> 4 | D21: =R8 -> 3 | E21: =O8/N8 -> 1 | F21: =Datos!$B$32 -> 20 | G21: =Datos!$B$35 -> 20
A22: =A9 -> 10 kg | B22: =I9 -> 15 | C22: =P9 -> 5 | D22: =R9 -> 3.75 | E22: =O9/N9 -> 1.25 | F22: =Datos!$B$32 -> 20 | G22: =Datos!$B$35 -> 20
A23: =A10 -> 25 kg | B23: =IF(Datos!$B$27="SI",Nesting!$B$52,I10) -> 7.1119843 | C23: =IF(Datos!$B$27="SI",Nesting!$B$53,P10) -> 3 | D23: =IF(Datos!$B$27="SI",Nesting!$B$54,R10) -> 4.1119843 | E23: =IF(Datos!$B$27="SI",Nesting!$B$55,O10/N10) -> 2.0559921 | F23: =Datos!$B$32 -> 20 | G23: =Datos!$B$35 -> 20
A24: =A11 -> 50 kg | B24: =IF(Datos!$B$27="SI",Nesting!$B$52,I11) -> 7.1119843 | C24: =IF(Datos!$B$27="SI",Nesting!$B$53,P11) -> 3 | D24: =IF(Datos!$B$27="SI",Nesting!$B$54,R11) -> 4.1119843 | E24: =IF(Datos!$B$27="SI",Nesting!$B$55,O11/N11) -> 2.0559921 | F24: =Datos!$B$32 -> 20 | G24: =Datos!$B$35 -> 20
A25: =A12 -> 70 kg | B25: =I12 -> 4 | C25: =P12 -> 4 | D25: =R12 -> 1.3333333 | E25: =O12/N12 -> 1.3333333 | F25: =Datos!$B$32 -> 20 | G25: =Datos!$B$35 -> 20
A26: =A13 -> 100 kg | B26: =I13 -> 3 | C26: =P13 -> 3 | D26: =R13 -> 1.5 | E26: =O13/N13 -> 1.5 | F26: =Datos!$B$32 -> 20 | G26: =Datos!$B$35 -> 20
A27: =A14 -> Hoja mixta 70 + 100 kg | B27: =I14 -> 4 | C27: =P14 -> 4 | D27: =R14 -> 1.3333333 | E27: =O14/N14 -> 1.3333333 | F27: =Datos!$B$32 -> 20 | G27: =Datos!$B$35 -> 20
A30: B) Cuerpos en bobina de ancho estándar con línea de corte transversal (A) y a medida (Ref.)
A31: Formato | B31: Ancho de bobina (mm) | C31: Piezas por golpe | D31: Avance por golpe (mm) | E31: Aprovech. | F31: kg comprados por cuerpo | G31: USD por cuerpo | H31: Peso de bobina (t) | I31: USD por cuerpo a medida (Ref.)
A32: 1 kg | B32: 1220 | C32: =IF(INT((B32-Datos!$B$19)/Piezas!$F$6)*Piezas!$F$6/B32>=INT((B32-Datos!$B$19)/Piezas!$G$6)*Piezas!$G$6/B32,INT((B32-Datos!$B$19)/Piezas!$F$6),INT((B32-Datos!$B$19)/Piezas!$G$6)) -> 5 | D32: =IF(INT((B32-Datos!$B$19)/Piezas!$F$6)*Piezas!$F$6/B32>=INT((B32-Datos!$B$19)/Piezas!$G$6)*Piezas!$G$6/B32,Piezas!$G$6,Piezas!$F$6) -> 263.5 | E32: =MAX(INT((B32-Datos!$B$19)/Piezas!$F$6)*Piezas!$F$6/B32,INT((B32-Datos!$B$19)/Piezas!$G$6)*Piezas!$G$6/B32)*(1-Datos!$B$20) -> 0.96441598 | F32: =Piezas!$H$6/E32 -> 0.45768282 | G32: =F32*INDEX(Datos!$B$95:$B$100,MATCH(Piezas!$E$6,Datos!$A$95:$A$100,0)) -> 0.57798474 | H32: =MIN(ROUNDDOWN(MIN(B32*Datos!$B$57,Datos!$B$58)*2,0)/2,MAX(Datos!$B$54,ROUNDUP(INDEX(Demanda!$C$6:$L$6,Datos!$B$6-2025)*F32/1000/12*Datos!$B$52*2,0)/2)) -> 8 | I32: =Piezas!$H$6*INDEX(Datos!$F$95:$F$100,MATCH(Piezas!$E$6,Datos!$A$95:$A$100,0)) -> 0.59857796
A33: 2,5 kg | B33: 1220 | C33: =IF(INT((B33-Datos!$B$19)/Piezas!$F$7)*Piezas!$F$7/B33>=INT((B33-Datos!$B$19)/Piezas!$G$7)*Piezas!$G$7/B33,INT((B33-Datos!$B$19)/Piezas!$F$7),INT((B33-Datos!$B$19)/Piezas!$G$7)) -> 3 | D33: =IF(INT((B33-Datos!$B$19)/Piezas!$F$7)*Piezas!$F$7/B33>=INT((B33-Datos!$B$19)/Piezas!$G$7)*Piezas!$G$7/B33,Piezas!$G$7,Piezas!$F$7) -> 267.5 | E33: =MAX(INT((B33-Datos!$B$19)/Piezas!$F$7)*Piezas!$F$7/B33,INT((B33-Datos!$B$19)/Piezas!$G$7)*Piezas!$G$7/B33)*(1-Datos!$B$20) -> 0.94321107 | F33: =Piezas!$H$7/E33 -> 1.0755337 | G33: =F33*INDEX(Datos!$B$95:$B$100,MATCH(Piezas!$E$7,Datos!$A$95:$A$100,0)) -> 1.3450194 | H33: =MIN(ROUNDDOWN(MIN(B33*Datos!$B$57,Datos!$B$58)*2,0)/2,MAX(Datos!$B$54,ROUNDUP(INDEX(Demanda!$C$7:$L$7,Datos!$B$6-2025)*F33/1000/12*Datos!$B$52*2,0)/2)) -> 1.5 | I33: =Piezas!$H$7*INDEX(Datos!$F$95:$F$100,MATCH(Piezas!$E$7,Datos!$A$95:$A$100,0)) -> 1.4466133
A34: 5 kg | B34: 1000 | C34: =IF(INT((B34-Datos!$B$19)/Piezas!$F$8)*Piezas!$F$8/B34>=INT((B34-Datos!$B$19)/Piezas!$G$8)*Piezas!$G$8/B34,INT((B34-Datos!$B$19)/Piezas!$F$8),INT((B34-Datos!$B$19)/Piezas!$G$8)) -> 3 | D34: =IF(INT((B34-Datos!$B$19)/Piezas!$F$8)*Piezas!$F$8/B34>=INT((B34-Datos!$B$19)/Piezas!$G$8)*Piezas!$G$8/B34,Piezas!$G$8,Piezas!$F$8) -> 475.5 | E34: =MAX(INT((B34-Datos!$B$19)/Piezas!$F$8)*Piezas!$F$8/B34,INT((B34-Datos!$B$19)/Piezas!$G$8)*Piezas!$G$8/B34)*(1-Datos!$B$20) -> 0.9775875 | F34: =Piezas!$H$8/E34 -> 2.0058613 | G34: =F34*INDEX(Datos!$B$95:$B$100,MATCH(Piezas!$E$8,Datos!$A$95:$A$100,0)) -> 2.5084499 | H34: =MIN(ROUNDDOWN(MIN(B34*Datos!$B$57,Datos!$B$58)*2,0)/2,MAX(Datos!$B$54,ROUNDUP(INDEX(Demanda!$C$8:$L$8,Datos!$B$6-2025)*F34/1000/12*Datos!$B$52*2,0)/2)) -> 10 | I34: =Piezas!$H$8*INDEX(Datos!$F$95:$F$100,MATCH(Piezas!$E$8,Datos!$A$95:$A$100,0)) -> 2.8491949
A35: 10 kg | B35: 1000 | C35: =IF(INT((B35-Datos!$B$19)/Piezas!$F$9)*Piezas!$F$9/B35>=INT((B35-Datos!$B$19)/Piezas!$G$9)*Piezas!$G$9/B35,INT((B35-Datos!$B$19)/Piezas!$F$9),INT((B35-Datos!$B$19)/Piezas!$G$9)) -> 2 | D35: =IF(INT((B35-Datos!$B$19)/Piezas!$F$9)*Piezas!$F$9/B35>=INT((B35-Datos!$B$19)/Piezas!$G$9)*Piezas!$G$9/B35,Piezas!$G$9,Piezas!$F$9) -> 564 | E35: =MAX(INT((B35-Datos!$B$19)/Piezas!$F$9)*Piezas!$F$9/B35,INT((B35-Datos!$B$19)/Piezas!$G$9)*Piezas!$G$9/B35)*(1-Datos!$B$20) -> 0.98107 | F35: =Piezas!$H$9/E35 -> 4.4609849 | G35: =F35*INDEX(Datos!$B$95:$B$100,MATCH(Piezas!$E$9,Datos!$A$95:$A$100,0)) -> 5.6335548 | H35: =MIN(ROUNDDOWN(MIN(B35*Datos!$B$57,Datos!$B$58)*2,0)/2,MAX(Datos!$B$54,ROUNDUP(INDEX(Demanda!$C$9:$L$9,Datos!$B$6-2025)*F35/1000/12*Datos!$B$52*2,0)/2)) -> 1.5 | I35: =Piezas!$H$9*INDEX(Datos!$F$95:$F$100,MATCH(Piezas!$E$9,Datos!$A$95:$A$100,0)) -> 6.2540735
A36: 25 kg | B36: 1500 | C36: =IF(INT((B36-Datos!$B$19)/Piezas!$F$10)*Piezas!$F$10/B36>=INT((B36-Datos!$B$19)/Piezas!$G$10)*Piezas!$G$10/B36,INT((B36-Datos!$B$19)/Piezas!$F$10),INT((B36-Datos!$B$19)/Piezas!$G$10)) -> 3 | D36: =IF(INT((B36-Datos!$B$19)/Piezas!$F$10)*Piezas!$F$10/B36>=INT((B36-Datos!$B$19)/Piezas!$G$10)*Piezas!$G$10/B36,Piezas!$G$10,Piezas!$F$10) -> 858.5 | E36: =MAX(INT((B36-Datos!$B$19)/Piezas!$F$10)*Piezas!$F$10/B36,INT((B36-Datos!$B$19)/Piezas!$G$10)*Piezas!$G$10/B36)*(1-Datos!$B$20) -> 0.98107 | F36: =Piezas!$H$10/E36 -> 10.864555 | G36: =F36*INDEX(Datos!$B$95:$B$100,MATCH(Piezas!$E$10,Datos!$A$95:$A$100,0)) -> 12.100181 | H36: =MIN(ROUNDDOWN(MIN(B36*Datos!$B$57,Datos!$B$58)*2,0)/2,MAX(Datos!$B$54,ROUNDUP(INDEX(Demanda!$C$10:$L$10,Datos!$B$6-2025)*F36/1000/12*Datos!$B$52*2,0)/2)) -> 1 | I36: =Piezas!$H$10*INDEX(Datos!$F$95:$F$100,MATCH(Piezas!$E$10,Datos!$A$95:$A$100,0)) -> 13.387564
A37: 50 kg | B37: 1500 | C37: =IF(INT((B37-Datos!$B$19)/Piezas!$F$11)*Piezas!$F$11/B37>=INT((B37-Datos!$B$19)/Piezas!$G$11)*Piezas!$G$11/B37,INT((B37-Datos!$B$19)/Piezas!$F$11),INT((B37-Datos!$B$19)/Piezas!$G$11)) -> 2 | D37: =IF(INT((B37-Datos!$B$19)/Piezas!$F$11)*Piezas!$F$11/B37>=INT((B37-Datos!$B$19)/Piezas!$G$11)*Piezas!$G$11/B37,Piezas!$G$11,Piezas!$F$11) -> 995.5 | E37: =MAX(INT((B37-Datos!$B$19)/Piezas!$F$11)*Piezas!$F$11/B37,INT((B37-Datos!$B$19)/Piezas!$G$11)*Piezas!$G$11/B37)*(1-Datos!$B$20) -> 0.84906667 | F37: =Piezas!$H$11/E37 -> 18.897491 | G37: =F37*INDEX(Datos!$B$95:$B$100,MATCH(Piezas!$E$11,Datos!$A$95:$A$100,0)) -> 21.046703 | H37: =MIN(ROUNDDOWN(MIN(B37*Datos!$B$57,Datos!$B$58)*2,0)/2,MAX(Datos!$B$54,ROUNDUP(INDEX(Demanda!$C$11:$L$11,Datos!$B$6-2025)*F37/1000/12*Datos!$B$52*2,0)/2)) -> 3 | I37: =Piezas!$H$11*INDEX(Datos!$F$95:$F$100,MATCH(Piezas!$E$11,Datos!$A$95:$A$100,0)) -> 20.152809
A38: 70 kg | B38: 1245 | C38: =IF(INT((B38-Datos!$B$19)/Piezas!$F$12)*Piezas!$F$12/B38>=INT((B38-Datos!$B$19)/Piezas!$G$12)*Piezas!$G$12/B38,INT((B38-Datos!$B$19)/Piezas!$F$12),INT((B38-Datos!$B$19)/Piezas!$G$12)) -> 1 | D38: =IF(INT((B38-Datos!$B$19)/Piezas!$F$12)*Piezas!$F$12/B38>=INT((B38-Datos!$B$19)/Piezas!$G$12)*Piezas!$G$12/B38,Piezas!$G$12,Piezas!$F$12) -> 680 | E38: =MAX(INT((B38-Datos!$B$19)/Piezas!$F$12)*Piezas!$F$12/B38,INT((B38-Datos!$B$19)/Piezas!$G$12)*Piezas!$G$12/B38)*(1-Datos!$B$20) -> 0.96742771 | F38: =Piezas!$H$12/E38 -> 31.80706 | G38: =F38*INDEX(Datos!$B$95:$B$100,MATCH(Piezas!$E$12,Datos!$A$95:$A$100,0)) -> 35.424477 | H38: =MIN(ROUNDDOWN(MIN(B38*Datos!$B$57,Datos!$B$58)*2,0)/2,MAX(Datos!$B$54,ROUNDUP(INDEX(Demanda!$C$12:$L$12,Datos!$B$6-2025)*F38/1000/12*Datos!$B$52*2,0)/2)) -> 1 | I38: =Piezas!$H$12*INDEX(Datos!$F$95:$F$100,MATCH(Piezas!$E$12,Datos!$A$95:$A$100,0)) -> 38.032994
A39: 100 kg | B39: 1245 | C39: =IF(INT((B39-Datos!$B$19)/Piezas!$F$13)*Piezas!$F$13/B39>=INT((B39-Datos!$B$19)/Piezas!$G$13)*Piezas!$G$13/B39,INT((B39-Datos!$B$19)/Piezas!$F$13),INT((B39-Datos!$B$19)/Piezas!$G$13)) -> 1 | D39: =IF(INT((B39-Datos!$B$19)/Piezas!$F$13)*Piezas!$F$13/B39>=INT((B39-Datos!$B$19)/Piezas!$G$13)*Piezas!$G$13/B39,Piezas!$G$13,Piezas!$F$13) -> 900 | E39: =MAX(INT((B39-Datos!$B$19)/Piezas!$F$13)*Piezas!$F$13/B39,INT((B39-Datos!$B$19)/Piezas!$G$13)*Piezas!$G$13/B39)*(1-Datos!$B$20) -> 0.96742771 | F39: =Piezas!$H$13/E39 -> 42.097579 | G39: =F39*INDEX(Datos!$B$95:$B$100,MATCH(Piezas!$E$13,Datos!$A$95:$A$100,0)) -> 46.885337 | H39: =MIN(ROUNDDOWN(MIN(B39*Datos!$B$57,Datos!$B$58)*2,0)/2,MAX(Datos!$B$54,ROUNDUP(INDEX(Demanda!$C$13:$L$13,Datos!$B$6-2025)*F39/1000/12*Datos!$B$52*2,0)/2)) -> 1 | I39: =Piezas!$H$13*INDEX(Datos!$F$95:$F$100,MATCH(Piezas!$E$13,Datos!$A$95:$A$100,0)) -> 50.337787
A42: C) Cúpulas y fondos: fleje a medida (A, D, Ref.) o tiras de hoja (B)
A43: Pieza | B43: Ø disco (mm) | C43: Espesor (mm) | D43: Puente de avance (mm) | E43: Puente al borde (mm) | F43: Ancho de fleje (mm) | G43: Paso (mm) | H43: Aprovech. del fleje | I43: kg de fleje por disco | J43: USD de fleje por disco | K43: Peso de rollo (t) | L43: Hoja: lado corto = largo de la tira | M43: lado largo | N43: Tiras por hoja | O43: Discos por tira | P43: Discos por hoja | Q43: Aprovech. de la hoja | R43: kg de hoja por disco | S43: USD de hoja por disco | T43: Fleje 1 fila: ancho (mm) | U43: Aprovech. 1 fila | V43: Fleje 2 filas al tresbolillo: ancho (mm) | W43: Aprovech. 2 filas | X43: kg por disco, 1 fila | Y43: kg por disco, 2 filas
