Workbook

Sheet Links
A1: Links e IMPORTRANGE
A2: Pegar en B el link de cada Google Sheet. La primera vez, tocar la primera celda de cada bloque y «Permitir acceso». Todos los IMPORTRANGE del libro están en esta hoja; las demás la leen.
A3: Archivo | B3: Link | G3: Qué se importa | M3: Estado
A4: Proyecciones | B4: https://docs.google.com/spreadsheets/d/1xc4xDAwSYT3l-RulPYtcePxiCninrbQGzaBUsgO0YEs/edit?gid=1764491891#gid=1764491891 | G4: Indexado Dim Técnico B27:K43, U61:U74, V61 y V63 | M4: =IF(ISERROR(B12),"Falta el link o «Permitir acceso»","OK") -> OK
A5: Aprovechamiento Manuales | B5: PEGAR ACÁ EL LINK DEL GOOGLE SHEET | G5: parametros_manuales K33, K34, K39, K40, K41 y K43 (equivalencia del rodante) | M5: =IF(ISERROR(B65),"Falta el link o «Permitir acceso»","OK") -> OK
A6: Aprovechamiento Carros | B6: PEGAR ACÁ EL LINK DEL GOOGLE SHEET | G6: parametros_carros I29, I30, I33 e I34 (equivalencia del rodante) | M6: =IF(ISERROR(B68),"Falta el link o «Permitir acceso»","OK") -> OK
A7: MRP (FLAMA_MRP) | B7: PEGAR ACÁ EL LINK DEL GOOGLE SHEET | G7: ESTACIONALIDAD C4:N6 (llegada de los sustitutos ABC nuevos) | M7: =IF(ISERROR(B54),"Falta el link o «Permitir acceso»","OK") -> OK
A10: Proyecciones · Indexado Dim Técnico!B27:K43: recargas por tipo
B11: 2026 | C11: 2027 | D11: 2028 | E11: 2029 | F11: 2030 | G11: 2031 | H11: 2032 | I11: 2033 | J11: 2034 | K11: 2035
A12: ABC 1 kg | B12: =IFERROR(__xludf.DUMMYFUNCTION("IMPORTRANGE(Links!$B$4,""Indexado Dim Técnico!B27:K43"")"),3477.482124) -> 3477.4821 | C12: =IFERROR(__xludf.DUMMYFUNCTION("""COMPUTED_VALUE"""),16970.58564) -> 16970.586 | D12: =IFERROR(__xludf.DUMMYFUNCTION("""COMPUTED_VALUE"""),30546.08951) -> 30546.09 | E12: =IFERROR(__xludf.DUMMYFUNCTION("""COMPUTED_VALUE"""),56048.31106) -> 56048.311 | F12: =IFERROR(__xludf.DUMMYFUNCTION("""COMPUTED_VALUE"""),84270.22613) -> 84270.226 | G12: =IFERROR(__xludf.DUMMYFUNCTION("""COMPUTED_VALUE"""),117407.8231) -> 117407.82 | H12: =IFERROR(__xludf.DUMMYFUNCTION("""COMPUTED_VALUE"""),147610.6356) -> 147610.64 | I12: =IFERROR(__xludf.DUMMYFUNCTION("""COMPUTED_VALUE"""),171404.3607) -> 171404.36 | J12: =IFERROR(__xludf.DUMMYFUNCTION("""COMPUTED_VALUE"""),183690.566) -> 183690.57 | K12: =IFERROR(__xludf.DUMMYFUNCTION("""COMPUTED_VALUE"""),196282.6907) -> 196282.69
A13: ABC 2,5 kg | B13: =IFERROR(__xludf.DUMMYFUNCTION("""COMPUTED_VALUE"""),329.996668) -> 329.99667 | C13: =IFERROR(__xludf.DUMMYFUNCTION("""COMPUTED_VALUE"""),1287.414024) -> 1287.414 | D13: =IFERROR(__xludf.DUMMYFUNCTION("""COMPUTED_VALUE"""),2947.169216) -> 2947.1692 | E13: =IFERROR(__xludf.DUMMYFUNCTION("""COMPUTED_VALUE"""),5426.043269) -> 5426.0433 | F13: =IFERROR(__xludf.DUMMYFUNCTION("""COMPUTED_VALUE"""),7850.875806) -> 7850.8758 | G13: =IFERROR(__xludf.DUMMYFUNCTION("""COMPUTED_VALUE"""),10423.94365) -> 10423.944 | H13: =IFERROR(__xludf.DUMMYFUNCTION("""COMPUTED_VALUE"""),12809.89571) -> 12809.896 | I13: =IFERROR(__xludf.DUMMYFUNCTION("""COMPUTED_VALUE"""),14263.06831) -> 14263.068 | J13: =IFERROR(__xludf.DUMMYFUNCTION("""COMPUTED_VALUE"""),15432.86983) -> 15432.87 | K13: =IFERROR(__xludf.DUMMYFUNCTION("""COMPUTED_VALUE"""),16620.76117) -> 16620.761
A14: ABC 5 kg | B14: =IFERROR(__xludf.DUMMYFUNCTION("""COMPUTED_VALUE"""),1950.394097) -> 1950.3941 | C14: =IFERROR(__xludf.DUMMYFUNCTION("""COMPUTED_VALUE"""),7852.61852) -> 7852.6185 | D14: =IFERROR(__xludf.DUMMYFUNCTION("""COMPUTED_VALUE"""),17775.85701) -> 17775.857 | E14: =IFERROR(__xludf.DUMMYFUNCTION("""COMPUTED_VALUE"""),33605.56835) -> 33605.568 | F14: =IFERROR(__xludf.DUMMYFUNCTION("""COMPUTED_VALUE"""),48407.57189) -> 48407.572 | G14: =IFERROR(__xludf.DUMMYFUNCTION("""COMPUTED_VALUE"""),64323.04276) -> 64323.043 | H14: =IFERROR(__xludf.DUMMYFUNCTION("""COMPUTED_VALUE"""),78721.10039) -> 78721.1 | I14: =IFERROR(__xludf.DUMMYFUNCTION("""COMPUTED_VALUE"""),87237.2124) -> 87237.212 | J14: =IFERROR(__xludf.DUMMYFUNCTION("""COMPUTED_VALUE"""),94103.66761) -> 94103.668 | K14: =IFERROR(__xludf.DUMMYFUNCTION("""COMPUTED_VALUE"""),101095.1762) -> 101095.18
A15: ABC 10 kg | B15: =IFERROR(__xludf.DUMMYFUNCTION("""COMPUTED_VALUE"""),118.343632) -> 118.34363 | C15: =IFERROR(__xludf.DUMMYFUNCTION("""COMPUTED_VALUE"""),437.716578) -> 437.71658 | D15: =IFERROR(__xludf.DUMMYFUNCTION("""COMPUTED_VALUE"""),1024.974821) -> 1024.9748 | E15: =IFERROR(__xludf.DUMMYFUNCTION("""COMPUTED_VALUE"""),1960.409862) -> 1960.4099 | F15: =IFERROR(__xludf.DUMMYFUNCTION("""COMPUTED_VALUE"""),2844.976846) -> 2844.9768 | G15: =IFERROR(__xludf.DUMMYFUNCTION("""COMPUTED_VALUE"""),3810.390622) -> 3810.3906 | H15: =IFERROR(__xludf.DUMMYFUNCTION("""COMPUTED_VALUE"""),4663.67807) -> 4663.6781 | I15: =IFERROR(__xludf.DUMMYFUNCTION("""COMPUTED_VALUE"""),5164.514584) -> 5164.5146 | J15: =IFERROR(__xludf.DUMMYFUNCTION("""COMPUTED_VALUE"""),5571.544328) -> 5571.5443 | K15: =IFERROR(__xludf.DUMMYFUNCTION("""COMPUTED_VALUE"""),5985.950855) -> 5985.9509
A16: Agua 10 l | B16: =IFERROR(__xludf.DUMMYFUNCTION("""COMPUTED_VALUE"""),159.308736) -> 159.30874 | C16: =IFERROR(__xludf.DUMMYFUNCTION("""COMPUTED_VALUE"""),643.423542) -> 643.42354 | D16: =IFERROR(__xludf.DUMMYFUNCTION("""COMPUTED_VALUE"""),1474.362741) -> 1474.3627 | E16: =IFERROR(__xludf.DUMMYFUNCTION("""COMPUTED_VALUE"""),2766.451205) -> 2766.4512 | F16: =IFERROR(__xludf.DUMMYFUNCTION("""COMPUTED_VALUE"""),3991.465221) -> 3991.4652 | G16: =IFERROR(__xludf.DUMMYFUNCTION("""COMPUTED_VALUE"""),5335.75578) -> 5335.7558 | H16: =IFERROR(__xludf.DUMMYFUNCTION("""COMPUTED_VALUE"""),6538.958887) -> 6538.9589 | I16: =IFERROR(__xludf.DUMMYFUNCTION("""COMPUTED_VALUE"""),7269.819681) -> 7269.8197 | J16: =IFERROR(__xludf.DUMMYFUNCTION("""COMPUTED_VALUE"""),7855.44139) -> 7855.4414 | K16: =IFERROR(__xludf.DUMMYFUNCTION("""COMPUTED_VALUE"""),8450.814081) -> 8450.8141
A17: AFFF 10 l | B17: =IFERROR(__xludf.DUMMYFUNCTION("""COMPUTED_VALUE"""),22.758391) -> 22.758391 | C17: =IFERROR(__xludf.DUMMYFUNCTION("""COMPUTED_VALUE"""),161.315751) -> 161.31575 | D17: =IFERROR(__xludf.DUMMYFUNCTION("""COMPUTED_VALUE"""),316.607276) -> 316.60728 | E17: =IFERROR(__xludf.DUMMYFUNCTION("""COMPUTED_VALUE"""),527.39462) -> 527.39462 | F17: =IFERROR(__xludf.DUMMYFUNCTION("""COMPUTED_VALUE"""),743.788946) -> 743.78895 | G17: =IFERROR(__xludf.DUMMYFUNCTION("""COMPUTED_VALUE"""),962.874335) -> 962.87433 | H17: =IFERROR(__xludf.DUMMYFUNCTION("""COMPUTED_VALUE"""),1194.942207) -> 1194.9422 | I17: =IFERROR(__xludf.DUMMYFUNCTION("""COMPUTED_VALUE"""),1351.617183) -> 1351.6172 | J17: =IFERROR(__xludf.DUMMYFUNCTION("""COMPUTED_VALUE"""),1477.54886) -> 1477.5489 | K17: =IFERROR(__xludf.DUMMYFUNCTION("""COMPUTED_VALUE"""),1604.441422) -> 1604.4414
A18: AFFF 50 l s/ruedas | B18: =IFERROR(__xludf.DUMMYFUNCTION("""COMPUTED_VALUE"""),11.379195) -> 11.379195 | C18: =IFERROR(__xludf.DUMMYFUNCTION("""COMPUTED_VALUE"""),83.22352) -> 83.22352 | D18: =IFERROR(__xludf.DUMMYFUNCTION("""COMPUTED_VALUE"""),164.463834) -> 164.46383 | E18: =IFERROR(__xludf.DUMMYFUNCTION("""COMPUTED_VALUE"""),281.341145) -> 281.34114 | F18: =IFERROR(__xludf.DUMMYFUNCTION("""COMPUTED_VALUE"""),398.902509) -> 398.90251 | G18: =IFERROR(__xludf.DUMMYFUNCTION("""COMPUTED_VALUE"""),514.527284) -> 514.52728 | H18: =IFERROR(__xludf.DUMMYFUNCTION("""COMPUTED_VALUE"""),629.065505) -> 629.06551 | I18: =IFERROR(__xludf.DUMMYFUNCTION("""COMPUTED_VALUE"""),711.178024) -> 711.17802 | J18: =IFERROR(__xludf.DUMMYFUNCTION("""COMPUTED_VALUE"""),773.41098) -> 773.41098 | K18: =IFERROR(__xludf.DUMMYFUNCTION("""COMPUTED_VALUE"""),836.350805) -> 836.35081
A19: BC 5 kg | B19: =IFERROR(__xludf.DUMMYFUNCTION("""COMPUTED_VALUE"""),6.827517) -> 6.827517 | C19: =IFERROR(__xludf.DUMMYFUNCTION("""COMPUTED_VALUE"""),47.073112) -> 47.073112 | D19: =IFERROR(__xludf.DUMMYFUNCTION("""COMPUTED_VALUE"""),88.889676) -> 88.889676 | E19: =IFERROR(__xludf.DUMMYFUNCTION("""COMPUTED_VALUE"""),159.502491) -> 159.50249 | F19: =IFERROR(__xludf.DUMMYFUNCTION("""COMPUTED_VALUE"""),219.796202) -> 219.7962 | G19: =IFERROR(__xludf.DUMMYFUNCTION("""COMPUTED_VALUE"""),291.869853) -> 291.86985 | H19: =IFERROR(__xludf.DUMMYFUNCTION("""COMPUTED_VALUE"""),368.844169) -> 368.84417 | I19: =IFERROR(__xludf.DUMMYFUNCTION("""COMPUTED_VALUE"""),408.408953) -> 408.40895 | J19: =IFERROR(__xludf.DUMMYFUNCTION("""COMPUTED_VALUE"""),445.781944) -> 445.78194 | K19: =IFERROR(__xludf.DUMMYFUNCTION("""COMPUTED_VALUE"""),483.479203) -> 483.4792
A20: Sales K 6 l | B20: =IFERROR(__xludf.DUMMYFUNCTION("""COMPUTED_VALUE"""),81.930207) -> 81.930207 | C20: =IFERROR(__xludf.DUMMYFUNCTION("""COMPUTED_VALUE"""),335.398855) -> 335.39886 | D20: =IFERROR(__xludf.DUMMYFUNCTION("""COMPUTED_VALUE"""),746.598352) -> 746.59835 | E20: =IFERROR(__xludf.DUMMYFUNCTION("""COMPUTED_VALUE"""),1358.899837) -> 1358.8998 | F20: =IFERROR(__xludf.DUMMYFUNCTION("""COMPUTED_VALUE"""),1961.125522) -> 1961.1255 | G20: =IFERROR(__xludf.DUMMYFUNCTION("""COMPUTED_VALUE"""),2598.541412) -> 2598.5414 | H20: =IFERROR(__xludf.DUMMYFUNCTION("""COMPUTED_VALUE"""),3197.263477) -> 3197.2635 | I20: =IFERROR(__xludf.DUMMYFUNCTION("""COMPUTED_VALUE"""),3578.539452) -> 3578.5395 | J20: =IFERROR(__xludf.DUMMYFUNCTION("""COMPUTED_VALUE"""),3870.747997) -> 3870.748 | K20: =IFERROR(__xludf.DUMMYFUNCTION("""COMPUTED_VALUE"""),4167.559622) -> 4167.5596
A21: CO₂ 2 kg | B21: =IFERROR(__xludf.DUMMYFUNCTION("""COMPUTED_VALUE"""),450.616139) -> 450.61614 | C21: =IFERROR(__xludf.DUMMYFUNCTION("""COMPUTED_VALUE"""),1697.18149) -> 1697.1815 | D21: =IFERROR(__xludf.DUMMYFUNCTION("""COMPUTED_VALUE"""),3955.196858) -> 3955.1969 | E21: =IFERROR(__xludf.DUMMYFUNCTION("""COMPUTED_VALUE"""),7561.26033) -> 7561.2603 | F21: =IFERROR(__xludf.DUMMYFUNCTION("""COMPUTED_VALUE"""),10920.14481) -> 10920.145 | G21: =IFERROR(__xludf.DUMMYFUNCTION("""COMPUTED_VALUE"""),14514.88522) -> 14514.885 | H21: =IFERROR(__xludf.DUMMYFUNCTION("""COMPUTED_VALUE"""),17746.49927) -> 17746.499 | I21: =IFERROR(__xludf.DUMMYFUNCTION("""COMPUTED_VALUE"""),19617.20546) -> 19617.205 | J21: =IFERROR(__xludf.DUMMYFUNCTION("""COMPUTED_VALUE"""),21161.80625) -> 21161.806 | K21: =IFERROR(__xludf.DUMMYFUNCTION("""COMPUTED_VALUE"""),22734.50171) -> 22734.502
A22: CO₂ 5 kg | B22: =IFERROR(__xludf.DUMMYFUNCTION("""COMPUTED_VALUE"""),125.17115) -> 125.17115 | C22: =IFERROR(__xludf.DUMMYFUNCTION("""COMPUTED_VALUE"""),643.630371) -> 643.63037 | D22: =IFERROR(__xludf.DUMMYFUNCTION("""COMPUTED_VALUE"""),1375.626719) -> 1375.6267 | E22: =IFERROR(__xludf.DUMMYFUNCTION("""COMPUTED_VALUE"""),2460.284265) -> 2460.2843 | F22: =IFERROR(__xludf.DUMMYFUNCTION("""COMPUTED_VALUE"""),3545.257683) -> 3545.2577 | G22: =IFERROR(__xludf.DUMMYFUNCTION("""COMPUTED_VALUE"""),4723.461784) -> 4723.4618 | H22: =IFERROR(__xludf.DUMMYFUNCTION("""COMPUTED_VALUE"""),5853.905178) -> 5853.9052 | I22: =IFERROR(__xludf.DUMMYFUNCTION("""COMPUTED_VALUE"""),6608.459909) -> 6608.4599 | J22: =IFERROR(__xludf.DUMMYFUNCTION("""COMPUTED_VALUE"""),7185.708397) -> 7185.7084 | K22: =IFERROR(__xludf.DUMMYFUNCTION("""COMPUTED_VALUE"""),7769.577127) -> 7769.5771
A23: HCFC/HFC 5 kg | B23: =IFERROR(__xludf.DUMMYFUNCTION("""COMPUTED_VALUE"""),18.206713) -> 18.206713 | C23: =IFERROR(__xludf.DUMMYFUNCTION("""COMPUTED_VALUE"""),112.075122) -> 112.07512 | D23: =IFERROR(__xludf.DUMMYFUNCTION("""COMPUTED_VALUE"""),230.854041) -> 230.85404 | E23: =IFERROR(__xludf.DUMMYFUNCTION("""COMPUTED_VALUE"""),400.715334) -> 400.71533 | F23: =IFERROR(__xludf.DUMMYFUNCTION("""COMPUTED_VALUE"""),574.507789) -> 574.50779 | G23: =IFERROR(__xludf.DUMMYFUNCTION("""COMPUTED_VALUE"""),754.345623) -> 754.34562 | H23: =IFERROR(__xludf.DUMMYFUNCTION("""COMPUTED_VALUE"""),944.84884) -> 944.84884 | I23: =IFERROR(__xludf.DUMMYFUNCTION("""COMPUTED_VALUE"""),1072.234671) -> 1072.2347 | J23: =IFERROR(__xludf.DUMMYFUNCTION("""COMPUTED_VALUE"""),1171.695753) -> 1171.6958 | K23: =IFERROR(__xludf.DUMMYFUNCTION("""COMPUTED_VALUE"""),1271.941099) -> 1271.9411
A24: Clase D 9 l | B24: =IFERROR(__xludf.DUMMYFUNCTION("""COMPUTED_VALUE"""),6.827517) -> 6.827517 | C24: =IFERROR(__xludf.DUMMYFUNCTION("""COMPUTED_VALUE"""),47.073112) -> 47.073112 | D24: =IFERROR(__xludf.DUMMYFUNCTION("""COMPUTED_VALUE"""),88.889676) -> 88.889676 | E24: =IFERROR(__xludf.DUMMYFUNCTION("""COMPUTED_VALUE"""),148.279182) -> 148.27918 | F24: =IFERROR(__xludf.DUMMYFUNCTION("""COMPUTED_VALUE"""),205.226053) -> 205.22605 | G24: =IFERROR(__xludf.DUMMYFUNCTION("""COMPUTED_VALUE"""),255.765145) -> 255.76514 | H24: =IFERROR(__xludf.DUMMYFUNCTION("""COMPUTED_VALUE"""),328.417902) -> 328.4179 | I24: =IFERROR(__xludf.DUMMYFUNCTION("""COMPUTED_VALUE"""),366.908071) -> 366.90807 | J24: =IFERROR(__xludf.DUMMYFUNCTION("""COMPUTED_VALUE"""),401.681707) -> 401.68171 | K24: =IFERROR(__xludf.DUMMYFUNCTION("""COMPUTED_VALUE"""),436.686782) -> 436.68678
A25: ABC 25 kg s/ruedas | B25: =IFERROR(__xludf.DUMMYFUNCTION("""COMPUTED_VALUE"""),17.637753) -> 17.637753 | C25: =IFERROR(__xludf.DUMMYFUNCTION("""COMPUTED_VALUE"""),85.987819) -> 85.987819 | D25: =IFERROR(__xludf.DUMMYFUNCTION("""COMPUTED_VALUE"""),186.869567) -> 186.86957 | E25: =IFERROR(__xludf.DUMMYFUNCTION("""COMPUTED_VALUE"""),336.583621) -> 336.58362 | F25: =IFERROR(__xludf.DUMMYFUNCTION("""COMPUTED_VALUE"""),484.132598) -> 484.1326 | G25: =IFERROR(__xludf.DUMMYFUNCTION("""COMPUTED_VALUE"""),643.220385) -> 643.22038 | H25: =IFERROR(__xludf.DUMMYFUNCTION("""COMPUTED_VALUE"""),792.431742) -> 792.43174 | I25: =IFERROR(__xludf.DUMMYFUNCTION("""COMPUTED_VALUE"""),889.677707) -> 889.67771 | J25: =IFERROR(__xludf.DUMMYFUNCTION("""COMPUTED_VALUE"""),965.31111) -> 965.31111 | K25: =IFERROR(__xludf.DUMMYFUNCTION("""COMPUTED_VALUE"""),1041.939702) -> 1041.9397
A26: ABC 50 kg s/ruedas | B26: =IFERROR(__xludf.DUMMYFUNCTION("""COMPUTED_VALUE"""),38.803056) -> 38.803056 | C26: =IFERROR(__xludf.DUMMYFUNCTION("""COMPUTED_VALUE"""),189.173203) -> 189.1732 | D26: =IFERROR(__xludf.DUMMYFUNCTION("""COMPUTED_VALUE"""),411.113048) -> 411.11305 | E26: =IFERROR(__xludf.DUMMYFUNCTION("""COMPUTED_VALUE"""),740.483966) -> 740.48397 | F26: =IFERROR(__xludf.DUMMYFUNCTION("""COMPUTED_VALUE"""),1065.091715) -> 1065.0917 | G26: =IFERROR(__xludf.DUMMYFUNCTION("""COMPUTED_VALUE"""),1415.084848) -> 1415.0848 | H26: =IFERROR(__xludf.DUMMYFUNCTION("""COMPUTED_VALUE"""),1743.349833) -> 1743.3498 | I26: =IFERROR(__xludf.DUMMYFUNCTION("""COMPUTED_VALUE"""),1957.290955) -> 1957.291 | J26: =IFERROR(__xludf.DUMMYFUNCTION("""COMPUTED_VALUE"""),2123.684441) -> 2123.6844 | K26: =IFERROR(__xludf.DUMMYFUNCTION("""COMPUTED_VALUE"""),2292.267343) -> 2292.2673
A27: ABC 70 kg s/ruedas | B27: =IFERROR(__xludf.DUMMYFUNCTION("""COMPUTED_VALUE"""),8.466121) -> 8.466121 | C27: =IFERROR(__xludf.DUMMYFUNCTION("""COMPUTED_VALUE"""),41.274153) -> 41.274153 | D27: =IFERROR(__xludf.DUMMYFUNCTION("""COMPUTED_VALUE"""),89.697392) -> 89.697392 | E27: =IFERROR(__xludf.DUMMYFUNCTION("""COMPUTED_VALUE"""),161.560138) -> 161.56014 | F27: =IFERROR(__xludf.DUMMYFUNCTION("""COMPUTED_VALUE"""),232.383647) -> 232.38365 | G27: =IFERROR(__xludf.DUMMYFUNCTION("""COMPUTED_VALUE"""),308.745785) -> 308.74579 | H27: =IFERROR(__xludf.DUMMYFUNCTION("""COMPUTED_VALUE"""),380.367236) -> 380.36724 | I27: =IFERROR(__xludf.DUMMYFUNCTION("""COMPUTED_VALUE"""),427.045299) -> 427.0453 | J27: =IFERROR(__xludf.DUMMYFUNCTION("""COMPUTED_VALUE"""),463.349333) -> 463.34933 | K27: =IFERROR(__xludf.DUMMYFUNCTION("""COMPUTED_VALUE"""),500.131057) -> 500.13106
A28: ABC 100 kg s/ruedas | B28: =IFERROR(__xludf.DUMMYFUNCTION("""COMPUTED_VALUE"""),5.644081) -> 5.644081 | C28: =IFERROR(__xludf.DUMMYFUNCTION("""COMPUTED_VALUE"""),27.516102) -> 27.516102 | D28: =IFERROR(__xludf.DUMMYFUNCTION("""COMPUTED_VALUE"""),59.798262) -> 59.798262 | E28: =IFERROR(__xludf.DUMMYFUNCTION("""COMPUTED_VALUE"""),107.706759) -> 107.70676 | F28: =IFERROR(__xludf.DUMMYFUNCTION("""COMPUTED_VALUE"""),154.922431) -> 154.92243 | G28: =IFERROR(__xludf.DUMMYFUNCTION("""COMPUTED_VALUE"""),205.830523) -> 205.83052 | H28: =IFERROR(__xludf.DUMMYFUNCTION("""COMPUTED_VALUE"""),253.578158) -> 253.57816 | I28: =IFERROR(__xludf.DUMMYFUNCTION("""COMPUTED_VALUE"""),284.696866) -> 284.69687 | J28: =IFERROR(__xludf.DUMMYFUNCTION("""COMPUTED_VALUE"""),308.899555) -> 308.89956 | K28: =IFERROR(__xludf.DUMMYFUNCTION("""COMPUTED_VALUE"""),333.420704) -> 333.4207
A30: Proyecciones · Indexado Dim Técnico!U61:U74: % de recargas por zona 2035
A31: CABA Norte | B31: =IFERROR(__xludf.DUMMYFUNCTION("IMPORTRANGE(Links!$B$4,""Indexado Dim Técnico!U61:U74"")"),0.0521797399) -> 0.05217974
A32: CABA Este | B32: =IFERROR(__xludf.DUMMYFUNCTION("""COMPUTED_VALUE"""),0.0798836162) -> 0.079883616
A33: CABA Sur | B33: =IFERROR(__xludf.DUMMYFUNCTION("""COMPUTED_VALUE"""),0.059817286) -> 0.059817286
A34: CABA Oeste | B34: =IFERROR(__xludf.DUMMYFUNCTION("""COMPUTED_VALUE"""),0.0637650712) -> 0.063765071
A35: PBA Sur 1er (Avellaneda) | B35: =IFERROR(__xludf.DUMMYFUNCTION("""COMPUTED_VALUE"""),0.0676801452) -> 0.067680145
A36: PBA Sur 2do cordón | B36: =IFERROR(__xludf.DUMMYFUNCTION("""COMPUTED_VALUE"""),0.0932172985) -> 0.093217299
A37: PBA Sur 3er cordón | B37: =IFERROR(__xludf.DUMMYFUNCTION("""COMPUTED_VALUE"""),0.0675217758) -> 0.067521776
A38: PBA Norte 1er cordón | B38: =IFERROR(__xludf.DUMMYFUNCTION("""COMPUTED_VALUE"""),0.0533558834) -> 0.053355883
A39: PBA Norte 2do cordón | B39: =IFERROR(__xludf.DUMMYFUNCTION("""COMPUTED_VALUE"""),0.0885682049) -> 0.088568205
A40: PBA Norte 3er cordón | B40: =IFERROR(__xludf.DUMMYFUNCTION("""COMPUTED_VALUE"""),0.0471361107) -> 0.047136111
A41: PBA Oeste 1er cordón | B41: =IFERROR(__xludf.DUMMYFUNCTION("""COMPUTED_VALUE"""),0.0848900664) -> 0.084890066
A42: PBA Oeste 2do cordón | B42: =IFERROR(__xludf.DUMMYFUNCTION("""COMPUTED_VALUE"""),0.0672643024) -> 0.067264302
A43: PBA Oeste 3er cordón | B43: =IFERROR(__xludf.DUMMYFUNCTION("""COMPUTED_VALUE"""),0.0174767438) -> 0.017476744
...

Sheet PROY_Indexado
A1: Proyecciones — Indexado Dim Técnico
A3: Recargas por tipo | B3: 2026 | C3: 2027 | D3: 2028 | E3: 2029 | F3: 2030 | G3: 2031 | H3: 2032 | I3: 2033 | J3: 2034 | K3: 2035
A4: ABC 1 kg | B4: =Links!B12 -> 3477.4821 | C4: =Links!C12 -> 16970.586 | D4: =Links!D12 -> 30546.09 | E4: =Links!E12 -> 56048.311 | F4: =Links!F12 -> 84270.226 | G4: =Links!G12 -> 117407.82 | H4: =Links!H12 -> 147610.64 | I4: =Links!I12 -> 171404.36 | ... K4: =Links!K12 -> 196282.69
A5: ABC 2,5 kg | B5: =Links!B13 -> 329.99667 | C5: =Links!C13 -> 1287.414 | D5: =Links!D13 -> 2947.1692 | E5: =Links!E13 -> 5426.0433 | F5: =Links!F13 -> 7850.8758 | G5: =Links!G13 -> 10423.944 | H5: =Links!H13 -> 12809.896 | I5: =Links!I13 -> 14263.068 | ... K5: =Links!K13 -> 16620.761
A6: ABC 5 kg | B6: =Links!B14 -> 1950.3941 | C6: =Links!C14 -> 7852.6185 | D6: =Links!D14 -> 17775.857 | E6: =Links!E14 -> 33605.568 | F6: =Links!F14 -> 48407.572 | G6: =Links!G14 -> 64323.043 | H6: =Links!H14 -> 78721.1 | I6: =Links!I14 -> 87237.212 | ... K6: =Links!K14 -> 101095.18
A7: ABC 10 kg | B7: =Links!B15 -> 118.34363 | C7: =Links!C15 -> 437.71658 | D7: =Links!D15 -> 1024.9748 | E7: =Links!E15 -> 1960.4099 | F7: =Links!F15 -> 2844.9768 | G7: =Links!G15 -> 3810.3906 | H7: =Links!H15 -> 4663.6781 | I7: =Links!I15 -> 5164.5146 | ... K7: =Links!K15 -> 5985.9509
A8: Agua 10 l | B8: =Links!B16 -> 159.30874 | C8: =Links!C16 -> 643.42354 | D8: =Links!D16 -> 1474.3627 | E8: =Links!E16 -> 2766.4512 | F8: =Links!F16 -> 3991.4652 | G8: =Links!G16 -> 5335.7558 | H8: =Links!H16 -> 6538.9589 | I8: =Links!I16 -> 7269.8197 | ... K8: =Links!K16 -> 8450.8141
A9: AFFF 10 l | B9: =Links!B17 -> 22.758391 | C9: =Links!C17 -> 161.31575 | D9: =Links!D17 -> 316.60728 | E9: =Links!E17 -> 527.39462 | F9: =Links!F17 -> 743.78895 | G9: =Links!G17 -> 962.87433 | H9: =Links!H17 -> 1194.9422 | I9: =Links!I17 -> 1351.6172 | ... K9: =Links!K17 -> 1604.4414
A10: AFFF 50 l s/ruedas | B10: =Links!B18 -> 11.379195 | C10: =Links!C18 -> 83.22352 | D10: =Links!D18 -> 164.46383 | E10: =Links!E18 -> 281.34114 | F10: =Links!F18 -> 398.90251 | G10: =Links!G18 -> 514.52728 | H10: =Links!H18 -> 629.06551 | I10: =Links!I18 -> 711.17802 | ... K10: =Links!K18 -> 836.35081
A11: BC 5 kg | B11: =Links!B19 -> 6.827517 | C11: =Links!C19 -> 47.073112 | D11: =Links!D19 -> 88.889676 | E11: =Links!E19 -> 159.50249 | F11: =Links!F19 -> 219.7962 | G11: =Links!G19 -> 291.86985 | H11: =Links!H19 -> 368.84417 | I11: =Links!I19 -> 408.40895 | ... K11: =Links!K19 -> 483.4792
A12: Sales K 6 l | B12: =Links!B20 -> 81.930207 | C12: =Links!C20 -> 335.39886 | D12: =Links!D20 -> 746.59835 | E12: =Links!E20 -> 1358.8998 | F12: =Links!F20 -> 1961.1255 | G12: =Links!G20 -> 2598.5414 | H12: =Links!H20 -> 3197.2635 | I12: =Links!I20 -> 3578.5395 | ... K12: =Links!K20 -> 4167.5596
A13: CO₂ 2 kg | B13: =Links!B21 -> 450.61614 | C13: =Links!C21 -> 1697.1815 | D13: =Links!D21 -> 3955.1969 | E13: =Links!E21 -> 7561.2603 | F13: =Links!F21 -> 10920.145 | G13: =Links!G21 -> 14514.885 | H13: =Links!H21 -> 17746.499 | I13: =Links!I21 -> 19617.205 | ... K13: =Links!K21 -> 22734.502
A14: CO₂ 5 kg | B14: =Links!B22 -> 125.17115 | C14: =Links!C22 -> 643.63037 | D14: =Links!D22 -> 1375.6267 | E14: =Links!E22 -> 2460.2843 | F14: =Links!F22 -> 3545.2577 | G14: =Links!G22 -> 4723.4618 | H14: =Links!H22 -> 5853.9052 | I14: =Links!I22 -> 6608.4599 | ... K14: =Links!K22 -> 7769.5771
A15: HCFC/HFC 5 kg | B15: =Links!B23 -> 18.206713 | C15: =Links!C23 -> 112.07512 | D15: =Links!D23 -> 230.85404 | E15: =Links!E23 -> 400.71533 | F15: =Links!F23 -> 574.50779 | G15: =Links!G23 -> 754.34562 | H15: =Links!H23 -> 944.84884 | I15: =Links!I23 -> 1072.2347 | ... K15: =Links!K23 -> 1271.9411
... A20: ABC 100 kg s/ruedas | B20: =Links!B28 -> 5.644081 | C20: =Links!C28 -> 27.516102 | D20: =Links!D28 -> 59.798262 | E20: =Links!E28 -> 107.70676 | F20: =Links!F28 -> 154.92243 | G20: =Links!G28 -> 205.83052 | H20: =Links!H28 -> 253.57816 | I20: =Links!I28 -> 284.69687 | ... K20: =Links!K28 -> 333.4207
A21: Recargas total | B21: =SUM(B4:B20) -> 6829.7931 | C21: =SUM(C4:C20) -> 30662.681 | D21: =SUM(D4:D20) -> 61483.058 | E21: =SUM(E4:E20) -> 114050.8 | F21: =SUM(F4:F20) -> 167870.4 | G21: =SUM(G4:G20) -> 228490.11 | H21: =SUM(H4:H20) -> 283777.78 | I21: =SUM(I4:I20) -> 322612.24 | ... K21: =SUM(K4:K20) -> 371907.69
A23: Recargas por zona y planta (PBA Interior queda fuera: la atienden distribuidores ajenos)
A24: Zona | B24: % zonal 2035 | C24: Planta
A25: CABA Norte | B25: =Links!B31 -> 0.05217974 | C25: Comercial
A26: CABA Este | B26: =Links!B32 -> 0.079883616 | C26: Comercial
A27: CABA Sur | B27: =Links!B33 -> 0.059817286 | C27: Industrial
A28: CABA Oeste | B28: =Links!B34 -> 0.063765071 | C28: Comercial
A29: PBA Sur 1er (Avellaneda) | B29: =Links!B35 -> 0.067680145 | C29: Industrial
A30: PBA Sur 2do cordón | B30: =Links!B36 -> 0.093217299 | C30: Industrial
A31: PBA Sur 3er cordón | B31: =Links!B37 -> 0.067521776 | C31: Industrial
A32: PBA Norte 1er cordón | B32: =Links!B38 -> 0.053355883 | C32: Comercial
A33: PBA Norte 2do cordón | B33: =Links!B39 -> 0.088568205 | C33: Comercial
A34: PBA Norte 3er cordón | B34: =Links!B40 -> 0.047136111 | C34: Comercial
A35: PBA Oeste 1er cordón | B35: =Links!B41 -> 0.084890066 | C35: Comercial
A36: PBA Oeste 2do cordón | B36: =Links!B42 -> 0.067264302 | C36: Comercial
... A38: PBA Interior | B38: =Links!B44 -> 0.15724376 | C38: Fuera
A39: Planta | B39: % de recargas | C39: Control: suma de sus zonas
A40: Comercial (Proyecciones V61) | B40: =Links!B47 -> 0.55451974 | C40: =SUMIF($C$25:$C$38,"Comercial",$B$25:$B$38) -> 0.55451974
A41: Industrial (Proyecciones V63) | B41: =Links!B50 -> 0.28823651 | C41: =SUMIF($C$25:$C$38,"Industrial",$B$25:$B$38) -> 0.28823651
A42: Fuera: PBA Interior (distribuidores ajenos) | B42: =SUMIF($C$25:$C$38,"Fuera",$B$25:$B$38) -> 0.15724376
A43: Total (tiene que dar 100 %) | B43: =SUM(B40:B42) -> 1
A44: Tasas de Proyecciones (hojas PROYECCION por rubro; iguales en todos los tipos)
A45: Concepto | B45: Valor | C45: Uso en este archivo
A46: Mat Usados ÷ RECARGAS An | B46: 0.05 | C46: Llega descargado por uso (parametros_recargas fila 22)
A47: Mat PH ÷ RECARGAS An | B47: 0.02 | C47: No pasa la PH (fila 19)
...

Sheet datos_base
A1: Tipo de matafuego | B1: =PROY_Indexado!B3 -> 2026 | C1: =PROY_Indexado!C3 -> 2027 | D1: =PROY_Indexado!D3 -> 2028 | E1: =PROY_Indexado!E3 -> 2029 | F1: =PROY_Indexado!F3 -> 2030 | G1: =PROY_Indexado!G3 -> 2031 | H1: =PROY_Indexado!H3 -> 2032 | I1: =PROY_Indexado!I3 -> 2033 | ... K1: =PROY_Indexado!K3 -> 2035
A2: =PROY_Indexado!A4 -> ABC 1 kg | B2: =PROY_Indexado!B4*PROY_Indexado!$B$52 -> 1928.3325 | C2: =PROY_Indexado!C4*PROY_Indexado!$B$52 -> 9410.5247 | D2: =PROY_Indexado!D4*PROY_Indexado!$B$52 -> 16938.41 | E2: =PROY_Indexado!E4*PROY_Indexado!$B$52 -> 31079.895 | F2: =PROY_Indexado!F4*PROY_Indexado!$B$52 -> 46729.504 | G2: =PROY_Indexado!G4*PROY_Indexado!$B$52 -> 65104.955 | H2: =PROY_Indexado!H4*PROY_Indexado!$B$52 -> 81853.011 | I2: =PROY_Indexado!I4*PROY_Indexado!$B$52 -> 95047.101 | ... K2: =PROY_Indexado!K4*PROY_Indexado!$B$52 -> 108842.63
A3: =PROY_Indexado!A5 -> ABC 2,5 kg | B3: =PROY_Indexado!B5*PROY_Indexado!$B$52 -> 182.98967 | C3: =PROY_Indexado!C5*PROY_Indexado!$B$52 -> 713.89649 | D3: =PROY_Indexado!D5*PROY_Indexado!$B$52 -> 1634.2635 | E3: =PROY_Indexado!E5*PROY_Indexado!$B$52 -> 3008.8481 | F3: =PROY_Indexado!F5*PROY_Indexado!$B$52 -> 4353.4656 | G3: =PROY_Indexado!G5*PROY_Indexado!$B$52 -> 5780.2825 | H3: =PROY_Indexado!H5*PROY_Indexado!$B$52 -> 7103.34 | I3: =PROY_Indexado!I5*PROY_Indexado!$B$52 -> 7909.1529 | ... K3: =PROY_Indexado!K5*PROY_Indexado!$B$52 -> 9216.5401
A4: =PROY_Indexado!A6 -> ABC 5 kg | B4: =PROY_Indexado!B6*PROY_Indexado!$B$52 -> 1081.532 | C4: =PROY_Indexado!C6*PROY_Indexado!$B$52 -> 4354.432 | D4: =PROY_Indexado!D6*PROY_Indexado!$B$52 -> 9857.0636 | E4: =PROY_Indexado!E6*PROY_Indexado!$B$52 -> 18634.951 | F4: =PROY_Indexado!F6*PROY_Indexado!$B$52 -> 26842.954 | G4: =PROY_Indexado!G6*PROY_Indexado!$B$52 -> 35668.397 | H4: =PROY_Indexado!H6*PROY_Indexado!$B$52 -> 43652.404 | I4: =PROY_Indexado!I6*PROY_Indexado!$B$52 -> 48374.756 | ... K4: =PROY_Indexado!K6*PROY_Indexado!$B$52 -> 56059.271
A5: =PROY_Indexado!A7 -> ABC 10 kg | B5: =PROY_Indexado!B7*PROY_Indexado!$B$52 -> 65.62388 | C5: =PROY_Indexado!C7*PROY_Indexado!$B$52 -> 242.72248 | D5: =PROY_Indexado!D7*PROY_Indexado!$B$52 -> 568.36877 | E5: =PROY_Indexado!E7*PROY_Indexado!$B$52 -> 1087.086 | F5: =PROY_Indexado!F7*PROY_Indexado!$B$52 -> 1577.5958 | G5: =PROY_Indexado!G7*PROY_Indexado!$B$52 -> 2112.9368 | H5: =PROY_Indexado!H7*PROY_Indexado!$B$52 -> 2586.1015 | I5: =PROY_Indexado!I7*PROY_Indexado!$B$52 -> 2863.8253 | ... K5: =PROY_Indexado!K7*PROY_Indexado!$B$52 -> 3319.3279
A6: =PROY_Indexado!A8 -> Agua 10 l | B6: =PROY_Indexado!B8*PROY_Indexado!$B$52 -> 88.339839 | C6: =PROY_Indexado!C8*PROY_Indexado!$B$52 -> 356.79105 | D6: =PROY_Indexado!D8*PROY_Indexado!$B$52 -> 817.56324 | E6: =PROY_Indexado!E8*PROY_Indexado!$B$52 -> 1534.0518 | F6: =PROY_Indexado!F8*PROY_Indexado!$B$52 -> 2213.3463 | G6: =PROY_Indexado!G8*PROY_Indexado!$B$52 -> 2958.7819 | H6: =PROY_Indexado!H8*PROY_Indexado!$B$52 -> 3625.9818 | I6: =PROY_Indexado!I8*PROY_Indexado!$B$52 -> 4031.2585 | ... K6: =PROY_Indexado!K8*PROY_Indexado!$B$52 -> 4686.1432
A7: =PROY_Indexado!A9 -> AFFF 10 l | B7: =PROY_Indexado!B9*PROY_Indexado!$B$52 -> 12.619977 | C7: =PROY_Indexado!C9*PROY_Indexado!$B$52 -> 89.452768 | D7: =PROY_Indexado!D9*PROY_Indexado!$B$52 -> 175.56498 | E7: =PROY_Indexado!E9*PROY_Indexado!$B$52 -> 292.45073 | F7: =PROY_Indexado!F9*PROY_Indexado!$B$52 -> 412.44565 | G7: =PROY_Indexado!G9*PROY_Indexado!$B$52 -> 533.93282 | H7: =PROY_Indexado!H9*PROY_Indexado!$B$52 -> 662.61904 | I7: =PROY_Indexado!I9*PROY_Indexado!$B$52 -> 749.49841 | ... K7: =PROY_Indexado!K9*PROY_Indexado!$B$52 -> 889.69444
A8: =PROY_Indexado!A10 -> AFFF 50 l s/ruedas | B8: =PROY_Indexado!B10*PROY_Indexado!$B$52 -> 6.3099882 | C8: =PROY_Indexado!C10*PROY_Indexado!$B$52 -> 46.149085 | D8: =PROY_Indexado!D10*PROY_Indexado!$B$52 -> 91.198442 | E8: =PROY_Indexado!E10*PROY_Indexado!$B$52 -> 156.00922 | F8: =PROY_Indexado!F10*PROY_Indexado!$B$52 -> 221.19932 | G8: =PROY_Indexado!G10*PROY_Indexado!$B$52 -> 285.31554 | H8: =PROY_Indexado!H10*PROY_Indexado!$B$52 -> 348.82924 | I8: =PROY_Indexado!I10*PROY_Indexado!$B$52 -> 394.36225 | ... K8: =PROY_Indexado!K10*PROY_Indexado!$B$52 -> 463.77303
A9: =PROY_Indexado!A11 -> BC 5 kg | B9: =PROY_Indexado!B11*PROY_Indexado!$B$52 -> 3.7859929 | C9: =PROY_Indexado!C11*PROY_Indexado!$B$52 -> 26.10297 | D9: =PROY_Indexado!D11*PROY_Indexado!$B$52 -> 49.29108 | E9: =PROY_Indexado!E11*PROY_Indexado!$B$52 -> 88.44728 | F9: =PROY_Indexado!F11*PROY_Indexado!$B$52 -> 121.88133 | G9: =PROY_Indexado!G11*PROY_Indexado!$B$52 -> 161.84759 | H9: =PROY_Indexado!H11*PROY_Indexado!$B$52 -> 204.53137 | I9: =PROY_Indexado!I11*PROY_Indexado!$B$52 -> 226.47083 | ... K9: =PROY_Indexado!K11*PROY_Indexado!$B$52 -> 268.09876
A10: =PROY_Indexado!A12 -> Sales K 6 l | B10: =PROY_Indexado!B12*PROY_Indexado!$B$52 -> 45.431917 | C10: =PROY_Indexado!C12*PROY_Indexado!$B$52 -> 185.98529 | D10: =PROY_Indexado!D12*PROY_Indexado!$B$52 -> 414.00352 | E10: =PROY_Indexado!E12*PROY_Indexado!$B$52 -> 753.53678 | F10: =PROY_Indexado!F12*PROY_Indexado!$B$52 -> 1087.4828 | G10: =PROY_Indexado!G12*PROY_Indexado!$B$52 -> 1440.9425 | H10: =PROY_Indexado!H12*PROY_Indexado!$B$52 -> 1772.9457 | I10: =PROY_Indexado!I12*PROY_Indexado!$B$52 -> 1984.3708 | ... K10: =PROY_Indexado!K12*PROY_Indexado!$B$52 -> 2310.9941
A11: =PROY_Indexado!A13 -> CO₂ 2 kg | B11: =PROY_Indexado!B13*PROY_Indexado!$B$52 -> 249.87554 | C11: =PROY_Indexado!C13*PROY_Indexado!$B$52 -> 941.12064 | D11: =PROY_Indexado!D13*PROY_Indexado!$B$52 -> 2193.2347 | E11: =PROY_Indexado!E13*PROY_Indexado!$B$52 -> 4192.8681 | F11: =PROY_Indexado!F13*PROY_Indexado!$B$52 -> 6055.4358 | G11: =PROY_Indexado!G13*PROY_Indexado!$B$52 -> 8048.7904 | H11: =PROY_Indexado!H13*PROY_Indexado!$B$52 -> 9840.7841 | I11: =PROY_Indexado!I13*PROY_Indexado!$B$52 -> 10878.128 | ... K11: =PROY_Indexado!K13*PROY_Indexado!$B$52 -> 12606.73
A12: =PROY_Indexado!A14 -> CO₂ 5 kg | B12: =PROY_Indexado!B14*PROY_Indexado!$B$52 -> 69.409873 | C12: =PROY_Indexado!C14*PROY_Indexado!$B$52 -> 356.90575 | D12: =PROY_Indexado!D14*PROY_Indexado!$B$52 -> 762.81217 | E12: =PROY_Indexado!E14*PROY_Indexado!$B$52 -> 1364.2762 | F12: =PROY_Indexado!F14*PROY_Indexado!$B$52 -> 1965.9154 | G12: =PROY_Indexado!G14*PROY_Indexado!$B$52 -> 2619.2528 | H12: =PROY_Indexado!H14*PROY_Indexado!$B$52 -> 3246.106 | I12: =PROY_Indexado!I14*PROY_Indexado!$B$52 -> 3664.5215 | ... K12: =PROY_Indexado!K14*PROY_Indexado!$B$52 -> 4308.3839
A13: =PROY_Indexado!A15 -> HCFC/HFC 5 kg | B13: =PROY_Indexado!B15*PROY_Indexado!$B$52 -> 10.095982 | C13: =PROY_Indexado!C15*PROY_Indexado!$B$52 -> 62.147867 | D13: =PROY_Indexado!D15*PROY_Indexado!$B$52 -> 128.01312 | E13: =PROY_Indexado!E15*PROY_Indexado!$B$52 -> 222.20456 | F13: =PROY_Indexado!F15*PROY_Indexado!$B$52 -> 318.57591 | G13: =PROY_Indexado!G15*PROY_Indexado!$B$52 -> 418.29954 | H13: =PROY_Indexado!H15*PROY_Indexado!$B$52 -> 523.93733 | I13: =PROY_Indexado!I15*PROY_Indexado!$B$52 -> 594.57529 | ... K13: =PROY_Indexado!K15*PROY_Indexado!$B$52 -> 705.31645
... A18: =PROY_Indexado!A20 -> ABC 100 kg s/ruedas | B18: =PROY_Indexado!B20*PROY_Indexado!$B$52 -> 3.1297543 | C18: =PROY_Indexado!C20*PROY_Indexado!$B$52 -> 15.258222 | D18: =PROY_Indexado!D20*PROY_Indexado!$B$52 -> 33.159317 | E18: =PROY_Indexado!E20*PROY_Indexado!$B$52 -> 59.725524 | F18: =PROY_Indexado!F20*PROY_Indexado!$B$52 -> 85.907546 | G18: =PROY_Indexado!G20*PROY_Indexado!$B$52 -> 114.13709 | H18: =PROY_Indexado!H20*PROY_Indexado!$B$52 -> 140.61409 | I18: =PROY_Indexado!I20*PROY_Indexado!$B$52 -> 157.87003 | ... K18: =PROY_Indexado!K20*PROY_Indexado!$B$52 -> 184.88836
A19: Recargas Total | B19: =SUM(B2:B18) -> 3787.2551 | C19: =SUM(C2:C18) -> 17003.062 | D19: =SUM(D2:D18) -> 34093.569 | E19: =SUM(E2:E18) -> 63243.417 | F19: =SUM(F2:F18) -> 93087.448 | G19: =SUM(G2:G18) -> 126702.28 | H19: =SUM(H2:H18) -> 157360.38 | I19: =SUM(I2:I18) -> 178894.85 | ... K19: =SUM(K2:K18) -> 206230.15

Sheet parametros_recargas
A1: Parámetro | B1: Valor | C1: Fuente / criterio
A2: Días hábiles por mes | B2: 20 | C2: 2035: 248 hábiles (Ley 27.399) · § 11
A3: Horas por día (1 turno) | B3: 8 | C3: Ley 11.544 · § 11
A4: Refrigerio (min/turno) | B4: 30 | C4: Excel del grupo · § 11
A5: Horas productivas por turno | B5: =B3-B4/60 -> 7.5
A6: Horas productivas por mes (1 turno) | B6: =B2*B5 -> 150
A7: Umbral de aprovechamiento | B7: 0.9 | C7: Límite del grupo · § 8
A8: Turnos máximos por día | B8: 2 | C8: Ley 11.544 · § 8
A9: Equivalencia de un rodante (u. equivalentes) | B9: =D120 -> 6.3608539 | C9: Tiempos de FLAMA · § 6
A10: Año de inicio del 2° turno (antes: más máquinas) | B10: 2032 | C10: Criterio del grupo · § 8
A11: CRITERIOS DE RECARGA POR AGENTE — PLANTA COMERCIAL (qué le pasa al equipo en el año)
A12: Qué le pasa al equipo | B12: Unidad | C12: Fuente | D12: Estado | E12: ABC | F12: BC | G12: Clase D | H12: Agua | I12: AFFF | J12: Sales K | K12: CO₂ | L12: Halogenado
A13: Intervalo de prueba hidráulica | B13: años | C13: IRAM 3517-2 Anexo E | D13: Norma | E13: 5 | F13: 5 | G13: 5 | H13: 2 | I13: 2 | J13: 2 | K13: 5 | L13: 5
A14: Vence la prueba hidráulica | B14: % por año | C14: 1 ÷ intervalo (9.7.2) | D14: Norma | E14: =1/E13 -> 0.2 | F14: =1/F13 -> 0.2 | G14: =1/G13 -> 0.2 | H14: =1/H13 -> 0.5 | I14: =1/I13 -> 0.5 | J14: =1/J13 -> 0.5 | K14: =1/K13 -> 0.2 | L14: =1/L13 -> 0.2
A15: Daño menor (corrosión o golpe): va a PH | B15: % por año | C15: 9.7.1.2 · § 4.3 | D15: Criterio | E15: 0.05 | F15: 0.05 | G15: 0.05 | H15: 0.05 | I15: 0.05 | J15: 0.05 | K15: 0.05 | L15: 0.05
A16: Pasa por prueba hidráulica | B16: % por año | C16: Vence + daño | D16: Cálculo | E16: =E14+E15 -> 0.25 | F16: =F14+F15 -> 0.25 | G16: =G14+G15 -> 0.25 | H16: =H14+H15 -> 0.55 | I16: =I14+I15 -> 0.55 | J16: =J14+J15 -> 0.55 | K16: =K14+K15 -> 0.25 | L16: =L14+L15 -> 0.25
A17: Vida útil | B17: años | C17: IRAM 3517-2 Anexo E | D17: Norma | E17: 20 | F17: 20 | G17: 20 | H17: 20 | I17: 20 | J17: 20 | K17: 30 | L17: 20
A18: Llega al fin de la vida útil | B18: % por año | C18: 1 ÷ vida útil | D18: Norma | E18: =1/E17 -> 0.05 | F18: =1/F17 -> 0.05 | G18: =1/G17 -> 0.05 | H18: =1/H17 -> 0.05 | I18: =1/I17 -> 0.05 | J18: =1/J17 -> 0.05 | K18: =1/K17 -> 0.033333333 | L18: =1/L17 -> 0.05
A19: No pasa la prueba hidráulica | B19: % por año | C19: Proyecciones (Mat PH) | D19: Dato | E19: =PROY_Indexado!$B$47 -> 0.02 | F19: =PROY_Indexado!$B$47 -> 0.02 | G19: =PROY_Indexado!$B$47 -> 0.02 | H19: =PROY_Indexado!$B$47 -> 0.02 | I19: =PROY_Indexado!$B$47 -> 0.02 | J19: =PROY_Indexado!$B$47 -> 0.02 | K19: =PROY_Indexado!$B$47 -> 0.02 | L19: =PROY_Indexado!$B$47 -> 0.02
A20: Se rompe en el uso | B20: % por año | C20: Proyecciones (Mat Rot) | D20: Dato | E20: =PROY_Indexado!$B$48 -> 0.01 | F20: =PROY_Indexado!$B$48 -> 0.01 | G20: =PROY_Indexado!$B$48 -> 0.01 | H20: =PROY_Indexado!$B$48 -> 0.01 | I20: =PROY_Indexado!$B$48 -> 0.01 | J20: =PROY_Indexado!$B$48 -> 0.01 | K20: =PROY_Indexado!$B$48 -> 0.01 | L20: =PROY_Indexado!$B$48 -> 0.01
A21: Se inutiliza | B21: % por año | C21: Fin de vida + PH + roto (9.12) | D21: Cálculo | E21: =E18+E19+E20 -> 0.08 | F21: =F18+F19+F20 -> 0.08 | G21: =G18+G19+G20 -> 0.08 | H21: =H18+H19+H20 -> 0.08 | I21: =I18+I19+I20 -> 0.08 | J21: =J18+J19+J20 -> 0.08 | K21: =K18+K19+K20 -> 0.063333333 | L21: =L18+L19+L20 -> 0.08
A22: Llega descargado por uso | B22: % por año | C22: Proyecciones (Mat Usados) | D22: Dato | E22: =PROY_Indexado!$B$46 -> 0.05 | F22: =PROY_Indexado!$B$46 -> 0.05 | G22: =PROY_Indexado!$B$46 -> 0.05 | H22: =PROY_Indexado!$B$46 -> 0.05 | I22: =PROY_Indexado!$B$46 -> 0.05 | J22: =PROY_Indexado!$B$46 -> 0.05 | K22: =PROY_Indexado!$B$46 -> 0.05 | L22: =PROY_Indexado!$B$46 -> 0.05
A23: Cambio obligatorio del agente | B23: % por año | C23: 9.9.4 a), Anexo E · § 4.5 | D23: Norma | E23: =1/10 -> 0.1 | F23: 1 | G23: 1 | H23: 1 | I23: 1 | J23: 1 | K23: 0 | L23: 0
A24: Hay que abrir la válvula (pérdida de masa o daño) | B24: % por año | C24: Anexo F · § 4.6 | D24: Criterio | E24: 0 | F24: 0 | G24: 0 | H24: 0 | I24: 0 | J24: 0 | K24: 0.05 | L24: 0.05
A25: Se pinta | B25: % por año | C25: 9.10 · § 4.7 | D25: Criterio | E25: 0.15 | F25: 0.15 | G25: 0.15 | H25: 0.15 | I25: 0.15 | J25: 0.15 | K25: 0.15 | L25: 0.15
A26: Humedad interior al desarmar (secado extra) | B26: % por año | C26: 9.8 · § 4.8 | D26: Criterio | E26: 0.01 | F26: 0.01 | G26: 0.01 | H26: 0 | I26: 0 | J26: 0 | K26: 0 | L26: 0
A27: Capacidad de la tolva de polvo recuperado | B27: kg | C27: Word, op. 3 (Yukon) | D27: Dato | E27: 240 | F27: 0 | G27: 0 | H27: 0 | I27: 0 | J27: 0 | K27: 0 | L27: 0
A28: Ensayos de laboratorio por equipo | B28: ensayos/u. | C28: 1 por tolva (9.9.3) · § 4.9 | D28: Cálculo | E28: =IF(E27=0,0,(1-E22)*(1-E23)*SUMPRODUCT(($B$55:$B$71=E$12)*datos_base!$K$2:$K$18*$R$55:$R$71)/SUMPRODUCT(($B$55:$B$71=E$12)*datos_base!$K$2:$K$18*$C$55:$C$71)/E27) -> 0.010406792 | F28: =IF(F27=0,0,(1-F22)*(1-F23)*SUMPRODUCT(($B$55:$B$71=F$12)*datos_base!$K$2:$K$18*$R$55:$R$71)/SUMPRODUCT(($B$55:$B$71=F$12)*datos_base!$K$2:$K$18*$C$55:$C$71)/F27) -> 0 | G28: =IF(G27=0,0,(1-G22)*(1-G23)*SUMPRODUCT(($B$55:$B$71=G$12)*datos_base!$K$2:$K$18*$R$55:$R$71)/SUMPRODUCT(($B$55:$B$71=G$12)*datos_base!$K$2:$K$18*$C$55:$C$71)/G27) -> 0 | H28: =IF(H27=0,0,(1-H22)*(1-H23)*SUMPRODUCT(($B$55:$B$71=H$12)*datos_base!$K$2:$K$18*$R$55:$R$71)/SUMPRODUCT(($B$55:$B$71=H$12)*datos_base!$K$2:$K$18*$C$55:$C$71)/H27) -> 0 | I28: =IF(I27=0,0,(1-I22)*(1-I23)*SUMPRODUCT(($B$55:$B$71=I$12)*datos_base!$K$2:$K$18*$R$55:$R$71)/SUMPRODUCT(($B$55:$B$71=I$12)*datos_base!$K$2:$K$18*$C$55:$C$71)/I27) -> 0 | J28: =IF(J27=0,0,(1-J22)*(1-J23)*SUMPRODUCT(($B$55:$B$71=J$12)*datos_base!$K$2:$K$18*$R$55:$R$71)/SUMPRODUCT(($B$55:$B$71=J$12)*datos_base!$K$2:$K$18*$C$55:$C$71)/J27) -> 0 | K28: =IF(K27=0,0,(1-K22)*(1-K23)*SUMPRODUCT(($B$55:$B$71=K$12)*datos_base!$K$2:$K$18*$R$55:$R$71)/SUMPRODUCT(($B$55:$B$71=K$12)*datos_base!$K$2:$K$18*$C$55:$C$71)/K27) -> 0 | L28: =IF(L27=0,0,(1-L22)*(1-L23)*SUMPRODUCT(($B$55:$B$71=L$12)*datos_base!$K$2:$K$18*$R$55:$R$71)/SUMPRODUCT(($B$55:$B$71=L$12)*datos_base!$K$2:$K$18*$C$55:$C$71)/L27) -> 0
A29: Estado: Norma = IRAM 3517-2 · Dato = Proyecciones o Word · Criterio (fondo gris) = sin estadística publicada, a confirmar en la visita (§ 12) · Cálculo = sale de las filas de arriba
A32: ESTACIONALIDAD DE LAS RECARGAS POR RUBRO (% de las recargas del año en cada mes)
A33: IRAM 3517-2 9.2.1 y 9.4.14: cada equipo vuelve en el mes de su último mantenimiento · § 3
A34: Rubro | B34: Fuente / criterio | E34: Ene | F34: Feb | G34: Mar | H34: Abr | I34: May | J34: Jun | K34: Jul | L34: Ago | M34: Sep | N34: Oct | O34: Nov | P34: Dic | Q34: Total
A35: Automotor | B35: Temporada dic.-ene., transición nov. y feb. · § 3.1 | E35: =$B$44 -> 0.12 | F35: =$B$49 -> 0.095555556 | G35: =$B$48 -> 0.071111111 | H35: =$B$48 -> 0.071111111 | I35: =$B$48 -> 0.071111111 | J35: =$B$48 -> 0.071111111 | K35: =$B$48 -> 0.071111111 | L35: =$B$48 -> 0.071111111 | M35: =$B$48 -> 0.071111111 | N35: =$B$48 -> 0.071111111 | O35: =$B$49 -> 0.095555556 | P35: =$B$45 -> 0.12 | Q35: =SUM(E35:P35) -> 1
A36: Edificios | B36: Asambleas abr.-jun. (+); receso ene.-feb. (−) · § 3.2 | E36: =(1+$B$50*-1)/(12+$B$50*1) -> 0.054054054 | F36: =(1+$B$50*-1)/(12+$B$50*1) -> 0.054054054 | G36: =(1+$B$50*0)/(12+$B$50*1) -> 0.081081081 | H36: =(1+$B$50*1)/(12+$B$50*1) -> 0.10810811 | I36: =(1+$B$50*1)/(12+$B$50*1) -> 0.10810811 | J36: =(1+$B$50*1)/(12+$B$50*1) -> 0.10810811 | K36: =(1+$B$50*0)/(12+$B$50*1) -> 0.081081081 | L36: =(1+$B$50*0)/(12+$B$50*1) -> 0.081081081 | M36: =(1+$B$50*0)/(12+$B$50*1) -> 0.081081081 | N36: =(1+$B$50*0)/(12+$B$50*1) -> 0.081081081 | O36: =(1+$B$50*0)/(12+$B$50*1) -> 0.081081081 | P36: =(1+$B$50*0)/(12+$B$50*1) -> 0.081081081 | Q36: =SUM(E36:P36) -> 1
A37: Educación | B37: Receso de verano e inicio de clases ene.-mar. (+); receso de invierno jul. (+½) · § 3.3 | E37: =(1+$B$50*1)/(12+$B$50*3.5) -> 0.10126582 | F37: =(1+$B$50*1)/(12+$B$50*3.5) -> 0.10126582 | G37: =(1+$B$50*1)/(12+$B$50*3.5) -> 0.10126582 | H37: =(1+$B$50*0)/(12+$B$50*3.5) -> 0.075949367 | I37: =(1+$B$50*0)/(12+$B$50*3.5) -> 0.075949367 | J37: =(1+$B$50*0)/(12+$B$50*3.5) -> 0.075949367 | K37: =(1+$B$50*0.5)/(12+$B$50*3.5) -> 0.088607595 | L37: =(1+$B$50*0)/(12+$B$50*3.5) -> 0.075949367 | M37: =(1+$B$50*0)/(12+$B$50*3.5) -> 0.075949367 | N37: =(1+$B$50*0)/(12+$B$50*3.5) -> 0.075949367 | O37: =(1+$B$50*0)/(12+$B$50*3.5) -> 0.075949367 | P37: =(1+$B$50*0)/(12+$B$50*3.5) -> 0.075949367 | Q37: =SUM(E37:P37) -> 1
A38: Hoteles | B38: Baja ocupación may.-jun. y ago.-oct. (+); temporada ene., feb. y jul. (−) · § 3.4 | E38: =(1+$B$50*-1)/(12+$B$50*2) -> 0.052631579 | F38: =(1+$B$50*-1)/(12+$B$50*2) -> 0.052631579 | G38: =(1+$B$50*0)/(12+$B$50*2) -> 0.078947368 | H38: =(1+$B$50*0)/(12+$B$50*2) -> 0.078947368 | I38: =(1+$B$50*1)/(12+$B$50*2) -> 0.10526316 | J38: =(1+$B$50*1)/(12+$B$50*2) -> 0.10526316 | K38: =(1+$B$50*-1)/(12+$B$50*2) -> 0.052631579 | L38: =(1+$B$50*1)/(12+$B$50*2) -> 0.10526316 | M38: =(1+$B$50*1)/(12+$B$50*2) -> 0.10526316 | N38: =(1+$B$50*1)/(12+$B$50*2) -> 0.10526316 | O38: =(1+$B$50*0)/(12+$B$50*2) -> 0.078947368 | P38: =(1+$B$50*0)/(12+$B$50*2) -> 0.078947368 | Q38: =SUM(E38:P38) -> 1
A39: Industrias / almacenes | B39: Sin estacionalidad (Res. SRT 463/09) · § 3.5 | E39: =1/12 -> 0.083333333 | F39: =1/12 -> 0.083333333 | G39: =1/12 -> 0.083333333 | H39: =1/12 -> 0.083333333 | I39: =1/12 -> 0.083333333 | J39: =1/12 -> 0.083333333 | K39: =1/12 -> 0.083333333 | L39: =1/12 -> 0.083333333 | ... P39: =1/12 -> 0.083333333 | Q39: =SUM(E39:P39) -> 1
A40: Salud | B40: Verano dic.-feb. (+); campaña de invierno jun.-ago. (−) · § 3.6 | E40: =(1+$B$50*1)/(12+$B$50*0) -> 0.11111111 | F40: =(1+$B$50*1)/(12+$B$50*0) -> 0.11111111 | G40: =(1+$B$50*0)/(12+$B$50*0) -> 0.083333333 | H40: =(1+$B$50*0)/(12+$B$50*0) -> 0.083333333 | I40: =(1+$B$50*0)/(12+$B$50*0) -> 0.083333333 | J40: =(1+$B$50*-1)/(12+$B$50*0) -> 0.055555556 | K40: =(1+$B$50*-1)/(12+$B$50*0) -> 0.055555556 | L40: =(1+$B$50*-1)/(12+$B$50*0) -> 0.055555556 | M40: =(1+$B$50*0)/(12+$B$50*0) -> 0.083333333 | N40: =(1+$B$50*0)/(12+$B$50*0) -> 0.083333333 | O40: =(1+$B$50*0)/(12+$B$50*0) -> 0.083333333 | P40: =(1+$B$50*1)/(12+$B$50*0) -> 0.11111111 | Q40: =SUM(E40:P40) -> 1
A41: Supermercados | B41: Baja venta may.-ago. (+); fiestas y verano nov.-feb. (−) · § 3.7 | E41: =(1+$B$50*-1)/(12+$B$50*0) -> 0.055555556 | F41: =(1+$B$50*-1)/(12+$B$50*0) -> 0.055555556 | G41: =(1+$B$50*0)/(12+$B$50*0) -> 0.083333333 | H41: =(1+$B$50*0)/(12+$B$50*0) -> 0.083333333 | I41: =(1+$B$50*1)/(12+$B$50*0) -> 0.11111111 | J41: =(1+$B$50*1)/(12+$B$50*0) -> 0.11111111 | K41: =(1+$B$50*1)/(12+$B$50*0) -> 0.11111111 | L41: =(1+$B$50*1)/(12+$B$50*0) -> 0.11111111 | M41: =(1+$B$50*0)/(12+$B$50*0) -> 0.083333333 | N41: =(1+$B$50*0)/(12+$B$50*0) -> 0.083333333 | O41: =(1+$B$50*-1)/(12+$B$50*0) -> 0.055555556 | P41: =(1+$B$50*-1)/(12+$B$50*0) -> 0.055555556 | Q41: =SUM(E41:P41) -> 1
A43: Dato de la estacionalidad | B43: Valor | C43: Fuente
...

Sheet sobrestock_sustitutos
A1: SUSTITUTOS (IRAM 3517-2:2020, 9.4.5)
A2: Mismo tipo que el equipo retirado; sale y vuelve con el camión del lote · § 7
A4: Parámetro | B4: Valor | C4: Fuente / criterio
A5: Días hábiles por mes | B5: =parametros_recargas!B2 -> 20
A6: Día de retiro | B6: 1 | C6: Sale con el camión que retira el lote
A7: Día de devolución | B7: 1 | C7: Vuelve con el camión que devuelve el lote
A8: Minutos productivos por turno | B8: =parametros_recargas!B5*60 -> 450
A9: Planta | B9: =PROY_Indexado!B51 -> Comercial | C9: Origen del alta de los ABC · § 7.4
A10: Turnos por día desde el año del 2° turno | B10: =parametros_recargas!B8 -> 2 | C10: Antes, 1 turno
A11: Año del 2° turno | B11: =parametros_recargas!B10 -> 2032 | C11: El mismo del aprovechamiento
A12: Superficie por matafuego (m²) | B12: 200 | C12: Dec. 351/79, anexo VII
A14: PASO 1 — Lote, días en planta y ciclo por rubro
A15: Días en planta = minutos del lote ÷ minutos por día, hacia arriba · § 7.2
A16: Concepto | B16: Automotor | C16: Edificios | D16: Educación | E16: Hoteles | F16: Industrias / almacenes | G16: Salud | H16: Supermercados
A17: % de las recargas (mercado, zonas de la planta) | B17: =SUM(PROY_Indexado!B$57:B$73)/SUM(PROY_Indexado!$B$57:$H$73) -> 0.5764961 | C17: =SUM(PROY_Indexado!C$57:C$73)/SUM(PROY_Indexado!$B$57:$H$73) -> 0.29351867 | D17: =SUM(PROY_Indexado!D$57:D$73)/SUM(PROY_Indexado!$B$57:$H$73) -> 0.025513514 | E17: =SUM(PROY_Indexado!E$57:E$73)/SUM(PROY_Indexado!$B$57:$H$73) -> 0.017680713 | F17: =SUM(PROY_Indexado!F$57:F$73)/SUM(PROY_Indexado!$B$57:$H$73) -> 0.057564605 | G17: =SUM(PROY_Indexado!G$57:G$73)/SUM(PROY_Indexado!$B$57:$H$73) -> 0.02547121 | H17: =SUM(PROY_Indexado!H$57:H$73)/SUM(PROY_Indexado!$B$57:$H$73) -> 0.0037551838
A18: Lote por cliente (equipos que se retiran juntos) | B18: =PROY_Indexado!B83 -> 9 | C18: =PROY_Indexado!C83 -> 15 | D18: =PROY_Indexado!D83 -> 12 | E18: =PROY_Indexado!E83 -> 11 | F18: =PROY_Indexado!F83 -> 10 | G18: =PROY_Indexado!G83 -> 61 | H18: =PROY_Indexado!H83 -> 6
A19: Superficie mínima que protege el lote (m²) | B19: =B18*$B$12 -> 1800 | C19: =C18*$B$12 -> 3000 | D19: =D18*$B$12 -> 2400 | E19: =E18*$B$12 -> 2200 | F19: =F18*$B$12 -> 2000 | G19: =G18*$B$12 -> 12200 | H19: =H18*$B$12 -> 1200
A20: Minutos de operación por equipo (mix del rubro) | B20: =IF(SUM(PROY_Indexado!B$57:B$73)=0,0,SUMPRODUCT(PROY_Indexado!B$57:B$73,$C$30:$C$46)/SUM(PROY_Indexado!B$57:B$73)) -> 18.51156 | C20: =IF(SUM(PROY_Indexado!C$57:C$73)=0,0,SUMPRODUCT(PROY_Indexado!C$57:C$73,$C$30:$C$46)/SUM(PROY_Indexado!C$57:C$73)) -> 19.515155 | D20: =IF(SUM(PROY_Indexado!D$57:D$73)=0,0,SUMPRODUCT(PROY_Indexado!D$57:D$73,$C$30:$C$46)/SUM(PROY_Indexado!D$57:D$73)) -> 18.645333 | E20: =IF(SUM(PROY_Indexado!E$57:E$73)=0,0,SUMPRODUCT(PROY_Indexado!E$57:E$73,$C$30:$C$46)/SUM(PROY_Indexado!E$57:E$73)) -> 19.425742 | F20: =IF(SUM(PROY_Indexado!F$57:F$73)=0,0,SUMPRODUCT(PROY_Indexado!F$57:F$73,$C$30:$C$46)/SUM(PROY_Indexado!F$57:F$73)) -> 30.26804 | G20: =IF(SUM(PROY_Indexado!G$57:G$73)=0,0,SUMPRODUCT(PROY_Indexado!G$57:G$73,$C$30:$C$46)/SUM(PROY_Indexado!G$57:G$73)) -> 23.818067 | H20: =IF(SUM(PROY_Indexado!H$57:H$73)=0,0,SUMPRODUCT(PROY_Indexado!H$57:H$73,$C$30:$C$46)/SUM(PROY_Indexado!H$57:H$73)) -> 18.694396
A21: Minutos del lote en planta | B21: =B18*B20 -> 166.60404 | C21: =C18*C20 -> 292.72733 | D21: =D18*D20 -> 223.744 | E21: =E18*E20 -> 213.68316 | F21: =F18*F20 -> 302.6804 | G21: =G18*G20 -> 1452.9021 | H21: =H18*H20 -> 112.16638
A22: Días en planta con 1 turno | B22: =MAX(1,ROUNDUP(B21/$B$8,0)) -> 1 | C22: =MAX(1,ROUNDUP(C21/$B$8,0)) -> 1 | D22: =MAX(1,ROUNDUP(D21/$B$8,0)) -> 1 | E22: =MAX(1,ROUNDUP(E21/$B$8,0)) -> 1 | F22: =MAX(1,ROUNDUP(F21/$B$8,0)) -> 1 | G22: =MAX(1,ROUNDUP(G21/$B$8,0)) -> 4 | H22: =MAX(1,ROUNDUP(H21/$B$8,0)) -> 1
A23: Días en planta con 2 turnos | B23: =MAX(1,ROUNDUP(B21/($B$8*$B$10),0)) -> 1 | C23: =MAX(1,ROUNDUP(C21/($B$8*$B$10),0)) -> 1 | D23: =MAX(1,ROUNDUP(D21/($B$8*$B$10),0)) -> 1 | E23: =MAX(1,ROUNDUP(E21/($B$8*$B$10),0)) -> 1 | F23: =MAX(1,ROUNDUP(F21/($B$8*$B$10),0)) -> 1 | G23: =MAX(1,ROUNDUP(G21/($B$8*$B$10),0)) -> 2 | H23: =MAX(1,ROUNDUP(H21/($B$8*$B$10),0)) -> 1
A24: Ciclo del sustituto con 1 turno (días) | B24: =$B$6+B22+$B$7 -> 3 | C24: =$B$6+C22+$B$7 -> 3 | D24: =$B$6+D22+$B$7 -> 3 | E24: =$B$6+E22+$B$7 -> 3 | F24: =$B$6+F22+$B$7 -> 3 | G24: =$B$6+G22+$B$7 -> 6 | H24: =$B$6+H22+$B$7 -> 3
A25: Ciclo del sustituto con 2 turnos (días) | B25: =$B$6+B23+$B$7 -> 3 | C25: =$B$6+C23+$B$7 -> 3 | D25: =$B$6+D23+$B$7 -> 3 | E25: =$B$6+E23+$B$7 -> 3 | F25: =$B$6+F23+$B$7 -> 3 | G25: =$B$6+G23+$B$7 -> 4 | H25: =$B$6+H23+$B$7 -> 3
A28: PASO 2 — Tipos (el ciclo de cada tipo pesa los rubros según sus recargas)
A29: Tipo | B29: Lleva sustituto (1 = sí) | C29: Minutos de operación por equipo | D29: Ciclo con 1 turno (días) | E29: Ciclo con 2 turnos (días) | F29: Origen del alta | G29: Nota
A30: =datos_base!A2 -> ABC 1 kg | B30: 0 | C30: {=(SUMPRODUCT(INDEX(parametros_recargas!$E$76:$L$97,0,MATCH(parametros_recargas!$B$55,parametros_recargas!$E$75:$L$75,0)),parametros_recargas!$N$76:$N$97)*parametros_recargas!$C$55+parametros_recargas!$D$55*parametros_recargas!$N$98)/60} -> 18.51156 | D30: =IF(SUM(PROY_Indexado!$B$57:$H$57)=0,$B$6+1+$B$7,SUMPRODUCT(PROY_Indexado!$B$57:$H$57,$B$24:$H$24)/SUM(PROY_Indexado!$B$57:$H$57)) -> 3 | E30: =IF(SUM(PROY_Indexado!$B$57:$H$57)=0,$B$6+1+$B$7,SUMPRODUCT(PROY_Indexado!$B$57:$H$57,$B$25:$H$25)/SUM(PROY_Indexado!$B$57:$H$57)) -> 3 | F30: =IF(LEFT(A30,3)="ABC",IF($B$9="Comercial","Fábrica: cilindro vacío","Fábrica: terminado"),"Compra") -> Fábrica: cilindro vacío | G30: Automotor: sin canje
A31: =datos_base!A3 -> ABC 2,5 kg | B31: 1 | C31: {=(SUMPRODUCT(INDEX(parametros_recargas!$E$76:$L$97,0,MATCH(parametros_recargas!$B$56,parametros_recargas!$E$75:$L$75,0)),parametros_recargas!$N$76:$N$97)*parametros_recargas!$C$56+parametros_recargas!$D$56*parametros_recargas!$N$98)/60} -> 18.51156 | D31: =IF(SUM(PROY_Indexado!$B$58:$H$58)=0,$B$6+1+$B$7,SUMPRODUCT(PROY_Indexado!$B$58:$H$58,$B$24:$H$24)/SUM(PROY_Indexado!$B$58:$H$58)) -> 3.1266769 | E31: =IF(SUM(PROY_Indexado!$B$58:$H$58)=0,$B$6+1+$B$7,SUMPRODUCT(PROY_Indexado!$B$58:$H$58,$B$25:$H$25)/SUM(PROY_Indexado!$B$58:$H$58)) -> 3.0422256 | F31: =IF(LEFT(A31,3)="ABC",IF($B$9="Comercial","Fábrica: cilindro vacío","Fábrica: terminado"),"Compra") -> Fábrica: cilindro vacío
A32: =datos_base!A4 -> ABC 5 kg | B32: 1 | C32: {=(SUMPRODUCT(INDEX(parametros_recargas!$E$76:$L$97,0,MATCH(parametros_recargas!$B$57,parametros_recargas!$E$75:$L$75,0)),parametros_recargas!$N$76:$N$97)*parametros_recargas!$C$57+parametros_recargas!$D$57*parametros_recargas!$N$98)/60} -> 18.51156 | D32: =IF(SUM(PROY_Indexado!$B$59:$H$59)=0,$B$6+1+$B$7,SUMPRODUCT(PROY_Indexado!$B$59:$H$59,$B$24:$H$24)/SUM(PROY_Indexado!$B$59:$H$59)) -> 3.1366752 | E32: =IF(SUM(PROY_Indexado!$B$59:$H$59)=0,$B$6+1+$B$7,SUMPRODUCT(PROY_Indexado!$B$59:$H$59,$B$25:$H$25)/SUM(PROY_Indexado!$B$59:$H$59)) -> 3.0455584 | F32: =IF(LEFT(A32,3)="ABC",IF($B$9="Comercial","Fábrica: cilindro vacío","Fábrica: terminado"),"Compra") -> Fábrica: cilindro vacío
A33: =datos_base!A5 -> ABC 10 kg | B33: 1 | C33: {=(SUMPRODUCT(INDEX(parametros_recargas!$E$76:$L$97,0,MATCH(parametros_recargas!$B$58,parametros_recargas!$E$75:$L$75,0)),parametros_recargas!$N$76:$N$97)*parametros_recargas!$C$58+parametros_recargas!$D$58*parametros_recargas!$N$98)/60} -> 18.51156 | D33: =IF(SUM(PROY_Indexado!$B$60:$H$60)=0,$B$6+1+$B$7,SUMPRODUCT(PROY_Indexado!$B$60:$H$60,$B$24:$H$24)/SUM(PROY_Indexado!$B$60:$H$60)) -> 3.3190115 | E33: =IF(SUM(PROY_Indexado!$B$60:$H$60)=0,$B$6+1+$B$7,SUMPRODUCT(PROY_Indexado!$B$60:$H$60,$B$25:$H$25)/SUM(PROY_Indexado!$B$60:$H$60)) -> 3.1063372 | F33: =IF(LEFT(A33,3)="ABC",IF($B$9="Comercial","Fábrica: cilindro vacío","Fábrica: terminado"),"Compra") -> Fábrica: cilindro vacío
A34: =datos_base!A6 -> Agua 10 l | B34: 1 | C34: {=(SUMPRODUCT(INDEX(parametros_recargas!$E$76:$L$97,0,MATCH(parametros_recargas!$B$59,parametros_recargas!$E$75:$L$75,0)),parametros_recargas!$N$76:$N$97)*parametros_recargas!$C$59+parametros_recargas!$D$59*parametros_recargas!$N$98)/60} -> 19.355 | D34: =IF(SUM(PROY_Indexado!$B$61:$H$61)=0,$B$6+1+$B$7,SUMPRODUCT(PROY_Indexado!$B$61:$H$61,$B$24:$H$24)/SUM(PROY_Indexado!$B$61:$H$61)) -> 3.3158284 | E34: =IF(SUM(PROY_Indexado!$B$61:$H$61)=0,$B$6+1+$B$7,SUMPRODUCT(PROY_Indexado!$B$61:$H$61,$B$25:$H$25)/SUM(PROY_Indexado!$B$61:$H$61)) -> 3.1052761 | F34: =IF(LEFT(A34,3)="ABC",IF($B$9="Comercial","Fábrica: cilindro vacío","Fábrica: terminado"),"Compra") -> Compra
A35: =datos_base!A7 -> AFFF 10 l | B35: 1 | C35: {=(SUMPRODUCT(INDEX(parametros_recargas!$E$76:$L$97,0,MATCH(parametros_recargas!$B$60,parametros_recargas!$E$75:$L$75,0)),parametros_recargas!$N$76:$N$97)*parametros_recargas!$C$60+parametros_recargas!$D$60*parametros_recargas!$N$98)/60} -> 19.355 | D35: =IF(SUM(PROY_Indexado!$B$62:$H$62)=0,$B$6+1+$B$7,SUMPRODUCT(PROY_Indexado!$B$62:$H$62,$B$24:$H$24)/SUM(PROY_Indexado!$B$62:$H$62)) -> 3 | E35: =IF(SUM(PROY_Indexado!$B$62:$H$62)=0,$B$6+1+$B$7,SUMPRODUCT(PROY_Indexado!$B$62:$H$62,$B$25:$H$25)/SUM(PROY_Indexado!$B$62:$H$62)) -> 3 | F35: =IF(LEFT(A35,3)="ABC",IF($B$9="Comercial","Fábrica: cilindro vacío","Fábrica: terminado"),"Compra") -> Compra
A36: =datos_base!A8 -> AFFF 50 l s/ruedas | B36: 1 | C36: {=(SUMPRODUCT(INDEX(parametros_recargas!$E$76:$L$97,0,MATCH(parametros_recargas!$B$61,parametros_recargas!$E$75:$L$75,0)),parametros_recargas!$N$76:$N$97)*parametros_recargas!$C$61+parametros_recargas!$D$61*parametros_recargas!$N$98)/60} -> 128.11433 | D36: =IF(SUM(PROY_Indexado!$B$63:$H$63)=0,$B$6+1+$B$7,SUMPRODUCT(PROY_Indexado!$B$63:$H$63,$B$24:$H$24)/SUM(PROY_Indexado!$B$63:$H$63)) -> 3 | E36: =IF(SUM(PROY_Indexado!$B$63:$H$63)=0,$B$6+1+$B$7,SUMPRODUCT(PROY_Indexado!$B$63:$H$63,$B$25:$H$25)/SUM(PROY_Indexado!$B$63:$H$63)) -> 3 | F36: =IF(LEFT(A36,3)="ABC",IF($B$9="Comercial","Fábrica: cilindro vacío","Fábrica: terminado"),"Compra") -> Compra
A37: =datos_base!A9 -> BC 5 kg | B37: 1 | C37: {=(SUMPRODUCT(INDEX(parametros_recargas!$E$76:$L$97,0,MATCH(parametros_recargas!$B$62,parametros_recargas!$E$75:$L$75,0)),parametros_recargas!$N$76:$N$97)*parametros_recargas!$C$62+parametros_recargas!$D$62*parametros_recargas!$N$98)/60} -> 18.626667 | D37: =IF(SUM(PROY_Indexado!$B$64:$H$64)=0,$B$6+1+$B$7,SUMPRODUCT(PROY_Indexado!$B$64:$H$64,$B$24:$H$24)/SUM(PROY_Indexado!$B$64:$H$64)) -> 3 | E37: =IF(SUM(PROY_Indexado!$B$64:$H$64)=0,$B$6+1+$B$7,SUMPRODUCT(PROY_Indexado!$B$64:$H$64,$B$25:$H$25)/SUM(PROY_Indexado!$B$64:$H$64)) -> 3 | F37: =IF(LEFT(A37,3)="ABC",IF($B$9="Comercial","Fábrica: cilindro vacío","Fábrica: terminado"),"Compra") -> Compra
A38: =datos_base!A10 -> Sales K 6 l | B38: 1 | C38: {=(SUMPRODUCT(INDEX(parametros_recargas!$E$76:$L$97,0,MATCH(parametros_recargas!$B$63,parametros_recargas!$E$75:$L$75,0)),parametros_recargas!$N$76:$N$97)*parametros_recargas!$C$63+parametros_recargas!$D$63*parametros_recargas!$N$98)/60} -> 19.355 | D38: =IF(SUM(PROY_Indexado!$B$65:$H$65)=0,$B$6+1+$B$7,SUMPRODUCT(PROY_Indexado!$B$65:$H$65,$B$24:$H$24)/SUM(PROY_Indexado!$B$65:$H$65)) -> 3.215395 | E38: =IF(SUM(PROY_Indexado!$B$65:$H$65)=0,$B$6+1+$B$7,SUMPRODUCT(PROY_Indexado!$B$65:$H$65,$B$25:$H$25)/SUM(PROY_Indexado!$B$65:$H$65)) -> 3.0717983 | F38: =IF(LEFT(A38,3)="ABC",IF($B$9="Comercial","Fábrica: cilindro vacío","Fábrica: terminado"),"Compra") -> Compra
A39: =datos_base!A11 -> CO₂ 2 kg | B39: 1 | C39: {=(SUMPRODUCT(INDEX(parametros_recargas!$E$76:$L$97,0,MATCH(parametros_recargas!$B$64,parametros_recargas!$E$75:$L$75,0)),parametros_recargas!$N$76:$N$97)*parametros_recargas!$C$64+parametros_recargas!$D$64*parametros_recargas!$N$98)/60} -> 14.416667 | D39: =IF(SUM(PROY_Indexado!$B$66:$H$66)=0,$B$6+1+$B$7,SUMPRODUCT(PROY_Indexado!$B$66:$H$66,$B$24:$H$24)/SUM(PROY_Indexado!$B$66:$H$66)) -> 3.142125 | E39: =IF(SUM(PROY_Indexado!$B$66:$H$66)=0,$B$6+1+$B$7,SUMPRODUCT(PROY_Indexado!$B$66:$H$66,$B$25:$H$25)/SUM(PROY_Indexado!$B$66:$H$66)) -> 3.047375 | F39: =IF(LEFT(A39,3)="ABC",IF($B$9="Comercial","Fábrica: cilindro vacío","Fábrica: terminado"),"Compra") -> Compra
A40: =datos_base!A12 -> CO₂ 5 kg | B40: 1 | C40: {=(SUMPRODUCT(INDEX(parametros_recargas!$E$76:$L$97,0,MATCH(parametros_recargas!$B$65,parametros_recargas!$E$75:$L$75,0)),parametros_recargas!$N$76:$N$97)*parametros_recargas!$C$65+parametros_recargas!$D$65*parametros_recargas!$N$98)/60} -> 19.416667 | D40: =IF(SUM(PROY_Indexado!$B$67:$H$67)=0,$B$6+1+$B$7,SUMPRODUCT(PROY_Indexado!$B$67:$H$67,$B$24:$H$24)/SUM(PROY_Indexado!$B$67:$H$67)) -> 3.4688708 | E40: =IF(SUM(PROY_Indexado!$B$67:$H$67)=0,$B$6+1+$B$7,SUMPRODUCT(PROY_Indexado!$B$67:$H$67,$B$25:$H$25)/SUM(PROY_Indexado!$B$67:$H$67)) -> 3.1562903 | F40: =IF(LEFT(A40,3)="ABC",IF($B$9="Comercial","Fábrica: cilindro vacío","Fábrica: terminado"),"Compra") -> Compra
A41: =datos_base!A13 -> HCFC/HFC 5 kg | B41: 1 | C41: {=(SUMPRODUCT(INDEX(parametros_recargas!$E$76:$L$97,0,MATCH(parametros_recargas!$B$66,parametros_recargas!$E$75:$L$75,0)),parametros_recargas!$N$76:$N$97)*parametros_recargas!$C$66+parametros_recargas!$D$66*parametros_recargas!$N$98)/60} -> 17.609167 | D41: =IF(SUM(PROY_Indexado!$B$68:$H$68)=0,$B$6+1+$B$7,SUMPRODUCT(PROY_Indexado!$B$68:$H$68,$B$24:$H$24)/SUM(PROY_Indexado!$B$68:$H$68)) -> 3.6221943 | E41: =IF(SUM(PROY_Indexado!$B$68:$H$68)=0,$B$6+1+$B$7,SUMPRODUCT(PROY_Indexado!$B$68:$H$68,$B$25:$H$25)/SUM(PROY_Indexado!$B$68:$H$68)) -> 3.2073981 | F41: =IF(LEFT(A41,3)="ABC",IF($B$9="Comercial","Fábrica: cilindro vacío","Fábrica: terminado"),"Compra") -> Compra
A42: =datos_base!A14 -> Clase D 9 l | B42: 1 | C42: {=(SUMPRODUCT(INDEX(parametros_recargas!$E$76:$L$97,0,MATCH(parametros_recargas!$B$67,parametros_recargas!$E$75:$L$75,0)),parametros_recargas!$N$76:$N$97)*parametros_recargas!$C$67+parametros_recargas!$D$67*parametros_recargas!$N$98)/60} -> 19.71 | D42: =IF(SUM(PROY_Indexado!$B$69:$H$69)=0,$B$6+1+$B$7,SUMPRODUCT(PROY_Indexado!$B$69:$H$69,$B$24:$H$24)/SUM(PROY_Indexado!$B$69:$H$69)) -> 3 | E42: =IF(SUM(PROY_Indexado!$B$69:$H$69)=0,$B$6+1+$B$7,SUMPRODUCT(PROY_Indexado!$B$69:$H$69,$B$25:$H$25)/SUM(PROY_Indexado!$B$69:$H$69)) -> 3 | F42: =IF(LEFT(A42,3)="ABC",IF($B$9="Comercial","Fábrica: cilindro vacío","Fábrica: terminado"),"Compra") -> Compra
A43: =datos_base!A15 -> ABC 25 kg s/ruedas | B43: 1 | C43: {=(SUMPRODUCT(INDEX(parametros_recargas!$E$76:$L$97,0,MATCH(parametros_recargas!$B$68,parametros_recargas!$E$75:$L$75,0)),parametros_recargas!$N$76:$N$97)*parametros_recargas!$C$68+parametros_recargas!$D$68*parametros_recargas!$N$98)/60} -> 122.74933 | D43: =IF(SUM(PROY_Indexado!$B$70:$H$70)=0,$B$6+1+$B$7,SUMPRODUCT(PROY_Indexado!$B$70:$H$70,$B$24:$H$24)/SUM(PROY_Indexado!$B$70:$H$70)) -> 3.4002386 | E43: =IF(SUM(PROY_Indexado!$B$70:$H$70)=0,$B$6+1+$B$7,SUMPRODUCT(PROY_Indexado!$B$70:$H$70,$B$25:$H$25)/SUM(PROY_Indexado!$B$70:$H$70)) -> 3.1334129 | F43: =IF(LEFT(A43,3)="ABC",IF($B$9="Comercial","Fábrica: cilindro vacío","Fábrica: terminado"),"Compra") -> Fábrica: cilindro vacío
A44: =datos_base!A16 -> ABC 50 kg s/ruedas | B44: 1 | C44: {=(SUMPRODUCT(INDEX(parametros_recargas!$E$76:$L$97,0,MATCH(parametros_recargas!$B$69,parametros_recargas!$E$75:$L$75,0)),parametros_recargas!$N$76:$N$97)*parametros_recargas!$C$69+parametros_recargas!$D$69*parametros_recargas!$N$98)/60} -> 122.74933 | D44: =IF(SUM(PROY_Indexado!$B$71:$H$71)=0,$B$6+1+$B$7,SUMPRODUCT(PROY_Indexado!$B$71:$H$71,$B$24:$H$24)/SUM(PROY_Indexado!$B$71:$H$71)) -> 3.4002276 | E44: =IF(SUM(PROY_Indexado!$B$71:$H$71)=0,$B$6+1+$B$7,SUMPRODUCT(PROY_Indexado!$B$71:$H$71,$B$25:$H$25)/SUM(PROY_Indexado!$B$71:$H$71)) -> 3.1334092 | F44: =IF(LEFT(A44,3)="ABC",IF($B$9="Comercial","Fábrica: cilindro vacío","Fábrica: terminado"),"Compra") -> Fábrica: cilindro vacío
...

Sheet Plan mensual
A1: 2026 | B1: Agente | C1: u. equiv. | D1: Ene | E1: Feb | F1: Mar | G1: Abr | H1: May | I1: Jun | J1: Jul | K1: Ago | L1: Sep | M1: Oct | N1: Nov | O1: Dic | P1: Total
A2: =parametros_recargas!A55 -> ABC 1 kg | B2: =parametros_recargas!B55 -> ABC | C2: =parametros_recargas!C55 -> 1 | D2: =datos_base!$B$2*parametros_recargas!E$55 -> 231.16456 | E2: =datos_base!$B$2*parametros_recargas!F$55 -> 184.11342 | F2: =datos_base!$B$2*parametros_recargas!G$55 -> 137.15538 | G2: =datos_base!$B$2*parametros_recargas!H$55 -> 137.15538 | H2: =datos_base!$B$2*parametros_recargas!I$55 -> 137.24849 | I2: =datos_base!$B$2*parametros_recargas!J$55 -> 137.24849 | J2: =datos_base!$B$2*parametros_recargas!K$55 -> 137.08745 | K2: =datos_base!$B$2*parametros_recargas!L$55 -> 137.24849 | ... O2: =datos_base!$B$2*parametros_recargas!P$55 -> 231.24508 | P2: =SUM(D2:O2) -> 1928.3325
