Workbook

Sheet Links
A1: Links e IMPORTRANGE
A2: Pegar en B el link de cada Google Sheet. La primera vez, tocar la primera celda de cada bloque y «Permitir acceso». Todos los IMPORTRANGE del libro están en esta hoja; las demás la leen.
A3: Archivo | B3: Link | G3: Qué se importa | M3: Estado
A4: Proyecciones | B4: https://docs.google.com/spreadsheets/d/1xc4xDAwSYT3l-RulPYtcePxiCninrbQGzaBUsgO0YEs/edit?gid=1764491891#gid=1764491891 | G4: Indexado Dim Técnico B3:K10 y B15:K22 → datos_base y carros en las guillotinas compartidas | M4: =IF(ISERROR(B13),"Falta el link o «Permitir acceso»","OK") -> OK
A5: Aprovechamiento Recargas Planta Comercial | B5: PEGAR ACÁ EL LINK DEL GOOGLE SHEET | G5: sobrestock_sustitutos B73:K76 y B86:K89: alta de sustitutos ABC (cilindros vacíos) | M5: =IF(ISERROR(B34),"Falta el link o «Permitir acceso»","OK") -> OK
A6: Aprovechamiento Recargas Planta Industrial | B6: PEGAR ACÁ EL LINK DEL GOOGLE SHEET | G6: sobrestock_sustitutos B73:K76 y B86:K89: alta de sustitutos ABC (terminados) | M6: =IF(ISERROR(B27),"Falta el link o «Permitir acceso»","OK") -> OK
A7: MRP (FLAMA_MRP) | B7: PEGAR ACÁ EL LINK DEL GOOGLE SHEET | G7: ESTACIONALIDAD C4:N6 (E01, E02 y E03) → parametros_manuales | M7: =IF(ISERROR(B41),"Falta el link o «Permitir acceso»","OK") -> OK
A8: Análisis alternativas corte chapa | B8: PEGAR ACÁ EL LINK DEL GOOGLE SHEET | G8: Corte B19:G27 (piezas y golpes por hoja; golpes por minuto) → parametros_manuales filas 118 a 137 | M8: =IF(ISERROR(B49),"Falta el link o «Permitir acceso»","OK") -> OK
A11: Proyecciones · Indexado Dim Técnico!B3:K6: matafuegos terminados
B12: 2026 | C12: 2027 | D12: 2028 | E12: 2029 | F12: 2030 | G12: 2031 | H12: 2032 | I12: 2033 | J12: 2034 | K12: 2035
A13: ABC 1 kg | B13: =IFERROR(__xludf.DUMMYFUNCTION("IMPORTRANGE(Links!$B$4,""Indexado Dim Técnico!B3:K6"")"),4178.736543) -> 4178.7365
A14: ABC 2,5 kg
A15: ABC 5 kg
A16: ABC 10 kg
A18: Proyecciones · Indexado Dim Técnico!B15:K18: cilindros vendidos vacíos
B19: 2026 | C19: 2027 | D19: 2028 | E19: 2029 | F19: 2030 | G19: 2031 | H19: 2032 | I19: 2033 | J19: 2034 | K19: 2035
A20: ABC 1 kg | B20: =IFERROR(__xludf.DUMMYFUNCTION("IMPORTRANGE(Links!$B$4,""Indexado Dim Técnico!B15:K18"")"),0) -> 0
A21: ABC 2,5 kg
A22: ABC 5 kg
A23: ABC 10 kg
A25: Aprovechamiento Recargas Planta Industrial · sobrestock_sustitutos!B73:K76: alta de sustitutos ABC terminados
B26: 2026 | C26: 2027 | D26: 2028 | E26: 2029 | F26: 2030 | G26: 2031 | H26: 2032 | I26: 2033 | J26: 2034 | K26: 2035
A27: ABC 1 kg | B27: =IFERROR(__xludf.DUMMYFUNCTION("IMPORTRANGE(Links!$B$6,""sobrestock_sustitutos!B73:K76"")"),0) -> 0
A28: ABC 2,5 kg
A29: ABC 5 kg
A30: ABC 10 kg
A32: Aprovechamiento Recargas Planta Comercial · sobrestock_sustitutos!B73:K76: alta de sustitutos ABC cilindros vacíos
B33: 2026 | C33: 2027 | D33: 2028 | E33: 2029 | F33: 2030 | G33: 2031 | H33: 2032 | I33: 2033 | J33: 2034 | K33: 2035
A34: ABC 1 kg | B34: =IFERROR(__xludf.DUMMYFUNCTION("IMPORTRANGE(Links!$B$5,""sobrestock_sustitutos!B73:K76"")"),0) -> 0
A35: ABC 2,5 kg
A36: ABC 5 kg
A37: ABC 10 kg
A39: MRP (FLAMA_MRP) · ESTACIONALIDAD!C4:N4: E01 automotor (1 kg)
B40: Ene | C40: Feb | D40: Mar | E40: Abr | F40: May | G40: Jun | H40: Jul | I40: Ago | J40: Sep | K40: Oct | L40: Nov | M40: Dic
A41: E01 automotor (1 kg) | B41: =IFERROR(__xludf.DUMMYFUNCTION("IMPORTRANGE(Links!$B$7,""ESTACIONALIDAD!C4:N4"")"),0.12) -> 0.12
A43: MRP (FLAMA_MRP) · ESTACIONALIDAD!C5:N5: E02 manual comercial (2,5 a 10 kg)
B44: Ene | C44: Feb | D44: Mar | E44: Abr | F44: May | G44: Jun | H44: Jul | I44: Ago | J44: Sep | K44: Oct | L44: Nov | M44: Dic
A45: E02 manual comercial (2,5 a 10 kg) | B45: =IFERROR(__xludf.DUMMYFUNCTION("IMPORTRANGE(Links!$B$7,""ESTACIONALIDAD!C5:N5"")"),0.1) -> 0.1
A47: Análisis alternativas corte chapa · Corte!B19:G22: piezas, golpes y tandas por hoja y golpes por minuto (1 a 10 kg)
B48: Piezas por hoja | C48: Golpes G1 por hoja | D48: Golpes G2 por hoja | E48: Tandas G2 por hoja | F48: Golpes/min G1 | G48: Golpes/min G2
...

Sheet datos_base
A1: Matafuegos terminados (total para el cálculo = base + planta industrial) | B1: 2026 | C1: 2027 | D1: 2028 | E1: 2029 | F1: 2030 | G1: 2031 | H1: 2032 | I1: 2033 | J1: 2034 | K1: 2035
A2: ABC 1 kg | B2: =B19+B33 -> 4178.7365 | C2: =C19+C33 -> 5997.304 | D2: =D19+D33 -> 6851.7478 | E2: =E19+E33 -> 8467.1355 | F2: =F19+F33 -> 12680.633 | G2: =G19+G33 -> 15620.253 | H2: =H19+H33 -> 20332.553 | I2: =I19+I33 -> 25132.078 | ... K2: =K19+K33 -> 32072.639
A3: ABC 2,5 kg | B3: =B20+B34 -> 297.03036 | C3: =C20+C34 -> 714.88745 | D3: =D20+D34 -> 994.42806 | E3: =E20+E34 -> 1513.7582 | F3: =F20+F34 -> 2325.7077 | G3: =G20+G34 -> 3267.8299 | H3: =H20+H34 -> 4116.2355 | I3: =I20+I34 -> 5115.0266 | ... K3: =K20+K34 -> 7436.4584
A4: ABC 5 kg | B4: =B21+B35 -> 2264.773 | C4: =C21+C35 -> 3874.6989 | D4: =D21+D35 -> 5141.4176 | E4: =E21+E35 -> 6901.5953 | F4: =F21+F35 -> 10899.547 | G4: =G21+G35 -> 14695.644 | H4: =H21+H35 -> 18955.2 | I4: =I21+I35 -> 23433.946 | ... K4: =K21+K35 -> 30814.979
A5: ABC 10 kg | B5: =B22+B36 -> 92.833182 | C5: =C22+C36 -> 179.3273 | D5: =D22+D36 -> 256.21878 | E5: =E22+E36 -> 362.50049 | F5: =F22+F36 -> 607.51815 | G5: =G22+G36 -> 878.72503 | H5: =H22+H36 -> 1131.6805 | I5: =I22+I36 -> 1399.2048 | ... K5: =K22+K36 -> 1844.9281
A6: Total terminados | B6: =SUM(B2:B5) -> 6833.3731 | C6: =SUM(C2:C5) -> 10766.218 | D6: =SUM(D2:D5) -> 13243.812 | E6: =SUM(E2:E5) -> 17244.99 | F6: =SUM(F2:F5) -> 26513.406 | G6: =SUM(G2:G5) -> 34462.452 | H6: =SUM(H2:H5) -> 44535.669 | I6: =SUM(I2:I5) -> 55080.256 | ... K6: =SUM(K2:K5) -> 72169.004
A8: Cilindros vendidos vacíos (total para el cálculo = base + planta comercial) | B8: 2026 | C8: 2027 | D8: 2028 | E8: 2029 | F8: 2030 | G8: 2031 | H8: 2032 | I8: 2033 | J8: 2034 | K8: 2035
A9: Cilindros ABC 1 kg | B9: =B26+B41 -> 0 | C9: =C26+C41 -> 0 | D9: =D26+D41 -> 7662.4 | E9: =E26+E41 -> 26694.8 | F9: =F26+F41 -> 49434.8 | G9: =G26+G41 -> 71680.2 | H9: =H26+H41 -> 101340.6 | I9: =I26+I41 -> 131001 | ... K9: =K26+K41 -> 170548
A10: Cilindros ABC 2,5 kg | B10: =B27+B42 -> 3 | C10: =C27+C42 -> 9.24 | D10: =D27+D42 -> 315.56 | E10: =E27+E42 -> 1067.96 | F10: =F27+F42 -> 1958.92 | G10: =G27+G42 -> 2831.68 | H10: =H27+H42 -> 3989.52 | I10: =I27+I42 -> 5144.04 | ... K10: =K27+K42 -> 6689.88
A11: Cilindros ABC 5 kg | B11: =B28+B43 -> 17 | C11: =C28+C43 -> 53.36 | D11: =D28+D43 -> 1570.32 | E11: =E28+E43 -> 5302.4 | F11: =F28+F43 -> 9693.24 | G11: =G28+G43 -> 14005.96 | H11: =H28+H43 -> 19709.4 | I11: =I28+I43 -> 25408.28 | ... K11: =K28+K43 -> 33037.68
A12: Cilindros ABC 10 kg | B12: =B29+B44 -> 2 | C12: =C29+C44 -> 3.16 | D12: =D29+D44 -> 95.8 | E12: =E29+E44 -> 324.8 | F12: =F29+F44 -> 592.92 | G12: =G29+G44 -> 856.96 | H12: =H29+H44 -> 1204.28 | I12: =I29+I44 -> 1552.36 | ... K12: =K29+K44 -> 2018
A13: Total cilindros | B13: =SUM(B9:B12) -> 22 | C13: =SUM(C9:C12) -> 65.76 | D13: =SUM(D9:D12) -> 9644.08 | E13: =SUM(E9:E12) -> 33389.96 | F13: =SUM(F9:F12) -> 61679.88 | G13: =SUM(G9:G12) -> 89374.8 | H13: =SUM(H9:H12) -> 126243.8 | I13: =SUM(I9:I12) -> 163105.68 | ... K13: =SUM(K9:K12) -> 212293.56
A15: Total recipientes a fabricar | B15: =B6+B13 -> 6855.3731 | C15: =C6+C13 -> 10831.978 | D15: =D6+D13 -> 22887.892 | E15: =E6+E13 -> 50634.95 | F15: =F6+F13 -> 88193.286 | G15: =G6+G13 -> 123837.25 | H15: =H6+H13 -> 170779.47 | I15: =I6+I13 -> 218185.94 | ... K15: =K6+K13 -> 284462.56
A18: PROYECCIONES — Matafuegos terminados (Indexado Dim Técnico B3:K6, hoja Links) | B18: 2026 | C18: 2027 | D18: 2028 | E18: 2029 | F18: 2030 | G18: 2031 | H18: 2032 | I18: 2033 | J18: 2034 | K18: 2035
A19: ABC 1 kg | B19: =Links!B13 -> 4178.7365 | C19: =Links!C13 -> 5997.304 | D19: =Links!D13 -> 6851.7478 | E19: =Links!E13 -> 8467.1355 | F19: =Links!F13 -> 12680.633 | G19: =Links!G13 -> 15620.253 | H19: =Links!H13 -> 20332.553 | I19: =Links!I13 -> 25132.078 | ... K19: =Links!K13 -> 32072.639
A20: ABC 2,5 kg | B20: =Links!B14 -> 295.03036 | C20: =Links!C14 -> 709.72745 | D20: =Links!D14 -> 986.86806 | E20: =Links!E14 -> 1500.6382 | F20: =Links!F14 -> 2312.6277 | G20: =Links!G14 -> 3252.8699 | H20: =Links!H14 -> 4102.3155 | I20: =Links!I14 -> 5104.3066 | ... K20: =Links!K14 -> 7424.8584
A21: ABC 5 kg | B21: =Links!B15 -> 2255.773 | C21: =Links!C15 -> 3846.9789 | D21: =Links!D15 -> 5093.5376 | E21: =Links!E15 -> 6823.1153 | F21: =Links!F15 -> 10819.307 | G21: =Links!G15 -> 14605.964 | H21: =Links!H15 -> 18877.76 | I21: =Links!I15 -> 23368.186 | ... K21: =Links!K15 -> 30750.779
A22: ABC 10 kg | B22: =Links!B16 -> 91.833182 | C22: =Links!C16 -> 177.2473 | D22: =Links!D16 -> 252.97878 | E22: =Links!E16 -> 358.02049 | F22: =Links!F16 -> 602.71815 | G22: =Links!G16 -> 872.60503 | H22: =Links!H16 -> 1127.1605 | I22: =Links!I16 -> 1395.4448 | ... K22: =Links!K16 -> 1840.8481
A23: Total base terminados | B23: =SUM(B19:B22) -> 6821.3731 | C23: =SUM(C19:C22) -> 10731.258 | D23: =SUM(D19:D22) -> 13185.132 | E23: =SUM(E19:E22) -> 17148.91 | F23: =SUM(F19:F22) -> 26415.286 | G23: =SUM(G19:G22) -> 34351.692 | H23: =SUM(H19:H22) -> 44439.789 | I23: =SUM(I19:I22) -> 55000.016 | ... K23: =SUM(K19:K22) -> 72089.124
A25: PROYECCIONES — Cilindros vendidos vacíos (Indexado Dim Técnico B15:K18, hoja Links) | B25: 2026 | C25: 2027 | D25: 2028 | E25: 2029 | F25: 2030 | G25: 2031 | H25: 2032 | I25: 2033 | J25: 2034 | K25: 2035
A26: Cilindros ABC 1 kg | B26: =Links!B20 -> 0 | C26: =Links!C20 -> 0 | D26: =Links!D20 -> 7662.4 | E26: =Links!E20 -> 26694.8 | F26: =Links!F20 -> 49434.8 | G26: =Links!G20 -> 71680.2 | H26: =Links!H20 -> 101340.6 | I26: =Links!I20 -> 131001 | ... K26: =Links!K20 -> 170548
A27: Cilindros ABC 2,5 kg | B27: =Links!B21 -> 0 | C27: =Links!C21 -> 0 | D27: =Links!D21 -> 299.6 | E27: =Links!E21 -> 1043.8 | F27: =Links!F21 -> 1933 | G27: =Links!G21 -> 2803 | H27: =Links!H21 -> 3963 | I27: =Links!I21 -> 5123 | ... K27: =Links!K21 -> 6669
A28: Cilindros ABC 5 kg | B28: =Links!B22 -> 0 | C28: =Links!C22 -> 0 | D28: =Links!D22 -> 1478.8 | E28: =Links!E22 -> 5152 | F28: =Links!F22 -> 9540.8 | G28: =Links!G22 -> 13834.2 | H28: =Links!H22 -> 19558.6 | I28: =Links!I22 -> 25283 | ... K28: =Links!K22 -> 32915
A29: Cilindros ABC 10 kg | B29: =Links!B23 -> 0 | C29: =Links!C23 -> 0 | D29: =Links!D23 -> 90.4 | E29: =Links!E23 -> 315 | F29: =Links!F23 -> 583.4 | G29: =Links!G23 -> 845.8 | H29: =Links!H23 -> 1195.4 | I29: =Links!I23 -> 1545 | ... K29: =Links!K23 -> 2011
A30: Total base cilindros | B30: =SUM(B26:B29) -> 0 | C30: =SUM(C26:C29) -> 0 | D30: =SUM(D26:D29) -> 9531.2 | E30: =SUM(E26:E29) -> 33205.6 | F30: =SUM(F26:F29) -> 61492 | G30: =SUM(G26:G29) -> 89163.2 | H30: =SUM(H26:H29) -> 126057.6 | I30: =SUM(I26:I29) -> 162952 | ... K30: =SUM(K26:K29) -> 212143
A32: PLANTA INDUSTRIAL — Sustitutos ABC terminados: alta anual (sobrestock_sustitutos, paso 4) | B32: 2026 | C32: 2027 | D32: 2028 | E32: 2029 | F32: 2030 | G32: 2031 | H32: 2032 | I32: 2033 | J32: 2034 | K32: 2035
A33: ABC 1 kg | B33: =IFERROR(Links!B27,0) -> 0 | C33: =IFERROR(Links!C27,0) -> 0 | D33: =IFERROR(Links!D27,0) -> 0 | E33: =IFERROR(Links!E27,0) -> 0 | F33: =IFERROR(Links!F27,0) -> 0 | G33: =IFERROR(Links!G27,0) -> 0 | H33: =IFERROR(Links!H27,0) -> 0 | I33: =IFERROR(Links!I27,0) -> 0 | ... K33: =IFERROR(Links!K27,0) -> 0
A34: ABC 2,5 kg | B34: =IFERROR(Links!B28,0) -> 2 | C34: =IFERROR(Links!C28,0) -> 5.16 | D34: =IFERROR(Links!D28,0) -> 7.56 | E34: =IFERROR(Links!E28,0) -> 13.12 | F34: =IFERROR(Links!F28,0) -> 13.08 | G34: =IFERROR(Links!G28,0) -> 14.96 | H34: =IFERROR(Links!H28,0) -> 13.92 | I34: =IFERROR(Links!I28,0) -> 10.72 | ... K34: =IFERROR(Links!K28,0) -> 11.6
A35: ABC 5 kg | B35: =IFERROR(Links!B29,0) -> 9 | C35: =IFERROR(Links!C29,0) -> 27.72 | D35: =IFERROR(Links!D29,0) -> 47.88 | E35: =IFERROR(Links!E29,0) -> 78.48 | F35: =IFERROR(Links!F29,0) -> 80.24 | G35: =IFERROR(Links!G29,0) -> 89.68 | H35: =IFERROR(Links!H29,0) -> 77.44 | I35: =IFERROR(Links!I29,0) -> 65.76 | ... K35: =IFERROR(Links!K29,0) -> 64.2
A36: ABC 10 kg | B36: =IFERROR(Links!B30,0) -> 1 | C36: =IFERROR(Links!C30,0) -> 2.08 | D36: =IFERROR(Links!D30,0) -> 3.24 | E36: =IFERROR(Links!E30,0) -> 4.48 | F36: =IFERROR(Links!F30,0) -> 4.8 | G36: =IFERROR(Links!G30,0) -> 6.12 | H36: =IFERROR(Links!H30,0) -> 4.52 | I36: =IFERROR(Links!I30,0) -> 3.76 | ... K36: =IFERROR(Links!K30,0) -> 4.08
A37: Total sustitutos planta industrial | B37: =SUM(B33:B36) -> 12 | C37: =SUM(C33:C36) -> 34.96 | D37: =SUM(D33:D36) -> 58.68 | E37: =SUM(E33:E36) -> 96.08 | F37: =SUM(F33:F36) -> 98.12 | G37: =SUM(G33:G36) -> 110.76 | H37: =SUM(H33:H36) -> 95.88 | I37: =SUM(I33:I36) -> 80.24 | ... K37: =SUM(K33:K36) -> 79.88
A40: PLANTA COMERCIAL — Sustitutos ABC cilindros vacíos: alta anual (sobrestock_sustitutos, paso 4) | B40: 2026 | C40: 2027 | D40: 2028 | E40: 2029 | F40: 2030 | G40: 2031 | H40: 2032 | I40: 2033 | J40: 2034 | K40: 2035
A41: ABC 1 kg | B41: =IFERROR(Links!B34,0) -> 0 | C41: =IFERROR(Links!C34,0) -> 0 | D41: =IFERROR(Links!D34,0) -> 0 | E41: =IFERROR(Links!E34,0) -> 0 | F41: =IFERROR(Links!F34,0) -> 0 | G41: =IFERROR(Links!G34,0) -> 0 | H41: =IFERROR(Links!H34,0) -> 0 | I41: =IFERROR(Links!I34,0) -> 0 | ... K41: =IFERROR(Links!K34,0) -> 0
A42: ABC 2,5 kg | B42: =IFERROR(Links!B35,0) -> 3 | C42: =IFERROR(Links!C35,0) -> 9.24 | D42: =IFERROR(Links!D35,0) -> 15.96 | E42: =IFERROR(Links!E35,0) -> 24.16 | F42: =IFERROR(Links!F35,0) -> 25.92 | G42: =IFERROR(Links!G35,0) -> 28.68 | H42: =IFERROR(Links!H35,0) -> 26.52 | I42: =IFERROR(Links!I35,0) -> 21.04 | ... K42: =IFERROR(Links!K35,0) -> 20.88
A43: ABC 5 kg | B43: =IFERROR(Links!B36,0) -> 17 | C43: =IFERROR(Links!C36,0) -> 53.36 | D43: =IFERROR(Links!D36,0) -> 91.52 | E43: =IFERROR(Links!E36,0) -> 150.4 | F43: =IFERROR(Links!F36,0) -> 152.44 | G43: =IFERROR(Links!G36,0) -> 171.76 | H43: =IFERROR(Links!H36,0) -> 150.8 | I43: =IFERROR(Links!I36,0) -> 125.28 | ... K43: =IFERROR(Links!K36,0) -> 122.68
A44: ABC 10 kg | B44: =IFERROR(Links!B37,0) -> 2 | C44: =IFERROR(Links!C37,0) -> 3.16 | D44: =IFERROR(Links!D37,0) -> 5.4 | E44: =IFERROR(Links!E37,0) -> 9.8 | F44: =IFERROR(Links!F37,0) -> 9.52 | G44: =IFERROR(Links!G37,0) -> 11.16 | H44: =IFERROR(Links!H37,0) -> 8.88 | I44: =IFERROR(Links!I37,0) -> 7.36 | ... K44: =IFERROR(Links!K37,0) -> 7
A45: Total sustitutos planta comercial | B45: =SUM(B41:B44) -> 22 | C45: =SUM(C41:C44) -> 65.76 | D45: =SUM(D41:D44) -> 112.88 | E45: =SUM(E41:E44) -> 184.36 | F45: =SUM(F41:F44) -> 187.88 | G45: =SUM(G41:G44) -> 211.6 | H45: =SUM(H41:H44) -> 186.2 | I45: =SUM(I41:I44) -> 153.68 | ... K45: =SUM(K41:K44) -> 150.56
A47: A la línea de manuales entran solo los ABC de 1 a 10 kg; los demás tipos se compran.

Sheet parametros_manuales
A1: Parámetro | B1: Valor | C1: Nota
A2: Días hábiles por mes | B2: 20 | C2: Excel original, Parametros B37
A3: Horas por día (1 turno) | B3: 8 | C3: Excel original, Parametros D37
A4: Refrigerio (min/turno) | B4: 30 | C4: Excel original, Parametros H37
A5: Horas productivas por turno | B5: =B3-B4/60 -> 7.5 | C5: Horas/día − refrigerio
A6: Turnos por día | B6: 1 | C6: Un solo turno (editable)
A7: Horas productivas por mes | B7: =B2*B5*B6 -> 150 | C7: Días × horas productivas × turnos
A8: Umbral de aprovechamiento | B8: 0.9 | C8: Límite duro (análisis de riesgos) · Word de recargas § 8
A9: Año de inicio del 2° turno (antes: más máquinas) | B9: 2032 | C9: Todos los turnos entran ese año · Word de recargas § 8
A10: ESTACIONALIDAD (% de la demanda anual por mes; MRP, hoja Links)
A11: Modelo | B11: Ene | C11: Feb | D11: Mar | E11: Abr | F11: May | G11: Jun | H11: Jul | I11: Ago | J11: Sep | K11: Oct | L11: Nov | M11: Dic | N11: Total
A12: 1 kg | B12: =Links!B41 -> 0.12 | C12: =Links!C41 -> 0.09 | D12: =Links!D41 -> 0.08 | E12: =Links!E41 -> 0.075 | F12: =Links!F41 -> 0.07 | G12: =Links!G41 -> 0.07 | H12: =Links!H41 -> 0.075 | I12: =Links!I41 -> 0.075 | ... M12: =Links!M41 -> 0.12 | N12: =SUM(B12:M12) -> 1 | O12: MRP, ESTACIONALIDAD E01 automotor (1 kg) (hoja Links)
A13: 2,5 kg | B13: =Links!B45 -> 0.1 | C13: =Links!C45 -> 0.08 | D13: =Links!D45 -> 0.085 | E13: =Links!E45 -> 0.085 | F13: =Links!F45 -> 0.08 | G13: =Links!G45 -> 0.075 | H13: =Links!H45 -> 0.08 | I13: =Links!I45 -> 0.08 | ... M13: =Links!M45 -> 0.11 | N13: =SUM(B13:M13) -> 1 | O13: MRP, ESTACIONALIDAD E02 manual comercial (2,5 a 10 kg) (hoja Links)
A14: 5 kg | B14: =Links!B45 -> 0.1 | C14: =Links!C45 -> 0.08 | D14: =Links!D45 -> 0.085 | E14: =Links!E45 -> 0.085 | F14: =Links!F45 -> 0.08 | G14: =Links!G45 -> 0.075 | H14: =Links!H45 -> 0.08 | I14: =Links!I45 -> 0.08 | ... M14: =Links!M45 -> 0.11 | N14: =SUM(B14:M14) -> 1 | O14: MRP, ESTACIONALIDAD E02 manual comercial (2,5 a 10 kg) (hoja Links)
A15: 10 kg | B15: =Links!B45 -> 0.1 | C15: =Links!C45 -> 0.08 | D15: =Links!D45 -> 0.085 | E15: =Links!E45 -> 0.085 | F15: =Links!F45 -> 0.08 | G15: =Links!G45 -> 0.075 | H15: =Links!H45 -> 0.08 | I15: =Links!I45 -> 0.08 | ... M15: =Links!M45 -> 0.11 | N15: =SUM(B15:M15) -> 1 | O15: MRP, ESTACIONALIDAD E02 manual comercial (2,5 a 10 kg) (hoja Links)
A17: CAPACIDAD POR PUESTO
A18: N° | B18: Puesto | C18: Máquina | D18: 1 kg | E18: 2,5 kg | F18: 5 kg | G18: 10 kg | H18: Alcance | I18: Piezas por unidad | J18: % que pasa | K18: Tiempo tipo (s/u) | L18: Disponibilidad | M18: Cap. real (u/h) | N18: Cap. real (u/mes) | O18: SUPOSICIONES
A19: 1 | B19: Recepción de materia prima | C19: Autoelevador Heli CPCD50 + micrómetro | D19: 1 | E19: 1 | F19: 1 | G19: 1 | H19: Todos | I19: 1 | J19: 1 | K19: 60 | L19: =F52 -> 1 | M19: =IF(K19>0,3600/K19*L19,0) -> 60 | N19: =M19*$B$7 -> 9000 | O19: 25 min x pallet de 20 hojas en carros (1,25 min x hoja)
A20: 2 | B20: Corte de chapa — 1.er corte en franjas (guillotina 1, manuales + carros) | C20: Guillotina hidráulica Ermaksan CNC HGS 2600-6 (tope 1.000 mm), compartida con carros | D20: 1 | E20: 1 | F20: 1 | G20: 1 | H20: Todos | I20: 1 | J20: 1 | K20: =$H$128 -> 6.5815524 | L20: =F53 -> 0.97422222 | M20: =IF(K20>0,3600/K20*L20,0) -> 532.88339 | N20: =M20*$B$7 -> 79932.509 | O20: (Golpes G1 × min por corte + parte de la manipulación por hoja) ÷ piezas; promedio ponderado (fila 128). La carga de carros se suma en Demanda puesto (filas 148 a 157)
A21: 3 | B21: Corte de chapa — 2.º corte en piezas (guillotina 2, manuales + carros) | C21: Guillotina hidráulica QC12Y 6 × 2500 (tope 800 mm), compartida con carros | D21: 1 | E21: 1 | F21: 1 | G21: 1 | H21: Todos | I21: 1 | J21: 1 | K21: =$I$128 -> 4.8793839 | L21: =F54 -> 0.99333333 | M21: =IF(K21>0,3600/K21*L21,0) -> 732.87941 | N21: =M21*$B$7 -> 109931.91 | O21: (Golpes G2 × min por corte + resto de la manipulación) ÷ piezas; promedio ponderado (fila 128). La carga de carros se suma en Demanda puesto (filas 160 a 169)
A22: 4 | B22: Corte de disco y embutido (cúpula y fondo) | C22: Prensa embutidora Sangiacomo + alimentador Cena PRE-1 | D22: 1 | E22: 1 | F22: 1 | G22: 1 | H22: Todos | I22: 2 | J22: 1 | K22: 8 | L22: =F55 -> 0.68 | M22: =IF(K22>0,3600/K22*L22,0) -> 306 | N22: =M22*$B$7 -> 45900 | O22: Son 10c segundos contemplando cupula y fondo
A23: 5 | B23: Preparación de cuello | C23: Prensa de banco Pannier MarkFirst MB-21 | D23: 1 | E23: 1 | F23: 1 | G23: 1 | H23: Todos | I23: 1 | J23: 1 | K23: 60 | L23: =F56 -> 1 | M23: =IF(K23>0,3600/K23*L23,0) -> 60 | N23: =M23*$B$7 -> 9000
A24: 6 | B24: Numerado de cúpula | C24: Micropercusión Pannier ADP120160D Deep Marker | D24: 1 | E24: 1 | F24: 1 | G24: 1 | H24: Todos | I24: 1 | J24: 1 | K24: 20 | L24: =F57 -> 1 | M24: =IF(K24>0,3600/K24*L24,0) -> 180 | N24: =M24*$B$7 -> 27000
A25: 7 | B25: Soldadura del cuello a la cúpula | C25: Firesafer FS-HFM1 (versión manual) | D25: 1 | E25: 1 | F25: 1 | G25: 1 | H25: Todos | I25: 1 | J25: 1 | K25: 25 | L25: =F58 -> 0.97333333 | M25: =IF(K25>0,3600/K25*L25,0) -> 140.16 | N25: =M25*$B$7 -> 21024
A26: 8 | B26: Cilindrado | C26: Cilindradora Firesafer × 2 (cotización FS202609FFCLM01, ítem 8), moldes de 1 a 10 kg | D26: 1 | E26: 1 | F26: 1 | G26: 1 | H26: Todos | I26: 1 | J26: 1 | K26: 15 | L26: =F59 -> 0.98666667 | M26: =IF(K26>0,3600/K26*L26,0) -> 236.8 | N26: =M26*$B$7 -> 35520 | O26: Cotización Firesafer: 4 a 10 piezas/min; se toma 4 (15 s). Son 2 máquinas (ítem 8 × 2, CNY 58.500 c/u) más moldes de CNY 8.000 por tamaño; en los resúmenes queda 1 máquina
A27: 9 | B27: Soldadura longitudinal — 2,5 a 10 kg | C27: Soldadora longitudinal Firesafer | D27: 0 | E27: 1 | F27: 1 | G27: 1 | H27: Todos | I27: 1 | J27: 1 | K27: 115 | L27: =F60 -> 0.98666667 | M27: =IF(K27>0,3600/K27*L27,0) -> 30.886957 | N27: =M27*$B$7 -> 4633.0435
A28: 10 | B28: Soldadura longitudinal TIG — 1 kg | C28: Soldadora longitudinal Firesafer + fuente TIG (cotización FS202609FFCLM01, ítems 13 y 14) | D28: 1 | E28: 0 | F28: 0 | G28: 0 | H28: Todos | I28: 1 | J28: 1 | K28: 30 | L28: =F61 -> 1 | M28: =IF(K28>0,3600/K28*L28,0) -> 120 | N28: =M28*$B$7 -> 18000 | O28: Cotización Firesafer: 2 a 4 piezas/min; se toma 2 (30 s). Puesto exclusivo del 1 kg (Ø76,2 × 0,90 × 263,5 mm), CNY 58.500 + CNY 11.000 de la fuente TIG
A29: 11 | B29: Encastre de fondo | C29: Prensa hidráulica motorizada Del Fabro 30 t | D29: 1 | E29: 1 | F29: 1 | G29: 1 | H29: Todos | I29: 1 | J29: 1 | K29: 30 | L29: =F62 -> 0.98222222 | M29: =IF(K29>0,3600/K29*L29,0) -> 117.86667 | N29: =M29*$B$7 -> 17680
A30: 12 | B30: Bordoneado | C30: Bordoneadora motorizada Pilman SWM-400 | D30: 1 | E30: 1 | F30: 1 | G30: 1 | H30: Todos | I30: 1 | J30: 1 | K30: 20 | L30: =F63 -> 0.98222222 | M30: =IF(K30>0,3600/K30*L30,0) -> 176.8 | N30: =M30*$B$7 -> 26520
A31: 13 | B31: Soldadura circunferencial de cúpula y fondo | C31: Soldadora circunferencial Firesafer | D31: 1 | E31: 1 | F31: 1 | G31: 1 | H31: Todos | I31: 1 | J31: 1 | K31: 60 | L31: =F64 -> 0.98222222 | M31: =IF(K31>0,3600/K31*L31,0) -> 58.933333 | N31: =M31*$B$7 -> 8840
A32: 14 | B32: Control de calidad — Espesor | C32: Medidor de espesores Melisam MR017 | D32: 1 | E32: 1 | F32: 1 | G32: 1 | H32: Todos | I32: 1 | J32: 0.02 | K32: 120 | L32: =F65 -> 1 | M32: =IF(K32>0,3600/K32*L32,0) -> 30 | N32: =M32*$B$7 -> 4500
A33: 15 | B33: Prueba hidráulica | C33: Banco Firesafer FS-JD12A | D33: 1 | E33: 1 | F33: 1 | G33: 1 | H33: Todos | I33: 1 | J33: 1 | K33: 60 | L33: =F66 -> 0.98222222 | M33: =IF(K33>0,3600/K33*L33,0) -> 58.933333 | N33: =M33*$B$7 -> 8840
A34: 16 | B34: Secado | C34: Secadora de cilindros Yukon | D34: 1 | E34: 1 | F34: 1 | G34: 1 | H34: Todos | I34: 1 | J34: 1 | K34: 120 | L34: =F67 -> 1 | M34: =IF(K34>0,3600/K34*L34,0) -> 30 | N34: =M34*$B$7 -> 4500 | O34: las 4 maquinas sirven para secado de carros
A35: 17 | B35: Granallado | C35: Granalladora de rodillos AirBlast G-100 | D35: 1 | E35: 1 | F35: 1 | G35: 1 | H35: Todos | I35: 1 | J35: 1 | K35: 30 | L35: =F68 -> 1 | M35: =IF(K35>0,3600/K35*L35,0) -> 120 | N35: =M35*$B$7 -> 18000
A36: 18 | B36: Detección de defectos | C36: Mesa de inspección con iluminación | D36: 1 | E36: 1 | F36: 1 | G36: 1 | H36: Todos | I36: 1 | J36: 1 | K36: 20 | L36: =F69 -> 1 | M36: =IF(K36>0,3600/K36*L36,0) -> 180 | N36: =M36*$B$7 -> 27000
A37: 19 | B37: Corrección de defectos | C37: Amoladora 115 mm + machos y calibres | D37: 1 | E37: 1 | F37: 1 | G37: 1 | H37: Todos | I37: 1 | J37: 0.05 | K37: 180 | L37: =F70 -> 1 | M37: =IF(K37>0,3600/K37*L37,0) -> 20 | N37: =M37*$B$7 -> 3000
A38: 20 | B38: Pintura en polvo + horno | C38: Línea de pintura en polvo Firesafer | D38: 1 | E38: 1 | F38: 1 | G38: 1 | H38: Todos | I38: 1 | J38: 1 | K38: 25 | L38: =F71 -> 0.94666667 | M38: =IF(K38>0,3600/K38*L38,0) -> 136.32 | N38: =M38*$B$7 -> 20448
A39: 21 | B39: Carga de polvo | C39: Cargadora Firesafer FS-A10 / Yukon M-000121 | D39: 1 | E39: 1 | F39: 1 | G39: 1 | H39: Terminados | I39: 1 | J39: 1 | K39: 45 | L39: =F72 -> 1 | M39: =IF(K39>0,3600/K39*L39,0) -> 80 | N39: =M39*$B$7 -> 12000
A40: 22 | B40: Ensamblaje | C40: Puesto manual con llave dinamométrica | D40: 1 | E40: 1 | F40: 1 | G40: 1 | H40: Terminados | I40: 1 | J40: 1 | K40: 100 | L40: =F73 -> 0.98222222 | M40: =IF(K40>0,3600/K40*L40,0) -> 35.36 | N40: =M40*$B$7 -> 5304
A41: 23 | B41: Presurización | C41: Pinza neumática Yukon M-000150 + pack N₂ | D41: 1 | E41: 1 | F41: 1 | G41: 1 | H41: Terminados | I41: 1 | J41: 1 | K41: 30 | L41: =F74 -> 1 | M41: =IF(K41>0,3600/K41*L41,0) -> 120 | N41: =M41*$B$7 -> 18000
...

Sheet Plan mensual
A1: 2026 | B1: Producto | C1: Tipo | D1: Ene | E1: Feb | F1: Mar | G1: Abr | H1: May | I1: Jun | J1: Jul | K1: Ago | L1: Sep | M1: Oct | N1: Nov | O1: Dic | P1: Total anual
A2: 2026 | B2: ABC 1 kg | C2: Terminado | D2: =datos_base!$B$2*parametros_manuales!B$12 -> 501.44839 | E2: =datos_base!$B$2*parametros_manuales!C$12 -> 376.08629 | F2: =datos_base!$B$2*parametros_manuales!D$12 -> 334.29892 | G2: =datos_base!$B$2*parametros_manuales!E$12 -> 313.40524 | H2: =datos_base!$B$2*parametros_manuales!F$12 -> 292.51156 | I2: =datos_base!$B$2*parametros_manuales!G$12 -> 292.51156 | J2: =datos_base!$B$2*parametros_manuales!H$12 -> 313.40524 | K2: =datos_base!$B$2*parametros_manuales!I$12 -> 313.40524 | ... O2: =datos_base!$B$2*parametros_manuales!M$12 -> 501.44839 | P2: =SUM(D2:O2) -> 4178.7365
A3: 2026 | B3: ABC 2,5 kg | C3: Terminado | D3: =datos_base!$B$3*parametros_manuales!B$13 -> 29.703036 | E3: =datos_base!$B$3*parametros_manuales!C$13 -> 23.762429 | F3: =datos_base!$B$3*parametros_manuales!D$13 -> 25.24758 | G3: =datos_base!$B$3*parametros_manuales!E$13 -> 25.24758 | H3: =datos_base!$B$3*parametros_manuales!F$13 -> 23.762429 | I3: =datos_base!$B$3*parametros_manuales!G$13 -> 22.277277 | J3: =datos_base!$B$3*parametros_manuales!H$13 -> 23.762429 | K3: =datos_base!$B$3*parametros_manuales!I$13 -> 23.762429 | ... O3: =datos_base!$B$3*parametros_manuales!M$13 -> 32.673339 | P3: =SUM(D3:O3) -> 297.03036
A4: 2026 | B4: ABC 5 kg | C4: Terminado | D4: =datos_base!$B$4*parametros_manuales!B$14 -> 226.4773 | E4: =datos_base!$B$4*parametros_manuales!C$14 -> 181.18184 | F4: =datos_base!$B$4*parametros_manuales!D$14 -> 192.50571 | G4: =datos_base!$B$4*parametros_manuales!E$14 -> 192.50571 | H4: =datos_base!$B$4*parametros_manuales!F$14 -> 181.18184 | I4: =datos_base!$B$4*parametros_manuales!G$14 -> 169.85798 | J4: =datos_base!$B$4*parametros_manuales!H$14 -> 181.18184 | K4: =datos_base!$B$4*parametros_manuales!I$14 -> 181.18184 | ... O4: =datos_base!$B$4*parametros_manuales!M$14 -> 249.12503 | P4: =SUM(D4:O4) -> 2264.773
A5: 2026 | B5: ABC 10 kg | C5: Terminado | D5: =datos_base!$B$5*parametros_manuales!B$15 -> 9.2833182 | E5: =datos_base!$B$5*parametros_manuales!C$15 -> 7.4266545 | F5: =datos_base!$B$5*parametros_manuales!D$15 -> 7.8908204 | G5: =datos_base!$B$5*parametros_manuales!E$15 -> 7.8908204 | H5: =datos_base!$B$5*parametros_manuales!F$15 -> 7.4266545 | I5: =datos_base!$B$5*parametros_manuales!G$15 -> 6.9624886 | J5: =datos_base!$B$5*parametros_manuales!H$15 -> 7.4266545 | K5: =datos_base!$B$5*parametros_manuales!I$15 -> 7.4266545 | ... O5: =datos_base!$B$5*parametros_manuales!M$15 -> 10.21165 | P5: =SUM(D5:O5) -> 92.833182
A6: 2026 | B6: Cilindros ABC 1 kg | C6: Cilindro | D6: =datos_base!$B$9*parametros_manuales!B$12 -> 0 | E6: =datos_base!$B$9*parametros_manuales!C$12 -> 0 | F6: =datos_base!$B$9*parametros_manuales!D$12 -> 0 | G6: =datos_base!$B$9*parametros_manuales!E$12 -> 0 | H6: =datos_base!$B$9*parametros_manuales!F$12 -> 0 | I6: =datos_base!$B$9*parametros_manuales!G$12 -> 0 | J6: =datos_base!$B$9*parametros_manuales!H$12 -> 0 | K6: =datos_base!$B$9*parametros_manuales!I$12 -> 0 | ... O6: =datos_base!$B$9*parametros_manuales!M$12 -> 0 | P6: =SUM(D6:O6) -> 0
A7: 2026 | B7: Cilindros ABC 2,5 kg | C7: Cilindro | D7: =datos_base!$B$10*parametros_manuales!B$13 -> 0.3 | E7: =datos_base!$B$10*parametros_manuales!C$13 -> 0.24 | F7: =datos_base!$B$10*parametros_manuales!D$13 -> 0.255 | G7: =datos_base!$B$10*parametros_manuales!E$13 -> 0.255 | H7: =datos_base!$B$10*parametros_manuales!F$13 -> 0.24 | I7: =datos_base!$B$10*parametros_manuales!G$13 -> 0.225 | J7: =datos_base!$B$10*parametros_manuales!H$13 -> 0.24 | K7: =datos_base!$B$10*parametros_manuales!I$13 -> 0.24 | ... O7: =datos_base!$B$10*parametros_manuales!M$13 -> 0.33 | P7: =SUM(D7:O7) -> 3
A8: 2026 | B8: Cilindros ABC 5 kg | C8: Cilindro | D8: =datos_base!$B$11*parametros_manuales!B$14 -> 1.7 | E8: =datos_base!$B$11*parametros_manuales!C$14 -> 1.36 | F8: =datos_base!$B$11*parametros_manuales!D$14 -> 1.445 | G8: =datos_base!$B$11*parametros_manuales!E$14 -> 1.445 | H8: =datos_base!$B$11*parametros_manuales!F$14 -> 1.36 | I8: =datos_base!$B$11*parametros_manuales!G$14 -> 1.275 | J8: =datos_base!$B$11*parametros_manuales!H$14 -> 1.36 | K8: =datos_base!$B$11*parametros_manuales!I$14 -> 1.36 | ... O8: =datos_base!$B$11*parametros_manuales!M$14 -> 1.87 | P8: =SUM(D8:O8) -> 17
A9: 2026 | B9: Cilindros ABC 10 kg | C9: Cilindro | D9: =datos_base!$B$12*parametros_manuales!B$15 -> 0.2 | E9: =datos_base!$B$12*parametros_manuales!C$15 -> 0.16 | F9: =datos_base!$B$12*parametros_manuales!D$15 -> 0.17 | G9: =datos_base!$B$12*parametros_manuales!E$15 -> 0.17 | H9: =datos_base!$B$12*parametros_manuales!F$15 -> 0.16 | I9: =datos_base!$B$12*parametros_manuales!G$15 -> 0.15 | J9: =datos_base!$B$12*parametros_manuales!H$15 -> 0.16 | K9: =datos_base!$B$12*parametros_manuales!I$15 -> 0.16 | ... O9: =datos_base!$B$12*parametros_manuales!M$15 -> 0.22 | P9: =SUM(D9:O9) -> 2
B10: Total recipientes | D10: =SUM(D2:D9) -> 769.11204 | E10: =SUM(E2:E9) -> 590.21721 | F10: =SUM(F2:F9) -> 561.81303 | G10: =SUM(G2:G9) -> 540.91935 | H10: =SUM(H2:H9) -> 506.64248 | I10: =SUM(I2:I9) -> 493.2593 | J10: =SUM(J2:J9) -> 527.53617 | K10: =SUM(K2:K9) -> 527.53617 | ... P10: =SUM(P2:P9) -> 6855.3731
A12: 2027 | B12: Producto | C12: Tipo | D12: Ene | E12: Feb | F12: Mar | G12: Abr | H12: May | I12: Jun | J12: Jul | K12: Ago | L12: Sep | M12: Oct | N12: Nov | O12: Dic | P12: Total anual
A13: 2027 | B13: ABC 1 kg | C13: Terminado | D13: =datos_base!$C$2*parametros_manuales!B$12 -> 719.67648 | E13: =datos_base!$C$2*parametros_manuales!C$12 -> 539.75736 | F13: =datos_base!$C$2*parametros_manuales!D$12 -> 479.78432 | G13: =datos_base!$C$2*parametros_manuales!E$12 -> 449.7978 | H13: =datos_base!$C$2*parametros_manuales!F$12 -> 419.81128 | I13: =datos_base!$C$2*parametros_manuales!G$12 -> 419.81128 | J13: =datos_base!$C$2*parametros_manuales!H$12 -> 449.7978 | K13: =datos_base!$C$2*parametros_manuales!I$12 -> 449.7978 | ... O13: =datos_base!$C$2*parametros_manuales!M$12 -> 719.67648 | P13: =SUM(D13:O13) -> 5997.304
A14: 2027 | B14: ABC 2,5 kg | C14: Terminado | D14: =datos_base!$C$3*parametros_manuales!B$13 -> 71.488745 | E14: =datos_base!$C$3*parametros_manuales!C$13 -> 57.190996 | F14: =datos_base!$C$3*parametros_manuales!D$13 -> 60.765433 | G14: =datos_base!$C$3*parametros_manuales!E$13 -> 60.765433 | H14: =datos_base!$C$3*parametros_manuales!F$13 -> 57.190996 | I14: =datos_base!$C$3*parametros_manuales!G$13 -> 53.616559 | J14: =datos_base!$C$3*parametros_manuales!H$13 -> 57.190996 | K14: =datos_base!$C$3*parametros_manuales!I$13 -> 57.190996 | ... O14: =datos_base!$C$3*parametros_manuales!M$13 -> 78.63762 | P14: =SUM(D14:O14) -> 714.88745
A15: 2027 | B15: ABC 5 kg | C15: Terminado | D15: =datos_base!$C$4*parametros_manuales!B$14 -> 387.46989 | E15: =datos_base!$C$4*parametros_manuales!C$14 -> 309.97591 | F15: =datos_base!$C$4*parametros_manuales!D$14 -> 329.3494 | G15: =datos_base!$C$4*parametros_manuales!E$14 -> 329.3494 | H15: =datos_base!$C$4*parametros_manuales!F$14 -> 309.97591 | I15: =datos_base!$C$4*parametros_manuales!G$14 -> 290.60242 | J15: =datos_base!$C$4*parametros_manuales!H$14 -> 309.97591 | K15: =datos_base!$C$4*parametros_manuales!I$14 -> 309.97591 | ... O15: =datos_base!$C$4*parametros_manuales!M$14 -> 426.21688 | P15: =SUM(D15:O15) -> 3874.6989
A16: 2027 | B16: ABC 10 kg | C16: Terminado | D16: =datos_base!$C$5*parametros_manuales!B$15 -> 17.93273 | E16: =datos_base!$C$5*parametros_manuales!C$15 -> 14.346184 | F16: =datos_base!$C$5*parametros_manuales!D$15 -> 15.24282 | G16: =datos_base!$C$5*parametros_manuales!E$15 -> 15.24282 | H16: =datos_base!$C$5*parametros_manuales!F$15 -> 14.346184 | I16: =datos_base!$C$5*parametros_manuales!G$15 -> 13.449547 | J16: =datos_base!$C$5*parametros_manuales!H$15 -> 14.346184 | K16: =datos_base!$C$5*parametros_manuales!I$15 -> 14.346184 | ... O16: =datos_base!$C$5*parametros_manuales!M$15 -> 19.726003 | P16: =SUM(D16:O16) -> 179.3273
A17: 2027 | B17: Cilindros ABC 1 kg | C17: Cilindro | D17: =datos_base!$C$9*parametros_manuales!B$12 -> 0 | E17: =datos_base!$C$9*parametros_manuales!C$12 -> 0 | F17: =datos_base!$C$9*parametros_manuales!D$12 -> 0 | G17: =datos_base!$C$9*parametros_manuales!E$12 -> 0 | H17: =datos_base!$C$9*parametros_manuales!F$12 -> 0 | I17: =datos_base!$C$9*parametros_manuales!G$12 -> 0 | J17: =datos_base!$C$9*parametros_manuales!H$12 -> 0 | K17: =datos_base!$C$9*parametros_manuales!I$12 -> 0 | ... O17: =datos_base!$C$9*parametros_manuales!M$12 -> 0 | P17: =SUM(D17:O17) -> 0
A18: 2027 | B18: Cilindros ABC 2,5 kg | C18: Cilindro | D18: =datos_base!$C$10*parametros_manuales!B$13 -> 0.924 | E18: =datos_base!$C$10*parametros_manuales!C$13 -> 0.7392 | F18: =datos_base!$C$10*parametros_manuales!D$13 -> 0.7854 | G18: =datos_base!$C$10*parametros_manuales!E$13 -> 0.7854 | H18: =datos_base!$C$10*parametros_manuales!F$13 -> 0.7392 | I18: =datos_base!$C$10*parametros_manuales!G$13 -> 0.693 | J18: =datos_base!$C$10*parametros_manuales!H$13 -> 0.7392 | K18: =datos_base!$C$10*parametros_manuales!I$13 -> 0.7392 | ... O18: =datos_base!$C$10*parametros_manuales!M$13 -> 1.0164 | P18: =SUM(D18:O18) -> 9.24
A19: 2027 | B19: Cilindros ABC 5 kg | C19: Cilindro | D19: =datos_base!$C$11*parametros_manuales!B$14 -> 5.336 | E19: =datos_base!$C$11*parametros_manuales!C$14 -> 4.2688 | F19: =datos_base!$C$11*parametros_manuales!D$14 -> 4.5356 | G19: =datos_base!$C$11*parametros_manuales!E$14 -> 4.5356 | H19: =datos_base!$C$11*parametros_manuales!F$14 -> 4.2688 | I19: =datos_base!$C$11*parametros_manuales!G$14 -> 4.002 | J19: =datos_base!$C$11*parametros_manuales!H$14 -> 4.2688 | K19: =datos_base!$C$11*parametros_manuales!I$14 -> 4.2688 | ... O19: =datos_base!$C$11*parametros_manuales!M$14 -> 5.8696 | P19: =SUM(D19:O19) -> 53.36
A20: 2027 | B20: Cilindros ABC 10 kg | C20: Cilindro | D20: =datos_base!$C$12*parametros_manuales!B$15 -> 0.316 | E20: =datos_base!$C$12*parametros_manuales!C$15 -> 0.2528 | F20: =datos_base!$C$12*parametros_manuales!D$15 -> 0.2686 | G20: =datos_base!$C$12*parametros_manuales!E$15 -> 0.2686 | H20: =datos_base!$C$12*parametros_manuales!F$15 -> 0.2528 | I20: =datos_base!$C$12*parametros_manuales!G$15 -> 0.237 | J20: =datos_base!$C$12*parametros_manuales!H$15 -> 0.2528 | K20: =datos_base!$C$12*parametros_manuales!I$15 -> 0.2528 | ... O20: =datos_base!$C$12*parametros_manuales!M$15 -> 0.3476 | P20: =SUM(D20:O20) -> 3.16
B21: Total recipientes | D21: =SUM(D13:D20) -> 1203.1438 | E21: =SUM(E13:E20) -> 926.53125 | F21: =SUM(F13:F20) -> 890.73158 | G21: =SUM(G13:G20) -> 860.74506 | H21: =SUM(H13:H20) -> 806.58517 | I21: =SUM(I13:I20) -> 782.4118 | J21: =SUM(J13:J20) -> 836.57169 | K21: =SUM(K13:K20) -> 836.57169 | ... P21: =SUM(P13:P20) -> 10831.978
A23: 2028 | B23: Producto | C23: Tipo | D23: Ene | E23: Feb | F23: Mar | G23: Abr | H23: May | I23: Jun | J23: Jul | K23: Ago | L23: Sep | M23: Oct | N23: Nov | O23: Dic | P23: Total anual
A24: 2028 | B24: ABC 1 kg | C24: Terminado | D24: =datos_base!$D$2*parametros_manuales!B$12 -> 822.20973 | E24: =datos_base!$D$2*parametros_manuales!C$12 -> 616.6573 | F24: =datos_base!$D$2*parametros_manuales!D$12 -> 548.13982 | G24: =datos_base!$D$2*parametros_manuales!E$12 -> 513.88108 | H24: =datos_base!$D$2*parametros_manuales!F$12 -> 479.62234 | I24: =datos_base!$D$2*parametros_manuales!G$12 -> 479.62234 | J24: =datos_base!$D$2*parametros_manuales!H$12 -> 513.88108 | K24: =datos_base!$D$2*parametros_manuales!I$12 -> 513.88108 | ... O24: =datos_base!$D$2*parametros_manuales!M$12 -> 822.20973 | P24: =SUM(D24:O24) -> 6851.7478
A25: 2028 | B25: ABC 2,5 kg | C25: Terminado | D25: =datos_base!$D$3*parametros_manuales!B$13 -> 99.442806 | E25: =datos_base!$D$3*parametros_manuales!C$13 -> 79.554245 | F25: =datos_base!$D$3*parametros_manuales!D$13 -> 84.526385 | G25: =datos_base!$D$3*parametros_manuales!E$13 -> 84.526385 | H25: =datos_base!$D$3*parametros_manuales!F$13 -> 79.554245 | I25: =datos_base!$D$3*parametros_manuales!G$13 -> 74.582104 | J25: =datos_base!$D$3*parametros_manuales!H$13 -> 79.554245 | K25: =datos_base!$D$3*parametros_manuales!I$13 -> 79.554245 | ... O25: =datos_base!$D$3*parametros_manuales!M$13 -> 109.38709 | P25: =SUM(D25:O25) -> 994.42806
A26: 2028 | B26: ABC 5 kg | C26: Terminado | D26: =datos_base!$D$4*parametros_manuales!B$14 -> 514.14176 | E26: =datos_base!$D$4*parametros_manuales!C$14 -> 411.31341 | F26: =datos_base!$D$4*parametros_manuales!D$14 -> 437.0205 | G26: =datos_base!$D$4*parametros_manuales!E$14 -> 437.0205 | H26: =datos_base!$D$4*parametros_manuales!F$14 -> 411.31341 | I26: =datos_base!$D$4*parametros_manuales!G$14 -> 385.60632 | J26: =datos_base!$D$4*parametros_manuales!H$14 -> 411.31341 | K26: =datos_base!$D$4*parametros_manuales!I$14 -> 411.31341 | ... O26: =datos_base!$D$4*parametros_manuales!M$14 -> 565.55594 | P26: =SUM(D26:O26) -> 5141.4176
A27: 2028 | B27: ABC 10 kg | C27: Terminado | D27: =datos_base!$D$5*parametros_manuales!B$15 -> 25.621878 | E27: =datos_base!$D$5*parametros_manuales!C$15 -> 20.497502 | F27: =datos_base!$D$5*parametros_manuales!D$15 -> 21.778596 | G27: =datos_base!$D$5*parametros_manuales!E$15 -> 21.778596 | H27: =datos_base!$D$5*parametros_manuales!F$15 -> 20.497502 | I27: =datos_base!$D$5*parametros_manuales!G$15 -> 19.216408 | J27: =datos_base!$D$5*parametros_manuales!H$15 -> 20.497502 | K27: =datos_base!$D$5*parametros_manuales!I$15 -> 20.497502 | ... O27: =datos_base!$D$5*parametros_manuales!M$15 -> 28.184066 | P27: =SUM(D27:O27) -> 256.21878
A28: 2028 | B28: Cilindros ABC 1 kg | C28: Cilindro | D28: =datos_base!$D$9*parametros_manuales!B$12 -> 919.488 | E28: =datos_base!$D$9*parametros_manuales!C$12 -> 689.616 | F28: =datos_base!$D$9*parametros_manuales!D$12 -> 612.992 | G28: =datos_base!$D$9*parametros_manuales!E$12 -> 574.68 | H28: =datos_base!$D$9*parametros_manuales!F$12 -> 536.368 | I28: =datos_base!$D$9*parametros_manuales!G$12 -> 536.368 | J28: =datos_base!$D$9*parametros_manuales!H$12 -> 574.68 | K28: =datos_base!$D$9*parametros_manuales!I$12 -> 574.68 | ... O28: =datos_base!$D$9*parametros_manuales!M$12 -> 919.488 | P28: =SUM(D28:O28) -> 7662.4
A29: 2028 | B29: Cilindros ABC 2,5 kg | C29: Cilindro | D29: =datos_base!$D$10*parametros_manuales!B$13 -> 31.556 | E29: =datos_base!$D$10*parametros_manuales!C$13 -> 25.2448 | F29: =datos_base!$D$10*parametros_manuales!D$13 -> 26.8226 | G29: =datos_base!$D$10*parametros_manuales!E$13 -> 26.8226 | H29: =datos_base!$D$10*parametros_manuales!F$13 -> 25.2448 | I29: =datos_base!$D$10*parametros_manuales!G$13 -> 23.667 | J29: =datos_base!$D$10*parametros_manuales!H$13 -> 25.2448 | K29: =datos_base!$D$10*parametros_manuales!I$13 -> 25.2448 | ... O29: =datos_base!$D$10*parametros_manuales!M$13 -> 34.7116 | P29: =SUM(D29:O29) -> 315.56
A30: 2028 | B30: Cilindros ABC 5 kg | C30: Cilindro | D30: =datos_base!$D$11*parametros_manuales!B$14 -> 157.032 | E30: =datos_base!$D$11*parametros_manuales!C$14 -> 125.6256 | F30: =datos_base!$D$11*parametros_manuales!D$14 -> 133.4772 | G30: =datos_base!$D$11*parametros_manuales!E$14 -> 133.4772 | H30: =datos_base!$D$11*parametros_manuales!F$14 -> 125.6256 | I30: =datos_base!$D$11*parametros_manuales!G$14 -> 117.774 | J30: =datos_base!$D$11*parametros_manuales!H$14 -> 125.6256 | K30: =datos_base!$D$11*parametros_manuales!I$14 -> 125.6256 | ... O30: =datos_base!$D$11*parametros_manuales!M$14 -> 172.7352 | P30: =SUM(D30:O30) -> 1570.32
A31: 2028 | B31: Cilindros ABC 10 kg | C31: Cilindro | D31: =datos_base!$D$12*parametros_manuales!B$15 -> 9.58 | E31: =datos_base!$D$12*parametros_manuales!C$15 -> 7.664 | F31: =datos_base!$D$12*parametros_manuales!D$15 -> 8.143 | G31: =datos_base!$D$12*parametros_manuales!E$15 -> 8.143 | H31: =datos_base!$D$12*parametros_manuales!F$15 -> 7.664 | I31: =datos_base!$D$12*parametros_manuales!G$15 -> 7.185 | J31: =datos_base!$D$12*parametros_manuales!H$15 -> 7.664 | K31: =datos_base!$D$12*parametros_manuales!I$15 -> 7.664 | ... O31: =datos_base!$D$12*parametros_manuales!M$15 -> 10.538 | P31: =SUM(D31:O31) -> 95.8
B32: Total recipientes | D32: =SUM(D24:D31) -> 2579.0722 | E32: =SUM(E24:E31) -> 1976.1729 | F32: =SUM(F24:F31) -> 1872.9001 | G32: =SUM(G24:G31) -> 1800.3294 | H32: =SUM(H24:H31) -> 1685.8899 | I32: =SUM(I24:I31) -> 1644.0212 | J32: =SUM(J24:J31) -> 1758.4606 | K32: =SUM(K24:K31) -> 1758.4606 | ... P32: =SUM(P24:P31) -> 22887.892
A34: 2029 | B34: Producto | C34: Tipo | D34: Ene | E34: Feb | F34: Mar | G34: Abr | H34: May | I34: Jun | J34: Jul | K34: Ago | L34: Sep | M34: Oct | N34: Nov | O34: Dic | P34: Total anual
A35: 2029 | B35: ABC 1 kg | C35: Terminado | D35: =datos_base!$E$2*parametros_manuales!B$12 -> 1016.0563 | E35: =datos_base!$E$2*parametros_manuales!C$12 -> 762.0422 | F35: =datos_base!$E$2*parametros_manuales!D$12 -> 677.37084 | G35: =datos_base!$E$2*parametros_manuales!E$12 -> 635.03517 | H35: =datos_base!$E$2*parametros_manuales!F$12 -> 592.69949 | I35: =datos_base!$E$2*parametros_manuales!G$12 -> 592.69949 | J35: =datos_base!$E$2*parametros_manuales!H$12 -> 635.03517 | K35: =datos_base!$E$2*parametros_manuales!I$12 -> 635.03517 | ... O35: =datos_base!$E$2*parametros_manuales!M$12 -> 1016.0563 | P35: =SUM(D35:O35) -> 8467.1355
A36: 2029 | B36: ABC 2,5 kg | C36: Terminado | D36: =datos_base!$E$3*parametros_manuales!B$13 -> 151.37582 | E36: =datos_base!$E$3*parametros_manuales!C$13 -> 121.10065 | F36: =datos_base!$E$3*parametros_manuales!D$13 -> 128.66944 | G36: =datos_base!$E$3*parametros_manuales!E$13 -> 128.66944 | H36: =datos_base!$E$3*parametros_manuales!F$13 -> 121.10065 | I36: =datos_base!$E$3*parametros_manuales!G$13 -> 113.53186 | J36: =datos_base!$E$3*parametros_manuales!H$13 -> 121.10065 | K36: =datos_base!$E$3*parametros_manuales!I$13 -> 121.10065 | ... O36: =datos_base!$E$3*parametros_manuales!M$13 -> 166.5134 | P36: =SUM(D36:O36) -> 1513.7582
A37: 2029 | B37: ABC 5 kg | C37: Terminado | D37: =datos_base!$E$4*parametros_manuales!B$14 -> 690.15953 | E37: =datos_base!$E$4*parametros_manuales!C$14 -> 552.12763 | F37: =datos_base!$E$4*parametros_manuales!D$14 -> 586.6356 | G37: =datos_base!$E$4*parametros_manuales!E$14 -> 586.6356 | H37: =datos_base!$E$4*parametros_manuales!F$14 -> 552.12763 | I37: =datos_base!$E$4*parametros_manuales!G$14 -> 517.61965 | J37: =datos_base!$E$4*parametros_manuales!H$14 -> 552.12763 | K37: =datos_base!$E$4*parametros_manuales!I$14 -> 552.12763 | ... O37: =datos_base!$E$4*parametros_manuales!M$14 -> 759.17548 | P37: =SUM(D37:O37) -> 6901.5953
A38: 2029 | B38: ABC 10 kg | C38: Terminado | D38: =datos_base!$E$5*parametros_manuales!B$15 -> 36.250049 | E38: =datos_base!$E$5*parametros_manuales!C$15 -> 29.00004 | F38: =datos_base!$E$5*parametros_manuales!D$15 -> 30.812542 | G38: =datos_base!$E$5*parametros_manuales!E$15 -> 30.812542 | H38: =datos_base!$E$5*parametros_manuales!F$15 -> 29.00004 | I38: =datos_base!$E$5*parametros_manuales!G$15 -> 27.187537 | J38: =datos_base!$E$5*parametros_manuales!H$15 -> 29.00004 | K38: =datos_base!$E$5*parametros_manuales!I$15 -> 29.00004 | ... O38: =datos_base!$E$5*parametros_manuales!M$15 -> 39.875054 | P38: =SUM(D38:O38) -> 362.50049
A39: 2029 | B39: Cilindros ABC 1 kg | C39: Cilindro | D39: =datos_base!$E$9*parametros_manuales!B$12 -> 3203.376 | E39: =datos_base!$E$9*parametros_manuales!C$12 -> 2402.532 | F39: =datos_base!$E$9*parametros_manuales!D$12 -> 2135.584 | G39: =datos_base!$E$9*parametros_manuales!E$12 -> 2002.11 | H39: =datos_base!$E$9*parametros_manuales!F$12 -> 1868.636 | I39: =datos_base!$E$9*parametros_manuales!G$12 -> 1868.636 | J39: =datos_base!$E$9*parametros_manuales!H$12 -> 2002.11 | K39: =datos_base!$E$9*parametros_manuales!I$12 -> 2002.11 | ... O39: =datos_base!$E$9*parametros_manuales!M$12 -> 3203.376 | P39: =SUM(D39:O39) -> 26694.8
A40: 2029 | B40: Cilindros ABC 2,5 kg | C40: Cilindro | D40: =datos_base!$E$10*parametros_manuales!B$13 -> 106.796 | E40: =datos_base!$E$10*parametros_manuales!C$13 -> 85.4368 | F40: =datos_base!$E$10*parametros_manuales!D$13 -> 90.7766 | G40: =datos_base!$E$10*parametros_manuales!E$13 -> 90.7766 | H40: =datos_base!$E$10*parametros_manuales!F$13 -> 85.4368 | I40: =datos_base!$E$10*parametros_manuales!G$13 -> 80.097 | J40: =datos_base!$E$10*parametros_manuales!H$13 -> 85.4368 | K40: =datos_base!$E$10*parametros_manuales!I$13 -> 85.4368 | ... O40: =datos_base!$E$10*parametros_manuales!M$13 -> 117.4756 | P40: =SUM(D40:O40) -> 1067.96
A41: 2029 | B41: Cilindros ABC 5 kg | C41: Cilindro | D41: =datos_base!$E$11*parametros_manuales!B$14 -> 530.24 | E41: =datos_base!$E$11*parametros_manuales!C$14 -> 424.192 | F41: =datos_base!$E$11*parametros_manuales!D$14 -> 450.704 | G41: =datos_base!$E$11*parametros_manuales!E$14 -> 450.704 | H41: =datos_base!$E$11*parametros_manuales!F$14 -> 424.192 | I41: =datos_base!$E$11*parametros_manuales!G$14 -> 397.68 | J41: =datos_base!$E$11*parametros_manuales!H$14 -> 424.192 | K41: =datos_base!$E$11*parametros_manuales!I$14 -> 424.192 | ... O41: =datos_base!$E$11*parametros_manuales!M$14 -> 583.264 | P41: =SUM(D41:O41) -> 5302.4
A42: 2029 | B42: Cilindros ABC 10 kg | C42: Cilindro | D42: =datos_base!$E$12*parametros_manuales!B$15 -> 32.48 | E42: =datos_base!$E$12*parametros_manuales!C$15 -> 25.984 | F42: =datos_base!$E$12*parametros_manuales!D$15 -> 27.608 | G42: =datos_base!$E$12*parametros_manuales!E$15 -> 27.608 | H42: =datos_base!$E$12*parametros_manuales!F$15 -> 25.984 | I42: =datos_base!$E$12*parametros_manuales!G$15 -> 24.36 | J42: =datos_base!$E$12*parametros_manuales!H$15 -> 25.984 | K42: =datos_base!$E$12*parametros_manuales!I$15 -> 25.984 | ... O42: =datos_base!$E$12*parametros_manuales!M$15 -> 35.728 | P42: =SUM(D42:O42) -> 324.8
B43: Total recipientes | D43: =SUM(D35:D42) -> 5766.7337 | E43: =SUM(E35:E42) -> 4402.4153 | F43: =SUM(F35:F42) -> 4128.161 | G43: =SUM(G35:G42) -> 3952.3514 | H43: =SUM(H35:H42) -> 3699.1766 | I43: =SUM(I35:I42) -> 3621.8115 | J43: =SUM(J35:J42) -> 3874.9863 | K43: =SUM(K35:K42) -> 3874.9863 | ... P43: =SUM(P35:P42) -> 50634.95
...

Sheet Demanda puesto sin sobrestock
A1: Año 2026 | B1: Ene | C1: Feb | D1: Mar | E1: Abr | F1: May | G1: Jun | H1: Jul | I1: Ago | J1: Sep | K1: Oct | L1: Nov | M1: Dic | N1: Total anual | O1: Mes pico (u/mes) | P1: Demanda pico (u/h) | Q1: Mes pico
A2: =parametros_manuales!$B$19 -> Recepción de materia prima | B2: =(parametros_manuales!$D$19*('Plan mensual'!D2+IF(parametros_manuales!$H$19="Todos",'Plan mensual'!D6,0))+parametros_manuales!$E$19*('Plan mensual'!D3+IF(parametros_manuales!$H$19="Todos",'Plan mensual'!D7,0))+parametros_manuales!$F$19*('Plan mensual'!D4+IF(parametros_manuales!$H$19="Todos",'Plan mensual'!D8,0))+parametros_manuales!$G$19*('Plan mensual'!D5+IF(parametros_manuales!$H$19="Todos",'Plan mensual'!D9,0)))*parametros_manuales!$I$19*parametros_manuales!$J$19 -> 769.11204 | C2: =(parametros_manuales!$D$19*('Plan mensual'!E2+IF(parametros_manuales!$H$19="Todos",'Plan mensual'!E6,0))+parametros_manuales!$E$19*('Plan mensual'!E3+IF(parametros_manuales!$H$19="Todos",'Plan mensual'!E7,0))+parametros_manuales!$F$19*('Plan mensual'!E4+IF(parametros_manuales!$H$19="Todos",'Plan mensual'!E8,0))+parametros_manuales!$G$19*('Plan mensual'!E5+IF(parametros_manuales!$H$19="Todos",'Plan mensual'!E9,0)))*parametros_manuales!$I$19*parametros_manuales!$J$19 -> 590.21721 | D2: =(parametros_manuales!$D$19*('Plan mensual'!F2+IF(parametros_manuales!$H$19="Todos",'Plan mensual'!F6,0))+parametros_manuales!$E$19*('Plan mensual'!F3+IF(parametros_manuales!$H$19="Todos",'Plan mensual'!F7,0))+parametros_manuales!$F$19*('Plan mensual'!F4+IF(parametros_manuales!$H$19="Todos",'Plan mensual'!F8,0))+parametros_manuales!$G$19*('Plan mensual'!F5+IF(parametros_manuales!$H$19="Todos",'Plan mensual'!F9,0)))*parametros_manuales!$I$19*parametros_manuales!$J$19 -> 561.81303 | E2: =(parametros_manuales!$D$19*('Plan mensual'!G2+IF(parametros_manuales!$H$19="Todos",'Plan mensual'!G6,0))+parametros_manuales!$E$19*('Plan mensual'!G3+IF(parametros_manuales!$H$19="Todos",'Plan mensual'!G7,0))+parametros_manuales!$F$19*('Plan mensual'!G4+IF(parametros_manuales!$H$19="Todos",'Plan mensual'!G8,0))+parametros_manuales!$G$19*('Plan mensual'!G5+IF(parametros_manuales!$H$19="Todos",'Plan mensual'!G9,0)))*parametros_manuales!$I$19*parametros_manuales!$J$19 -> 540.91935 | F2: =(parametros_manuales!$D$19*('Plan mensual'!H2+IF(parametros_manuales!$H$19="Todos",'Plan mensual'!H6,0))+parametros_manuales!$E$19*('Plan mensual'!H3+IF(parametros_manuales!$H$19="Todos",'Plan mensual'!H7,0))+parametros_manuales!$F$19*('Plan mensual'!H4+IF(parametros_manuales!$H$19="Todos",'Plan mensual'!H8,0))+parametros_manuales!$G$19*('Plan mensual'!H5+IF(parametros_manuales!$H$19="Todos",'Plan mensual'!H9,0)))*parametros_manuales!$I$19*parametros_manuales!$J$19 -> 506.64248 | G2: =(parametros_manuales!$D$19*('Plan mensual'!I2+IF(parametros_manuales!$H$19="Todos",'Plan mensual'!I6,0))+parametros_manuales!$E$19*('Plan mensual'!I3+IF(parametros_manuales!$H$19="Todos",'Plan mensual'!I7,0))+parametros_manuales!$F$19*('Plan mensual'!I4+IF(parametros_manuales!$H$19="Todos",'Plan mensual'!I8,0))+parametros_manuales!$G$19*('Plan mensual'!I5+IF(parametros_manuales!$H$19="Todos",'Plan mensual'!I9,0)))*parametros_manuales!$I$19*parametros_manuales!$J$19 -> 493.2593 | H2: =(parametros_manuales!$D$19*('Plan mensual'!J2+IF(parametros_manuales!$H$19="Todos",'Plan mensual'!J6,0))+parametros_manuales!$E$19*('Plan mensual'!J3+IF(parametros_manuales!$H$19="Todos",'Plan mensual'!J7,0))+parametros_manuales!$F$19*('Plan mensual'!J4+IF(parametros_manuales!$H$19="Todos",'Plan mensual'!J8,0))+parametros_manuales!$G$19*('Plan mensual'!J5+IF(parametros_manuales!$H$19="Todos",'Plan mensual'!J9,0)))*parametros_manuales!$I$19*parametros_manuales!$J$19 -> 527.53617 | I2: =(parametros_manuales!$D$19*('Plan mensual'!K2+IF(parametros_manuales!$H$19="Todos",'Plan mensual'!K6,0))+parametros_manuales!$E$19*('Plan mensual'!K3+IF(parametros_manuales!$H$19="Todos",'Plan mensual'!K7,0))+parametros_manuales!$F$19*('Plan mensual'!K4+IF(parametros_manuales!$H$19="Todos",'Plan mensual'!K8,0))+parametros_manuales!$G$19*('Plan mensual'!K5+IF(parametros_manuales!$H$19="Todos",'Plan mensual'!K9,0)))*parametros_manuales!$I$19*parametros_manuales!$J$19 -> 527.53617 | ... M2: =(parametros_manuales!$D$19*('Plan mensual'!O2+IF(parametros_manuales!$H$19="Todos",'Plan mensual'!O6,0))+parametros_manuales!$E$19*('Plan mensual'!O3+IF(parametros_manuales!$H$19="Todos",'Plan mensual'!O7,0))+parametros_manuales!$F$19*('Plan mensual'!O4+IF(parametros_manuales!$H$19="Todos",'Plan mensual'!O8,0))+parametros_manuales!$G$19*('Plan mensual'!O5+IF(parametros_manuales!$H$19="Todos",'Plan mensual'!O9,0)))*parametros_manuales!$I$19*parametros_manuales!$J$19 -> 795.87841 | N2: =SUM(B2:M2) -> 6855.3731 | O2: =MAX(B2:M2) -> 795.87841 | P2: =O2/(parametros_manuales!$B$7) -> 5.305856 | Q2: =IF(O2=0,"-",INDEX($B$1:$M$1,MATCH(O2,B2:M2,0))) -> Dic
A3: =parametros_manuales!$B$20 -> Corte de chapa — 1.er corte en franjas (guillotina 1, manuales + carros) | B3: =(parametros_manuales!$D$20*('Plan mensual'!D2+IF(parametros_manuales!$H$20="Todos",'Plan mensual'!D6,0))+parametros_manuales!$E$20*('Plan mensual'!D3+IF(parametros_manuales!$H$20="Todos",'Plan mensual'!D7,0))+parametros_manuales!$F$20*('Plan mensual'!D4+IF(parametros_manuales!$H$20="Todos",'Plan mensual'!D8,0))+parametros_manuales!$G$20*('Plan mensual'!D5+IF(parametros_manuales!$H$20="Todos",'Plan mensual'!D9,0)))*parametros_manuales!$I$20*parametros_manuales!$J$20+parametros_manuales!$B$148 -> 860.94037 | C3: =(parametros_manuales!$D$20*('Plan mensual'!E2+IF(parametros_manuales!$H$20="Todos",'Plan mensual'!E6,0))+parametros_manuales!$E$20*('Plan mensual'!E3+IF(parametros_manuales!$H$20="Todos",'Plan mensual'!E7,0))+parametros_manuales!$F$20*('Plan mensual'!E4+IF(parametros_manuales!$H$20="Todos",'Plan mensual'!E8,0))+parametros_manuales!$G$20*('Plan mensual'!E5+IF(parametros_manuales!$H$20="Todos",'Plan mensual'!E9,0)))*parametros_manuales!$I$20*parametros_manuales!$J$20+parametros_manuales!$C$148 -> 671.24221 | D3: =(parametros_manuales!$D$20*('Plan mensual'!F2+IF(parametros_manuales!$H$20="Todos",'Plan mensual'!F6,0))+parametros_manuales!$E$20*('Plan mensual'!F3+IF(parametros_manuales!$H$20="Todos",'Plan mensual'!F7,0))+parametros_manuales!$F$20*('Plan mensual'!F4+IF(parametros_manuales!$H$20="Todos",'Plan mensual'!F8,0))+parametros_manuales!$G$20*('Plan mensual'!F5+IF(parametros_manuales!$H$20="Todos",'Plan mensual'!F9,0)))*parametros_manuales!$I$20*parametros_manuales!$J$20+parametros_manuales!$D$148 -> 659.04302 | E3: =(parametros_manuales!$D$20*('Plan mensual'!G2+IF(parametros_manuales!$H$20="Todos",'Plan mensual'!G6,0))+parametros_manuales!$E$20*('Plan mensual'!G3+IF(parametros_manuales!$H$20="Todos",'Plan mensual'!G7,0))+parametros_manuales!$F$20*('Plan mensual'!G4+IF(parametros_manuales!$H$20="Todos",'Plan mensual'!G8,0))+parametros_manuales!$G$20*('Plan mensual'!G5+IF(parametros_manuales!$H$20="Todos",'Plan mensual'!G9,0)))*parametros_manuales!$I$20*parametros_manuales!$J$20+parametros_manuales!$E$148 -> 638.14934 | F3: =(parametros_manuales!$D$20*('Plan mensual'!H2+IF(parametros_manuales!$H$20="Todos",'Plan mensual'!H6,0))+parametros_manuales!$E$20*('Plan mensual'!H3+IF(parametros_manuales!$H$20="Todos",'Plan mensual'!H7,0))+parametros_manuales!$F$20*('Plan mensual'!H4+IF(parametros_manuales!$H$20="Todos",'Plan mensual'!H8,0))+parametros_manuales!$G$20*('Plan mensual'!H5+IF(parametros_manuales!$H$20="Todos",'Plan mensual'!H9,0)))*parametros_manuales!$I$20*parametros_manuales!$J$20+parametros_manuales!$F$148 -> 603.87247 | G3: =(parametros_manuales!$D$20*('Plan mensual'!I2+IF(parametros_manuales!$H$20="Todos",'Plan mensual'!I6,0))+parametros_manuales!$E$20*('Plan mensual'!I3+IF(parametros_manuales!$H$20="Todos",'Plan mensual'!I7,0))+parametros_manuales!$F$20*('Plan mensual'!I4+IF(parametros_manuales!$H$20="Todos",'Plan mensual'!I8,0))+parametros_manuales!$G$20*('Plan mensual'!I5+IF(parametros_manuales!$H$20="Todos",'Plan mensual'!I9,0)))*parametros_manuales!$I$20*parametros_manuales!$J$20+parametros_manuales!$G$148 -> 579.68596 | H3: =(parametros_manuales!$D$20*('Plan mensual'!J2+IF(parametros_manuales!$H$20="Todos",'Plan mensual'!J6,0))+parametros_manuales!$E$20*('Plan mensual'!J3+IF(parametros_manuales!$H$20="Todos",'Plan mensual'!J7,0))+parametros_manuales!$F$20*('Plan mensual'!J4+IF(parametros_manuales!$H$20="Todos",'Plan mensual'!J8,0))+parametros_manuales!$G$20*('Plan mensual'!J5+IF(parametros_manuales!$H$20="Todos",'Plan mensual'!J9,0)))*parametros_manuales!$I$20*parametros_manuales!$J$20+parametros_manuales!$H$148 -> 624.76616 | I3: =(parametros_manuales!$D$20*('Plan mensual'!K2+IF(parametros_manuales!$H$20="Todos",'Plan mensual'!K6,0))+parametros_manuales!$E$20*('Plan mensual'!K3+IF(parametros_manuales!$H$20="Todos",'Plan mensual'!K7,0))+parametros_manuales!$F$20*('Plan mensual'!K4+IF(parametros_manuales!$H$20="Todos",'Plan mensual'!K8,0))+parametros_manuales!$G$20*('Plan mensual'!K5+IF(parametros_manuales!$H$20="Todos",'Plan mensual'!K9,0)))*parametros_manuales!$I$20*parametros_manuales!$J$20+parametros_manuales!$I$148 -> 624.76616 | J3: =(parametros_manuales!$D$20*('Plan mensual'!L2+IF(parametros_manuales!$H$20="Todos",'Plan mensual'!L6,0))+parametros_manuales!$E$20*('Plan mensual'!L3+IF(parametros_manuales!$H$20="Todos",'Plan mensual'!L7,0))+parametros_manuales!$F$20*('Plan mensual'!L4+IF(parametros_manuales!$H$20="Todos",'Plan mensual'!L8,0))+parametros_manuales!$G$20*('Plan mensual'!L5+IF(parametros_manuales!$H$20="Todos",'Plan mensual'!L9,0)))*parametros_manuales!$I$20*parametros_manuales!$J$20+parametros_manuales!$J$148 -> 619.36449 | K3: =(parametros_manuales!$D$20*('Plan mensual'!M2+IF(parametros_manuales!$H$20="Todos",'Plan mensual'!M6,0))+parametros_manuales!$E$20*('Plan mensual'!M3+IF(parametros_manuales!$H$20="Todos",'Plan mensual'!M7,0))+parametros_manuales!$F$20*('Plan mensual'!M4+IF(parametros_manuales!$H$20="Todos",'Plan mensual'!M8,0))+parametros_manuales!$G$20*('Plan mensual'!M5+IF(parametros_manuales!$H$20="Todos",'Plan mensual'!M9,0)))*parametros_manuales!$I$20*parametros_manuales!$J$20+parametros_manuales!$K$148 -> 595.17798 | L3: =(parametros_manuales!$D$20*('Plan mensual'!N2+IF(parametros_manuales!$H$20="Todos",'Plan mensual'!N6,0))+parametros_manuales!$E$20*('Plan mensual'!N3+IF(parametros_manuales!$H$20="Todos",'Plan mensual'!N7,0))+parametros_manuales!$F$20*('Plan mensual'!N4+IF(parametros_manuales!$H$20="Todos",'Plan mensual'!N8,0))+parametros_manuales!$G$20*('Plan mensual'!N5+IF(parametros_manuales!$H$20="Todos",'Plan mensual'!N9,0)))*parametros_manuales!$I$20*parametros_manuales!$J$20+parametros_manuales!$L$148 -> 576.39313 | M3: =(parametros_manuales!$D$20*('Plan mensual'!O2+IF(parametros_manuales!$H$20="Todos",'Plan mensual'!O6,0))+parametros_manuales!$E$20*('Plan mensual'!O3+IF(parametros_manuales!$H$20="Todos",'Plan mensual'!O7,0))+parametros_manuales!$F$20*('Plan mensual'!O4+IF(parametros_manuales!$H$20="Todos",'Plan mensual'!O8,0))+parametros_manuales!$G$20*('Plan mensual'!O5+IF(parametros_manuales!$H$20="Todos",'Plan mensual'!O9,0)))*parametros_manuales!$I$20*parametros_manuales!$J$20+parametros_manuales!$M$148 -> 882.30507 | N3: =SUM(B3:M3) -> 7935.7063 | O3: =MAX(B3:M3) -> 882.30507 | P3: =O3/(parametros_manuales!$B$7) -> 5.8820338 | Q3: =IF(O3=0,"-",INDEX($B$1:$M$1,MATCH(O3,B3:M3,0))) -> Dic
