Workbook

Sheet Links
A1: Links e IMPORTRANGE
A2: Pegar en B el link de cada Google Sheet. La primera vez, tocar la primera celda de cada bloque y «Permitir acceso». Todos los IMPORTRANGE del libro están en esta hoja; las demás la leen.
A3: Archivo | B3: Link | G3: Qué se importa | M3: Estado
A4: MRP (FLAMA_MRP) | B4: PEGAR ACÁ EL LINK DEL GOOGLE SHEET | G4: DEMANDA, MANUALES, RODANTES, RECARGAS, REVENDIDOS y POLITICA_STOCK | M4: =IF(ISERROR(B12),"Falta el link o «Permitir acceso»","OK") -> OK
A5: Aprovechamiento Manuales | B5: PEGAR ACÁ EL LINK DEL GOOGLE SHEET | G5: datos_base, parametros, Plan mensual, Demanda puesto y Resumen cap. con sobrestock | M5: =IF(ISERROR(B472),"Falta el link o «Permitir acceso»","OK") -> OK
A6: Aprovechamiento Carros | B6: PEGAR ACÁ EL LINK DEL GOOGLE SHEET | G6: datos_base, parametros, Plan mensual, Demanda por puesto y Resumen Capacidad | M6: =IF(ISERROR(B1011),"Falta el link o «Permitir acceso»","OK") -> OK
A7: Aprovechamiento Recargas Planta Industrial | B7: PEGAR ACÁ EL LINK DEL GOOGLE SHEET | G7: datos_base, parametros, Plan mensual, Demanda por puesto y Resumen Capacidad | M7: =IF(ISERROR(B1421),"Falta el link o «Permitir acceso»","OK") -> OK
A8: Análisis alternativas corte chapa | B8: PEGAR ACÁ EL LINK DEL GOOGLE SHEET | G8: Corte (hojas y piezas por hoja) y Piezas (masas y discos) | M8: =IF(ISERROR(B2191),"Falta el link o «Permitir acceso»","OK") -> OK
A11: MRP (FLAMA_MRP) · DEMANDA!C4:M50: demanda por producto (D01 a D47)
B12: =IFERROR(__xludf.DUMMYFUNCTION("IMPORTRANGE(Links!$B$4,""DEMANDA!C4:M50"")"),"Parte de la planta industrial") -> Parte de la planta industrial
A60: MRP (FLAMA_MRP) · MANUALES!B16:W75: consumo por unidad y compra por año
B61: =IFERROR(__xludf.DUMMYFUNCTION("IMPORTRANGE(Links!$B$4,""MANUALES!B16:W75"")"),"MP-01") -> MP-01
A122: MRP (FLAMA_MRP) · RODANTES!B16:W72: consumo por unidad y compra por año
B123: =IFERROR(__xludf.DUMMYFUNCTION("IMPORTRANGE(Links!$B$4,""RODANTES!B16:W72"")"),"MP-11") -> MP-11
A181: MRP (FLAMA_MRP) · RECARGAS!B16:AG37: consumo por unidad y compra por año
B182: =IFERROR(__xludf.DUMMYFUNCTION("IMPORTRANGE(Links!$B$4,""RECARGAS!B16:AG37"")"),"MP-33") -> MP-33
A205: MRP (FLAMA_MRP) · REVENDIDOS!B16:X25: consumo por unidad y compra por año
B206: =IFERROR(__xludf.DUMMYFUNCTION("IMPORTRANGE(Links!$B$4,""REVENDIDOS!B16:X25"")"),"RV-AGUA_10l") -> RV-AGUA_10l
A217: MRP (FLAMA_MRP) · POLITICA_STOCK!B5:B129: código
B218: =IFERROR(__xludf.DUMMYFUNCTION("IMPORTRANGE(Links!$B$4,""POLITICA_STOCK!B5:B129"")"),"MP-01") -> MP-01
A344: MRP (FLAMA_MRP) · POLITICA_STOCK!O5:P129: unidad de compra y contenido
B345: =IFERROR(__xludf.DUMMYFUNCTION("IMPORTRANGE(Links!$B$4,""POLITICA_STOCK!O5:P129"")"),"Paquete de 50 hojas") -> Paquete de 50 hojas
A471: Aprovechamiento Manuales · datos_base!B2:K29: producción y proyecciones
B472: =IFERROR(__xludf.DUMMYFUNCTION("IMPORTRANGE(Links!$B$5,""datos_base!B2:K29"")"),4178.736543) -> 4178.7365
A501: Aprovechamiento Manuales · Plan mensual!D1:P109: plan mensual por año (11 filas por año)
B502: =IFERROR(__xludf.DUMMYFUNCTION("IMPORTRANGE(Links!$B$5,""Plan mensual!D1:P109"")"),"Ene") -> Ene
A612: Aprovechamiento Manuales · parametros_manuales!K19:K44: tiempo tipo (s/u)
B613: =IFERROR(__xludf.DUMMYFUNCTION("IMPORTRANGE(Links!$B$5,""parametros_manuales!K19:K44"")"),60) -> 60
A640: Aprovechamiento Manuales · parametros_manuales!B7:B7: horas productivas por mes (1 turno)
B641: =IFERROR(__xludf.DUMMYFUNCTION("IMPORTRANGE(Links!$B$5,""parametros_manuales!B7:B7"")"),150) -> 150
A643: Aprovechamiento Manuales · Demanda puesto con sobrestock!N1:N279: unidades por puesto y año (28 filas por año)
B644: =IFERROR(__xludf.DUMMYFUNCTION("IMPORTRANGE(Links!$B$5,""Demanda puesto con sobrestock!N1:N279"")"),"Total anual") -> Total anual
A924: Aprovechamiento Manuales · Resumen cap. con sobrestock!B2:K85: aprovechamiento, máquinas y turnos
B925: =IFERROR(__xludf.DUMMYFUNCTION("IMPORTRANGE(Links!$B$5,""Resumen cap. con sobrestock!B2:K85"")"),0.0685537310673) -> 0.068553731
A1010: Aprovechamiento Carros · datos_base!B2:K12: proyección de carros y cilindros
B1011: =IFERROR(__xludf.DUMMYFUNCTION("IMPORTRANGE(Links!$B$6,""datos_base!B2:K12"")"),34.05179136) -> 34.051791
A1023: Aprovechamiento Carros · Plan mensual!D1:P109: plan mensual por año (11 filas por año)
B1024: =IFERROR(__xludf.DUMMYFUNCTION("IMPORTRANGE(Links!$B$6,""Plan mensual!D1:P109"")"),"Ene") -> Ene
A1134: Aprovechamiento Carros · parametros_carros!I19:I36: tiempo ponderado (min/u)
B1135: =IFERROR(__xludf.DUMMYFUNCTION("IMPORTRANGE(Links!$B$6,""parametros_carros!I19:I36"")"),1.7825) -> 1.7825
...

Sheet Resumen
A1: BALANCEO DE MATERIALES Y DE LÍNEA — planta industrial FLAMA
A2: Elegí el año en C3. Todo sale de las hojas que llegan por IMPORTRANGE (hoja Links).
A3: Año | C3: 2035
A5: 1) Producción contra demanda y contra lo que compra el MRP (año elegido)
A6: Línea | B6: Producto | C6: Demanda (Proyecciones) | D6: Producción (Aprovechamiento) | E6: Sobrestock (u) | F6: Sobrestock (%) | G6: ¿Producción ≥ demanda? | H6: El MRP compra para (u) | I6: ¿El MRP cubre la producción? | J6: MRP − producción (u)
A7: MANUALES | B7: Matafuego ABC 1 kg | C7: =INDEX(Links!$B$489:$K$489,1,(Resumen!$C$3-2025)) -> 32072.639 | D7: =INDEX(Links!$N$502:$N$610,(Resumen!$C$3-2026)*11+2) -> 32072.639 | E7: =D7-C7 -> 0 | F7: =IF(C7=0,0,D7/C7-1) -> 0 | G7: =IF(ROUND(D7-C7,1)>=0,"✔ Sí","✖ No") -> ✔ Sí | H7: =INDEX(Links!$C$16:$L$16,1,(Resumen!$C$3-2025)) -> 32072.639 | I7: =IF(ROUND(H7-D7,1)>=0,"✔ Sí","✖ No") -> ✔ Sí | J7: =H7-D7 -> 0
A8: MANUALES | B8: Matafuego ABC 2,5 kg | C8: =INDEX(Links!$B$490:$K$490,1,(Resumen!$C$3-2025)) -> 7424.8584 | D8: =INDEX(Links!$N$502:$N$610,(Resumen!$C$3-2026)*11+3) -> 7436.4584 | E8: =D8-C8 -> 11.6 | F8: =IF(C8=0,0,D8/C8-1) -> 0.0015623193 | G8: =IF(ROUND(D8-C8,1)>=0,"✔ Sí","✖ No") -> ✔ Sí | H8: =INDEX(Links!$C$17:$L$17,1,(Resumen!$C$3-2025)) -> 7424.8584 | I8: =IF(ROUND(H8-D8,1)>=0,"✔ Sí","✖ No") -> ✖ No | J8: =H8-D8 -> -11.6
A9: MANUALES | B9: Matafuego ABC 5 kg | C9: =INDEX(Links!$B$491:$K$491,1,(Resumen!$C$3-2025)) -> 30750.779 | D9: =INDEX(Links!$N$502:$N$610,(Resumen!$C$3-2026)*11+4) -> 30814.979 | E9: =D9-C9 -> 64.2 | F9: =IF(C9=0,0,D9/C9-1) -> 0.002087752 | G9: =IF(ROUND(D9-C9,1)>=0,"✔ Sí","✖ No") -> ✔ Sí | H9: =INDEX(Links!$C$18:$L$18,1,(Resumen!$C$3-2025)) -> 30860.771 | I9: =IF(ROUND(H9-D9,1)>=0,"✔ Sí","✖ No") -> ✔ Sí | J9: =H9-D9 -> 45.791966
A10: MANUALES | B10: Matafuego ABC 10 kg | C10: =INDEX(Links!$B$492:$K$492,1,(Resumen!$C$3-2025)) -> 1840.8481 | D10: =INDEX(Links!$N$502:$N$610,(Resumen!$C$3-2026)*11+5) -> 1844.9281 | E10: =D10-C10 -> 4.08 | F10: =IF(C10=0,0,D10/C10-1) -> 0.0022163698 | G10: =IF(ROUND(D10-C10,1)>=0,"✔ Sí","✖ No") -> ✔ Sí | H10: =INDEX(Links!$C$19:$L$19,1,(Resumen!$C$3-2025)) -> 1842.877 | I10: =IF(ROUND(H10-D10,1)>=0,"✔ Sí","✖ No") -> ✖ No | J10: =H10-D10 -> -2.0511058
A11: MANUALES | B11: Cilindro ABC 1 kg vacío | C11: =INDEX(Links!$B$496:$K$496,1,(Resumen!$C$3-2025)) -> 170548 | D11: =INDEX(Links!$N$502:$N$610,(Resumen!$C$3-2026)*11+6) -> 170548 | E11: =D11-C11 -> 0 | F11: =IF(C11=0,0,D11/C11-1) -> 0 | G11: =IF(ROUND(D11-C11,1)>=0,"✔ Sí","✖ No") -> ✔ Sí | H11: =INDEX(Links!$C$20:$L$20,1,(Resumen!$C$3-2025)) -> 170548 | I11: =IF(ROUND(H11-D11,1)>=0,"✔ Sí","✖ No") -> ✔ Sí | J11: =H11-D11 -> 0
A12: MANUALES | B12: Cilindro ABC 2,5 kg vacío | C12: =INDEX(Links!$B$497:$K$497,1,(Resumen!$C$3-2025)) -> 6669 | D12: =INDEX(Links!$N$502:$N$610,(Resumen!$C$3-2026)*11+7) -> 6689.88 | E12: =D12-C12 -> 20.88 | F12: =IF(C12=0,0,D12/C12-1) -> 0.0031309042 | G12: =IF(ROUND(D12-C12,1)>=0,"✔ Sí","✖ No") -> ✔ Sí | H12: =INDEX(Links!$C$21:$L$21,1,(Resumen!$C$3-2025)) -> 6669 | I12: =IF(ROUND(H12-D12,1)>=0,"✔ Sí","✖ No") -> ✖ No | J12: =H12-D12 -> -20.88
A13: MANUALES | B13: Cilindro ABC 5 kg vacío | C13: =INDEX(Links!$B$498:$K$498,1,(Resumen!$C$3-2025)) -> 32915 | D13: =INDEX(Links!$N$502:$N$610,(Resumen!$C$3-2026)*11+8) -> 33037.68 | E13: =D13-C13 -> 122.68 | F13: =IF(C13=0,0,D13/C13-1) -> 0.0037271761 | G13: =IF(ROUND(D13-C13,1)>=0,"✔ Sí","✖ No") -> ✔ Sí | H13: =INDEX(Links!$C$22:$L$22,1,(Resumen!$C$3-2025)) -> 32915 | I13: =IF(ROUND(H13-D13,1)>=0,"✔ Sí","✖ No") -> ✖ No | J13: =H13-D13 -> -122.68
A14: MANUALES | B14: Cilindro ABC 10 kg vacío | C14: =INDEX(Links!$B$499:$K$499,1,(Resumen!$C$3-2025)) -> 2011 | D14: =INDEX(Links!$N$502:$N$610,(Resumen!$C$3-2026)*11+9) -> 2018 | E14: =D14-C14 -> 7 | F14: =IF(C14=0,0,D14/C14-1) -> 0.0034808553 | G14: =IF(ROUND(D14-C14,1)>=0,"✔ Sí","✖ No") -> ✔ Sí | H14: =INDEX(Links!$C$23:$L$23,1,(Resumen!$C$3-2025)) -> 2011 | I14: =IF(ROUND(H14-D14,1)>=0,"✔ Sí","✖ No") -> ✖ No | J14: =H14-D14 -> -7
A15: RODANTES | B15: Carro ABC 25 kg | C15: =INDEX(Links!$B$1011:$K$1011,1,(Resumen!$C$3-2025)) -> 453.27053 | D15: =INDEX(Links!$N$1024:$N$1132,(Resumen!$C$3-2026)*11+2) -> 453.67053 | E15: =D15-C15 -> 0.4 | F15: =IF(C15=0,0,D15/C15-1) -> 0.00088247519 | G15: =IF(ROUND(D15-C15,1)>=0,"✔ Sí","✖ No") -> ✔ Sí | H15: =INDEX(Links!$C$24:$L$24,1,(Resumen!$C$3-2025)) -> 453.27053 | I15: =IF(ROUND(H15-D15,1)>=0,"✔ Sí","✖ No") -> ✖ No | J15: =H15-D15 -> -0.4
A16: RODANTES | B16: Carro ABC 50 kg | C16: =INDEX(Links!$B$1012:$K$1012,1,(Resumen!$C$3-2025)) -> 997.19517 | D16: =INDEX(Links!$N$1024:$N$1132,(Resumen!$C$3-2026)*11+3) -> 997.99517 | E16: =D16-C16 -> 0.8 | F16: =IF(C16=0,0,D16/C16-1) -> 0.00080225017 | G16: =IF(ROUND(D16-C16,1)>=0,"✔ Sí","✖ No") -> ✔ Sí | H16: =INDEX(Links!$C$25:$L$25,1,(Resumen!$C$3-2025)) -> 998.25998 | I16: =IF(ROUND(H16-D16,1)>=0,"✔ Sí","✖ No") -> ✔ Sí | J16: =H16-D16 -> 0.26480972
A17: RODANTES | B17: Carro ABC 70 kg | C17: =INDEX(Links!$B$1013:$K$1013,1,(Resumen!$C$3-2025)) -> 217.56986 | D17: =INDEX(Links!$N$1024:$N$1132,(Resumen!$C$3-2026)*11+4) -> 217.80986 | E17: =D17-C17 -> 0.24 | F17: =IF(C17=0,0,D17/C17-1) -> 0.001103094 | G17: =IF(ROUND(D17-C17,1)>=0,"✔ Sí","✖ No") -> ✔ Sí | H17: =INDEX(Links!$C$26:$L$26,1,(Resumen!$C$3-2025)) -> 217.56986 | I17: =IF(ROUND(H17-D17,1)>=0,"✔ Sí","✖ No") -> ✖ No | J17: =H17-D17 -> -0.24
A18: RODANTES | B18: Carro ABC 100 kg | C18: =INDEX(Links!$B$1014:$K$1014,1,(Resumen!$C$3-2025)) -> 145.04657 | D18: =INDEX(Links!$N$1024:$N$1132,(Resumen!$C$3-2026)*11+5) -> 145.20657 | E18: =D18-C18 -> 0.16 | F18: =IF(C18=0,0,D18/C18-1) -> 0.001103094 | G18: =IF(ROUND(D18-C18,1)>=0,"✔ Sí","✖ No") -> ✔ Sí | H18: =INDEX(Links!$C$27:$L$27,1,(Resumen!$C$3-2025)) -> 145.17607 | I18: =IF(ROUND(H18-D18,1)>=0,"✔ Sí","✖ No") -> ✔ Sí | J18: =H18-D18 -> -0.030496115
A19: RODANTES | B19: Cilindro ABC 25 kg vacío | C19: =INDEX(Links!$B$1018:$K$1018,1,(Resumen!$C$3-2025)) -> 322 | D19: =INDEX(Links!$N$1024:$N$1132,(Resumen!$C$3-2026)*11+6) -> 323.64 | E19: =D19-C19 -> 1.64 | F19: =IF(C19=0,0,D19/C19-1) -> 0.0050931677 | G19: =IF(ROUND(D19-C19,1)>=0,"✔ Sí","✖ No") -> ✔ Sí | H19: =INDEX(Links!$C$28:$L$28,1,(Resumen!$C$3-2025)) -> 322 | I19: =IF(ROUND(H19-D19,1)>=0,"✔ Sí","✖ No") -> ✖ No | J19: =H19-D19 -> -1.64
A20: RODANTES | B20: Cilindro ABC 50 kg vacío | C20: =INDEX(Links!$B$1019:$K$1019,1,(Resumen!$C$3-2025)) -> 708 | D20: =INDEX(Links!$N$1024:$N$1132,(Resumen!$C$3-2026)*11+7) -> 710.44 | E20: =D20-C20 -> 2.44 | F20: =IF(C20=0,0,D20/C20-1) -> 0.0034463277 | G20: =IF(ROUND(D20-C20,1)>=0,"✔ Sí","✖ No") -> ✔ Sí | H20: =INDEX(Links!$C$29:$L$29,1,(Resumen!$C$3-2025)) -> 708 | I20: =IF(ROUND(H20-D20,1)>=0,"✔ Sí","✖ No") -> ✖ No | J20: =H20-D20 -> -2.44
A21: RODANTES | B21: Cilindro ABC 70 kg vacío | C21: =INDEX(Links!$B$1020:$K$1020,1,(Resumen!$C$3-2025)) -> 155 | D21: =INDEX(Links!$N$1024:$N$1132,(Resumen!$C$3-2026)*11+8) -> 156.32 | E21: =D21-C21 -> 1.32 | F21: =IF(C21=0,0,D21/C21-1) -> 0.008516129 | G21: =IF(ROUND(D21-C21,1)>=0,"✔ Sí","✖ No") -> ✔ Sí | H21: =INDEX(Links!$C$30:$L$30,1,(Resumen!$C$3-2025)) -> 155 | I21: =IF(ROUND(H21-D21,1)>=0,"✔ Sí","✖ No") -> ✖ No | J21: =H21-D21 -> -1.32
A22: RODANTES | B22: Cilindro ABC 100 kg vacío | C22: =INDEX(Links!$B$1021:$K$1021,1,(Resumen!$C$3-2025)) -> 102 | D22: =INDEX(Links!$N$1024:$N$1132,(Resumen!$C$3-2026)*11+9) -> 102.24 | E22: =D22-C22 -> 0.24 | F22: =IF(C22=0,0,D22/C22-1) -> 0.0023529412 | G22: =IF(ROUND(D22-C22,1)>=0,"✔ Sí","✖ No") -> ✔ Sí | H22: =INDEX(Links!$C$31:$L$31,1,(Resumen!$C$3-2025)) -> 102 | I22: =IF(ROUND(H22-D22,1)>=0,"✔ Sí","✖ No") -> ✖ No | J22: =H22-D22 -> -0.24
A23: RECARGAS | B23: Recarga ABC 1 kg | C23: =INDEX(Links!$B$1421:$K$1421,1,(Resumen!$C$3-2025)) -> 56575.837 | D23: =INDEX(Links!$N$1440:$N$1757,(Resumen!$C$3-2026)*32+2) -> 56575.837 | E23: =D23-C23 -> 0 | F23: =IF(C23=0,0,D23/C23-1) -> 0 | G23: =IF(ROUND(D23-C23,1)>=0,"✔ Sí","✖ No") -> ✔ Sí | H23: =INDEX(Links!$C$32:$L$32,1,(Resumen!$C$3-2025)) -> 56487.491 | I23: =IF(ROUND(H23-D23,1)>=0,"✔ Sí","✖ No") -> ✖ No | J23: =H23-D23 -> -88.345775
A24: RECARGAS | B24: Recarga ABC 2,5 kg | C24: =INDEX(Links!$B$1422:$K$1422,1,(Resumen!$C$3-2025)) -> 4790.7101 | D24: =INDEX(Links!$N$1440:$N$1757,(Resumen!$C$3-2026)*32+3) -> 4860.7101 | E24: =D24-C24 -> 70 | F24: =IF(C24=0,0,D24/C24-1) -> 0.014611613 | G24: =IF(ROUND(D24-C24,1)>=0,"✔ Sí","✖ No") -> ✔ Sí | H24: =INDEX(Links!$C$33:$L$33,1,(Resumen!$C$3-2025)) -> 4783.2292 | I24: =IF(ROUND(H24-D24,1)>=0,"✔ Sí","✖ No") -> ✖ No | J24: =H24-D24 -> -77.480915
A25: RECARGAS | B25: Recarga ABC 5 kg | C25: =INDEX(Links!$B$1423:$K$1423,1,(Resumen!$C$3-2025)) -> 29139.32 | D25: =INDEX(Links!$N$1440:$N$1757,(Resumen!$C$3-2026)*32+4) -> 29554.32 | E25: =D25-C25 -> 415 | F25: =IF(C25=0,0,D25/C25-1) -> 0.014241925 | G25: =IF(ROUND(D25-C25,1)>=0,"✔ Sí","✖ No") -> ✔ Sí | H25: =INDEX(Links!$C$34:$L$34,1,(Resumen!$C$3-2025)) -> 30068.838 | I25: =IF(ROUND(H25-D25,1)>=0,"✔ Sí","✖ No") -> ✔ Sí | J25: =H25-D25 -> 514.51797
A26: RECARGAS | B26: Recarga ABC 10 kg | C26: =INDEX(Links!$B$1424:$K$1424,1,(Resumen!$C$3-2025)) -> 1725.3696 | D26: =INDEX(Links!$N$1440:$N$1757,(Resumen!$C$3-2026)*32+5) -> 1751.3696 | E26: =D26-C26 -> 26 | F26: =IF(C26=0,0,D26/C26-1) -> 0.015069235 | G26: =IF(ROUND(D26-C26,1)>=0,"✔ Sí","✖ No") -> ✔ Sí | H26: =INDEX(Links!$C$35:$L$35,1,(Resumen!$C$3-2025)) -> 1741.3814 | I26: =IF(ROUND(H26-D26,1)>=0,"✔ Sí","✖ No") -> ✖ No | J26: =H26-D26 -> -9.9881273
A27: RECARGAS | B27: Recarga Agua 10 l | C27: =INDEX(Links!$B$1425:$K$1425,1,(Resumen!$C$3-2025)) -> 2435.8331 | D27: =INDEX(Links!$N$1440:$N$1757,(Resumen!$C$3-2026)*32+6) -> 2471.8331 | E27: =D27-C27 -> 36 | F27: =IF(C27=0,0,D27/C27-1) -> 0.014779338 | G27: =IF(ROUND(D27-C27,1)>=0,"✔ Sí","✖ No") -> ✔ Sí | H27: =INDEX(Links!$C$36:$L$36,1,(Resumen!$C$3-2025)) -> 2458.5058 | I27: =IF(ROUND(H27-D27,1)>=0,"✔ Sí","✖ No") -> ✖ No | J27: =H27-D27 -> -13.327316
A28: RECARGAS | B28: Recarga AFFF 10 l | C28: =INDEX(Links!$B$1426:$K$1426,1,(Resumen!$C$3-2025)) -> 462.45859 | D28: =INDEX(Links!$N$1440:$N$1757,(Resumen!$C$3-2026)*32+7) -> 468.45859 | E28: =D28-C28 -> 6 | F28: =IF(C28=0,0,D28/C28-1) -> 0.012974135 | G28: =IF(ROUND(D28-C28,1)>=0,"✔ Sí","✖ No") -> ✔ Sí | H28: =INDEX(Links!$C$37:$L$37,1,(Resumen!$C$3-2025)) -> 466.91659 | I28: =IF(ROUND(H28-D28,1)>=0,"✔ Sí","✖ No") -> ✖ No | J28: =H28-D28 -> -1.541995
A29: RECARGAS | B29: Recarga AFFF 50 l s/ruedas | C29: =INDEX(Links!$B$1427:$K$1427,1,(Resumen!$C$3-2025)) -> 241.06683 | D29: =INDEX(Links!$N$1440:$N$1757,(Resumen!$C$3-2026)*32+8) -> 244.06683 | E29: =D29-C29 -> 3 | F29: =IF(C29=0,0,D29/C29-1) -> 0.012444682 | G29: =IF(ROUND(D29-C29,1)>=0,"✔ Sí","✖ No") -> ✔ Sí | H29: =INDEX(Links!$C$38:$L$38,1,(Resumen!$C$3-2025)) -> 243.56826 | I29: =IF(ROUND(H29-D29,1)>=0,"✔ Sí","✖ No") -> ✖ No | J29: =H29-D29 -> -0.49857283
A30: RECARGAS | B30: Recarga BC 5 kg | C30: =INDEX(Links!$B$1428:$K$1428,1,(Resumen!$C$3-2025)) -> 139.35636 | D30: =INDEX(Links!$N$1440:$N$1757,(Resumen!$C$3-2026)*32+9) -> 141.35636 | E30: =D30-C30 -> 2 | F30: =IF(C30=0,0,D30/C30-1) -> 0.014351696 | G30: =IF(ROUND(D30-C30,1)>=0,"✔ Sí","✖ No") -> ✔ Sí | H30: =INDEX(Links!$C$39:$L$39,1,(Resumen!$C$3-2025)) -> 140.86546 | I30: =IF(ROUND(H30-D30,1)>=0,"✔ Sí","✖ No") -> ✖ No | J30: =H30-D30 -> -0.49089279
A31: RECARGAS | B31: Recarga Sales K 6 l | C31: =INDEX(Links!$B$1429:$K$1429,1,(Resumen!$C$3-2025)) -> 1201.2428 | D31: =INDEX(Links!$N$1440:$N$1757,(Resumen!$C$3-2026)*32+10) -> 1218.2428 | E31: =D31-C31 -> 17 | F31: =IF(C31=0,0,D31/C31-1) -> 0.01415201 | G31: =IF(ROUND(D31-C31,1)>=0,"✔ Sí","✖ No") -> ✔ Sí | H31: =INDEX(Links!$C$40:$L$40,1,(Resumen!$C$3-2025)) -> 1212.3174 | I31: =IF(ROUND(H31-D31,1)>=0,"✔ Sí","✖ No") -> ✖ No | J31: =H31-D31 -> -5.9254075
A32: RECARGAS | B32: Recarga CO₂ 2 kg | C32: =INDEX(Links!$B$1430:$K$1430,1,(Resumen!$C$3-2025)) -> 6552.9133 | D32: =INDEX(Links!$N$1440:$N$1757,(Resumen!$C$3-2026)*32+11) -> 6648.9133 | E32: =D32-C32 -> 96 | F32: =IF(C32=0,0,D32/C32-1) -> 0.014649972 | G32: =IF(ROUND(D32-C32,1)>=0,"✔ Sí","✖ No") -> ✔ Sí | H32: =INDEX(Links!$C$41:$L$41,1,(Resumen!$C$3-2025)) -> 6542.6807 | I32: =IF(ROUND(H32-D32,1)>=0,"✔ Sí","✖ No") -> ✖ No | J32: =H32-D32 -> -106.23268
A33: RECARGAS | B33: Recarga CO₂ 5 kg | C33: =INDEX(Links!$B$1431:$K$1431,1,(Resumen!$C$3-2025)) -> 2239.4758 | D33: =INDEX(Links!$N$1440:$N$1757,(Resumen!$C$3-2026)*32+12) -> 2270.4758 | E33: =D33-C33 -> 31 | F33: =IF(C33=0,0,D33/C33-1) -> 0.013842525 | G33: =IF(ROUND(D33-C33,1)>=0,"✔ Sí","✖ No") -> ✔ Sí | H33: =INDEX(Links!$C$42:$L$42,1,(Resumen!$C$3-2025)) -> 2330.9482 | I33: =IF(ROUND(H33-D33,1)>=0,"✔ Sí","✖ No") -> ✔ Sí | J33: =H33-D33 -> 60.472471
A34: RECARGAS | B34: Recarga HCFC/HFC 5 kg | C34: =INDEX(Links!$B$1432:$K$1432,1,(Resumen!$C$3-2025)) -> 366.61986 | D34: =INDEX(Links!$N$1440:$N$1757,(Resumen!$C$3-2026)*32+13) -> 372.61986 | E34: =D34-C34 -> 6 | F34: =IF(C34=0,0,D34/C34-1) -> 0.016365726 | G34: =IF(ROUND(D34-C34,1)>=0,"✔ Sí","✖ No") -> ✔ Sí | H34: =INDEX(Links!$C$43:$L$43,1,(Resumen!$C$3-2025)) -> 370.07637 | I34: =IF(ROUND(H34-D34,1)>=0,"✔ Sí","✖ No") -> ✖ No | J34: =H34-D34 -> -2.543484
A35: RECARGAS | B35: Recarga Clase D 9 l | C35: =INDEX(Links!$B$1433:$K$1433,1,(Resumen!$C$3-2025)) -> 125.86907 | D35: =INDEX(Links!$N$1440:$N$1757,(Resumen!$C$3-2026)*32+14) -> 127.86907 | E35: =D35-C35 -> 2 | F35: =IF(C35=0,0,D35/C35-1) -> 0.015889527 | G35: =IF(ROUND(D35-C35,1)>=0,"✔ Sí","✖ No") -> ✔ Sí | H35: =INDEX(Links!$C$44:$L$44,1,(Resumen!$C$3-2025)) -> 127.11145 | I35: =IF(ROUND(H35-D35,1)>=0,"✔ Sí","✖ No") -> ✖ No | J35: =H35-D35 -> -0.75761821
A36: RECARGAS | B36: Recarga ABC 25 kg s/ruedas | C36: =INDEX(Links!$B$1434:$K$1434,1,(Resumen!$C$3-2025)) -> 300.32506 | D36: =INDEX(Links!$N$1440:$N$1757,(Resumen!$C$3-2026)*32+15) -> 305.32506 | E36: =D36-C36 -> 5 | F36: =IF(C36=0,0,D36/C36-1) -> 0.016648627 | G36: =IF(ROUND(D36-C36,1)>=0,"✔ Sí","✖ No") -> ✔ Sí | H36: =INDEX(Links!$C$45:$L$45,1,(Resumen!$C$3-2025)) -> 299.85609 | I36: =IF(ROUND(H36-D36,1)>=0,"✔ Sí","✖ No") -> ✖ No | J36: =H36-D36 -> -5.4689714
A37: RECARGAS | B37: Recarga ABC 50 kg s/ruedas | C37: =INDEX(Links!$B$1435:$K$1435,1,(Resumen!$C$3-2025)) -> 660.71513 | D37: =INDEX(Links!$N$1440:$N$1757,(Resumen!$C$3-2026)*32+16) -> 670.71513 | E37: =D37-C37 -> 10 | F37: =IF(C37=0,0,D37/C37-1) -> 0.015135116 | G37: =IF(ROUND(D37-C37,1)>=0,"✔ Sí","✖ No") -> ✔ Sí | H37: =INDEX(Links!$C$46:$L$46,1,(Resumen!$C$3-2025)) -> 670.0437 | I37: =IF(ROUND(H37-D37,1)>=0,"✔ Sí","✖ No") -> ✖ No | J37: =H37-D37 -> -0.67142631
A38: RECARGAS | B38: Recarga ABC 70 kg s/ruedas | C38: =INDEX(Links!$B$1436:$K$1436,1,(Resumen!$C$3-2025)) -> 144.15603 | D38: =INDEX(Links!$N$1440:$N$1757,(Resumen!$C$3-2026)*32+17) -> 147.15603 | E38: =D38-C38 -> 3 | F38: =IF(C38=0,0,D38/C38-1) -> 0.020810784 | G38: =IF(ROUND(D38-C38,1)>=0,"✔ Sí","✖ No") -> ✔ Sí | H38: =INDEX(Links!$C$47:$L$47,1,(Resumen!$C$3-2025)) -> 143.93092 | I38: =IF(ROUND(H38-D38,1)>=0,"✔ Sí","✖ No") -> ✖ No | J38: =H38-D38 -> -3.2251064
A39: RECARGAS | B39: Recarga ABC 100 kg s/ruedas | C39: =INDEX(Links!$B$1437:$K$1437,1,(Resumen!$C$3-2025)) -> 96.104019 | D39: =INDEX(Links!$N$1440:$N$1757,(Resumen!$C$3-2026)*32+18) -> 98.104019 | E39: =D39-C39 -> 2 | F39: =IF(C39=0,0,D39/C39-1) -> 0.020810784 | G39: =IF(ROUND(D39-C39,1)>=0,"✔ Sí","✖ No") -> ✔ Sí | H39: =INDEX(Links!$C$48:$L$48,1,(Resumen!$C$3-2025)) -> 98.544026 | I39: =IF(ROUND(H39-D39,1)>=0,"✔ Sí","✖ No") -> ✔ Sí | J39: =H39-D39 -> 0.44000699
A41: Totales por línea (año elegido)
A42: Línea | C42: Demanda | D42: Producción | E42: Sobrestock (u) | F42: Sobrestock (%) | G42: Productos con producción < demanda | H42: MRP compra para | I42: Productos que el MRP no cubre | J42: MRP − producción
...

Sheet Esquema materiales
A1: ESQUEMA DEL BALANCE DE MATERIALES (año elegido en Resumen) — los números salen de la hoja Materiales
A2: Azul: materia prima · amarillo: semielaborados · verde: producto terminado · rojo: scrap, desechos y mermas · gris: checks. Editable: los textos son fórmulas.
B4: LÍNEA DE MANUALES
B5: ="MATERIA PRIMA"&CHAR(10)&"Chapa: "&TEXT(Materiales!$C$7,"#,##0")&" hojas"&CHAR(10)&"Fleje: "&TEXT(Materiales!$C$8,"#,##0")&" kg"&CHAR(10)&"Polvo ABC: "&TEXT(Materiales!$C$15,"#,##0")&" kg"&CHAR(10)&"Componentes: "&TEXT(Materiales!$C$17,"#,##0")&" u" -> MATERIA PRIMA Chapa: 10,604 hojas Fleje: 100,701 kg Polvo ABC: 230,062 kg Componentes: 693,428 u | G5: ➜ | H5: ="CORTE"&CHAR(10)&TEXT(Materiales!$G$22,"#,##0")&" planchuelas"&CHAR(10)&TEXT(Materiales!$G$23,"#,##0")&" discos" -> CORTE 284,463 planchuelas 568,925 discos | M5: ➜ | N5: ="EMBUTIDO Y SOLDADURA"&CHAR(10)&TEXT(Materiales!$G$24,"#,##0")&" casquetes"&CHAR(10)&TEXT(Materiales!$G$26,"#,##0")&" recipientes" -> EMBUTIDO Y SOLDADURA 568,925 casquetes 284,463 recipientes | S5: ➜ | T5: ="TERMINACIÓN"&CHAR(10)&"PH, secado, granallado, pintura"&CHAR(10)&TEXT(Materiales!$G$27,"#,##0")&" recipientes pintados" -> TERMINACIÓN PH, secado, granallado, pintura 284,463 recipientes pintados | Y5: ➜ | Z5: ="CARGA Y ARMADO"&CHAR(10)&"polvo, válvula, N₂, ensayo de pérdidas" -> CARGA Y ARMADO polvo, válvula, N₂, ensayo de pérdidas | AE5: ➜ | AF5: ="PRODUCTO TERMINADO"&CHAR(10)&TEXT(Materiales!$C$51,"#,##0")&" u"&CHAR(10)&"matafuegos 1 a 10 kg y cilindros vacíos" -> PRODUCTO TERMINADO 284,463 u matafuegos 1 a 10 kg y cilindros vacíos | AL5: ="CHECKS "&Resumen!$C$3&""&CHAR(10)&"Producción ≥ demanda: "&IF(Resumen!$G$43=0,"✔","✖ "&Resumen!$G$43&" productos")&CHAR(10)&"Sobrestock: "&TEXT(Resumen!$F$43,"0.0%")&CHAR(10)&"MRP cubre la producción: "&IF(Resumen!$I$43=0,"✔","✖ "&Resumen!$I$43&" productos") -> CHECKS 2035 Producción ≥ demanda: ✔ Sobrestock: 0.1% MRP cubre la producción: ✖ 5 productos
J12: ▼ | P12: ▼ | V12: ▼ | AB12: ▼
H13: ="SCRAP Y MERMAS"&CHAR(10)&"Chatarra: "&TEXT(Materiales!$C$32+Materiales!$C$33,"#,##0")&" kg (recortes y esqueleto de fleje)"&CHAR(10)&"Desechos: "&TEXT(Materiales!$C$34+Materiales!$C$37+Materiales!$C$38,"#,##0")&" kg (salpicadura, granalla, pintura)"&CHAR(10)&"Gases: "&TEXT(Materiales!$C$35,"#,##0")&" m³" -> SCRAP Y MERMAS Chatarra: 42,322 kg (recortes y esqueleto de fleje) Desechos: 23,236 kg (salpicadura, granalla, pintura) Gases: 8,199 m³
B19: LÍNEA DE CARROS
B20: ="MATERIA PRIMA"&CHAR(10)&"Chapa: "&TEXT(Materiales!$C$61,"#,##0")&" hojas"&CHAR(10)&"Casquetes y cuplas: "&TEXT(Materiales!$C$62,"#,##0")&" u"&CHAR(10)&"Polvo ABC 90: "&TEXT(Materiales!$C$68,"#,##0")&" kg"&CHAR(10)&"Caños y barras: "&TEXT(Materiales!$C$63,"#,##0.0")&" barras" -> MATERIA PRIMA Chapa: 515 hojas Casquetes y cuplas: 9,322 u Polvo ABC 90: 91,919 kg Caños y barras: 783.5 barras | G20: ➜ | H20: ="CORTE Y ROLADO"&CHAR(10)&TEXT(Materiales!$G$75,"#,##0")&" planchuelas"&CHAR(10)&TEXT(Materiales!$G$76,"#,##0")&" virolas" -> CORTE Y ROLADO 3,107 planchuelas 3,107 virolas | M20: ➜ | N20: ="ARMADO Y SOLDADURA"&CHAR(10)&TEXT(Materiales!$G$77,"#,##0")&" recipientes"&CHAR(10)&"accesorios del carro" -> ARMADO Y SOLDADURA 3,107 recipientes accesorios del carro | S20: ➜ | T20: ="PH, SECADO Y PINTURA"&CHAR(10)&TEXT(Materiales!$G$79,"#,##0")&" recipientes"&CHAR(10)&"(pintura tercerizada)" -> PH, SECADO Y PINTURA 3,107 recipientes (pintura tercerizada) | Y20: ➜ | Z20: ="CARGA Y ARMADO"&CHAR(10)&TEXT(Materiales!$G$80,"#,##0")&" carros" -> CARGA Y ARMADO 1,815 carros | AE20: ➜ | AF20: ="PRODUCTO TERMINADO"&CHAR(10)&TEXT(Materiales!$C$101,"#,##0")&" u"&CHAR(10)&"carros 25 a 100 kg y cilindros vacíos" -> PRODUCTO TERMINADO 3,107 u carros 25 a 100 kg y cilindros vacíos | AL20: ="CHECKS "&Resumen!$C$3&""&CHAR(10)&"Producción ≥ demanda: "&IF(Resumen!$G$44=0,"✔","✖ "&Resumen!$G$44&" productos")&CHAR(10)&"Sobrestock: "&TEXT(Resumen!$F$44,"0.0%")&CHAR(10)&"MRP cubre la producción: "&IF(Resumen!$I$44=0,"✔","✖ "&Resumen!$I$44&" productos") -> CHECKS 2035 Producción ≥ demanda: ✔ Sobrestock: 0.2% MRP cubre la producción: ✖ 6 productos
J27: ▼ | P27: ▼ | V27: ▼ | AB27: ▼
H28: ="SCRAP Y MERMAS"&CHAR(10)&"Chatarra de chapa: "&TEXT(Materiales!$C$84,"#,##0")&" kg"&CHAR(10)&"Recorte de caño y barra: "&TEXT(Materiales!$C$85,"#,##0.0")&" m"&CHAR(10)&"Desechos: "&TEXT(Materiales!$C$86,"#,##0.0")&" kg y "&TEXT(Materiales!$C$88,"#,##0")&" abrasivos" -> SCRAP Y MERMAS Chatarra de chapa: 10,012 kg Recorte de caño y barra: 223.5 m Desechos: 69.5 kg y 176 abrasivos
B34: LÍNEA DE RECARGAS
B35: ="MATERIA PRIMA"&CHAR(10)&"Polvos: "&TEXT(Materiales!$C$111,"#,##0")&" kg"&CHAR(10)&"CO₂ y limpio: "&TEXT(Materiales!$C$112,"#,##0")&" kg"&CHAR(10)&"Líquidos: "&TEXT(Materiales!$C$113,"#,##0")&" L"&CHAR(10)&"Repuestos e identificación: "&TEXT(Materiales!$C$116+Materiales!$C$117,"#,##0")&" u" -> MATERIA PRIMA Polvos: 54,828 kg CO₂ y limpio: 2,651 kg Líquidos: 7,926 L Repuestos e identificación: 622,638 u | G35: ➜ | H35: ="RECEPCIÓN Y DESCARGA"&CHAR(10)&TEXT(Materiales!$C$121,"#,##0")&" recibidos"&CHAR(10)&TEXT(Materiales!$C$122,"#,##0")&" descargados" -> RECEPCIÓN Y DESCARGA 115,783 recibidos 106,704 descargados | M35: ➜ | N35: ="DESARME Y PH"&CHAR(10)&TEXT(Materiales!$C$123,"#,##0")&" desarmados"&CHAR(10)&TEXT(Materiales!$C$124,"#,##0")&" con PH" -> DESARME Y PH 109,297 desarmados 30,659 con PH | S35: ➜ | T35: ="SECADO Y PINTURA"&CHAR(10)&TEXT(Materiales!$C$125,"#,##0")&" secados"&CHAR(10)&TEXT(Materiales!$C$126,"#,##0")&" pintados" -> SECADO Y PINTURA 28,526 secados 17,367 pintados | Y35: ➜ | Z35: ="CARGA Y ENSAYO"&CHAR(10)&TEXT(Materiales!$C$127,"#,##0")&" cargados"&CHAR(10)&TEXT(Materiales!$C$128,"#,##0")&" ensayados" -> CARGA Y ENSAYO 100,780 cargados 115,783 ensayados | AE35: ➜ | AF35: ="PRODUCTO TERMINADO"&CHAR(10)&TEXT(Materiales!$C$146,"#,##0")&" recargas"&CHAR(10)&"precintadas y etiquetadas" -> PRODUCTO TERMINADO 107,927 recargas precintadas y etiquetadas | AL35: ="CHECKS "&Resumen!$C$3&""&CHAR(10)&"Producción ≥ demanda: "&IF(Resumen!$G$45=0,"✔","✖ "&Resumen!$G$45&" productos")&CHAR(10)&"Sobrestock: "&TEXT(Resumen!$F$45,"0.0%")&CHAR(10)&"MRP cubre la producción: "&IF(Resumen!$I$45=0,"✔","✖ "&Resumen!$I$45&" productos") -> CHECKS 2035 Producción ≥ demanda: ✔ Sobrestock: 0.7% MRP cubre la producción: ✖ 14 productos
J42: ▼ | P42: ▼ | V42: ▼ | AB42: ▼
H43: ="SCRAP Y MERMAS"&CHAR(10)&"Polvo a descarte: "&TEXT(Materiales!$C$133,"#,##0")&" kg"&CHAR(10)&"Líquidos: "&TEXT(Materiales!$C$134,"#,##0")&" L"&CHAR(10)&"Equipos inutilizados: "&TEXT(Materiales!$C$135,"#,##0")&" (chatarra)" -> SCRAP Y MERMAS Polvo a descarte: 54,828 kg Líquidos: 48,916 L Equipos inutilizados: 9,114 (chatarra)
B49: REVENDIDOS
B50: ="COMPRA"&CHAR(10)&TEXT(Materiales!$C$159,"#,##0")&" equipos" -> COMPRA 18,027 equipos | G50: ➜ | H50: ="VENTA"&CHAR(10)&TEXT(Materiales!$C$159,"#,##0")&" equipos" -> VENTA 18,027 equipos

Sheet Esquema linea
A1: ESQUEMA DEL BALANCEO DE LÍNEA (año elegido en Resumen) — cada caja es un puesto, en orden de proceso
A2: Color por aprovechamiento: verde < 75 % · amarillo 75 a 90 % · rojo ≥ 90 % (umbral). El borde grueso marca el cuello de botella. Los números salen de la hoja Linea.
B4: LÍNEA DE MANUALES | N4: ="Takt "&TEXT(Linea!$C$8,"#,##0.0")&" s/u · contenido "&TEXT(Linea!$C$9,"#,##0.0")&" s/u · eficiencia de balanceo "&TEXT(Linea!$C$15,"0%")&" · cuello: "&Linea!$C$13&" ("&TEXT(Linea!$C$14,"0%")&")" -> Takt 16.2 s/u · contenido 754.1 s/u · eficiencia de balanceo 78% · cuello: Soldadura longitudinal — 2,5 a 10 kg (79%)
B5: =Linea!$A$19&". "&Linea!$B$19&CHAR(10)&Linea!$I$19&" recurso(s)" -> 1. Recepción de materia prima 4 recurso(s) | I5: =Linea!$A$20&". "&Linea!$B$20&CHAR(10)&Linea!$I$20&" recurso(s)" -> 2. Corte de chapa — 1.er corte en franjas (guillotina 1, manuales + carros) 1 recurso(s) | P5: =Linea!$A$21&". "&Linea!$B$21&CHAR(10)&Linea!$I$21&" recurso(s)" -> 3. Corte de chapa — 2.º corte en piezas (guillotina 2, manuales + carros) 1 recurso(s) | W5: =Linea!$A$22&". "&Linea!$B$22&CHAR(10)&Linea!$I$22&" recurso(s)" -> 4. Corte de disco y embutido (cúpula y fondo) 2 recurso(s) | AD5: =Linea!$A$23&". "&Linea!$B$23&CHAR(10)&Linea!$I$23&" recurso(s)" -> 5. Preparación de cuello 4 recurso(s) | AK5: =Linea!$A$24&". "&Linea!$B$24&CHAR(10)&Linea!$I$24&" recurso(s)" -> 6. Numerado de cúpula 2 recurso(s)
H6: ➜ | O6: ➜ | V6: ➜ | AC6: ➜ | AJ6: ➜
B8: =Linea!$J$19 -> 0.71115641 | I8: =Linea!$J$20 -> 0.34440579 | P8: =Linea!$J$21 -> 0.25565166 | W8: =Linea!$J$22 -> 0.55776973 | AD8: =Linea!$J$23 -> 0.71115641 | AK8: =Linea!$J$24 -> 0.47410427
AM9: ⬇
B10: =Linea!$A$30&". "&Linea!$B$30&CHAR(10)&Linea!$I$30&" recurso(s)" -> 12. Bordoneado 2 recurso(s) | I10: =Linea!$A$29&". "&Linea!$B$29&CHAR(10)&Linea!$I$29&" recurso(s)" -> 11. Encastre de fondo 2 recurso(s) | P10: =Linea!$A$28&". "&Linea!$B$28&CHAR(10)&Linea!$I$28&" recurso(s)" -> 10. Soldadura longitudinal TIG — 1 kg 2 recurso(s) | W10: =Linea!$A$27&". "&Linea!$B$27&CHAR(10)&Linea!$I$27&" recurso(s)" -> 9. Soldadura longitudinal — 2,5 a 10 kg 2 recurso(s) | AD10: =Linea!$A$26&". "&Linea!$B$26&CHAR(10)&Linea!$I$26&" recurso(s)" -> 8. Cilindrado 1 recurso(s) | AK10: =Linea!$A$25&". "&Linea!$B$25&CHAR(10)&Linea!$I$25&" recurso(s)" -> 7. Soldadura del cuello a la cúpula 2 recurso(s)
H11: ⬅ | O11: ⬅ | V11: ⬅ | AC11: ⬅ | AJ11: ⬅
B13: =Linea!$J$30 -> 0.48268535 | I13: =Linea!$J$29 -> 0.72402802 | P13: =Linea!$J$28 -> 0.5065516 | W13: =Linea!$J$27 -> 0.79491735 | AD13: =Linea!$J$26 -> 0.72076663 | AK13: =Linea!$J$25 -> 0.60886679
D14: ⬇
B15: =Linea!$A$31&". "&Linea!$B$31&CHAR(10)&Linea!$I$31&" recurso(s)" -> 13. Soldadura circunferencial de cúpula y fondo 4 recurso(s) | I15: =Linea!$A$32&". "&Linea!$B$32&CHAR(10)&Linea!$I$32&" recurso(s)" -> 14. Control de calidad — Espesor 1 recurso(s) | P15: =Linea!$A$33&". "&Linea!$B$33&CHAR(10)&Linea!$I$33&" recurso(s)" -> 15. Prueba hidráulica 4 recurso(s) | W15: =Linea!$A$34&". "&Linea!$B$34&CHAR(10)&Linea!$I$34&" recurso(s)" -> 16. Secado 8 recurso(s) | AD15: =Linea!$A$35&". "&Linea!$B$35&CHAR(10)&Linea!$I$35&" recurso(s)" -> 17. Granallado 2 recurso(s) | AK15: =Linea!$A$36&". "&Linea!$B$36&CHAR(10)&Linea!$I$36&" recurso(s)" -> 18. Detección de defectos 2 recurso(s)
H16: ➜ | O16: ➜ | V16: ➜ | AC16: ➜ | AJ16: ➜
B18: =Linea!$J$31 -> 0.72402802 | I18: =Linea!$J$32 -> 0.11378503 | P18: =Linea!$J$33 -> 0.72402802 | W18: =Linea!$J$34 -> 0.71115641 | AD18: =Linea!$J$35 -> 0.71115641 | AK18: =Linea!$J$36 -> 0.47410427
AM19: ⬇
B20: =Linea!$A$42&". "&Linea!$B$42&CHAR(10)&Linea!$I$42&" recurso(s)" -> 24. Control de calidad — Ensayo de pérdidas 1 recurso(s) | I20: =Linea!$A$41&". "&Linea!$B$41&CHAR(10)&Linea!$I$41&" recurso(s)" -> 23. Presurización 1 recurso(s) | P20: =Linea!$A$40&". "&Linea!$B$40&CHAR(10)&Linea!$I$40&" recurso(s)" -> 22. Ensamblaje 2 recurso(s) | W20: =Linea!$A$39&". "&Linea!$B$39&CHAR(10)&Linea!$I$39&" recurso(s)" -> 21. Carga de polvo 1 recurso(s) | AD20: =Linea!$A$38&". "&Linea!$B$38&CHAR(10)&Linea!$I$38&" recurso(s)" -> 20. Pintura en polvo + horno 2 recurso(s) | AK20: =Linea!$A$37&". "&Linea!$B$37&CHAR(10)&Linea!$I$37&" recurso(s)" -> 19. Corrección de defectos 1 recurso(s)
H21: ⬅ | O21: ⬅ | V21: ⬅ | AC21: ⬅ | AJ21: ⬅
B23: =Linea!$J$42 -> 0.4811267 | I23: =Linea!$J$41 -> 0.36084502 | P23: =Linea!$J$40 -> 0.61229359 | W23: =Linea!$J$39 -> 0.54126753 | AD23: =Linea!$J$38 -> 0.62601797 | AK23: =Linea!$J$37 -> 0.42669385
D24: ⬇
B25: =Linea!$A$43&". "&Linea!$B$43&CHAR(10)&Linea!$I$43&" recurso(s)" -> 25. Etiquetado 1 recurso(s) | I25: =Linea!$A$44&". "&Linea!$B$44&CHAR(10)&Linea!$I$44&" recurso(s)" -> 26. Embalaje y paletizado 4 recurso(s)
H26: ➜
B28: =Linea!$J$43 -> 0.72169004 | I28: =Linea!$J$44 -> 0.53815087
B32: LÍNEA DE CARROS | N32: ="Takt "&TEXT(Linea!$C$52,"#,##0.0")&" s/u · contenido "&TEXT(Linea!$C$53,"#,##0.0")&" s/u · eficiencia de balanceo "&TEXT(Linea!$C$59,"0%")&" · cuello: "&Linea!$C$57&" ("&TEXT(Linea!$C$58,"0%")&")" -> Takt 1,930.9 s/u · contenido 6,202.1 s/u · eficiencia de balanceo 43% · cuello: Soldadura de accesorios (52%)
B33: =Linea!$A$63&". "&Linea!$B$63&CHAR(10)&Linea!$I$63&" recurso(s)" -> 1. Recepción de materia prima 1 recurso(s) | I33: =Linea!$A$64&". "&Linea!$B$64&CHAR(10)&Linea!$I$64&" recurso(s)" -> 2. Corte de chapa (guillotina) 1 recurso(s) | P33: =Linea!$A$65&". "&Linea!$B$65&CHAR(10)&Linea!$I$65&" recurso(s)" -> 3. Marcado del cuerpo 1 recurso(s) | W33: =Linea!$A$66&". "&Linea!$B$66&CHAR(10)&Linea!$I$66&" recurso(s)" -> 4. Cilindrado 1 recurso(s) | AD33: =Linea!$A$67&". "&Linea!$B$67&CHAR(10)&Linea!$I$67&" recurso(s)" -> 5. Punteo del cuerpo 1 recurso(s) | AK33: =Linea!$A$68&". "&Linea!$B$68&CHAR(10)&Linea!$I$68&" recurso(s)" -> 6. Soldadura longitudinal 1 recurso(s)
H34: ➜ | O34: ➜ | V34: ➜ | AC34: ➜ | AJ34: ➜
B36: =Linea!$J$63 -> 0.10349913 | I36: =Linea!$J$64 -> 0.17603599 | P36: =Linea!$J$65 -> 0.060696783 | W36: =Linea!$J$66 -> 0.14374045 | AD36: =Linea!$J$67 -> 0.16491995 | AK36: =Linea!$J$68 -> 0.12344906
AM37: ⬇
B38: =Linea!$A$74&". "&Linea!$B$74&CHAR(10)&Linea!$I$74&" recurso(s)" -> 12. Secado 1 recurso(s) | I38: =Linea!$A$73&". "&Linea!$B$73&CHAR(10)&Linea!$I$73&" recurso(s)" -> 11. Prueba hidráulica 1 recurso(s) | P38: =Linea!$A$72&". "&Linea!$B$72&CHAR(10)&Linea!$I$72&" recurso(s)" -> 10. Fabricación de accesorios 1 recurso(s) | W38: =Linea!$A$71&". "&Linea!$B$71&CHAR(10)&Linea!$I$71&" recurso(s)" -> 9. Soldadura de accesorios 1 recurso(s) | AD38: =Linea!$A$70&". "&Linea!$B$70&CHAR(10)&Linea!$I$70&" recurso(s)" -> 8. Armado y soldadura circunferencial 1 recurso(s) | AK38: =Linea!$A$69&". "&Linea!$B$69&CHAR(10)&Linea!$I$69&" recurso(s)" -> 7. Soldadura de cupla en la cúpula 1 recurso(s)
H39: ⬅ | O39: ⬅ | V39: ⬅ | AC39: ⬅ | AJ39: ⬅
B41: =Linea!$J$74 -> 0.31256646 | I41: =Linea!$J$73 -> 0.30125591 | P41: =Linea!$J$72 -> 0.37513877 | W41: =Linea!$J$71 -> 0.5230764 | AD41: =Linea!$J$70 -> 0.51375531 | AK41: =Linea!$J$69 -> 0.12440692
D42: ⬇
B43: =Linea!$A$75&". "&Linea!$B$75&CHAR(10)&Linea!$I$75&" recurso(s)" -> 13. Pulmón de despacho y carga a pintura 1 recurso(s) | I43: =Linea!$A$76&". "&Linea!$B$76&CHAR(10)&Linea!$I$76&" recurso(s)" -> 14. Recepción de pintados y cambio de juego 1 recurso(s) | P43: =Linea!$A$77&". "&Linea!$B$77&CHAR(10)&Linea!$I$77&" recurso(s)" -> 15. Carga de polvo y presurización 1 recurso(s) | W43: =Linea!$A$78&". "&Linea!$B$78&CHAR(10)&Linea!$I$78&" recurso(s)" -> 16. Montaje, manga, precinto y etiquetado 1 recurso(s) | AD43: =Linea!$A$79&". "&Linea!$B$79&CHAR(10)&Linea!$I$79&" recurso(s)" -> 17. Calidad: pérdidas, inspección final, liberación y ensayos de lote 1 recurso(s) | AK43: =Linea!$A$80&". "&Linea!$B$80&CHAR(10)&Linea!$I$80&" recurso(s)" -> 18. Depósito de producto terminado y despacho 1 recurso(s)
H44: ➜ | O44: ➜ | V44: ➜ | AC44: ➜ | AJ44: ➜
B46: =Linea!$J$75 -> 0.058606883 | I46: =Linea!$J$76 -> 0.10614908 | P46: =Linea!$J$77 -> 0.31227327 | W46: =Linea!$J$78 -> 0.16135546 | AD46: =Linea!$J$79 -> 0.4571455 | AK46: =Linea!$J$80 -> 0.064482699
B50: LÍNEA DE RECARGAS | N50: ="Takt "&TEXT(Linea!$C$88,"#,##0.0")&" s/u · contenido "&TEXT(Linea!$C$89,"#,##0.0")&" s/u · eficiencia de balanceo "&TEXT(Linea!$C$95,"0%")&" · cuello: "&Linea!$C$93&" ("&TEXT(Linea!$C$94,"0%")&")" -> Takt 48.6 s/u · contenido 1,184.2 s/u · eficiencia de balanceo 59% · cuello: Ensayo de pérdidas (87%)
B51: =Linea!$A$99&". "&Linea!$B$99&CHAR(10)&Linea!$I$99&" recurso(s)" -> 1. Recepción y registro 2 recurso(s) | I51: =Linea!$A$100&". "&Linea!$B$100&CHAR(10)&Linea!$I$100&" recurso(s)" -> 2. Inspección visual 4 recurso(s) | P51: =Linea!$A$101&". "&Linea!$B$101&CHAR(10)&Linea!$I$101&" recurso(s)" -> 3. Descarga ABC — ruta recuperable 2 recurso(s) | W51: =Linea!$A$102&". "&Linea!$B$102&CHAR(10)&Linea!$I$102&" recurso(s)" -> 4. Descarga a descarte (ABC, BC y Clase D) 1 recurso(s) | AD51: =Linea!$A$103&". "&Linea!$B$103&CHAR(10)&Linea!$I$103&" recurso(s)" -> 5. Descarga y carga de agua / AFFF / sales K 1 recurso(s) | AK51: =Linea!$A$104&". "&Linea!$B$104&CHAR(10)&Linea!$I$104&" recurso(s)" -> 6. Recuperación y carga de CO₂ 1 recurso(s)
H52: ➜ | O52: ➜ | V52: ➜ | AC52: ➜ | AJ52: ➜
B54: =Linea!$J$99 -> 0.81813919 | I54: =Linea!$J$100 -> 0.49088352 | P54: =Linea!$J$101 -> 0.7069479 | W54: =Linea!$J$102 -> 0.16045446 | AD54: =Linea!$J$103 -> 0.19268982 | AK54: =Linea!$J$104 -> 0.24142776
AM55: ⬇
B56: =Linea!$A$110&". "&Linea!$B$110&CHAR(10)&Linea!$I$110&" recurso(s)" -> 12. Secado 2 recurso(s) | I56: =Linea!$A$109&". "&Linea!$B$109&CHAR(10)&Linea!$I$109&" recurso(s)" -> 11. Prueba hidráulica 2 recurso(s) | P56: =Linea!$A$108&". "&Linea!$B$108&CHAR(10)&Linea!$I$108&" recurso(s)" -> 10. Laboratorio — Puffer y mufla 1 recurso(s) | W56: =Linea!$A$107&". "&Linea!$B$107&CHAR(10)&Linea!$I$107&" recurso(s)" -> 9. Desarme e inspección interior — zona general 1 recurso(s) | AD56: =Linea!$A$106&". "&Linea!$B$106&CHAR(10)&Linea!$I$106&" recurso(s)" -> 8. Desarme y limpieza — recinto 4 recurso(s) | AK56: =Linea!$A$105&". "&Linea!$B$105&CHAR(10)&Linea!$I$105&" recurso(s)" -> 7. Recuperación y carga de halogenado 1 recurso(s)
...

Sheet Materiales
A1: BALANCE DE MATERIALES (año elegido en Resumen)
A2: 1) materia prima que entra · 2) semielaborados en proceso · 3) scrap, desechos y mermas · 4) producto terminado. Cantidades = lo que pide la producción del año (MP_detalle).
A4: LÍNEA DE MANUALES (1 a 10 kg)
A5: 1) Materia prima que entra
A6: Familia | B6: Formato de compra | C6: Cantidad | D6: UM | E6: Unidades de compra | F6: kg
A7: Chapa en hojas | B7: =IFERROR(INDEX(MP_detalle!$F$7:$F$66,MATCH("Chapa en hojas",MP_detalle!$B$7:$B$66,0)),"") -> Paquete de 50 hojas | C7: =SUMIFS(MP_detalle!$H$7:$H$66,MP_detalle!$B$7:$B$66,"Chapa en hojas") -> 10604.462 | D7: hojas | E7: =SUMIFS(MP_detalle!$L$7:$L$66,MP_detalle!$B$7:$B$66,"Chapa en hojas") -> 179.90718 | F7: =SUMIFS(MP_detalle!$N$7:$N$66,MP_detalle!$B$7:$B$66,"Chapa en hojas") -> 261838.11
A8: Fleje en rollos | B8: =IFERROR(INDEX(MP_detalle!$F$7:$F$66,MATCH("Fleje en rollos",MP_detalle!$B$7:$B$66,0)),"") -> Rollo de 1.900 kg | C8: =SUMIFS(MP_detalle!$H$7:$H$66,MP_detalle!$B$7:$B$66,"Fleje en rollos") -> 100700.72 | D8: kg | E8: =SUMIFS(MP_detalle!$L$7:$L$66,MP_detalle!$B$7:$B$66,"Fleje en rollos") -> 142.79836 | F8: =SUMIFS(MP_detalle!$N$7:$N$66,MP_detalle!$B$7:$B$66,"Fleje en rollos") -> 100700.72
A9: Asientos de válvula | B9: =IFERROR(INDEX(MP_detalle!$F$7:$F$66,MATCH("Asientos de válvula",MP_detalle!$B$7:$B$66,0)),"") -> Caja de 1.000 u | C9: =SUMIFS(MP_detalle!$H$7:$H$66,MP_detalle!$B$7:$B$66,"Asientos de válvula") -> 284462.56 | D9: u | E9: =SUMIFS(MP_detalle!$L$7:$L$66,MP_detalle!$B$7:$B$66,"Asientos de válvula") -> 284.46256 | F9: =SUMIFS(MP_detalle!$N$7:$N$66,MP_detalle!$B$7:$B$66,"Asientos de válvula") -> 0
A10: Soldadura: alambre | B10: =IFERROR(INDEX(MP_detalle!$F$7:$F$66,MATCH("Soldadura: alambre",MP_detalle!$B$7:$B$66,0)),"") -> Pallet de 900 kg | C10: =SUMIFS(MP_detalle!$H$7:$H$66,MP_detalle!$B$7:$B$66,"Soldadura: alambre") -> 5990.0382 | D10: kg | E10: =SUMIFS(MP_detalle!$L$7:$L$66,MP_detalle!$B$7:$B$66,"Soldadura: alambre") -> 6.655598 | F10: =SUMIFS(MP_detalle!$N$7:$N$66,MP_detalle!$B$7:$B$66,"Soldadura: alambre") -> 5990.0382
A11: Soldadura: gases | B11: =IFERROR(INDEX(MP_detalle!$F$7:$F$66,MATCH("Soldadura: gases",MP_detalle!$B$7:$B$66,0)),"") -> Batería de 11 cilindros | C11: =SUMIFS(MP_detalle!$H$7:$H$66,MP_detalle!$B$7:$B$66,"Soldadura: gases") -> 8198.9088 | D11: m³ | E11: =SUMIFS(MP_detalle!$L$7:$L$66,MP_detalle!$B$7:$B$66,"Soldadura: gases") -> 140.29827 | F11: =SUMIFS(MP_detalle!$N$7:$N$66,MP_detalle!$B$7:$B$66,"Soldadura: gases") -> 0
A12: Soldadura: electrodo TIG | B12: =IFERROR(INDEX(MP_detalle!$F$7:$F$66,MATCH("Soldadura: electrodo TIG",MP_detalle!$B$7:$B$66,0)),"") -> Caja de 10 u | C12: =SUMIFS(MP_detalle!$H$7:$H$66,MP_detalle!$B$7:$B$66,"Soldadura: electrodo TIG") -> 166.62882 | D12: u | E12: =SUMIFS(MP_detalle!$L$7:$L$66,MP_detalle!$B$7:$B$66,"Soldadura: electrodo TIG") -> 16.662882 | F12: =SUMIFS(MP_detalle!$N$7:$N$66,MP_detalle!$B$7:$B$66,"Soldadura: electrodo TIG") -> 0
A13: Granalla | B13: =IFERROR(INDEX(MP_detalle!$F$7:$F$66,MATCH("Granalla",MP_detalle!$B$7:$B$66,0)),"") -> Pallet de 1.000 kg | C13: =SUMIFS(MP_detalle!$H$7:$H$66,MP_detalle!$B$7:$B$66,"Granalla") -> 22757.005 | D13: kg | E13: =SUMIFS(MP_detalle!$L$7:$L$66,MP_detalle!$B$7:$B$66,"Granalla") -> 22.757005 | F13: =SUMIFS(MP_detalle!$N$7:$N$66,MP_detalle!$B$7:$B$66,"Granalla") -> 22757.005
A14: Pintura | B14: =IFERROR(INDEX(MP_detalle!$F$7:$F$66,MATCH("Pintura",MP_detalle!$B$7:$B$66,0)),"") -> Pallet de 600 kg | C14: =SUMIFS(MP_detalle!$H$7:$H$66,MP_detalle!$B$7:$B$66,"Pintura") -> 3581.9354 | D14: kg | E14: =SUMIFS(MP_detalle!$L$7:$L$66,MP_detalle!$B$7:$B$66,"Pintura") -> 5.9698923 | F14: =SUMIFS(MP_detalle!$N$7:$N$66,MP_detalle!$B$7:$B$66,"Pintura") -> 3581.9354
A15: Agente: polvo | B15: =IFERROR(INDEX(MP_detalle!$F$7:$F$66,MATCH("Agente: polvo",MP_detalle!$B$7:$B$66,0)),"") -> Big bag de 1.000 kg | C15: =SUMIFS(MP_detalle!$H$7:$H$66,MP_detalle!$B$7:$B$66,"Agente: polvo") -> 230062.4 | D15: kg | E15: =SUMIFS(MP_detalle!$L$7:$L$66,MP_detalle!$B$7:$B$66,"Agente: polvo") -> 230.0624 | F15: =SUMIFS(MP_detalle!$N$7:$N$66,MP_detalle!$B$7:$B$66,"Agente: polvo") -> 230062.4
A16: Nitrógeno | B16: =IFERROR(INDEX(MP_detalle!$F$7:$F$66,MATCH("Nitrógeno",MP_detalle!$B$7:$B$66,0)),"") -> Pack de 12 cilindros | C16: =SUMIFS(MP_detalle!$H$7:$H$66,MP_detalle!$B$7:$B$66,"Nitrógeno") -> 1268.5157 | D16: m³ | E16: =SUMIFS(MP_detalle!$L$7:$L$66,MP_detalle!$B$7:$B$66,"Nitrógeno") -> 11.531961 | F16: =SUMIFS(MP_detalle!$N$7:$N$66,MP_detalle!$B$7:$B$66,"Nitrógeno") -> 0
A17: Componentes comprados | B17: =IFERROR(INDEX(MP_detalle!$F$7:$F$66,MATCH("Componentes comprados",MP_detalle!$B$7:$B$66,0)),"") & " (varios)" -> Pallet de 3.000 u (varios) | C17: =SUMIFS(MP_detalle!$H$7:$H$66,MP_detalle!$B$7:$B$66,"Componentes comprados") -> 693427.68 | D17: u | E17: =SUMIFS(MP_detalle!$L$7:$L$66,MP_detalle!$B$7:$B$66,"Componentes comprados") -> 3319.4842 | F17: =SUMIFS(MP_detalle!$N$7:$N$66,MP_detalle!$B$7:$B$66,"Componentes comprados") -> 0
A18: Identificación y embalaje | B18: =IFERROR(INDEX(MP_detalle!$F$7:$F$66,MATCH("Identificación y embalaje",MP_detalle!$B$7:$B$66,0)),"") & " (varios)" -> Rollo de 1.000 u (varios) | C18: =SUMIFS(MP_detalle!$H$7:$H$66,MP_detalle!$B$7:$B$66,"Identificación y embalaje") -> 1421744.6 | D18: u | E18: =SUMIFS(MP_detalle!$L$7:$L$66,MP_detalle!$B$7:$B$66,"Identificación y embalaje") -> 2052.1905 | F18: =SUMIFS(MP_detalle!$N$7:$N$66,MP_detalle!$B$7:$B$66,"Identificación y embalaje") -> 0
A20: 2) Semielaborados en proceso
A21: Etapa | B21: Formato | C21: ABC 1 kg | D21: ABC 2,5 kg | E21: ABC 5 kg | F21: ABC 10 kg | G21: Total (u) | H21: kg de acero
A22: Planchuela de cuerpo cortada | B22: Rectángulo de chapa: desarrollo × alto (Piezas) | C22: =1*(Resumen!$D$7+Resumen!$D$11) -> 202620.64 | D22: =1*(Resumen!$D$8+Resumen!$D$12) -> 14126.338 | E22: =1*(Resumen!$D$9+Resumen!$D$13) -> 63852.659 | F22: =1*(Resumen!$D$10+Resumen!$D$14) -> 3862.9281 | G22: =SUM(C22:F22) -> 284462.56 | H22: =(Resumen!$D$7+Resumen!$D$11)*Links!$F$2202+(Resumen!$D$8+Resumen!$D$12)*Links!$F$2203+(Resumen!$D$9+Resumen!$D$13)*Links!$F$2204+(Resumen!$D$10+Resumen!$D$14)*Links!$F$2205 -> 245881.85
A23: Discos de cúpula y fondo | B23: Disco plano Ø D0 desde fleje (2 por recipiente) | C23: =2*(Resumen!$D$7+Resumen!$D$11) -> 405241.28 | D23: =2*(Resumen!$D$8+Resumen!$D$12) -> 28252.677 | E23: =2*(Resumen!$D$9+Resumen!$D$13) -> 127705.32 | F23: =2*(Resumen!$D$10+Resumen!$D$14) -> 7725.8562 | G23: =SUM(C23:F23) -> 568925.13 | H23: =(Resumen!$D$7+Resumen!$D$11)*((PI()*Links!$J$2212^2/4*Links!$B$2212*7.85/1000000)+(PI()*Links!$J$2213^2/4*Links!$B$2213*7.85/1000000))+(Resumen!$D$8+Resumen!$D$12)*((PI()*Links!$J$2214^2/4*Links!$B$2214*7.85/1000000)+(PI()*Links!$J$2215^2/4*Links!$B$2215*7.85/1000000))+(Resumen!$D$9+Resumen!$D$13)*((PI()*Links!$J$2216^2/4*Links!$B$2216*7.85/1000000)+(PI()*Links!$J$2217^2/4*Links!$B$2217*7.85/1000000))+(Resumen!$D$10+Resumen!$D$14)*((PI()*Links!$J$2218^2/4*Links!$B$2218*7.85/1000000)+(PI()*Links!$J$2219^2/4*Links!$B$2219*7.85/1000000)) -> 74334.72
A24: Casquetes embutidos (cúpula numerada con cuello, fondo) | B24: Casquete embutido | C24: =2*(Resumen!$D$7+Resumen!$D$11) -> 405241.28 | D24: =2*(Resumen!$D$8+Resumen!$D$12) -> 28252.677 | E24: =2*(Resumen!$D$9+Resumen!$D$13) -> 127705.32 | F24: =2*(Resumen!$D$10+Resumen!$D$14) -> 7725.8562 | G24: =SUM(C24:F24) -> 568925.13 | H24: =(Resumen!$D$7+Resumen!$D$11)*((PI()*Links!$J$2212^2/4*Links!$B$2212*7.85/1000000)+(PI()*Links!$J$2213^2/4*Links!$B$2213*7.85/1000000))+(Resumen!$D$8+Resumen!$D$12)*((PI()*Links!$J$2214^2/4*Links!$B$2214*7.85/1000000)+(PI()*Links!$J$2215^2/4*Links!$B$2215*7.85/1000000))+(Resumen!$D$9+Resumen!$D$13)*((PI()*Links!$J$2216^2/4*Links!$B$2216*7.85/1000000)+(PI()*Links!$J$2217^2/4*Links!$B$2217*7.85/1000000))+(Resumen!$D$10+Resumen!$D$14)*((PI()*Links!$J$2218^2/4*Links!$B$2218*7.85/1000000)+(PI()*Links!$J$2219^2/4*Links!$B$2219*7.85/1000000)) -> 74334.72
A25: Virola cilindrada y soldada | B25: Tubo con costura longitudinal | C25: =1*(Resumen!$D$7+Resumen!$D$11) -> 202620.64 | D25: =1*(Resumen!$D$8+Resumen!$D$12) -> 14126.338 | E25: =1*(Resumen!$D$9+Resumen!$D$13) -> 63852.659 | F25: =1*(Resumen!$D$10+Resumen!$D$14) -> 3862.9281 | G25: =SUM(C25:F25) -> 284462.56 | H25: =(Resumen!$D$7+Resumen!$D$11)*Links!$F$2202+(Resumen!$D$8+Resumen!$D$12)*Links!$F$2203+(Resumen!$D$9+Resumen!$D$13)*Links!$F$2204+(Resumen!$D$10+Resumen!$D$14)*Links!$F$2205 -> 245881.85
A26: Recipiente soldado (PH, secado, granallado) | B26: Recipiente cerrado sin pintar | C26: =1*(Resumen!$D$7+Resumen!$D$11) -> 202620.64 | D26: =1*(Resumen!$D$8+Resumen!$D$12) -> 14126.338 | E26: =1*(Resumen!$D$9+Resumen!$D$13) -> 63852.659 | F26: =1*(Resumen!$D$10+Resumen!$D$14) -> 3862.9281 | G26: =SUM(C26:F26) -> 284462.56 | H26: =(Resumen!$D$7+Resumen!$D$11)*(Links!$F$2202+((PI()*Links!$J$2212^2/4*Links!$B$2212*7.85/1000000)+(PI()*Links!$J$2213^2/4*Links!$B$2213*7.85/1000000)))+(Resumen!$D$8+Resumen!$D$12)*(Links!$F$2203+((PI()*Links!$J$2214^2/4*Links!$B$2214*7.85/1000000)+(PI()*Links!$J$2215^2/4*Links!$B$2215*7.85/1000000)))+(Resumen!$D$9+Resumen!$D$13)*(Links!$F$2204+((PI()*Links!$J$2216^2/4*Links!$B$2216*7.85/1000000)+(PI()*Links!$J$2217^2/4*Links!$B$2217*7.85/1000000)))+(Resumen!$D$10+Resumen!$D$14)*(Links!$F$2205+((PI()*Links!$J$2218^2/4*Links!$B$2218*7.85/1000000)+(PI()*Links!$J$2219^2/4*Links!$B$2219*7.85/1000000))) -> 320216.57
A27: Recipiente pintado | B27: Cilindro pintado rojo | C27: =1*(Resumen!$D$7+Resumen!$D$11) -> 202620.64 | D27: =1*(Resumen!$D$8+Resumen!$D$12) -> 14126.338 | E27: =1*(Resumen!$D$9+Resumen!$D$13) -> 63852.659 | F27: =1*(Resumen!$D$10+Resumen!$D$14) -> 3862.9281 | G27: =SUM(C27:F27) -> 284462.56 | H27: =(Resumen!$D$7+Resumen!$D$11)*(Links!$F$2202+((PI()*Links!$J$2212^2/4*Links!$B$2212*7.85/1000000)+(PI()*Links!$J$2213^2/4*Links!$B$2213*7.85/1000000)))+(Resumen!$D$8+Resumen!$D$12)*(Links!$F$2203+((PI()*Links!$J$2214^2/4*Links!$B$2214*7.85/1000000)+(PI()*Links!$J$2215^2/4*Links!$B$2215*7.85/1000000)))+(Resumen!$D$9+Resumen!$D$13)*(Links!$F$2204+((PI()*Links!$J$2216^2/4*Links!$B$2216*7.85/1000000)+(PI()*Links!$J$2217^2/4*Links!$B$2217*7.85/1000000)))+(Resumen!$D$10+Resumen!$D$14)*(Links!$F$2205+((PI()*Links!$J$2218^2/4*Links!$B$2218*7.85/1000000)+(PI()*Links!$J$2219^2/4*Links!$B$2219*7.85/1000000))) -> 320216.57
A28: Matafuego cargado y presurizado (antes de etiquetar) | B28: Recipiente + válvula + polvo + N₂ | C28: =Resumen!$D$7 -> 32072.639 | D28: =Resumen!$D$8 -> 7436.4584 | E28: =Resumen!$D$9 -> 30814.979 | F28: =Resumen!$D$10 -> 1844.9281 | G28: =SUM(C28:F28) -> 72169.004
A30: 3) Scrap, desechos no recuperables y mermas
A31: Qué | B31: De dónde sale | C31: Cantidad | D31: UM | E31: ¿Se recupera? | F31: Destino / formato
A32: Recortes de hoja | B32: Corte en guillotinas | C32: =SUMIFS(MP_detalle!$N$7:$N$66,MP_detalle!$B$7:$B$66,"Chapa en hojas")-H22 -> 15956.261 | D32: kg | E32: Sí: chatarra | F32: Contenedor de chatarra (playa de scrap)
A33: Esqueleto de fleje y despunte | B33: Corte de disco y embutido | C33: =SUMIFS(MP_detalle!$N$7:$N$66,MP_detalle!$B$7:$B$66,"Fleje en rollos")-H23 -> 26365.995 | D33: kg | E33: Sí: chatarra | F33: Contenedor de chatarra
A34: Salpicadura de soldadura | B34: Soldaduras MAG | C34: =SUMIFS(MP_detalle!$H$7:$H$66,MP_detalle!$B$7:$B$66,"Soldadura: alambre")*0.05 -> 299.50191 | D34: kg | E34: No | F34: Residuo (5% del alambre: BOM, rendimiento ESAB)
A35: Gas de protección y argón | B35: Soldaduras MAG y TIG | C35: =SUMIFS(MP_detalle!$H$7:$H$66,MP_detalle!$B$7:$B$66,"Soldadura: gases") -> 8198.9088 | D35: m³ | E35: No (se consume) | F35: Merma: queda en el ambiente de soldadura
A36: Electrodo de tungsteno gastado | B36: Soldadura TIG del 1 kg | C36: =SUMIFS(MP_detalle!$H$7:$H$66,MP_detalle!$B$7:$B$66,"Soldadura: electrodo TIG") -> 166.62882 | D36: u | E36: No | F36: Residuo (criterio a medir: MRP)
A37: Granalla gastada y óxido | B37: Granallado | C37: =SUMIFS(MP_detalle!$H$7:$H$66,MP_detalle!$B$7:$B$66,"Granalla") -> 22757.005 | D37: kg | E37: No | F37: Residuo del colector de la granalladora
A38: Polvo de pintura no recuperado | B38: Cabina de pintura | C38: =SUMIFS(MP_detalle!$H$7:$H$66,MP_detalle!$B$7:$B$66,"Pintura")*0.05 -> 179.09677 | D38: kg | E38: No | F38: Residuo (5%: el resto se recupera en la cabina)
A39: Polvo ABC de carga | B39: Carga de polvo | C39: =0 -> 0 | D39: kg | E39: — | F39: El proceso de manuales no agrega merma (MRP)
A41: 4) Producto terminado
A42: Producto | B42: Formato | C42: Unidades
A43: Matafuego ABC 1 kg | B43: Embalado en caja, en pallet | C43: =Resumen!$D$7 -> 32072.639
A44: Matafuego ABC 2,5 kg | B44: Embalado en caja, en pallet | C44: =Resumen!$D$8 -> 7436.4584
...

Sheet MP_detalle
A1: CASCADA DEL MRP: compra de cada material contra lo que pide la producción (año elegido)
A2: Necesario = consumo por unidad del MRP × producción de cada producto (Resumen). Si el MRP compra menos de lo necesario, el balance no cierra para esa producción.
A4: MANUALES
A5: Producción | B5: (mismo orden que el MRP) → | O5: =Resumen!$D$7 -> 32072.639 | P5: =Resumen!$D$8 -> 7436.4584 | Q5: =Resumen!$D$9 -> 30814.979 | R5: =Resumen!$D$10 -> 1844.9281 | S5: =Resumen!$D$11 -> 170548 | T5: =Resumen!$D$12 -> 6689.88 | U5: =Resumen!$D$13 -> 33037.68 | V5: =Resumen!$D$14 -> 2018
A6: Línea | B6: Familia | C6: Código | D6: Material | E6: UM | F6: Formato de compra | G6: Compra MRP | H6: Necesario para la producción | I6: Compra − necesario | J6: ¿Cubre? | K6: Contenido de la unidad de compra | L6: Unidades de compra necesarias | M6: kg por UM | N6: kg necesarios
A7: MANUALES | B7: Chapa en hojas | C7: =Links!$B$61 -> MP-01 | D7: =Links!$C$61 -> Hoja LAF 0,9 × 1220 × 2440 mm (cuerpo 1 kg) | E7: =Links!$D$61 -> hoja | F7: =IFERROR(INDEX(Links!$B$345:$B$469,MATCH(C7,Links!$B$218:$B$342,0)),"") -> Paquete de 50 hojas | G7: =INDEX(Links!$N$61:$W$61,1,(Resumen!$C$3-2025)) -> 4502.6809 | H7: =SUMPRODUCT(Links!$F$61:$M$61,$O$5:$V$5)*IF(Links!$E$61="CABA",INDEX(Links!$C$13:$L$13,1,(Resumen!$C$3-2025)),IF(Links!$E$61="PBA",1-INDEX(Links!$C$13:$L$13,1,(Resumen!$C$3-2025)),1)) -> 4502.6809 | I7: =G7-H7 -> 0 | J7: =IF(ROUND(G7-H7,1)>=0,"✔ Sí","✖ No") -> ✔ Sí | K7: =IFERROR(INDEX(Links!$C$345:$C$469,MATCH(C7,Links!$B$218:$B$342,0)),1) -> 50 | L7: =IF(K7>0,H7/K7,0) -> 90.053617 | M7: =Links!$B$2191*Links!$C$2191*Links!$C$2202*7.85/1000000 -> 21.031092 | N7: =H7*M7 -> 94696.296
A8: MANUALES | B8: Chapa en hojas | C8: =Links!$B$62 -> MP-02 | D8: =Links!$C$62 -> Hoja LAF 1,25 × 1220 × 2440 mm | E8: =Links!$D$62 -> hoja | F8: =IFERROR(INDEX(Links!$B$345:$B$469,MATCH(C8,Links!$B$218:$B$342,0)),"") -> Paquete de 50 hojas | G8: =INDEX(Links!$N$62:$W$62,1,(Resumen!$C$3-2025)) -> 521.99476 | H8: =SUMPRODUCT(Links!$F$62:$M$62,$O$5:$V$5)*IF(Links!$E$62="CABA",INDEX(Links!$C$13:$L$13,1,(Resumen!$C$3-2025)),IF(Links!$E$62="PBA",1-INDEX(Links!$C$13:$L$13,1,(Resumen!$C$3-2025)),1)) -> 523.19772 | I8: =G8-H8 -> -1.202963 | J8: =IF(ROUND(G8-H8,1)>=0,"✔ Sí","✖ No") -> ✖ No | K8: =IFERROR(INDEX(Links!$C$345:$C$469,MATCH(C8,Links!$B$218:$B$342,0)),1) -> 50 | L8: =IF(K8>0,H8/K8,0) -> 10.463954 | M8: =Links!$B$2192*Links!$C$2192*Links!$C$2203*7.85/1000000 -> 29.20985 | N8: =H8*M8 -> 15282.527
A9: MANUALES | B9: Chapa en hojas | C9: =Links!$B$63 -> MP-03 | D9: =Links!$C$63 -> Hoja LAF 1,6 × 1000 × 2000 mm | E9: =Links!$D$63 -> hoja | F9: =IFERROR(INDEX(Links!$B$345:$B$469,MATCH(C9,Links!$B$218:$B$342,0)),"") -> Paquete de 80 hojas | G9: =INDEX(Links!$N$63:$W$63,1,(Resumen!$C$3-2025)) -> 5314.6476 | H9: =SUMPRODUCT(Links!$F$63:$M$63,$O$5:$V$5)*IF(Links!$E$63="CABA",INDEX(Links!$C$13:$L$13,1,(Resumen!$C$3-2025)),IF(Links!$E$63="PBA",1-INDEX(Links!$C$13:$L$13,1,(Resumen!$C$3-2025)),1)) -> 5321.0549 | I9: =G9-H9 -> -6.4073361 | J9: =IF(ROUND(G9-H9,1)>=0,"✔ Sí","✖ No") -> ✖ No | K9: =IFERROR(INDEX(Links!$C$345:$C$469,MATCH(C9,Links!$B$218:$B$342,0)),1) -> 80 | L9: =IF(K9>0,H9/K9,0) -> 66.513186 | M9: =Links!$B$2193*Links!$C$2193*Links!$C$2204*7.85/1000000 -> 25.12 | N9: =H9*M9 -> 133664.9
A10: MANUALES | B10: Chapa en hojas | C10: =Links!$B$64 -> MP-04 | D10: =Links!$C$64 -> Hoja LAF 2,0 × 1500 × 3000 mm | E10: =Links!$D$64 -> hoja | F10: =IFERROR(INDEX(Links!$B$345:$B$469,MATCH(C10,Links!$B$218:$B$342,0)),"") -> Paquete de 20 hojas | G10: =INDEX(Links!$N$64:$W$64,1,(Resumen!$C$3-2025)) -> 256.92513 | H10: =SUMPRODUCT(Links!$F$64:$M$64,$O$5:$V$5)*IF(Links!$E$64="CABA",INDEX(Links!$C$13:$L$13,1,(Resumen!$C$3-2025)),IF(Links!$E$64="PBA",1-INDEX(Links!$C$13:$L$13,1,(Resumen!$C$3-2025)),1)) -> 257.52854 | I10: =G10-H10 -> -0.60340705 | J10: =IF(ROUND(G10-H10,1)>=0,"✔ Sí","✖ No") -> ✖ No | K10: =IFERROR(INDEX(Links!$C$345:$C$469,MATCH(C10,Links!$B$218:$B$342,0)),1) -> 20 | L10: =IF(K10>0,H10/K10,0) -> 12.876427 | M10: =Links!$B$2194*Links!$C$2194*Links!$C$2205*7.85/1000000 -> 70.65 | N10: =H10*M10 -> 18194.391
A11: MANUALES | B11: Fleje en rollos | C11: =Links!$B$65 -> MP-05 | D11: =Links!$C$65 -> Fleje LAF 0,9 × 93,05 mm (cúpula 1 kg) | E11: =Links!$D$65 -> kg | F11: =IFERROR(INDEX(Links!$B$345:$B$469,MATCH(C11,Links!$B$218:$B$342,0)),"") -> Rollo de 1.900 kg | G11: =INDEX(Links!$N$65:$W$65,1,(Resumen!$C$3-2025)) -> 12095.318 | H11: =SUMPRODUCT(Links!$F$65:$M$65,$O$5:$V$5)*IF(Links!$E$65="CABA",INDEX(Links!$C$13:$L$13,1,(Resumen!$C$3-2025)),IF(Links!$E$65="PBA",1-INDEX(Links!$C$13:$L$13,1,(Resumen!$C$3-2025)),1)) -> 12095.318 | I11: =G11-H11 -> 0 | J11: =IF(ROUND(G11-H11,1)>=0,"✔ Sí","✖ No") -> ✔ Sí | K11: =IFERROR(INDEX(Links!$C$345:$C$469,MATCH(C11,Links!$B$218:$B$342,0)),1) -> 1900 | L11: =IF(K11>0,H11/K11,0) -> 6.365957 | M11: =IF(E11="kg",1,0) -> 1 | N11: =H11*M11 -> 12095.318
A12: MANUALES | B12: Fleje en rollos | C12: =Links!$B$66 -> MP-13 | D12: =Links!$C$66 -> Fleje LAF 1,25 × 100,6 mm (fondo 1 kg) | E12: =Links!$D$66 -> kg | F12: =IFERROR(INDEX(Links!$B$345:$B$469,MATCH(C12,Links!$B$218:$B$342,0)),"") -> Rollo de 1.900 kg | G12: =INDEX(Links!$N$66:$W$66,1,(Resumen!$C$3-2025)) -> 19478.606 | H12: =SUMPRODUCT(Links!$F$66:$M$66,$O$5:$V$5)*IF(Links!$E$66="CABA",INDEX(Links!$C$13:$L$13,1,(Resumen!$C$3-2025)),IF(Links!$E$66="PBA",1-INDEX(Links!$C$13:$L$13,1,(Resumen!$C$3-2025)),1)) -> 19478.606 | I12: =G12-H12 -> 0 | J12: =IF(ROUND(G12-H12,1)>=0,"✔ Sí","✖ No") -> ✔ Sí | K12: =IFERROR(INDEX(Links!$C$345:$C$469,MATCH(C12,Links!$B$218:$B$342,0)),1) -> 1900 | L12: =IF(K12>0,H12/K12,0) -> 10.251898 | M12: =IF(E12="kg",1,0) -> 1 | N12: =H12*M12 -> 19478.606
A13: MANUALES | B13: Fleje en rollos | C13: =Links!$B$67 -> MP-06 | D13: =Links!$C$67 -> Fleje LAF 1,25 × 162,1 mm (cúpula 2,5 kg) | E13: =Links!$D$67 -> kg | F13: =IFERROR(INDEX(Links!$B$345:$B$469,MATCH(C13,Links!$B$218:$B$342,0)),"") -> Rollo de 492 kg | G13: =INDEX(Links!$N$67:$W$67,1,(Resumen!$C$3-2025)) -> 3568.8074 | H13: =SUMPRODUCT(Links!$F$67:$M$67,$O$5:$V$5)*IF(Links!$E$67="CABA",INDEX(Links!$C$13:$L$13,1,(Resumen!$C$3-2025)),IF(Links!$E$67="PBA",1-INDEX(Links!$C$13:$L$13,1,(Resumen!$C$3-2025)),1)) -> 3577.0319 | I13: =G13-H13 -> -8.2244947 | J13: =IF(ROUND(G13-H13,1)>=0,"✔ Sí","✖ No") -> ✖ No | K13: =IFERROR(INDEX(Links!$C$345:$C$469,MATCH(C13,Links!$B$218:$B$342,0)),1) -> 492 | L13: =IF(K13>0,H13/K13,0) -> 7.27039 | M13: =IF(E13="kg",1,0) -> 1 | N13: =H13*M13 -> 3577.0319
A14: MANUALES | B14: Fleje en rollos | C14: =Links!$B$68 -> MP-14 | D14: =Links!$C$68 -> Fleje LAF 1,25 × 146,1 mm (fondo 2,5 kg) | E14: =Links!$D$68 -> kg | F14: =IFERROR(INDEX(Links!$B$345:$B$469,MATCH(C14,Links!$B$218:$B$342,0)),"") -> Rollo de 492 kg | G14: =INDEX(Links!$N$68:$W$68,1,(Resumen!$C$3-2025)) -> 2891.6435 | H14: =SUMPRODUCT(Links!$F$68:$M$68,$O$5:$V$5)*IF(Links!$E$68="CABA",INDEX(Links!$C$13:$L$13,1,(Resumen!$C$3-2025)),IF(Links!$E$68="PBA",1-INDEX(Links!$C$13:$L$13,1,(Resumen!$C$3-2025)),1)) -> 2898.3075 | I14: =G14-H14 -> -6.6639368 | J14: =IF(ROUND(G14-H14,1)>=0,"✔ Sí","✖ No") -> ✖ No | K14: =IFERROR(INDEX(Links!$C$345:$C$469,MATCH(C14,Links!$B$218:$B$342,0)),1) -> 492 | L14: =IF(K14>0,H14/K14,0) -> 5.8908689 | M14: =IF(E14="kg",1,0) -> 1 | N14: =H14*M14 -> 2898.3075
A15: MANUALES | B15: Fleje en rollos | C15: =Links!$B$69 -> MP-07 | D15: =Links!$C$69 -> Fleje LAF 1,6 × 204,2 mm (cúpula 5 kg) | E15: =Links!$D$69 -> kg | F15: =IFERROR(INDEX(Links!$B$345:$B$469,MATCH(C15,Links!$B$218:$B$342,0)),"") -> Rollo de 615 kg | G15: =INDEX(Links!$N$69:$W$69,1,(Resumen!$C$3-2025)) -> 32779.563 | H15: =SUMPRODUCT(Links!$F$69:$M$69,$O$5:$V$5)*IF(Links!$E$69="CABA",INDEX(Links!$C$13:$L$13,1,(Resumen!$C$3-2025)),IF(Links!$E$69="PBA",1-INDEX(Links!$C$13:$L$13,1,(Resumen!$C$3-2025)),1)) -> 32819.083 | I15: =G15-H15 -> -39.519024 | J15: =IF(ROUND(G15-H15,1)>=0,"✔ Sí","✖ No") -> ✖ No | K15: =IFERROR(INDEX(Links!$C$345:$C$469,MATCH(C15,Links!$B$218:$B$342,0)),1) -> 615 | L15: =IF(K15>0,H15/K15,0) -> 53.364362 | M15: =IF(E15="kg",1,0) -> 1 | N15: =H15*M15 -> 32819.083
A16: MANUALES | B16: Fleje en rollos | C16: =Links!$B$70 -> MP-08 | D16: =Links!$C$70 -> Fleje LAF 1,6 × 177,2 mm (fondo 5 kg) | E16: =Links!$D$70 -> kg | F16: =IFERROR(INDEX(Links!$B$345:$B$469,MATCH(C16,Links!$B$218:$B$342,0)),"") -> Rollo de 492 kg | G16: =INDEX(Links!$N$70:$W$70,1,(Resumen!$C$3-2025)) -> 24593.665 | H16: =SUMPRODUCT(Links!$F$70:$M$70,$O$5:$V$5)*IF(Links!$E$70="CABA",INDEX(Links!$C$13:$L$13,1,(Resumen!$C$3-2025)),IF(Links!$E$70="PBA",1-INDEX(Links!$C$13:$L$13,1,(Resumen!$C$3-2025)),1)) -> 24623.315 | I16: =G16-H16 -> -29.650109 | J16: =IF(ROUND(G16-H16,1)>=0,"✔ Sí","✖ No") -> ✖ No | K16: =IFERROR(INDEX(Links!$C$345:$C$469,MATCH(C16,Links!$B$218:$B$342,0)),1) -> 492 | L16: =IF(K16>0,H16/K16,0) -> 50.047388 | M16: =IF(E16="kg",1,0) -> 1 | N16: =H16*M16 -> 24623.315
A17: MANUALES | B17: Fleje en rollos | C17: =Links!$B$71 -> MP-09 | D17: =Links!$C$71 -> Fleje LAF 1,6 × 238,7 mm (cúpula 10 kg) | E17: =Links!$D$71 -> kg | F17: =IFERROR(INDEX(Links!$B$345:$B$469,MATCH(C17,Links!$B$218:$B$342,0)),"") -> Rollo de 590 kg | G17: =INDEX(Links!$N$71:$W$71,1,(Resumen!$C$3-2025)) -> 2716.1081 | H17: =SUMPRODUCT(Links!$F$71:$M$71,$O$5:$V$5)*IF(Links!$E$71="CABA",INDEX(Links!$C$13:$L$13,1,(Resumen!$C$3-2025)),IF(Links!$E$71="PBA",1-INDEX(Links!$C$13:$L$13,1,(Resumen!$C$3-2025)),1)) -> 2722.487 | I17: =G17-H17 -> -6.3789741 | J17: =IF(ROUND(G17-H17,1)>=0,"✔ Sí","✖ No") -> ✖ No | K17: =IFERROR(INDEX(Links!$C$345:$C$469,MATCH(C17,Links!$B$218:$B$342,0)),1) -> 590 | L17: =IF(K17>0,H17/K17,0) -> 4.6143848 | M17: =IF(E17="kg",1,0) -> 1 | N17: =H17*M17 -> 2722.487
