Workbook

Sheet Resumen
A1: Corte de chapa: comparación de alternativas 2026-2035
A2: Cuerpos de 1 a 100 kg, cúpulas y fondos de 1 a 10 kg. Valor actual = inversión + costos de 10 años descontados. Menor es mejor.
A4: Indicador | B4: A: bobina por formato + fleje | C4: B: hojas para todo | D4: C: bobina madre propia | E4: D: hojas + fleje | F4: Referencia: cuerpos a medida
A5: Cuerpos: se compra | B5: Bobina de ancho estándar por formato, línea de corte transversal | C5: Hojas estándar, dos guillotinas en serie | D5: Bobina madre por espesor, cortada en flejes propios | E5: Hojas estándar, dos guillotinas en serie | F5: Cuerpos comprados cortados a medida
A6: Cúpulas y fondos: se compra | B6: Fleje a medida por disco | C6: Tiras de hoja cargadas a mano | D6: Flejes propios de la bobina madre | E6: Fleje a medida por disco | F6: Fleje a medida por disco
A7: Inversión en equipos (USD) | B7: =Datos!$C$112 -> 167800 | C7: =Datos!$D$112 -> 79500 | D7: =Datos!$E$112 -> 191000 | E7: =Datos!$F$112 -> 93000 | F7: =Datos!$G$112 -> 15000
A8: Acero comprado 2026-2035 (t) | B8: =SUM(Cálculo!$C$32:$L$32) -> 1818.7749 | C8: =SUM(Cálculo!$C$58:$L$58) -> 1931.7673 | D8: =SUM(Cálculo!$C$82:$L$82) -> 1835.2968 | E8: =SUM(Cálculo!$C$96:$L$96) -> 1889.6979 | F8: =SUM(Cálculo!$C$110:$L$110) -> 1761.4191
A9: Aprovechamiento de chapa 2026-2035 | B9: =SUM(Cálculo!$C$25:$L$25)/B8 -> 0.90524548 | C9: =SUM(Cálculo!$C$25:$L$25)/C8 -> 0.85229613 | D9: =SUM(Cálculo!$C$25:$L$25)/D8 -> 0.89709617 | E9: =SUM(Cálculo!$C$25:$L$25)/E8 -> 0.87127038 | F9: =SUM(Cálculo!$C$25:$L$25)/F8 -> 0.93472235
A10: Horas-hombre de corte en el año de referencia | B10: =INDEX(Cálculo!$C$41:$L$41,Datos!$B$6-2025) -> 558.01462 | C10: =INDEX(Cálculo!$C$64:$L$64,Datos!$B$6-2025) -> 301.50285 | D10: =INDEX(Cálculo!$C$90:$L$90,Datos!$B$6-2025) -> 406.12929 | E10: =INDEX(Cálculo!$C$102:$L$102,Datos!$B$6-2025) -> 118.26219 | F10: =INDEX(Cálculo!$C$116:$L$116,Datos!$B$6-2025) -> 20.15545
A11: Costo anual en el año de referencia (USD) | B11: =INDEX(Cálculo!$C$44:$L$44,Datos!$B$6-2025) -> 512740.56 | C11: =INDEX(Cálculo!$C$67:$L$67,Datos!$B$6-2025) -> 566169.1 | D11: =INDEX(Cálculo!$C$93:$L$93,Datos!$B$6-2025) -> 523613.79 | E11: =INDEX(Cálculo!$C$105:$L$105,Datos!$B$6-2025) -> 542274.01 | F11: =INDEX(Cálculo!$C$119:$L$119,Datos!$B$6-2025) -> 539391.98
A12: Valor actual a 10 años (USD) | B12: =B7+SUMPRODUCT(Cálculo!$C$44:$L$44,Cálculo!$C$6:$L$6) -> 1151597 | C12: =C7+SUMPRODUCT(Cálculo!$C$67:$L$67,Cálculo!$C$6:$L$6) -> 1150161.1 | D12: =D7+SUMPRODUCT(Cálculo!$C$93:$L$93,Cálculo!$C$6:$L$6) -> 1203055.3 | E12: =E7+SUMPRODUCT(Cálculo!$C$105:$L$105,Cálculo!$C$6:$L$6) -> 1121061.7 | F12: =F7+SUMPRODUCT(Cálculo!$C$119:$L$119,Cálculo!$C$6:$L$6) -> 1029277.7
A13: Ranking (1 = conviene; la referencia no corta en planta) | B13: =RANK(B12,$B$12:$E$12,1) -> 3 | C13: =RANK(C12,$B$12:$E$12,1) -> 2 | D13: =RANK(D12,$B$12:$E$12,1) -> 4 | E13: =RANK(E12,$B$12:$E$12,1) -> 1 | F13: —
A14: Diferencia contra la que conviene (USD) | B14: =B12-MIN($B$12:$E$12) -> 30535.286 | C14: =C12-MIN($B$12:$E$12) -> 29099.411 | D14: =D12-MIN($B$12:$E$12) -> 81993.62 | E14: =E12-MIN($B$12:$E$12) -> 0 | F14: =F12-MIN($B$12:$E$12) -> -91783.991
A16: Conviene (de las que cortan en planta) | B16: =INDEX({"A: bobina por formato + fleje","B: hojas para todo","C: bobina madre propia","D: hojas + fleje"},MATCH(MIN($B$12:$E$12),$B$12:$E$12,0)) -> D: hojas + fleje
A17: Margen de D: suba del precio de la hoja que la iguala con A | B17: =($B$12-$E$12)/SUMPRODUCT(Cálculo!$C$52:$L$52,Cálculo!$C$6:$L$6) -> 0.038134177
A18: Margen de D: suba del precio del fleje que la iguala con B | B18: =($C$12-$E$12)/SUMPRODUCT(Cálculo!$C$31:$L$31,Cálculo!$C$6:$L$6) -> 0.12894913
A20: Datos editables en la hoja Datos (gris claro). Demanda por IMPORTRANGE (hoja Links). Medidas de cuerpos y discos del plano (hoja Piezas).

Sheet Datos
A1: Datos
A2: Gris claro: dato editable. Todo lo demás del libro sale de acá, de Demanda y de Piezas.
A4: 1. Generales
A5: Concepto | B5: Valor | C5: Unidad | D5: Fuente o criterio
A6: Año de referencia | B6: 2035 | C6: año | D6: Año de diseño del proyecto (Proyecciones).
A7: Tasa de descuento anual en USD | B7: 0.12 | C7: % | D7: Evaluación económica del Excel V2 (12 % real).
A8: Mantenimiento anual de equipos | B8: 0.03 | C8: % de la inversión | D8: Criterio del grupo.
A9: Precio de venta del scrap | B9: 250 | C9: USD/t | D9: Reaquila (mar-2026): acero reciclado $300-1.200/kg con dólar ~$1.480.
A10: Densidad del acero SAE 1010 | B10: 7.87 | C10: g/cm³ | D10: Planilla «Dimensiones de chapa».
A11: Costo mensual de un operario con cargas | B11: 1337922 | C11: ARS/mes | D11: Planilla «Costo oportunidad operario-máquina», CCT 260/75, ago-2026.
A12: Horas por mes | B12: 150 | C12: h/mes | D12: Excel V2.
A13: Horas productivas por operario y año | B13: 1800 | C13: h/año | D13: Excel V2 (150 h × 12).
A14: Tipo de cambio | B14: 1420 | C14: ARS/USD | D14: Valor fijo del proyecto (criterio del grupo).
A15: Costo hora de operario | B15: =Datos!$B$11/Datos!$B$12/Datos!$B$14 -> 6.2813239 | C15: USD/h | D15: Cálculo.
A17: 2. Corte y puentes
A18: Concepto | B18: Valor | C18: Unidad | D18: Fuente o criterio
A19: Margen mínimo de borde a lo ancho de una bobina | B19: 10 | C19: mm | D19: Criterio del grupo: bordes de laminación y tolerancia de ancho.
A20: Despunte de cabeza y cola de bobina | B20: 0.005 | C20: % | D20: Criterio del grupo.
A21: Puente de avance entre discos | B21: 1.5 | C21: × espesor | D21: MISUMI, Press Dies Tutorial: 1,5 veces el espesor, mínimo 0,7 mm.
A22: Puente mínimo entre discos | B22: 0.7 | C22: mm | D22: MISUMI.
A23: Puente al borde del fleje | B23: 1.5 | C23: × puente de avance | D23: MISUMI: 1,5 veces el de avance (la guía del fleje deja juego).
A24: ¿Mezclar 70 y 100 kg en la misma hoja? | B24: SI | C24: SI/NO | D24: Proceso de carros: la hoja mixta lleva 1 cuerpo de 100 kg y 3 de 70 kg.
A25: Cuerpos de 100 kg por hoja mixta | B25: 1 | C25: u | D25: Proceso de carros.
A26: Cuerpos de 70 kg por hoja mixta | B26: 3 | C26: u | D26: Proceso de carros.
A28: 3. Máquinas
A29: Concepto | B29: Valor | C29: Unidad | D29: Fuente o criterio
A30: Guillotina 1 (franjas) CENA 8 × 3200: golpes por minuto | B30: 10 | C30: golpes/min | D30: Cotización CENA (Drive).
A31: Guillotina 1: largo de corte | B31: 3200 | C31: mm | D31: Cotización CENA.
A32: Guillotina 1: recorrido del tope trasero | B32: 1000 | C32: mm | D32: Cotización CENA: 20 a 1.000 mm.
A33: Guillotina 2 (piezas) QC12Y 6 × 2500: golpes por minuto | B33: 20 | C33: golpes/min | D33: Confirmado por el grupo (igual que la HG 6 × 2500 de la ficha Molinari Panther).
A34: Guillotina 2: largo de corte para franjas en paralelo | B34: 2500 | C34: mm | D34: Publicación Alibaba 1600900259147: 6 × 2500, cuchilla de 2.550 mm.
A35: Guillotina 2: recorrido del tope trasero | B35: 800 | C35: mm | D35: Publicación Alibaba 1600900259147: 20 a 800 mm.
A36: Línea de corte transversal (A y C): golpes por hora | B36: 1200 | C36: golpes/h | D36: Criterio del grupo: 20 golpes por minuto.
A37: Cortadora longitudinal (C): velocidad efectiva | B37: 40 | C37: m/min | D37: Criterio del grupo (máquinas de 60 a 120 m/min nominales).
A38: Cortadora: armado de cuchillas por bobina madre | B38: 45 | C38: min | D38: Criterio del grupo.
A39: Operarios en la cortadora | B39: 2 | C39: personas | D39: Criterio del grupo.
A40: Carga manual de una tira en el balancín (B) | B40: 15 | C40: s/tira | D40: Criterio del grupo.
A41: Cambio de fleje en el desbobinador de la prensa | B41: 15 | C41: min/fleje | D41: Criterio del grupo.
A43: 4. Compras y stock
A44: Concepto | B44: Valor | C44: Unidad | D44: Fuente o criterio
...

Sheet Links
A1: Links de los IMPORTRANGE
A2: Pegar en B el link de cada Google Sheet: todos los IMPORTRANGE lo leen de acá.
A3: Archivo | B3: Link | C3: Qué se importa
A4: Proyecciones | B4: https://docs.google.com/spreadsheets/d/1xc4xDAwSYT3l-RulPYtcePxiCninrbQGzaBUsgO0YEs/edit?gid=1764491891#gid=1764491891 | C4: Indexado Dim Técnico B3:K10 (terminados 1 a 100 kg) y B15:K22 (cilindros vacíos) → Demanda
A5: Dimensionamiento Recargas Planta Comercial | B5: PEGAR ACÁ EL LINK DEL GOOGLE SHEET | C5: sobrestock_sustitutos B73:K76 y B86:K89: sustitutos ABC como cilindro vacío → Demanda
A6: Dimensionamiento Recargas Planta Industrial | B6: PEGAR ACÁ EL LINK DEL GOOGLE SHEET | C6: sobrestock_sustitutos B73:K76 y B86:K89: sustitutos ABC terminados → Demanda

Sheet Demanda
A1: Demanda: cuerpos a fabricar por formato
A2: Por IMPORTRANGE (hoja Links). Cada unidad lleva un cuerpo; las de 1 a 10 kg, además, una cúpula y un fondo.
A4: Unidades a fabricar = terminados + cilindros + sustitutos
A5: Formato | B5: Línea | C5: 2026 | D5: 2027 | E5: 2028 | F5: 2029 | G5: 2030 | H5: 2031 | I5: 2032 | J5: 2033 | K5: 2034 | L5: 2035
A6: 1 kg | B6: Manual | C6: =C18+C30+C42+C54 -> 4178.7365 | D6: =D18+D30+D42+D54 -> 5997.304 | E6: =E18+E30+E42+E54 -> 14514.148 | F6: =F18+F30+F42+F54 -> 35161.936 | G6: =G18+G30+G42+G54 -> 62115.433 | H6: =H18+H30+H42+H54 -> 87300.453 | I6: =I18+I30+I42+I54 -> 121673.15 | J6: =J18+J30+J42+J54 -> 156133.08 | ... L6: =L18+L30+L42+L54 -> 202620.64
A7: 2,5 kg | B7: Manual | C7: =C19+C31+C43+C55 -> 302.03036 | D7: =D19+D31+D43+D55 -> 727.28745 | E7: =E19+E31+E43+E55 -> 1317.3881 | F7: =F19+F31+F43+F55 -> 2592.6782 | G7: =G19+G31+G43+G55 -> 4297.3877 | H7: =H19+H31+H43+H55 -> 6113.1499 | I7: =I19+I31+I43+I55 -> 8117.2755 | J7: =J19+J31+J43+J55 -> 10270.227 | ... L7: =L19+L31+L43+L55 -> 14135.378
A8: 5 kg | B8: Manual | C8: =C20+C32+C44+C56 -> 2286.773 | D8: =D20+D32+D44+D56 -> 3940.4589 | E8: =E20+E32+E44+E56 -> 6733.0976 | F8: =F20+F32+F44+F56 -> 12240.955 | G8: =G20+G32+G44+G56 -> 20628.467 | H8: =H20+H32+H44+H56 -> 28744.684 | I8: =I20+I32+I44+I56 -> 38699.48 | J8: =J20+J32+J44+J56 -> 48872.026 | ... L8: =L20+L32+L44+L56 -> 63882.939
A9: 10 kg | B9: Manual | C9: =C21+C33+C45+C57 -> 94.833182 | D9: =D21+D33+D45+D57 -> 184.4873 | E9: =E21+E33+E45+E57 -> 356.17878 | F9: =F21+F33+F45+F57 -> 693.78049 | G9: =G21+G33+G45+G57 -> 1206.3982 | H9: =H21+H33+H45+H57 -> 1743.045 | I9: =I21+I33+I45+I57 -> 2339.8005 | J9: =J21+J33+J45+J57 -> 2957.5648 | ... L9: =L21+L33+L45+L57 -> 3868.3281
A10: 25 kg | B10: Rodante | C10: =C22+C34+C46+C58 -> 36.051791 | D10: =D22+D34+D46+D58 -> 58.622147 | E10: =E22+E34+E46+E58 -> 90.76854 | F10: =F22+F34+F46+F58 -> 153.96985 | G10: =G22+G34+G46+G58 -> 251.356 | H10: =H22+H34+H46+H58 -> 349.57448 | I10: =I22+I34+I46+I58 -> 465.46823 | J10: =J22+J34+J46+J58 -> 587.72867 | ... L10: =L22+L34+L46+L58 -> 777.31053
A11: 50 kg | B11: Rodante | C11: =C23+C35+C47+C59 -> 76.913941 | D11: =D23+D35+D47+D59 -> 129.77672 | E11: =E23+E35+E47+E59 -> 201.49879 | F11: =F23+F35+F47+F59 -> 336.52568 | G11: =G23+G35+G47+G59 -> 554.00721 | H11: =H23+H35+H47+H59 -> 770.13586 | I11: =I23+I35+I47+I59 -> 1024.3501 | J11: =J23+J35+J47+J59 -> 1292.1071 | ... L11: =L23+L35+L47+L59 -> 1709.4352
A12: 70 kg | B12: Rodante | C12: =C24+C36+C48+C60 -> 18.34486 | D12: =D24+D36+D48+D60 -> 28.221831 | E12: =E24+E36+E48+E60 -> 43.260099 | F12: =F24+F36+F48+F60 -> 73.814329 | G12: =G24+G36+G48+G60 -> 122.26048 | H12: =H24+H36+H48+H60 -> 167.52855 | I12: =I24+I36+I48+I60 -> 224.48075 | J12: =J24+J36+J48+J60 -> 281.64736 | ... L12: =L24+L36+L48+L60 -> 374.12986
A13: 100 kg | B13: Rodante | C13: =C25+C37+C49+C61 -> 12.896573 | D13: =D25+D37+D49+D61 -> 18.867887 | E13: =E25+E37+E49+E61 -> 28.826733 | F13: =F25+F37+F49+F61 -> 48.329553 | G13: =G25+G37+G49+G61 -> 80.640321 | H13: =H25+H37+H49+H61 -> 111.85903 | I13: =I25+I37+I49+I61 -> 148.97383 | J13: =J25+J37+J49+J61 -> 186.51157 | ... L13: =L25+L37+L49+L61 -> 247.44657
A14: Total | C14: =SUM(C6:C13) -> 7006.5803 | D14: =SUM(D6:D13) -> 11085.026 | E14: =SUM(E6:E13) -> 23285.166 | F14: =SUM(F6:F13) -> 51301.989 | G14: =SUM(G6:G13) -> 89255.95 | H14: =SUM(H6:H13) -> 125300.43 | I14: =SUM(I6:I13) -> 172692.98 | J14: =SUM(J6:J13) -> 220580.89 | ... L14: =SUM(L6:L13) -> 287615.61
A16: Matafuegos terminados (Proyecciones)
A17: Formato | B17: Línea | C17: 2026 | D17: 2027 | E17: 2028 | F17: 2029 | G17: 2030 | H17: 2031 | I17: 2032 | J17: 2033 | K17: 2034 | L17: 2035
A18: 1 kg | B18: Manual | C18: =IFERROR(__xludf.DUMMYFUNCTION("IMPORTRANGE(Links!$B$4,""Indexado Dim Técnico!B3:K10"")"),4178.736543) -> 4178.7365 | D18: =IFERROR(__xludf.DUMMYFUNCTION("""COMPUTED_VALUE"""),5997.303977) -> 5997.304 | E18: =IFERROR(__xludf.DUMMYFUNCTION("""COMPUTED_VALUE"""),6851.747758) -> 6851.7478 | F18: =IFERROR(__xludf.DUMMYFUNCTION("""COMPUTED_VALUE"""),8467.135549) -> 8467.1355 | G18: =IFERROR(__xludf.DUMMYFUNCTION("""COMPUTED_VALUE"""),12680.63271) -> 12680.633 | H18: =IFERROR(__xludf.DUMMYFUNCTION("""COMPUTED_VALUE"""),15620.25307) -> 15620.253 | I18: =IFERROR(__xludf.DUMMYFUNCTION("""COMPUTED_VALUE"""),20332.55326) -> 20332.553 | J18: =IFERROR(__xludf.DUMMYFUNCTION("""COMPUTED_VALUE"""),25132.07848) -> 25132.078 | K18: =IFERROR(__xludf.DUMMYFUNCTION("""COMPUTED_VALUE"""),28573.33614) -> 28573.336 | L18: =IFERROR(__xludf.DUMMYFUNCTION("""COMPUTED_VALUE"""),32072.63913) -> 32072.639
A19: 2,5 kg | B19: Manual | C19: =IFERROR(__xludf.DUMMYFUNCTION("""COMPUTED_VALUE"""),295.0303572) -> 295.03036 | D19: =IFERROR(__xludf.DUMMYFUNCTION("""COMPUTED_VALUE"""),709.7274503) -> 709.72745 | E19: =IFERROR(__xludf.DUMMYFUNCTION("""COMPUTED_VALUE"""),986.8680576) -> 986.86806 | F19: =IFERROR(__xludf.DUMMYFUNCTION("""COMPUTED_VALUE"""),1500.638174) -> 1500.6382 | G19: =IFERROR(__xludf.DUMMYFUNCTION("""COMPUTED_VALUE"""),2312.627726) -> 2312.6277 | H19: =IFERROR(__xludf.DUMMYFUNCTION("""COMPUTED_VALUE"""),3252.869887) -> 3252.8699 | I19: =IFERROR(__xludf.DUMMYFUNCTION("""COMPUTED_VALUE"""),4102.315524) -> 4102.3155 | J19: =IFERROR(__xludf.DUMMYFUNCTION("""COMPUTED_VALUE"""),5104.306587) -> 5104.3066 | K19: =IFERROR(__xludf.DUMMYFUNCTION("""COMPUTED_VALUE"""),6195.186243) -> 6195.1862 | L19: =IFERROR(__xludf.DUMMYFUNCTION("""COMPUTED_VALUE"""),7424.858444) -> 7424.8584
A20: 5 kg | B20: Manual | C20: =IFERROR(__xludf.DUMMYFUNCTION("""COMPUTED_VALUE"""),2255.773025) -> 2255.773 | D20: =IFERROR(__xludf.DUMMYFUNCTION("""COMPUTED_VALUE"""),3846.978881) -> 3846.9789 | E20: =IFERROR(__xludf.DUMMYFUNCTION("""COMPUTED_VALUE"""),5093.537591) -> 5093.5376 | F20: =IFERROR(__xludf.DUMMYFUNCTION("""COMPUTED_VALUE"""),6823.115313) -> 6823.1153 | G20: =IFERROR(__xludf.DUMMYFUNCTION("""COMPUTED_VALUE"""),10819.30694) -> 10819.307 | H20: =IFERROR(__xludf.DUMMYFUNCTION("""COMPUTED_VALUE"""),14605.96411) -> 14605.964 | I20: =IFERROR(__xludf.DUMMYFUNCTION("""COMPUTED_VALUE"""),18877.75984) -> 18877.76 | J20: =IFERROR(__xludf.DUMMYFUNCTION("""COMPUTED_VALUE"""),23368.18637) -> 23368.186 | K20: =IFERROR(__xludf.DUMMYFUNCTION("""COMPUTED_VALUE"""),26967.72455) -> 26967.725 | L20: =IFERROR(__xludf.DUMMYFUNCTION("""COMPUTED_VALUE"""),30750.77872) -> 30750.779
A21: 10 kg | B21: Manual | C21: =IFERROR(__xludf.DUMMYFUNCTION("""COMPUTED_VALUE"""),91.83318153) -> 91.833182 | D21: =IFERROR(__xludf.DUMMYFUNCTION("""COMPUTED_VALUE"""),177.2472967) -> 177.2473 | E21: =IFERROR(__xludf.DUMMYFUNCTION("""COMPUTED_VALUE"""),252.9787798) -> 252.97878 | F21: =IFERROR(__xludf.DUMMYFUNCTION("""COMPUTED_VALUE"""),358.0204941) -> 358.02049 | G21: =IFERROR(__xludf.DUMMYFUNCTION("""COMPUTED_VALUE"""),602.7181519) -> 602.71815 | H21: =IFERROR(__xludf.DUMMYFUNCTION("""COMPUTED_VALUE"""),872.605032) -> 872.60503 | I21: =IFERROR(__xludf.DUMMYFUNCTION("""COMPUTED_VALUE"""),1127.160545) -> 1127.1605 | J21: =IFERROR(__xludf.DUMMYFUNCTION("""COMPUTED_VALUE"""),1395.444812) -> 1395.4448 | K21: =IFERROR(__xludf.DUMMYFUNCTION("""COMPUTED_VALUE"""),1612.350054) -> 1612.3501 | L21: =IFERROR(__xludf.DUMMYFUNCTION("""COMPUTED_VALUE"""),1840.848079) -> 1840.8481
A22: 25 kg | B22: Rodante | C22: =IFERROR(__xludf.DUMMYFUNCTION("""COMPUTED_VALUE"""),34.05179136) -> 34.051791 | D22: =IFERROR(__xludf.DUMMYFUNCTION("""COMPUTED_VALUE"""),58.46214745) -> 58.462147 | E22: =IFERROR(__xludf.DUMMYFUNCTION("""COMPUTED_VALUE"""),75.20853998) -> 75.20854 | F22: =IFERROR(__xludf.DUMMYFUNCTION("""COMPUTED_VALUE"""),100.5298529) -> 100.52985 | G22: =IFERROR(__xludf.DUMMYFUNCTION("""COMPUTED_VALUE"""),155.8760035) -> 155.876 | H22: =IFERROR(__xludf.DUMMYFUNCTION("""COMPUTED_VALUE"""),211.9344827) -> 211.93448 | I22: =IFERROR(__xludf.DUMMYFUNCTION("""COMPUTED_VALUE"""),272.6682332) -> 272.66823 | J22: =IFERROR(__xludf.DUMMYFUNCTION("""COMPUTED_VALUE"""),337.8486707) -> 337.84867 | K22: =IFERROR(__xludf.DUMMYFUNCTION("""COMPUTED_VALUE"""),393.6274156) -> 393.62742 | L22: =IFERROR(__xludf.DUMMYFUNCTION("""COMPUTED_VALUE"""),453.2705332) -> 453.27053
A23: 50 kg | B23: Rodante | C23: =IFERROR(__xludf.DUMMYFUNCTION("""COMPUTED_VALUE"""),74.913941) -> 74.913941 | D23: =IFERROR(__xludf.DUMMYFUNCTION("""COMPUTED_VALUE"""),128.6167244) -> 128.61672 | E23: =IFERROR(__xludf.DUMMYFUNCTION("""COMPUTED_VALUE"""),165.458788) -> 165.45879 | F23: =IFERROR(__xludf.DUMMYFUNCTION("""COMPUTED_VALUE"""),221.1656765) -> 221.16568 | G23: =IFERROR(__xludf.DUMMYFUNCTION("""COMPUTED_VALUE"""),342.9272077) -> 342.92721 | H23: =IFERROR(__xludf.DUMMYFUNCTION("""COMPUTED_VALUE"""),466.255862) -> 466.25586 | I23: =IFERROR(__xludf.DUMMYFUNCTION("""COMPUTED_VALUE"""),599.8701129) -> 599.87011 | J23: =IFERROR(__xludf.DUMMYFUNCTION("""COMPUTED_VALUE"""),743.2670756) -> 743.26708 | K23: =IFERROR(__xludf.DUMMYFUNCTION("""COMPUTED_VALUE"""),865.9803143) -> 865.98031 | L23: =IFERROR(__xludf.DUMMYFUNCTION("""COMPUTED_VALUE"""),997.1951731) -> 997.19517
A24: 70 kg | B24: Rodante | C24: =IFERROR(__xludf.DUMMYFUNCTION("""COMPUTED_VALUE"""),16.34485985) -> 16.34486 | D24: =IFERROR(__xludf.DUMMYFUNCTION("""COMPUTED_VALUE"""),28.06183078) -> 28.061831 | E24: =IFERROR(__xludf.DUMMYFUNCTION("""COMPUTED_VALUE"""),36.10009919) -> 36.100099 | F24: =IFERROR(__xludf.DUMMYFUNCTION("""COMPUTED_VALUE"""),48.25432941) -> 48.254329 | G24: =IFERROR(__xludf.DUMMYFUNCTION("""COMPUTED_VALUE"""),74.82048167) -> 74.820482 | H24: =IFERROR(__xludf.DUMMYFUNCTION("""COMPUTED_VALUE"""),101.7285517) -> 101.72855 | I24: =IFERROR(__xludf.DUMMYFUNCTION("""COMPUTED_VALUE"""),130.8807519) -> 130.88075 | J24: =IFERROR(__xludf.DUMMYFUNCTION("""COMPUTED_VALUE"""),162.1673619) -> 162.16736 | K24: =IFERROR(__xludf.DUMMYFUNCTION("""COMPUTED_VALUE"""),188.9411595) -> 188.94116 | L24: =IFERROR(__xludf.DUMMYFUNCTION("""COMPUTED_VALUE"""),217.569856) -> 217.56986
A25: 100 kg | B25: Rodante | C25: =IFERROR(__xludf.DUMMYFUNCTION("""COMPUTED_VALUE"""),10.89657324) -> 10.896573 | D25: =IFERROR(__xludf.DUMMYFUNCTION("""COMPUTED_VALUE"""),18.70788719) -> 18.707887 | E25: =IFERROR(__xludf.DUMMYFUNCTION("""COMPUTED_VALUE"""),24.06673279) -> 24.066733 | F25: =IFERROR(__xludf.DUMMYFUNCTION("""COMPUTED_VALUE"""),32.16955294) -> 32.169553 | G25: =IFERROR(__xludf.DUMMYFUNCTION("""COMPUTED_VALUE"""),49.88032112) -> 49.880321 | H25: =IFERROR(__xludf.DUMMYFUNCTION("""COMPUTED_VALUE"""),67.81903447) -> 67.819034 | I25: =IFERROR(__xludf.DUMMYFUNCTION("""COMPUTED_VALUE"""),87.25383461) -> 87.253835 | J25: =IFERROR(__xludf.DUMMYFUNCTION("""COMPUTED_VALUE"""),108.1115746) -> 108.11157 | K25: =IFERROR(__xludf.DUMMYFUNCTION("""COMPUTED_VALUE"""),125.960773) -> 125.96077 | L25: =IFERROR(__xludf.DUMMYFUNCTION("""COMPUTED_VALUE"""),145.0465706) -> 145.04657
A26: Total | C26: =SUM(C18:C25) -> 6957.5803 | D26: =SUM(D18:D25) -> 10965.106 | E26: =SUM(E18:E25) -> 13485.966 | F26: =SUM(F18:F25) -> 17551.029 | G26: =SUM(G18:G25) -> 27038.79 | H26: =SUM(H18:H25) -> 35199.43 | I26: =SUM(I18:I25) -> 45530.462 | J26: =SUM(J18:J25) -> 56351.411 | ... L26: =SUM(L18:L25) -> 73902.207
A28: Cilindros vendidos vacíos (Proyecciones)
A29: Formato | B29: Línea | C29: 2026 | D29: 2027 | E29: 2028 | F29: 2029 | G29: 2030 | H29: 2031 | I29: 2032 | J29: 2033 | K29: 2034 | L29: 2035
A30: 1 kg | B30: Manual | C30: =IFERROR(__xludf.DUMMYFUNCTION("IMPORTRANGE(Links!$B$4,""Indexado Dim Técnico!B15:K22"")"),0) -> 0 | D30: =IFERROR(__xludf.DUMMYFUNCTION("""COMPUTED_VALUE"""),0) -> 0 | E30: =IFERROR(__xludf.DUMMYFUNCTION("""COMPUTED_VALUE"""),7662.4) -> 7662.4 | F30: =IFERROR(__xludf.DUMMYFUNCTION("""COMPUTED_VALUE"""),26694.8) -> 26694.8 | G30: =IFERROR(__xludf.DUMMYFUNCTION("""COMPUTED_VALUE"""),49434.8) -> 49434.8 | H30: =IFERROR(__xludf.DUMMYFUNCTION("""COMPUTED_VALUE"""),71680.2) -> 71680.2 | I30: =IFERROR(__xludf.DUMMYFUNCTION("""COMPUTED_VALUE"""),101340.6) -> 101340.6 | J30: =IFERROR(__xludf.DUMMYFUNCTION("""COMPUTED_VALUE"""),131001) -> 131001 | K30: =IFERROR(__xludf.DUMMYFUNCTION("""COMPUTED_VALUE"""),146819.8) -> 146819.8 | L30: =IFERROR(__xludf.DUMMYFUNCTION("""COMPUTED_VALUE"""),170548) -> 170548
A31: 2,5 kg | B31: Manual | C31: =IFERROR(__xludf.DUMMYFUNCTION("""COMPUTED_VALUE"""),0) -> 0 | D31: =IFERROR(__xludf.DUMMYFUNCTION("""COMPUTED_VALUE"""),0) -> 0 | E31: =IFERROR(__xludf.DUMMYFUNCTION("""COMPUTED_VALUE"""),299.6) -> 299.6 | F31: =IFERROR(__xludf.DUMMYFUNCTION("""COMPUTED_VALUE"""),1043.8) -> 1043.8 | G31: =IFERROR(__xludf.DUMMYFUNCTION("""COMPUTED_VALUE"""),1933) -> 1933 | H31: =IFERROR(__xludf.DUMMYFUNCTION("""COMPUTED_VALUE"""),2803) -> 2803 | I31: =IFERROR(__xludf.DUMMYFUNCTION("""COMPUTED_VALUE"""),3963) -> 3963 | J31: =IFERROR(__xludf.DUMMYFUNCTION("""COMPUTED_VALUE"""),5123) -> 5123 | K31: =IFERROR(__xludf.DUMMYFUNCTION("""COMPUTED_VALUE"""),5741.4) -> 5741.4 | L31: =IFERROR(__xludf.DUMMYFUNCTION("""COMPUTED_VALUE"""),6669) -> 6669
A32: 5 kg | B32: Manual | C32: =IFERROR(__xludf.DUMMYFUNCTION("""COMPUTED_VALUE"""),0) -> 0 | D32: =IFERROR(__xludf.DUMMYFUNCTION("""COMPUTED_VALUE"""),0) -> 0 | E32: =IFERROR(__xludf.DUMMYFUNCTION("""COMPUTED_VALUE"""),1478.8) -> 1478.8 | F32: =IFERROR(__xludf.DUMMYFUNCTION("""COMPUTED_VALUE"""),5152) -> 5152 | G32: =IFERROR(__xludf.DUMMYFUNCTION("""COMPUTED_VALUE"""),9540.8) -> 9540.8 | H32: =IFERROR(__xludf.DUMMYFUNCTION("""COMPUTED_VALUE"""),13834.2) -> 13834.2 | I32: =IFERROR(__xludf.DUMMYFUNCTION("""COMPUTED_VALUE"""),19558.6) -> 19558.6 | J32: =IFERROR(__xludf.DUMMYFUNCTION("""COMPUTED_VALUE"""),25283) -> 25283 | K32: =IFERROR(__xludf.DUMMYFUNCTION("""COMPUTED_VALUE"""),28335.8) -> 28335.8 | L32: =IFERROR(__xludf.DUMMYFUNCTION("""COMPUTED_VALUE"""),32915) -> 32915
A33: 10 kg | B33: Manual | C33: =IFERROR(__xludf.DUMMYFUNCTION("""COMPUTED_VALUE"""),0) -> 0 | D33: =IFERROR(__xludf.DUMMYFUNCTION("""COMPUTED_VALUE"""),0) -> 0 | E33: =IFERROR(__xludf.DUMMYFUNCTION("""COMPUTED_VALUE"""),90.4) -> 90.4 | F33: =IFERROR(__xludf.DUMMYFUNCTION("""COMPUTED_VALUE"""),315) -> 315 | G33: =IFERROR(__xludf.DUMMYFUNCTION("""COMPUTED_VALUE"""),583.4) -> 583.4 | H33: =IFERROR(__xludf.DUMMYFUNCTION("""COMPUTED_VALUE"""),845.8) -> 845.8 | I33: =IFERROR(__xludf.DUMMYFUNCTION("""COMPUTED_VALUE"""),1195.4) -> 1195.4 | J33: =IFERROR(__xludf.DUMMYFUNCTION("""COMPUTED_VALUE"""),1545) -> 1545 | K33: =IFERROR(__xludf.DUMMYFUNCTION("""COMPUTED_VALUE"""),1731.4) -> 1731.4 | L33: =IFERROR(__xludf.DUMMYFUNCTION("""COMPUTED_VALUE"""),2011) -> 2011
A34: 25 kg | B34: Rodante | C34: =IFERROR(__xludf.DUMMYFUNCTION("""COMPUTED_VALUE"""),0) -> 0 | D34: =IFERROR(__xludf.DUMMYFUNCTION("""COMPUTED_VALUE"""),0) -> 0 | E34: =IFERROR(__xludf.DUMMYFUNCTION("""COMPUTED_VALUE"""),14.4) -> 14.4 | F34: =IFERROR(__xludf.DUMMYFUNCTION("""COMPUTED_VALUE"""),50.2) -> 50.2 | G34: =IFERROR(__xludf.DUMMYFUNCTION("""COMPUTED_VALUE"""),93) -> 93 | H34: =IFERROR(__xludf.DUMMYFUNCTION("""COMPUTED_VALUE"""),135) -> 135 | I34: =IFERROR(__xludf.DUMMYFUNCTION("""COMPUTED_VALUE"""),191) -> 191 | J34: =IFERROR(__xludf.DUMMYFUNCTION("""COMPUTED_VALUE"""),247) -> 247 | K34: =IFERROR(__xludf.DUMMYFUNCTION("""COMPUTED_VALUE"""),277) -> 277 | L34: =IFERROR(__xludf.DUMMYFUNCTION("""COMPUTED_VALUE"""),322) -> 322
A35: 50 kg | B35: Rodante | C35: =IFERROR(__xludf.DUMMYFUNCTION("""COMPUTED_VALUE"""),0) -> 0 | D35: =IFERROR(__xludf.DUMMYFUNCTION("""COMPUTED_VALUE"""),0) -> 0 | E35: =IFERROR(__xludf.DUMMYFUNCTION("""COMPUTED_VALUE"""),31.8) -> 31.8 | F35: =IFERROR(__xludf.DUMMYFUNCTION("""COMPUTED_VALUE"""),110.8) -> 110.8 | G35: =IFERROR(__xludf.DUMMYFUNCTION("""COMPUTED_VALUE"""),205.2) -> 205.2 | H35: =IFERROR(__xludf.DUMMYFUNCTION("""COMPUTED_VALUE"""),297.6) -> 297.6 | I35: =IFERROR(__xludf.DUMMYFUNCTION("""COMPUTED_VALUE"""),420.8) -> 420.8 | J35: =IFERROR(__xludf.DUMMYFUNCTION("""COMPUTED_VALUE"""),544) -> 544 | K35: =IFERROR(__xludf.DUMMYFUNCTION("""COMPUTED_VALUE"""),609.6) -> 609.6 | L35: =IFERROR(__xludf.DUMMYFUNCTION("""COMPUTED_VALUE"""),708) -> 708
A36: 70 kg | B36: Rodante | C36: =IFERROR(__xludf.DUMMYFUNCTION("""COMPUTED_VALUE"""),0) -> 0 | D36: =IFERROR(__xludf.DUMMYFUNCTION("""COMPUTED_VALUE"""),0) -> 0 | E36: =IFERROR(__xludf.DUMMYFUNCTION("""COMPUTED_VALUE"""),7) -> 7 | F36: =IFERROR(__xludf.DUMMYFUNCTION("""COMPUTED_VALUE"""),24.4) -> 24.4 | G36: =IFERROR(__xludf.DUMMYFUNCTION("""COMPUTED_VALUE"""),45.2) -> 45.2 | H36: =IFERROR(__xludf.DUMMYFUNCTION("""COMPUTED_VALUE"""),65.4) -> 65.4 | I36: =IFERROR(__xludf.DUMMYFUNCTION("""COMPUTED_VALUE"""),92.2) -> 92.2 | J36: =IFERROR(__xludf.DUMMYFUNCTION("""COMPUTED_VALUE"""),119) -> 119 | K36: =IFERROR(__xludf.DUMMYFUNCTION("""COMPUTED_VALUE"""),133.4) -> 133.4 | L36: =IFERROR(__xludf.DUMMYFUNCTION("""COMPUTED_VALUE"""),155) -> 155
A37: 100 kg | B37: Rodante | C37: =IFERROR(__xludf.DUMMYFUNCTION("""COMPUTED_VALUE"""),0) -> 0 | D37: =IFERROR(__xludf.DUMMYFUNCTION("""COMPUTED_VALUE"""),0) -> 0 | E37: =IFERROR(__xludf.DUMMYFUNCTION("""COMPUTED_VALUE"""),4.6) -> 4.6 | F37: =IFERROR(__xludf.DUMMYFUNCTION("""COMPUTED_VALUE"""),16) -> 16 | G37: =IFERROR(__xludf.DUMMYFUNCTION("""COMPUTED_VALUE"""),29.6) -> 29.6 | H37: =IFERROR(__xludf.DUMMYFUNCTION("""COMPUTED_VALUE"""),42.8) -> 42.8 | I37: =IFERROR(__xludf.DUMMYFUNCTION("""COMPUTED_VALUE"""),60.4) -> 60.4 | J37: =IFERROR(__xludf.DUMMYFUNCTION("""COMPUTED_VALUE"""),78) -> 78 | K37: =IFERROR(__xludf.DUMMYFUNCTION("""COMPUTED_VALUE"""),87.6) -> 87.6 | L37: =IFERROR(__xludf.DUMMYFUNCTION("""COMPUTED_VALUE"""),102) -> 102
A38: Total | C38: =SUM(C30:C37) -> 0 | D38: =SUM(D30:D37) -> 0 | E38: =SUM(E30:E37) -> 9589 | F38: =SUM(F30:F37) -> 33407 | G38: =SUM(G30:G37) -> 61865 | H38: =SUM(H30:H37) -> 89704 | I38: =SUM(I30:I37) -> 126822 | J38: =SUM(J30:J37) -> 163940 | ... L38: =SUM(L30:L37) -> 213430
A40: Sustitutos ABC terminados para la planta industrial de recargas
A41: Formato | B41: Línea | C41: 2026 | D41: 2027 | E41: 2028 | F41: 2029 | G41: 2030 | H41: 2031 | I41: 2032 | J41: 2033 | K41: 2034 | L41: 2035
A42: 1 kg | B42: Manual | C42: =IFERROR(__xludf.DUMMYFUNCTION("IMPORTRANGE(Links!$B$6,""sobrestock_sustitutos!B73:K76"")"),0) -> 0 | D42: =IFERROR(__xludf.DUMMYFUNCTION("""COMPUTED_VALUE"""),0) -> 0 | E42: =IFERROR(__xludf.DUMMYFUNCTION("""COMPUTED_VALUE"""),0) -> 0 | F42: =IFERROR(__xludf.DUMMYFUNCTION("""COMPUTED_VALUE"""),0) -> 0 | G42: =IFERROR(__xludf.DUMMYFUNCTION("""COMPUTED_VALUE"""),0) -> 0 | H42: =IFERROR(__xludf.DUMMYFUNCTION("""COMPUTED_VALUE"""),0) -> 0 | I42: =IFERROR(__xludf.DUMMYFUNCTION("""COMPUTED_VALUE"""),0) -> 0 | J42: =IFERROR(__xludf.DUMMYFUNCTION("""COMPUTED_VALUE"""),0) -> 0 | K42: =IFERROR(__xludf.DUMMYFUNCTION("""COMPUTED_VALUE"""),0) -> 0 | L42: =IFERROR(__xludf.DUMMYFUNCTION("""COMPUTED_VALUE"""),0) -> 0
A43: 2,5 kg | B43: Manual | C43: =IFERROR(__xludf.DUMMYFUNCTION("""COMPUTED_VALUE"""),3) -> 3 | D43: =IFERROR(__xludf.DUMMYFUNCTION("""COMPUTED_VALUE"""),6.24) -> 6.24 | E43: =IFERROR(__xludf.DUMMYFUNCTION("""COMPUTED_VALUE"""),10.72) -> 10.72 | F43: =IFERROR(__xludf.DUMMYFUNCTION("""COMPUTED_VALUE"""),17.52) -> 17.52 | G43: =IFERROR(__xludf.DUMMYFUNCTION("""COMPUTED_VALUE"""),18.8) -> 18.8 | H43: =IFERROR(__xludf.DUMMYFUNCTION("""COMPUTED_VALUE"""),21.08) -> 21.08 | I43: =IFERROR(__xludf.DUMMYFUNCTION("""COMPUTED_VALUE"""),18.44) -> 18.44 | J43: =IFERROR(__xludf.DUMMYFUNCTION("""COMPUTED_VALUE"""),15.48) -> 15.48 | K43: =IFERROR(__xludf.DUMMYFUNCTION("""COMPUTED_VALUE"""),14.2) -> 14.2 | L43: =IFERROR(__xludf.DUMMYFUNCTION("""COMPUTED_VALUE"""),14.76) -> 14.76
A44: 5 kg | B44: Manual | C44: =IFERROR(__xludf.DUMMYFUNCTION("""COMPUTED_VALUE"""),11) -> 11 | D44: =IFERROR(__xludf.DUMMYFUNCTION("""COMPUTED_VALUE"""),33.88) -> 33.88 | E44: =IFERROR(__xludf.DUMMYFUNCTION("""COMPUTED_VALUE"""),57.52) -> 57.52 | F44: =IFERROR(__xludf.DUMMYFUNCTION("""COMPUTED_VALUE"""),95.84) -> 95.84 | G44: =IFERROR(__xludf.DUMMYFUNCTION("""COMPUTED_VALUE"""),95.88) -> 95.88 | H44: =IFERROR(__xludf.DUMMYFUNCTION("""COMPUTED_VALUE"""),109.36) -> 109.36 | I44: =IFERROR(__xludf.DUMMYFUNCTION("""COMPUTED_VALUE"""),93.4) -> 93.4 | J44: =IFERROR(__xludf.DUMMYFUNCTION("""COMPUTED_VALUE"""),79.6) -> 79.6 | K44: =IFERROR(__xludf.DUMMYFUNCTION("""COMPUTED_VALUE"""),73.28) -> 73.28 | L44: =IFERROR(__xludf.DUMMYFUNCTION("""COMPUTED_VALUE"""),78.16) -> 78.16
...

Sheet Piezas
A1: Piezas del plano: cuerpos y discos de cúpula y fondo
A2: Medidas de los planos de recipiente (modelo 3D). El disco sale de la pieza embutida por igualdad de superficie, con su relación de embutido.
A4: A) Cuerpos (desarrollo = π·(Ø − e), fibra media)
A5: Formato | B5: Línea | C5: Plano | D5: Ø ext. (mm) | E5: Espesor (mm) | F5: Alto (mm) | G5: Desarrollo (mm) | H5: Masa (kg) | I5: Acero
A6: 1 kg | B6: Manual | C6: Plano recipiente 1 kg 3" R1 | D6: 76.2 | E6: 0.9 | F6: 263.5 | G6: =ROUND(PI()*(D6-E6)*2,0)/2 -> 236.5 | H6: =F6*G6*E6*Datos!$B$10/1000000 -> 0.44139662 | I6: LAF
A7: 2,5 kg | B7: Manual | C7: Plano recipiente 2,5 kg R2 | D7: 124 | E7: 1.25 | F7: 267.5 | G7: =ROUND(PI()*(D7-E7)*2,0)/2 -> 385.5 | H7: =F7*G7*E7*Datos!$B$10/1000000 -> 1.0144553 | I7: LAF
A8: 5 kg | B8: Manual | C8: Plano recipiente 5 kg R2 | D8: 153 | E8: 1.6 | F8: 327.5 | G8: =ROUND(PI()*(D8-E8)*2,0)/2 -> 475.5 | H8: =F8*G8*E8*Datos!$B$10/1000000 -> 1.9609049 | I8: LAF
A9: 10 kg | B9: Manual | C9: Plano recipiente 10 kg R2 | D9: 181.5 | E9: 2 | F9: 493 | G9: =ROUND(PI()*(D9-E9)*2,0)/2 -> 564 | H9: =F9*G9*E9*Datos!$B$10/1000000 -> 4.3765385 | I9: LAF
A10: 25 kg | B10: Rodante | C10: Plano recipiente 25 kg R3 | D10: 276.5 | E10: 3.2 | F10: 493 | G10: =ROUND(PI()*(D10-E10)*2,0)/2 -> 858.5 | H10: =F10*G10*E10*Datos!$B$10/1000000 -> 10.658889 | I10: LAC
A11: 50 kg | B11: Rodante | C11: Plano recipiente 50 kg R2 | D11: 320 | E11: 3.2 | F11: 640 | G11: =ROUND(PI()*(D11-E11)*2,0)/2 -> 995.5 | H11: =F11*G11*E11*Datos!$B$10/1000000 -> 16.04523 | I11: LAC
A12: 70 kg | B12: Rodante | C12: Plano extintor rodante 70 kg (Ø390) | D12: 390 | E12: 4.75 | F12: 680 | G12: =ROUND(PI()*(D12-E12)*2,0)/2 -> 1210.5 | H12: =F12*G12*E12*Datos!$B$10/1000000 -> 30.771031 | I12: LAC
A13: 100 kg | B13: Rodante | C13: Plano extintor rodante 100 kg R1 (Ø390) | D13: 390 | E13: 4.75 | F13: 900 | G13: =ROUND(PI()*(D13-E13)*2,0)/2 -> 1210.5 | H13: =F13*G13*E13*Datos!$B$10/1000000 -> 40.726365 | I13: LAC
A14: Alto: cuerpo del modelo 3D del plano (incluye el labio del encastre). 1 kg en chapa de 0,9 mm por decisión del grupo.
A16: B) Discos: igual superficie que la pieza embutida (sin sobremedida de recorte)
A17: Formato | B17: Pieza | C17: Perfil del plano | D17: Espesor e (mm) | E17: Ø ext. (mm) | F17: Altura h (mm) | G17: Pollera o pestaña p (mm) | H17: a = Ø/2 − e/2 (mm) | I17: b o profundidad (mm) | J17: Área media (mm²) | K17: D0 = √(4A/π) (mm) | L17: D0 adoptado (mm) | M17: d = 2a (mm) | N17: m = d/D0 | O17: e/D0 × 100 | P17: m1 mínimo | Q17: ¿Un solo embutido? | R17: h/d | S17: Masa del disco (kg) | T17: Plano | V17: e/D0 × 100 desde | W17: hasta | X17: m1 (1.er embutido)
A18: 1 kg | B18: Cúpula | C18: Semielipsoide + pollera | D18: 0.9 | E18: 76.2 | F18: 12.5 | G18: 6 | H18: =E18/2-D18/2 -> 37.65 | I18: =F18-G18-D18/2 -> 6.05 | J18: =PI()*H18^2+PI()*I18^2/(2*SQRT(1-(I18/H18)^2))*LN((1+SQRT(1-(I18/H18)^2))/(1-SQRT(1-(I18/H18)^2)))+2*PI()*H18*G18 -> 6165.6464 | K18: =SQRT(4*J18/PI()) -> 88.602172 | L18: =CEILING(K18,0.5) -> 89 | M18: =2*H18 -> 75.3 | N18: =M18/L18 -> 0.84606742 | O18: =D18/L18*100 -> 1.011236 | P18: =INDEX($X$18:$X$23,MATCH(O18,$V$18:$V$23,1)) -> 0.53 | Q18: =IF(N18>=P18,"Sí","No: dos embutidos") -> Sí | R18: =F18/E18 -> 0.16404199 | S18: =PI()*L18^2/4*D18*Datos!$B$10/1000000 -> 0.044064326 | T18: Plano recipiente 1 kg 3" R1 | V18: 0.08 | W18: 0.15 | X18: 0.63
A19: 1 kg | B19: Fondo | C19: Semielipsoide + pollera | D19: 1.25 | E19: 76.2 | F19: 22 | G19: 6 | H19: =E19/2-D19/2 -> 37.475 | I19: =F19-G19-D19/2 -> 15.375 | J19: =PI()*H19^2+PI()*I19^2/(2*SQRT(1-(I19/H19)^2))*LN((1+SQRT(1-(I19/H19)^2))/(1-SQRT(1-(I19/H19)^2)))+2*PI()*H19*G19 -> 7078.062 | K19: =SQRT(4*J19/PI()) -> 94.931915 | L19: =CEILING(K19,0.5) -> 95 | M19: =2*H19 -> 74.95 | N19: =M19/L19 -> 0.78894737 | O19: =D19/L19*100 -> 1.3157895 | P19: =INDEX($X$18:$X$23,MATCH(O19,$V$18:$V$23,1)) -> 0.53 | Q19: =IF(N19>=P19,"Sí","No: dos embutidos") -> Sí | R19: =F19/E19 -> 0.28871391 | S19: =PI()*L19^2/4*D19*Datos!$B$10/1000000 -> 0.069730349 | T19: Plano recipiente 1 kg 3" R1 | V19: 0.15 | W19: 0.3 | X19: 0.6
A20: 2,5 kg | B20: Cúpula | C20: Semielipsoide + pollera | D20: 1.25 | E20: 124 | F20: 39.5 | G20: 6 | H20: =E20/2-D20/2 -> 61.375 | I20: =F20-G20-D20/2 -> 32.875 | J20: =PI()*H20^2+PI()*I20^2/(2*SQRT(1-(I20/H20)^2))*LN((1+SQRT(1-(I20/H20)^2))/(1-SQRT(1-(I20/H20)^2)))+2*PI()*H20*G20 -> 19119.382 | K20: =SQRT(4*J20/PI()) -> 156.02421 | L20: =CEILING(K20,0.5) -> 156.5 | M20: =2*H20 -> 122.75 | N20: =M20/L20 -> 0.78434505 | O20: =D20/L20*100 -> 0.79872204 | P20: =INDEX($X$18:$X$23,MATCH(O20,$V$18:$V$23,1)) -> 0.55 | Q20: =IF(N20>=P20,"Sí","No: dos embutidos") -> Sí | R20: =F20/E20 -> 0.31854839 | S20: =PI()*L20^2/4*D20*Datos!$B$10/1000000 -> 0.1892358 | T20: Plano recipiente 2,5 kg R2 | V20: 0.3 | W20: 0.6 | X20: 0.58
A21: 2,5 kg | B21: Fondo | C21: Paraboloide + pestaña | D21: 1.25 | E21: 121.5 | F21: 10.5 | G21: 10 | H21: =E21/2-D21/2 -> 60.125 | I21: =F21 -> 10.5 | J21: =PI()*H21^4/(6*I21^2)*((1+4*I21^2/H21^2)^1.5-1)+2*PI()*H21*G21 -> 15474.294 | K21: =SQRT(4*J21/PI()) -> 140.36553 | L21: =CEILING(K21,0.5) -> 140.5 | M21: =2*H21 -> 120.25 | N21: =M21/L21 -> 0.85587189 | O21: =D21/L21*100 -> 0.88967972 | P21: =INDEX($X$18:$X$23,MATCH(O21,$V$18:$V$23,1)) -> 0.55 | Q21: =IF(N21>=P21,"Sí","No: dos embutidos") -> Sí | R21: =(F21+G21)/E21 -> 0.16872428 | S21: =PI()*L21^2/4*D21*Datos!$B$10/1000000 -> 0.15252017 | T21: Plano recipiente 2,5 kg R2; Ø del fondo = Ø del cuerpo − 2 e | V21: 0.6 | W21: 1 | X21: 0.55
A22: 5 kg | B22: Cúpula | C22: Semielipsoide + pollera | D22: 1.6 | E22: 153 | F22: 54.5 | G22: 6 | H22: =E22/2-D22/2 -> 75.7 | I22: =F22-G22-D22/2 -> 47.7 | J22: =PI()*H22^2+PI()*I22^2/(2*SQRT(1-(I22/H22)^2))*LN((1+SQRT(1-(I22/H22)^2))/(1-SQRT(1-(I22/H22)^2)))+2*PI()*H22*G22 -> 30398.075 | K22: =SQRT(4*J22/PI()) -> 196.7334 | L22: =CEILING(K22,0.5) -> 197 | M22: =2*H22 -> 151.4 | N22: =M22/L22 -> 0.76852792 | O22: =D22/L22*100 -> 0.81218274 | P22: =INDEX($X$18:$X$23,MATCH(O22,$V$18:$V$23,1)) -> 0.55 | Q22: =IF(N22>=P22,"Sí","No: dos embutidos") -> Sí | R22: =F22/E22 -> 0.35620915 | S22: =PI()*L22^2/4*D22*Datos!$B$10/1000000 -> 0.38381067 | T22: Plano recipiente 5 kg R2 | V22: 1 | W22: 1.5 | X22: 0.53
A23: 5 kg | B23: Fondo | C23: Paraboloide + pestaña | D23: 1.6 | E23: 149.8 | F23: 16 | G23: 10 | H23: =E23/2-D23/2 -> 74.1 | I23: =F23 -> 16 | J23: =PI()*H23^4/(6*I23^2)*((1+4*I23^2/H23^2)^1.5-1)+2*PI()*H23*G23 -> 22686.58 | K23: =SQRT(4*J23/PI()) -> 169.9572 | L23: =CEILING(K23,0.5) -> 170 | M23: =2*H23 -> 148.2 | N23: =M23/L23 -> 0.87176471 | O23: =D23/L23*100 -> 0.94117647 | P23: =INDEX($X$18:$X$23,MATCH(O23,$V$18:$V$23,1)) -> 0.55 | Q23: =IF(N23>=P23,"Sí","No: dos embutidos") -> Sí | R23: =(F23+G23)/E23 -> 0.17356475 | S23: =PI()*L23^2/4*D23*Datos!$B$10/1000000 -> 0.2858133 | T23: Plano recipiente 5 kg R2; Ø del fondo = Ø del cuerpo − 2 e | V23: 1.5 | W23: 2 | X23: 0.5
A24: 10 kg | B24: Cúpula | C24: Semielipsoide + pollera | D24: 1.6 | E24: 181.5 | F24: 62.5 | G24: 6 | H24: =E24/2-D24/2 -> 89.95 | I24: =F24-G24-D24/2 -> 55.7 | J24: =PI()*H24^2+PI()*I24^2/(2*SQRT(1-(I24/H24)^2))*LN((1+SQRT(1-(I24/H24)^2))/(1-SQRT(1-(I24/H24)^2)))+2*PI()*H24*G24 -> 41952.632 | K24: =SQRT(4*J24/PI()) -> 231.11848 | L24: =CEILING(K24,0.5) -> 231.5 | M24: =2*H24 -> 179.9 | N24: =M24/L24 -> 0.77710583 | O24: =D24/L24*100 -> 0.69114471 | P24: =INDEX($X$18:$X$23,MATCH(O24,$V$18:$V$23,1)) -> 0.55 | Q24: =IF(N24>=P24,"Sí","No: dos embutidos") -> Sí | R24: =F24/E24 -> 0.34435262 | S24: =PI()*L24^2/4*D24*Datos!$B$10/1000000 -> 0.53001308 | T24: Plano recipiente 10 kg R2 | V24: Valor alto de cada rango (lado seguro).
A25: 10 kg | B25: Fondo | C25: Paraboloide + pestaña | D25: 2 | E25: 177.5 | F25: 11.7 | G25: 10 | H25: =E25/2-D25/2 -> 87.75 | I25: =F25 -> 11.7 | J25: =PI()*H25^4/(6*I25^2)*((1+4*I25^2/H25^2)^1.5-1)+2*PI()*H25*G25 -> 30129.042 | K25: =SQRT(4*J25/PI()) -> 195.86089 | L25: =CEILING(K25,0.5) -> 196 | M25: =2*H25 -> 175.5 | N25: =M25/L25 -> 0.89540816 | O25: =D25/L25*100 -> 1.0204082 | P25: =INDEX($X$18:$X$23,MATCH(O25,$V$18:$V$23,1)) -> 0.53 | Q25: =IF(N25>=P25,"Sí","No: dos embutidos") -> Sí | R25: =(F25+G25)/E25 -> 0.12225352 | S25: =PI()*L25^2/4*D25*Datos!$B$10/1000000 -> 0.47490501 | T25: Plano recipiente 10 kg R2; Ø del fondo = Ø del cuerpo − 2 e
A27: Fuentes
A28: Disco y pieza tienen la misma superficie (el espesor no cambia): Harsle, «How to Calculate Deep Drawing Parts» (harslepress.com).
A29: Superficie del semielipsoide achatado y del paraboloide de revolución: fórmulas de geometría (MathWorld, «Oblate Spheroid» y «Paraboloid»).
A30: m1: relación de embutido del primer paso, copa sin brida, con prensachapas (EasyChair, preprint Vxvp, tabla 2). Límite general D0/d ≤ 2 (Univ. Mustansiriyah, apunte de embutido).
A31: Sin sobremedida de recorte: la prensa corta y embute en el mismo golpe, sin recorte después (W-MAN, puesto 4), y la tabla de recorte de Harsle arranca en h/d = 0,5 (estas piezas tienen h/d de 0,12 a 0,36).
A32: Geometría (Ø, alturas, pollera de 6 mm, pestaña de 10 mm, espesores): planos de recipiente (modelo 3D).

Sheet Corte
A1: Corte: cómo sale cada pieza de la hoja, la bobina, el fleje y la bobina madre
A2: Medidas de la hoja Piezas. Dos guillotinas en serie: G1 corta franjas, pasan por un pulmón y G2 apoya varias franjas una al lado de la otra y corta una pieza de cada una por golpe.
A4: A) Cuerpos en hoja estándar con dos guillotinas en serie (B y D)
A5: Formato | B5: Hoja ancho (mm) | C5: Hoja largo (mm) | D5: Piezas por hoja | E5: Aprovech. | F5: Franja = 1.er corte (mm) | G5: Franjas por hoja | H5: Piezas por franja | I5: Pieza = 2.º corte (mm) | J5: Tope de G1 en el 1.er corte (mm) | K5: 2.º corte en | L5: Franjas en paralelo | M5: Golpes G1 por hoja | N5: Golpes G2 por hoja | O5: Minutos de guillotina por hoja | P5: Masa de la hoja (kg) | Q5: USD por hoja | R5: Control
A6: 1 kg | B6: 1220 | C6: 2440 | D6: =MAX(INT(B6/Piezas!$F$6)*INT(C6/Piezas!$G$6),INT(B6/Piezas!$G$6)*INT(C6/Piezas!$F$6)) -> 45 | E6: =D6*Piezas!$F$6*Piezas!$G$6/(B6*C6) -> 0.94205145 | F6: =IF(INT(B6/Piezas!$F$6)*INT(C6/Piezas!$G$6)>=INT(B6/Piezas!$G$6)*INT(C6/Piezas!$F$6),Piezas!$F$6,Piezas!$G$6) -> 236.5 | G6: =INT(B6/F6) -> 5 | H6: =IF(INT(B6/Piezas!$F$6)*INT(C6/Piezas!$G$6)>=INT(B6/Piezas!$G$6)*INT(C6/Piezas!$F$6),INT(C6/Piezas!$G$6),INT(C6/Piezas!$F$6)) -> 9 | I6: =IF(INT(B6/Piezas!$F$6)*INT(C6/Piezas!$G$6)>=INT(B6/Piezas!$G$6)*INT(C6/Piezas!$F$6),Piezas!$G$6,Piezas!$F$6) -> 263.5 | J6: =IF(F6<=Datos!$B$32,F6,B6-F6*G6) -> 236.5 | K6: =IF(AND(I6<=Datos!$B$35,F6<=Datos!$B$34),"G2","G1") -> G2 | L6: =INT(IF(K6="G2",Datos!$B$34,Datos!$B$31)/F6) -> 10 | M6: =G6+IF(K6="G1",G6*H6/L6,0) -> 5 | N6: =IF(K6="G2",G6*H6/L6,0) -> 4.5 | O6: =M6/Datos!$B$30+N6/Datos!$B$33 -> 0.725 | P6: =B6*C6*Piezas!$E$6*Datos!$B$10/1000000 -> 21.084674 | Q6: =P6*INDEX(Datos!$C$90:$C$95,MATCH(Piezas!$E$6,Datos!$A$90:$A$95,0)) -> 28.592927 | R6: =IF(C6>Datos!$B$31,"Hoja más larga que la cuchilla de G1",IF(J6>Datos!$B$32,"Franja mayor que el tope de G1",IF(AND(K6="G1",I6>Datos!$B$32),"Pieza mayor que el tope de G1: va en la hoja mixta","OK"))) -> OK
A7: 2,5 kg | B7: 1220 | C7: 2440 | D7: =MAX(INT(B7/Piezas!$F$7)*INT(C7/Piezas!$G$7),INT(B7/Piezas!$G$7)*INT(C7/Piezas!$F$7)) -> 27 | E7: =D7*Piezas!$F$7*Piezas!$G$7/(B7*C7) -> 0.93532443 | F7: =IF(INT(B7/Piezas!$F$7)*INT(C7/Piezas!$G$7)>=INT(B7/Piezas!$G$7)*INT(C7/Piezas!$F$7),Piezas!$F$7,Piezas!$G$7) -> 385.5 | G7: =INT(B7/F7) -> 3 | H7: =IF(INT(B7/Piezas!$F$7)*INT(C7/Piezas!$G$7)>=INT(B7/Piezas!$G$7)*INT(C7/Piezas!$F$7),INT(C7/Piezas!$G$7),INT(C7/Piezas!$F$7)) -> 9 | I7: =IF(INT(B7/Piezas!$F$7)*INT(C7/Piezas!$G$7)>=INT(B7/Piezas!$G$7)*INT(C7/Piezas!$F$7),Piezas!$G$7,Piezas!$F$7) -> 267.5 | J7: =IF(F7<=Datos!$B$32,F7,B7-F7*G7) -> 385.5 | K7: =IF(AND(I7<=Datos!$B$35,F7<=Datos!$B$34),"G2","G1") -> G2 | L7: =INT(IF(K7="G2",Datos!$B$34,Datos!$B$31)/F7) -> 6 | M7: =G7+IF(K7="G1",G7*H7/L7,0) -> 3 | N7: =IF(K7="G2",G7*H7/L7,0) -> 4.5 | O7: =M7/Datos!$B$30+N7/Datos!$B$33 -> 0.525 | P7: =B7*C7*Piezas!$E$7*Datos!$B$10/1000000 -> 29.28427 | Q7: =P7*INDEX(Datos!$C$90:$C$95,MATCH(Piezas!$E$7,Datos!$A$90:$A$95,0)) -> 37.785427 | R7: =IF(C7>Datos!$B$31,"Hoja más larga que la cuchilla de G1",IF(J7>Datos!$B$32,"Franja mayor que el tope de G1",IF(AND(K7="G1",I7>Datos!$B$32),"Pieza mayor que el tope de G1: va en la hoja mixta","OK"))) -> OK
A8: 5 kg | B8: 1000 | C8: 2000 | D8: =MAX(INT(B8/Piezas!$F$8)*INT(C8/Piezas!$G$8),INT(B8/Piezas!$G$8)*INT(C8/Piezas!$F$8)) -> 12 | E8: =D8*Piezas!$F$8*Piezas!$G$8/(B8*C8) -> 0.9343575 | F8: =IF(INT(B8/Piezas!$F$8)*INT(C8/Piezas!$G$8)>=INT(B8/Piezas!$G$8)*INT(C8/Piezas!$F$8),Piezas!$F$8,Piezas!$G$8) -> 327.5 | G8: =INT(B8/F8) -> 3 | H8: =IF(INT(B8/Piezas!$F$8)*INT(C8/Piezas!$G$8)>=INT(B8/Piezas!$G$8)*INT(C8/Piezas!$F$8),INT(C8/Piezas!$G$8),INT(C8/Piezas!$F$8)) -> 4 | I8: =IF(INT(B8/Piezas!$F$8)*INT(C8/Piezas!$G$8)>=INT(B8/Piezas!$G$8)*INT(C8/Piezas!$F$8),Piezas!$G$8,Piezas!$F$8) -> 475.5 | J8: =IF(F8<=Datos!$B$32,F8,B8-F8*G8) -> 327.5 | K8: =IF(AND(I8<=Datos!$B$35,F8<=Datos!$B$34),"G2","G1") -> G2 | L8: =INT(IF(K8="G2",Datos!$B$34,Datos!$B$31)/F8) -> 7 | M8: =G8+IF(K8="G1",G8*H8/L8,0) -> 3 | N8: =IF(K8="G2",G8*H8/L8,0) -> 1.7142857 | O8: =M8/Datos!$B$30+N8/Datos!$B$33 -> 0.38571429 | P8: =B8*C8*Piezas!$E$8*Datos!$B$10/1000000 -> 25.184 | Q8: =P8*INDEX(Datos!$C$90:$C$95,MATCH(Piezas!$E$8,Datos!$A$90:$A$95,0)) -> 33.43229 | R8: =IF(C8>Datos!$B$31,"Hoja más larga que la cuchilla de G1",IF(J8>Datos!$B$32,"Franja mayor que el tope de G1",IF(AND(K8="G1",I8>Datos!$B$32),"Pieza mayor que el tope de G1: va en la hoja mixta","OK"))) -> OK
A9: 10 kg | B9: 1500 | C9: 3000 | D9: =MAX(INT(B9/Piezas!$F$9)*INT(C9/Piezas!$G$9),INT(B9/Piezas!$G$9)*INT(C9/Piezas!$F$9)) -> 15 | E9: =D9*Piezas!$F$9*Piezas!$G$9/(B9*C9) -> 0.92684 | F9: =IF(INT(B9/Piezas!$F$9)*INT(C9/Piezas!$G$9)>=INT(B9/Piezas!$G$9)*INT(C9/Piezas!$F$9),Piezas!$F$9,Piezas!$G$9) -> 493 | G9: =INT(B9/F9) -> 3 | H9: =IF(INT(B9/Piezas!$F$9)*INT(C9/Piezas!$G$9)>=INT(B9/Piezas!$G$9)*INT(C9/Piezas!$F$9),INT(C9/Piezas!$G$9),INT(C9/Piezas!$F$9)) -> 5 | I9: =IF(INT(B9/Piezas!$F$9)*INT(C9/Piezas!$G$9)>=INT(B9/Piezas!$G$9)*INT(C9/Piezas!$F$9),Piezas!$G$9,Piezas!$F$9) -> 564 | J9: =IF(F9<=Datos!$B$32,F9,B9-F9*G9) -> 493 | K9: =IF(AND(I9<=Datos!$B$35,F9<=Datos!$B$34),"G2","G1") -> G2 | L9: =INT(IF(K9="G2",Datos!$B$34,Datos!$B$31)/F9) -> 5 | M9: =G9+IF(K9="G1",G9*H9/L9,0) -> 3 | N9: =IF(K9="G2",G9*H9/L9,0) -> 3 | O9: =M9/Datos!$B$30+N9/Datos!$B$33 -> 0.45 | P9: =B9*C9*Piezas!$E$9*Datos!$B$10/1000000 -> 70.83 | Q9: =P9*INDEX(Datos!$C$90:$C$95,MATCH(Piezas!$E$9,Datos!$A$90:$A$95,0)) -> 90.690824 | R9: =IF(C9>Datos!$B$31,"Hoja más larga que la cuchilla de G1",IF(J9>Datos!$B$32,"Franja mayor que el tope de G1",IF(AND(K9="G1",I9>Datos!$B$32),"Pieza mayor que el tope de G1: va en la hoja mixta","OK"))) -> OK
A10: 25 kg | B10: 1500 | C10: 3000 | D10: =MAX(INT(B10/Piezas!$F$10)*INT(C10/Piezas!$G$10),INT(B10/Piezas!$G$10)*INT(C10/Piezas!$F$10)) -> 9 | E10: =D10*Piezas!$F$10*Piezas!$G$10/(B10*C10) -> 0.846481 | F10: =IF(INT(B10/Piezas!$F$10)*INT(C10/Piezas!$G$10)>=INT(B10/Piezas!$G$10)*INT(C10/Piezas!$F$10),Piezas!$F$10,Piezas!$G$10) -> 493 | G10: =INT(B10/F10) -> 3 | H10: =IF(INT(B10/Piezas!$F$10)*INT(C10/Piezas!$G$10)>=INT(B10/Piezas!$G$10)*INT(C10/Piezas!$F$10),INT(C10/Piezas!$G$10),INT(C10/Piezas!$F$10)) -> 3 | I10: =IF(INT(B10/Piezas!$F$10)*INT(C10/Piezas!$G$10)>=INT(B10/Piezas!$G$10)*INT(C10/Piezas!$F$10),Piezas!$G$10,Piezas!$F$10) -> 858.5 | J10: =IF(F10<=Datos!$B$32,F10,B10-F10*G10) -> 493 | K10: =IF(AND(I10<=Datos!$B$35,F10<=Datos!$B$34),"G2","G1") -> G1 | L10: =INT(IF(K10="G2",Datos!$B$34,Datos!$B$31)/F10) -> 6 | M10: =G10+IF(K10="G1",G10*H10/L10,0) -> 4.5 | N10: =IF(K10="G2",G10*H10/L10,0) -> 0 | O10: =M10/Datos!$B$30+N10/Datos!$B$33 -> 0.45 | P10: =B10*C10*Piezas!$E$10*Datos!$B$10/1000000 -> 113.328 | Q10: =P10*INDEX(Datos!$C$90:$C$95,MATCH(Piezas!$E$10,Datos!$A$90:$A$95,0)) -> 124.88012 | R10: =IF(C10>Datos!$B$31,"Hoja más larga que la cuchilla de G1",IF(J10>Datos!$B$32,"Franja mayor que el tope de G1",IF(AND(K10="G1",I10>Datos!$B$32),"Pieza mayor que el tope de G1: va en la hoja mixta","OK"))) -> OK
A11: 50 kg | B11: 1500 | C11: 3000 | D11: =MAX(INT(B11/Piezas!$F$11)*INT(C11/Piezas!$G$11),INT(B11/Piezas!$G$11)*INT(C11/Piezas!$F$11)) -> 6 | E11: =D11*Piezas!$F$11*Piezas!$G$11/(B11*C11) -> 0.84949333 | F11: =IF(INT(B11/Piezas!$F$11)*INT(C11/Piezas!$G$11)>=INT(B11/Piezas!$G$11)*INT(C11/Piezas!$F$11),Piezas!$F$11,Piezas!$G$11) -> 640 | G11: =INT(B11/F11) -> 2 | H11: =IF(INT(B11/Piezas!$F$11)*INT(C11/Piezas!$G$11)>=INT(B11/Piezas!$G$11)*INT(C11/Piezas!$F$11),INT(C11/Piezas!$G$11),INT(C11/Piezas!$F$11)) -> 3 | I11: =IF(INT(B11/Piezas!$F$11)*INT(C11/Piezas!$G$11)>=INT(B11/Piezas!$G$11)*INT(C11/Piezas!$F$11),Piezas!$G$11,Piezas!$F$11) -> 995.5 | J11: =IF(F11<=Datos!$B$32,F11,B11-F11*G11) -> 640 | K11: =IF(AND(I11<=Datos!$B$35,F11<=Datos!$B$34),"G2","G1") -> G1 | L11: =INT(IF(K11="G2",Datos!$B$34,Datos!$B$31)/F11) -> 5 | M11: =G11+IF(K11="G1",G11*H11/L11,0) -> 3.2 | N11: =IF(K11="G2",G11*H11/L11,0) -> 0 | O11: =M11/Datos!$B$30+N11/Datos!$B$33 -> 0.32 | P11: =B11*C11*Piezas!$E$11*Datos!$B$10/1000000 -> 113.328 | Q11: =P11*INDEX(Datos!$C$90:$C$95,MATCH(Piezas!$E$11,Datos!$A$90:$A$95,0)) -> 124.88012 | R11: =IF(C11>Datos!$B$31,"Hoja más larga que la cuchilla de G1",IF(J11>Datos!$B$32,"Franja mayor que el tope de G1",IF(AND(K11="G1",I11>Datos!$B$32),"Pieza mayor que el tope de G1: va en la hoja mixta","OK"))) -> OK
A12: 70 kg | B12: 1500 | C12: 3000 | D12: =MAX(INT(B12/Piezas!$F$12)*INT(C12/Piezas!$G$12),INT(B12/Piezas!$G$12)*INT(C12/Piezas!$F$12)) -> 4 | E12: =D12*Piezas!$F$12*Piezas!$G$12/(B12*C12) -> 0.73168 | F12: =IF(INT(B12/Piezas!$F$12)*INT(C12/Piezas!$G$12)>=INT(B12/Piezas!$G$12)*INT(C12/Piezas!$F$12),Piezas!$F$12,Piezas!$G$12) -> 680 | G12: =INT(B12/F12) -> 2 | H12: =IF(INT(B12/Piezas!$F$12)*INT(C12/Piezas!$G$12)>=INT(B12/Piezas!$G$12)*INT(C12/Piezas!$F$12),INT(C12/Piezas!$G$12),INT(C12/Piezas!$F$12)) -> 2 | I12: =IF(INT(B12/Piezas!$F$12)*INT(C12/Piezas!$G$12)>=INT(B12/Piezas!$G$12)*INT(C12/Piezas!$F$12),Piezas!$G$12,Piezas!$F$12) -> 1210.5 | J12: =IF(F12<=Datos!$B$32,F12,B12-F12*G12) -> 680 | K12: =IF(AND(I12<=Datos!$B$35,F12<=Datos!$B$34),"G2","G1") -> G1 | L12: =INT(IF(K12="G2",Datos!$B$34,Datos!$B$31)/F12) -> 4 | M12: =G12+IF(K12="G1",G12*H12/L12,0) -> 3 | N12: =IF(K12="G2",G12*H12/L12,0) -> 0 | O12: =M12/Datos!$B$30+N12/Datos!$B$33 -> 0.3 | P12: =B12*C12*Piezas!$E$12*Datos!$B$10/1000000 -> 168.22125 | Q12: =P12*INDEX(Datos!$C$90:$C$95,MATCH(Piezas!$E$12,Datos!$A$90:$A$95,0)) -> 183.52557 | R12: =IF(C12>Datos!$B$31,"Hoja más larga que la cuchilla de G1",IF(J12>Datos!$B$32,"Franja mayor que el tope de G1",IF(AND(K12="G1",I12>Datos!$B$32),"Pieza mayor que el tope de G1: va en la hoja mixta","OK"))) -> Pieza mayor que el tope de G1: va en la hoja mixta
A13: 100 kg | B13: 1500 | C13: 3000 | D13: =MAX(INT(B13/Piezas!$F$13)*INT(C13/Piezas!$G$13),INT(B13/Piezas!$G$13)*INT(C13/Piezas!$F$13)) -> 3 | E13: =D13*Piezas!$F$13*Piezas!$G$13/(B13*C13) -> 0.7263 | F13: =IF(INT(B13/Piezas!$F$13)*INT(C13/Piezas!$G$13)>=INT(B13/Piezas!$G$13)*INT(C13/Piezas!$F$13),Piezas!$F$13,Piezas!$G$13) -> 1210.5 | G13: =INT(B13/F13) -> 1 | H13: =IF(INT(B13/Piezas!$F$13)*INT(C13/Piezas!$G$13)>=INT(B13/Piezas!$G$13)*INT(C13/Piezas!$F$13),INT(C13/Piezas!$G$13),INT(C13/Piezas!$F$13)) -> 3 | I13: =IF(INT(B13/Piezas!$F$13)*INT(C13/Piezas!$G$13)>=INT(B13/Piezas!$G$13)*INT(C13/Piezas!$F$13),Piezas!$G$13,Piezas!$F$13) -> 900 | J13: =IF(F13<=Datos!$B$32,F13,B13-F13*G13) -> 289.5 | K13: =IF(AND(I13<=Datos!$B$35,F13<=Datos!$B$34),"G2","G1") -> G1 | L13: =INT(IF(K13="G2",Datos!$B$34,Datos!$B$31)/F13) -> 2 | M13: =G13+IF(K13="G1",G13*H13/L13,0) -> 2.5 | N13: =IF(K13="G2",G13*H13/L13,0) -> 0 | O13: =M13/Datos!$B$30+N13/Datos!$B$33 -> 0.25 | P13: =B13*C13*Piezas!$E$13*Datos!$B$10/1000000 -> 168.22125 | Q13: =P13*INDEX(Datos!$C$90:$C$95,MATCH(Piezas!$E$13,Datos!$A$90:$A$95,0)) -> 183.52557 | R13: =IF(C13>Datos!$B$31,"Hoja más larga que la cuchilla de G1",IF(J13>Datos!$B$32,"Franja mayor que el tope de G1",IF(AND(K13="G1",I13>Datos!$B$32),"Pieza mayor que el tope de G1: va en la hoja mixta","OK"))) -> OK
A14: Hoja mixta 70 + 100 kg | B14: =B13 -> 1500 | C14: =C13 -> 3000 | D14: =Datos!$B$25+Datos!$B$26 -> 4 | E14: =(Datos!$B$25*Piezas!$F$13*Piezas!$G$13+Datos!$B$26*Piezas!$F$12*Piezas!$G$12)/(B14*C14) -> 0.79086 | F14: =Piezas!$G$13 -> 1210.5 | G14: 1 | H14: =D14 -> 4 | I14: =MAX(Piezas!$F$13,Piezas!$F$12) -> 900 | J14: =IF(F14<=Datos!$B$32,F14,B14-F14*G14) -> 289.5 | K14: =IF(AND(I14<=Datos!$B$35,F14<=Datos!$B$34),"G2","G1") -> G1 | L14: =INT(IF(K14="G2",Datos!$B$34,Datos!$B$31)/F14) -> 2 | M14: =G14+IF(K14="G1",G14*H14/L14,0) -> 3 | N14: =IF(K14="G2",G14*H14/L14,0) -> 0 | O14: =M14/Datos!$B$30+N14/Datos!$B$33 -> 0.3 | P14: =B14*C14*Piezas!$E$13*Datos!$B$10/1000000 -> 168.22125 | Q14: =P14*INDEX(Datos!$C$90:$C$95,MATCH(Piezas!$E$13,Datos!$A$90:$A$95,0)) -> 183.52557 | R14: =IF(AND(Piezas!$G$12<=B14,Piezas!$G$13<=B14,Datos!$B$25*Piezas!$F$13+Datos!$B$26*Piezas!$F$12<=C14),"OK: 1 de 100 kg y 3 de 70 kg","No entra") -> OK: 1 de 100 kg y 3 de 70 kg
A15: 2.º corte en G2 si la pieza entra en su tope (800 mm); si no, en G1 (tope 1.000 mm). La franja más ancha que el tope de G1 se saca cortando la orilla del otro lado.
A17: B) Cuerpos en bobina de ancho estándar con línea de corte transversal (A) y a medida (Ref.)
A18: Formato | B18: Ancho de bobina (mm) | C18: Piezas por golpe | D18: Avance por golpe (mm) | E18: Aprovech. | F18: kg comprados por cuerpo | G18: USD por cuerpo | H18: Peso de bobina (t) | I18: USD por cuerpo a medida (Ref.)
A19: 1 kg | B19: 1220 | C19: =IF(INT((B19-Datos!$B$19)/Piezas!$F$6)*Piezas!$F$6/B19>=INT((B19-Datos!$B$19)/Piezas!$G$6)*Piezas!$G$6/B19,INT((B19-Datos!$B$19)/Piezas!$F$6),INT((B19-Datos!$B$19)/Piezas!$G$6)) -> 5 | D19: =IF(INT((B19-Datos!$B$19)/Piezas!$F$6)*Piezas!$F$6/B19>=INT((B19-Datos!$B$19)/Piezas!$G$6)*Piezas!$G$6/B19,Piezas!$G$6,Piezas!$F$6) -> 263.5 | E19: =MAX(INT((B19-Datos!$B$19)/Piezas!$F$6)*Piezas!$F$6/B19,INT((B19-Datos!$B$19)/Piezas!$G$6)*Piezas!$G$6/B19)*(1-Datos!$B$20) -> 0.96441598 | F19: =Piezas!$H$6/E19 -> 0.45768282 | G19: =F19*INDEX(Datos!$B$90:$B$95,MATCH(Piezas!$E$6,Datos!$A$90:$A$95,0)) -> 0.57798474 | H19: =MIN(ROUNDDOWN(MIN(B19*Datos!$B$52,Datos!$B$53)*2,0)/2,MAX(Datos!$B$49,ROUNDUP(INDEX(Demanda!$C$6:$L$6,Datos!$B$6-2025)*F19/1000/12*Datos!$B$47*2,0)/2)) -> 8 | I19: =Piezas!$H$6*INDEX(Datos!$F$90:$F$95,MATCH(Piezas!$E$6,Datos!$A$90:$A$95,0)) -> 0.59857796
A20: 2,5 kg | B20: 1220 | C20: =IF(INT((B20-Datos!$B$19)/Piezas!$F$7)*Piezas!$F$7/B20>=INT((B20-Datos!$B$19)/Piezas!$G$7)*Piezas!$G$7/B20,INT((B20-Datos!$B$19)/Piezas!$F$7),INT((B20-Datos!$B$19)/Piezas!$G$7)) -> 3 | D20: =IF(INT((B20-Datos!$B$19)/Piezas!$F$7)*Piezas!$F$7/B20>=INT((B20-Datos!$B$19)/Piezas!$G$7)*Piezas!$G$7/B20,Piezas!$G$7,Piezas!$F$7) -> 267.5 | E20: =MAX(INT((B20-Datos!$B$19)/Piezas!$F$7)*Piezas!$F$7/B20,INT((B20-Datos!$B$19)/Piezas!$G$7)*Piezas!$G$7/B20)*(1-Datos!$B$20) -> 0.94321107 | F20: =Piezas!$H$7/E20 -> 1.0755337 | G20: =F20*INDEX(Datos!$B$90:$B$95,MATCH(Piezas!$E$7,Datos!$A$90:$A$95,0)) -> 1.3450194 | H20: =MIN(ROUNDDOWN(MIN(B20*Datos!$B$52,Datos!$B$53)*2,0)/2,MAX(Datos!$B$49,ROUNDUP(INDEX(Demanda!$C$7:$L$7,Datos!$B$6-2025)*F20/1000/12*Datos!$B$47*2,0)/2)) -> 1.5 | I20: =Piezas!$H$7*INDEX(Datos!$F$90:$F$95,MATCH(Piezas!$E$7,Datos!$A$90:$A$95,0)) -> 1.4466133
A21: 5 kg | B21: 1000 | C21: =IF(INT((B21-Datos!$B$19)/Piezas!$F$8)*Piezas!$F$8/B21>=INT((B21-Datos!$B$19)/Piezas!$G$8)*Piezas!$G$8/B21,INT((B21-Datos!$B$19)/Piezas!$F$8),INT((B21-Datos!$B$19)/Piezas!$G$8)) -> 3 | D21: =IF(INT((B21-Datos!$B$19)/Piezas!$F$8)*Piezas!$F$8/B21>=INT((B21-Datos!$B$19)/Piezas!$G$8)*Piezas!$G$8/B21,Piezas!$G$8,Piezas!$F$8) -> 475.5 | E21: =MAX(INT((B21-Datos!$B$19)/Piezas!$F$8)*Piezas!$F$8/B21,INT((B21-Datos!$B$19)/Piezas!$G$8)*Piezas!$G$8/B21)*(1-Datos!$B$20) -> 0.9775875 | F21: =Piezas!$H$8/E21 -> 2.0058613 | G21: =F21*INDEX(Datos!$B$90:$B$95,MATCH(Piezas!$E$8,Datos!$A$90:$A$95,0)) -> 2.5084499 | H21: =MIN(ROUNDDOWN(MIN(B21*Datos!$B$52,Datos!$B$53)*2,0)/2,MAX(Datos!$B$49,ROUNDUP(INDEX(Demanda!$C$8:$L$8,Datos!$B$6-2025)*F21/1000/12*Datos!$B$47*2,0)/2)) -> 10 | I21: =Piezas!$H$8*INDEX(Datos!$F$90:$F$95,MATCH(Piezas!$E$8,Datos!$A$90:$A$95,0)) -> 2.8491949
A22: 10 kg | B22: 1000 | C22: =IF(INT((B22-Datos!$B$19)/Piezas!$F$9)*Piezas!$F$9/B22>=INT((B22-Datos!$B$19)/Piezas!$G$9)*Piezas!$G$9/B22,INT((B22-Datos!$B$19)/Piezas!$F$9),INT((B22-Datos!$B$19)/Piezas!$G$9)) -> 2 | D22: =IF(INT((B22-Datos!$B$19)/Piezas!$F$9)*Piezas!$F$9/B22>=INT((B22-Datos!$B$19)/Piezas!$G$9)*Piezas!$G$9/B22,Piezas!$G$9,Piezas!$F$9) -> 564 | E22: =MAX(INT((B22-Datos!$B$19)/Piezas!$F$9)*Piezas!$F$9/B22,INT((B22-Datos!$B$19)/Piezas!$G$9)*Piezas!$G$9/B22)*(1-Datos!$B$20) -> 0.98107 | F22: =Piezas!$H$9/E22 -> 4.4609849 | G22: =F22*INDEX(Datos!$B$90:$B$95,MATCH(Piezas!$E$9,Datos!$A$90:$A$95,0)) -> 5.6335548 | H22: =MIN(ROUNDDOWN(MIN(B22*Datos!$B$52,Datos!$B$53)*2,0)/2,MAX(Datos!$B$49,ROUNDUP(INDEX(Demanda!$C$9:$L$9,Datos!$B$6-2025)*F22/1000/12*Datos!$B$47*2,0)/2)) -> 1.5 | I22: =Piezas!$H$9*INDEX(Datos!$F$90:$F$95,MATCH(Piezas!$E$9,Datos!$A$90:$A$95,0)) -> 6.2540735
A23: 25 kg | B23: 1500 | C23: =IF(INT((B23-Datos!$B$19)/Piezas!$F$10)*Piezas!$F$10/B23>=INT((B23-Datos!$B$19)/Piezas!$G$10)*Piezas!$G$10/B23,INT((B23-Datos!$B$19)/Piezas!$F$10),INT((B23-Datos!$B$19)/Piezas!$G$10)) -> 3 | D23: =IF(INT((B23-Datos!$B$19)/Piezas!$F$10)*Piezas!$F$10/B23>=INT((B23-Datos!$B$19)/Piezas!$G$10)*Piezas!$G$10/B23,Piezas!$G$10,Piezas!$F$10) -> 858.5 | E23: =MAX(INT((B23-Datos!$B$19)/Piezas!$F$10)*Piezas!$F$10/B23,INT((B23-Datos!$B$19)/Piezas!$G$10)*Piezas!$G$10/B23)*(1-Datos!$B$20) -> 0.98107 | F23: =Piezas!$H$10/E23 -> 10.864555 | G23: =F23*INDEX(Datos!$B$90:$B$95,MATCH(Piezas!$E$10,Datos!$A$90:$A$95,0)) -> 12.100181 | H23: =MIN(ROUNDDOWN(MIN(B23*Datos!$B$52,Datos!$B$53)*2,0)/2,MAX(Datos!$B$49,ROUNDUP(INDEX(Demanda!$C$10:$L$10,Datos!$B$6-2025)*F23/1000/12*Datos!$B$47*2,0)/2)) -> 1 | I23: =Piezas!$H$10*INDEX(Datos!$F$90:$F$95,MATCH(Piezas!$E$10,Datos!$A$90:$A$95,0)) -> 13.387564
A24: 50 kg | B24: 1500 | C24: =IF(INT((B24-Datos!$B$19)/Piezas!$F$11)*Piezas!$F$11/B24>=INT((B24-Datos!$B$19)/Piezas!$G$11)*Piezas!$G$11/B24,INT((B24-Datos!$B$19)/Piezas!$F$11),INT((B24-Datos!$B$19)/Piezas!$G$11)) -> 2 | D24: =IF(INT((B24-Datos!$B$19)/Piezas!$F$11)*Piezas!$F$11/B24>=INT((B24-Datos!$B$19)/Piezas!$G$11)*Piezas!$G$11/B24,Piezas!$G$11,Piezas!$F$11) -> 995.5 | E24: =MAX(INT((B24-Datos!$B$19)/Piezas!$F$11)*Piezas!$F$11/B24,INT((B24-Datos!$B$19)/Piezas!$G$11)*Piezas!$G$11/B24)*(1-Datos!$B$20) -> 0.84906667 | F24: =Piezas!$H$11/E24 -> 18.897491 | G24: =F24*INDEX(Datos!$B$90:$B$95,MATCH(Piezas!$E$11,Datos!$A$90:$A$95,0)) -> 21.046703 | H24: =MIN(ROUNDDOWN(MIN(B24*Datos!$B$52,Datos!$B$53)*2,0)/2,MAX(Datos!$B$49,ROUNDUP(INDEX(Demanda!$C$11:$L$11,Datos!$B$6-2025)*F24/1000/12*Datos!$B$47*2,0)/2)) -> 3 | I24: =Piezas!$H$11*INDEX(Datos!$F$90:$F$95,MATCH(Piezas!$E$11,Datos!$A$90:$A$95,0)) -> 20.152809
A25: 70 kg | B25: 1245 | C25: =IF(INT((B25-Datos!$B$19)/Piezas!$F$12)*Piezas!$F$12/B25>=INT((B25-Datos!$B$19)/Piezas!$G$12)*Piezas!$G$12/B25,INT((B25-Datos!$B$19)/Piezas!$F$12),INT((B25-Datos!$B$19)/Piezas!$G$12)) -> 1 | D25: =IF(INT((B25-Datos!$B$19)/Piezas!$F$12)*Piezas!$F$12/B25>=INT((B25-Datos!$B$19)/Piezas!$G$12)*Piezas!$G$12/B25,Piezas!$G$12,Piezas!$F$12) -> 680 | E25: =MAX(INT((B25-Datos!$B$19)/Piezas!$F$12)*Piezas!$F$12/B25,INT((B25-Datos!$B$19)/Piezas!$G$12)*Piezas!$G$12/B25)*(1-Datos!$B$20) -> 0.96742771 | F25: =Piezas!$H$12/E25 -> 31.80706 | G25: =F25*INDEX(Datos!$B$90:$B$95,MATCH(Piezas!$E$12,Datos!$A$90:$A$95,0)) -> 35.424477 | H25: =MIN(ROUNDDOWN(MIN(B25*Datos!$B$52,Datos!$B$53)*2,0)/2,MAX(Datos!$B$49,ROUNDUP(INDEX(Demanda!$C$12:$L$12,Datos!$B$6-2025)*F25/1000/12*Datos!$B$47*2,0)/2)) -> 1 | I25: =Piezas!$H$12*INDEX(Datos!$F$90:$F$95,MATCH(Piezas!$E$12,Datos!$A$90:$A$95,0)) -> 38.032994
A26: 100 kg | B26: 1245 | C26: =IF(INT((B26-Datos!$B$19)/Piezas!$F$13)*Piezas!$F$13/B26>=INT((B26-Datos!$B$19)/Piezas!$G$13)*Piezas!$G$13/B26,INT((B26-Datos!$B$19)/Piezas!$F$13),INT((B26-Datos!$B$19)/Piezas!$G$13)) -> 1 | D26: =IF(INT((B26-Datos!$B$19)/Piezas!$F$13)*Piezas!$F$13/B26>=INT((B26-Datos!$B$19)/Piezas!$G$13)*Piezas!$G$13/B26,Piezas!$G$13,Piezas!$F$13) -> 900 | E26: =MAX(INT((B26-Datos!$B$19)/Piezas!$F$13)*Piezas!$F$13/B26,INT((B26-Datos!$B$19)/Piezas!$G$13)*Piezas!$G$13/B26)*(1-Datos!$B$20) -> 0.96742771 | F26: =Piezas!$H$13/E26 -> 42.097579 | G26: =F26*INDEX(Datos!$B$90:$B$95,MATCH(Piezas!$E$13,Datos!$A$90:$A$95,0)) -> 46.885337 | H26: =MIN(ROUNDDOWN(MIN(B26*Datos!$B$52,Datos!$B$53)*2,0)/2,MAX(Datos!$B$49,ROUNDUP(INDEX(Demanda!$C$13:$L$13,Datos!$B$6-2025)*F26/1000/12*Datos!$B$47*2,0)/2)) -> 1 | I26: =Piezas!$H$13*INDEX(Datos!$F$90:$F$95,MATCH(Piezas!$E$13,Datos!$A$90:$A$95,0)) -> 50.337787
A29: C) Cúpulas y fondos: fleje a medida (A, D, Ref.) o tiras de hoja (B)
A30: Pieza | B30: Ø disco (mm) | C30: Espesor (mm) | D30: Puente de avance (mm) | E30: Puente al borde (mm) | F30: Ancho de fleje (mm) | G30: Paso (mm) | H30: Aprovech. del fleje | I30: kg de fleje por disco | J30: USD de fleje por disco | K30: Peso de rollo (t) | L30: Hoja para tiras: ancho | M30: largo | N30: Tiras por hoja | O30: Discos por tira | P30: Discos por hoja | Q30: Aprovech. de la hoja | R30: kg de hoja por disco | S30: USD de hoja por disco
A31: Cúpula 1 kg | B31: =Piezas!$L$18 -> 89 | C31: =Piezas!$D$18 -> 0.9 | D31: =MAX(Datos!$B$21*C31,Datos!$B$22) -> 1.35 | E31: =Datos!$B$23*D31 -> 2.025 | F31: =B31+2*E31 -> 93.05 | G31: =B31+D31 -> 90.35 | H31: =PI()*B31^2/4/(F31*G31)*(1-Datos!$B$20) -> 0.73628922 | I31: =Piezas!$S$18/H31 -> 0.059846492 | J31: =I31*INDEX(Datos!$D$90:$D$95,MATCH(C31,Datos!$A$90:$A$95,0)) -> 0.075577142 | K31: =MIN(ROUNDDOWN(MIN(F31*Datos!$B$52,Datos!$B$54)*2,0)/2,MAX(Datos!$B$49,ROUNDUP(INDEX(Demanda!$C$6:$L$6,Datos!$B$6-2025)*I31/1000/12*Datos!$B$47*2,0)/2)) -> 1 | L31: 1220 | M31: 2440 | N31: =IF(INT(L31/F31)*INT((M31-D31)/G31)>=INT(M31/F31)*INT((L31-D31)/G31),INT(L31/F31),INT(M31/F31)) -> 13 | O31: =IF(INT(L31/F31)*INT((M31-D31)/G31)>=INT(M31/F31)*INT((L31-D31)/G31),INT((M31-D31)/G31),INT((L31-D31)/G31)) -> 26 | P31: =N31*O31 -> 338 | Q31: =P31*PI()*B31^2/4/(L31*M31) -> 0.70637763 | R31: =L31*M31*C31*Datos!$B$10/1000000/P31 -> 0.062380693 | S31: =R31*INDEX(Datos!$C$90:$C$95,MATCH(C31,Datos!$A$90:$A$95,0)) -> 0.084594458
