Workbook

Sheet Links
A1: Links e IMPORTRANGE
A2: Pegar en B el link de cada Google Sheet. La primera vez, tocar la primera celda de cada bloque y «Permitir acceso». Todos los IMPORTRANGE del libro están en esta hoja; las demás la leen.
A3: Archivo | B3: Link | G3: Qué se importa | M3: Estado
A4: Proyecciones | B4: https://docs.google.com/spreadsheets/d/1xc4xDAwSYT3l-RulPYtcePxiCninrbQGzaBUsgO0YEs/edit?gid=1764491891#gid=1764491891 | G4: Indexado Dim Técnico B7:K10 y B19:K22 → datos_base | M4: =IF(ISERROR(B16),"Falta el link o «Permitir acceso»","OK") -> OK
A5: Dimensionamiento Recargas Planta Comercial | B5: PEGAR ACÁ EL LINK DEL GOOGLE SHEET | G5: sobrestock_sustitutos B86:K89: alta de sustitutos ABC (cilindros vacíos) → datos_base | M5: =IF(ISERROR(B37),"Falta el link o «Permitir acceso»","OK") -> OK
A6: Dimensionamiento Recargas Planta Industrial | B6: PEGAR ACÁ EL LINK DEL GOOGLE SHEET | G6: sobrestock_sustitutos B86:K89: alta de sustitutos ABC (terminados) → datos_base | M6: =IF(ISERROR(B30),"Falta el link o «Permitir acceso»","OK") -> OK
A7: MRP (FLAMA_MRP) | B7: PEGAR ACÁ EL LINK DEL GOOGLE SHEET | G7: ESTACIONALIDAD C6:N6 (E03) → parametros_carros filas 12 a 15 | M7: =IF(ISERROR(B12),"Falta el link o «Permitir acceso»","OK") -> OK
A10: MRP (FLAMA_MRP) · ESTACIONALIDAD!C6:N6: E03 rodantes (25 a 100 kg)
B11: Ene | C11: Feb | D11: Mar | E11: Abr | F11: May | G11: Jun | H11: Jul | I11: Ago | J11: Sep | K11: Oct | L11: Nov | M11: Dic
A12: E03 rodantes (25 a 100 kg) | B12: =IFERROR(__xludf.DUMMYFUNCTION("IMPORTRANGE(Links!$B$7,""ESTACIONALIDAD!C6:N6"")"),0.085) -> 0.085 | C12: =IFERROR(__xludf.DUMMYFUNCTION("""COMPUTED_VALUE"""),0.075) -> 0.075 | D12: =IFERROR(__xludf.DUMMYFUNCTION("""COMPUTED_VALUE"""),0.09) -> 0.09 | E12: =IFERROR(__xludf.DUMMYFUNCTION("""COMPUTED_VALUE"""),0.09) -> 0.09 | F12: =IFERROR(__xludf.DUMMYFUNCTION("""COMPUTED_VALUE"""),0.09) -> 0.09 | G12: =IFERROR(__xludf.DUMMYFUNCTION("""COMPUTED_VALUE"""),0.08) -> 0.08 | H12: =IFERROR(__xludf.DUMMYFUNCTION("""COMPUTED_VALUE"""),0.09) -> 0.09 | I12: =IFERROR(__xludf.DUMMYFUNCTION("""COMPUTED_VALUE"""),0.09) -> 0.09 | J12: =IFERROR(__xludf.DUMMYFUNCTION("""COMPUTED_VALUE"""),0.085) -> 0.085 | K12: =IFERROR(__xludf.DUMMYFUNCTION("""COMPUTED_VALUE"""),0.075) -> 0.075 | L12: =IFERROR(__xludf.DUMMYFUNCTION("""COMPUTED_VALUE"""),0.07) -> 0.07 | M12: =IFERROR(__xludf.DUMMYFUNCTION("""COMPUTED_VALUE"""),0.08) -> 0.08
A14: Proyecciones · Indexado Dim Técnico!B7:K10: carros terminados
B15: 2026 | C15: 2027 | D15: 2028 | E15: 2029 | F15: 2030 | G15: 2031 | H15: 2032 | I15: 2033 | J15: 2034 | K15: 2035
A16: Carro ABC 25 kg | B16: =IFERROR(__xludf.DUMMYFUNCTION("IMPORTRANGE(Links!$B$4,""Indexado Dim Técnico!B7:K10"")"),34.05179136) -> 34.051791 | C16: =IFERROR(__xludf.DUMMYFUNCTION("""COMPUTED_VALUE"""),58.46214745) -> 58.462147 | D16: =IFERROR(__xludf.DUMMYFUNCTION("""COMPUTED_VALUE"""),75.20853998) -> 75.20854 | E16: =IFERROR(__xludf.DUMMYFUNCTION("""COMPUTED_VALUE"""),100.5298529) -> 100.52985 | F16: =IFERROR(__xludf.DUMMYFUNCTION("""COMPUTED_VALUE"""),155.8760035) -> 155.876 | G16: =IFERROR(__xludf.DUMMYFUNCTION("""COMPUTED_VALUE"""),211.9344827) -> 211.93448 | H16: =IFERROR(__xludf.DUMMYFUNCTION("""COMPUTED_VALUE"""),272.6682332) -> 272.66823 | I16: =IFERROR(__xludf.DUMMYFUNCTION("""COMPUTED_VALUE"""),337.8486707) -> 337.84867 | J16: =IFERROR(__xludf.DUMMYFUNCTION("""COMPUTED_VALUE"""),393.6274156) -> 393.62742 | K16: =IFERROR(__xludf.DUMMYFUNCTION("""COMPUTED_VALUE"""),453.2705332) -> 453.27053
A17: Carro ABC 50 kg | B17: =IFERROR(__xludf.DUMMYFUNCTION("""COMPUTED_VALUE"""),74.913941) -> 74.913941 | C17: =IFERROR(__xludf.DUMMYFUNCTION("""COMPUTED_VALUE"""),128.6167244) -> 128.61672 | D17: =IFERROR(__xludf.DUMMYFUNCTION("""COMPUTED_VALUE"""),165.458788) -> 165.45879 | E17: =IFERROR(__xludf.DUMMYFUNCTION("""COMPUTED_VALUE"""),221.1656765) -> 221.16568 | F17: =IFERROR(__xludf.DUMMYFUNCTION("""COMPUTED_VALUE"""),342.9272077) -> 342.92721 | G17: =IFERROR(__xludf.DUMMYFUNCTION("""COMPUTED_VALUE"""),466.255862) -> 466.25586 | H17: =IFERROR(__xludf.DUMMYFUNCTION("""COMPUTED_VALUE"""),599.8701129) -> 599.87011 | I17: =IFERROR(__xludf.DUMMYFUNCTION("""COMPUTED_VALUE"""),743.2670756) -> 743.26708 | J17: =IFERROR(__xludf.DUMMYFUNCTION("""COMPUTED_VALUE"""),865.9803143) -> 865.98031 | K17: =IFERROR(__xludf.DUMMYFUNCTION("""COMPUTED_VALUE"""),997.1951731) -> 997.19517
A18: Carro ABC 70 kg | B18: =IFERROR(__xludf.DUMMYFUNCTION("""COMPUTED_VALUE"""),16.34485985) -> 16.34486 | C18: =IFERROR(__xludf.DUMMYFUNCTION("""COMPUTED_VALUE"""),28.06183078) -> 28.061831 | D18: =IFERROR(__xludf.DUMMYFUNCTION("""COMPUTED_VALUE"""),36.10009919) -> 36.100099 | E18: =IFERROR(__xludf.DUMMYFUNCTION("""COMPUTED_VALUE"""),48.25432941) -> 48.254329 | F18: =IFERROR(__xludf.DUMMYFUNCTION("""COMPUTED_VALUE"""),74.82048167) -> 74.820482 | G18: =IFERROR(__xludf.DUMMYFUNCTION("""COMPUTED_VALUE"""),101.7285517) -> 101.72855 | H18: =IFERROR(__xludf.DUMMYFUNCTION("""COMPUTED_VALUE"""),130.8807519) -> 130.88075 | I18: =IFERROR(__xludf.DUMMYFUNCTION("""COMPUTED_VALUE"""),162.1673619) -> 162.16736 | J18: =IFERROR(__xludf.DUMMYFUNCTION("""COMPUTED_VALUE"""),188.9411595) -> 188.94116 | K18: =IFERROR(__xludf.DUMMYFUNCTION("""COMPUTED_VALUE"""),217.569856) -> 217.56986
A19: Carro ABC 100 kg | B19: =IFERROR(__xludf.DUMMYFUNCTION("""COMPUTED_VALUE"""),10.89657324) -> 10.896573 | C19: =IFERROR(__xludf.DUMMYFUNCTION("""COMPUTED_VALUE"""),18.70788719) -> 18.707887 | D19: =IFERROR(__xludf.DUMMYFUNCTION("""COMPUTED_VALUE"""),24.06673279) -> 24.066733 | E19: =IFERROR(__xludf.DUMMYFUNCTION("""COMPUTED_VALUE"""),32.16955294) -> 32.169553 | F19: =IFERROR(__xludf.DUMMYFUNCTION("""COMPUTED_VALUE"""),49.88032112) -> 49.880321 | G19: =IFERROR(__xludf.DUMMYFUNCTION("""COMPUTED_VALUE"""),67.81903447) -> 67.819034 | H19: =IFERROR(__xludf.DUMMYFUNCTION("""COMPUTED_VALUE"""),87.25383461) -> 87.253835 | I19: =IFERROR(__xludf.DUMMYFUNCTION("""COMPUTED_VALUE"""),108.1115746) -> 108.11157 | J19: =IFERROR(__xludf.DUMMYFUNCTION("""COMPUTED_VALUE"""),125.960773) -> 125.96077 | K19: =IFERROR(__xludf.DUMMYFUNCTION("""COMPUTED_VALUE"""),145.0465706) -> 145.04657
A21: Proyecciones · Indexado Dim Técnico!B19:K22: cilindros vendidos vacíos
B22: 2026 | C22: 2027 | D22: 2028 | E22: 2029 | F22: 2030 | G22: 2031 | H22: 2032 | I22: 2033 | J22: 2034 | K22: 2035
A23: Carro ABC 25 kg | B23: =IFERROR(__xludf.DUMMYFUNCTION("IMPORTRANGE(Links!$B$4,""Indexado Dim Técnico!B19:K22"")"),0) -> 0 | C23: =IFERROR(__xludf.DUMMYFUNCTION("""COMPUTED_VALUE"""),0) -> 0 | D23: =IFERROR(__xludf.DUMMYFUNCTION("""COMPUTED_VALUE"""),14.4) -> 14.4 | E23: =IFERROR(__xludf.DUMMYFUNCTION("""COMPUTED_VALUE"""),50.2) -> 50.2 | F23: =IFERROR(__xludf.DUMMYFUNCTION("""COMPUTED_VALUE"""),93) -> 93 | G23: =IFERROR(__xludf.DUMMYFUNCTION("""COMPUTED_VALUE"""),135) -> 135 | H23: =IFERROR(__xludf.DUMMYFUNCTION("""COMPUTED_VALUE"""),191) -> 191 | I23: =IFERROR(__xludf.DUMMYFUNCTION("""COMPUTED_VALUE"""),247) -> 247 | J23: =IFERROR(__xludf.DUMMYFUNCTION("""COMPUTED_VALUE"""),277) -> 277 | K23: =IFERROR(__xludf.DUMMYFUNCTION("""COMPUTED_VALUE"""),322) -> 322
A24: Carro ABC 50 kg | B24: =IFERROR(__xludf.DUMMYFUNCTION("""COMPUTED_VALUE"""),0) -> 0 | C24: =IFERROR(__xludf.DUMMYFUNCTION("""COMPUTED_VALUE"""),0) -> 0 | D24: =IFERROR(__xludf.DUMMYFUNCTION("""COMPUTED_VALUE"""),31.8) -> 31.8 | E24: =IFERROR(__xludf.DUMMYFUNCTION("""COMPUTED_VALUE"""),110.8) -> 110.8 | F24: =IFERROR(__xludf.DUMMYFUNCTION("""COMPUTED_VALUE"""),205.2) -> 205.2 | G24: =IFERROR(__xludf.DUMMYFUNCTION("""COMPUTED_VALUE"""),297.6) -> 297.6 | H24: =IFERROR(__xludf.DUMMYFUNCTION("""COMPUTED_VALUE"""),420.8) -> 420.8 | I24: =IFERROR(__xludf.DUMMYFUNCTION("""COMPUTED_VALUE"""),544) -> 544 | J24: =IFERROR(__xludf.DUMMYFUNCTION("""COMPUTED_VALUE"""),609.6) -> 609.6 | K24: =IFERROR(__xludf.DUMMYFUNCTION("""COMPUTED_VALUE"""),708) -> 708
A25: Carro ABC 70 kg | B25: =IFERROR(__xludf.DUMMYFUNCTION("""COMPUTED_VALUE"""),0) -> 0 | C25: =IFERROR(__xludf.DUMMYFUNCTION("""COMPUTED_VALUE"""),0) -> 0 | D25: =IFERROR(__xludf.DUMMYFUNCTION("""COMPUTED_VALUE"""),7) -> 7 | E25: =IFERROR(__xludf.DUMMYFUNCTION("""COMPUTED_VALUE"""),24.4) -> 24.4 | F25: =IFERROR(__xludf.DUMMYFUNCTION("""COMPUTED_VALUE"""),45.2) -> 45.2 | G25: =IFERROR(__xludf.DUMMYFUNCTION("""COMPUTED_VALUE"""),65.4) -> 65.4 | H25: =IFERROR(__xludf.DUMMYFUNCTION("""COMPUTED_VALUE"""),92.2) -> 92.2 | I25: =IFERROR(__xludf.DUMMYFUNCTION("""COMPUTED_VALUE"""),119) -> 119 | J25: =IFERROR(__xludf.DUMMYFUNCTION("""COMPUTED_VALUE"""),133.4) -> 133.4 | K25: =IFERROR(__xludf.DUMMYFUNCTION("""COMPUTED_VALUE"""),155) -> 155
A26: Carro ABC 100 kg | B26: =IFERROR(__xludf.DUMMYFUNCTION("""COMPUTED_VALUE"""),0) -> 0 | C26: =IFERROR(__xludf.DUMMYFUNCTION("""COMPUTED_VALUE"""),0) -> 0 | D26: =IFERROR(__xludf.DUMMYFUNCTION("""COMPUTED_VALUE"""),4.6) -> 4.6 | E26: =IFERROR(__xludf.DUMMYFUNCTION("""COMPUTED_VALUE"""),16) -> 16 | F26: =IFERROR(__xludf.DUMMYFUNCTION("""COMPUTED_VALUE"""),29.6) -> 29.6 | G26: =IFERROR(__xludf.DUMMYFUNCTION("""COMPUTED_VALUE"""),42.8) -> 42.8 | H26: =IFERROR(__xludf.DUMMYFUNCTION("""COMPUTED_VALUE"""),60.4) -> 60.4 | I26: =IFERROR(__xludf.DUMMYFUNCTION("""COMPUTED_VALUE"""),78) -> 78 | J26: =IFERROR(__xludf.DUMMYFUNCTION("""COMPUTED_VALUE"""),87.6) -> 87.6 | K26: =IFERROR(__xludf.DUMMYFUNCTION("""COMPUTED_VALUE"""),102) -> 102
A28: Dimensionamiento Recargas Planta Industrial · sobrestock_sustitutos!B86:K89: alta de sustitutos ABC (terminado, planta industrial)
B29: 2026 | C29: 2027 | D29: 2028 | E29: 2029 | F29: 2030 | G29: 2031 | H29: 2032 | I29: 2033 | J29: 2034 | K29: 2035
A30: Carro ABC 25 kg | B30: =IFERROR(__xludf.DUMMYFUNCTION("IMPORTRANGE(Links!$B$6,""sobrestock_sustitutos!B86:K89"")"),1) -> 1 | C30: =IFERROR(__xludf.DUMMYFUNCTION("""COMPUTED_VALUE"""),0.08) -> 0.08 | D30: =IFERROR(__xludf.DUMMYFUNCTION("""COMPUTED_VALUE"""),0.08) -> 0.08 | E30: =IFERROR(__xludf.DUMMYFUNCTION("""COMPUTED_VALUE"""),1.08) -> 1.08 | F30: =IFERROR(__xludf.DUMMYFUNCTION("""COMPUTED_VALUE"""),1.16) -> 1.16 | G30: =IFERROR(__xludf.DUMMYFUNCTION("""COMPUTED_VALUE"""),1.24) -> 1.24 | H30: =IFERROR(__xludf.DUMMYFUNCTION("""COMPUTED_VALUE"""),0.32) -> 0.32 | I30: =IFERROR(__xludf.DUMMYFUNCTION("""COMPUTED_VALUE"""),1.32) -> 1.32 | J30: =IFERROR(__xludf.DUMMYFUNCTION("""COMPUTED_VALUE"""),0.4) -> 0.4 | K30: =IFERROR(__xludf.DUMMYFUNCTION("""COMPUTED_VALUE"""),0.4) -> 0.4
A31: Carro ABC 50 kg | B31: =IFERROR(__xludf.DUMMYFUNCTION("""COMPUTED_VALUE"""),1) -> 1 | C31: =IFERROR(__xludf.DUMMYFUNCTION("""COMPUTED_VALUE"""),0.08) -> 0.08 | D31: =IFERROR(__xludf.DUMMYFUNCTION("""COMPUTED_VALUE"""),2.08) -> 2.08 | E31: =IFERROR(__xludf.DUMMYFUNCTION("""COMPUTED_VALUE"""),1.24) -> 1.24 | F31: =IFERROR(__xludf.DUMMYFUNCTION("""COMPUTED_VALUE"""),2.32) -> 2.32 | G31: =IFERROR(__xludf.DUMMYFUNCTION("""COMPUTED_VALUE"""),2.48) -> 2.48 | H31: =IFERROR(__xludf.DUMMYFUNCTION("""COMPUTED_VALUE"""),0.64) -> 0.64 | I31: =IFERROR(__xludf.DUMMYFUNCTION("""COMPUTED_VALUE"""),1.64) -> 1.64 | J31: =IFERROR(__xludf.DUMMYFUNCTION("""COMPUTED_VALUE"""),1.72) -> 1.72 | K31: =IFERROR(__xludf.DUMMYFUNCTION("""COMPUTED_VALUE"""),1.8) -> 1.8
A32: Carro ABC 70 kg | B32: =IFERROR(__xludf.DUMMYFUNCTION("""COMPUTED_VALUE"""),1) -> 1 | C32: =IFERROR(__xludf.DUMMYFUNCTION("""COMPUTED_VALUE"""),0.08) -> 0.08 | D32: =IFERROR(__xludf.DUMMYFUNCTION("""COMPUTED_VALUE"""),0.08) -> 0.08 | E32: =IFERROR(__xludf.DUMMYFUNCTION("""COMPUTED_VALUE"""),0.08) -> 0.08 | F32: =IFERROR(__xludf.DUMMYFUNCTION("""COMPUTED_VALUE"""),1.08) -> 1.08 | G32: =IFERROR(__xludf.DUMMYFUNCTION("""COMPUTED_VALUE"""),0.16) -> 0.16 | H32: =IFERROR(__xludf.DUMMYFUNCTION("""COMPUTED_VALUE"""),0.16) -> 0.16 | I32: =IFERROR(__xludf.DUMMYFUNCTION("""COMPUTED_VALUE"""),0.16) -> 0.16 | J32: =IFERROR(__xludf.DUMMYFUNCTION("""COMPUTED_VALUE"""),1.16) -> 1.16 | K32: =IFERROR(__xludf.DUMMYFUNCTION("""COMPUTED_VALUE"""),0.24) -> 0.24
A33: Carro ABC 100 kg | B33: =IFERROR(__xludf.DUMMYFUNCTION("""COMPUTED_VALUE"""),1) -> 1 | C33: =IFERROR(__xludf.DUMMYFUNCTION("""COMPUTED_VALUE"""),0.08) -> 0.08 | D33: =IFERROR(__xludf.DUMMYFUNCTION("""COMPUTED_VALUE"""),0.08) -> 0.08 | E33: =IFERROR(__xludf.DUMMYFUNCTION("""COMPUTED_VALUE"""),0.08) -> 0.08 | F33: =IFERROR(__xludf.DUMMYFUNCTION("""COMPUTED_VALUE"""),0.08) -> 0.08 | G33: =IFERROR(__xludf.DUMMYFUNCTION("""COMPUTED_VALUE"""),1.08) -> 1.08 | H33: =IFERROR(__xludf.DUMMYFUNCTION("""COMPUTED_VALUE"""),0.16) -> 0.16 | I33: =IFERROR(__xludf.DUMMYFUNCTION("""COMPUTED_VALUE"""),0.16) -> 0.16 | J33: =IFERROR(__xludf.DUMMYFUNCTION("""COMPUTED_VALUE"""),0.16) -> 0.16 | K33: =IFERROR(__xludf.DUMMYFUNCTION("""COMPUTED_VALUE"""),0.16) -> 0.16
A35: Dimensionamiento Recargas Planta Comercial · sobrestock_sustitutos!B86:K89: alta de sustitutos ABC (cilindro vacío, planta comercial)
B36: 2026 | C36: 2027 | D36: 2028 | E36: 2029 | F36: 2030 | G36: 2031 | H36: 2032 | I36: 2033 | J36: 2034 | K36: 2035
A37: Carro ABC 25 kg | B37: =IFERROR(__xludf.DUMMYFUNCTION("IMPORTRANGE(Links!$B$5,""sobrestock_sustitutos!B86:K89"")"),1) -> 1 | C37: =IFERROR(__xludf.DUMMYFUNCTION("""COMPUTED_VALUE"""),0.08) -> 0.08 | D37: =IFERROR(__xludf.DUMMYFUNCTION("""COMPUTED_VALUE"""),1.08) -> 1.08 | E37: =IFERROR(__xludf.DUMMYFUNCTION("""COMPUTED_VALUE"""),2.16) -> 2.16 | F37: =IFERROR(__xludf.DUMMYFUNCTION("""COMPUTED_VALUE"""),1.32) -> 1.32 | G37: =IFERROR(__xludf.DUMMYFUNCTION("""COMPUTED_VALUE"""),1.4) -> 1.4 | H37: =IFERROR(__xludf.DUMMYFUNCTION("""COMPUTED_VALUE"""),1.48) -> 1.48 | I37: =IFERROR(__xludf.DUMMYFUNCTION("""COMPUTED_VALUE"""),1.56) -> 1.56 | J37: =IFERROR(__xludf.DUMMYFUNCTION("""COMPUTED_VALUE"""),0.64) -> 0.64 | K37: =IFERROR(__xludf.DUMMYFUNCTION("""COMPUTED_VALUE"""),1.64) -> 1.64
A38: Carro ABC 50 kg | B38: =IFERROR(__xludf.DUMMYFUNCTION("""COMPUTED_VALUE"""),1) -> 1 | C38: =IFERROR(__xludf.DUMMYFUNCTION("""COMPUTED_VALUE"""),1.08) -> 1.08 | D38: =IFERROR(__xludf.DUMMYFUNCTION("""COMPUTED_VALUE"""),2.16) -> 2.16 | E38: =IFERROR(__xludf.DUMMYFUNCTION("""COMPUTED_VALUE"""),3.32) -> 3.32 | F38: =IFERROR(__xludf.DUMMYFUNCTION("""COMPUTED_VALUE"""),3.56) -> 3.56 | G38: =IFERROR(__xludf.DUMMYFUNCTION("""COMPUTED_VALUE"""),3.8) -> 3.8 | H38: =IFERROR(__xludf.DUMMYFUNCTION("""COMPUTED_VALUE"""),3.04) -> 3.04 | I38: =IFERROR(__xludf.DUMMYFUNCTION("""COMPUTED_VALUE"""),3.2) -> 3.2 | J38: =IFERROR(__xludf.DUMMYFUNCTION("""COMPUTED_VALUE"""),2.36) -> 2.36 | K38: =IFERROR(__xludf.DUMMYFUNCTION("""COMPUTED_VALUE"""),2.44) -> 2.44
A39: Carro ABC 70 kg | B39: =IFERROR(__xludf.DUMMYFUNCTION("""COMPUTED_VALUE"""),1) -> 1 | C39: =IFERROR(__xludf.DUMMYFUNCTION("""COMPUTED_VALUE"""),0.08) -> 0.08 | D39: =IFERROR(__xludf.DUMMYFUNCTION("""COMPUTED_VALUE"""),0.08) -> 0.08 | E39: =IFERROR(__xludf.DUMMYFUNCTION("""COMPUTED_VALUE"""),1.08) -> 1.08 | F39: =IFERROR(__xludf.DUMMYFUNCTION("""COMPUTED_VALUE"""),1.16) -> 1.16 | G39: =IFERROR(__xludf.DUMMYFUNCTION("""COMPUTED_VALUE"""),0.24) -> 0.24 | H39: =IFERROR(__xludf.DUMMYFUNCTION("""COMPUTED_VALUE"""),1.24) -> 1.24 | I39: =IFERROR(__xludf.DUMMYFUNCTION("""COMPUTED_VALUE"""),0.32) -> 0.32 | J39: =IFERROR(__xludf.DUMMYFUNCTION("""COMPUTED_VALUE"""),0.32) -> 0.32 | K39: =IFERROR(__xludf.DUMMYFUNCTION("""COMPUTED_VALUE"""),1.32) -> 1.32
A40: Carro ABC 100 kg | B40: =IFERROR(__xludf.DUMMYFUNCTION("""COMPUTED_VALUE"""),1) -> 1 | C40: =IFERROR(__xludf.DUMMYFUNCTION("""COMPUTED_VALUE"""),0.08) -> 0.08 | D40: =IFERROR(__xludf.DUMMYFUNCTION("""COMPUTED_VALUE"""),0.08) -> 0.08 | E40: =IFERROR(__xludf.DUMMYFUNCTION("""COMPUTED_VALUE"""),0.08) -> 0.08 | F40: =IFERROR(__xludf.DUMMYFUNCTION("""COMPUTED_VALUE"""),1.08) -> 1.08 | G40: =IFERROR(__xludf.DUMMYFUNCTION("""COMPUTED_VALUE"""),0.16) -> 0.16 | H40: =IFERROR(__xludf.DUMMYFUNCTION("""COMPUTED_VALUE"""),1.16) -> 1.16 | I40: =IFERROR(__xludf.DUMMYFUNCTION("""COMPUTED_VALUE"""),0.24) -> 0.24 | J40: =IFERROR(__xludf.DUMMYFUNCTION("""COMPUTED_VALUE"""),0.24) -> 0.24 | K40: =IFERROR(__xludf.DUMMYFUNCTION("""COMPUTED_VALUE"""),0.24) -> 0.24

Sheet datos_base
A1: Carros terminados | B1: 2026 | C1: 2027 | D1: 2028 | E1: 2029 | F1: 2030 | G1: 2031 | H1: 2032 | I1: 2033 | J1: 2034 | K1: 2035
A2: Carro ABC 25 kg | B2: =Links!B16 -> 34.051791 | C2: =Links!C16 -> 58.462147 | D2: =Links!D16 -> 75.20854 | E2: =Links!E16 -> 100.52985 | F2: =Links!F16 -> 155.876 | G2: =Links!G16 -> 211.93448 | H2: =Links!H16 -> 272.66823 | I2: =Links!I16 -> 337.84867 | ... K2: =Links!K16 -> 453.27053
A3: Carro ABC 50 kg | B3: =Links!B17 -> 74.913941 | C3: =Links!C17 -> 128.61672 | D3: =Links!D17 -> 165.45879 | E3: =Links!E17 -> 221.16568 | F3: =Links!F17 -> 342.92721 | G3: =Links!G17 -> 466.25586 | H3: =Links!H17 -> 599.87011 | I3: =Links!I17 -> 743.26708 | ... K3: =Links!K17 -> 997.19517
A4: Carro ABC 70 kg | B4: =Links!B18 -> 16.34486 | C4: =Links!C18 -> 28.061831 | D4: =Links!D18 -> 36.100099 | E4: =Links!E18 -> 48.254329 | F4: =Links!F18 -> 74.820482 | G4: =Links!G18 -> 101.72855 | H4: =Links!H18 -> 130.88075 | I4: =Links!I18 -> 162.16736 | ... K4: =Links!K18 -> 217.56986
A5: Carro ABC 100 kg | B5: =Links!B19 -> 10.896573 | C5: =Links!C19 -> 18.707887 | D5: =Links!D19 -> 24.066733 | E5: =Links!E19 -> 32.169553 | F5: =Links!F19 -> 49.880321 | G5: =Links!G19 -> 67.819034 | H5: =Links!H19 -> 87.253835 | I5: =Links!I19 -> 108.11157 | ... K5: =Links!K19 -> 145.04657
A6: Total terminados | B6: =SUM(B2:B5) -> 136.20717 | C6: =SUM(C2:C5) -> 233.84859 | D6: =SUM(D2:D5) -> 300.83416 | E6: =SUM(E2:E5) -> 402.11941 | F6: =SUM(F2:F5) -> 623.50401 | G6: =SUM(G2:G5) -> 847.73793 | H6: =SUM(H2:H5) -> 1090.6729 | I6: =SUM(I2:I5) -> 1351.3947 | ... K6: =SUM(K2:K5) -> 1813.0821
A8: Cilindros vendidos vacíos | B8: 2026 | C8: 2027 | D8: 2028 | E8: 2029 | F8: 2030 | G8: 2031 | H8: 2032 | I8: 2033 | J8: 2034 | K8: 2035
A9: Cilindros ABC 25 kg | B9: =Links!B23 -> 0 | C9: =Links!C23 -> 0 | D9: =Links!D23 -> 14.4 | E9: =Links!E23 -> 50.2 | F9: =Links!F23 -> 93 | G9: =Links!G23 -> 135 | H9: =Links!H23 -> 191 | I9: =Links!I23 -> 247 | ... K9: =Links!K23 -> 322
A10: Cilindros ABC 50 kg | B10: =Links!B24 -> 0 | C10: =Links!C24 -> 0 | D10: =Links!D24 -> 31.8 | E10: =Links!E24 -> 110.8 | F10: =Links!F24 -> 205.2 | G10: =Links!G24 -> 297.6 | H10: =Links!H24 -> 420.8 | I10: =Links!I24 -> 544 | ... K10: =Links!K24 -> 708
A11: Cilindros ABC 70 kg | B11: =Links!B25 -> 0 | C11: =Links!C25 -> 0 | D11: =Links!D25 -> 7 | E11: =Links!E25 -> 24.4 | F11: =Links!F25 -> 45.2 | G11: =Links!G25 -> 65.4 | H11: =Links!H25 -> 92.2 | I11: =Links!I25 -> 119 | ... K11: =Links!K25 -> 155
A12: Cilindros ABC 100 kg | B12: =Links!B26 -> 0 | C12: =Links!C26 -> 0 | D12: =Links!D26 -> 4.6 | E12: =Links!E26 -> 16 | F12: =Links!F26 -> 29.6 | G12: =Links!G26 -> 42.8 | H12: =Links!H26 -> 60.4 | I12: =Links!I26 -> 78 | ... K12: =Links!K26 -> 102
A13: Total cilindros | B13: =SUM(B9:B12) -> 0 | C13: =SUM(C9:C12) -> 0 | D13: =SUM(D9:D12) -> 57.8 | E13: =SUM(E9:E12) -> 201.4 | F13: =SUM(F9:F12) -> 373 | G13: =SUM(G9:G12) -> 540.8 | H13: =SUM(H9:H12) -> 764.4 | I13: =SUM(I9:I12) -> 988 | ... K13: =SUM(K9:K12) -> 1287
A15: Total recipientes a fabricar (con sustitutos) | B15: =B6+B13+B39+B44 -> 144.20717 | C15: =C6+C13+C39+C44 -> 235.48859 | D15: =D6+D13+D39+D44 -> 364.35416 | E15: =E6+E13+E39+E44 -> 612.63941 | F15: =F6+F13+F39+F44 -> 1008.264 | G15: =G6+G13+G39+G44 -> 1399.0979 | H15: =H6+H13+H39+H44 -> 1863.2729 | I15: =I6+I13+I39+I44 -> 2347.9947 | ... K15: =K6+K13+K39+K44 -> 3108.3221
A17: Total por modelo (terminados + cilindros) | B17: 2026 | C17: 2027 | D17: 2028 | E17: 2029 | F17: 2030 | G17: 2031 | H17: 2032 | I17: 2033 | J17: 2034 | K17: 2035
A18: Recipientes de 25 kg | B18: =B2+B9 -> 34.051791 | C18: =C2+C9 -> 58.462147 | D18: =D2+D9 -> 89.60854 | E18: =E2+E9 -> 150.72985 | F18: =F2+F9 -> 248.876 | G18: =G2+G9 -> 346.93448 | H18: =H2+H9 -> 463.66823 | I18: =I2+I9 -> 584.84867 | ... K18: =K2+K9 -> 775.27053
A19: Recipientes de 50 kg | B19: =B3+B10 -> 74.913941 | C19: =C3+C10 -> 128.61672 | D19: =D3+D10 -> 197.25879 | E19: =E3+E10 -> 331.96568 | F19: =F3+F10 -> 548.12721 | G19: =G3+G10 -> 763.85586 | H19: =H3+H10 -> 1020.6701 | I19: =I3+I10 -> 1287.2671 | ... K19: =K3+K10 -> 1705.1952
A20: Recipientes de 70 kg | B20: =B4+B11 -> 16.34486 | C20: =C4+C11 -> 28.061831 | D20: =D4+D11 -> 43.100099 | E20: =E4+E11 -> 72.654329 | F20: =F4+F11 -> 120.02048 | G20: =G4+G11 -> 167.12855 | H20: =H4+H11 -> 223.08075 | I20: =I4+I11 -> 281.16736 | ... K20: =K4+K11 -> 372.56986
A21: Recipientes de 100 kg | B21: =B5+B12 -> 10.896573 | C21: =C5+C12 -> 18.707887 | D21: =D5+D12 -> 28.666733 | E21: =E5+E12 -> 48.169553 | F21: =F5+F12 -> 79.480321 | G21: =G5+G12 -> 110.61903 | H21: =H5+H12 -> 147.65383 | I21: =I5+I12 -> 186.11157 | ... K21: =K5+K12 -> 247.04657
A22: Total | B22: =SUM(B18:B21) -> 136.20717 | C22: =SUM(C18:C21) -> 233.84859 | D22: =SUM(D18:D21) -> 358.63416 | E22: =SUM(E18:E21) -> 603.51941 | F22: =SUM(F18:F21) -> 996.50401 | G22: =SUM(G18:G21) -> 1388.5379 | H22: =SUM(H18:H21) -> 1855.0729 | I22: =SUM(I18:I21) -> 2339.3947 | ... K22: =SUM(K18:K21) -> 3100.0821
A24: Fuente: Proyecciones, Indexado Dim Técnico (hoja Links): terminados filas 7 a 10 y cilindros filas 19 a 22.
A26: Datos de cada modelo (Word, Tabla 0) | B26: Ø (mm) | C26: Chapa (mm) | D26: Altura cuerpo (mm) | E26: Cuerpo vacío (kg) | F26: Lleno de agua (kg) | G26: Volumen interior (l) | H26: Carro vacío c/ruedas (kg) | I26: Carro terminado (kg) | J26: Manga mínima (m) | K26: Casquete
A27: Carro 25 kg | B27: 276.5 | C27: 3.2 | D27: 490 | E27: 10.6 | F27: 43 | G27: 35 | H27: 25 | I27: 53 | J27: 5 | K27: 10" (MP-15)
A28: Carro 50 kg | B28: 320 | C28: 3.2 | D28: 640 | E28: 16 | F28: 68 | G28: 60 | H28: 36 | I28: 90 | J28: 5 | K28: 12" (MP-16)
A29: Carro 70 kg | B29: 390 | C29: 4.75 | D29: 680 | E29: 30.7 | F29: 127 | G29: 93 | H29: 61 | I29: 136 | J29: 5 | K29: 15" (MP-17)
A30: Carro 100 kg | B30: 390 | C30: 4.75 | D30: 900 | E30: 40.7 | F30: 157 | G30: 118 | H30: 71 | I30: 179 | J30: 12 | K30: 15" (MP-17)
A32: Chapa LAC 1500 × 3000 mm: 3,2 mm (25 y 50 kg) y 4,75 mm (70 y 100 kg). Cupla M30 × 1,5 (25 y 50 kg) y 2½" BSP (70 y 100 kg). Prueba hidráulica a 4 MPa; presión de servicio 14 bar (N₂).
A34: Sustitutos ABC para las plantas de recargas | B34: 2026 | C34: 2027 | D34: 2028 | E34: 2029 | F34: 2030 | G34: 2031 | H34: 2032 | I34: 2033 | J34: 2034 | K34: 2035
A35: Carro ABC 25 kg — sustituto (terminado, planta industrial) | B35: =IFERROR(Links!B30,0) -> 1 | C35: =IFERROR(Links!C30,0) -> 0.08 | D35: =IFERROR(Links!D30,0) -> 0.08 | E35: =IFERROR(Links!E30,0) -> 1.08 | F35: =IFERROR(Links!F30,0) -> 1.16 | G35: =IFERROR(Links!G30,0) -> 1.24 | H35: =IFERROR(Links!H30,0) -> 0.32 | I35: =IFERROR(Links!I30,0) -> 1.32 | ... K35: =IFERROR(Links!K30,0) -> 0.4
A36: Carro ABC 50 kg — sustituto (terminado, planta industrial) | B36: =IFERROR(Links!B31,0) -> 1 | C36: =IFERROR(Links!C31,0) -> 0.08 | D36: =IFERROR(Links!D31,0) -> 2.08 | E36: =IFERROR(Links!E31,0) -> 1.24 | F36: =IFERROR(Links!F31,0) -> 2.32 | G36: =IFERROR(Links!G31,0) -> 2.48 | H36: =IFERROR(Links!H31,0) -> 0.64 | I36: =IFERROR(Links!I31,0) -> 1.64 | ... K36: =IFERROR(Links!K31,0) -> 1.8
A37: Carro ABC 70 kg — sustituto (terminado, planta industrial) | B37: =IFERROR(Links!B32,0) -> 1 | C37: =IFERROR(Links!C32,0) -> 0.08 | D37: =IFERROR(Links!D32,0) -> 0.08 | E37: =IFERROR(Links!E32,0) -> 0.08 | F37: =IFERROR(Links!F32,0) -> 1.08 | G37: =IFERROR(Links!G32,0) -> 0.16 | H37: =IFERROR(Links!H32,0) -> 0.16 | I37: =IFERROR(Links!I32,0) -> 0.16 | ... K37: =IFERROR(Links!K32,0) -> 0.24
A38: Carro ABC 100 kg — sustituto (terminado, planta industrial) | B38: =IFERROR(Links!B33,0) -> 1 | C38: =IFERROR(Links!C33,0) -> 0.08 | D38: =IFERROR(Links!D33,0) -> 0.08 | E38: =IFERROR(Links!E33,0) -> 0.08 | F38: =IFERROR(Links!F33,0) -> 0.08 | G38: =IFERROR(Links!G33,0) -> 1.08 | H38: =IFERROR(Links!H33,0) -> 0.16 | I38: =IFERROR(Links!I33,0) -> 0.16 | ... K38: =IFERROR(Links!K33,0) -> 0.16
A39: Total sustitutos terminados | B39: =SUM(B35:B38) -> 4 | C39: =SUM(C35:C38) -> 0.32 | D39: =SUM(D35:D38) -> 2.32 | E39: =SUM(E35:E38) -> 2.48 | F39: =SUM(F35:F38) -> 4.64 | G39: =SUM(G35:G38) -> 4.96 | H39: =SUM(H35:H38) -> 1.28 | I39: =SUM(I35:I38) -> 3.28 | ... K39: =SUM(K35:K38) -> 2.6
A40: Carro ABC 25 kg — sustituto (cilindro vacío, planta comercial) | B40: =IFERROR(Links!B37,0) -> 1 | C40: =IFERROR(Links!C37,0) -> 0.08 | D40: =IFERROR(Links!D37,0) -> 1.08 | E40: =IFERROR(Links!E37,0) -> 2.16 | F40: =IFERROR(Links!F37,0) -> 1.32 | G40: =IFERROR(Links!G37,0) -> 1.4 | H40: =IFERROR(Links!H37,0) -> 1.48 | I40: =IFERROR(Links!I37,0) -> 1.56 | ... K40: =IFERROR(Links!K37,0) -> 1.64
A41: Carro ABC 50 kg — sustituto (cilindro vacío, planta comercial) | B41: =IFERROR(Links!B38,0) -> 1 | C41: =IFERROR(Links!C38,0) -> 1.08 | D41: =IFERROR(Links!D38,0) -> 2.16 | E41: =IFERROR(Links!E38,0) -> 3.32 | F41: =IFERROR(Links!F38,0) -> 3.56 | G41: =IFERROR(Links!G38,0) -> 3.8 | H41: =IFERROR(Links!H38,0) -> 3.04 | I41: =IFERROR(Links!I38,0) -> 3.2 | ... K41: =IFERROR(Links!K38,0) -> 2.44
A42: Carro ABC 70 kg — sustituto (cilindro vacío, planta comercial) | B42: =IFERROR(Links!B39,0) -> 1 | C42: =IFERROR(Links!C39,0) -> 0.08 | D42: =IFERROR(Links!D39,0) -> 0.08 | E42: =IFERROR(Links!E39,0) -> 1.08 | F42: =IFERROR(Links!F39,0) -> 1.16 | G42: =IFERROR(Links!G39,0) -> 0.24 | H42: =IFERROR(Links!H39,0) -> 1.24 | I42: =IFERROR(Links!I39,0) -> 0.32 | ... K42: =IFERROR(Links!K39,0) -> 1.32
A43: Carro ABC 100 kg — sustituto (cilindro vacío, planta comercial) | B43: =IFERROR(Links!B40,0) -> 1 | C43: =IFERROR(Links!C40,0) -> 0.08 | D43: =IFERROR(Links!D40,0) -> 0.08 | E43: =IFERROR(Links!E40,0) -> 0.08 | F43: =IFERROR(Links!F40,0) -> 1.08 | G43: =IFERROR(Links!G40,0) -> 0.16 | H43: =IFERROR(Links!H40,0) -> 1.16 | I43: =IFERROR(Links!I40,0) -> 0.24 | ... K43: =IFERROR(Links!K40,0) -> 0.24
A44: Total sustitutos cilindros vacíos | B44: =SUM(B40:B43) -> 4 | C44: =SUM(C40:C43) -> 1.32 | D44: =SUM(D40:D43) -> 3.4 | E44: =SUM(E40:E43) -> 6.64 | F44: =SUM(F40:F43) -> 7.12 | G44: =SUM(G40:G43) -> 5.6 | H44: =SUM(H40:H43) -> 6.92 | I44: =SUM(I40:I43) -> 5.32 | ... K44: =SUM(K40:K43) -> 5.64
A45: Sustitutos: alta (paso 4) de cada Dimensionamiento de recargas · Word de recargas § 9

Sheet parametros_carros
A1: Parámetro | B1: Valor | C1: Nota
A2: Días hábiles por mes | B2: 20 | C2: Mismo valor que Manuales y que el Word (20 días por mes)
A3: Horas por día (1 turno) | B3: 8 | C3: Jornada de 8 h
A4: Refrigerio y pausas (min/turno) | B4: 30 | C4: Ajustado para que el turno productivo dé 410 min, como en el Word (ritmo pico = 410 min / 20 carros = 20,5 min por carro)
A5: Horas productivas por turno | B5: =B3-B4/60 -> 7.5 | C5: Horas/día − refrigerio y pausas (= 410 min)
A6: Turnos por día | B6: 1 | C6: Un solo turno (editable; los turnos por puesto se cargan en Resumen Capacidad)
A7: Horas productivas por mes | B7: =B2*B5*B6 -> 150 | C7: Días × horas productivas × turnos
A8: Umbral de aprovechamiento | B8: 0.9 | C8: Límite duro (análisis de riesgos) · Word de recargas § 8
A9: Año de inicio del 2° turno (antes: más máquinas) | B9: 2032 | C9: Todos los turnos entran ese año · Word de recargas § 8
A10: ESTACIONALIDAD (% de la demanda anual por mes; MRP, hoja Links)
A11: Modelo | B11: Ene | C11: Feb | D11: Mar | E11: Abr | F11: May | G11: Jun | H11: Jul | I11: Ago | J11: Sep | K11: Oct | L11: Nov | M11: Dic | N11: Total
A12: 25 kg | B12: =Links!B12 -> 0.085 | C12: =Links!C12 -> 0.075 | D12: =Links!D12 -> 0.09 | E12: =Links!E12 -> 0.09 | F12: =Links!F12 -> 0.09 | G12: =Links!G12 -> 0.08 | H12: =Links!H12 -> 0.09 | I12: =Links!I12 -> 0.09 | ... M12: =Links!M12 -> 0.08 | N12: =SUM(B12:M12) -> 1 | O12: MRP, ESTACIONALIDAD E03 rodantes (25 a 100 kg) (hoja Links)
A13: 50 kg | B13: =Links!B12 -> 0.085 | C13: =Links!C12 -> 0.075 | D13: =Links!D12 -> 0.09 | E13: =Links!E12 -> 0.09 | F13: =Links!F12 -> 0.09 | G13: =Links!G12 -> 0.08 | H13: =Links!H12 -> 0.09 | I13: =Links!I12 -> 0.09 | ... M13: =Links!M12 -> 0.08 | N13: =SUM(B13:M13) -> 1 | O13: MRP, ESTACIONALIDAD E03 rodantes (25 a 100 kg) (hoja Links)
A14: 70 kg | B14: =Links!B12 -> 0.085 | C14: =Links!C12 -> 0.075 | D14: =Links!D12 -> 0.09 | E14: =Links!E12 -> 0.09 | F14: =Links!F12 -> 0.09 | G14: =Links!G12 -> 0.08 | H14: =Links!H12 -> 0.09 | I14: =Links!I12 -> 0.09 | ... M14: =Links!M12 -> 0.08 | N14: =SUM(B14:M14) -> 1 | O14: MRP, ESTACIONALIDAD E03 rodantes (25 a 100 kg) (hoja Links)
A15: 100 kg | B15: =Links!B12 -> 0.085 | C15: =Links!C12 -> 0.075 | D15: =Links!D12 -> 0.09 | E15: =Links!E12 -> 0.09 | F15: =Links!F12 -> 0.09 | G15: =Links!G12 -> 0.08 | H15: =Links!H12 -> 0.09 | I15: =Links!I12 -> 0.09 | ... M15: =Links!M12 -> 0.08 | N15: =SUM(B15:M15) -> 1 | O15: MRP, ESTACIONALIDAD E03 rodantes (25 a 100 kg) (hoja Links)
A17: CAPACIDAD POR PUESTO (tiempos en minutos por recipiente, del Word)
A18: N° | B18: Puesto | C18: Máquina / equipo principal | D18: t 25 kg (min/u) | E18: t 50 kg (min/u) | F18: t 70 kg (min/u) | G18: t 100 kg (min/u) | H18: Alcance | I18: Tiempo ponderado (min/u) | J18: Disponibilidad | K18: Cap. real (u/h) | L18: Cap. real (u/mes) | M18: Control: min/día con el pico del Word | N18: Word: min/día pico | O18: SUPOSICIONES
A19: 1 | B19: Recepción de materia prima | C19: Autoelevador Heli CPCD50 K2 (compartido con manuales) + balanza de plataforma + medidor de espesores Melisam MR017 | D19: =(93+330+110+90+90)/400 -> 1.7825 | E19: =(93+330+110+90+90)/400 -> 1.7825 | F19: =(93+330+110+90+90)/400 -> 1.7825 | G19: =(93+330+110+90+90)/400 -> 1.7825 | H19: Todos | I19: =IF(H19="Todos",(D19*datos_base!$K$18+E19*datos_base!$K$19+F19*datos_base!$K$20+G19*datos_base!$K$21)/datos_base!$K$22,(D19*datos_base!$K$2+E19*datos_base!$K$3+F19*datos_base!$K$4+G19*datos_base!$K$5)/datos_base!$K$6) -> 1.7825 | J19: =H45 -> 0.95188889 | K19: =IF(I19>0,60/I19*J19,0) -> 32.041141 | L19: =K19*$B$7 -> 4806.1711 | M19: =5*D19+11*E19+3*F19+1*G19+F45 -> 57.3 | N19: 60 | O19: Tabla 4 del Word (min/mes en el pico de 400 carros): chapa 93 + casquetes 330 + polvo 110 + caño y barra 90 + otros insumos 90, repartidos por carro. La tabla suma 1.146 min/mes aunque el Word indica 1.199. Lo hace el operario de almacén
A20: 2 | B20: Corte de chapa (guillotina) | C20: Guillotinas Ermaksan CNC HGS 2600-6 (1.er corte) y QC12Y 6 × 2500 (2.º corte), compartidas con manuales + mesa elevadora de tijera 3 t + ventosas | D20: =10.6/9+3.5/9+0.2+0.8 -> 2.5666667 | E20: =8.8/6+5.5/6+0.2+0.8 -> 3.3833333 | F20: =14.5/4+5*2/23+12.1*(2/3)/4+0.2+0.8 -> 7.0764493 | G20: =14.5/4+5*2/23+12.1*(2/3)/4+0.2+0.8 -> 7.0764493 | H20: Todos | I20: =IF(H20="Todos",(D20*datos_base!$K$18+E20*datos_base!$K$19+F20*datos_base!$K$20+G20*datos_base!$K$21)/datos_base!$K$22,(D20*datos_base!$K$2+E20*datos_base!$K$3+F20*datos_base!$K$4+G20*datos_base!$K$5)/datos_base!$K$6) -> 3.9172475 | J20: =H46 -> 0.93777778 | K20: =IF(I20>0,60/I20*J20,0) -> 14.363827 | L20: =K20*$B$7 -> 2154.5741 | M20: =5*D20+11*E20+3*F20+1*G20+F46 -> 106.3558 | N20: 107 | O20: Hoja 25 kg: 10,6 min / 9 cuerpos + tiras de patas 3,5 min / 9. Hoja 50 kg: 8,8 min / 6 + tiras de 40 mm 5,5 min / 6. Hoja mixta 70+100: 14,5 min / 4 + tiras de placas (5 min cada 23 placas, 2 por cuerpo) + tiras de triángulos (12,1 min en 2 de cada 3 hojas mixtas). Todos: pata 0,2 min + piezas de accesorios a largo 0,8 min (4 cortes de 0,2). Las hojas de 4,75 mm las cortan dos personas
A21: 2.1 | B21: Marcado del cuerpo | C21: Marcadora por micropercusión DTMAQ MPE 150130 + mesa con topes + punzón DPS | D21: 1.5 | E21: 1.5 | F21: 1.8 | G21: 1.8 | H21: Todos | I21: =IF(H21="Todos",(D21*datos_base!$K$18+E21*datos_base!$K$19+F21*datos_base!$K$20+G21*datos_base!$K$21)/datos_base!$K$22,(D21*datos_base!$K$2+E21*datos_base!$K$3+F21*datos_base!$K$4+G21*datos_base!$K$5)/datos_base!$K$6) -> 1.5599613 | J21: =H47 -> 0.98777778 | K21: =IF(I21>0,60/I21*J21,0) -> 37.992396 | L21: =K21*$B$7 -> 5698.8594 | M21: =5*D21+11*E21+3*F21+1*G21+F47 -> 36.7 | N21: 37 | O21: Tabla de secuencia del puesto 2.1: 1,5 min por cuerpo de 25 y 50 kg y 1,8 min en 70 y 100 kg (entre dos). Lo hace el operario de corte
A22: 3 | B22: Cilindrado | C22: Roladora hidráulica CNC de 4 rodillos W12 8 × 1500 (Anhui Runbang), exclusiva de carros | D22: 2.6 | E22: 2.8 | F22: =4.5+12/11.5 -> 5.5434783 | G22: =5+12/11.5 -> 6.0434783 | H22: Todos | I22: =IF(H22="Todos",(D22*datos_base!$K$18+E22*datos_base!$K$19+F22*datos_base!$K$20+G22*datos_base!$K$21)/datos_base!$K$22,(D22*datos_base!$K$2+E22*datos_base!$K$3+F22*datos_base!$K$4+G22*datos_base!$K$5)/datos_base!$K$6) -> 3.3381707 | J22: =H48 -> 0.96 | K22: =IF(I22>0,60/I22*J22,0) -> 17.254959 | L22: =K22*$B$7 -> 2588.2439 | M22: =5*D22+11*E22+3*F22+1*G22+F48 -> 84.473913 | N22: 84 | O22: Ciclo por pieza: 2,6 / 2,8 / 4,5 / 5,0 min. En 70 y 100 kg se suma la tanda de tiras de refuerzo (12 min cada 23 placas = 11,5 cuerpos). No se comparte con manuales (rodillos grandes)
A23: 4 | B23: Punteo del cuerpo | C23: Virador de soldadura Serecon ZJ R-410 sobre base fija + MIG/MAG Pampa 300 | D23: 3 | E23: 3.3 | F23: =7.8+35/11.5+1 -> 11.843478 | G23: =8+35/11.5+1 -> 12.043478 | H23: Todos | I23: =IF(H23="Todos",(D23*datos_base!$K$18+E23*datos_base!$K$19+F23*datos_base!$K$20+G23*datos_base!$K$21)/datos_base!$K$22,(D23*datos_base!$K$2+E23*datos_base!$K$3+F23*datos_base!$K$4+G23*datos_base!$K$5)/datos_base!$K$6) -> 4.9485072 | J23: =H49 -> 0.98888889 | K23: =IF(I23>0,60/I23*J23,0) -> 11.990148 | L23: =K23*$B$7 -> 1798.5222 | M23: =5*D23+11*E23+3*F23+1*G23+F49 -> 103.87391 | N23: 104 | O23: 3,0 / 3,3 min; 70 y 100 kg con los dos refuerzos 7,8 / 8,0 min + corte de placas (35 min por tanda de 23 placas = 11,5 cuerpos) + 1 min de ayuda para sacar el cuerpo de la roladora
A24: 5 | B24: Soldadura longitudinal | C24: Soldadora longitudinal automática ZH-1300 (Dragon Welding) + fuente MIG-350IX + chiller SDL-1000 | D24: 3 | E24: 3.3 | F24: 3.9 | G24: 4.6 | H24: Todos | I24: =IF(H24="Todos",(D24*datos_base!$K$18+E24*datos_base!$K$19+F24*datos_base!$K$20+G24*datos_base!$K$21)/datos_base!$K$22,(D24*datos_base!$K$2+E24*datos_base!$K$3+F24*datos_base!$K$4+G24*datos_base!$K$5)/datos_base!$K$6) -> 3.4006816 | J24: =H50 -> 0.98222222 | K24: =IF(I24>0,60/I24*J24,0) -> 17.329859 | L24: =K24*$B$7 -> 2599.4789 | M24: =5*D24+11*E24+3*F24+1*G24+F50 -> 75.6 | N24: 76 | O24: Arco (490-900 mm a 500 mm/min en 3,2 mm y 350 mm/min en 4,75 mm) + 2 min de carga, mordazas, retiro e inspección. El mismo operario hace el punteo
A25: 6 | B25: Soldadura de cupla en la cúpula | C25: Posicionador VEVOR 30 kg sobre mesa Müller + soporte de torcha + MIG/MAG Pampa 300 | D25: 3.2 | E25: 3.2 | F25: 4 | G25: 4 | H25: Todos | I25: =IF(H25="Todos",(D25*datos_base!$K$18+E25*datos_base!$K$19+F25*datos_base!$K$20+G25*datos_base!$K$21)/datos_base!$K$22,(D25*datos_base!$K$2+E25*datos_base!$K$3+F25*datos_base!$K$4+G25*datos_base!$K$5)/datos_base!$K$6) -> 3.3598968 | J25: =H51 -> 0.98 | K25: =IF(I25>0,60/I25*J25,0) -> 17.500538 | L25: =K25*$B$7 -> 2625.0806 | M25: =5*D25+11*E25+3*F25+1*G25+F51 -> 76.2 | N25: 76 | O25: 3,2 min por cúpula con cupla M30 (25 y 50 kg) y 4,0 min con cupla 2½" (70 y 100 kg). El Word lo asigna al operario de punteo y soldadura longitudinal
A26: 7 | B26: Armado y soldadura circunferencial | C26: Virador de 1.000 kg (USA Tools) con soporte fijo de torcha X-Y-Z + MIG/MAG Pampa 300 | D26: 14.6 | E26: 15.2 | F26: 19.4 | G26: 19.4 | H26: Todos | I26: =IF(H26="Todos",(D26*datos_base!$K$18+E26*datos_base!$K$19+F26*datos_base!$K$20+G26*datos_base!$K$21)/datos_base!$K$22,(D26*datos_base!$K$2+E26*datos_base!$K$3+F26*datos_base!$K$4+G26*datos_base!$K$5)/datos_base!$K$6) -> 15.88941 | J26: =H52 -> 0.98 | K26: =IF(I26>0,60/I26*J26,0) -> 3.700578 | L26: =K26*$B$7 -> 555.0867 | M26: =5*D26+11*E26+3*F26+1*G26+F52 -> 326.8 | N26: 327 | O26: Encastre, punteo, soldadura automática (cilindro girando, torcha fija) e inspección de fondo y cúpula: 14,6 / 15,2 / 19,4 min. Puesto más cargado de la línea: operario propio
A27: 8 | B27: Soldadura de accesorios | C27: Virador de 1.000 kg + MIG/MAG Pampa 300 (soldadura manual) | D27: 15.7 | E27: 15.9 | F27: 17.6 | G27: 17.6 | H27: Todos | I27: =IF(H27="Todos",(D27*datos_base!$K$18+E27*datos_base!$K$19+F27*datos_base!$K$20+G27*datos_base!$K$21)/datos_base!$K$22,(D27*datos_base!$K$2+E27*datos_base!$K$3+F27*datos_base!$K$4+G27*datos_base!$K$5)/datos_base!$K$6) -> 16.189765 | J27: =H53 -> 0.98 | K27: =IF(I27>0,60/I27*J27,0) -> 3.6319244 | L27: =K27*$B$7 -> 544.78865 | M27: =5*D27+11*E27+3*F27+1*G27+F53 -> 332.8 | N27: 333 | O27: Marcar posiciones, puntear y soldar manija, flejes, pata, triángulos y caño del eje: 15,7 / 15,9 / 17,6 min por carro. Operario propio
A28: 8.1 | B28: Fabricación de accesorios | C28: Sensitiva Bosch GCO 220 + prensa hidráulica 20 t + dobladora de caños 12 t + taladro de banco | D28: 11 | E28: 11 | F28: 11 | G28: 11 | H28: Todos | I28: =IF(H28="Todos",(D28*datos_base!$K$18+E28*datos_base!$K$19+F28*datos_base!$K$20+G28*datos_base!$K$21)/datos_base!$K$22,(D28*datos_base!$K$2+E28*datos_base!$K$3+F28*datos_base!$K$4+G28*datos_base!$K$5)/datos_base!$K$6) -> 11 | J28: =H54 -> 0.96666667 | K28: =IF(I28>0,60/I28*J28,0) -> 5.2727273 | L28: =K28*$B$7 -> 790.90909 | M28: =5*D28+11*E28+3*F28+1*G28+F54 -> 235 | N28: 235 | O28: 11,0 min por juego (manija, caño del eje, eje, 2 triángulos, 2 flejes y pata). El Word lo asigna al operario de cilindrado
A29: 9 | B29: Prueba hidráulica | C29: Máquina de prueba Yukon M-000200 + 2 bandejas de prueba + tanque y bomba | D29: =7.9+4*0.12 -> 8.38 | E29: =8.7+4*0.12 -> 9.18 | F29: =8.7+4*0.12 -> 9.18 | G29: =8.7+4*0.12 -> 9.18 | H29: Todos | I29: =IF(H29="Todos",(D29*datos_base!$K$18+E29*datos_base!$K$19+F29*datos_base!$K$20+G29*datos_base!$K$21)/datos_base!$K$22,(D29*datos_base!$K$2+E29*datos_base!$K$3+F29*datos_base!$K$4+G29*datos_base!$K$5)/datos_base!$K$6) -> 8.9799355 | J29: =H55 -> 0.97777778 | K29: =IF(I29>0,60/I29*J29,0) -> 6.5330833 | L29: =K29*$B$7 -> 979.9625 | M29: =5*D29+11*E29+3*F29+1*G29+F55 -> 189.6 | N29: 190 | O29: Estanquidad al 100 %: 7,9 min (25 kg) y 8,7 min (resto, con la ayuda para dar vuelta el cilindro y el juego provisorio) + expansión 4 min en la muestra (≈12 % del lote semanal)
A30: 10 | B30: Secado | C30: Secadora eléctrica Melisam MR011 (1 boca) | D30: 8 | E30: 10 | F30: 12 | G30: 14 | H30: Todos | I30: =IF(H30="Todos",(D30*datos_base!$K$18+E30*datos_base!$K$19+F30*datos_base!$K$20+G30*datos_base!$K$21)/datos_base!$K$22,(D30*datos_base!$K$2+E30*datos_base!$K$3+F30*datos_base!$K$4+G30*datos_base!$K$5)/datos_base!$K$6) -> 10.058961 | J30: =H56 -> 1 | K30: =IF(I30>0,60/I30*J30,0) -> 5.9648306 | L30: =K30*$B$7 -> 894.72459 | M30: =5*D30+11*E30+3*F30+1*G30+F56 -> 200 | N30: 200 | O30: Tiempo de máquina por modelo. El operario (el de prueba hidráulica) solo ocupa 2 min por carro: el secado corre solo
A31: 11 | B31: Pulmón de despacho y carga a pintura | C31: Autoelevador Heli CPCD50 + tarimas de carga con topes (2 operarios) | D31: 1.45 | E31: 1.45 | F31: 2.2 | G31: 2.2 | H31: Todos | I31: =IF(H31="Todos",(D31*datos_base!$K$18+E31*datos_base!$K$19+F31*datos_base!$K$20+G31*datos_base!$K$21)/datos_base!$K$22,(D31*datos_base!$K$2+E31*datos_base!$K$3+F31*datos_base!$K$4+G31*datos_base!$K$5)/datos_base!$K$6) -> 1.5999032 | J31: =H57 -> 0.99111111 | K31: =IF(I31>0,60/I31*J31,0) -> 37.168915 | L31: =K31*$B$7 -> 5575.3372 | M31: =5*D31+11*E31+3*F31+1*G31+F57 -> 36 | N31: 36 | O31: Por cada uno de los 2 operarios (almacén y montaje): 5,8 min por tarima de 4 carros chicos y 4,4 min por tarima de 2 grandes
A32: 12 | B32: Recepción de pintados y cambio de juego | C32: Criques carrito 2 t + zorra de retorno (2 operarios). Pintura en polvo tercerizada | D32: =1.45+3/2 -> 2.95 | E32: =1.45+3/2 -> 2.95 | F32: =2.2+3.3/2 -> 3.85 | G32: =2.2+3.3/2 -> 3.85 | H32: Todos | I32: =IF(H32="Todos",(D32*datos_base!$K$18+E32*datos_base!$K$19+F32*datos_base!$K$20+G32*datos_base!$K$21)/datos_base!$K$22,(D32*datos_base!$K$2+E32*datos_base!$K$3+F32*datos_base!$K$4+G32*datos_base!$K$5)/datos_base!$K$6) -> 3.1298839 | J32: =H58 -> 0.99111111 | K32: =IF(I32>0,60/I32*J32,0) -> 18.99964 | L32: =K32*$B$7 -> 2849.946 | M32: =5*D32+11*E32+3*F32+1*G32+F58 -> 66.6 | N32: =(180+153)/5 -> 66.6 | O32: Por operario: descarga igual que la carga (1,45 / 2,2 min) + la mitad del cambio de juego provisorio (3,0 / 3,3 min por carro). La pintura es tercerizada (3 días hábiles ida y vuelta; USD 13,5 / 20,3 / 27,5 / 32 por carro)
A33: 13 B | B33: Carga de polvo y presurización | C33: Cargadora de polvo por vacío Yukon M-000121 + balanza 300 kg + batería de N₂ + llave dinamométrica | D33: 8.3 | E33: 11.3 | F33: 13.8 | G33: 17.3 | H33: Terminados | I33: =IF(H33="Todos",(D33*datos_base!$K$18+E33*datos_base!$K$19+F33*datos_base!$K$20+G33*datos_base!$K$21)/datos_base!$K$22,(D33*datos_base!$K$2+E33*datos_base!$K$3+F33*datos_base!$K$4+G33*datos_base!$K$5)/datos_base!$K$6) -> 11.33 | J33: =H59 -> 0.89333333 | K33: =IF(I33>0,60/I33*J33,0) -> 4.7308032 | L33: =K33*$B$7 -> 709.62048 | M33: =5*D33+11*E33+3*F33+1*G33+F59 -> 272.5 | N33: 273 | O33: Estación B: balanza, carga de polvo (≈5 s por kg), válvula, presurización a 14 bar y detector de fugas. Operario de carga
A34: 13 A-C / 15 | B34: Montaje, manga, precinto y etiquetado | C34: Puesto manual (estaciones A y C) + mesa de etiquetado | D34: =3.6+2.5 -> 6.1 | E34: =3.6+2.5 -> 6.1 | F34: =4.3+2.5 -> 6.8 | G34: =5.3+2.5 -> 7.8 | H34: Terminados | I34: =IF(H34="Todos",(D34*datos_base!$K$18+E34*datos_base!$K$19+F34*datos_base!$K$20+G34*datos_base!$K$21)/datos_base!$K$22,(D34*datos_base!$K$2+E34*datos_base!$K$3+F34*datos_base!$K$4+G34*datos_base!$K$5)/datos_base!$K$6) -> 6.32 | J34: =H60 -> 0.95333333 | K34: =IF(I34>0,60/I34*J34,0) -> 9.0506329 | L34: =K34*$B$7 -> 1357.5949 | M34: =5*D34+11*E34+3*F34+1*G34+F60 -> 146.8 | N34: 147 | O34: Estaciones A y C: 3,6 / 3,6 / 4,3 / 5,3 min + placa de características y traslado al depósito (puesto 15) 2,5 min. Operario de montaje
A35: 14-17 | B35: Calidad: pérdidas, inspección final, liberación y ensayos de lote | C35: Sala de pérdidas 5 × 5 m (21 °C) + recinto de descarga + Yukon M-000200 + balanza | D35: =1+8*3/100+3*0.25+1.5+0.3+4*0.25 -> 4.79 | E35: =1+8*3/100+3*0.25+1.5+0.3+4*0.25 -> 4.79 | F35: =1+8*3/100+3*0.25+1.5+0.3+4*0.25 -> 4.79 | G35: =1+8*3/100+3*0.25+1.5+0.3+4*0.25 -> 4.79 | H35: Terminados | I35: =IF(H35="Todos",(D35*datos_base!$K$18+E35*datos_base!$K$19+F35*datos_base!$K$20+G35*datos_base!$K$21)/datos_base!$K$22,(D35*datos_base!$K$2+E35*datos_base!$K$3+F35*datos_base!$K$4+G35*datos_base!$K$5)/datos_base!$K$6) -> 4.79 | J35: =H61 -> 0.62977778 | K35: =IF(I35>0,60/I35*J35,0) -> 7.8886569 | L35: =K35*$B$7 -> 1183.2985 | M35: =5*D35+11*E35+3*F35+1*G35+F61 -> 262.4 | N35: 262 | O35: Técnico de calidad, por carro: recepción de pintados 1 min + espesor 0,24; pérdidas 3 min × 25 % de muestra; inspección final 1,5; liberación 0,3; medidas 4 min × 25 %
A36: 16 | B36: Depósito de producto terminado y despacho | C36: Autoelevador + tarima de carga (2 operarios) | D36: 1.2 | E36: 1.2 | F36: 2 | G36: 2 | H36: Todos | I36: =IF(H36="Todos",(D36*datos_base!$K$18+E36*datos_base!$K$19+F36*datos_base!$K$20+G36*datos_base!$K$21)/datos_base!$K$22,(D36*datos_base!$K$2+E36*datos_base!$K$3+F36*datos_base!$K$4+G36*datos_base!$K$5)/datos_base!$K$6) -> 1.3598968 | J36: =H62 -> 0.97777778 | K36: =IF(I36>0,60/I36*J36,0) -> 43.140529 | L36: =K36*$B$7 -> 6471.0794 | M36: =5*D36+11*E36+3*F36+1*G36+F62 -> 37.2 | N36: =186/5 -> 37.2 | O36: Por cada uno de los 2 operarios: 1,2 min por carro chico y 2,0 min por carro grande
A38: Alcance: "Todos" = carros terminados + cilindros vendidos vacíos; "Terminados" = solo los que se cargan como matafuego (puestos 13 a 17, salvo el despacho).
A39: Tiempo ponderado = promedio de los 4 tiempos con la mezcla de modelos de 2035 (datos_base). Cap. real (u/h) = 60 / tiempo ponderado × disponibilidad. Cap. real (u/mes) = cap. real × horas productivas del mes.
A40: Control: carga en min/día con la mezcla del pico del Word (5 de 25 kg, 11 de 50 kg, 3 de 70 kg y 1 de 100 kg = 20 carros/día, más los tiempos fijos). Tiene que dar parecido a la columna del Word.
A41: Ocupación (Demanda por puesto y Resumen Capacidad) = (carga del mes pico + pérdida por cambios y tiempos fijos) / horas productivas del mes: es comparable con el '% del turno' del Word. En Resumen se divide por máquinas × turnos.
A42: Los puestos 11, 12 y 16 los hacen 2 operarios a la vez (almacén y montaje): el tiempo es el de cada uno. La guillotina y el autoelevador se comparten con la línea de manuales: su carga real es la suma de las dos planillas. Corte: tiempos del W-CAR (una sola guillotina); con G1 y G2 en serie falta que el grupo los separe por máquina.
...

Sheet Plan mensual
A1: 2026 | B1: Producto | C1: Tipo | D1: Ene | E1: Feb | F1: Mar | G1: Abr | H1: May | I1: Jun | J1: Jul | K1: Ago | L1: Sep | M1: Oct | N1: Nov | O1: Dic | P1: Total anual
A2: 2026 | B2: Carro ABC 25 kg | C2: Terminado | D2: =(datos_base!$B$2+datos_base!$B$35)*parametros_carros!B$12 -> 2.9794023 | E2: =(datos_base!$B$2+datos_base!$B$35)*parametros_carros!C$12 -> 2.6288844 | F2: =(datos_base!$B$2+datos_base!$B$35)*parametros_carros!D$12 -> 3.1546612 | G2: =(datos_base!$B$2+datos_base!$B$35)*parametros_carros!E$12 -> 3.1546612 | H2: =(datos_base!$B$2+datos_base!$B$35)*parametros_carros!F$12 -> 3.1546612 | I2: =(datos_base!$B$2+datos_base!$B$35)*parametros_carros!G$12 -> 2.8041433 | J2: =(datos_base!$B$2+datos_base!$B$35)*parametros_carros!H$12 -> 3.1546612 | K2: =(datos_base!$B$2+datos_base!$B$35)*parametros_carros!I$12 -> 3.1546612 | ... O2: =(datos_base!$B$2+datos_base!$B$35)*parametros_carros!M$12 -> 2.8041433 | P2: =SUM(D2:O2) -> 35.051791
A3: 2026 | B3: Carro ABC 50 kg | C3: Terminado | D3: =(datos_base!$B$3+datos_base!$B$36)*parametros_carros!B$13 -> 6.452685 | E3: =(datos_base!$B$3+datos_base!$B$36)*parametros_carros!C$13 -> 5.6935456 | F3: =(datos_base!$B$3+datos_base!$B$36)*parametros_carros!D$13 -> 6.8322547 | G3: =(datos_base!$B$3+datos_base!$B$36)*parametros_carros!E$13 -> 6.8322547 | H3: =(datos_base!$B$3+datos_base!$B$36)*parametros_carros!F$13 -> 6.8322547 | I3: =(datos_base!$B$3+datos_base!$B$36)*parametros_carros!G$13 -> 6.0731153 | J3: =(datos_base!$B$3+datos_base!$B$36)*parametros_carros!H$13 -> 6.8322547 | K3: =(datos_base!$B$3+datos_base!$B$36)*parametros_carros!I$13 -> 6.8322547 | ... O3: =(datos_base!$B$3+datos_base!$B$36)*parametros_carros!M$13 -> 6.0731153 | P3: =SUM(D3:O3) -> 75.913941
A4: 2026 | B4: Carro ABC 70 kg | C4: Terminado | D4: =(datos_base!$B$4+datos_base!$B$37)*parametros_carros!B$14 -> 1.4743131 | E4: =(datos_base!$B$4+datos_base!$B$37)*parametros_carros!C$14 -> 1.3008645 | F4: =(datos_base!$B$4+datos_base!$B$37)*parametros_carros!D$14 -> 1.5610374 | G4: =(datos_base!$B$4+datos_base!$B$37)*parametros_carros!E$14 -> 1.5610374 | H4: =(datos_base!$B$4+datos_base!$B$37)*parametros_carros!F$14 -> 1.5610374 | I4: =(datos_base!$B$4+datos_base!$B$37)*parametros_carros!G$14 -> 1.3875888 | J4: =(datos_base!$B$4+datos_base!$B$37)*parametros_carros!H$14 -> 1.5610374 | K4: =(datos_base!$B$4+datos_base!$B$37)*parametros_carros!I$14 -> 1.5610374 | ... O4: =(datos_base!$B$4+datos_base!$B$37)*parametros_carros!M$14 -> 1.3875888 | P4: =SUM(D4:O4) -> 17.34486
A5: 2026 | B5: Carro ABC 100 kg | C5: Terminado | D5: =(datos_base!$B$5+datos_base!$B$38)*parametros_carros!B$15 -> 1.0112087 | E5: =(datos_base!$B$5+datos_base!$B$38)*parametros_carros!C$15 -> 0.89224299 | F5: =(datos_base!$B$5+datos_base!$B$38)*parametros_carros!D$15 -> 1.0706916 | G5: =(datos_base!$B$5+datos_base!$B$38)*parametros_carros!E$15 -> 1.0706916 | H5: =(datos_base!$B$5+datos_base!$B$38)*parametros_carros!F$15 -> 1.0706916 | I5: =(datos_base!$B$5+datos_base!$B$38)*parametros_carros!G$15 -> 0.95172586 | J5: =(datos_base!$B$5+datos_base!$B$38)*parametros_carros!H$15 -> 1.0706916 | K5: =(datos_base!$B$5+datos_base!$B$38)*parametros_carros!I$15 -> 1.0706916 | ... O5: =(datos_base!$B$5+datos_base!$B$38)*parametros_carros!M$15 -> 0.95172586 | P5: =SUM(D5:O5) -> 11.896573
A6: 2026 | B6: Cilindros ABC 25 kg | C6: Cilindro | D6: =(datos_base!$B$9+datos_base!$B$40)*parametros_carros!B$12 -> 0.085 | E6: =(datos_base!$B$9+datos_base!$B$40)*parametros_carros!C$12 -> 0.075 | F6: =(datos_base!$B$9+datos_base!$B$40)*parametros_carros!D$12 -> 0.09 | G6: =(datos_base!$B$9+datos_base!$B$40)*parametros_carros!E$12 -> 0.09 | H6: =(datos_base!$B$9+datos_base!$B$40)*parametros_carros!F$12 -> 0.09 | I6: =(datos_base!$B$9+datos_base!$B$40)*parametros_carros!G$12 -> 0.08 | J6: =(datos_base!$B$9+datos_base!$B$40)*parametros_carros!H$12 -> 0.09 | K6: =(datos_base!$B$9+datos_base!$B$40)*parametros_carros!I$12 -> 0.09 | ... O6: =(datos_base!$B$9+datos_base!$B$40)*parametros_carros!M$12 -> 0.08 | P6: =SUM(D6:O6) -> 1
A7: 2026 | B7: Cilindros ABC 50 kg | C7: Cilindro | D7: =(datos_base!$B$10+datos_base!$B$41)*parametros_carros!B$13 -> 0.085 | E7: =(datos_base!$B$10+datos_base!$B$41)*parametros_carros!C$13 -> 0.075 | F7: =(datos_base!$B$10+datos_base!$B$41)*parametros_carros!D$13 -> 0.09 | G7: =(datos_base!$B$10+datos_base!$B$41)*parametros_carros!E$13 -> 0.09 | H7: =(datos_base!$B$10+datos_base!$B$41)*parametros_carros!F$13 -> 0.09 | I7: =(datos_base!$B$10+datos_base!$B$41)*parametros_carros!G$13 -> 0.08 | J7: =(datos_base!$B$10+datos_base!$B$41)*parametros_carros!H$13 -> 0.09 | K7: =(datos_base!$B$10+datos_base!$B$41)*parametros_carros!I$13 -> 0.09 | ... O7: =(datos_base!$B$10+datos_base!$B$41)*parametros_carros!M$13 -> 0.08 | P7: =SUM(D7:O7) -> 1
A8: 2026 | B8: Cilindros ABC 70 kg | C8: Cilindro | D8: =(datos_base!$B$11+datos_base!$B$42)*parametros_carros!B$14 -> 0.085 | E8: =(datos_base!$B$11+datos_base!$B$42)*parametros_carros!C$14 -> 0.075 | F8: =(datos_base!$B$11+datos_base!$B$42)*parametros_carros!D$14 -> 0.09 | G8: =(datos_base!$B$11+datos_base!$B$42)*parametros_carros!E$14 -> 0.09 | H8: =(datos_base!$B$11+datos_base!$B$42)*parametros_carros!F$14 -> 0.09 | I8: =(datos_base!$B$11+datos_base!$B$42)*parametros_carros!G$14 -> 0.08 | J8: =(datos_base!$B$11+datos_base!$B$42)*parametros_carros!H$14 -> 0.09 | K8: =(datos_base!$B$11+datos_base!$B$42)*parametros_carros!I$14 -> 0.09 | ... O8: =(datos_base!$B$11+datos_base!$B$42)*parametros_carros!M$14 -> 0.08 | P8: =SUM(D8:O8) -> 1
A9: 2026 | B9: Cilindros ABC 100 kg | C9: Cilindro | D9: =(datos_base!$B$12+datos_base!$B$43)*parametros_carros!B$15 -> 0.085 | E9: =(datos_base!$B$12+datos_base!$B$43)*parametros_carros!C$15 -> 0.075 | F9: =(datos_base!$B$12+datos_base!$B$43)*parametros_carros!D$15 -> 0.09 | G9: =(datos_base!$B$12+datos_base!$B$43)*parametros_carros!E$15 -> 0.09 | H9: =(datos_base!$B$12+datos_base!$B$43)*parametros_carros!F$15 -> 0.09 | I9: =(datos_base!$B$12+datos_base!$B$43)*parametros_carros!G$15 -> 0.08 | J9: =(datos_base!$B$12+datos_base!$B$43)*parametros_carros!H$15 -> 0.09 | K9: =(datos_base!$B$12+datos_base!$B$43)*parametros_carros!I$15 -> 0.09 | ... O9: =(datos_base!$B$12+datos_base!$B$43)*parametros_carros!M$15 -> 0.08 | P9: =SUM(D9:O9) -> 1
B10: Total recipientes | D10: =SUM(D2:D9) -> 12.257609 | E10: =SUM(E2:E9) -> 10.815537 | F10: =SUM(F2:F9) -> 12.978645 | G10: =SUM(G2:G9) -> 12.978645 | H10: =SUM(H2:H9) -> 12.978645 | I10: =SUM(I2:I9) -> 11.536573 | J10: =SUM(J2:J9) -> 12.978645 | K10: =SUM(K2:K9) -> 12.978645 | ... P10: =SUM(P2:P9) -> 144.20717
A12: 2027 | B12: Producto | C12: Tipo | D12: Ene | E12: Feb | F12: Mar | G12: Abr | H12: May | I12: Jun | J12: Jul | K12: Ago | L12: Sep | M12: Oct | N12: Nov | O12: Dic | P12: Total anual
A13: 2027 | B13: Carro ABC 25 kg | C13: Terminado | D13: =(datos_base!$C$2+datos_base!$C$35)*parametros_carros!B$12 -> 4.9760825 | E13: =(datos_base!$C$2+datos_base!$C$35)*parametros_carros!C$12 -> 4.3906611 | F13: =(datos_base!$C$2+datos_base!$C$35)*parametros_carros!D$12 -> 5.2687933 | G13: =(datos_base!$C$2+datos_base!$C$35)*parametros_carros!E$12 -> 5.2687933 | H13: =(datos_base!$C$2+datos_base!$C$35)*parametros_carros!F$12 -> 5.2687933 | I13: =(datos_base!$C$2+datos_base!$C$35)*parametros_carros!G$12 -> 4.6833718 | J13: =(datos_base!$C$2+datos_base!$C$35)*parametros_carros!H$12 -> 5.2687933 | K13: =(datos_base!$C$2+datos_base!$C$35)*parametros_carros!I$12 -> 5.2687933 | ... O13: =(datos_base!$C$2+datos_base!$C$35)*parametros_carros!M$12 -> 4.6833718 | P13: =SUM(D13:O13) -> 58.542147
A14: 2027 | B14: Carro ABC 50 kg | C14: Terminado | D14: =(datos_base!$C$3+datos_base!$C$36)*parametros_carros!B$13 -> 10.939222 | E14: =(datos_base!$C$3+datos_base!$C$36)*parametros_carros!C$13 -> 9.6522543 | F14: =(datos_base!$C$3+datos_base!$C$36)*parametros_carros!D$13 -> 11.582705 | G14: =(datos_base!$C$3+datos_base!$C$36)*parametros_carros!E$13 -> 11.582705 | H14: =(datos_base!$C$3+datos_base!$C$36)*parametros_carros!F$13 -> 11.582705 | I14: =(datos_base!$C$3+datos_base!$C$36)*parametros_carros!G$13 -> 10.295738 | J14: =(datos_base!$C$3+datos_base!$C$36)*parametros_carros!H$13 -> 11.582705 | K14: =(datos_base!$C$3+datos_base!$C$36)*parametros_carros!I$13 -> 11.582705 | ... O14: =(datos_base!$C$3+datos_base!$C$36)*parametros_carros!M$13 -> 10.295738 | P14: =SUM(D14:O14) -> 128.69672
A15: 2027 | B15: Carro ABC 70 kg | C15: Terminado | D15: =(datos_base!$C$4+datos_base!$C$37)*parametros_carros!B$14 -> 2.3920556 | E15: =(datos_base!$C$4+datos_base!$C$37)*parametros_carros!C$14 -> 2.1106373 | F15: =(datos_base!$C$4+datos_base!$C$37)*parametros_carros!D$14 -> 2.5327648 | G15: =(datos_base!$C$4+datos_base!$C$37)*parametros_carros!E$14 -> 2.5327648 | H15: =(datos_base!$C$4+datos_base!$C$37)*parametros_carros!F$14 -> 2.5327648 | I15: =(datos_base!$C$4+datos_base!$C$37)*parametros_carros!G$14 -> 2.2513465 | J15: =(datos_base!$C$4+datos_base!$C$37)*parametros_carros!H$14 -> 2.5327648 | K15: =(datos_base!$C$4+datos_base!$C$37)*parametros_carros!I$14 -> 2.5327648 | ... O15: =(datos_base!$C$4+datos_base!$C$37)*parametros_carros!M$14 -> 2.2513465 | P15: =SUM(D15:O15) -> 28.141831
A16: 2027 | B16: Carro ABC 100 kg | C16: Terminado | D16: =(datos_base!$C$5+datos_base!$C$38)*parametros_carros!B$15 -> 1.5969704 | E16: =(datos_base!$C$5+datos_base!$C$38)*parametros_carros!C$15 -> 1.4090915 | F16: =(datos_base!$C$5+datos_base!$C$38)*parametros_carros!D$15 -> 1.6909098 | G16: =(datos_base!$C$5+datos_base!$C$38)*parametros_carros!E$15 -> 1.6909098 | H16: =(datos_base!$C$5+datos_base!$C$38)*parametros_carros!F$15 -> 1.6909098 | I16: =(datos_base!$C$5+datos_base!$C$38)*parametros_carros!G$15 -> 1.503031 | J16: =(datos_base!$C$5+datos_base!$C$38)*parametros_carros!H$15 -> 1.6909098 | K16: =(datos_base!$C$5+datos_base!$C$38)*parametros_carros!I$15 -> 1.6909098 | ... O16: =(datos_base!$C$5+datos_base!$C$38)*parametros_carros!M$15 -> 1.503031 | P16: =SUM(D16:O16) -> 18.787887
A17: 2027 | B17: Cilindros ABC 25 kg | C17: Cilindro | D17: =(datos_base!$C$9+datos_base!$C$40)*parametros_carros!B$12 -> 0.0068 | E17: =(datos_base!$C$9+datos_base!$C$40)*parametros_carros!C$12 -> 0.006 | F17: =(datos_base!$C$9+datos_base!$C$40)*parametros_carros!D$12 -> 0.0072 | G17: =(datos_base!$C$9+datos_base!$C$40)*parametros_carros!E$12 -> 0.0072 | H17: =(datos_base!$C$9+datos_base!$C$40)*parametros_carros!F$12 -> 0.0072 | I17: =(datos_base!$C$9+datos_base!$C$40)*parametros_carros!G$12 -> 0.0064 | J17: =(datos_base!$C$9+datos_base!$C$40)*parametros_carros!H$12 -> 0.0072 | K17: =(datos_base!$C$9+datos_base!$C$40)*parametros_carros!I$12 -> 0.0072 | ... O17: =(datos_base!$C$9+datos_base!$C$40)*parametros_carros!M$12 -> 0.0064 | P17: =SUM(D17:O17) -> 0.08
A18: 2027 | B18: Cilindros ABC 50 kg | C18: Cilindro | D18: =(datos_base!$C$10+datos_base!$C$41)*parametros_carros!B$13 -> 0.0918 | E18: =(datos_base!$C$10+datos_base!$C$41)*parametros_carros!C$13 -> 0.081 | F18: =(datos_base!$C$10+datos_base!$C$41)*parametros_carros!D$13 -> 0.0972 | G18: =(datos_base!$C$10+datos_base!$C$41)*parametros_carros!E$13 -> 0.0972 | H18: =(datos_base!$C$10+datos_base!$C$41)*parametros_carros!F$13 -> 0.0972 | I18: =(datos_base!$C$10+datos_base!$C$41)*parametros_carros!G$13 -> 0.0864 | J18: =(datos_base!$C$10+datos_base!$C$41)*parametros_carros!H$13 -> 0.0972 | K18: =(datos_base!$C$10+datos_base!$C$41)*parametros_carros!I$13 -> 0.0972 | ... O18: =(datos_base!$C$10+datos_base!$C$41)*parametros_carros!M$13 -> 0.0864 | P18: =SUM(D18:O18) -> 1.08
A19: 2027 | B19: Cilindros ABC 70 kg | C19: Cilindro | D19: =(datos_base!$C$11+datos_base!$C$42)*parametros_carros!B$14 -> 0.0068 | E19: =(datos_base!$C$11+datos_base!$C$42)*parametros_carros!C$14 -> 0.006 | F19: =(datos_base!$C$11+datos_base!$C$42)*parametros_carros!D$14 -> 0.0072 | G19: =(datos_base!$C$11+datos_base!$C$42)*parametros_carros!E$14 -> 0.0072 | H19: =(datos_base!$C$11+datos_base!$C$42)*parametros_carros!F$14 -> 0.0072 | I19: =(datos_base!$C$11+datos_base!$C$42)*parametros_carros!G$14 -> 0.0064 | J19: =(datos_base!$C$11+datos_base!$C$42)*parametros_carros!H$14 -> 0.0072 | K19: =(datos_base!$C$11+datos_base!$C$42)*parametros_carros!I$14 -> 0.0072 | ... O19: =(datos_base!$C$11+datos_base!$C$42)*parametros_carros!M$14 -> 0.0064 | P19: =SUM(D19:O19) -> 0.08
A20: 2027 | B20: Cilindros ABC 100 kg | C20: Cilindro | D20: =(datos_base!$C$12+datos_base!$C$43)*parametros_carros!B$15 -> 0.0068 | E20: =(datos_base!$C$12+datos_base!$C$43)*parametros_carros!C$15 -> 0.006 | F20: =(datos_base!$C$12+datos_base!$C$43)*parametros_carros!D$15 -> 0.0072 | G20: =(datos_base!$C$12+datos_base!$C$43)*parametros_carros!E$15 -> 0.0072 | H20: =(datos_base!$C$12+datos_base!$C$43)*parametros_carros!F$15 -> 0.0072 | I20: =(datos_base!$C$12+datos_base!$C$43)*parametros_carros!G$15 -> 0.0064 | J20: =(datos_base!$C$12+datos_base!$C$43)*parametros_carros!H$15 -> 0.0072 | K20: =(datos_base!$C$12+datos_base!$C$43)*parametros_carros!I$15 -> 0.0072 | ... O20: =(datos_base!$C$12+datos_base!$C$43)*parametros_carros!M$15 -> 0.0064 | P20: =SUM(D20:O20) -> 0.08
B21: Total recipientes | D21: =SUM(D13:D20) -> 20.01653 | E21: =SUM(E13:E20) -> 17.661644 | F21: =SUM(F13:F20) -> 21.193973 | G21: =SUM(G13:G20) -> 21.193973 | H21: =SUM(H13:H20) -> 21.193973 | I21: =SUM(I13:I20) -> 18.839087 | J21: =SUM(J13:J20) -> 21.193973 | K21: =SUM(K13:K20) -> 21.193973 | ... P21: =SUM(P13:P20) -> 235.48859
A23: 2028 | B23: Producto | C23: Tipo | D23: Ene | E23: Feb | F23: Mar | G23: Abr | H23: May | I23: Jun | J23: Jul | K23: Ago | L23: Sep | M23: Oct | N23: Nov | O23: Dic | P23: Total anual
A24: 2028 | B24: Carro ABC 25 kg | C24: Terminado | D24: =(datos_base!$D$2+datos_base!$D$35)*parametros_carros!B$12 -> 6.3995259 | E24: =(datos_base!$D$2+datos_base!$D$35)*parametros_carros!C$12 -> 5.6466405 | F24: =(datos_base!$D$2+datos_base!$D$35)*parametros_carros!D$12 -> 6.7759686 | G24: =(datos_base!$D$2+datos_base!$D$35)*parametros_carros!E$12 -> 6.7759686 | H24: =(datos_base!$D$2+datos_base!$D$35)*parametros_carros!F$12 -> 6.7759686 | I24: =(datos_base!$D$2+datos_base!$D$35)*parametros_carros!G$12 -> 6.0230832 | J24: =(datos_base!$D$2+datos_base!$D$35)*parametros_carros!H$12 -> 6.7759686 | K24: =(datos_base!$D$2+datos_base!$D$35)*parametros_carros!I$12 -> 6.7759686 | ... O24: =(datos_base!$D$2+datos_base!$D$35)*parametros_carros!M$12 -> 6.0230832 | P24: =SUM(D24:O24) -> 75.28854
A25: 2028 | B25: Carro ABC 50 kg | C25: Terminado | D25: =(datos_base!$D$3+datos_base!$D$36)*parametros_carros!B$13 -> 14.240797 | E25: =(datos_base!$D$3+datos_base!$D$36)*parametros_carros!C$13 -> 12.565409 | F25: =(datos_base!$D$3+datos_base!$D$36)*parametros_carros!D$13 -> 15.078491 | G25: =(datos_base!$D$3+datos_base!$D$36)*parametros_carros!E$13 -> 15.078491 | H25: =(datos_base!$D$3+datos_base!$D$36)*parametros_carros!F$13 -> 15.078491 | I25: =(datos_base!$D$3+datos_base!$D$36)*parametros_carros!G$13 -> 13.403103 | J25: =(datos_base!$D$3+datos_base!$D$36)*parametros_carros!H$13 -> 15.078491 | K25: =(datos_base!$D$3+datos_base!$D$36)*parametros_carros!I$13 -> 15.078491 | ... O25: =(datos_base!$D$3+datos_base!$D$36)*parametros_carros!M$13 -> 13.403103 | P25: =SUM(D25:O25) -> 167.53879
