Workbook

Sheet PROY_Indexado
A1: Proyecciones — Indexado Dim Técnico
A3: Recargas por tipo | B3: 2026 | C3: 2027 | D3: 2028 | E3: 2029 | F3: 2030 | G3: 2031 | H3: 2032 | I3: 2033 | J3: 2034 | K3: 2035
A4: ABC 1 kg | B4: =IFERROR(__xludf.DUMMYFUNCTION("IMPORTRANGE(""https://docs.google.com/spreadsheets/d/1xc4xDAwSYT3l-RulPYtcePxiCninrbQGzaBUsgO0YEs/edit?gid=1764491891#gid=1764491891"",""Indexado Dim Técnico!B27:K43"")"),3477.482124) -> 3477.4821 | C4: =IFERROR(__xludf.DUMMYFUNCTION("""COMPUTED_VALUE"""),16970.58564) -> 16970.586 | D4: =IFERROR(__xludf.DUMMYFUNCTION("""COMPUTED_VALUE"""),30546.08951) -> 30546.09 | E4: =IFERROR(__xludf.DUMMYFUNCTION("""COMPUTED_VALUE"""),56048.31106) -> 56048.311 | F4: =IFERROR(__xludf.DUMMYFUNCTION("""COMPUTED_VALUE"""),84270.22613) -> 84270.226 | G4: =IFERROR(__xludf.DUMMYFUNCTION("""COMPUTED_VALUE"""),117407.8231) -> 117407.82 | H4: =IFERROR(__xludf.DUMMYFUNCTION("""COMPUTED_VALUE"""),147610.6356) -> 147610.64 | I4: =IFERROR(__xludf.DUMMYFUNCTION("""COMPUTED_VALUE"""),171404.3607) -> 171404.36 | J4: =IFERROR(__xludf.DUMMYFUNCTION("""COMPUTED_VALUE"""),183690.566) -> 183690.57 | K4: =IFERROR(__xludf.DUMMYFUNCTION("""COMPUTED_VALUE"""),196282.6907) -> 196282.69
A5: ABC 2,5 kg | B5: =IFERROR(__xludf.DUMMYFUNCTION("""COMPUTED_VALUE"""),329.996668) -> 329.99667 | C5: =IFERROR(__xludf.DUMMYFUNCTION("""COMPUTED_VALUE"""),1287.414024) -> 1287.414 | D5: =IFERROR(__xludf.DUMMYFUNCTION("""COMPUTED_VALUE"""),2947.169216) -> 2947.1692 | E5: =IFERROR(__xludf.DUMMYFUNCTION("""COMPUTED_VALUE"""),5426.043269) -> 5426.0433 | F5: =IFERROR(__xludf.DUMMYFUNCTION("""COMPUTED_VALUE"""),7850.875806) -> 7850.8758 | G5: =IFERROR(__xludf.DUMMYFUNCTION("""COMPUTED_VALUE"""),10423.94365) -> 10423.944 | H5: =IFERROR(__xludf.DUMMYFUNCTION("""COMPUTED_VALUE"""),12809.89571) -> 12809.896 | I5: =IFERROR(__xludf.DUMMYFUNCTION("""COMPUTED_VALUE"""),14263.06831) -> 14263.068 | J5: =IFERROR(__xludf.DUMMYFUNCTION("""COMPUTED_VALUE"""),15432.86983) -> 15432.87 | K5: =IFERROR(__xludf.DUMMYFUNCTION("""COMPUTED_VALUE"""),16620.76117) -> 16620.761
A6: ABC 5 kg | B6: =IFERROR(__xludf.DUMMYFUNCTION("""COMPUTED_VALUE"""),1950.394097) -> 1950.3941 | C6: =IFERROR(__xludf.DUMMYFUNCTION("""COMPUTED_VALUE"""),7852.61852) -> 7852.6185 | D6: =IFERROR(__xludf.DUMMYFUNCTION("""COMPUTED_VALUE"""),17775.85701) -> 17775.857 | E6: =IFERROR(__xludf.DUMMYFUNCTION("""COMPUTED_VALUE"""),33605.56835) -> 33605.568 | F6: =IFERROR(__xludf.DUMMYFUNCTION("""COMPUTED_VALUE"""),48407.57189) -> 48407.572 | G6: =IFERROR(__xludf.DUMMYFUNCTION("""COMPUTED_VALUE"""),64323.04276) -> 64323.043 | H6: =IFERROR(__xludf.DUMMYFUNCTION("""COMPUTED_VALUE"""),78721.10039) -> 78721.1 | I6: =IFERROR(__xludf.DUMMYFUNCTION("""COMPUTED_VALUE"""),87237.2124) -> 87237.212 | J6: =IFERROR(__xludf.DUMMYFUNCTION("""COMPUTED_VALUE"""),94103.66761) -> 94103.668 | K6: =IFERROR(__xludf.DUMMYFUNCTION("""COMPUTED_VALUE"""),101095.1762) -> 101095.18
A7: ABC 10 kg | B7: =IFERROR(__xludf.DUMMYFUNCTION("""COMPUTED_VALUE"""),118.343632) -> 118.34363 | C7: =IFERROR(__xludf.DUMMYFUNCTION("""COMPUTED_VALUE"""),437.716578) -> 437.71658 | D7: =IFERROR(__xludf.DUMMYFUNCTION("""COMPUTED_VALUE"""),1024.974821) -> 1024.9748 | E7: =IFERROR(__xludf.DUMMYFUNCTION("""COMPUTED_VALUE"""),1960.409862) -> 1960.4099 | F7: =IFERROR(__xludf.DUMMYFUNCTION("""COMPUTED_VALUE"""),2844.976846) -> 2844.9768 | G7: =IFERROR(__xludf.DUMMYFUNCTION("""COMPUTED_VALUE"""),3810.390622) -> 3810.3906 | H7: =IFERROR(__xludf.DUMMYFUNCTION("""COMPUTED_VALUE"""),4663.67807) -> 4663.6781 | I7: =IFERROR(__xludf.DUMMYFUNCTION("""COMPUTED_VALUE"""),5164.514584) -> 5164.5146 | J7: =IFERROR(__xludf.DUMMYFUNCTION("""COMPUTED_VALUE"""),5571.544328) -> 5571.5443 | K7: =IFERROR(__xludf.DUMMYFUNCTION("""COMPUTED_VALUE"""),5985.950855) -> 5985.9509
A8: Agua 10 l | B8: =IFERROR(__xludf.DUMMYFUNCTION("""COMPUTED_VALUE"""),159.308736) -> 159.30874 | C8: =IFERROR(__xludf.DUMMYFUNCTION("""COMPUTED_VALUE"""),643.423542) -> 643.42354 | D8: =IFERROR(__xludf.DUMMYFUNCTION("""COMPUTED_VALUE"""),1474.362741) -> 1474.3627 | E8: =IFERROR(__xludf.DUMMYFUNCTION("""COMPUTED_VALUE"""),2766.451205) -> 2766.4512 | F8: =IFERROR(__xludf.DUMMYFUNCTION("""COMPUTED_VALUE"""),3991.465221) -> 3991.4652 | G8: =IFERROR(__xludf.DUMMYFUNCTION("""COMPUTED_VALUE"""),5335.75578) -> 5335.7558 | H8: =IFERROR(__xludf.DUMMYFUNCTION("""COMPUTED_VALUE"""),6538.958887) -> 6538.9589 | I8: =IFERROR(__xludf.DUMMYFUNCTION("""COMPUTED_VALUE"""),7269.819681) -> 7269.8197 | J8: =IFERROR(__xludf.DUMMYFUNCTION("""COMPUTED_VALUE"""),7855.44139) -> 7855.4414 | K8: =IFERROR(__xludf.DUMMYFUNCTION("""COMPUTED_VALUE"""),8450.814081) -> 8450.8141
A9: AFFF 10 l | B9: =IFERROR(__xludf.DUMMYFUNCTION("""COMPUTED_VALUE"""),22.758391) -> 22.758391 | C9: =IFERROR(__xludf.DUMMYFUNCTION("""COMPUTED_VALUE"""),161.315751) -> 161.31575 | D9: =IFERROR(__xludf.DUMMYFUNCTION("""COMPUTED_VALUE"""),316.607276) -> 316.60728 | E9: =IFERROR(__xludf.DUMMYFUNCTION("""COMPUTED_VALUE"""),527.39462) -> 527.39462 | F9: =IFERROR(__xludf.DUMMYFUNCTION("""COMPUTED_VALUE"""),743.788946) -> 743.78895 | G9: =IFERROR(__xludf.DUMMYFUNCTION("""COMPUTED_VALUE"""),962.874335) -> 962.87433 | H9: =IFERROR(__xludf.DUMMYFUNCTION("""COMPUTED_VALUE"""),1194.942207) -> 1194.9422 | I9: =IFERROR(__xludf.DUMMYFUNCTION("""COMPUTED_VALUE"""),1351.617183) -> 1351.6172 | J9: =IFERROR(__xludf.DUMMYFUNCTION("""COMPUTED_VALUE"""),1477.54886) -> 1477.5489 | K9: =IFERROR(__xludf.DUMMYFUNCTION("""COMPUTED_VALUE"""),1604.441422) -> 1604.4414
A10: AFFF 50 l s/ruedas | B10: =IFERROR(__xludf.DUMMYFUNCTION("""COMPUTED_VALUE"""),11.379195) -> 11.379195 | C10: =IFERROR(__xludf.DUMMYFUNCTION("""COMPUTED_VALUE"""),83.22352) -> 83.22352 | D10: =IFERROR(__xludf.DUMMYFUNCTION("""COMPUTED_VALUE"""),164.463834) -> 164.46383 | E10: =IFERROR(__xludf.DUMMYFUNCTION("""COMPUTED_VALUE"""),281.341145) -> 281.34114 | F10: =IFERROR(__xludf.DUMMYFUNCTION("""COMPUTED_VALUE"""),398.902509) -> 398.90251 | G10: =IFERROR(__xludf.DUMMYFUNCTION("""COMPUTED_VALUE"""),514.527284) -> 514.52728 | H10: =IFERROR(__xludf.DUMMYFUNCTION("""COMPUTED_VALUE"""),629.065505) -> 629.06551 | I10: =IFERROR(__xludf.DUMMYFUNCTION("""COMPUTED_VALUE"""),711.178024) -> 711.17802 | J10: =IFERROR(__xludf.DUMMYFUNCTION("""COMPUTED_VALUE"""),773.41098) -> 773.41098 | K10: =IFERROR(__xludf.DUMMYFUNCTION("""COMPUTED_VALUE"""),836.350805) -> 836.35081
A11: BC 5 kg | B11: =IFERROR(__xludf.DUMMYFUNCTION("""COMPUTED_VALUE"""),6.827517) -> 6.827517 | C11: =IFERROR(__xludf.DUMMYFUNCTION("""COMPUTED_VALUE"""),47.073112) -> 47.073112 | D11: =IFERROR(__xludf.DUMMYFUNCTION("""COMPUTED_VALUE"""),88.889676) -> 88.889676 | E11: =IFERROR(__xludf.DUMMYFUNCTION("""COMPUTED_VALUE"""),159.502491) -> 159.50249 | F11: =IFERROR(__xludf.DUMMYFUNCTION("""COMPUTED_VALUE"""),219.796202) -> 219.7962 | G11: =IFERROR(__xludf.DUMMYFUNCTION("""COMPUTED_VALUE"""),291.869853) -> 291.86985 | H11: =IFERROR(__xludf.DUMMYFUNCTION("""COMPUTED_VALUE"""),368.844169) -> 368.84417 | I11: =IFERROR(__xludf.DUMMYFUNCTION("""COMPUTED_VALUE"""),408.408953) -> 408.40895 | J11: =IFERROR(__xludf.DUMMYFUNCTION("""COMPUTED_VALUE"""),445.781944) -> 445.78194 | K11: =IFERROR(__xludf.DUMMYFUNCTION("""COMPUTED_VALUE"""),483.479203) -> 483.4792
A12: Sales K 6 l | B12: =IFERROR(__xludf.DUMMYFUNCTION("""COMPUTED_VALUE"""),81.930207) -> 81.930207 | C12: =IFERROR(__xludf.DUMMYFUNCTION("""COMPUTED_VALUE"""),335.398855) -> 335.39886 | D12: =IFERROR(__xludf.DUMMYFUNCTION("""COMPUTED_VALUE"""),746.598352) -> 746.59835 | E12: =IFERROR(__xludf.DUMMYFUNCTION("""COMPUTED_VALUE"""),1358.899837) -> 1358.8998 | F12: =IFERROR(__xludf.DUMMYFUNCTION("""COMPUTED_VALUE"""),1961.125522) -> 1961.1255 | G12: =IFERROR(__xludf.DUMMYFUNCTION("""COMPUTED_VALUE"""),2598.541412) -> 2598.5414 | H12: =IFERROR(__xludf.DUMMYFUNCTION("""COMPUTED_VALUE"""),3197.263477) -> 3197.2635 | I12: =IFERROR(__xludf.DUMMYFUNCTION("""COMPUTED_VALUE"""),3578.539452) -> 3578.5395 | J12: =IFERROR(__xludf.DUMMYFUNCTION("""COMPUTED_VALUE"""),3870.747997) -> 3870.748 | K12: =IFERROR(__xludf.DUMMYFUNCTION("""COMPUTED_VALUE"""),4167.559622) -> 4167.5596
A13: CO₂ 2 kg | B13: =IFERROR(__xludf.DUMMYFUNCTION("""COMPUTED_VALUE"""),450.616139) -> 450.61614 | C13: =IFERROR(__xludf.DUMMYFUNCTION("""COMPUTED_VALUE"""),1697.18149) -> 1697.1815 | D13: =IFERROR(__xludf.DUMMYFUNCTION("""COMPUTED_VALUE"""),3955.196858) -> 3955.1969 | E13: =IFERROR(__xludf.DUMMYFUNCTION("""COMPUTED_VALUE"""),7561.26033) -> 7561.2603 | F13: =IFERROR(__xludf.DUMMYFUNCTION("""COMPUTED_VALUE"""),10920.14481) -> 10920.145 | G13: =IFERROR(__xludf.DUMMYFUNCTION("""COMPUTED_VALUE"""),14514.88522) -> 14514.885 | H13: =IFERROR(__xludf.DUMMYFUNCTION("""COMPUTED_VALUE"""),17746.49927) -> 17746.499 | I13: =IFERROR(__xludf.DUMMYFUNCTION("""COMPUTED_VALUE"""),19617.20546) -> 19617.205 | J13: =IFERROR(__xludf.DUMMYFUNCTION("""COMPUTED_VALUE"""),21161.80625) -> 21161.806 | K13: =IFERROR(__xludf.DUMMYFUNCTION("""COMPUTED_VALUE"""),22734.50171) -> 22734.502
A14: CO₂ 5 kg | B14: =IFERROR(__xludf.DUMMYFUNCTION("""COMPUTED_VALUE"""),125.17115) -> 125.17115 | C14: =IFERROR(__xludf.DUMMYFUNCTION("""COMPUTED_VALUE"""),643.630371) -> 643.63037 | D14: =IFERROR(__xludf.DUMMYFUNCTION("""COMPUTED_VALUE"""),1375.626719) -> 1375.6267 | E14: =IFERROR(__xludf.DUMMYFUNCTION("""COMPUTED_VALUE"""),2460.284265) -> 2460.2843 | F14: =IFERROR(__xludf.DUMMYFUNCTION("""COMPUTED_VALUE"""),3545.257683) -> 3545.2577 | G14: =IFERROR(__xludf.DUMMYFUNCTION("""COMPUTED_VALUE"""),4723.461784) -> 4723.4618 | H14: =IFERROR(__xludf.DUMMYFUNCTION("""COMPUTED_VALUE"""),5853.905178) -> 5853.9052 | I14: =IFERROR(__xludf.DUMMYFUNCTION("""COMPUTED_VALUE"""),6608.459909) -> 6608.4599 | J14: =IFERROR(__xludf.DUMMYFUNCTION("""COMPUTED_VALUE"""),7185.708397) -> 7185.7084 | K14: =IFERROR(__xludf.DUMMYFUNCTION("""COMPUTED_VALUE"""),7769.577127) -> 7769.5771
A15: HCFC/HFC 5 kg | B15: =IFERROR(__xludf.DUMMYFUNCTION("""COMPUTED_VALUE"""),18.206713) -> 18.206713 | C15: =IFERROR(__xludf.DUMMYFUNCTION("""COMPUTED_VALUE"""),112.075122) -> 112.07512 | D15: =IFERROR(__xludf.DUMMYFUNCTION("""COMPUTED_VALUE"""),230.854041) -> 230.85404 | E15: =IFERROR(__xludf.DUMMYFUNCTION("""COMPUTED_VALUE"""),400.715334) -> 400.71533 | F15: =IFERROR(__xludf.DUMMYFUNCTION("""COMPUTED_VALUE"""),574.507789) -> 574.50779 | G15: =IFERROR(__xludf.DUMMYFUNCTION("""COMPUTED_VALUE"""),754.345623) -> 754.34562 | H15: =IFERROR(__xludf.DUMMYFUNCTION("""COMPUTED_VALUE"""),944.84884) -> 944.84884 | I15: =IFERROR(__xludf.DUMMYFUNCTION("""COMPUTED_VALUE"""),1072.234671) -> 1072.2347 | J15: =IFERROR(__xludf.DUMMYFUNCTION("""COMPUTED_VALUE"""),1171.695753) -> 1171.6958 | K15: =IFERROR(__xludf.DUMMYFUNCTION("""COMPUTED_VALUE"""),1271.941099) -> 1271.9411
A16: Clase D 9 l | B16: =IFERROR(__xludf.DUMMYFUNCTION("""COMPUTED_VALUE"""),6.827517) -> 6.827517 | C16: =IFERROR(__xludf.DUMMYFUNCTION("""COMPUTED_VALUE"""),47.073112) -> 47.073112 | D16: =IFERROR(__xludf.DUMMYFUNCTION("""COMPUTED_VALUE"""),88.889676) -> 88.889676 | E16: =IFERROR(__xludf.DUMMYFUNCTION("""COMPUTED_VALUE"""),148.279182) -> 148.27918 | F16: =IFERROR(__xludf.DUMMYFUNCTION("""COMPUTED_VALUE"""),205.226053) -> 205.22605 | G16: =IFERROR(__xludf.DUMMYFUNCTION("""COMPUTED_VALUE"""),255.765145) -> 255.76514 | H16: =IFERROR(__xludf.DUMMYFUNCTION("""COMPUTED_VALUE"""),328.417902) -> 328.4179 | I16: =IFERROR(__xludf.DUMMYFUNCTION("""COMPUTED_VALUE"""),366.908071) -> 366.90807 | J16: =IFERROR(__xludf.DUMMYFUNCTION("""COMPUTED_VALUE"""),401.681707) -> 401.68171 | K16: =IFERROR(__xludf.DUMMYFUNCTION("""COMPUTED_VALUE"""),436.686782) -> 436.68678
A17: ABC 25 kg s/ruedas | B17: =IFERROR(__xludf.DUMMYFUNCTION("""COMPUTED_VALUE"""),17.637753) -> 17.637753 | C17: =IFERROR(__xludf.DUMMYFUNCTION("""COMPUTED_VALUE"""),85.987819) -> 85.987819 | D17: =IFERROR(__xludf.DUMMYFUNCTION("""COMPUTED_VALUE"""),186.869567) -> 186.86957 | E17: =IFERROR(__xludf.DUMMYFUNCTION("""COMPUTED_VALUE"""),336.583621) -> 336.58362 | F17: =IFERROR(__xludf.DUMMYFUNCTION("""COMPUTED_VALUE"""),484.132598) -> 484.1326 | G17: =IFERROR(__xludf.DUMMYFUNCTION("""COMPUTED_VALUE"""),643.220385) -> 643.22038 | H17: =IFERROR(__xludf.DUMMYFUNCTION("""COMPUTED_VALUE"""),792.431742) -> 792.43174 | I17: =IFERROR(__xludf.DUMMYFUNCTION("""COMPUTED_VALUE"""),889.677707) -> 889.67771 | J17: =IFERROR(__xludf.DUMMYFUNCTION("""COMPUTED_VALUE"""),965.31111) -> 965.31111 | K17: =IFERROR(__xludf.DUMMYFUNCTION("""COMPUTED_VALUE"""),1041.939702) -> 1041.9397
A18: ABC 50 kg s/ruedas | B18: =IFERROR(__xludf.DUMMYFUNCTION("""COMPUTED_VALUE"""),38.803056) -> 38.803056 | C18: =IFERROR(__xludf.DUMMYFUNCTION("""COMPUTED_VALUE"""),189.173203) -> 189.1732 | D18: =IFERROR(__xludf.DUMMYFUNCTION("""COMPUTED_VALUE"""),411.113048) -> 411.11305 | E18: =IFERROR(__xludf.DUMMYFUNCTION("""COMPUTED_VALUE"""),740.483966) -> 740.48397 | F18: =IFERROR(__xludf.DUMMYFUNCTION("""COMPUTED_VALUE"""),1065.091715) -> 1065.0917 | G18: =IFERROR(__xludf.DUMMYFUNCTION("""COMPUTED_VALUE"""),1415.084848) -> 1415.0848 | H18: =IFERROR(__xludf.DUMMYFUNCTION("""COMPUTED_VALUE"""),1743.349833) -> 1743.3498 | I18: =IFERROR(__xludf.DUMMYFUNCTION("""COMPUTED_VALUE"""),1957.290955) -> 1957.291 | J18: =IFERROR(__xludf.DUMMYFUNCTION("""COMPUTED_VALUE"""),2123.684441) -> 2123.6844 | K18: =IFERROR(__xludf.DUMMYFUNCTION("""COMPUTED_VALUE"""),2292.267343) -> 2292.2673
A19: ABC 70 kg s/ruedas | B19: =IFERROR(__xludf.DUMMYFUNCTION("""COMPUTED_VALUE"""),8.466121) -> 8.466121 | C19: =IFERROR(__xludf.DUMMYFUNCTION("""COMPUTED_VALUE"""),41.274153) -> 41.274153 | D19: =IFERROR(__xludf.DUMMYFUNCTION("""COMPUTED_VALUE"""),89.697392) -> 89.697392 | E19: =IFERROR(__xludf.DUMMYFUNCTION("""COMPUTED_VALUE"""),161.560138) -> 161.56014 | F19: =IFERROR(__xludf.DUMMYFUNCTION("""COMPUTED_VALUE"""),232.383647) -> 232.38365 | G19: =IFERROR(__xludf.DUMMYFUNCTION("""COMPUTED_VALUE"""),308.745785) -> 308.74579 | H19: =IFERROR(__xludf.DUMMYFUNCTION("""COMPUTED_VALUE"""),380.367236) -> 380.36724 | I19: =IFERROR(__xludf.DUMMYFUNCTION("""COMPUTED_VALUE"""),427.045299) -> 427.0453 | J19: =IFERROR(__xludf.DUMMYFUNCTION("""COMPUTED_VALUE"""),463.349333) -> 463.34933 | K19: =IFERROR(__xludf.DUMMYFUNCTION("""COMPUTED_VALUE"""),500.131057) -> 500.13106
A20: ABC 100 kg s/ruedas | B20: =IFERROR(__xludf.DUMMYFUNCTION("""COMPUTED_VALUE"""),5.644081) -> 5.644081 | C20: =IFERROR(__xludf.DUMMYFUNCTION("""COMPUTED_VALUE"""),27.516102) -> 27.516102 | D20: =IFERROR(__xludf.DUMMYFUNCTION("""COMPUTED_VALUE"""),59.798262) -> 59.798262 | E20: =IFERROR(__xludf.DUMMYFUNCTION("""COMPUTED_VALUE"""),107.706759) -> 107.70676 | F20: =IFERROR(__xludf.DUMMYFUNCTION("""COMPUTED_VALUE"""),154.922431) -> 154.92243 | G20: =IFERROR(__xludf.DUMMYFUNCTION("""COMPUTED_VALUE"""),205.830523) -> 205.83052 | H20: =IFERROR(__xludf.DUMMYFUNCTION("""COMPUTED_VALUE"""),253.578158) -> 253.57816 | I20: =IFERROR(__xludf.DUMMYFUNCTION("""COMPUTED_VALUE"""),284.696866) -> 284.69687 | J20: =IFERROR(__xludf.DUMMYFUNCTION("""COMPUTED_VALUE"""),308.899555) -> 308.89956 | K20: =IFERROR(__xludf.DUMMYFUNCTION("""COMPUTED_VALUE"""),333.420704) -> 333.4207
A21: Recargas total | B21: =SUM(B4:B20) -> 6829.7931 | C21: =SUM(C4:C20) -> 30662.681 | D21: =SUM(D4:D20) -> 61483.058 | E21: =SUM(E4:E20) -> 114050.8 | F21: =SUM(F4:F20) -> 167870.4 | G21: =SUM(G4:G20) -> 228490.11 | H21: =SUM(H4:H20) -> 283777.78 | I21: =SUM(I4:I20) -> 322612.24 | ... K21: =SUM(K4:K20) -> 371907.69
A23: Recargas por zona y planta
A24: Zona | B24: % zonal 2035 | C24: Planta
A25: CABA Norte | B25: =IFERROR(__xludf.DUMMYFUNCTION("IMPORTRANGE(""https://docs.google.com/spreadsheets/d/1xc4xDAwSYT3l-RulPYtcePxiCninrbQGzaBUsgO0YEs/edit?gid=1764491891#gid=1764491891"",""Indexado Dim Técnico!u61:u74"")"),0.0521797399) -> 0.05217974 | C25: Comercial
A26: CABA Este | B26: =IFERROR(__xludf.DUMMYFUNCTION("""COMPUTED_VALUE"""),0.0798836162) -> 0.079883616 | C26: Comercial
A27: CABA Sur | B27: =IFERROR(__xludf.DUMMYFUNCTION("""COMPUTED_VALUE"""),0.059817286) -> 0.059817286 | C27: Industrial
A28: CABA Oeste | B28: =IFERROR(__xludf.DUMMYFUNCTION("""COMPUTED_VALUE"""),0.0637650712) -> 0.063765071 | C28: Comercial
A29: PBA Sur 1er (Avellaneda) | B29: =IFERROR(__xludf.DUMMYFUNCTION("""COMPUTED_VALUE"""),0.0676801452) -> 0.067680145 | C29: Industrial
A30: PBA Sur 2do cordón | B30: =IFERROR(__xludf.DUMMYFUNCTION("""COMPUTED_VALUE"""),0.0932172985) -> 0.093217299 | C30: Industrial
A31: PBA Sur 3er cordón | B31: =IFERROR(__xludf.DUMMYFUNCTION("""COMPUTED_VALUE"""),0.0675217758) -> 0.067521776 | C31: Industrial
A32: PBA Norte 1er cordón | B32: =IFERROR(__xludf.DUMMYFUNCTION("""COMPUTED_VALUE"""),0.0533558834) -> 0.053355883 | C32: Comercial
A33: PBA Norte 2do cordón | B33: =IFERROR(__xludf.DUMMYFUNCTION("""COMPUTED_VALUE"""),0.0885682049) -> 0.088568205 | C33: Comercial
A34: PBA Norte 3er cordón | B34: =IFERROR(__xludf.DUMMYFUNCTION("""COMPUTED_VALUE"""),0.0471361107) -> 0.047136111 | C34: Comercial
A35: PBA Oeste 1er cordón | B35: =IFERROR(__xludf.DUMMYFUNCTION("""COMPUTED_VALUE"""),0.0848900664) -> 0.084890066 | C35: Comercial
A36: PBA Oeste 2do cordón | B36: =IFERROR(__xludf.DUMMYFUNCTION("""COMPUTED_VALUE"""),0.0672643024) -> 0.067264302 | C36: Comercial
A37: PBA Oeste 3er cordón | B37: =IFERROR(__xludf.DUMMYFUNCTION("""COMPUTED_VALUE"""),0.0174767438) -> 0.017476744 | C37: Comercial
A38: PBA Interior | B38: =IFERROR(__xludf.DUMMYFUNCTION("""COMPUTED_VALUE"""),0.1572437555) -> 0.15724376 | C38: Comercial
A40: % planta comercial | B40: =SUMIF($C$25:$C$38,"Comercial",$B$25:$B$38) -> 0.71176349
A41: % planta industrial | B41: =SUMIF($C$25:$C$38,"Industrial",$B$25:$B$38) -> 0.28823651
A42: Control (tiene que dar 100 %) | B42: =B40+B41 -> 1
A44: Tasas de Proyecciones (hojas PROYECCION por rubro; iguales para todos los tipos)
...

Sheet datos_base
A1: Tipo de matafuego | B1: =PROY_Indexado!B3 -> 2026 | C1: =PROY_Indexado!C3 -> 2027 | D1: =PROY_Indexado!D3 -> 2028 | E1: =PROY_Indexado!E3 -> 2029 | F1: =PROY_Indexado!F3 -> 2030 | G1: =PROY_Indexado!G3 -> 2031 | H1: =PROY_Indexado!H3 -> 2032 | I1: =PROY_Indexado!I3 -> 2033 | ... K1: =PROY_Indexado!K3 -> 2035
A2: =PROY_Indexado!A4 -> ABC 1 kg | B2: =PROY_Indexado!B4*PROY_Indexado!$B$52 -> 1002.3373 | C2: =PROY_Indexado!C4*PROY_Indexado!$B$52 -> 4891.5423 | D2: =PROY_Indexado!D4*PROY_Indexado!$B$52 -> 8804.4981 | E2: =PROY_Indexado!E4*PROY_Indexado!$B$52 -> 16155.169 | F2: =PROY_Indexado!F4*PROY_Indexado!$B$52 -> 24289.755 | G2: =PROY_Indexado!G4*PROY_Indexado!$B$52 -> 33841.221 | H2: =PROY_Indexado!H4*PROY_Indexado!$B$52 -> 42546.774 | I2: =PROY_Indexado!I4*PROY_Indexado!$B$52 -> 49404.994 | ... K2: =PROY_Indexado!K4*PROY_Indexado!$B$52 -> 56575.837
A3: =PROY_Indexado!A5 -> ABC 2,5 kg | B3: =PROY_Indexado!B5*PROY_Indexado!$B$52 -> 95.117086 | C3: =PROY_Indexado!C5*PROY_Indexado!$B$52 -> 371.07972 | D3: =PROY_Indexado!D5*PROY_Indexado!$B$52 -> 849.48176 | E3: =PROY_Indexado!E5*PROY_Indexado!$B$52 -> 1563.9838 | F3: =PROY_Indexado!F5*PROY_Indexado!$B$52 -> 2262.909 | G3: =PROY_Indexado!G5*PROY_Indexado!$B$52 -> 3004.5611 | H3: =PROY_Indexado!H5*PROY_Indexado!$B$52 -> 3692.2796 | I3: =PROY_Indexado!I5*PROY_Indexado!$B$52 -> 4111.137 | ... K3: =PROY_Indexado!K5*PROY_Indexado!$B$52 -> 4790.7101
A4: =PROY_Indexado!A6 -> ABC 5 kg | B4: =PROY_Indexado!B6*PROY_Indexado!$B$52 -> 562.17478 | C4: =PROY_Indexado!C6*PROY_Indexado!$B$52 -> 2263.4113 | D4: =PROY_Indexado!D6*PROY_Indexado!$B$52 -> 5123.6509 | E4: =PROY_Indexado!E6*PROY_Indexado!$B$52 -> 9686.3516 | F4: =PROY_Indexado!F6*PROY_Indexado!$B$52 -> 13952.829 | G4: =PROY_Indexado!G6*PROY_Indexado!$B$52 -> 18540.249 | H4: =PROY_Indexado!H6*PROY_Indexado!$B$52 -> 22690.295 | I4: =PROY_Indexado!I6*PROY_Indexado!$B$52 -> 25144.949 | ... K4: =PROY_Indexado!K6*PROY_Indexado!$B$52 -> 29139.32
A5: =PROY_Indexado!A7 -> ABC 10 kg | B5: =PROY_Indexado!B7*PROY_Indexado!$B$52 -> 34.110955 | C5: =PROY_Indexado!C7*PROY_Indexado!$B$52 -> 126.1659 | D5: =PROY_Indexado!D7*PROY_Indexado!$B$52 -> 295.43516 | E5: =PROY_Indexado!E7*PROY_Indexado!$B$52 -> 565.06169 | F5: =PROY_Indexado!F7*PROY_Indexado!$B$52 -> 820.02618 | G5: =PROY_Indexado!G7*PROY_Indexado!$B$52 -> 1098.2937 | H5: =PROY_Indexado!H7*PROY_Indexado!$B$52 -> 1344.2423 | I5: =PROY_Indexado!I7*PROY_Indexado!$B$52 -> 1488.6016 | ... K5: =PROY_Indexado!K7*PROY_Indexado!$B$52 -> 1725.3696
A6: =PROY_Indexado!A8 -> Agua 10 l | B6: =PROY_Indexado!B8*PROY_Indexado!$B$52 -> 45.918593 | C6: =PROY_Indexado!C8*PROY_Indexado!$B$52 -> 185.45815 | D6: =PROY_Indexado!D8*PROY_Indexado!$B$52 -> 424.96516 | E6: =PROY_Indexado!E8*PROY_Indexado!$B$52 -> 797.39223 | F6: =PROY_Indexado!F8*PROY_Indexado!$B$52 -> 1150.486 | G6: =PROY_Indexado!G8*PROY_Indexado!$B$52 -> 1537.9596 | H6: =PROY_Indexado!H8*PROY_Indexado!$B$52 -> 1884.7667 | I6: =PROY_Indexado!I8*PROY_Indexado!$B$52 -> 2095.4274 | ... K6: =PROY_Indexado!K8*PROY_Indexado!$B$52 -> 2435.8331
A7: =PROY_Indexado!A9 -> AFFF 10 l | B7: =PROY_Indexado!B9*PROY_Indexado!$B$52 -> 6.5597991 | C7: =PROY_Indexado!C9*PROY_Indexado!$B$52 -> 46.497088 | D7: =PROY_Indexado!D9*PROY_Indexado!$B$52 -> 91.257775 | E7: =PROY_Indexado!E9*PROY_Indexado!$B$52 -> 152.01438 | F7: =PROY_Indexado!F9*PROY_Indexado!$B$52 -> 214.38713 | G7: =PROY_Indexado!G9*PROY_Indexado!$B$52 -> 277.53553 | H7: =PROY_Indexado!H9*PROY_Indexado!$B$52 -> 344.42597 | I7: =PROY_Indexado!I9*PROY_Indexado!$B$52 -> 389.58541 | ... K7: =PROY_Indexado!K9*PROY_Indexado!$B$52 -> 462.45859
A8: =PROY_Indexado!A10 -> AFFF 50 l s/ruedas | B8: =PROY_Indexado!B10*PROY_Indexado!$B$52 -> 3.2798994 | C8: =PROY_Indexado!C10*PROY_Indexado!$B$52 -> 23.988057 | D8: =PROY_Indexado!D10*PROY_Indexado!$B$52 -> 47.404481 | E8: =PROY_Indexado!E10*PROY_Indexado!$B$52 -> 81.092788 | F8: =PROY_Indexado!F10*PROY_Indexado!$B$52 -> 114.97827 | G8: =PROY_Indexado!G10*PROY_Indexado!$B$52 -> 148.30555 | H8: =PROY_Indexado!H10*PROY_Indexado!$B$52 -> 181.31964 | I8: =PROY_Indexado!I10*PROY_Indexado!$B$52 -> 204.98747 | ... K8: =PROY_Indexado!K10*PROY_Indexado!$B$52 -> 241.06683
A9: =PROY_Indexado!A11 -> BC 5 kg | B9: =PROY_Indexado!B11*PROY_Indexado!$B$52 -> 1.9679396 | C9: =PROY_Indexado!C11*PROY_Indexado!$B$52 -> 13.568189 | D9: =PROY_Indexado!D11*PROY_Indexado!$B$52 -> 25.62125 | E9: =PROY_Indexado!E11*PROY_Indexado!$B$52 -> 45.974441 | F9: =PROY_Indexado!F11*PROY_Indexado!$B$52 -> 63.353289 | G9: =PROY_Indexado!G11*PROY_Indexado!$B$52 -> 84.127546 | H9: =PROY_Indexado!H11*PROY_Indexado!$B$52 -> 106.31435 | I9: =PROY_Indexado!I11*PROY_Indexado!$B$52 -> 117.71837 | ... K9: =PROY_Indexado!K11*PROY_Indexado!$B$52 -> 139.35636
A10: =PROY_Indexado!A12 -> Sales K 6 l | B10: =PROY_Indexado!B12*PROY_Indexado!$B$52 -> 23.615277 | C10: =PROY_Indexado!C12*PROY_Indexado!$B$52 -> 96.674194 | D10: =PROY_Indexado!D12*PROY_Indexado!$B$52 -> 215.1969 | E10: =PROY_Indexado!E12*PROY_Indexado!$B$52 -> 391.68454 | F10: =PROY_Indexado!F12*PROY_Indexado!$B$52 -> 565.26797 | G10: =PROY_Indexado!G12*PROY_Indexado!$B$52 -> 748.9945 | H10: =PROY_Indexado!H12*PROY_Indexado!$B$52 -> 921.56805 | I10: =PROY_Indexado!I12*PROY_Indexado!$B$52 -> 1031.4657 | ... K10: =PROY_Indexado!K12*PROY_Indexado!$B$52 -> 1201.2428
A11: =PROY_Indexado!A13 -> CO₂ 2 kg | B11: =PROY_Indexado!B13*PROY_Indexado!$B$52 -> 129.88402 | C11: =PROY_Indexado!C13*PROY_Indexado!$B$52 -> 489.18966 | D11: =PROY_Indexado!D13*PROY_Indexado!$B$52 -> 1140.0321 | E11: =PROY_Indexado!E13*PROY_Indexado!$B$52 -> 2179.4313 | F11: =PROY_Indexado!F13*PROY_Indexado!$B$52 -> 3147.5844 | G11: =PROY_Indexado!G13*PROY_Indexado!$B$52 -> 4183.7198 | H11: =PROY_Indexado!H13*PROY_Indexado!$B$52 -> 5115.1889 | I11: =PROY_Indexado!I13*PROY_Indexado!$B$52 -> 5654.3947 | ... K11: =PROY_Indexado!K13*PROY_Indexado!$B$52 -> 6552.9133
A12: =PROY_Indexado!A14 -> CO₂ 5 kg | B12: =PROY_Indexado!B14*PROY_Indexado!$B$52 -> 36.078895 | C12: =PROY_Indexado!C14*PROY_Indexado!$B$52 -> 185.51777 | D12: =PROY_Indexado!D14*PROY_Indexado!$B$52 -> 396.50584 | E12: =PROY_Indexado!E14*PROY_Indexado!$B$52 -> 709.14374 | F12: =PROY_Indexado!F14*PROY_Indexado!$B$52 -> 1021.8727 | G12: =PROY_Indexado!G14*PROY_Indexado!$B$52 -> 1361.4741 | H12: =PROY_Indexado!H14*PROY_Indexado!$B$52 -> 1687.3092 | I12: =PROY_Indexado!I14*PROY_Indexado!$B$52 -> 1904.7994 | ... K12: =PROY_Indexado!K14*PROY_Indexado!$B$52 -> 2239.4758
A13: =PROY_Indexado!A15 -> HCFC/HFC 5 kg | B13: =PROY_Indexado!B15*PROY_Indexado!$B$52 -> 5.2478393 | C13: =PROY_Indexado!C15*PROY_Indexado!$B$52 -> 32.304142 | D13: =PROY_Indexado!D15*PROY_Indexado!$B$52 -> 66.540562 | E13: =PROY_Indexado!E15*PROY_Indexado!$B$52 -> 115.50079 | F13: =PROY_Indexado!F15*PROY_Indexado!$B$52 -> 165.59412 | G13: =PROY_Indexado!G15*PROY_Indexado!$B$52 -> 217.42995 | H13: =PROY_Indexado!H15*PROY_Indexado!$B$52 -> 272.33993 | I13: =PROY_Indexado!I15*PROY_Indexado!$B$52 -> 309.05717 | ... K13: =PROY_Indexado!K15*PROY_Indexado!$B$52 -> 366.61986
... A18: =PROY_Indexado!A20 -> ABC 100 kg s/ruedas | B18: =PROY_Indexado!B20*PROY_Indexado!$B$52 -> 1.6268302 | C18: =PROY_Indexado!C20*PROY_Indexado!$B$52 -> 7.9311451 | D18: =PROY_Indexado!D20*PROY_Indexado!$B$52 -> 17.236042 | E18: =PROY_Indexado!E20*PROY_Indexado!$B$52 -> 31.04502 | F18: =PROY_Indexado!F20*PROY_Indexado!$B$52 -> 44.6543 | G18: =PROY_Indexado!G20*PROY_Indexado!$B$52 -> 59.327871 | H18: =PROY_Indexado!H20*PROY_Indexado!$B$52 -> 73.090482 | I18: =PROY_Indexado!I20*PROY_Indexado!$B$52 -> 82.06003 | ... K18: =PROY_Indexado!K20*PROY_Indexado!$B$52 -> 96.104019
A19: Recargas Total | B19: =SUM(B2:B18) -> 1968.5957 | C19: =SUM(C2:C18) -> 8838.104 | D19: =SUM(D2:D18) -> 17721.662 | E19: =SUM(E2:E18) -> 32873.603 | F19: =SUM(F2:F18) -> 48386.376 | G19: =SUM(G2:G18) -> 65859.19 | H19: =SUM(H2:H18) -> 81795.116 | I19: =SUM(I2:I18) -> 92988.624 | ... K19: =SUM(K2:K18) -> 107197.37

Sheet parametros_recargas
A1: Parámetro | B1: Valor | C1: Fuente / criterio
A2: Días hábiles por mes | B2: 20 | C2: 240 días hábiles por año ÷ 12
A3: Horas por día (1 turno) | B3: 8
A4: Refrigerio (min/turno) | B4: 30
A5: Horas productivas por turno | B5: =B3-B4/60 -> 7.5
A6: Horas productivas por mes (1 turno) | B6: =B2*B5 -> 150
A7: Umbral de aprovechamiento | B7: 0.9 | C7: 10 % de holgura para variabilidad, averías y mantenimiento
A8: Turnos máximos por día | B8: 2 | C8: hasta 2 turnos de 8 h; después se agrega máquina
A9: Equivalencia de un rodante (u. equivalentes) | B9: 3 | C9: Traslado en carro, morsa y manipuleo del porte
A10: Año de inicio del 2° turno (antes: más máquinas) | B10: 2032 | C10: Prioridad del aprovechamiento: antes de ese año se agrega máquina u operario; desde ese año, turno
A11: CRITERIOS DE RUTA — PLANTA INDUSTRIAL (IRAM 3517-2:2020 y Proyecciones)
A12: Parámetro | B12: Valor | C12: Fuente / criterio
A13: Intervalo máximo de PH — polvos, CO₂ y halogenados (años) | B13: 5 | C13: IRAM 3517-2:2020, Anexo E (IRAM 3523, 3550, 3509, 3565 y 3504)
A14: Intervalo máximo de PH — agua, AFFF y sales K (años) | B14: 2 | C14: IRAM 3517-2:2020, Anexo E (IRAM 3525, 3527, 3537, 3541, 3693 y 3694)
A15: % con PH — polvos, CO₂ y halogenados | B15: =1/B13 -> 0.2 | C15: En régimen vence la PH de 1 de cada 5 equipos por año
A16: % con PH — agua, AFFF y sales K | B16: =1/B14 -> 0.5 | C16: En régimen vence la PH de 1 de cada 2 equipos por año
A17: Vida útil — CO₂ (años) | B17: 30 | C17: IRAM 3517-2:2020, Anexo E (IRAM 3509; IRAM 3565 hasta 10 kg)
A18: Vida útil — resto de los tipos (años) | B18: 20 | C18: IRAM 3517-2:2020, Anexo E
A19: % fin de vida útil — CO₂ | B19: =1/B17 -> 0.033333333 | C19: En régimen llega al fin de su vida 1 de cada 30
A20: % fin de vida útil — resto | B20: =1/B18 -> 0.05 | C20: En régimen llega al fin de su vida 1 de cada 20
A21: % que no pasan la PH | B21: =PROY_Indexado!B47 -> 0.02 | C21: Proyecciones (Mat PH). La norma manda inutilizarlos (9.12) pero no fija el %
A22: % rotos | B22: =PROY_Indexado!B48 -> 0.01 | C22: Proyecciones (Mat Rot)
A23: % inutilizados — CO₂ | B23: =B19+B21+B22 -> 0.063333333 | C23: Fin de vida útil + no pasan la PH + rotos
A24: % inutilizados — resto | B24: =B20+B21+B22 -> 0.08 | C24: Fin de vida útil + no pasan la PH + rotos
A25: % que llegan descargados por uso | B25: =PROY_Indexado!B46 -> 0.05 | C25: Proyecciones (Mat Usados). 9.2.2: se recarga después de usarlo; la norma no fija el %
A26: Dígitos posibles del año de fabricación | B26: 10 | C26: 9.9.4 a): se cambia el polvo ABC cuando el último dígito del año de fabricación coincide con el del año del mantenimiento
A27: % ABC con cambio de polvo (a descarte) | B27: =1/B26 -> 0.1 | C27: 1 de cada 10 equipos por año
A28: % agua, AFFF y sales K que se vacían y recargan | B28: 1 | C28: Anexo E: el agente se cambia cada año; 9.9.1.9 (sales K) y 9.9.1.10 (AFFF)
A29: % CO₂ que se abren por daño o cambio de piezas | B29: 0.05 | C29: 9.7.1.2: el dañado se examina y va a PH
A30: % que se pintan | B30: 0.1 | C30: 9.10 pide pintar los deteriorados; no fija %
A31: % polvos con humedad en el desarme (secado extra) | B31: 0.01
A32: Ensayos de laboratorio por recipiente de polvo | B32: 0.001 | C32: Criterio. 9.9.3.1: el ensayo se hace cuando hay dudas sobre el polvo
A34: PERFIL MENSUAL POR AÑO (plano, 1/12 por mes)
A35: IRAM 3517-2:2020 9.2.1 (mantenimiento como mínimo anual) y 9.4.14 a) (la etiqueta fija el mes y año del próximo): cada equipo vuelve en su mes y la norma no fija ningún mes del calendario. El crecimiento se toma entre años (Proyecciones es anual).
A36: Año | B36: Ene | C36: Feb | D36: Mar | E36: Abr | F36: May | G36: Jun | H36: Jul | I36: Ago | J36: Sep | K36: Oct | L36: Nov | M36: Dic | N36: Total
A37: 2026 | B37: =1/12 -> 0.083333333 | C37: =1/12 -> 0.083333333 | D37: =1/12 -> 0.083333333 | E37: =1/12 -> 0.083333333 | F37: =1/12 -> 0.083333333 | G37: =1/12 -> 0.083333333 | H37: =1/12 -> 0.083333333 | I37: =1/12 -> 0.083333333 | ... M37: =1/12 -> 0.083333333 | N37: =SUM(B37:M37) -> 1
A38: 2027 | B38: =1/12 -> 0.083333333 | C38: =1/12 -> 0.083333333 | D38: =1/12 -> 0.083333333 | E38: =1/12 -> 0.083333333 | F38: =1/12 -> 0.083333333 | G38: =1/12 -> 0.083333333 | H38: =1/12 -> 0.083333333 | I38: =1/12 -> 0.083333333 | ... M38: =1/12 -> 0.083333333 | N38: =SUM(B38:M38) -> 1
A39: 2028 | B39: =1/12 -> 0.083333333 | C39: =1/12 -> 0.083333333 | D39: =1/12 -> 0.083333333 | E39: =1/12 -> 0.083333333 | F39: =1/12 -> 0.083333333 | G39: =1/12 -> 0.083333333 | H39: =1/12 -> 0.083333333 | I39: =1/12 -> 0.083333333 | ... M39: =1/12 -> 0.083333333 | N39: =SUM(B39:M39) -> 1
A40: 2029 | B40: =1/12 -> 0.083333333 | C40: =1/12 -> 0.083333333 | D40: =1/12 -> 0.083333333 | E40: =1/12 -> 0.083333333 | F40: =1/12 -> 0.083333333 | G40: =1/12 -> 0.083333333 | H40: =1/12 -> 0.083333333 | I40: =1/12 -> 0.083333333 | ... M40: =1/12 -> 0.083333333 | N40: =SUM(B40:M40) -> 1
A41: 2030 | B41: =1/12 -> 0.083333333 | C41: =1/12 -> 0.083333333 | D41: =1/12 -> 0.083333333 | E41: =1/12 -> 0.083333333 | F41: =1/12 -> 0.083333333 | G41: =1/12 -> 0.083333333 | H41: =1/12 -> 0.083333333 | I41: =1/12 -> 0.083333333 | ... M41: =1/12 -> 0.083333333 | N41: =SUM(B41:M41) -> 1
...

Sheet sobrestock_sustitutos
A1: SUSTITUTOS (IRAM 3517-2:2020, 9.4.5)
A2: Mismo tipo que el equipo retirado. Va con el camión al retirar y vuelve cuando se devuelve el recargado.
A4: Parámetro | B4: Valor | C4: Fuente / criterio
A5: Días hábiles por mes | B5: =parametros_recargas!B2 -> 20
A6: Día de retiro | B6: 1 | C6: El sustituto sale con el camión que retira
A7: Día de devolución | B7: 1 | C7: El sustituto vuelve con el camión que devuelve; no se deja en otro cliente en ese viaje
A8: Minutos productivos por turno | B8: =parametros_recargas!B5*60 -> 450
A9: Planta | B9: =PROY_Indexado!B51 -> Industrial | C9: Comercial: compra todos. Industrial: fabrica los ABC
A11: PASO 1 — Tiempo por rubro (mix del rubro × tiempos de operación)
A12: Días de proceso = minutos por equipo ÷ minutos del turno, redondeado hacia arriba (mínimo 1). Ciclo del sustituto = retiro + proceso + devolución
A13: Concepto | B13: Automotor | C13: Edificios | D13: Educación | E13: Hoteles | F13: Industrias / almacenes | G13: Salud | H13: Supermercados
A14: % de las recargas (mercado, zonas de la planta) | B14: =SUM(PROY_Indexado!B$97:B$113)/SUM(PROY_Indexado!$B$97:$H$113) -> 0.5859526 | C14: =SUM(PROY_Indexado!C$97:C$113)/SUM(PROY_Indexado!$B$97:$H$113) -> 0.28820088 | D14: =SUM(PROY_Indexado!D$97:D$113)/SUM(PROY_Indexado!$B$97:$H$113) -> 0.030211304 | E14: =SUM(PROY_Indexado!E$97:E$113)/SUM(PROY_Indexado!$B$97:$H$113) -> 0.019867201 | F14: =SUM(PROY_Indexado!F$97:F$113)/SUM(PROY_Indexado!$B$97:$H$113) -> 0.043422904 | G14: =SUM(PROY_Indexado!G$97:G$113)/SUM(PROY_Indexado!$B$97:$H$113) -> 0.027889583 | H14: =SUM(PROY_Indexado!H$97:H$113)/SUM(PROY_Indexado!$B$97:$H$113) -> 0.0044555242
A15: Minutos de operación por equipo | B15: =IF(SUM(PROY_Indexado!B$97:B$113)=0,0,SUMPRODUCT(PROY_Indexado!B$97:B$113,$C$21:$C$37)/SUM(PROY_Indexado!B$97:B$113)) -> 17.253 | C15: =IF(SUM(PROY_Indexado!C$97:C$113)=0,0,SUMPRODUCT(PROY_Indexado!C$97:C$113,$C$21:$C$37)/SUM(PROY_Indexado!C$97:C$113)) -> 17.32219 | D15: =IF(SUM(PROY_Indexado!D$97:D$113)=0,0,SUMPRODUCT(PROY_Indexado!D$97:D$113,$C$21:$C$37)/SUM(PROY_Indexado!D$97:D$113)) -> 16.941268 | E15: =IF(SUM(PROY_Indexado!E$97:E$113)=0,0,SUMPRODUCT(PROY_Indexado!E$97:E$113,$C$21:$C$37)/SUM(PROY_Indexado!E$97:E$113)) -> 17.66419 | F15: =IF(SUM(PROY_Indexado!F$97:F$113)=0,0,SUMPRODUCT(PROY_Indexado!F$97:F$113,$C$21:$C$37)/SUM(PROY_Indexado!F$97:F$113)) -> 21.877646 | G15: =IF(SUM(PROY_Indexado!G$97:G$113)=0,0,SUMPRODUCT(PROY_Indexado!G$97:G$113,$C$21:$C$37)/SUM(PROY_Indexado!G$97:G$113)) -> 19.158559 | H15: =IF(SUM(PROY_Indexado!H$97:H$113)=0,0,SUMPRODUCT(PROY_Indexado!H$97:H$113,$C$21:$C$37)/SUM(PROY_Indexado!H$97:H$113)) -> 17.453005
A16: Días de proceso | B16: =MAX(1,ROUNDUP(B15/$B$8,0)) -> 1 | C16: =MAX(1,ROUNDUP(C15/$B$8,0)) -> 1 | D16: =MAX(1,ROUNDUP(D15/$B$8,0)) -> 1 | E16: =MAX(1,ROUNDUP(E15/$B$8,0)) -> 1 | F16: =MAX(1,ROUNDUP(F15/$B$8,0)) -> 1 | G16: =MAX(1,ROUNDUP(G15/$B$8,0)) -> 1 | H16: =MAX(1,ROUNDUP(H15/$B$8,0)) -> 1
A17: Ciclo del sustituto (días) | B17: =$B$6+B16+$B$7 -> 3 | C17: =$B$6+C16+$B$7 -> 3 | D17: =$B$6+D16+$B$7 -> 3 | E17: =$B$6+E16+$B$7 -> 3 | F17: =$B$6+F16+$B$7 -> 3 | G17: =$B$6+G16+$B$7 -> 3 | H17: =$B$6+H16+$B$7 -> 3
A18: Horas de planta por día (2035) | B18: =datos_base!$K$19*B14/(12*$B$5)*B15/60 -> 75.257322 | C18: =datos_base!$K$19*C14/(12*$B$5)*C15/60 -> 37.163769 | D18: =datos_base!$K$19*D14/(12*$B$5)*D15/60 -> 3.8101058 | E18: =datos_base!$K$19*E14/(12*$B$5)*E15/60 -> 2.6124744 | F18: =datos_base!$K$19*F14/(12*$B$5)*F15/60 -> 7.0719812 | G18: =datos_base!$K$19*G14/(12*$B$5)*G15/60 -> 3.9776495 | H18: =datos_base!$K$19*H14/(12*$B$5)*H15/60 -> 0.57888283
A19: PASO 2 — Tipos (el ciclo de cada tipo pesa los rubros según sus recargas)
A20: Tipo | B20: Lleva sustituto (1 = sí) | C20: Minutos de operación por equipo | D20: Ciclo del sustituto (días) | E20: Origen | G20: Nota
A21: =datos_base!A2 -> ABC 1 kg | B21: 0 | C21: {=(SUMPRODUCT(INDEX(parametros_recargas!$E$72:$L$99,0,MATCH(parametros_recargas!$B$51,parametros_recargas!$E$71:$L$71,0)),parametros_recargas!$M$72:$M$99)*parametros_recargas!$C$51+parametros_recargas!$D$51*parametros_recargas!$M$100)/60} -> 17.253 | D21: =IF(SUM(PROY_Indexado!$B$97:$H$97)=0,$B$6+1+$B$7,SUMPRODUCT(PROY_Indexado!$B$97:$H$97,$B$17:$H$17)/SUM(PROY_Indexado!$B$97:$H$97)) -> 3 | E21: =IF(AND($B$9="Industrial",LEFT(A21,3)="ABC"),"Fabrica","Compra") -> Fabrica | G21: Automotor: sin canje
A22: =datos_base!A3 -> ABC 2,5 kg | B22: 1 | C22: {=(SUMPRODUCT(INDEX(parametros_recargas!$E$72:$L$99,0,MATCH(parametros_recargas!$B$52,parametros_recargas!$E$71:$L$71,0)),parametros_recargas!$M$72:$M$99)*parametros_recargas!$C$52+parametros_recargas!$D$52*parametros_recargas!$M$100)/60} -> 17.253 | D22: =IF(SUM(PROY_Indexado!$B$98:$H$98)=0,$B$6+1+$B$7,SUMPRODUCT(PROY_Indexado!$B$98:$H$98,$B$17:$H$17)/SUM(PROY_Indexado!$B$98:$H$98)) -> 3 | E22: =IF(AND($B$9="Industrial",LEFT(A22,3)="ABC"),"Fabrica","Compra") -> Fabrica
A23: =datos_base!A4 -> ABC 5 kg | B23: 1 | C23: {=(SUMPRODUCT(INDEX(parametros_recargas!$E$72:$L$99,0,MATCH(parametros_recargas!$B$53,parametros_recargas!$E$71:$L$71,0)),parametros_recargas!$M$72:$M$99)*parametros_recargas!$C$53+parametros_recargas!$D$53*parametros_recargas!$M$100)/60} -> 17.253 | D23: =IF(SUM(PROY_Indexado!$B$99:$H$99)=0,$B$6+1+$B$7,SUMPRODUCT(PROY_Indexado!$B$99:$H$99,$B$17:$H$17)/SUM(PROY_Indexado!$B$99:$H$99)) -> 3 | E23: =IF(AND($B$9="Industrial",LEFT(A23,3)="ABC"),"Fabrica","Compra") -> Fabrica
A24: =datos_base!A5 -> ABC 10 kg | B24: 1 | C24: {=(SUMPRODUCT(INDEX(parametros_recargas!$E$72:$L$99,0,MATCH(parametros_recargas!$B$54,parametros_recargas!$E$71:$L$71,0)),parametros_recargas!$M$72:$M$99)*parametros_recargas!$C$54+parametros_recargas!$D$54*parametros_recargas!$M$100)/60} -> 17.253 | D24: =IF(SUM(PROY_Indexado!$B$100:$H$100)=0,$B$6+1+$B$7,SUMPRODUCT(PROY_Indexado!$B$100:$H$100,$B$17:$H$17)/SUM(PROY_Indexado!$B$100:$H$100)) -> 3 | E24: =IF(AND($B$9="Industrial",LEFT(A24,3)="ABC"),"Fabrica","Compra") -> Fabrica
A25: =datos_base!A6 -> Agua 10 l | B25: 1 | C25: {=(SUMPRODUCT(INDEX(parametros_recargas!$E$72:$L$99,0,MATCH(parametros_recargas!$B$55,parametros_recargas!$E$71:$L$71,0)),parametros_recargas!$M$72:$M$99)*parametros_recargas!$C$55+parametros_recargas!$D$55*parametros_recargas!$M$100)/60} -> 18.986667 | D25: =IF(SUM(PROY_Indexado!$B$101:$H$101)=0,$B$6+1+$B$7,SUMPRODUCT(PROY_Indexado!$B$101:$H$101,$B$17:$H$17)/SUM(PROY_Indexado!$B$101:$H$101)) -> 3 | E25: =IF(AND($B$9="Industrial",LEFT(A25,3)="ABC"),"Fabrica","Compra") -> Compra
A26: =datos_base!A7 -> AFFF 10 l | B26: 1 | C26: {=(SUMPRODUCT(INDEX(parametros_recargas!$E$72:$L$99,0,MATCH(parametros_recargas!$B$56,parametros_recargas!$E$71:$L$71,0)),parametros_recargas!$M$72:$M$99)*parametros_recargas!$C$56+parametros_recargas!$D$56*parametros_recargas!$M$100)/60} -> 18.986667 | D26: =IF(SUM(PROY_Indexado!$B$102:$H$102)=0,$B$6+1+$B$7,SUMPRODUCT(PROY_Indexado!$B$102:$H$102,$B$17:$H$17)/SUM(PROY_Indexado!$B$102:$H$102)) -> 3 | E26: =IF(AND($B$9="Industrial",LEFT(A26,3)="ABC"),"Fabrica","Compra") -> Compra
A27: =datos_base!A8 -> AFFF 50 l s/ruedas | B27: 1 | C27: {=(SUMPRODUCT(INDEX(parametros_recargas!$E$72:$L$99,0,MATCH(parametros_recargas!$B$57,parametros_recargas!$E$71:$L$71,0)),parametros_recargas!$M$72:$M$99)*parametros_recargas!$C$57+parametros_recargas!$D$57*parametros_recargas!$M$100)/60} -> 61.993333 | D27: =IF(SUM(PROY_Indexado!$B$103:$H$103)=0,$B$6+1+$B$7,SUMPRODUCT(PROY_Indexado!$B$103:$H$103,$B$17:$H$17)/SUM(PROY_Indexado!$B$103:$H$103)) -> 3 | E27: =IF(AND($B$9="Industrial",LEFT(A27,3)="ABC"),"Fabrica","Compra") -> Compra
A28: =datos_base!A9 -> BC 5 kg | B28: 1 | C28: {=(SUMPRODUCT(INDEX(parametros_recargas!$E$72:$L$99,0,MATCH(parametros_recargas!$B$58,parametros_recargas!$E$71:$L$71,0)),parametros_recargas!$M$72:$M$99)*parametros_recargas!$C$58+parametros_recargas!$D$58*parametros_recargas!$M$100)/60} -> 17.8905 | D28: =IF(SUM(PROY_Indexado!$B$104:$H$104)=0,$B$6+1+$B$7,SUMPRODUCT(PROY_Indexado!$B$104:$H$104,$B$17:$H$17)/SUM(PROY_Indexado!$B$104:$H$104)) -> 3 | E28: =IF(AND($B$9="Industrial",LEFT(A28,3)="ABC"),"Fabrica","Compra") -> Compra
A29: =datos_base!A10 -> Sales K 6 l | B29: 1 | C29: {=(SUMPRODUCT(INDEX(parametros_recargas!$E$72:$L$99,0,MATCH(parametros_recargas!$B$59,parametros_recargas!$E$71:$L$71,0)),parametros_recargas!$M$72:$M$99)*parametros_recargas!$C$59+parametros_recargas!$D$59*parametros_recargas!$M$100)/60} -> 18.986667 | D29: =IF(SUM(PROY_Indexado!$B$105:$H$105)=0,$B$6+1+$B$7,SUMPRODUCT(PROY_Indexado!$B$105:$H$105,$B$17:$H$17)/SUM(PROY_Indexado!$B$105:$H$105)) -> 3 | E29: =IF(AND($B$9="Industrial",LEFT(A29,3)="ABC"),"Fabrica","Compra") -> Compra
A30: =datos_base!A11 -> CO₂ 2 kg | B30: 1 | C30: {=(SUMPRODUCT(INDEX(parametros_recargas!$E$72:$L$99,0,MATCH(parametros_recargas!$B$60,parametros_recargas!$E$71:$L$71,0)),parametros_recargas!$M$72:$M$99)*parametros_recargas!$C$60+parametros_recargas!$D$60*parametros_recargas!$M$100)/60} -> 13.030833 | D30: =IF(SUM(PROY_Indexado!$B$106:$H$106)=0,$B$6+1+$B$7,SUMPRODUCT(PROY_Indexado!$B$106:$H$106,$B$17:$H$17)/SUM(PROY_Indexado!$B$106:$H$106)) -> 3 | E30: =IF(AND($B$9="Industrial",LEFT(A30,3)="ABC"),"Fabrica","Compra") -> Compra
A31: =datos_base!A12 -> CO₂ 5 kg | B31: 1 | C31: {=(SUMPRODUCT(INDEX(parametros_recargas!$E$72:$L$99,0,MATCH(parametros_recargas!$B$61,parametros_recargas!$E$71:$L$71,0)),parametros_recargas!$M$72:$M$99)*parametros_recargas!$C$61+parametros_recargas!$D$61*parametros_recargas!$M$100)/60} -> 18.064167 | D31: =IF(SUM(PROY_Indexado!$B$107:$H$107)=0,$B$6+1+$B$7,SUMPRODUCT(PROY_Indexado!$B$107:$H$107,$B$17:$H$17)/SUM(PROY_Indexado!$B$107:$H$107)) -> 3 | E31: =IF(AND($B$9="Industrial",LEFT(A31,3)="ABC"),"Fabrica","Compra") -> Compra
A32: =datos_base!A13 -> HCFC/HFC 5 kg | B32: 1 | C32: {=(SUMPRODUCT(INDEX(parametros_recargas!$E$72:$L$99,0,MATCH(parametros_recargas!$B$62,parametros_recargas!$E$71:$L$71,0)),parametros_recargas!$M$72:$M$99)*parametros_recargas!$C$62+parametros_recargas!$D$62*parametros_recargas!$M$100)/60} -> 14.8475 | D32: =IF(SUM(PROY_Indexado!$B$108:$H$108)=0,$B$6+1+$B$7,SUMPRODUCT(PROY_Indexado!$B$108:$H$108,$B$17:$H$17)/SUM(PROY_Indexado!$B$108:$H$108)) -> 3 | E32: =IF(AND($B$9="Industrial",LEFT(A32,3)="ABC"),"Fabrica","Compra") -> Compra
A33: =datos_base!A14 -> Clase D 9 l | B33: 1 | C33: {=(SUMPRODUCT(INDEX(parametros_recargas!$E$72:$L$99,0,MATCH(parametros_recargas!$B$63,parametros_recargas!$E$71:$L$71,0)),parametros_recargas!$M$72:$M$99)*parametros_recargas!$C$63+parametros_recargas!$D$63*parametros_recargas!$M$100)/60} -> 22.254167 | D33: =IF(SUM(PROY_Indexado!$B$109:$H$109)=0,$B$6+1+$B$7,SUMPRODUCT(PROY_Indexado!$B$109:$H$109,$B$17:$H$17)/SUM(PROY_Indexado!$B$109:$H$109)) -> 3 | E33: =IF(AND($B$9="Industrial",LEFT(A33,3)="ABC"),"Fabrica","Compra") -> Compra
A34: =datos_base!A15 -> ABC 25 kg s/ruedas | B34: 1 | C34: {=(SUMPRODUCT(INDEX(parametros_recargas!$E$72:$L$99,0,MATCH(parametros_recargas!$B$64,parametros_recargas!$E$71:$L$71,0)),parametros_recargas!$M$72:$M$99)*parametros_recargas!$C$64+parametros_recargas!$D$64*parametros_recargas!$M$100)/60} -> 56.792333 | D34: =IF(SUM(PROY_Indexado!$B$110:$H$110)=0,$B$6+1+$B$7,SUMPRODUCT(PROY_Indexado!$B$110:$H$110,$B$17:$H$17)/SUM(PROY_Indexado!$B$110:$H$110)) -> 3 | E34: =IF(AND($B$9="Industrial",LEFT(A34,3)="ABC"),"Fabrica","Compra") -> Fabrica
A35: =datos_base!A16 -> ABC 50 kg s/ruedas | B35: 1 | C35: {=(SUMPRODUCT(INDEX(parametros_recargas!$E$72:$L$99,0,MATCH(parametros_recargas!$B$65,parametros_recargas!$E$71:$L$71,0)),parametros_recargas!$M$72:$M$99)*parametros_recargas!$C$65+parametros_recargas!$D$65*parametros_recargas!$M$100)/60} -> 56.792333 | D35: =IF(SUM(PROY_Indexado!$B$111:$H$111)=0,$B$6+1+$B$7,SUMPRODUCT(PROY_Indexado!$B$111:$H$111,$B$17:$H$17)/SUM(PROY_Indexado!$B$111:$H$111)) -> 3 | E35: =IF(AND($B$9="Industrial",LEFT(A35,3)="ABC"),"Fabrica","Compra") -> Fabrica
A36: =datos_base!A17 -> ABC 70 kg s/ruedas | B36: 1 | C36: {=(SUMPRODUCT(INDEX(parametros_recargas!$E$72:$L$99,0,MATCH(parametros_recargas!$B$66,parametros_recargas!$E$71:$L$71,0)),parametros_recargas!$M$72:$M$99)*parametros_recargas!$C$66+parametros_recargas!$D$66*parametros_recargas!$M$100)/60} -> 56.792333 | D36: =IF(SUM(PROY_Indexado!$B$112:$H$112)=0,$B$6+1+$B$7,SUMPRODUCT(PROY_Indexado!$B$112:$H$112,$B$17:$H$17)/SUM(PROY_Indexado!$B$112:$H$112)) -> 3 | E36: =IF(AND($B$9="Industrial",LEFT(A36,3)="ABC"),"Fabrica","Compra") -> Fabrica
A37: =datos_base!A18 -> ABC 100 kg s/ruedas | B37: 1 | C37: {=(SUMPRODUCT(INDEX(parametros_recargas!$E$72:$L$99,0,MATCH(parametros_recargas!$B$67,parametros_recargas!$E$71:$L$71,0)),parametros_recargas!$M$72:$M$99)*parametros_recargas!$C$67+parametros_recargas!$D$67*parametros_recargas!$M$100)/60} -> 56.792333 | D37: =IF(SUM(PROY_Indexado!$B$113:$H$113)=0,$B$6+1+$B$7,SUMPRODUCT(PROY_Indexado!$B$113:$H$113,$B$17:$H$17)/SUM(PROY_Indexado!$B$113:$H$113)) -> 3 | E37: =IF(AND($B$9="Industrial",LEFT(A37,3)="ABC"),"Fabrica","Compra") -> Fabrica
A39: PASO 3 — Stock (u.)
A40: Stock = recargas del año × % del mes pico ÷ días del mes × ciclo del sustituto, redondeado hacia arriba
A41: Tipo | B41: 2026 | C41: 2027 | D41: 2028 | E41: 2029 | F41: 2030 | G41: 2031 | H41: 2032 | I41: 2033 | J41: 2034 | K41: 2035
A42: =datos_base!A2 -> ABC 1 kg | B42: =ROUNDUP(datos_base!B2*$B$21*$D$21*MAX(parametros_recargas!$B$37:$M$37)/$B$5,0) -> 0 | C42: =ROUNDUP(datos_base!C2*$B$21*$D$21*MAX(parametros_recargas!$B$38:$M$38)/$B$5,0) -> 0 | D42: =ROUNDUP(datos_base!D2*$B$21*$D$21*MAX(parametros_recargas!$B$39:$M$39)/$B$5,0) -> 0 | E42: =ROUNDUP(datos_base!E2*$B$21*$D$21*MAX(parametros_recargas!$B$40:$M$40)/$B$5,0) -> 0 | F42: =ROUNDUP(datos_base!F2*$B$21*$D$21*MAX(parametros_recargas!$B$41:$M$41)/$B$5,0) -> 0 | G42: =ROUNDUP(datos_base!G2*$B$21*$D$21*MAX(parametros_recargas!$B$42:$M$42)/$B$5,0) -> 0 | H42: =ROUNDUP(datos_base!H2*$B$21*$D$21*MAX(parametros_recargas!$B$43:$M$43)/$B$5,0) -> 0 | I42: =ROUNDUP(datos_base!I2*$B$21*$D$21*MAX(parametros_recargas!$B$44:$M$44)/$B$5,0) -> 0 | J42: =ROUNDUP(datos_base!J2*$B$21*$D$21*MAX(parametros_recargas!$B$45:$M$45)/$B$5,0) -> 0 | K42: =ROUNDUP(datos_base!K2*$B$21*$D$21*MAX(parametros_recargas!$B$46:$M$46)/$B$5,0) -> 0
A43: =datos_base!A3 -> ABC 2,5 kg | B43: =ROUNDUP(datos_base!B3*$B$22*$D$22*MAX(parametros_recargas!$B$37:$M$37)/$B$5,0) -> 2 | C43: =ROUNDUP(datos_base!C3*$B$22*$D$22*MAX(parametros_recargas!$B$38:$M$38)/$B$5,0) -> 5 | D43: =ROUNDUP(datos_base!D3*$B$22*$D$22*MAX(parametros_recargas!$B$39:$M$39)/$B$5,0) -> 11 | E43: =ROUNDUP(datos_base!E3*$B$22*$D$22*MAX(parametros_recargas!$B$40:$M$40)/$B$5,0) -> 20 | F43: =ROUNDUP(datos_base!F3*$B$22*$D$22*MAX(parametros_recargas!$B$41:$M$41)/$B$5,0) -> 29 | G43: =ROUNDUP(datos_base!G3*$B$22*$D$22*MAX(parametros_recargas!$B$42:$M$42)/$B$5,0) -> 38 | H43: =ROUNDUP(datos_base!H3*$B$22*$D$22*MAX(parametros_recargas!$B$43:$M$43)/$B$5,0) -> 47 | I43: =ROUNDUP(datos_base!I3*$B$22*$D$22*MAX(parametros_recargas!$B$44:$M$44)/$B$5,0) -> 52 | J43: =ROUNDUP(datos_base!J3*$B$22*$D$22*MAX(parametros_recargas!$B$45:$M$45)/$B$5,0) -> 56 | K43: =ROUNDUP(datos_base!K3*$B$22*$D$22*MAX(parametros_recargas!$B$46:$M$46)/$B$5,0) -> 60
...

Sheet Plan mensual
A1: 2026 | B1: Agente | C1: u. equiv. | D1: Ene | E1: Feb | F1: Mar | G1: Abr | H1: May | I1: Jun | J1: Jul | K1: Ago | L1: Sep | M1: Oct | N1: Nov | O1: Dic | P1: Total | Q1: Incluye mant. de sustitutos (u./año)
A2: =parametros_recargas!A51 -> ABC 1 kg | B2: =parametros_recargas!B51 -> ABC | C2: =parametros_recargas!C51 -> 1 | D2: =datos_base!$B$2*parametros_recargas!$B$37+sobrestock_sustitutos!$B$88/12 -> 83.528108 | E2: =datos_base!$B$2*parametros_recargas!$C$37+sobrestock_sustitutos!$B$88/12 -> 83.528108 | F2: =datos_base!$B$2*parametros_recargas!$D$37+sobrestock_sustitutos!$B$88/12 -> 83.528108 | G2: =datos_base!$B$2*parametros_recargas!$E$37+sobrestock_sustitutos!$B$88/12 -> 83.528108 | H2: =datos_base!$B$2*parametros_recargas!$F$37+sobrestock_sustitutos!$B$88/12 -> 83.528108 | I2: =datos_base!$B$2*parametros_recargas!$G$37+sobrestock_sustitutos!$B$88/12 -> 83.528108 | J2: =datos_base!$B$2*parametros_recargas!$H$37+sobrestock_sustitutos!$B$88/12 -> 83.528108 | K2: =datos_base!$B$2*parametros_recargas!$I$37+sobrestock_sustitutos!$B$88/12 -> 83.528108 | L2: =datos_base!$B$2*parametros_recargas!$J$37+sobrestock_sustitutos!$B$88/12 -> 83.528108 | M2: =datos_base!$B$2*parametros_recargas!$K$37+sobrestock_sustitutos!$B$88/12 -> 83.528108 | N2: =datos_base!$B$2*parametros_recargas!$L$37+sobrestock_sustitutos!$B$88/12 -> 83.528108 | O2: =datos_base!$B$2*parametros_recargas!$M$37+sobrestock_sustitutos!$B$88/12 -> 83.528108 | P2: =SUM(D2:O2) -> 1002.3373 | Q2: =sobrestock_sustitutos!$B$88 -> 0
A3: =parametros_recargas!A52 -> ABC 2,5 kg | B3: =parametros_recargas!B52 -> ABC | C3: =parametros_recargas!C52 -> 1 | D3: =datos_base!$B$3*parametros_recargas!$B$37+sobrestock_sustitutos!$B$89/12 -> 7.9264239 | E3: =datos_base!$B$3*parametros_recargas!$C$37+sobrestock_sustitutos!$B$89/12 -> 7.9264239 | F3: =datos_base!$B$3*parametros_recargas!$D$37+sobrestock_sustitutos!$B$89/12 -> 7.9264239 | G3: =datos_base!$B$3*parametros_recargas!$E$37+sobrestock_sustitutos!$B$89/12 -> 7.9264239 | H3: =datos_base!$B$3*parametros_recargas!$F$37+sobrestock_sustitutos!$B$89/12 -> 7.9264239 | I3: =datos_base!$B$3*parametros_recargas!$G$37+sobrestock_sustitutos!$B$89/12 -> 7.9264239 | J3: =datos_base!$B$3*parametros_recargas!$H$37+sobrestock_sustitutos!$B$89/12 -> 7.9264239 | K3: =datos_base!$B$3*parametros_recargas!$I$37+sobrestock_sustitutos!$B$89/12 -> 7.9264239 | L3: =datos_base!$B$3*parametros_recargas!$J$37+sobrestock_sustitutos!$B$89/12 -> 7.9264239 | M3: =datos_base!$B$3*parametros_recargas!$K$37+sobrestock_sustitutos!$B$89/12 -> 7.9264239 | N3: =datos_base!$B$3*parametros_recargas!$L$37+sobrestock_sustitutos!$B$89/12 -> 7.9264239 | O3: =datos_base!$B$3*parametros_recargas!$M$37+sobrestock_sustitutos!$B$89/12 -> 7.9264239 | P3: =SUM(D3:O3) -> 95.117086 | Q3: =sobrestock_sustitutos!$B$89 -> 0
A4: =parametros_recargas!A53 -> ABC 5 kg | B4: =parametros_recargas!B53 -> ABC | C4: =parametros_recargas!C53 -> 1 | D4: =datos_base!$B$4*parametros_recargas!$B$37+sobrestock_sustitutos!$B$90/12 -> 46.847898 | E4: =datos_base!$B$4*parametros_recargas!$C$37+sobrestock_sustitutos!$B$90/12 -> 46.847898 | F4: =datos_base!$B$4*parametros_recargas!$D$37+sobrestock_sustitutos!$B$90/12 -> 46.847898 | G4: =datos_base!$B$4*parametros_recargas!$E$37+sobrestock_sustitutos!$B$90/12 -> 46.847898 | H4: =datos_base!$B$4*parametros_recargas!$F$37+sobrestock_sustitutos!$B$90/12 -> 46.847898 | I4: =datos_base!$B$4*parametros_recargas!$G$37+sobrestock_sustitutos!$B$90/12 -> 46.847898 | J4: =datos_base!$B$4*parametros_recargas!$H$37+sobrestock_sustitutos!$B$90/12 -> 46.847898 | K4: =datos_base!$B$4*parametros_recargas!$I$37+sobrestock_sustitutos!$B$90/12 -> 46.847898 | L4: =datos_base!$B$4*parametros_recargas!$J$37+sobrestock_sustitutos!$B$90/12 -> 46.847898 | M4: =datos_base!$B$4*parametros_recargas!$K$37+sobrestock_sustitutos!$B$90/12 -> 46.847898 | N4: =datos_base!$B$4*parametros_recargas!$L$37+sobrestock_sustitutos!$B$90/12 -> 46.847898 | O4: =datos_base!$B$4*parametros_recargas!$M$37+sobrestock_sustitutos!$B$90/12 -> 46.847898 | P4: =SUM(D4:O4) -> 562.17478 | Q4: =sobrestock_sustitutos!$B$90 -> 0
A5: =parametros_recargas!A54 -> ABC 10 kg | B5: =parametros_recargas!B54 -> ABC | C5: =parametros_recargas!C54 -> 1 | D5: =datos_base!$B$5*parametros_recargas!$B$37+sobrestock_sustitutos!$B$91/12 -> 2.8425796 | E5: =datos_base!$B$5*parametros_recargas!$C$37+sobrestock_sustitutos!$B$91/12 -> 2.8425796 | F5: =datos_base!$B$5*parametros_recargas!$D$37+sobrestock_sustitutos!$B$91/12 -> 2.8425796 | G5: =datos_base!$B$5*parametros_recargas!$E$37+sobrestock_sustitutos!$B$91/12 -> 2.8425796 | H5: =datos_base!$B$5*parametros_recargas!$F$37+sobrestock_sustitutos!$B$91/12 -> 2.8425796 | I5: =datos_base!$B$5*parametros_recargas!$G$37+sobrestock_sustitutos!$B$91/12 -> 2.8425796 | J5: =datos_base!$B$5*parametros_recargas!$H$37+sobrestock_sustitutos!$B$91/12 -> 2.8425796 | K5: =datos_base!$B$5*parametros_recargas!$I$37+sobrestock_sustitutos!$B$91/12 -> 2.8425796 | L5: =datos_base!$B$5*parametros_recargas!$J$37+sobrestock_sustitutos!$B$91/12 -> 2.8425796 | M5: =datos_base!$B$5*parametros_recargas!$K$37+sobrestock_sustitutos!$B$91/12 -> 2.8425796 | N5: =datos_base!$B$5*parametros_recargas!$L$37+sobrestock_sustitutos!$B$91/12 -> 2.8425796 | O5: =datos_base!$B$5*parametros_recargas!$M$37+sobrestock_sustitutos!$B$91/12 -> 2.8425796 | P5: =SUM(D5:O5) -> 34.110955 | Q5: =sobrestock_sustitutos!$B$91 -> 0
A6: =parametros_recargas!A55 -> Agua 10 l | B6: =parametros_recargas!B55 -> Agua | C6: =parametros_recargas!C55 -> 1 | D6: =datos_base!$B$6*parametros_recargas!$B$37+sobrestock_sustitutos!$B$92/12 -> 3.8265494 | E6: =datos_base!$B$6*parametros_recargas!$C$37+sobrestock_sustitutos!$B$92/12 -> 3.8265494 | F6: =datos_base!$B$6*parametros_recargas!$D$37+sobrestock_sustitutos!$B$92/12 -> 3.8265494 | G6: =datos_base!$B$6*parametros_recargas!$E$37+sobrestock_sustitutos!$B$92/12 -> 3.8265494 | H6: =datos_base!$B$6*parametros_recargas!$F$37+sobrestock_sustitutos!$B$92/12 -> 3.8265494 | I6: =datos_base!$B$6*parametros_recargas!$G$37+sobrestock_sustitutos!$B$92/12 -> 3.8265494 | J6: =datos_base!$B$6*parametros_recargas!$H$37+sobrestock_sustitutos!$B$92/12 -> 3.8265494 | K6: =datos_base!$B$6*parametros_recargas!$I$37+sobrestock_sustitutos!$B$92/12 -> 3.8265494 | L6: =datos_base!$B$6*parametros_recargas!$J$37+sobrestock_sustitutos!$B$92/12 -> 3.8265494 | M6: =datos_base!$B$6*parametros_recargas!$K$37+sobrestock_sustitutos!$B$92/12 -> 3.8265494 | N6: =datos_base!$B$6*parametros_recargas!$L$37+sobrestock_sustitutos!$B$92/12 -> 3.8265494 | O6: =datos_base!$B$6*parametros_recargas!$M$37+sobrestock_sustitutos!$B$92/12 -> 3.8265494 | P6: =SUM(D6:O6) -> 45.918593 | Q6: =sobrestock_sustitutos!$B$92 -> 0
A7: =parametros_recargas!A56 -> AFFF 10 l | B7: =parametros_recargas!B56 -> AFFF | C7: =parametros_recargas!C56 -> 1 | D7: =datos_base!$B$7*parametros_recargas!$B$37+sobrestock_sustitutos!$B$93/12 -> 0.54664992 | E7: =datos_base!$B$7*parametros_recargas!$C$37+sobrestock_sustitutos!$B$93/12 -> 0.54664992 | F7: =datos_base!$B$7*parametros_recargas!$D$37+sobrestock_sustitutos!$B$93/12 -> 0.54664992 | G7: =datos_base!$B$7*parametros_recargas!$E$37+sobrestock_sustitutos!$B$93/12 -> 0.54664992 | H7: =datos_base!$B$7*parametros_recargas!$F$37+sobrestock_sustitutos!$B$93/12 -> 0.54664992 | I7: =datos_base!$B$7*parametros_recargas!$G$37+sobrestock_sustitutos!$B$93/12 -> 0.54664992 | J7: =datos_base!$B$7*parametros_recargas!$H$37+sobrestock_sustitutos!$B$93/12 -> 0.54664992 | K7: =datos_base!$B$7*parametros_recargas!$I$37+sobrestock_sustitutos!$B$93/12 -> 0.54664992 | L7: =datos_base!$B$7*parametros_recargas!$J$37+sobrestock_sustitutos!$B$93/12 -> 0.54664992 | M7: =datos_base!$B$7*parametros_recargas!$K$37+sobrestock_sustitutos!$B$93/12 -> 0.54664992 | N7: =datos_base!$B$7*parametros_recargas!$L$37+sobrestock_sustitutos!$B$93/12 -> 0.54664992 | O7: =datos_base!$B$7*parametros_recargas!$M$37+sobrestock_sustitutos!$B$93/12 -> 0.54664992 | P7: =SUM(D7:O7) -> 6.5597991 | Q7: =sobrestock_sustitutos!$B$93 -> 0
A8: =parametros_recargas!A57 -> AFFF 50 l s/ruedas | B8: =parametros_recargas!B57 -> AFFF | C8: =parametros_recargas!C57 -> 3 | D8: =datos_base!$B$8*parametros_recargas!$B$37+sobrestock_sustitutos!$B$94/12 -> 0.27332495 | E8: =datos_base!$B$8*parametros_recargas!$C$37+sobrestock_sustitutos!$B$94/12 -> 0.27332495 | F8: =datos_base!$B$8*parametros_recargas!$D$37+sobrestock_sustitutos!$B$94/12 -> 0.27332495 | G8: =datos_base!$B$8*parametros_recargas!$E$37+sobrestock_sustitutos!$B$94/12 -> 0.27332495 | H8: =datos_base!$B$8*parametros_recargas!$F$37+sobrestock_sustitutos!$B$94/12 -> 0.27332495 | I8: =datos_base!$B$8*parametros_recargas!$G$37+sobrestock_sustitutos!$B$94/12 -> 0.27332495 | J8: =datos_base!$B$8*parametros_recargas!$H$37+sobrestock_sustitutos!$B$94/12 -> 0.27332495 | K8: =datos_base!$B$8*parametros_recargas!$I$37+sobrestock_sustitutos!$B$94/12 -> 0.27332495 | L8: =datos_base!$B$8*parametros_recargas!$J$37+sobrestock_sustitutos!$B$94/12 -> 0.27332495 | M8: =datos_base!$B$8*parametros_recargas!$K$37+sobrestock_sustitutos!$B$94/12 -> 0.27332495 | N8: =datos_base!$B$8*parametros_recargas!$L$37+sobrestock_sustitutos!$B$94/12 -> 0.27332495 | O8: =datos_base!$B$8*parametros_recargas!$M$37+sobrestock_sustitutos!$B$94/12 -> 0.27332495 | P8: =SUM(D8:O8) -> 3.2798994 | Q8: =sobrestock_sustitutos!$B$94 -> 0
A9: =parametros_recargas!A58 -> BC 5 kg | B9: =parametros_recargas!B58 -> BC | C9: =parametros_recargas!C58 -> 1 | D9: =datos_base!$B$9*parametros_recargas!$B$37+sobrestock_sustitutos!$B$95/12 -> 0.16399497 | E9: =datos_base!$B$9*parametros_recargas!$C$37+sobrestock_sustitutos!$B$95/12 -> 0.16399497 | F9: =datos_base!$B$9*parametros_recargas!$D$37+sobrestock_sustitutos!$B$95/12 -> 0.16399497 | G9: =datos_base!$B$9*parametros_recargas!$E$37+sobrestock_sustitutos!$B$95/12 -> 0.16399497 | H9: =datos_base!$B$9*parametros_recargas!$F$37+sobrestock_sustitutos!$B$95/12 -> 0.16399497 | I9: =datos_base!$B$9*parametros_recargas!$G$37+sobrestock_sustitutos!$B$95/12 -> 0.16399497 | J9: =datos_base!$B$9*parametros_recargas!$H$37+sobrestock_sustitutos!$B$95/12 -> 0.16399497 | K9: =datos_base!$B$9*parametros_recargas!$I$37+sobrestock_sustitutos!$B$95/12 -> 0.16399497 | L9: =datos_base!$B$9*parametros_recargas!$J$37+sobrestock_sustitutos!$B$95/12 -> 0.16399497 | M9: =datos_base!$B$9*parametros_recargas!$K$37+sobrestock_sustitutos!$B$95/12 -> 0.16399497 | N9: =datos_base!$B$9*parametros_recargas!$L$37+sobrestock_sustitutos!$B$95/12 -> 0.16399497 | O9: =datos_base!$B$9*parametros_recargas!$M$37+sobrestock_sustitutos!$B$95/12 -> 0.16399497 | P9: =SUM(D9:O9) -> 1.9679396 | Q9: =sobrestock_sustitutos!$B$95 -> 0
A10: =parametros_recargas!A59 -> Sales K 6 l | B10: =parametros_recargas!B59 -> Sales K | C10: =parametros_recargas!C59 -> 1 | D10: =datos_base!$B$10*parametros_recargas!$B$37+sobrestock_sustitutos!$B$96/12 -> 1.9679397 | E10: =datos_base!$B$10*parametros_recargas!$C$37+sobrestock_sustitutos!$B$96/12 -> 1.9679397 | F10: =datos_base!$B$10*parametros_recargas!$D$37+sobrestock_sustitutos!$B$96/12 -> 1.9679397 | G10: =datos_base!$B$10*parametros_recargas!$E$37+sobrestock_sustitutos!$B$96/12 -> 1.9679397 | H10: =datos_base!$B$10*parametros_recargas!$F$37+sobrestock_sustitutos!$B$96/12 -> 1.9679397 | I10: =datos_base!$B$10*parametros_recargas!$G$37+sobrestock_sustitutos!$B$96/12 -> 1.9679397 | J10: =datos_base!$B$10*parametros_recargas!$H$37+sobrestock_sustitutos!$B$96/12 -> 1.9679397 | K10: =datos_base!$B$10*parametros_recargas!$I$37+sobrestock_sustitutos!$B$96/12 -> 1.9679397 | L10: =datos_base!$B$10*parametros_recargas!$J$37+sobrestock_sustitutos!$B$96/12 -> 1.9679397 | M10: =datos_base!$B$10*parametros_recargas!$K$37+sobrestock_sustitutos!$B$96/12 -> 1.9679397 | N10: =datos_base!$B$10*parametros_recargas!$L$37+sobrestock_sustitutos!$B$96/12 -> 1.9679397 | O10: =datos_base!$B$10*parametros_recargas!$M$37+sobrestock_sustitutos!$B$96/12 -> 1.9679397 | P10: =SUM(D10:O10) -> 23.615277 | Q10: =sobrestock_sustitutos!$B$96 -> 0
A11: =parametros_recargas!A60 -> CO₂ 2 kg | B11: =parametros_recargas!B60 -> CO₂ | C11: =parametros_recargas!C60 -> 1 | D11: =datos_base!$B$11*parametros_recargas!$B$37+sobrestock_sustitutos!$B$97/12 -> 10.823668 | E11: =datos_base!$B$11*parametros_recargas!$C$37+sobrestock_sustitutos!$B$97/12 -> 10.823668 | F11: =datos_base!$B$11*parametros_recargas!$D$37+sobrestock_sustitutos!$B$97/12 -> 10.823668 | G11: =datos_base!$B$11*parametros_recargas!$E$37+sobrestock_sustitutos!$B$97/12 -> 10.823668 | H11: =datos_base!$B$11*parametros_recargas!$F$37+sobrestock_sustitutos!$B$97/12 -> 10.823668 | I11: =datos_base!$B$11*parametros_recargas!$G$37+sobrestock_sustitutos!$B$97/12 -> 10.823668 | J11: =datos_base!$B$11*parametros_recargas!$H$37+sobrestock_sustitutos!$B$97/12 -> 10.823668 | K11: =datos_base!$B$11*parametros_recargas!$I$37+sobrestock_sustitutos!$B$97/12 -> 10.823668 | L11: =datos_base!$B$11*parametros_recargas!$J$37+sobrestock_sustitutos!$B$97/12 -> 10.823668 | M11: =datos_base!$B$11*parametros_recargas!$K$37+sobrestock_sustitutos!$B$97/12 -> 10.823668 | N11: =datos_base!$B$11*parametros_recargas!$L$37+sobrestock_sustitutos!$B$97/12 -> 10.823668 | O11: =datos_base!$B$11*parametros_recargas!$M$37+sobrestock_sustitutos!$B$97/12 -> 10.823668 | P11: =SUM(D11:O11) -> 129.88402 | Q11: =sobrestock_sustitutos!$B$97 -> 0
