Workbook

Sheet PROY_Indexado
A1: Proyecciones — Indexado Dim Técnico (valores copiados)
A2: Para actualizar: pegar valores de Proyecciones, Indexado Dim Técnico A27:K43 y U61:U74, o reemplazar por IMPORTRANGE. Celdas gris oscuro = datos.
A4: Recargas por tipo | B4: 2026 | C4: 2027 | D4: 2028 | E4: 2029 | F4: 2030 | G4: 2031 | H4: 2032 | I4: 2033 | J4: 2034 | K4: 2035
A5: ABC 1 kg | B5: 3477.4821 | C5: 16970.586 | D5: 30546.09 | E5: 56048.311 | F5: 84270.226 | G5: 117407.82 | H5: 147610.64 | I5: 171404.36 | J5: 183690.57 | K5: 196282.69
A6: ABC 2,5 kg | B6: 329.99667 | C6: 1287.414 | D6: 2947.1692 | E6: 5426.0433 | F6: 7850.8758 | G6: 10423.944 | H6: 12809.896 | I6: 14263.068 | J6: 15432.87 | K6: 16620.761
A7: ABC 5 kg | B7: 1950.3941 | C7: 7852.6185 | D7: 17775.857 | E7: 33605.568 | F7: 48407.572 | G7: 64323.043 | H7: 78721.1 | I7: 87237.212 | J7: 94103.668 | K7: 101095.18
A8: ABC 10 kg | B8: 118.34363 | C8: 437.71658 | D8: 1024.9748 | E8: 1960.4099 | F8: 2844.9768 | G8: 3810.3906 | H8: 4663.6781 | I8: 5164.5146 | J8: 5571.5443 | K8: 5985.9509
A9: Agua 10 l | B9: 159.30874 | C9: 643.42354 | D9: 1474.3627 | E9: 2766.4512 | F9: 3991.4652 | G9: 5335.7558 | H9: 6538.9589 | I9: 7269.8197 | J9: 7855.4414 | K9: 8450.8141
A10: AFFF 10 l | B10: 22.758391 | C10: 161.31575 | D10: 316.60728 | E10: 527.39462 | F10: 743.78895 | G10: 962.87433 | H10: 1194.9422 | I10: 1351.6172 | J10: 1477.5489 | K10: 1604.4414
A11: AFFF 50 l s/ruedas | B11: 11.379195 | C11: 83.22352 | D11: 164.46383 | E11: 281.34114 | F11: 398.90251 | G11: 514.52728 | H11: 629.06551 | I11: 711.17802 | J11: 773.41098 | K11: 836.35081
A12: BC 5 kg | B12: 6.827517 | C12: 47.073112 | D12: 88.889676 | E12: 159.50249 | F12: 219.7962 | G12: 291.86985 | H12: 368.84417 | I12: 408.40895 | J12: 445.78194 | K12: 483.4792
A13: Sales K 6 l | B13: 81.930207 | C13: 335.39886 | D13: 746.59835 | E13: 1358.8998 | F13: 1961.1255 | G13: 2598.5414 | H13: 3197.2635 | I13: 3578.5395 | J13: 3870.748 | K13: 4167.5596
A14: CO₂ 2 kg | B14: 450.61614 | C14: 1697.1815 | D14: 3955.1969 | E14: 7561.2603 | F14: 10920.145 | G14: 14514.885 | H14: 17746.499 | I14: 19617.205 | J14: 21161.806 | K14: 22734.502
A15: CO₂ 5 kg | B15: 125.17115 | C15: 643.63037 | D15: 1375.6267 | E15: 2460.2843 | F15: 3545.2577 | G15: 4723.4618 | H15: 5853.9052 | I15: 6608.4599 | J15: 7185.7084 | K15: 7769.5771
... A21: ABC 100 kg s/ruedas | B21: 5.644081 | C21: 27.516102 | D21: 59.798262 | E21: 107.70676 | F21: 154.92243 | G21: 205.83052 | H21: 253.57816 | I21: 284.69687 | J21: 308.89956 | K21: 333.4207
A22: Recargas total | B22: =SUM(B5:B21) -> 6829.7931 | C22: =SUM(C5:C21) -> 30662.681 | D22: =SUM(D5:D21) -> 61483.058 | E22: =SUM(E5:E21) -> 114050.8 | F22: =SUM(F5:F21) -> 167870.4 | G22: =SUM(G5:G21) -> 228490.11 | H22: =SUM(H5:H21) -> 283777.78 | I22: =SUM(I5:I21) -> 322612.24 | ... K22: =SUM(K5:K21) -> 371907.69
A24: Recargas por zona y planta (% zonal 2035, columna U; planta según V61 y V63)
A25: Zona | B25: % zonal 2035 | C25: Planta
A26: CABA Norte | B26: 0.05217974 | C26: Comercial
A27: CABA Este | B27: 0.079883616 | C27: Comercial
A28: CABA Sur | B28: 0.059817286 | C28: Industrial
A29: CABA Oeste | B29: 0.063765071 | C29: Comercial
A30: PBA Sur 1er (Avellaneda) | B30: 0.067680145 | C30: Industrial
A31: PBA Sur 2do cordón | B31: 0.093217299 | C31: Industrial
A32: PBA Sur 3er cordón | B32: 0.067521776 | C32: Industrial
A33: PBA Norte 1er cordón | B33: 0.053355883 | C33: Comercial
A34: PBA Norte 2do cordón | B34: 0.088568205 | C34: Comercial
A35: PBA Norte 3er cordón | B35: 0.047136111 | C35: Comercial
A36: PBA Oeste 1er cordón | B36: 0.084890066 | C36: Comercial
A37: PBA Oeste 2do cordón | B37: 0.067264302 | C37: Comercial
... A39: PBA Interior | B39: 0.15724376 | C39: Comercial
A41: % planta comercial | B41: =SUMIF($C$26:$C$39,"Comercial",$B$26:$B$39) -> 0.71176349
A42: % planta industrial | B42: =SUMIF($C$26:$C$39,"Industrial",$B$26:$B$39) -> 0.28823651
A43: Control (tiene que dar 100 %) | B43: =B41+B42 -> 1
A45: Tasas de Proyecciones (hojas PROYECCION por rubro; iguales para todos los tipos)
A46: Concepto | B46: Valor | C46: Uso en este archivo
A47: Mat Usados ÷ RECARGAS An | B47: 0.05 | C47: Se usa: equipos que llegan descargados por uso
A48: Mat PH ÷ RECARGAS An | B48: 0.02 | C48: Se usa: equipos que no pasan la PH y se inutilizan
A49: Mat Rot ÷ RECARGAS An | B49: 0.01 | C49: Se usa: equipos rotos que se inutilizan
A50: Mat Fin VU ÷ RECARGAS An | B50: 0.033020413 | C50: No se usa: Proyecciones aplica la misma vida útil a todos los tipos; acá va la del Anexo E (20 años, CO₂ 30)
...

Sheet datos_base
A1: Tipo de matafuego | B1: =PROY_Indexado!B4 -> 2026 | C1: =PROY_Indexado!C4 -> 2027 | D1: =PROY_Indexado!D4 -> 2028 | E1: =PROY_Indexado!E4 -> 2029 | F1: =PROY_Indexado!F4 -> 2030 | G1: =PROY_Indexado!G4 -> 2031 | H1: =PROY_Indexado!H4 -> 2032 | I1: =PROY_Indexado!I4 -> 2033 | ... K1: =PROY_Indexado!K4 -> 2035
A2: =PROY_Indexado!A5 -> ABC 1 kg | B2: =PROY_Indexado!B5*PROY_Indexado!$B$53 -> 2475.1448 | C2: =PROY_Indexado!C5*PROY_Indexado!$B$53 -> 12079.043 | D2: =PROY_Indexado!D5*PROY_Indexado!$B$53 -> 21741.591 | E2: =PROY_Indexado!E5*PROY_Indexado!$B$53 -> 39893.142 | F2: =PROY_Indexado!F5*PROY_Indexado!$B$53 -> 59980.471 | G2: =PROY_Indexado!G5*PROY_Indexado!$B$53 -> 83566.602 | H2: =PROY_Indexado!H5*PROY_Indexado!$B$53 -> 105063.86 | I2: =PROY_Indexado!I5*PROY_Indexado!$B$53 -> 121999.37 | ... K2: =PROY_Indexado!K5*PROY_Indexado!$B$53 -> 139706.85
A3: =PROY_Indexado!A6 -> ABC 2,5 kg | B3: =PROY_Indexado!B6*PROY_Indexado!$B$53 -> 234.87958 | C3: =PROY_Indexado!C6*PROY_Indexado!$B$53 -> 916.3343 | D3: =PROY_Indexado!D6*PROY_Indexado!$B$53 -> 2097.6875 | E3: =PROY_Indexado!E6*PROY_Indexado!$B$53 -> 3862.0595 | F3: =PROY_Indexado!F6*PROY_Indexado!$B$53 -> 5587.9668 | G3: =PROY_Indexado!G6*PROY_Indexado!$B$53 -> 7419.3826 | H3: =PROY_Indexado!H6*PROY_Indexado!$B$53 -> 9117.6161 | I3: =PROY_Indexado!I6*PROY_Indexado!$B$53 -> 10151.931 | ... K3: =PROY_Indexado!K6*PROY_Indexado!$B$53 -> 11830.051
A4: =PROY_Indexado!A7 -> ABC 5 kg | B4: =PROY_Indexado!B7*PROY_Indexado!$B$53 -> 1388.2193 | C4: =PROY_Indexado!C7*PROY_Indexado!$B$53 -> 5589.2072 | D4: =PROY_Indexado!D7*PROY_Indexado!$B$53 -> 12652.206 | E4: =PROY_Indexado!E7*PROY_Indexado!$B$53 -> 23919.217 | F4: =PROY_Indexado!F7*PROY_Indexado!$B$53 -> 34454.743 | G4: =PROY_Indexado!G7*PROY_Indexado!$B$53 -> 45782.794 | H4: =PROY_Indexado!H7*PROY_Indexado!$B$53 -> 56030.805 | I4: =PROY_Indexado!I7*PROY_Indexado!$B$53 -> 62092.263 | ... K4: =PROY_Indexado!K7*PROY_Indexado!$B$53 -> 71955.856
A5: =PROY_Indexado!A8 -> ABC 10 kg | B5: =PROY_Indexado!B8*PROY_Indexado!$B$53 -> 84.232677 | C5: =PROY_Indexado!C8*PROY_Indexado!$B$53 -> 311.55068 | D5: =PROY_Indexado!D8*PROY_Indexado!$B$53 -> 729.53966 | E5: =PROY_Indexado!E8*PROY_Indexado!$B$53 -> 1395.3482 | F5: =PROY_Indexado!F8*PROY_Indexado!$B$53 -> 2024.9507 | G5: =PROY_Indexado!G8*PROY_Indexado!$B$53 -> 2712.0969 | H5: =PROY_Indexado!H8*PROY_Indexado!$B$53 -> 3319.4358 | I5: =PROY_Indexado!I8*PROY_Indexado!$B$53 -> 3675.9129 | ... K5: =PROY_Indexado!K8*PROY_Indexado!$B$53 -> 4260.5813
A6: =PROY_Indexado!A9 -> Agua 10 l | B6: =PROY_Indexado!B9*PROY_Indexado!$B$53 -> 113.39014 | C6: =PROY_Indexado!C9*PROY_Indexado!$B$53 -> 457.96539 | D6: =PROY_Indexado!D9*PROY_Indexado!$B$53 -> 1049.3976 | E6: =PROY_Indexado!E9*PROY_Indexado!$B$53 -> 1969.059 | F6: =PROY_Indexado!F9*PROY_Indexado!$B$53 -> 2840.9792 | G6: =PROY_Indexado!G9*PROY_Indexado!$B$53 -> 3797.7962 | H6: =PROY_Indexado!H9*PROY_Indexado!$B$53 -> 4654.1922 | I6: =PROY_Indexado!I9*PROY_Indexado!$B$53 -> 5174.3923 | ... K6: =PROY_Indexado!K9*PROY_Indexado!$B$53 -> 6014.981
A7: =PROY_Indexado!A10 -> AFFF 10 l | B7: =PROY_Indexado!B10*PROY_Indexado!$B$53 -> 16.198592 | C7: =PROY_Indexado!C10*PROY_Indexado!$B$53 -> 114.81866 | D7: =PROY_Indexado!D10*PROY_Indexado!$B$53 -> 225.3495 | E7: =PROY_Indexado!E10*PROY_Indexado!$B$53 -> 375.38024 | F7: =PROY_Indexado!F10*PROY_Indexado!$B$53 -> 529.40182 | G7: =PROY_Indexado!G10*PROY_Indexado!$B$53 -> 685.3388 | H7: =PROY_Indexado!H10*PROY_Indexado!$B$53 -> 850.51624 | I7: =PROY_Indexado!I10*PROY_Indexado!$B$53 -> 962.03177 | ... K7: =PROY_Indexado!K10*PROY_Indexado!$B$53 -> 1141.9828
A8: =PROY_Indexado!A11 -> AFFF 50 l s/ruedas | B8: =PROY_Indexado!B11*PROY_Indexado!$B$53 -> 8.0992956 | C8: =PROY_Indexado!C11*PROY_Indexado!$B$53 -> 59.235463 | D8: =PROY_Indexado!D11*PROY_Indexado!$B$53 -> 117.05935 | E8: =PROY_Indexado!E11*PROY_Indexado!$B$53 -> 200.24836 | F8: =PROY_Indexado!F11*PROY_Indexado!$B$53 -> 283.92424 | G8: =PROY_Indexado!G11*PROY_Indexado!$B$53 -> 366.22174 | H8: =PROY_Indexado!H11*PROY_Indexado!$B$53 -> 447.74586 | I8: =PROY_Indexado!I11*PROY_Indexado!$B$53 -> 506.19056 | ... K8: =PROY_Indexado!K11*PROY_Indexado!$B$53 -> 595.28397
A9: =PROY_Indexado!A12 -> BC 5 kg | B9: =PROY_Indexado!B12*PROY_Indexado!$B$53 -> 4.8595774 | C9: =PROY_Indexado!C12*PROY_Indexado!$B$53 -> 33.504923 | D9: =PROY_Indexado!D12*PROY_Indexado!$B$53 -> 63.268426 | E9: =PROY_Indexado!E12*PROY_Indexado!$B$53 -> 113.52805 | F9: =PROY_Indexado!F12*PROY_Indexado!$B$53 -> 156.44291 | G9: =PROY_Indexado!G12*PROY_Indexado!$B$53 -> 207.74231 | H9: =PROY_Indexado!H12*PROY_Indexado!$B$53 -> 262.52981 | I9: =PROY_Indexado!I12*PROY_Indexado!$B$53 -> 290.69058 | ... K9: =PROY_Indexado!K12*PROY_Indexado!$B$53 -> 344.12285
A10: =PROY_Indexado!A13 -> Sales K 6 l | B10: =PROY_Indexado!B13*PROY_Indexado!$B$53 -> 58.31493 | C10: =PROY_Indexado!C13*PROY_Indexado!$B$53 -> 238.72466 | D10: =PROY_Indexado!D13*PROY_Indexado!$B$53 -> 531.40145 | E10: =PROY_Indexado!E13*PROY_Indexado!$B$53 -> 967.2153 | F10: =PROY_Indexado!F13*PROY_Indexado!$B$53 -> 1395.8576 | G10: =PROY_Indexado!G13*PROY_Indexado!$B$53 -> 1849.5469 | H10: =PROY_Indexado!H13*PROY_Indexado!$B$53 -> 2275.6954 | I10: =PROY_Indexado!I13*PROY_Indexado!$B$53 -> 2547.0737 | ... K10: =PROY_Indexado!K13*PROY_Indexado!$B$53 -> 2966.3168
A11: =PROY_Indexado!A14 -> CO₂ 2 kg | B11: =PROY_Indexado!B14*PROY_Indexado!$B$53 -> 320.73212 | C11: =PROY_Indexado!C14*PROY_Indexado!$B$53 -> 1207.9918 | D11: =PROY_Indexado!D14*PROY_Indexado!$B$53 -> 2815.1647 | E11: =PROY_Indexado!E14*PROY_Indexado!$B$53 -> 5381.8291 | F11: =PROY_Indexado!F14*PROY_Indexado!$B$53 -> 7772.5604 | G11: =PROY_Indexado!G14*PROY_Indexado!$B$53 -> 10331.165 | H11: =PROY_Indexado!H14*PROY_Indexado!$B$53 -> 12631.31 | I11: =PROY_Indexado!I14*PROY_Indexado!$B$53 -> 13962.811 | ... K11: =PROY_Indexado!K14*PROY_Indexado!$B$53 -> 16181.588
A12: =PROY_Indexado!A15 -> CO₂ 5 kg | B12: =PROY_Indexado!B15*PROY_Indexado!$B$53 -> 89.092255 | C12: =PROY_Indexado!C15*PROY_Indexado!$B$53 -> 458.1126 | D12: =PROY_Indexado!D15*PROY_Indexado!$B$53 -> 979.12088 | E12: =PROY_Indexado!E15*PROY_Indexado!$B$53 -> 1751.1405 | F12: =PROY_Indexado!F15*PROY_Indexado!$B$53 -> 2523.385 | G12: =PROY_Indexado!G15*PROY_Indexado!$B$53 -> 3361.9877 | H12: =PROY_Indexado!H15*PROY_Indexado!$B$53 -> 4166.596 | I12: =PROY_Indexado!I15*PROY_Indexado!$B$53 -> 4703.6605 | ... K12: =PROY_Indexado!K15*PROY_Indexado!$B$53 -> 5530.1014
A13: =PROY_Indexado!A16 -> HCFC/HFC 5 kg | B13: =PROY_Indexado!B16*PROY_Indexado!$B$53 -> 12.958874 | C13: =PROY_Indexado!C16*PROY_Indexado!$B$53 -> 79.77098 | D13: =PROY_Indexado!D16*PROY_Indexado!$B$53 -> 164.31348 | E13: =PROY_Indexado!E16*PROY_Indexado!$B$53 -> 285.21455 | F13: =PROY_Indexado!F16*PROY_Indexado!$B$53 -> 408.91367 | G13: =PROY_Indexado!G16*PROY_Indexado!$B$53 -> 536.91568 | H13: =PROY_Indexado!H16*PROY_Indexado!$B$53 -> 672.50891 | I13: =PROY_Indexado!I16*PROY_Indexado!$B$53 -> 763.1775 | ... K13: =PROY_Indexado!K16*PROY_Indexado!$B$53 -> 905.32124
... A18: =PROY_Indexado!A21 -> ABC 100 kg s/ruedas | B18: =PROY_Indexado!B21*PROY_Indexado!$B$53 -> 4.0172508 | C18: =PROY_Indexado!C21*PROY_Indexado!$B$53 -> 19.584957 | D18: =PROY_Indexado!D21*PROY_Indexado!$B$53 -> 42.56222 | E18: =PROY_Indexado!E21*PROY_Indexado!$B$53 -> 76.661739 | F18: =PROY_Indexado!F21*PROY_Indexado!$B$53 -> 110.26813 | G18: =PROY_Indexado!G21*PROY_Indexado!$B$53 -> 146.50265 | H18: =PROY_Indexado!H21*PROY_Indexado!$B$53 -> 180.48768 | I18: =PROY_Indexado!I21*PROY_Indexado!$B$53 -> 202.63684 | ... K18: =PROY_Indexado!K21*PROY_Indexado!$B$53 -> 237.31669
A19: Recargas Total | B19: =SUM(B2:B18) -> 4861.1974 | C19: =SUM(C2:C18) -> 21824.577 | D19: =SUM(D2:D18) -> 43761.396 | E19: =SUM(E2:E18) -> 81177.193 | F19: =SUM(F2:F18) -> 119484.02 | G19: =SUM(G2:G18) -> 162630.92 | H19: =SUM(H2:H18) -> 201982.67 | I19: =SUM(I2:I18) -> 229623.61 | ... K19: =SUM(K2:K18) -> 264710.32
A21: Recargas de la planta = recargas del Indexado × % de esta planta (PROY_Indexado B53).

Sheet parametros_recargas
A1: Parámetro | B1: Valor | C1: Fuente / criterio
A2: Días hábiles por mes | B2: 20 | C2: 240 días hábiles por año ÷ 12 (dato del usuario)
A3: Horas por día (1 turno) | B3: 8 | C3: Criterio: jornada de 8 h
A4: Refrigerio (min/turno) | B4: 30 | C4: Criterio
A5: Horas productivas por turno | B5: =B3-B4/60 -> 7.5
A6: Horas productivas por mes (1 turno) | B6: =B2*B5 -> 150
A7: Umbral de aprovechamiento | B7: 0.9 | C7: Criterio (Dimensionamiento Técnico V2): 10 % de holgura para variabilidad, averías y mantenimiento
A8: Turnos máximos por día | B8: 2 | C8: Criterio: hasta 2 turnos de 8 h; después se agrega máquina
A9: Equivalencia de un rodante (u. equivalentes) | B9: 3 | C9: Criterio (Dimensionamiento Técnico V2): traslado en carro, morsa y manipuleo del porte
A11: CRITERIOS DE RUTA — PLANTA COMERCIAL (IRAM 3517-2:2020 y Proyecciones)
A12: Parámetro | B12: Valor | C12: Fuente / criterio
A13: Intervalo máximo de PH — polvos, CO₂ y halogenados (años) | B13: 5 | C13: IRAM 3517-2:2020, Anexo E (IRAM 3523, 3550, 3509, 3565 y 3504)
A14: Intervalo máximo de PH — agua, AFFF y sales K (años) | B14: 2 | C14: IRAM 3517-2:2020, Anexo E (IRAM 3525, 3527, 3537, 3541, 3693 y 3694)
A15: % con PH — polvos, CO₂ y halogenados | B15: =1/B13 -> 0.2 | C15: En régimen vence la PH de 1 de cada 5 equipos por año
A16: % con PH — agua, AFFF y sales K | B16: =1/B14 -> 0.5 | C16: En régimen vence la PH de 1 de cada 2 equipos por año
A17: Vida útil — CO₂ (años) | B17: 30 | C17: IRAM 3517-2:2020, Anexo E (IRAM 3509; IRAM 3565 hasta 10 kg)
A18: Vida útil — resto de los tipos (años) | B18: 20 | C18: IRAM 3517-2:2020, Anexo E
A19: % fin de vida útil — CO₂ | B19: =1/B17 -> 0.033333333 | C19: En régimen llega al fin de su vida 1 de cada 30
A20: % fin de vida útil — resto | B20: =1/B18 -> 0.05 | C20: En régimen llega al fin de su vida 1 de cada 20
A21: % que no pasan la PH | B21: =PROY_Indexado!B48 -> 0.02 | C21: Proyecciones (Mat PH). La norma manda inutilizarlos (9.12) pero no fija el %
A22: % rotos | B22: =PROY_Indexado!B49 -> 0.01 | C22: Proyecciones (Mat Rot)
A23: % inutilizados — CO₂ | B23: =B19+B21+B22 -> 0.063333333 | C23: Fin de vida útil + no pasan la PH + rotos
A24: % inutilizados — resto | B24: =B20+B21+B22 -> 0.08 | C24: Fin de vida útil + no pasan la PH + rotos
A25: % que llegan descargados por uso | B25: =PROY_Indexado!B47 -> 0.05 | C25: Proyecciones (Mat Usados). 9.2.2: se recarga después de usarlo; la norma no fija el %
A26: Dígitos posibles del año de fabricación | B26: 10 | C26: 9.9.4 a): se cambia el polvo ABC cuando el último dígito del año de fabricación coincide con el del año del mantenimiento
A27: % ABC con cambio de polvo (a descarte) | B27: =1/B26 -> 0.1 | C27: 1 de cada 10 equipos por año
A28: % agua, AFFF y sales K que se vacían y recargan | B28: 1 | C28: Anexo E: el agente se cambia cada año; 9.9.1.9 (sales K) y 9.9.1.10 (AFFF)
A29: % CO₂ que se abren por daño o cambio de piezas | B29: 0.05 | C29: Criterio sin fuente, a validar con una recargadora. 9.7.1.2: el dañado se examina y va a PH
A30: % que se pintan | B30: 0.1 | C30: Criterio sin fuente. 9.10 pide pintar los deteriorados; no fija %
A31: % polvos con humedad en el desarme (secado extra) | B31: 0.01 | C31: Criterio sin fuente
A32: Ensayos de laboratorio por recipiente de polvo | B32: 0.001 | C32: Criterio. 9.9.3.1: el ensayo se hace cuando hay dudas sobre el polvo
A34: PERFIL MENSUAL POR AÑO (plano, 1/12 por mes)
A35: IRAM 3517-2:2020 9.2.1 (mantenimiento como mínimo anual) y 9.4.14 a) (la etiqueta fija el mes y año del próximo): cada equipo vuelve en su mes y la norma no fija ningún mes del calendario. El crecimiento se toma entre años (Proyecciones es anual).
A36: Año | B36: Ene | C36: Feb | D36: Mar | E36: Abr | F36: May | G36: Jun | H36: Jul | I36: Ago | J36: Sep | K36: Oct | L36: Nov | M36: Dic | N36: Total
A37: 2026 | B37: =1/12 -> 0.083333333 | C37: =1/12 -> 0.083333333 | D37: =1/12 -> 0.083333333 | E37: =1/12 -> 0.083333333 | F37: =1/12 -> 0.083333333 | G37: =1/12 -> 0.083333333 | H37: =1/12 -> 0.083333333 | I37: =1/12 -> 0.083333333 | ... M37: =1/12 -> 0.083333333 | N37: =SUM(B37:M37) -> 1
A38: 2027 | B38: =1/12 -> 0.083333333 | C38: =1/12 -> 0.083333333 | D38: =1/12 -> 0.083333333 | E38: =1/12 -> 0.083333333 | F38: =1/12 -> 0.083333333 | G38: =1/12 -> 0.083333333 | H38: =1/12 -> 0.083333333 | I38: =1/12 -> 0.083333333 | ... M38: =1/12 -> 0.083333333 | N38: =SUM(B38:M38) -> 1
A39: 2028 | B39: =1/12 -> 0.083333333 | C39: =1/12 -> 0.083333333 | D39: =1/12 -> 0.083333333 | E39: =1/12 -> 0.083333333 | F39: =1/12 -> 0.083333333 | G39: =1/12 -> 0.083333333 | H39: =1/12 -> 0.083333333 | I39: =1/12 -> 0.083333333 | ... M39: =1/12 -> 0.083333333 | N39: =SUM(B39:M39) -> 1
A40: 2029 | B40: =1/12 -> 0.083333333 | C40: =1/12 -> 0.083333333 | D40: =1/12 -> 0.083333333 | E40: =1/12 -> 0.083333333 | F40: =1/12 -> 0.083333333 | G40: =1/12 -> 0.083333333 | H40: =1/12 -> 0.083333333 | I40: =1/12 -> 0.083333333 | ... M40: =1/12 -> 0.083333333 | N40: =SUM(B40:M40) -> 1
A41: 2030 | B41: =1/12 -> 0.083333333 | C41: =1/12 -> 0.083333333 | D41: =1/12 -> 0.083333333 | E41: =1/12 -> 0.083333333 | F41: =1/12 -> 0.083333333 | G41: =1/12 -> 0.083333333 | H41: =1/12 -> 0.083333333 | I41: =1/12 -> 0.083333333 | ... M41: =1/12 -> 0.083333333 | N41: =SUM(B41:M41) -> 1
A42: 2031 | B42: =1/12 -> 0.083333333 | C42: =1/12 -> 0.083333333 | D42: =1/12 -> 0.083333333 | E42: =1/12 -> 0.083333333 | F42: =1/12 -> 0.083333333 | G42: =1/12 -> 0.083333333 | H42: =1/12 -> 0.083333333 | I42: =1/12 -> 0.083333333 | ... M42: =1/12 -> 0.083333333 | N42: =SUM(B42:M42) -> 1
...

Sheet Plan mensual
A1: 2026 | B1: Agente | C1: u. equiv. | D1: Ene | E1: Feb | F1: Mar | G1: Abr | H1: May | I1: Jun | J1: Jul | K1: Ago | L1: Sep | M1: Oct | N1: Nov | O1: Dic | P1: Total | Q1: Incluye mant. de sustitutos (u./año)
A2: =parametros_recargas!A51 -> ABC 1 kg | B2: =parametros_recargas!B51 -> ABC | C2: =parametros_recargas!C51 -> 1 | D2: =datos_base!$B$2*parametros_recargas!$B$37+sobrestock_sustitutos!$B$175/12 -> 206.26207 | E2: =datos_base!$B$2*parametros_recargas!$C$37+sobrestock_sustitutos!$B$175/12 -> 206.26207 | F2: =datos_base!$B$2*parametros_recargas!$D$37+sobrestock_sustitutos!$B$175/12 -> 206.26207 | G2: =datos_base!$B$2*parametros_recargas!$E$37+sobrestock_sustitutos!$B$175/12 -> 206.26207 | H2: =datos_base!$B$2*parametros_recargas!$F$37+sobrestock_sustitutos!$B$175/12 -> 206.26207 | I2: =datos_base!$B$2*parametros_recargas!$G$37+sobrestock_sustitutos!$B$175/12 -> 206.26207 | J2: =datos_base!$B$2*parametros_recargas!$H$37+sobrestock_sustitutos!$B$175/12 -> 206.26207 | K2: =datos_base!$B$2*parametros_recargas!$I$37+sobrestock_sustitutos!$B$175/12 -> 206.26207 | L2: =datos_base!$B$2*parametros_recargas!$J$37+sobrestock_sustitutos!$B$175/12 -> 206.26207 | M2: =datos_base!$B$2*parametros_recargas!$K$37+sobrestock_sustitutos!$B$175/12 -> 206.26207 | N2: =datos_base!$B$2*parametros_recargas!$L$37+sobrestock_sustitutos!$B$175/12 -> 206.26207 | O2: =datos_base!$B$2*parametros_recargas!$M$37+sobrestock_sustitutos!$B$175/12 -> 206.26207 | P2: =SUM(D2:O2) -> 2475.1448 | Q2: =sobrestock_sustitutos!$B$175 -> 0
A3: =parametros_recargas!A52 -> ABC 2,5 kg | B3: =parametros_recargas!B52 -> ABC | C3: =parametros_recargas!C52 -> 1 | D3: =datos_base!$B$3*parametros_recargas!$B$37+sobrestock_sustitutos!$B$176/12 -> 19.573298 | E3: =datos_base!$B$3*parametros_recargas!$C$37+sobrestock_sustitutos!$B$176/12 -> 19.573298 | F3: =datos_base!$B$3*parametros_recargas!$D$37+sobrestock_sustitutos!$B$176/12 -> 19.573298 | G3: =datos_base!$B$3*parametros_recargas!$E$37+sobrestock_sustitutos!$B$176/12 -> 19.573298 | H3: =datos_base!$B$3*parametros_recargas!$F$37+sobrestock_sustitutos!$B$176/12 -> 19.573298 | I3: =datos_base!$B$3*parametros_recargas!$G$37+sobrestock_sustitutos!$B$176/12 -> 19.573298 | J3: =datos_base!$B$3*parametros_recargas!$H$37+sobrestock_sustitutos!$B$176/12 -> 19.573298 | K3: =datos_base!$B$3*parametros_recargas!$I$37+sobrestock_sustitutos!$B$176/12 -> 19.573298 | L3: =datos_base!$B$3*parametros_recargas!$J$37+sobrestock_sustitutos!$B$176/12 -> 19.573298 | M3: =datos_base!$B$3*parametros_recargas!$K$37+sobrestock_sustitutos!$B$176/12 -> 19.573298 | N3: =datos_base!$B$3*parametros_recargas!$L$37+sobrestock_sustitutos!$B$176/12 -> 19.573298 | O3: =datos_base!$B$3*parametros_recargas!$M$37+sobrestock_sustitutos!$B$176/12 -> 19.573298 | P3: =SUM(D3:O3) -> 234.87958 | Q3: =sobrestock_sustitutos!$B$176 -> 0
A4: =parametros_recargas!A53 -> ABC 5 kg | B4: =parametros_recargas!B53 -> ABC | C4: =parametros_recargas!C53 -> 1 | D4: =datos_base!$B$4*parametros_recargas!$B$37+sobrestock_sustitutos!$B$177/12 -> 115.68494 | E4: =datos_base!$B$4*parametros_recargas!$C$37+sobrestock_sustitutos!$B$177/12 -> 115.68494 | F4: =datos_base!$B$4*parametros_recargas!$D$37+sobrestock_sustitutos!$B$177/12 -> 115.68494 | G4: =datos_base!$B$4*parametros_recargas!$E$37+sobrestock_sustitutos!$B$177/12 -> 115.68494 | H4: =datos_base!$B$4*parametros_recargas!$F$37+sobrestock_sustitutos!$B$177/12 -> 115.68494 | I4: =datos_base!$B$4*parametros_recargas!$G$37+sobrestock_sustitutos!$B$177/12 -> 115.68494 | J4: =datos_base!$B$4*parametros_recargas!$H$37+sobrestock_sustitutos!$B$177/12 -> 115.68494 | K4: =datos_base!$B$4*parametros_recargas!$I$37+sobrestock_sustitutos!$B$177/12 -> 115.68494 | L4: =datos_base!$B$4*parametros_recargas!$J$37+sobrestock_sustitutos!$B$177/12 -> 115.68494 | M4: =datos_base!$B$4*parametros_recargas!$K$37+sobrestock_sustitutos!$B$177/12 -> 115.68494 | N4: =datos_base!$B$4*parametros_recargas!$L$37+sobrestock_sustitutos!$B$177/12 -> 115.68494 | O4: =datos_base!$B$4*parametros_recargas!$M$37+sobrestock_sustitutos!$B$177/12 -> 115.68494 | P4: =SUM(D4:O4) -> 1388.2193 | Q4: =sobrestock_sustitutos!$B$177 -> 0
A5: =parametros_recargas!A54 -> ABC 10 kg | B5: =parametros_recargas!B54 -> ABC | C5: =parametros_recargas!C54 -> 1 | D5: =datos_base!$B$5*parametros_recargas!$B$37+sobrestock_sustitutos!$B$178/12 -> 7.0193898 | E5: =datos_base!$B$5*parametros_recargas!$C$37+sobrestock_sustitutos!$B$178/12 -> 7.0193898 | F5: =datos_base!$B$5*parametros_recargas!$D$37+sobrestock_sustitutos!$B$178/12 -> 7.0193898 | G5: =datos_base!$B$5*parametros_recargas!$E$37+sobrestock_sustitutos!$B$178/12 -> 7.0193898 | H5: =datos_base!$B$5*parametros_recargas!$F$37+sobrestock_sustitutos!$B$178/12 -> 7.0193898 | I5: =datos_base!$B$5*parametros_recargas!$G$37+sobrestock_sustitutos!$B$178/12 -> 7.0193898 | J5: =datos_base!$B$5*parametros_recargas!$H$37+sobrestock_sustitutos!$B$178/12 -> 7.0193898 | K5: =datos_base!$B$5*parametros_recargas!$I$37+sobrestock_sustitutos!$B$178/12 -> 7.0193898 | L5: =datos_base!$B$5*parametros_recargas!$J$37+sobrestock_sustitutos!$B$178/12 -> 7.0193898 | M5: =datos_base!$B$5*parametros_recargas!$K$37+sobrestock_sustitutos!$B$178/12 -> 7.0193898 | N5: =datos_base!$B$5*parametros_recargas!$L$37+sobrestock_sustitutos!$B$178/12 -> 7.0193898 | O5: =datos_base!$B$5*parametros_recargas!$M$37+sobrestock_sustitutos!$B$178/12 -> 7.0193898 | P5: =SUM(D5:O5) -> 84.232677 | Q5: =sobrestock_sustitutos!$B$178 -> 0
A6: =parametros_recargas!A55 -> Agua 10 l | B6: =parametros_recargas!B55 -> Agua | C6: =parametros_recargas!C55 -> 1 | D6: =datos_base!$B$6*parametros_recargas!$B$37+sobrestock_sustitutos!$B$179/12 -> 9.4491786 | E6: =datos_base!$B$6*parametros_recargas!$C$37+sobrestock_sustitutos!$B$179/12 -> 9.4491786 | F6: =datos_base!$B$6*parametros_recargas!$D$37+sobrestock_sustitutos!$B$179/12 -> 9.4491786 | G6: =datos_base!$B$6*parametros_recargas!$E$37+sobrestock_sustitutos!$B$179/12 -> 9.4491786 | H6: =datos_base!$B$6*parametros_recargas!$F$37+sobrestock_sustitutos!$B$179/12 -> 9.4491786 | I6: =datos_base!$B$6*parametros_recargas!$G$37+sobrestock_sustitutos!$B$179/12 -> 9.4491786 | J6: =datos_base!$B$6*parametros_recargas!$H$37+sobrestock_sustitutos!$B$179/12 -> 9.4491786 | K6: =datos_base!$B$6*parametros_recargas!$I$37+sobrestock_sustitutos!$B$179/12 -> 9.4491786 | L6: =datos_base!$B$6*parametros_recargas!$J$37+sobrestock_sustitutos!$B$179/12 -> 9.4491786 | M6: =datos_base!$B$6*parametros_recargas!$K$37+sobrestock_sustitutos!$B$179/12 -> 9.4491786 | N6: =datos_base!$B$6*parametros_recargas!$L$37+sobrestock_sustitutos!$B$179/12 -> 9.4491786 | O6: =datos_base!$B$6*parametros_recargas!$M$37+sobrestock_sustitutos!$B$179/12 -> 9.4491786 | P6: =SUM(D6:O6) -> 113.39014 | Q6: =sobrestock_sustitutos!$B$179 -> 0
A7: =parametros_recargas!A56 -> AFFF 10 l | B7: =parametros_recargas!B56 -> AFFF | C7: =parametros_recargas!C56 -> 1 | D7: =datos_base!$B$7*parametros_recargas!$B$37+sobrestock_sustitutos!$B$180/12 -> 1.3498827 | E7: =datos_base!$B$7*parametros_recargas!$C$37+sobrestock_sustitutos!$B$180/12 -> 1.3498827 | F7: =datos_base!$B$7*parametros_recargas!$D$37+sobrestock_sustitutos!$B$180/12 -> 1.3498827 | G7: =datos_base!$B$7*parametros_recargas!$E$37+sobrestock_sustitutos!$B$180/12 -> 1.3498827 | H7: =datos_base!$B$7*parametros_recargas!$F$37+sobrestock_sustitutos!$B$180/12 -> 1.3498827 | I7: =datos_base!$B$7*parametros_recargas!$G$37+sobrestock_sustitutos!$B$180/12 -> 1.3498827 | J7: =datos_base!$B$7*parametros_recargas!$H$37+sobrestock_sustitutos!$B$180/12 -> 1.3498827 | K7: =datos_base!$B$7*parametros_recargas!$I$37+sobrestock_sustitutos!$B$180/12 -> 1.3498827 | L7: =datos_base!$B$7*parametros_recargas!$J$37+sobrestock_sustitutos!$B$180/12 -> 1.3498827 | M7: =datos_base!$B$7*parametros_recargas!$K$37+sobrestock_sustitutos!$B$180/12 -> 1.3498827 | N7: =datos_base!$B$7*parametros_recargas!$L$37+sobrestock_sustitutos!$B$180/12 -> 1.3498827 | O7: =datos_base!$B$7*parametros_recargas!$M$37+sobrestock_sustitutos!$B$180/12 -> 1.3498827 | P7: =SUM(D7:O7) -> 16.198592 | Q7: =sobrestock_sustitutos!$B$180 -> 0
A8: =parametros_recargas!A57 -> AFFF 50 l s/ruedas | B8: =parametros_recargas!B57 -> AFFF | C8: =parametros_recargas!C57 -> 3 | D8: =datos_base!$B$8*parametros_recargas!$B$37+sobrestock_sustitutos!$B$181/12 -> 0.6749413 | E8: =datos_base!$B$8*parametros_recargas!$C$37+sobrestock_sustitutos!$B$181/12 -> 0.6749413 | F8: =datos_base!$B$8*parametros_recargas!$D$37+sobrestock_sustitutos!$B$181/12 -> 0.6749413 | G8: =datos_base!$B$8*parametros_recargas!$E$37+sobrestock_sustitutos!$B$181/12 -> 0.6749413 | H8: =datos_base!$B$8*parametros_recargas!$F$37+sobrestock_sustitutos!$B$181/12 -> 0.6749413 | I8: =datos_base!$B$8*parametros_recargas!$G$37+sobrestock_sustitutos!$B$181/12 -> 0.6749413 | J8: =datos_base!$B$8*parametros_recargas!$H$37+sobrestock_sustitutos!$B$181/12 -> 0.6749413 | K8: =datos_base!$B$8*parametros_recargas!$I$37+sobrestock_sustitutos!$B$181/12 -> 0.6749413 | L8: =datos_base!$B$8*parametros_recargas!$J$37+sobrestock_sustitutos!$B$181/12 -> 0.6749413 | M8: =datos_base!$B$8*parametros_recargas!$K$37+sobrestock_sustitutos!$B$181/12 -> 0.6749413 | N8: =datos_base!$B$8*parametros_recargas!$L$37+sobrestock_sustitutos!$B$181/12 -> 0.6749413 | O8: =datos_base!$B$8*parametros_recargas!$M$37+sobrestock_sustitutos!$B$181/12 -> 0.6749413 | P8: =SUM(D8:O8) -> 8.0992956 | Q8: =sobrestock_sustitutos!$B$181 -> 0
A9: =parametros_recargas!A58 -> BC 5 kg | B9: =parametros_recargas!B58 -> BC | C9: =parametros_recargas!C58 -> 1 | D9: =datos_base!$B$9*parametros_recargas!$B$37+sobrestock_sustitutos!$B$182/12 -> 0.40496478 | E9: =datos_base!$B$9*parametros_recargas!$C$37+sobrestock_sustitutos!$B$182/12 -> 0.40496478 | F9: =datos_base!$B$9*parametros_recargas!$D$37+sobrestock_sustitutos!$B$182/12 -> 0.40496478 | G9: =datos_base!$B$9*parametros_recargas!$E$37+sobrestock_sustitutos!$B$182/12 -> 0.40496478 | H9: =datos_base!$B$9*parametros_recargas!$F$37+sobrestock_sustitutos!$B$182/12 -> 0.40496478 | I9: =datos_base!$B$9*parametros_recargas!$G$37+sobrestock_sustitutos!$B$182/12 -> 0.40496478 | J9: =datos_base!$B$9*parametros_recargas!$H$37+sobrestock_sustitutos!$B$182/12 -> 0.40496478 | K9: =datos_base!$B$9*parametros_recargas!$I$37+sobrestock_sustitutos!$B$182/12 -> 0.40496478 | L9: =datos_base!$B$9*parametros_recargas!$J$37+sobrestock_sustitutos!$B$182/12 -> 0.40496478 | M9: =datos_base!$B$9*parametros_recargas!$K$37+sobrestock_sustitutos!$B$182/12 -> 0.40496478 | N9: =datos_base!$B$9*parametros_recargas!$L$37+sobrestock_sustitutos!$B$182/12 -> 0.40496478 | O9: =datos_base!$B$9*parametros_recargas!$M$37+sobrestock_sustitutos!$B$182/12 -> 0.40496478 | P9: =SUM(D9:O9) -> 4.8595774 | Q9: =sobrestock_sustitutos!$B$182 -> 0
A10: =parametros_recargas!A59 -> Sales K 6 l | B10: =parametros_recargas!B59 -> Sales K | C10: =parametros_recargas!C59 -> 1 | D10: =datos_base!$B$10*parametros_recargas!$B$37+sobrestock_sustitutos!$B$183/12 -> 4.8595775 | E10: =datos_base!$B$10*parametros_recargas!$C$37+sobrestock_sustitutos!$B$183/12 -> 4.8595775 | F10: =datos_base!$B$10*parametros_recargas!$D$37+sobrestock_sustitutos!$B$183/12 -> 4.8595775 | G10: =datos_base!$B$10*parametros_recargas!$E$37+sobrestock_sustitutos!$B$183/12 -> 4.8595775 | H10: =datos_base!$B$10*parametros_recargas!$F$37+sobrestock_sustitutos!$B$183/12 -> 4.8595775 | I10: =datos_base!$B$10*parametros_recargas!$G$37+sobrestock_sustitutos!$B$183/12 -> 4.8595775 | J10: =datos_base!$B$10*parametros_recargas!$H$37+sobrestock_sustitutos!$B$183/12 -> 4.8595775 | K10: =datos_base!$B$10*parametros_recargas!$I$37+sobrestock_sustitutos!$B$183/12 -> 4.8595775 | L10: =datos_base!$B$10*parametros_recargas!$J$37+sobrestock_sustitutos!$B$183/12 -> 4.8595775 | M10: =datos_base!$B$10*parametros_recargas!$K$37+sobrestock_sustitutos!$B$183/12 -> 4.8595775 | N10: =datos_base!$B$10*parametros_recargas!$L$37+sobrestock_sustitutos!$B$183/12 -> 4.8595775 | O10: =datos_base!$B$10*parametros_recargas!$M$37+sobrestock_sustitutos!$B$183/12 -> 4.8595775 | P10: =SUM(D10:O10) -> 58.31493 | Q10: =sobrestock_sustitutos!$B$183 -> 0
A11: =parametros_recargas!A60 -> CO₂ 2 kg | B11: =parametros_recargas!B60 -> CO₂ | C11: =parametros_recargas!C60 -> 1 | D11: =datos_base!$B$11*parametros_recargas!$B$37+sobrestock_sustitutos!$B$184/12 -> 26.727676 | E11: =datos_base!$B$11*parametros_recargas!$C$37+sobrestock_sustitutos!$B$184/12 -> 26.727676 | F11: =datos_base!$B$11*parametros_recargas!$D$37+sobrestock_sustitutos!$B$184/12 -> 26.727676 | G11: =datos_base!$B$11*parametros_recargas!$E$37+sobrestock_sustitutos!$B$184/12 -> 26.727676 | H11: =datos_base!$B$11*parametros_recargas!$F$37+sobrestock_sustitutos!$B$184/12 -> 26.727676 | I11: =datos_base!$B$11*parametros_recargas!$G$37+sobrestock_sustitutos!$B$184/12 -> 26.727676 | J11: =datos_base!$B$11*parametros_recargas!$H$37+sobrestock_sustitutos!$B$184/12 -> 26.727676 | K11: =datos_base!$B$11*parametros_recargas!$I$37+sobrestock_sustitutos!$B$184/12 -> 26.727676 | L11: =datos_base!$B$11*parametros_recargas!$J$37+sobrestock_sustitutos!$B$184/12 -> 26.727676 | M11: =datos_base!$B$11*parametros_recargas!$K$37+sobrestock_sustitutos!$B$184/12 -> 26.727676 | N11: =datos_base!$B$11*parametros_recargas!$L$37+sobrestock_sustitutos!$B$184/12 -> 26.727676 | O11: =datos_base!$B$11*parametros_recargas!$M$37+sobrestock_sustitutos!$B$184/12 -> 26.727676 | P11: =SUM(D11:O11) -> 320.73212 | Q11: =sobrestock_sustitutos!$B$184 -> 0
A12: =parametros_recargas!A61 -> CO₂ 5 kg | B12: =parametros_recargas!B61 -> CO₂ | C12: =parametros_recargas!C61 -> 1 | D12: =datos_base!$B$12*parametros_recargas!$B$37+sobrestock_sustitutos!$B$185/12 -> 7.4243546 | E12: =datos_base!$B$12*parametros_recargas!$C$37+sobrestock_sustitutos!$B$185/12 -> 7.4243546 | F12: =datos_base!$B$12*parametros_recargas!$D$37+sobrestock_sustitutos!$B$185/12 -> 7.4243546 | G12: =datos_base!$B$12*parametros_recargas!$E$37+sobrestock_sustitutos!$B$185/12 -> 7.4243546 | H12: =datos_base!$B$12*parametros_recargas!$F$37+sobrestock_sustitutos!$B$185/12 -> 7.4243546 | I12: =datos_base!$B$12*parametros_recargas!$G$37+sobrestock_sustitutos!$B$185/12 -> 7.4243546 | J12: =datos_base!$B$12*parametros_recargas!$H$37+sobrestock_sustitutos!$B$185/12 -> 7.4243546 | K12: =datos_base!$B$12*parametros_recargas!$I$37+sobrestock_sustitutos!$B$185/12 -> 7.4243546 | L12: =datos_base!$B$12*parametros_recargas!$J$37+sobrestock_sustitutos!$B$185/12 -> 7.4243546 | M12: =datos_base!$B$12*parametros_recargas!$K$37+sobrestock_sustitutos!$B$185/12 -> 7.4243546 | N12: =datos_base!$B$12*parametros_recargas!$L$37+sobrestock_sustitutos!$B$185/12 -> 7.4243546 | O12: =datos_base!$B$12*parametros_recargas!$M$37+sobrestock_sustitutos!$B$185/12 -> 7.4243546 | P12: =SUM(D12:O12) -> 89.092255 | Q12: =sobrestock_sustitutos!$B$185 -> 0
A13: =parametros_recargas!A62 -> HCFC/HFC 5 kg | B13: =parametros_recargas!B62 -> Halogenado | C13: =parametros_recargas!C62 -> 1 | D13: =datos_base!$B$13*parametros_recargas!$B$37+sobrestock_sustitutos!$B$186/12 -> 1.0799061 | E13: =datos_base!$B$13*parametros_recargas!$C$37+sobrestock_sustitutos!$B$186/12 -> 1.0799061 | F13: =datos_base!$B$13*parametros_recargas!$D$37+sobrestock_sustitutos!$B$186/12 -> 1.0799061 | G13: =datos_base!$B$13*parametros_recargas!$E$37+sobrestock_sustitutos!$B$186/12 -> 1.0799061 | H13: =datos_base!$B$13*parametros_recargas!$F$37+sobrestock_sustitutos!$B$186/12 -> 1.0799061 | I13: =datos_base!$B$13*parametros_recargas!$G$37+sobrestock_sustitutos!$B$186/12 -> 1.0799061 | J13: =datos_base!$B$13*parametros_recargas!$H$37+sobrestock_sustitutos!$B$186/12 -> 1.0799061 | K13: =datos_base!$B$13*parametros_recargas!$I$37+sobrestock_sustitutos!$B$186/12 -> 1.0799061 | L13: =datos_base!$B$13*parametros_recargas!$J$37+sobrestock_sustitutos!$B$186/12 -> 1.0799061 | M13: =datos_base!$B$13*parametros_recargas!$K$37+sobrestock_sustitutos!$B$186/12 -> 1.0799061 | N13: =datos_base!$B$13*parametros_recargas!$L$37+sobrestock_sustitutos!$B$186/12 -> 1.0799061 | O13: =datos_base!$B$13*parametros_recargas!$M$37+sobrestock_sustitutos!$B$186/12 -> 1.0799061 | P13: =SUM(D13:O13) -> 12.958874 | Q13: =sobrestock_sustitutos!$B$186 -> 0
A14: =parametros_recargas!A63 -> Clase D 9 l | B14: =parametros_recargas!B63 -> Clase D | C14: =parametros_recargas!C63 -> 1 | D14: =datos_base!$B$14*parametros_recargas!$B$37+sobrestock_sustitutos!$B$187/12 -> 0.40496478 | E14: =datos_base!$B$14*parametros_recargas!$C$37+sobrestock_sustitutos!$B$187/12 -> 0.40496478 | F14: =datos_base!$B$14*parametros_recargas!$D$37+sobrestock_sustitutos!$B$187/12 -> 0.40496478 | G14: =datos_base!$B$14*parametros_recargas!$E$37+sobrestock_sustitutos!$B$187/12 -> 0.40496478 | H14: =datos_base!$B$14*parametros_recargas!$F$37+sobrestock_sustitutos!$B$187/12 -> 0.40496478 | I14: =datos_base!$B$14*parametros_recargas!$G$37+sobrestock_sustitutos!$B$187/12 -> 0.40496478 | J14: =datos_base!$B$14*parametros_recargas!$H$37+sobrestock_sustitutos!$B$187/12 -> 0.40496478 | K14: =datos_base!$B$14*parametros_recargas!$I$37+sobrestock_sustitutos!$B$187/12 -> 0.40496478 | L14: =datos_base!$B$14*parametros_recargas!$J$37+sobrestock_sustitutos!$B$187/12 -> 0.40496478 | M14: =datos_base!$B$14*parametros_recargas!$K$37+sobrestock_sustitutos!$B$187/12 -> 0.40496478 | N14: =datos_base!$B$14*parametros_recargas!$L$37+sobrestock_sustitutos!$B$187/12 -> 0.40496478 | O14: =datos_base!$B$14*parametros_recargas!$M$37+sobrestock_sustitutos!$B$187/12 -> 0.40496478 | P14: =SUM(D14:O14) -> 4.8595774 | Q14: =sobrestock_sustitutos!$B$187 -> 0
A15: =parametros_recargas!A64 -> ABC 25 kg s/ruedas | B15: =parametros_recargas!B64 -> ABC | C15: =parametros_recargas!C64 -> 3 | D15: =datos_base!$B$15*parametros_recargas!$B$37+sobrestock_sustitutos!$B$188/12 -> 1.0461591 | E15: =datos_base!$B$15*parametros_recargas!$C$37+sobrestock_sustitutos!$B$188/12 -> 1.0461591 | F15: =datos_base!$B$15*parametros_recargas!$D$37+sobrestock_sustitutos!$B$188/12 -> 1.0461591 | G15: =datos_base!$B$15*parametros_recargas!$E$37+sobrestock_sustitutos!$B$188/12 -> 1.0461591 | H15: =datos_base!$B$15*parametros_recargas!$F$37+sobrestock_sustitutos!$B$188/12 -> 1.0461591 | I15: =datos_base!$B$15*parametros_recargas!$G$37+sobrestock_sustitutos!$B$188/12 -> 1.0461591 | J15: =datos_base!$B$15*parametros_recargas!$H$37+sobrestock_sustitutos!$B$188/12 -> 1.0461591 | K15: =datos_base!$B$15*parametros_recargas!$I$37+sobrestock_sustitutos!$B$188/12 -> 1.0461591 | L15: =datos_base!$B$15*parametros_recargas!$J$37+sobrestock_sustitutos!$B$188/12 -> 1.0461591 | M15: =datos_base!$B$15*parametros_recargas!$K$37+sobrestock_sustitutos!$B$188/12 -> 1.0461591 | N15: =datos_base!$B$15*parametros_recargas!$L$37+sobrestock_sustitutos!$B$188/12 -> 1.0461591 | O15: =datos_base!$B$15*parametros_recargas!$M$37+sobrestock_sustitutos!$B$188/12 -> 1.0461591 | P15: =SUM(D15:O15) -> 12.553909 | Q15: =sobrestock_sustitutos!$B$188 -> 0
A16: =parametros_recargas!A65 -> ABC 50 kg s/ruedas | B16: =parametros_recargas!B65 -> ABC | C16: =parametros_recargas!C65 -> 3 | D16: =datos_base!$B$16*parametros_recargas!$B$37+sobrestock_sustitutos!$B$189/12 -> 2.3015499 | E16: =datos_base!$B$16*parametros_recargas!$C$37+sobrestock_sustitutos!$B$189/12 -> 2.3015499 | F16: =datos_base!$B$16*parametros_recargas!$D$37+sobrestock_sustitutos!$B$189/12 -> 2.3015499 | G16: =datos_base!$B$16*parametros_recargas!$E$37+sobrestock_sustitutos!$B$189/12 -> 2.3015499 | H16: =datos_base!$B$16*parametros_recargas!$F$37+sobrestock_sustitutos!$B$189/12 -> 2.3015499 | I16: =datos_base!$B$16*parametros_recargas!$G$37+sobrestock_sustitutos!$B$189/12 -> 2.3015499 | J16: =datos_base!$B$16*parametros_recargas!$H$37+sobrestock_sustitutos!$B$189/12 -> 2.3015499 | K16: =datos_base!$B$16*parametros_recargas!$I$37+sobrestock_sustitutos!$B$189/12 -> 2.3015499 | L16: =datos_base!$B$16*parametros_recargas!$J$37+sobrestock_sustitutos!$B$189/12 -> 2.3015499 | M16: =datos_base!$B$16*parametros_recargas!$K$37+sobrestock_sustitutos!$B$189/12 -> 2.3015499 | N16: =datos_base!$B$16*parametros_recargas!$L$37+sobrestock_sustitutos!$B$189/12 -> 2.3015499 | O16: =datos_base!$B$16*parametros_recargas!$M$37+sobrestock_sustitutos!$B$189/12 -> 2.3015499 | P16: =SUM(D16:O16) -> 27.618599 | Q16: =sobrestock_sustitutos!$B$189 -> 0
A17: =parametros_recargas!A66 -> ABC 70 kg s/ruedas | B17: =parametros_recargas!B66 -> ABC | C17: =parametros_recargas!C66 -> 3 | D17: =datos_base!$B$17*parametros_recargas!$B$37+sobrestock_sustitutos!$B$190/12 -> 0.50215632 | E17: =datos_base!$B$17*parametros_recargas!$C$37+sobrestock_sustitutos!$B$190/12 -> 0.50215632 | F17: =datos_base!$B$17*parametros_recargas!$D$37+sobrestock_sustitutos!$B$190/12 -> 0.50215632 | G17: =datos_base!$B$17*parametros_recargas!$E$37+sobrestock_sustitutos!$B$190/12 -> 0.50215632 | H17: =datos_base!$B$17*parametros_recargas!$F$37+sobrestock_sustitutos!$B$190/12 -> 0.50215632 | I17: =datos_base!$B$17*parametros_recargas!$G$37+sobrestock_sustitutos!$B$190/12 -> 0.50215632 | J17: =datos_base!$B$17*parametros_recargas!$H$37+sobrestock_sustitutos!$B$190/12 -> 0.50215632 | K17: =datos_base!$B$17*parametros_recargas!$I$37+sobrestock_sustitutos!$B$190/12 -> 0.50215632 | L17: =datos_base!$B$17*parametros_recargas!$J$37+sobrestock_sustitutos!$B$190/12 -> 0.50215632 | M17: =datos_base!$B$17*parametros_recargas!$K$37+sobrestock_sustitutos!$B$190/12 -> 0.50215632 | N17: =datos_base!$B$17*parametros_recargas!$L$37+sobrestock_sustitutos!$B$190/12 -> 0.50215632 | O17: =datos_base!$B$17*parametros_recargas!$M$37+sobrestock_sustitutos!$B$190/12 -> 0.50215632 | P17: =SUM(D17:O17) -> 6.0258759 | Q17: =sobrestock_sustitutos!$B$190 -> 0
A18: =parametros_recargas!A67 -> ABC 100 kg s/ruedas | B18: =parametros_recargas!B67 -> ABC | C18: =parametros_recargas!C67 -> 3 | D18: =datos_base!$B$18*parametros_recargas!$B$37+sobrestock_sustitutos!$B$191/12 -> 0.3347709 | E18: =datos_base!$B$18*parametros_recargas!$C$37+sobrestock_sustitutos!$B$191/12 -> 0.3347709 | F18: =datos_base!$B$18*parametros_recargas!$D$37+sobrestock_sustitutos!$B$191/12 -> 0.3347709 | G18: =datos_base!$B$18*parametros_recargas!$E$37+sobrestock_sustitutos!$B$191/12 -> 0.3347709 | H18: =datos_base!$B$18*parametros_recargas!$F$37+sobrestock_sustitutos!$B$191/12 -> 0.3347709 | I18: =datos_base!$B$18*parametros_recargas!$G$37+sobrestock_sustitutos!$B$191/12 -> 0.3347709 | J18: =datos_base!$B$18*parametros_recargas!$H$37+sobrestock_sustitutos!$B$191/12 -> 0.3347709 | K18: =datos_base!$B$18*parametros_recargas!$I$37+sobrestock_sustitutos!$B$191/12 -> 0.3347709 | L18: =datos_base!$B$18*parametros_recargas!$J$37+sobrestock_sustitutos!$B$191/12 -> 0.3347709 | M18: =datos_base!$B$18*parametros_recargas!$K$37+sobrestock_sustitutos!$B$191/12 -> 0.3347709 | N18: =datos_base!$B$18*parametros_recargas!$L$37+sobrestock_sustitutos!$B$191/12 -> 0.3347709 | O18: =datos_base!$B$18*parametros_recargas!$M$37+sobrestock_sustitutos!$B$191/12 -> 0.3347709 | P18: =SUM(D18:O18) -> 4.0172508 | Q18: =sobrestock_sustitutos!$B$191 -> 0
A19: Total recipientes | D19: =SUM(D2:D18) -> 405.09978 | E19: =SUM(E2:E18) -> 405.09978 | F19: =SUM(F2:F18) -> 405.09978 | G19: =SUM(G2:G18) -> 405.09978 | H19: =SUM(H2:H18) -> 405.09978 | I19: =SUM(I2:I18) -> 405.09978 | J19: =SUM(J2:J18) -> 405.09978 | K19: =SUM(K2:K18) -> 405.09978 | ... P19: =SUM(P2:P18) -> 4861.1974
A20: Por agente (u. equivalentes)
A21: ABC | D21: =SUMPRODUCT(($B$2:$B$18=$A21)*D$2:D$18*$C$2:$C$18) -> 361.09361 | E21: =SUMPRODUCT(($B$2:$B$18=$A21)*E$2:E$18*$C$2:$C$18) -> 361.09361 | F21: =SUMPRODUCT(($B$2:$B$18=$A21)*F$2:F$18*$C$2:$C$18) -> 361.09361 | G21: =SUMPRODUCT(($B$2:$B$18=$A21)*G$2:G$18*$C$2:$C$18) -> 361.09361 | H21: =SUMPRODUCT(($B$2:$B$18=$A21)*H$2:H$18*$C$2:$C$18) -> 361.09361 | I21: =SUMPRODUCT(($B$2:$B$18=$A21)*I$2:I$18*$C$2:$C$18) -> 361.09361 | J21: =SUMPRODUCT(($B$2:$B$18=$A21)*J$2:J$18*$C$2:$C$18) -> 361.09361 | K21: =SUMPRODUCT(($B$2:$B$18=$A21)*K$2:K$18*$C$2:$C$18) -> 361.09361 | ... P21: =SUMPRODUCT(($B$2:$B$18=$A21)*P$2:P$18*$C$2:$C$18) -> 4333.1233
A22: BC | D22: =SUMPRODUCT(($B$2:$B$18=$A22)*D$2:D$18*$C$2:$C$18) -> 0.40496478 | E22: =SUMPRODUCT(($B$2:$B$18=$A22)*E$2:E$18*$C$2:$C$18) -> 0.40496478 | F22: =SUMPRODUCT(($B$2:$B$18=$A22)*F$2:F$18*$C$2:$C$18) -> 0.40496478 | G22: =SUMPRODUCT(($B$2:$B$18=$A22)*G$2:G$18*$C$2:$C$18) -> 0.40496478 | H22: =SUMPRODUCT(($B$2:$B$18=$A22)*H$2:H$18*$C$2:$C$18) -> 0.40496478 | I22: =SUMPRODUCT(($B$2:$B$18=$A22)*I$2:I$18*$C$2:$C$18) -> 0.40496478 | J22: =SUMPRODUCT(($B$2:$B$18=$A22)*J$2:J$18*$C$2:$C$18) -> 0.40496478 | K22: =SUMPRODUCT(($B$2:$B$18=$A22)*K$2:K$18*$C$2:$C$18) -> 0.40496478 | ... P22: =SUMPRODUCT(($B$2:$B$18=$A22)*P$2:P$18*$C$2:$C$18) -> 4.8595774
A23: Clase D | D23: =SUMPRODUCT(($B$2:$B$18=$A23)*D$2:D$18*$C$2:$C$18) -> 0.40496478 | E23: =SUMPRODUCT(($B$2:$B$18=$A23)*E$2:E$18*$C$2:$C$18) -> 0.40496478 | F23: =SUMPRODUCT(($B$2:$B$18=$A23)*F$2:F$18*$C$2:$C$18) -> 0.40496478 | G23: =SUMPRODUCT(($B$2:$B$18=$A23)*G$2:G$18*$C$2:$C$18) -> 0.40496478 | H23: =SUMPRODUCT(($B$2:$B$18=$A23)*H$2:H$18*$C$2:$C$18) -> 0.40496478 | I23: =SUMPRODUCT(($B$2:$B$18=$A23)*I$2:I$18*$C$2:$C$18) -> 0.40496478 | J23: =SUMPRODUCT(($B$2:$B$18=$A23)*J$2:J$18*$C$2:$C$18) -> 0.40496478 | K23: =SUMPRODUCT(($B$2:$B$18=$A23)*K$2:K$18*$C$2:$C$18) -> 0.40496478 | ... P23: =SUMPRODUCT(($B$2:$B$18=$A23)*P$2:P$18*$C$2:$C$18) -> 4.8595774
A24: Agua | D24: =SUMPRODUCT(($B$2:$B$18=$A24)*D$2:D$18*$C$2:$C$18) -> 9.4491786 | E24: =SUMPRODUCT(($B$2:$B$18=$A24)*E$2:E$18*$C$2:$C$18) -> 9.4491786 | F24: =SUMPRODUCT(($B$2:$B$18=$A24)*F$2:F$18*$C$2:$C$18) -> 9.4491786 | G24: =SUMPRODUCT(($B$2:$B$18=$A24)*G$2:G$18*$C$2:$C$18) -> 9.4491786 | H24: =SUMPRODUCT(($B$2:$B$18=$A24)*H$2:H$18*$C$2:$C$18) -> 9.4491786 | I24: =SUMPRODUCT(($B$2:$B$18=$A24)*I$2:I$18*$C$2:$C$18) -> 9.4491786 | J24: =SUMPRODUCT(($B$2:$B$18=$A24)*J$2:J$18*$C$2:$C$18) -> 9.4491786 | K24: =SUMPRODUCT(($B$2:$B$18=$A24)*K$2:K$18*$C$2:$C$18) -> 9.4491786 | ... P24: =SUMPRODUCT(($B$2:$B$18=$A24)*P$2:P$18*$C$2:$C$18) -> 113.39014
A25: AFFF | D25: =SUMPRODUCT(($B$2:$B$18=$A25)*D$2:D$18*$C$2:$C$18) -> 3.3747066 | E25: =SUMPRODUCT(($B$2:$B$18=$A25)*E$2:E$18*$C$2:$C$18) -> 3.3747066 | F25: =SUMPRODUCT(($B$2:$B$18=$A25)*F$2:F$18*$C$2:$C$18) -> 3.3747066 | G25: =SUMPRODUCT(($B$2:$B$18=$A25)*G$2:G$18*$C$2:$C$18) -> 3.3747066 | H25: =SUMPRODUCT(($B$2:$B$18=$A25)*H$2:H$18*$C$2:$C$18) -> 3.3747066 | I25: =SUMPRODUCT(($B$2:$B$18=$A25)*I$2:I$18*$C$2:$C$18) -> 3.3747066 | J25: =SUMPRODUCT(($B$2:$B$18=$A25)*J$2:J$18*$C$2:$C$18) -> 3.3747066 | K25: =SUMPRODUCT(($B$2:$B$18=$A25)*K$2:K$18*$C$2:$C$18) -> 3.3747066 | ... P25: =SUMPRODUCT(($B$2:$B$18=$A25)*P$2:P$18*$C$2:$C$18) -> 40.496479
A26: Sales K | D26: =SUMPRODUCT(($B$2:$B$18=$A26)*D$2:D$18*$C$2:$C$18) -> 4.8595775 | E26: =SUMPRODUCT(($B$2:$B$18=$A26)*E$2:E$18*$C$2:$C$18) -> 4.8595775 | F26: =SUMPRODUCT(($B$2:$B$18=$A26)*F$2:F$18*$C$2:$C$18) -> 4.8595775 | G26: =SUMPRODUCT(($B$2:$B$18=$A26)*G$2:G$18*$C$2:$C$18) -> 4.8595775 | H26: =SUMPRODUCT(($B$2:$B$18=$A26)*H$2:H$18*$C$2:$C$18) -> 4.8595775 | I26: =SUMPRODUCT(($B$2:$B$18=$A26)*I$2:I$18*$C$2:$C$18) -> 4.8595775 | J26: =SUMPRODUCT(($B$2:$B$18=$A26)*J$2:J$18*$C$2:$C$18) -> 4.8595775 | K26: =SUMPRODUCT(($B$2:$B$18=$A26)*K$2:K$18*$C$2:$C$18) -> 4.8595775 | ... P26: =SUMPRODUCT(($B$2:$B$18=$A26)*P$2:P$18*$C$2:$C$18) -> 58.31493
A27: CO₂ | D27: =SUMPRODUCT(($B$2:$B$18=$A27)*D$2:D$18*$C$2:$C$18) -> 34.152031 | E27: =SUMPRODUCT(($B$2:$B$18=$A27)*E$2:E$18*$C$2:$C$18) -> 34.152031 | F27: =SUMPRODUCT(($B$2:$B$18=$A27)*F$2:F$18*$C$2:$C$18) -> 34.152031 | G27: =SUMPRODUCT(($B$2:$B$18=$A27)*G$2:G$18*$C$2:$C$18) -> 34.152031 | H27: =SUMPRODUCT(($B$2:$B$18=$A27)*H$2:H$18*$C$2:$C$18) -> 34.152031 | I27: =SUMPRODUCT(($B$2:$B$18=$A27)*I$2:I$18*$C$2:$C$18) -> 34.152031 | J27: =SUMPRODUCT(($B$2:$B$18=$A27)*J$2:J$18*$C$2:$C$18) -> 34.152031 | K27: =SUMPRODUCT(($B$2:$B$18=$A27)*K$2:K$18*$C$2:$C$18) -> 34.152031 | ... P27: =SUMPRODUCT(($B$2:$B$18=$A27)*P$2:P$18*$C$2:$C$18) -> 409.82437
A28: Halogenado | D28: =SUMPRODUCT(($B$2:$B$18=$A28)*D$2:D$18*$C$2:$C$18) -> 1.0799061 | E28: =SUMPRODUCT(($B$2:$B$18=$A28)*E$2:E$18*$C$2:$C$18) -> 1.0799061 | F28: =SUMPRODUCT(($B$2:$B$18=$A28)*F$2:F$18*$C$2:$C$18) -> 1.0799061 | G28: =SUMPRODUCT(($B$2:$B$18=$A28)*G$2:G$18*$C$2:$C$18) -> 1.0799061 | H28: =SUMPRODUCT(($B$2:$B$18=$A28)*H$2:H$18*$C$2:$C$18) -> 1.0799061 | I28: =SUMPRODUCT(($B$2:$B$18=$A28)*I$2:I$18*$C$2:$C$18) -> 1.0799061 | J28: =SUMPRODUCT(($B$2:$B$18=$A28)*J$2:J$18*$C$2:$C$18) -> 1.0799061 | K28: =SUMPRODUCT(($B$2:$B$18=$A28)*K$2:K$18*$C$2:$C$18) -> 1.0799061 | ... P28: =SUMPRODUCT(($B$2:$B$18=$A28)*P$2:P$18*$C$2:$C$18) -> 12.958874
A29: Mangueras con PH anual (u.) | D29: =SUMPRODUCT(D$2:D$18*parametros_recargas!$D$51:$D$67) -> 12.283932 | E29: =SUMPRODUCT(E$2:E$18*parametros_recargas!$D$51:$D$67) -> 12.283932 | F29: =SUMPRODUCT(F$2:F$18*parametros_recargas!$D$51:$D$67) -> 12.283932 | G29: =SUMPRODUCT(G$2:G$18*parametros_recargas!$D$51:$D$67) -> 12.283932 | H29: =SUMPRODUCT(H$2:H$18*parametros_recargas!$D$51:$D$67) -> 12.283932 | I29: =SUMPRODUCT(I$2:I$18*parametros_recargas!$D$51:$D$67) -> 12.283932 | J29: =SUMPRODUCT(J$2:J$18*parametros_recargas!$D$51:$D$67) -> 12.283932 | K29: =SUMPRODUCT(K$2:K$18*parametros_recargas!$D$51:$D$67) -> 12.283932 | ... P29: =SUMPRODUCT(P$2:P$18*parametros_recargas!$D$51:$D$67) -> 147.40718
A33: 2027 | B33: Agente | C33: u. equiv. | D33: Ene | E33: Feb | F33: Mar | G33: Abr | H33: May | I33: Jun | J33: Jul | K33: Ago | L33: Sep | M33: Oct | N33: Nov | O33: Dic | P33: Total | Q33: Incluye mant. de sustitutos (u./año)
A34: =parametros_recargas!A51 -> ABC 1 kg | B34: =parametros_recargas!B51 -> ABC | C34: =parametros_recargas!C51 -> 1 | D34: =datos_base!$C$2*parametros_recargas!$B$38+sobrestock_sustitutos!$C$175/12 -> 1006.5869 | E34: =datos_base!$C$2*parametros_recargas!$C$38+sobrestock_sustitutos!$C$175/12 -> 1006.5869 | F34: =datos_base!$C$2*parametros_recargas!$D$38+sobrestock_sustitutos!$C$175/12 -> 1006.5869 | G34: =datos_base!$C$2*parametros_recargas!$E$38+sobrestock_sustitutos!$C$175/12 -> 1006.5869 | H34: =datos_base!$C$2*parametros_recargas!$F$38+sobrestock_sustitutos!$C$175/12 -> 1006.5869 | I34: =datos_base!$C$2*parametros_recargas!$G$38+sobrestock_sustitutos!$C$175/12 -> 1006.5869 | J34: =datos_base!$C$2*parametros_recargas!$H$38+sobrestock_sustitutos!$C$175/12 -> 1006.5869 | K34: =datos_base!$C$2*parametros_recargas!$I$38+sobrestock_sustitutos!$C$175/12 -> 1006.5869 | L34: =datos_base!$C$2*parametros_recargas!$J$38+sobrestock_sustitutos!$C$175/12 -> 1006.5869 | M34: =datos_base!$C$2*parametros_recargas!$K$38+sobrestock_sustitutos!$C$175/12 -> 1006.5869 | N34: =datos_base!$C$2*parametros_recargas!$L$38+sobrestock_sustitutos!$C$175/12 -> 1006.5869 | O34: =datos_base!$C$2*parametros_recargas!$M$38+sobrestock_sustitutos!$C$175/12 -> 1006.5869 | P34: =SUM(D34:O34) -> 12079.043 | Q34: =sobrestock_sustitutos!$C$175 -> 0
A35: =parametros_recargas!A52 -> ABC 2,5 kg | B35: =parametros_recargas!B52 -> ABC | C35: =parametros_recargas!C52 -> 1 | D35: =datos_base!$C$3*parametros_recargas!$B$38+sobrestock_sustitutos!$C$176/12 -> 76.361192 | E35: =datos_base!$C$3*parametros_recargas!$C$38+sobrestock_sustitutos!$C$176/12 -> 76.361192 | F35: =datos_base!$C$3*parametros_recargas!$D$38+sobrestock_sustitutos!$C$176/12 -> 76.361192 | G35: =datos_base!$C$3*parametros_recargas!$E$38+sobrestock_sustitutos!$C$176/12 -> 76.361192 | H35: =datos_base!$C$3*parametros_recargas!$F$38+sobrestock_sustitutos!$C$176/12 -> 76.361192 | I35: =datos_base!$C$3*parametros_recargas!$G$38+sobrestock_sustitutos!$C$176/12 -> 76.361192 | J35: =datos_base!$C$3*parametros_recargas!$H$38+sobrestock_sustitutos!$C$176/12 -> 76.361192 | K35: =datos_base!$C$3*parametros_recargas!$I$38+sobrestock_sustitutos!$C$176/12 -> 76.361192 | L35: =datos_base!$C$3*parametros_recargas!$J$38+sobrestock_sustitutos!$C$176/12 -> 76.361192 | M35: =datos_base!$C$3*parametros_recargas!$K$38+sobrestock_sustitutos!$C$176/12 -> 76.361192 | N35: =datos_base!$C$3*parametros_recargas!$L$38+sobrestock_sustitutos!$C$176/12 -> 76.361192 | O35: =datos_base!$C$3*parametros_recargas!$M$38+sobrestock_sustitutos!$C$176/12 -> 76.361192 | P35: =SUM(D35:O35) -> 916.3343 | Q35: =sobrestock_sustitutos!$C$176 -> 0
A36: =parametros_recargas!A53 -> ABC 5 kg | B36: =parametros_recargas!B53 -> ABC | C36: =parametros_recargas!C53 -> 1 | D36: =datos_base!$C$4*parametros_recargas!$B$38+sobrestock_sustitutos!$C$177/12 -> 466.3506 | E36: =datos_base!$C$4*parametros_recargas!$C$38+sobrestock_sustitutos!$C$177/12 -> 466.3506 | F36: =datos_base!$C$4*parametros_recargas!$D$38+sobrestock_sustitutos!$C$177/12 -> 466.3506 | G36: =datos_base!$C$4*parametros_recargas!$E$38+sobrestock_sustitutos!$C$177/12 -> 466.3506 | H36: =datos_base!$C$4*parametros_recargas!$F$38+sobrestock_sustitutos!$C$177/12 -> 466.3506 | I36: =datos_base!$C$4*parametros_recargas!$G$38+sobrestock_sustitutos!$C$177/12 -> 466.3506 | J36: =datos_base!$C$4*parametros_recargas!$H$38+sobrestock_sustitutos!$C$177/12 -> 466.3506 | K36: =datos_base!$C$4*parametros_recargas!$I$38+sobrestock_sustitutos!$C$177/12 -> 466.3506 | L36: =datos_base!$C$4*parametros_recargas!$J$38+sobrestock_sustitutos!$C$177/12 -> 466.3506 | M36: =datos_base!$C$4*parametros_recargas!$K$38+sobrestock_sustitutos!$C$177/12 -> 466.3506 | N36: =datos_base!$C$4*parametros_recargas!$L$38+sobrestock_sustitutos!$C$177/12 -> 466.3506 | O36: =datos_base!$C$4*parametros_recargas!$M$38+sobrestock_sustitutos!$C$177/12 -> 466.3506 | P36: =SUM(D36:O36) -> 5596.2072 | Q36: =sobrestock_sustitutos!$C$177 -> 7
A37: =parametros_recargas!A54 -> ABC 10 kg | B37: =parametros_recargas!B54 -> ABC | C37: =parametros_recargas!C54 -> 1 | D37: =datos_base!$C$5*parametros_recargas!$B$38+sobrestock_sustitutos!$C$178/12 -> 26.04589 | E37: =datos_base!$C$5*parametros_recargas!$C$38+sobrestock_sustitutos!$C$178/12 -> 26.04589 | F37: =datos_base!$C$5*parametros_recargas!$D$38+sobrestock_sustitutos!$C$178/12 -> 26.04589 | G37: =datos_base!$C$5*parametros_recargas!$E$38+sobrestock_sustitutos!$C$178/12 -> 26.04589 | H37: =datos_base!$C$5*parametros_recargas!$F$38+sobrestock_sustitutos!$C$178/12 -> 26.04589 | I37: =datos_base!$C$5*parametros_recargas!$G$38+sobrestock_sustitutos!$C$178/12 -> 26.04589 | J37: =datos_base!$C$5*parametros_recargas!$H$38+sobrestock_sustitutos!$C$178/12 -> 26.04589 | K37: =datos_base!$C$5*parametros_recargas!$I$38+sobrestock_sustitutos!$C$178/12 -> 26.04589 | L37: =datos_base!$C$5*parametros_recargas!$J$38+sobrestock_sustitutos!$C$178/12 -> 26.04589 | M37: =datos_base!$C$5*parametros_recargas!$K$38+sobrestock_sustitutos!$C$178/12 -> 26.04589 | N37: =datos_base!$C$5*parametros_recargas!$L$38+sobrestock_sustitutos!$C$178/12 -> 26.04589 | O37: =datos_base!$C$5*parametros_recargas!$M$38+sobrestock_sustitutos!$C$178/12 -> 26.04589 | P37: =SUM(D37:O37) -> 312.55068 | Q37: =sobrestock_sustitutos!$C$178 -> 1
A38: =parametros_recargas!A55 -> Agua 10 l | B38: =parametros_recargas!B55 -> Agua | C38: =parametros_recargas!C55 -> 1 | D38: =datos_base!$C$6*parametros_recargas!$B$38+sobrestock_sustitutos!$C$179/12 -> 38.247116 | E38: =datos_base!$C$6*parametros_recargas!$C$38+sobrestock_sustitutos!$C$179/12 -> 38.247116 | F38: =datos_base!$C$6*parametros_recargas!$D$38+sobrestock_sustitutos!$C$179/12 -> 38.247116 | G38: =datos_base!$C$6*parametros_recargas!$E$38+sobrestock_sustitutos!$C$179/12 -> 38.247116 | H38: =datos_base!$C$6*parametros_recargas!$F$38+sobrestock_sustitutos!$C$179/12 -> 38.247116 | I38: =datos_base!$C$6*parametros_recargas!$G$38+sobrestock_sustitutos!$C$179/12 -> 38.247116 | J38: =datos_base!$C$6*parametros_recargas!$H$38+sobrestock_sustitutos!$C$179/12 -> 38.247116 | K38: =datos_base!$C$6*parametros_recargas!$I$38+sobrestock_sustitutos!$C$179/12 -> 38.247116 | L38: =datos_base!$C$6*parametros_recargas!$J$38+sobrestock_sustitutos!$C$179/12 -> 38.247116 | M38: =datos_base!$C$6*parametros_recargas!$K$38+sobrestock_sustitutos!$C$179/12 -> 38.247116 | N38: =datos_base!$C$6*parametros_recargas!$L$38+sobrestock_sustitutos!$C$179/12 -> 38.247116 | O38: =datos_base!$C$6*parametros_recargas!$M$38+sobrestock_sustitutos!$C$179/12 -> 38.247116 | P38: =SUM(D38:O38) -> 458.96539 | Q38: =sobrestock_sustitutos!$C$179 -> 1
A39: =parametros_recargas!A56 -> AFFF 10 l | B39: =parametros_recargas!B56 -> AFFF | C39: =parametros_recargas!C56 -> 1 | D39: =datos_base!$C$7*parametros_recargas!$B$38+sobrestock_sustitutos!$C$180/12 -> 9.6515552 | E39: =datos_base!$C$7*parametros_recargas!$C$38+sobrestock_sustitutos!$C$180/12 -> 9.6515552 | F39: =datos_base!$C$7*parametros_recargas!$D$38+sobrestock_sustitutos!$C$180/12 -> 9.6515552 | G39: =datos_base!$C$7*parametros_recargas!$E$38+sobrestock_sustitutos!$C$180/12 -> 9.6515552 | H39: =datos_base!$C$7*parametros_recargas!$F$38+sobrestock_sustitutos!$C$180/12 -> 9.6515552 | I39: =datos_base!$C$7*parametros_recargas!$G$38+sobrestock_sustitutos!$C$180/12 -> 9.6515552 | J39: =datos_base!$C$7*parametros_recargas!$H$38+sobrestock_sustitutos!$C$180/12 -> 9.6515552 | K39: =datos_base!$C$7*parametros_recargas!$I$38+sobrestock_sustitutos!$C$180/12 -> 9.6515552 | L39: =datos_base!$C$7*parametros_recargas!$J$38+sobrestock_sustitutos!$C$180/12 -> 9.6515552 | M39: =datos_base!$C$7*parametros_recargas!$K$38+sobrestock_sustitutos!$C$180/12 -> 9.6515552 | N39: =datos_base!$C$7*parametros_recargas!$L$38+sobrestock_sustitutos!$C$180/12 -> 9.6515552 | O39: =datos_base!$C$7*parametros_recargas!$M$38+sobrestock_sustitutos!$C$180/12 -> 9.6515552 | P39: =SUM(D39:O39) -> 115.81866 | Q39: =sobrestock_sustitutos!$C$180 -> 1
A40: =parametros_recargas!A57 -> AFFF 50 l s/ruedas | B40: =parametros_recargas!B57 -> AFFF | C40: =parametros_recargas!C57 -> 3 | D40: =datos_base!$C$8*parametros_recargas!$B$38+sobrestock_sustitutos!$C$181/12 -> 5.019622 | E40: =datos_base!$C$8*parametros_recargas!$C$38+sobrestock_sustitutos!$C$181/12 -> 5.019622 | F40: =datos_base!$C$8*parametros_recargas!$D$38+sobrestock_sustitutos!$C$181/12 -> 5.019622 | G40: =datos_base!$C$8*parametros_recargas!$E$38+sobrestock_sustitutos!$C$181/12 -> 5.019622 | H40: =datos_base!$C$8*parametros_recargas!$F$38+sobrestock_sustitutos!$C$181/12 -> 5.019622 | I40: =datos_base!$C$8*parametros_recargas!$G$38+sobrestock_sustitutos!$C$181/12 -> 5.019622 | J40: =datos_base!$C$8*parametros_recargas!$H$38+sobrestock_sustitutos!$C$181/12 -> 5.019622 | K40: =datos_base!$C$8*parametros_recargas!$I$38+sobrestock_sustitutos!$C$181/12 -> 5.019622 | L40: =datos_base!$C$8*parametros_recargas!$J$38+sobrestock_sustitutos!$C$181/12 -> 5.019622 | M40: =datos_base!$C$8*parametros_recargas!$K$38+sobrestock_sustitutos!$C$181/12 -> 5.019622 | N40: =datos_base!$C$8*parametros_recargas!$L$38+sobrestock_sustitutos!$C$181/12 -> 5.019622 | O40: =datos_base!$C$8*parametros_recargas!$M$38+sobrestock_sustitutos!$C$181/12 -> 5.019622 | P40: =SUM(D40:O40) -> 60.235463 | Q40: =sobrestock_sustitutos!$C$181 -> 1
A41: =parametros_recargas!A58 -> BC 5 kg | B41: =parametros_recargas!B58 -> BC | C41: =parametros_recargas!C58 -> 1 | D41: =datos_base!$C$9*parametros_recargas!$B$38+sobrestock_sustitutos!$C$182/12 -> 2.8754102 | E41: =datos_base!$C$9*parametros_recargas!$C$38+sobrestock_sustitutos!$C$182/12 -> 2.8754102 | F41: =datos_base!$C$9*parametros_recargas!$D$38+sobrestock_sustitutos!$C$182/12 -> 2.8754102 | G41: =datos_base!$C$9*parametros_recargas!$E$38+sobrestock_sustitutos!$C$182/12 -> 2.8754102 | H41: =datos_base!$C$9*parametros_recargas!$F$38+sobrestock_sustitutos!$C$182/12 -> 2.8754102 | I41: =datos_base!$C$9*parametros_recargas!$G$38+sobrestock_sustitutos!$C$182/12 -> 2.8754102 | J41: =datos_base!$C$9*parametros_recargas!$H$38+sobrestock_sustitutos!$C$182/12 -> 2.8754102 | K41: =datos_base!$C$9*parametros_recargas!$I$38+sobrestock_sustitutos!$C$182/12 -> 2.8754102 | L41: =datos_base!$C$9*parametros_recargas!$J$38+sobrestock_sustitutos!$C$182/12 -> 2.8754102 | M41: =datos_base!$C$9*parametros_recargas!$K$38+sobrestock_sustitutos!$C$182/12 -> 2.8754102 | N41: =datos_base!$C$9*parametros_recargas!$L$38+sobrestock_sustitutos!$C$182/12 -> 2.8754102 | O41: =datos_base!$C$9*parametros_recargas!$M$38+sobrestock_sustitutos!$C$182/12 -> 2.8754102 | P41: =SUM(D41:O41) -> 34.504923 | Q41: =sobrestock_sustitutos!$C$182 -> 1
A42: =parametros_recargas!A59 -> Sales K 6 l | B42: =parametros_recargas!B59 -> Sales K | C42: =parametros_recargas!C59 -> 1 | D42: =datos_base!$C$10*parametros_recargas!$B$38+sobrestock_sustitutos!$C$183/12 -> 19.977055 | E42: =datos_base!$C$10*parametros_recargas!$C$38+sobrestock_sustitutos!$C$183/12 -> 19.977055 | F42: =datos_base!$C$10*parametros_recargas!$D$38+sobrestock_sustitutos!$C$183/12 -> 19.977055 | G42: =datos_base!$C$10*parametros_recargas!$E$38+sobrestock_sustitutos!$C$183/12 -> 19.977055 | H42: =datos_base!$C$10*parametros_recargas!$F$38+sobrestock_sustitutos!$C$183/12 -> 19.977055 | I42: =datos_base!$C$10*parametros_recargas!$G$38+sobrestock_sustitutos!$C$183/12 -> 19.977055 | J42: =datos_base!$C$10*parametros_recargas!$H$38+sobrestock_sustitutos!$C$183/12 -> 19.977055 | K42: =datos_base!$C$10*parametros_recargas!$I$38+sobrestock_sustitutos!$C$183/12 -> 19.977055 | L42: =datos_base!$C$10*parametros_recargas!$J$38+sobrestock_sustitutos!$C$183/12 -> 19.977055 | M42: =datos_base!$C$10*parametros_recargas!$K$38+sobrestock_sustitutos!$C$183/12 -> 19.977055 | N42: =datos_base!$C$10*parametros_recargas!$L$38+sobrestock_sustitutos!$C$183/12 -> 19.977055 | O42: =datos_base!$C$10*parametros_recargas!$M$38+sobrestock_sustitutos!$C$183/12 -> 19.977055 | P42: =SUM(D42:O42) -> 239.72466 | Q42: =sobrestock_sustitutos!$C$183 -> 1
