Workbook

Sheet Links
A1: Links de los IMPORTRANGE
A2: Pegar en B el link de cada Google Sheet: todos los IMPORTRANGE lo leen de acá.
A3: Archivo | B3: Link | C3: Qué se importa
A4: Proyecciones | B4: https://docs.google.com/spreadsheets/d/1xc4xDAwSYT3l-RulPYtcePxiCninrbQGzaBUsgO0YEs/edit?gid=1764491891#gid=1764491891 | C4: Indexado Dim Técnico B27:K43, U61:U74, V61 y V63
A5: Dimensionamiento Recargas Planta Comercial | B5: PEGAR ACÁ EL LINK DEL GOOGLE SHEET | C5: sobrestock_sustitutos, paso 4: alta de sustitutos ABC que pide como cilindro vacío
A6: Dimensionamiento Recargas Planta Industrial | B6: PEGAR ACÁ EL LINK DEL GOOGLE SHEET | C6: sobrestock_sustitutos, paso 4: alta de sustitutos ABC que pide como matafuego terminado
A7: MRP (FLAMA_MRP) | B7: PEGAR ACÁ EL LINK DEL GOOGLE SHEET | C7: ESTACIONALIDAD C4:N5: perfiles E01 (1 kg) y E02 (2,5 a 10 kg), filas 12 a 15 de parametros_manuales

Sheet datos_base
A1: Matafuegos terminados | B1: 2026 | C1: 2027 | D1: 2028 | E1: 2029 | F1: 2030 | G1: 2031 | H1: 2032 | I1: 2033 | J1: 2034 | K1: 2035
A2: ABC 1 kg | B2: =IFERROR(__xludf.DUMMYFUNCTION("IMPORTRANGE(Links!$B$4,""Indexado Dim Técnico!B3:K6"")"),4178.736543) -> 4178.7365 | C2: =IFERROR(__xludf.DUMMYFUNCTION("""COMPUTED_VALUE"""),5997.303977) -> 5997.304 | D2: =IFERROR(__xludf.DUMMYFUNCTION("""COMPUTED_VALUE"""),6851.747758) -> 6851.7478 | E2: =IFERROR(__xludf.DUMMYFUNCTION("""COMPUTED_VALUE"""),8467.135549) -> 8467.1355 | F2: =IFERROR(__xludf.DUMMYFUNCTION("""COMPUTED_VALUE"""),12680.63271) -> 12680.633 | G2: =IFERROR(__xludf.DUMMYFUNCTION("""COMPUTED_VALUE"""),15620.25307) -> 15620.253 | H2: =IFERROR(__xludf.DUMMYFUNCTION("""COMPUTED_VALUE"""),20332.55326) -> 20332.553 | I2: =IFERROR(__xludf.DUMMYFUNCTION("""COMPUTED_VALUE"""),25132.07848) -> 25132.078 | J2: =IFERROR(__xludf.DUMMYFUNCTION("""COMPUTED_VALUE"""),28573.33614) -> 28573.336 | K2: =IFERROR(__xludf.DUMMYFUNCTION("""COMPUTED_VALUE"""),32072.63913) -> 32072.639
A3: ABC 2,5 kg | B3: =IFERROR(__xludf.DUMMYFUNCTION("""COMPUTED_VALUE"""),295.0303572) -> 295.03036 | C3: =IFERROR(__xludf.DUMMYFUNCTION("""COMPUTED_VALUE"""),709.7274503) -> 709.72745 | D3: =IFERROR(__xludf.DUMMYFUNCTION("""COMPUTED_VALUE"""),986.8680576) -> 986.86806 | E3: =IFERROR(__xludf.DUMMYFUNCTION("""COMPUTED_VALUE"""),1500.638174) -> 1500.6382 | F3: =IFERROR(__xludf.DUMMYFUNCTION("""COMPUTED_VALUE"""),2312.627726) -> 2312.6277 | G3: =IFERROR(__xludf.DUMMYFUNCTION("""COMPUTED_VALUE"""),3252.869887) -> 3252.8699 | H3: =IFERROR(__xludf.DUMMYFUNCTION("""COMPUTED_VALUE"""),4102.315524) -> 4102.3155 | I3: =IFERROR(__xludf.DUMMYFUNCTION("""COMPUTED_VALUE"""),5104.306587) -> 5104.3066 | J3: =IFERROR(__xludf.DUMMYFUNCTION("""COMPUTED_VALUE"""),6195.186243) -> 6195.1862 | K3: =IFERROR(__xludf.DUMMYFUNCTION("""COMPUTED_VALUE"""),7424.858444) -> 7424.8584
A4: ABC 5 kg | B4: =IFERROR(__xludf.DUMMYFUNCTION("""COMPUTED_VALUE"""),2255.773025) -> 2255.773 | C4: =IFERROR(__xludf.DUMMYFUNCTION("""COMPUTED_VALUE"""),3846.978881) -> 3846.9789 | D4: =IFERROR(__xludf.DUMMYFUNCTION("""COMPUTED_VALUE"""),5093.537591) -> 5093.5376 | E4: =IFERROR(__xludf.DUMMYFUNCTION("""COMPUTED_VALUE"""),6823.115313) -> 6823.1153 | F4: =IFERROR(__xludf.DUMMYFUNCTION("""COMPUTED_VALUE"""),10819.30694) -> 10819.307 | G4: =IFERROR(__xludf.DUMMYFUNCTION("""COMPUTED_VALUE"""),14605.96411) -> 14605.964 | H4: =IFERROR(__xludf.DUMMYFUNCTION("""COMPUTED_VALUE"""),18877.75984) -> 18877.76 | I4: =IFERROR(__xludf.DUMMYFUNCTION("""COMPUTED_VALUE"""),23368.18637) -> 23368.186 | J4: =IFERROR(__xludf.DUMMYFUNCTION("""COMPUTED_VALUE"""),26967.72455) -> 26967.725 | K4: =IFERROR(__xludf.DUMMYFUNCTION("""COMPUTED_VALUE"""),30750.77872) -> 30750.779
A5: ABC 10 kg | B5: =IFERROR(__xludf.DUMMYFUNCTION("""COMPUTED_VALUE"""),91.83318153) -> 91.833182 | C5: =IFERROR(__xludf.DUMMYFUNCTION("""COMPUTED_VALUE"""),177.2472967) -> 177.2473 | D5: =IFERROR(__xludf.DUMMYFUNCTION("""COMPUTED_VALUE"""),252.9787798) -> 252.97878 | E5: =IFERROR(__xludf.DUMMYFUNCTION("""COMPUTED_VALUE"""),358.0204941) -> 358.02049 | F5: =IFERROR(__xludf.DUMMYFUNCTION("""COMPUTED_VALUE"""),602.7181519) -> 602.71815 | G5: =IFERROR(__xludf.DUMMYFUNCTION("""COMPUTED_VALUE"""),872.605032) -> 872.60503 | H5: =IFERROR(__xludf.DUMMYFUNCTION("""COMPUTED_VALUE"""),1127.160545) -> 1127.1605 | I5: =IFERROR(__xludf.DUMMYFUNCTION("""COMPUTED_VALUE"""),1395.444812) -> 1395.4448 | J5: =IFERROR(__xludf.DUMMYFUNCTION("""COMPUTED_VALUE"""),1612.350054) -> 1612.3501 | K5: =IFERROR(__xludf.DUMMYFUNCTION("""COMPUTED_VALUE"""),1840.848079) -> 1840.8481
A6: Total terminados | B6: =SUM(B2:B5) -> 6821.3731 | C6: =SUM(C2:C5) -> 10731.258 | D6: =SUM(D2:D5) -> 13185.132 | E6: =SUM(E2:E5) -> 17148.91 | F6: =SUM(F2:F5) -> 26415.286 | G6: =SUM(G2:G5) -> 34351.692 | H6: =SUM(H2:H5) -> 44439.789 | I6: =SUM(I2:I5) -> 55000.016 | ... K6: =SUM(K2:K5) -> 72089.124
A8: Cilindros vendidos vacíos | B8: 2026 | C8: 2027 | D8: 2028 | E8: 2029 | F8: 2030 | G8: 2031 | H8: 2032 | I8: 2033 | J8: 2034 | K8: 2035
A9: Cilindros ABC 1 kg | B9: =IFERROR(__xludf.DUMMYFUNCTION("IMPORTRANGE(Links!$B$4,""Indexado Dim Técnico!B15:K18"")"),0) -> 0 | C9: =IFERROR(__xludf.DUMMYFUNCTION("""COMPUTED_VALUE"""),0) -> 0 | D9: =IFERROR(__xludf.DUMMYFUNCTION("""COMPUTED_VALUE"""),7662.4) -> 7662.4 | E9: =IFERROR(__xludf.DUMMYFUNCTION("""COMPUTED_VALUE"""),26694.8) -> 26694.8 | F9: =IFERROR(__xludf.DUMMYFUNCTION("""COMPUTED_VALUE"""),49434.8) -> 49434.8 | G9: =IFERROR(__xludf.DUMMYFUNCTION("""COMPUTED_VALUE"""),71680.2) -> 71680.2 | H9: =IFERROR(__xludf.DUMMYFUNCTION("""COMPUTED_VALUE"""),101340.6) -> 101340.6 | I9: =IFERROR(__xludf.DUMMYFUNCTION("""COMPUTED_VALUE"""),131001) -> 131001 | J9: =IFERROR(__xludf.DUMMYFUNCTION("""COMPUTED_VALUE"""),146819.8) -> 146819.8 | K9: =IFERROR(__xludf.DUMMYFUNCTION("""COMPUTED_VALUE"""),170548) -> 170548
A10: Cilindros ABC 2,5 kg | B10: =IFERROR(__xludf.DUMMYFUNCTION("""COMPUTED_VALUE"""),0) -> 0 | C10: =IFERROR(__xludf.DUMMYFUNCTION("""COMPUTED_VALUE"""),0) -> 0 | D10: =IFERROR(__xludf.DUMMYFUNCTION("""COMPUTED_VALUE"""),299.6) -> 299.6 | E10: =IFERROR(__xludf.DUMMYFUNCTION("""COMPUTED_VALUE"""),1043.8) -> 1043.8 | F10: =IFERROR(__xludf.DUMMYFUNCTION("""COMPUTED_VALUE"""),1933) -> 1933 | G10: =IFERROR(__xludf.DUMMYFUNCTION("""COMPUTED_VALUE"""),2803) -> 2803 | H10: =IFERROR(__xludf.DUMMYFUNCTION("""COMPUTED_VALUE"""),3963) -> 3963 | I10: =IFERROR(__xludf.DUMMYFUNCTION("""COMPUTED_VALUE"""),5123) -> 5123 | J10: =IFERROR(__xludf.DUMMYFUNCTION("""COMPUTED_VALUE"""),5741.4) -> 5741.4 | K10: =IFERROR(__xludf.DUMMYFUNCTION("""COMPUTED_VALUE"""),6669) -> 6669
A11: Cilindros ABC 5 kg | B11: =IFERROR(__xludf.DUMMYFUNCTION("""COMPUTED_VALUE"""),0) -> 0 | C11: =IFERROR(__xludf.DUMMYFUNCTION("""COMPUTED_VALUE"""),0) -> 0 | D11: =IFERROR(__xludf.DUMMYFUNCTION("""COMPUTED_VALUE"""),1478.8) -> 1478.8 | E11: =IFERROR(__xludf.DUMMYFUNCTION("""COMPUTED_VALUE"""),5152) -> 5152 | F11: =IFERROR(__xludf.DUMMYFUNCTION("""COMPUTED_VALUE"""),9540.8) -> 9540.8 | G11: =IFERROR(__xludf.DUMMYFUNCTION("""COMPUTED_VALUE"""),13834.2) -> 13834.2 | H11: =IFERROR(__xludf.DUMMYFUNCTION("""COMPUTED_VALUE"""),19558.6) -> 19558.6 | I11: =IFERROR(__xludf.DUMMYFUNCTION("""COMPUTED_VALUE"""),25283) -> 25283 | J11: =IFERROR(__xludf.DUMMYFUNCTION("""COMPUTED_VALUE"""),28335.8) -> 28335.8 | K11: =IFERROR(__xludf.DUMMYFUNCTION("""COMPUTED_VALUE"""),32915) -> 32915
A12: Cilindros ABC 10 kg | B12: =IFERROR(__xludf.DUMMYFUNCTION("""COMPUTED_VALUE"""),0) -> 0 | C12: =IFERROR(__xludf.DUMMYFUNCTION("""COMPUTED_VALUE"""),0) -> 0 | D12: =IFERROR(__xludf.DUMMYFUNCTION("""COMPUTED_VALUE"""),90.4) -> 90.4 | E12: =IFERROR(__xludf.DUMMYFUNCTION("""COMPUTED_VALUE"""),315) -> 315 | F12: =IFERROR(__xludf.DUMMYFUNCTION("""COMPUTED_VALUE"""),583.4) -> 583.4 | G12: =IFERROR(__xludf.DUMMYFUNCTION("""COMPUTED_VALUE"""),845.8) -> 845.8 | H12: =IFERROR(__xludf.DUMMYFUNCTION("""COMPUTED_VALUE"""),1195.4) -> 1195.4 | I12: =IFERROR(__xludf.DUMMYFUNCTION("""COMPUTED_VALUE"""),1545) -> 1545 | J12: =IFERROR(__xludf.DUMMYFUNCTION("""COMPUTED_VALUE"""),1731.4) -> 1731.4 | K12: =IFERROR(__xludf.DUMMYFUNCTION("""COMPUTED_VALUE"""),2011) -> 2011
A13: Total cilindros | B13: =SUM(B9:B12) -> 0 | C13: =SUM(C9:C12) -> 0 | D13: =SUM(D9:D12) -> 9531.2 | E13: =SUM(E9:E12) -> 33205.6 | F13: =SUM(F9:F12) -> 61492 | G13: =SUM(G9:G12) -> 89163.2 | H13: =SUM(H9:H12) -> 126057.6 | I13: =SUM(I9:I12) -> 162952 | ... K13: =SUM(K9:K12) -> 212143
A15: Total recipientes a fabricar (con sustitutos) | B15: =B6+B13+B22+B27 -> 6862.3731 | C15: =C6+C13+C22+C27 -> 10849.538 | D15: =D6+D13+D22+D27 -> 22920.812 | E15: =E6+E13+E22+E27 -> 50689.35 | F15: =F6+F13+F22+F27 -> 88247.686 | G15: =G6+G13+G22+G27 -> 123901.33 | H15: =H6+H13+H22+H27 -> 170829.71 | I15: =I6+I13+I22+I27 -> 218232.9 | ... K15: =K6+K13+K22+K27 -> 284507.28
A17: Sustitutos ABC para las plantas de recargas | B17: 2026 | C17: 2027 | D17: 2028 | E17: 2029 | F17: 2030 | G17: 2031 | H17: 2032 | I17: 2033 | J17: 2034 | K17: 2035
A18: ABC 1 kg — sustituto (terminado, planta industrial) | B18: =IFERROR(__xludf.DUMMYFUNCTION("IMPORTRANGE(Links!$B$6,""sobrestock_sustitutos!B73:K76"")"),0) -> 0 | C18: =IFERROR(__xludf.DUMMYFUNCTION("""COMPUTED_VALUE"""),0) -> 0 | D18: =IFERROR(__xludf.DUMMYFUNCTION("""COMPUTED_VALUE"""),0) -> 0 | E18: =IFERROR(__xludf.DUMMYFUNCTION("""COMPUTED_VALUE"""),0) -> 0 | F18: =IFERROR(__xludf.DUMMYFUNCTION("""COMPUTED_VALUE"""),0) -> 0 | G18: =IFERROR(__xludf.DUMMYFUNCTION("""COMPUTED_VALUE"""),0) -> 0 | H18: =IFERROR(__xludf.DUMMYFUNCTION("""COMPUTED_VALUE"""),0) -> 0 | I18: =IFERROR(__xludf.DUMMYFUNCTION("""COMPUTED_VALUE"""),0) -> 0 | J18: =IFERROR(__xludf.DUMMYFUNCTION("""COMPUTED_VALUE"""),0) -> 0 | K18: =IFERROR(__xludf.DUMMYFUNCTION("""COMPUTED_VALUE"""),0) -> 0
A19: ABC 2,5 kg — sustituto (terminado, planta industrial) | B19: =IFERROR(__xludf.DUMMYFUNCTION("""COMPUTED_VALUE"""),3) -> 3 | C19: =IFERROR(__xludf.DUMMYFUNCTION("""COMPUTED_VALUE"""),6.24) -> 6.24 | D19: =IFERROR(__xludf.DUMMYFUNCTION("""COMPUTED_VALUE"""),10.72) -> 10.72 | E19: =IFERROR(__xludf.DUMMYFUNCTION("""COMPUTED_VALUE"""),17.52) -> 17.52 | F19: =IFERROR(__xludf.DUMMYFUNCTION("""COMPUTED_VALUE"""),18.8) -> 18.8 | G19: =IFERROR(__xludf.DUMMYFUNCTION("""COMPUTED_VALUE"""),21.08) -> 21.08 | H19: =IFERROR(__xludf.DUMMYFUNCTION("""COMPUTED_VALUE"""),18.44) -> 18.44 | I19: =IFERROR(__xludf.DUMMYFUNCTION("""COMPUTED_VALUE"""),15.48) -> 15.48 | J19: =IFERROR(__xludf.DUMMYFUNCTION("""COMPUTED_VALUE"""),14.2) -> 14.2 | K19: =IFERROR(__xludf.DUMMYFUNCTION("""COMPUTED_VALUE"""),14.76) -> 14.76
A20: ABC 5 kg — sustituto (terminado, planta industrial) | B20: =IFERROR(__xludf.DUMMYFUNCTION("""COMPUTED_VALUE"""),11) -> 11 | C20: =IFERROR(__xludf.DUMMYFUNCTION("""COMPUTED_VALUE"""),33.88) -> 33.88 | D20: =IFERROR(__xludf.DUMMYFUNCTION("""COMPUTED_VALUE"""),57.52) -> 57.52 | E20: =IFERROR(__xludf.DUMMYFUNCTION("""COMPUTED_VALUE"""),95.84) -> 95.84 | F20: =IFERROR(__xludf.DUMMYFUNCTION("""COMPUTED_VALUE"""),95.88) -> 95.88 | G20: =IFERROR(__xludf.DUMMYFUNCTION("""COMPUTED_VALUE"""),109.36) -> 109.36 | H20: =IFERROR(__xludf.DUMMYFUNCTION("""COMPUTED_VALUE"""),93.4) -> 93.4 | I20: =IFERROR(__xludf.DUMMYFUNCTION("""COMPUTED_VALUE"""),79.6) -> 79.6 | J20: =IFERROR(__xludf.DUMMYFUNCTION("""COMPUTED_VALUE"""),73.28) -> 73.28 | K20: =IFERROR(__xludf.DUMMYFUNCTION("""COMPUTED_VALUE"""),78.16) -> 78.16
A21: ABC 10 kg — sustituto (terminado, planta industrial) | B21: =IFERROR(__xludf.DUMMYFUNCTION("""COMPUTED_VALUE"""),1) -> 1 | C21: =IFERROR(__xludf.DUMMYFUNCTION("""COMPUTED_VALUE"""),3.08) -> 3.08 | D21: =IFERROR(__xludf.DUMMYFUNCTION("""COMPUTED_VALUE"""),4.32) -> 4.32 | E21: =IFERROR(__xludf.DUMMYFUNCTION("""COMPUTED_VALUE"""),7.64) -> 7.64 | F21: =IFERROR(__xludf.DUMMYFUNCTION("""COMPUTED_VALUE"""),7.2) -> 7.2 | G21: =IFERROR(__xludf.DUMMYFUNCTION("""COMPUTED_VALUE"""),8.68) -> 8.68 | H21: =IFERROR(__xludf.DUMMYFUNCTION("""COMPUTED_VALUE"""),6.24) -> 6.24 | I21: =IFERROR(__xludf.DUMMYFUNCTION("""COMPUTED_VALUE"""),6.56) -> 6.56 | J21: =IFERROR(__xludf.DUMMYFUNCTION("""COMPUTED_VALUE"""),4.88) -> 4.88 | K21: =IFERROR(__xludf.DUMMYFUNCTION("""COMPUTED_VALUE"""),6.04) -> 6.04
A22: Total sustitutos terminados | B22: =SUM(B18:B21) -> 15 | C22: =SUM(C18:C21) -> 43.2 | D22: =SUM(D18:D21) -> 72.56 | E22: =SUM(E18:E21) -> 121 | F22: =SUM(F18:F21) -> 121.88 | G22: =SUM(G18:G21) -> 139.12 | H22: =SUM(H18:H21) -> 118.08 | I22: =SUM(I18:I21) -> 101.64 | ... K22: =SUM(K18:K21) -> 98.96
A23: ABC 1 kg — sustituto (cilindro vacío, planta comercial) | B23: =IFERROR(__xludf.DUMMYFUNCTION("IMPORTRANGE(Links!$B$5,""sobrestock_sustitutos!B73:K76"")"),0) -> 0 | C23: =IFERROR(__xludf.DUMMYFUNCTION("""COMPUTED_VALUE"""),0) -> 0 | D23: =IFERROR(__xludf.DUMMYFUNCTION("""COMPUTED_VALUE"""),0) -> 0 | E23: =IFERROR(__xludf.DUMMYFUNCTION("""COMPUTED_VALUE"""),0) -> 0 | F23: =IFERROR(__xludf.DUMMYFUNCTION("""COMPUTED_VALUE"""),0) -> 0 | G23: =IFERROR(__xludf.DUMMYFUNCTION("""COMPUTED_VALUE"""),0) -> 0 | H23: =IFERROR(__xludf.DUMMYFUNCTION("""COMPUTED_VALUE"""),0) -> 0 | I23: =IFERROR(__xludf.DUMMYFUNCTION("""COMPUTED_VALUE"""),0) -> 0 | J23: =IFERROR(__xludf.DUMMYFUNCTION("""COMPUTED_VALUE"""),0) -> 0 | K23: =IFERROR(__xludf.DUMMYFUNCTION("""COMPUTED_VALUE"""),0) -> 0
A24: ABC 2,5 kg — sustituto (cilindro vacío, planta comercial) | B24: =IFERROR(__xludf.DUMMYFUNCTION("""COMPUTED_VALUE"""),4) -> 4 | C24: =IFERROR(__xludf.DUMMYFUNCTION("""COMPUTED_VALUE"""),11.32) -> 11.32 | D24: =IFERROR(__xludf.DUMMYFUNCTION("""COMPUTED_VALUE"""),20.2) -> 20.2 | E24: =IFERROR(__xludf.DUMMYFUNCTION("""COMPUTED_VALUE"""),30.72) -> 30.72 | F24: =IFERROR(__xludf.DUMMYFUNCTION("""COMPUTED_VALUE"""),32.96) -> 32.96 | G24: =IFERROR(__xludf.DUMMYFUNCTION("""COMPUTED_VALUE"""),36.2) -> 36.2 | H24: =IFERROR(__xludf.DUMMYFUNCTION("""COMPUTED_VALUE"""),33.52) -> 33.52 | I24: =IFERROR(__xludf.DUMMYFUNCTION("""COMPUTED_VALUE"""),27.44) -> 27.44 | J24: =IFERROR(__xludf.DUMMYFUNCTION("""COMPUTED_VALUE"""),25.72) -> 25.72 | K24: =IFERROR(__xludf.DUMMYFUNCTION("""COMPUTED_VALUE"""),26.76) -> 26.76
A25: ABC 5 kg — sustituto (cilindro vacío, planta comercial) | B25: =IFERROR(__xludf.DUMMYFUNCTION("""COMPUTED_VALUE"""),20) -> 20 | C25: =IFERROR(__xludf.DUMMYFUNCTION("""COMPUTED_VALUE"""),59.6) -> 59.6 | D25: =IFERROR(__xludf.DUMMYFUNCTION("""COMPUTED_VALUE"""),103.24) -> 103.24 | E25: =IFERROR(__xludf.DUMMYFUNCTION("""COMPUTED_VALUE"""),170) -> 170 | F25: =IFERROR(__xludf.DUMMYFUNCTION("""COMPUTED_VALUE"""),172.48) -> 172.48 | G25: =IFERROR(__xludf.DUMMYFUNCTION("""COMPUTED_VALUE"""),195.16) -> 195.16 | H25: =IFERROR(__xludf.DUMMYFUNCTION("""COMPUTED_VALUE"""),169.72) -> 169.72 | I25: =IFERROR(__xludf.DUMMYFUNCTION("""COMPUTED_VALUE"""),141.24) -> 141.24 | J25: =IFERROR(__xludf.DUMMYFUNCTION("""COMPUTED_VALUE"""),132.72) -> 132.72 | K25: =IFERROR(__xludf.DUMMYFUNCTION("""COMPUTED_VALUE"""),139) -> 139
A26: ABC 10 kg — sustituto (cilindro vacío, planta comercial) | B26: =IFERROR(__xludf.DUMMYFUNCTION("""COMPUTED_VALUE"""),2) -> 2 | C26: =IFERROR(__xludf.DUMMYFUNCTION("""COMPUTED_VALUE"""),4.16) -> 4.16 | D26: =IFERROR(__xludf.DUMMYFUNCTION("""COMPUTED_VALUE"""),8.48) -> 8.48 | E26: =IFERROR(__xludf.DUMMYFUNCTION("""COMPUTED_VALUE"""),13.12) -> 13.12 | F26: =IFERROR(__xludf.DUMMYFUNCTION("""COMPUTED_VALUE"""),13.08) -> 13.08 | G26: =IFERROR(__xludf.DUMMYFUNCTION("""COMPUTED_VALUE"""),15.96) -> 15.96 | H26: =IFERROR(__xludf.DUMMYFUNCTION("""COMPUTED_VALUE"""),11) -> 11 | I26: =IFERROR(__xludf.DUMMYFUNCTION("""COMPUTED_VALUE"""),10.56) -> 10.56 | J26: =IFERROR(__xludf.DUMMYFUNCTION("""COMPUTED_VALUE"""),10.04) -> 10.04 | K26: =IFERROR(__xludf.DUMMYFUNCTION("""COMPUTED_VALUE"""),10.44) -> 10.44
A27: Total sustitutos cilindros vacíos | B27: =SUM(B23:B26) -> 26 | C27: =SUM(C23:C26) -> 75.08 | D27: =SUM(D23:D26) -> 131.92 | E27: =SUM(E23:E26) -> 213.84 | F27: =SUM(F23:F26) -> 218.52 | G27: =SUM(G23:G26) -> 247.32 | H27: =SUM(H23:H26) -> 214.24 | I27: =SUM(I23:I26) -> 179.24 | ... K27: =SUM(K23:K26) -> 176.2
A28: Sustitutos: alta (paso 4) de cada Dimensionamiento de recargas · Word de recargas § 9

Sheet parametros_manuales
A1: Parámetro | B1: Valor | C1: Nota
A2: Días hábiles por mes | B2: 20 | C2: Excel original, Parametros B37
A3: Horas por día (1 turno) | B3: 8 | C3: Excel original, Parametros D37
A4: Refrigerio (min/turno) | B4: 30 | C4: Excel original, Parametros H37
A5: Horas productivas por turno | B5: =B3-B4/60 -> 7.5 | C5: Horas/día − refrigerio
A6: Turnos por día | B6: 1 | C6: Un solo turno (editable)
A7: Horas productivas por mes | B7: =B2*B5*B6 -> 150 | C7: Días × horas productivas × turnos
A8: Umbral de aprovechamiento | B8: 0.9 | C8: Límite duro (análisis de riesgos) · Word de recargas § 8
A9: Año de inicio del 2° turno (antes: más máquinas) | B9: 2032 | C9: Todos los turnos entran ese año · Word de recargas § 8
A10: ESTACIONALIDAD (% de la demanda anual por mes; IMPORTRANGE del MRP, que define los picos)
A11: Modelo | B11: Ene | C11: Feb | D11: Mar | E11: Abr | F11: May | G11: Jun | H11: Jul | I11: Ago | J11: Sep | K11: Oct | L11: Nov | M11: Dic | N11: Total
A12: 1 kg | B12: =IFERROR(__xludf.DUMMYFUNCTION("IMPORTRANGE(Links!$B$7,""ESTACIONALIDAD!C4:N4"")"),0.12) -> 0.12 | C12: =IFERROR(__xludf.DUMMYFUNCTION("""COMPUTED_VALUE"""),0.09) -> 0.09 | D12: =IFERROR(__xludf.DUMMYFUNCTION("""COMPUTED_VALUE"""),0.08) -> 0.08 | E12: =IFERROR(__xludf.DUMMYFUNCTION("""COMPUTED_VALUE"""),0.075) -> 0.075 | F12: =IFERROR(__xludf.DUMMYFUNCTION("""COMPUTED_VALUE"""),0.07) -> 0.07 | G12: =IFERROR(__xludf.DUMMYFUNCTION("""COMPUTED_VALUE"""),0.07) -> 0.07 | H12: =IFERROR(__xludf.DUMMYFUNCTION("""COMPUTED_VALUE"""),0.075) -> 0.075 | I12: =IFERROR(__xludf.DUMMYFUNCTION("""COMPUTED_VALUE"""),0.075) -> 0.075 | J12: =IFERROR(__xludf.DUMMYFUNCTION("""COMPUTED_VALUE"""),0.075) -> 0.075 | K12: =IFERROR(__xludf.DUMMYFUNCTION("""COMPUTED_VALUE"""),0.075) -> 0.075 | L12: =IFERROR(__xludf.DUMMYFUNCTION("""COMPUTED_VALUE"""),0.075) -> 0.075 | M12: =IFERROR(__xludf.DUMMYFUNCTION("""COMPUTED_VALUE"""),0.12) -> 0.12 | N12: =SUM(B12:M12) -> 1 | O12: MRP, ESTACIONALIDAD E01 automotor (1 kg) (IMPORTRANGE)
A13: 2,5 kg | B13: =IFERROR(__xludf.DUMMYFUNCTION("IMPORTRANGE(Links!$B$7,""ESTACIONALIDAD!C5:N5"")"),0.1) -> 0.1 | C13: =IFERROR(__xludf.DUMMYFUNCTION("""COMPUTED_VALUE"""),0.08) -> 0.08 | D13: =IFERROR(__xludf.DUMMYFUNCTION("""COMPUTED_VALUE"""),0.085) -> 0.085 | E13: =IFERROR(__xludf.DUMMYFUNCTION("""COMPUTED_VALUE"""),0.085) -> 0.085 | F13: =IFERROR(__xludf.DUMMYFUNCTION("""COMPUTED_VALUE"""),0.08) -> 0.08 | G13: =IFERROR(__xludf.DUMMYFUNCTION("""COMPUTED_VALUE"""),0.075) -> 0.075 | H13: =IFERROR(__xludf.DUMMYFUNCTION("""COMPUTED_VALUE"""),0.08) -> 0.08 | I13: =IFERROR(__xludf.DUMMYFUNCTION("""COMPUTED_VALUE"""),0.08) -> 0.08 | J13: =IFERROR(__xludf.DUMMYFUNCTION("""COMPUTED_VALUE"""),0.08) -> 0.08 | K13: =IFERROR(__xludf.DUMMYFUNCTION("""COMPUTED_VALUE"""),0.075) -> 0.075 | L13: =IFERROR(__xludf.DUMMYFUNCTION("""COMPUTED_VALUE"""),0.07) -> 0.07 | M13: =IFERROR(__xludf.DUMMYFUNCTION("""COMPUTED_VALUE"""),0.11) -> 0.11 | N13: =SUM(B13:M13) -> 1 | O13: MRP, ESTACIONALIDAD E02 manual comercial (2,5 a 10 kg) (IMPORTRANGE)
A14: 5 kg | B14: =IFERROR(__xludf.DUMMYFUNCTION("IMPORTRANGE(Links!$B$7,""ESTACIONALIDAD!C5:N5"")"),0.1) -> 0.1 | C14: =IFERROR(__xludf.DUMMYFUNCTION("""COMPUTED_VALUE"""),0.08) -> 0.08 | D14: =IFERROR(__xludf.DUMMYFUNCTION("""COMPUTED_VALUE"""),0.085) -> 0.085 | E14: =IFERROR(__xludf.DUMMYFUNCTION("""COMPUTED_VALUE"""),0.085) -> 0.085 | F14: =IFERROR(__xludf.DUMMYFUNCTION("""COMPUTED_VALUE"""),0.08) -> 0.08 | G14: =IFERROR(__xludf.DUMMYFUNCTION("""COMPUTED_VALUE"""),0.075) -> 0.075 | H14: =IFERROR(__xludf.DUMMYFUNCTION("""COMPUTED_VALUE"""),0.08) -> 0.08 | I14: =IFERROR(__xludf.DUMMYFUNCTION("""COMPUTED_VALUE"""),0.08) -> 0.08 | J14: =IFERROR(__xludf.DUMMYFUNCTION("""COMPUTED_VALUE"""),0.08) -> 0.08 | K14: =IFERROR(__xludf.DUMMYFUNCTION("""COMPUTED_VALUE"""),0.075) -> 0.075 | L14: =IFERROR(__xludf.DUMMYFUNCTION("""COMPUTED_VALUE"""),0.07) -> 0.07 | M14: =IFERROR(__xludf.DUMMYFUNCTION("""COMPUTED_VALUE"""),0.11) -> 0.11 | N14: =SUM(B14:M14) -> 1 | O14: MRP, ESTACIONALIDAD E02 manual comercial (2,5 a 10 kg) (IMPORTRANGE)
A15: 10 kg | B15: =IFERROR(__xludf.DUMMYFUNCTION("IMPORTRANGE(Links!$B$7,""ESTACIONALIDAD!C5:N5"")"),0.1) -> 0.1 | C15: =IFERROR(__xludf.DUMMYFUNCTION("""COMPUTED_VALUE"""),0.08) -> 0.08 | D15: =IFERROR(__xludf.DUMMYFUNCTION("""COMPUTED_VALUE"""),0.085) -> 0.085 | E15: =IFERROR(__xludf.DUMMYFUNCTION("""COMPUTED_VALUE"""),0.085) -> 0.085 | F15: =IFERROR(__xludf.DUMMYFUNCTION("""COMPUTED_VALUE"""),0.08) -> 0.08 | G15: =IFERROR(__xludf.DUMMYFUNCTION("""COMPUTED_VALUE"""),0.075) -> 0.075 | H15: =IFERROR(__xludf.DUMMYFUNCTION("""COMPUTED_VALUE"""),0.08) -> 0.08 | I15: =IFERROR(__xludf.DUMMYFUNCTION("""COMPUTED_VALUE"""),0.08) -> 0.08 | J15: =IFERROR(__xludf.DUMMYFUNCTION("""COMPUTED_VALUE"""),0.08) -> 0.08 | K15: =IFERROR(__xludf.DUMMYFUNCTION("""COMPUTED_VALUE"""),0.075) -> 0.075 | L15: =IFERROR(__xludf.DUMMYFUNCTION("""COMPUTED_VALUE"""),0.07) -> 0.07 | M15: =IFERROR(__xludf.DUMMYFUNCTION("""COMPUTED_VALUE"""),0.11) -> 0.11 | N15: =SUM(B15:M15) -> 1 | O15: MRP, ESTACIONALIDAD E02 manual comercial (2,5 a 10 kg) (IMPORTRANGE)
A17: CAPACIDAD POR PUESTO
A18: N° | B18: Puesto | C18: Máquina | D18: 1 kg | E18: 2,5 kg | F18: 5 kg | G18: 10 kg | H18: Alcance | I18: Piezas por unidad | J18: % que pasa | K18: Tiempo tipo (s/u) | L18: Disponibilidad | M18: Cap. real (u/h) | N18: Cap. real (u/mes) | O18: SUPOSICIONES
A19: 1 | B19: Recepción de materia prima | C19: Autoelevador Heli CPCD50 + micrómetro | D19: 1 | E19: 1 | F19: 1 | G19: 1 | H19: Todos | I19: 1 | J19: 1 | K19: 60 | L19: =F51 -> 1 | M19: =IF(K19>0,3600/K19*L19,0) -> 60 | N19: =M19*$B$7 -> 9000 | O19: 25 min x pallet de 20 hojas en carros (1,25 min x hoja)
A20: 2 | B20: Corte de chapa (guillotina) — 2,5 a 10 kg | C20: Guillotina hidráulica Cena serie O 3.200 mm | D20: 0 | E20: 1 | F20: 1 | G20: 1 | H20: Todos | I20: 1 | J20: 1 | K20: 90 | L20: =F52 -> 0.99333333 | M20: =IF(K20>0,3600/K20*L20,0) -> 39.733333 | N20: =M20*$B$7 -> 5960 | O20: ref carros - 1,2/1,5 min x cuerpo (+ CORTES + TIEMPO)
A21: 3 | B21: Corte de tubo — 1 kg | C21: Cortadora láser de tubo Leapion 1,5 kW | D21: 1 | E21: 0 | F21: 0 | G21: 0 | H21: Todos | I21: 1 | J21: 1 | K21: 30 | L21: =F53 -> 1 | M21: =IF(K21>0,3600/K21*L21,0) -> 120 | N21: =M21*$B$7 -> 18000 | O21: 10 minutos por tubo de 6m (en cada tubo entran 23 cuerpos)
A22: 4 | B22: Corte de disco y embutido (cúpula y fondo) | C22: Prensa embutidora Sangiacomo + alimentador Cena PRE-1 | D22: 1 | E22: 1 | F22: 1 | G22: 1 | H22: Todos | I22: 2 | J22: 1 | K22: 8 | L22: =F54 -> 0.68 | M22: =IF(K22>0,3600/K22*L22,0) -> 306 | N22: =M22*$B$7 -> 45900 | O22: Son 10c segundos contemplando cupula y fondo
A23: 5 | B23: Preparación de cuello | C23: Prensa de banco Pannier MarkFirst MB-21 | D23: 1 | E23: 1 | F23: 1 | G23: 1 | H23: Todos | I23: 1 | J23: 1 | K23: 60 | L23: =F55 -> 1 | M23: =IF(K23>0,3600/K23*L23,0) -> 60 | N23: =M23*$B$7 -> 9000
A24: 6 | B24: Numerado de cúpula | C24: Micropercusión Pannier ADP120160D Deep Marker | D24: 1 | E24: 1 | F24: 1 | G24: 1 | H24: Todos | I24: 1 | J24: 1 | K24: 20 | L24: =F56 -> 1 | M24: =IF(K24>0,3600/K24*L24,0) -> 180 | N24: =M24*$B$7 -> 27000
A25: 7 | B25: Soldadura del cuello a la cúpula | C25: Firesafer FS-HFM1 (versión manual) | D25: 1 | E25: 1 | F25: 1 | G25: 1 | H25: Todos | I25: 1 | J25: 1 | K25: 25 | L25: =F57 -> 0.97333333 | M25: =IF(K25>0,3600/K25*L25,0) -> 140.16 | N25: =M25*$B$7 -> 21024
A26: 8 | B26: Cilindrado | C26: Roladora Firesafer FS-RM01 | D26: 0 | E26: 1 | F26: 1 | G26: 1 | H26: Todos | I26: 1 | J26: 1 | K26: 80 | L26: =F58 -> 0.98666667 | M26: =IF(K26>0,3600/K26*L26,0) -> 44.4 | N26: =M26*$B$7 -> 6660
A27: 9 | B27: Soldadura longitudinal | C27: Soldadora longitudinal Firesafer | D27: 0 | E27: 1 | F27: 1 | G27: 1 | H27: Todos | I27: 1 | J27: 1 | K27: 115 | L27: =F59 -> 0.98666667 | M27: =IF(K27>0,3600/K27*L27,0) -> 30.886957 | N27: =M27*$B$7 -> 4633.0435
A28: 10 | B28: Encastre de fondo | C28: Prensa hidráulica motorizada Del Fabro 30 t | D28: 1 | E28: 1 | F28: 1 | G28: 1 | H28: Todos | I28: 1 | J28: 1 | K28: 30 | L28: =F60 -> 0.98222222 | M28: =IF(K28>0,3600/K28*L28,0) -> 117.86667 | N28: =M28*$B$7 -> 17680
A29: 11 | B29: Bordoneado | C29: Bordoneadora motorizada Pilman SWM-400 | D29: 1 | E29: 1 | F29: 1 | G29: 1 | H29: Todos | I29: 1 | J29: 1 | K29: 20 | L29: =F61 -> 0.98222222 | M29: =IF(K29>0,3600/K29*L29,0) -> 176.8 | N29: =M29*$B$7 -> 26520
A30: 12 | B30: Soldadura circunferencial de cúpula y fondo | C30: Soldadora circunferencial Firesafer | D30: 1 | E30: 1 | F30: 1 | G30: 1 | H30: Todos | I30: 1 | J30: 1 | K30: 60 | L30: =F62 -> 0.98222222 | M30: =IF(K30>0,3600/K30*L30,0) -> 58.933333 | N30: =M30*$B$7 -> 8840
A31: 13 | B31: Control de calidad — Espesor | C31: Medidor de espesores Melisam MR017 | D31: 1 | E31: 1 | F31: 1 | G31: 1 | H31: Todos | I31: 1 | J31: 0.02 | K31: 120 | L31: =F63 -> 1 | M31: =IF(K31>0,3600/K31*L31,0) -> 30 | N31: =M31*$B$7 -> 4500
A32: 14 | B32: Prueba hidráulica | C32: Banco Firesafer FS-JD12A | D32: 1 | E32: 1 | F32: 1 | G32: 1 | H32: Todos | I32: 1 | J32: 1 | K32: 60 | L32: =F64 -> 0.98222222 | M32: =IF(K32>0,3600/K32*L32,0) -> 58.933333 | N32: =M32*$B$7 -> 8840
A33: 15 | B33: Secado | C33: Secadora de cilindros Yukon | D33: 1 | E33: 1 | F33: 1 | G33: 1 | H33: Todos | I33: 1 | J33: 1 | K33: 120 | L33: =F65 -> 1 | M33: =IF(K33>0,3600/K33*L33,0) -> 30 | N33: =M33*$B$7 -> 4500 | O33: las 4 maquinas sirven para secado de carros
A34: 16 | B34: Granallado | C34: Granalladora de rodillos AirBlast G-100 | D34: 1 | E34: 1 | F34: 1 | G34: 1 | H34: Todos | I34: 1 | J34: 1 | K34: 30 | L34: =F66 -> 1 | M34: =IF(K34>0,3600/K34*L34,0) -> 120 | N34: =M34*$B$7 -> 18000
A35: 17 | B35: Detección de defectos | C35: Mesa de inspección con iluminación | D35: 1 | E35: 1 | F35: 1 | G35: 1 | H35: Todos | I35: 1 | J35: 1 | K35: 20 | L35: =F67 -> 1 | M35: =IF(K35>0,3600/K35*L35,0) -> 180 | N35: =M35*$B$7 -> 27000
A36: 18 | B36: Corrección de defectos | C36: Amoladora 115 mm + machos y calibres | D36: 1 | E36: 1 | F36: 1 | G36: 1 | H36: Todos | I36: 1 | J36: 0.05 | K36: 180 | L36: =F68 -> 1 | M36: =IF(K36>0,3600/K36*L36,0) -> 20 | N36: =M36*$B$7 -> 3000
A37: 19 | B37: Pintura en polvo + horno | C37: Línea de pintura en polvo Firesafer | D37: 1 | E37: 1 | F37: 1 | G37: 1 | H37: Todos | I37: 1 | J37: 1 | K37: 25 | L37: =F69 -> 0.94666667 | M37: =IF(K37>0,3600/K37*L37,0) -> 136.32 | N37: =M37*$B$7 -> 20448
A38: 20 | B38: Carga de polvo | C38: Cargadora Firesafer FS-A10 / Yukon M-000121 | D38: 1 | E38: 1 | F38: 1 | G38: 1 | H38: Terminados | I38: 1 | J38: 1 | K38: 45 | L38: =F70 -> 1 | M38: =IF(K38>0,3600/K38*L38,0) -> 80 | N38: =M38*$B$7 -> 12000
A39: 21 | B39: Ensamblaje | C39: Puesto manual con llave dinamométrica | D39: 1 | E39: 1 | F39: 1 | G39: 1 | H39: Terminados | I39: 1 | J39: 1 | K39: 100 | L39: =F71 -> 0.98222222 | M39: =IF(K39>0,3600/K39*L39,0) -> 35.36 | N39: =M39*$B$7 -> 5304
A40: 22 | B40: Presurización | C40: Pinza neumática Yukon M-000150 + pack N₂ | D40: 1 | E40: 1 | F40: 1 | G40: 1 | H40: Terminados | I40: 1 | J40: 1 | K40: 30 | L40: =F72 -> 1 | M40: =IF(K40>0,3600/K40*L40,0) -> 120 | N40: =M40*$B$7 -> 18000
A41: 23 | B41: Control de calidad — Ensayo de pérdidas | C41: Tanque de inmersión de acero inoxidable | D41: 1 | E41: 1 | F41: 1 | G41: 1 | H41: Terminados | I41: 1 | J41: 1 | K41: 55 | L41: =F73 -> 1 | M41: =IF(K41>0,3600/K41*L41,0) -> 65.454545 | N41: =M41*$B$7 -> 9818.1818
...

Sheet Plan mensual
A1: 2026 | B1: Producto | C1: Tipo | D1: Ene | E1: Feb | F1: Mar | G1: Abr | H1: May | I1: Jun | J1: Jul | K1: Ago | L1: Sep | M1: Oct | N1: Nov | O1: Dic | P1: Total anual
A2: 2026 | B2: ABC 1 kg | C2: Terminado | D2: =(datos_base!$B$2+datos_base!$B$18)*parametros_manuales!B$12 -> 501.44839 | E2: =(datos_base!$B$2+datos_base!$B$18)*parametros_manuales!C$12 -> 376.08629 | F2: =(datos_base!$B$2+datos_base!$B$18)*parametros_manuales!D$12 -> 334.29892 | G2: =(datos_base!$B$2+datos_base!$B$18)*parametros_manuales!E$12 -> 313.40524 | H2: =(datos_base!$B$2+datos_base!$B$18)*parametros_manuales!F$12 -> 292.51156 | I2: =(datos_base!$B$2+datos_base!$B$18)*parametros_manuales!G$12 -> 292.51156 | J2: =(datos_base!$B$2+datos_base!$B$18)*parametros_manuales!H$12 -> 313.40524 | K2: =(datos_base!$B$2+datos_base!$B$18)*parametros_manuales!I$12 -> 313.40524 | ... O2: =(datos_base!$B$2+datos_base!$B$18)*parametros_manuales!M$12 -> 501.44839 | P2: =SUM(D2:O2) -> 4178.7365
A3: 2026 | B3: ABC 2,5 kg | C3: Terminado | D3: =(datos_base!$B$3+datos_base!$B$19)*parametros_manuales!B$13 -> 29.803036 | E3: =(datos_base!$B$3+datos_base!$B$19)*parametros_manuales!C$13 -> 23.842429 | F3: =(datos_base!$B$3+datos_base!$B$19)*parametros_manuales!D$13 -> 25.33258 | G3: =(datos_base!$B$3+datos_base!$B$19)*parametros_manuales!E$13 -> 25.33258 | H3: =(datos_base!$B$3+datos_base!$B$19)*parametros_manuales!F$13 -> 23.842429 | I3: =(datos_base!$B$3+datos_base!$B$19)*parametros_manuales!G$13 -> 22.352277 | J3: =(datos_base!$B$3+datos_base!$B$19)*parametros_manuales!H$13 -> 23.842429 | K3: =(datos_base!$B$3+datos_base!$B$19)*parametros_manuales!I$13 -> 23.842429 | ... O3: =(datos_base!$B$3+datos_base!$B$19)*parametros_manuales!M$13 -> 32.783339 | P3: =SUM(D3:O3) -> 298.03036
A4: 2026 | B4: ABC 5 kg | C4: Terminado | D4: =(datos_base!$B$4+datos_base!$B$20)*parametros_manuales!B$14 -> 226.6773 | E4: =(datos_base!$B$4+datos_base!$B$20)*parametros_manuales!C$14 -> 181.34184 | F4: =(datos_base!$B$4+datos_base!$B$20)*parametros_manuales!D$14 -> 192.67571 | G4: =(datos_base!$B$4+datos_base!$B$20)*parametros_manuales!E$14 -> 192.67571 | H4: =(datos_base!$B$4+datos_base!$B$20)*parametros_manuales!F$14 -> 181.34184 | I4: =(datos_base!$B$4+datos_base!$B$20)*parametros_manuales!G$14 -> 170.00798 | J4: =(datos_base!$B$4+datos_base!$B$20)*parametros_manuales!H$14 -> 181.34184 | K4: =(datos_base!$B$4+datos_base!$B$20)*parametros_manuales!I$14 -> 181.34184 | ... O4: =(datos_base!$B$4+datos_base!$B$20)*parametros_manuales!M$14 -> 249.34503 | P4: =SUM(D4:O4) -> 2266.773
A5: 2026 | B5: ABC 10 kg | C5: Terminado | D5: =(datos_base!$B$5+datos_base!$B$21)*parametros_manuales!B$15 -> 9.2833182 | E5: =(datos_base!$B$5+datos_base!$B$21)*parametros_manuales!C$15 -> 7.4266545 | F5: =(datos_base!$B$5+datos_base!$B$21)*parametros_manuales!D$15 -> 7.8908204 | G5: =(datos_base!$B$5+datos_base!$B$21)*parametros_manuales!E$15 -> 7.8908204 | H5: =(datos_base!$B$5+datos_base!$B$21)*parametros_manuales!F$15 -> 7.4266545 | I5: =(datos_base!$B$5+datos_base!$B$21)*parametros_manuales!G$15 -> 6.9624886 | J5: =(datos_base!$B$5+datos_base!$B$21)*parametros_manuales!H$15 -> 7.4266545 | K5: =(datos_base!$B$5+datos_base!$B$21)*parametros_manuales!I$15 -> 7.4266545 | ... O5: =(datos_base!$B$5+datos_base!$B$21)*parametros_manuales!M$15 -> 10.21165 | P5: =SUM(D5:O5) -> 92.833182
A6: 2026 | B6: Cilindros ABC 1 kg | C6: Cilindro | D6: =(datos_base!$B$9+datos_base!$B$23)*parametros_manuales!B$12 -> 0 | E6: =(datos_base!$B$9+datos_base!$B$23)*parametros_manuales!C$12 -> 0 | F6: =(datos_base!$B$9+datos_base!$B$23)*parametros_manuales!D$12 -> 0 | G6: =(datos_base!$B$9+datos_base!$B$23)*parametros_manuales!E$12 -> 0 | H6: =(datos_base!$B$9+datos_base!$B$23)*parametros_manuales!F$12 -> 0 | I6: =(datos_base!$B$9+datos_base!$B$23)*parametros_manuales!G$12 -> 0 | J6: =(datos_base!$B$9+datos_base!$B$23)*parametros_manuales!H$12 -> 0 | K6: =(datos_base!$B$9+datos_base!$B$23)*parametros_manuales!I$12 -> 0 | ... O6: =(datos_base!$B$9+datos_base!$B$23)*parametros_manuales!M$12 -> 0 | P6: =SUM(D6:O6) -> 0
A7: 2026 | B7: Cilindros ABC 2,5 kg | C7: Cilindro | D7: =(datos_base!$B$10+datos_base!$B$24)*parametros_manuales!B$13 -> 0.4 | E7: =(datos_base!$B$10+datos_base!$B$24)*parametros_manuales!C$13 -> 0.32 | F7: =(datos_base!$B$10+datos_base!$B$24)*parametros_manuales!D$13 -> 0.34 | G7: =(datos_base!$B$10+datos_base!$B$24)*parametros_manuales!E$13 -> 0.34 | H7: =(datos_base!$B$10+datos_base!$B$24)*parametros_manuales!F$13 -> 0.32 | I7: =(datos_base!$B$10+datos_base!$B$24)*parametros_manuales!G$13 -> 0.3 | J7: =(datos_base!$B$10+datos_base!$B$24)*parametros_manuales!H$13 -> 0.32 | K7: =(datos_base!$B$10+datos_base!$B$24)*parametros_manuales!I$13 -> 0.32 | ... O7: =(datos_base!$B$10+datos_base!$B$24)*parametros_manuales!M$13 -> 0.44 | P7: =SUM(D7:O7) -> 4
A8: 2026 | B8: Cilindros ABC 5 kg | C8: Cilindro | D8: =(datos_base!$B$11+datos_base!$B$25)*parametros_manuales!B$14 -> 2 | E8: =(datos_base!$B$11+datos_base!$B$25)*parametros_manuales!C$14 -> 1.6 | F8: =(datos_base!$B$11+datos_base!$B$25)*parametros_manuales!D$14 -> 1.7 | G8: =(datos_base!$B$11+datos_base!$B$25)*parametros_manuales!E$14 -> 1.7 | H8: =(datos_base!$B$11+datos_base!$B$25)*parametros_manuales!F$14 -> 1.6 | I8: =(datos_base!$B$11+datos_base!$B$25)*parametros_manuales!G$14 -> 1.5 | J8: =(datos_base!$B$11+datos_base!$B$25)*parametros_manuales!H$14 -> 1.6 | K8: =(datos_base!$B$11+datos_base!$B$25)*parametros_manuales!I$14 -> 1.6 | ... O8: =(datos_base!$B$11+datos_base!$B$25)*parametros_manuales!M$14 -> 2.2 | P8: =SUM(D8:O8) -> 20
A9: 2026 | B9: Cilindros ABC 10 kg | C9: Cilindro | D9: =(datos_base!$B$12+datos_base!$B$26)*parametros_manuales!B$15 -> 0.2 | E9: =(datos_base!$B$12+datos_base!$B$26)*parametros_manuales!C$15 -> 0.16 | F9: =(datos_base!$B$12+datos_base!$B$26)*parametros_manuales!D$15 -> 0.17 | G9: =(datos_base!$B$12+datos_base!$B$26)*parametros_manuales!E$15 -> 0.17 | H9: =(datos_base!$B$12+datos_base!$B$26)*parametros_manuales!F$15 -> 0.16 | I9: =(datos_base!$B$12+datos_base!$B$26)*parametros_manuales!G$15 -> 0.15 | J9: =(datos_base!$B$12+datos_base!$B$26)*parametros_manuales!H$15 -> 0.16 | K9: =(datos_base!$B$12+datos_base!$B$26)*parametros_manuales!I$15 -> 0.16 | ... O9: =(datos_base!$B$12+datos_base!$B$26)*parametros_manuales!M$15 -> 0.22 | P9: =SUM(D9:O9) -> 2
B10: Total recipientes | D10: =SUM(D2:D9) -> 769.81204 | E10: =SUM(E2:E9) -> 590.77721 | F10: =SUM(F2:F9) -> 562.40803 | G10: =SUM(G2:G9) -> 541.51435 | H10: =SUM(H2:H9) -> 507.20248 | I10: =SUM(I2:I9) -> 493.7843 | J10: =SUM(J2:J9) -> 528.09617 | K10: =SUM(K2:K9) -> 528.09617 | ... P10: =SUM(P2:P9) -> 6862.3731
A12: 2027 | B12: Producto | C12: Tipo | D12: Ene | E12: Feb | F12: Mar | G12: Abr | H12: May | I12: Jun | J12: Jul | K12: Ago | L12: Sep | M12: Oct | N12: Nov | O12: Dic | P12: Total anual
A13: 2027 | B13: ABC 1 kg | C13: Terminado | D13: =(datos_base!$C$2+datos_base!$C$18)*parametros_manuales!B$12 -> 719.67648 | E13: =(datos_base!$C$2+datos_base!$C$18)*parametros_manuales!C$12 -> 539.75736 | F13: =(datos_base!$C$2+datos_base!$C$18)*parametros_manuales!D$12 -> 479.78432 | G13: =(datos_base!$C$2+datos_base!$C$18)*parametros_manuales!E$12 -> 449.7978 | H13: =(datos_base!$C$2+datos_base!$C$18)*parametros_manuales!F$12 -> 419.81128 | I13: =(datos_base!$C$2+datos_base!$C$18)*parametros_manuales!G$12 -> 419.81128 | J13: =(datos_base!$C$2+datos_base!$C$18)*parametros_manuales!H$12 -> 449.7978 | K13: =(datos_base!$C$2+datos_base!$C$18)*parametros_manuales!I$12 -> 449.7978 | ... O13: =(datos_base!$C$2+datos_base!$C$18)*parametros_manuales!M$12 -> 719.67648 | P13: =SUM(D13:O13) -> 5997.304
A14: 2027 | B14: ABC 2,5 kg | C14: Terminado | D14: =(datos_base!$C$3+datos_base!$C$19)*parametros_manuales!B$13 -> 71.596745 | E14: =(datos_base!$C$3+datos_base!$C$19)*parametros_manuales!C$13 -> 57.277396 | F14: =(datos_base!$C$3+datos_base!$C$19)*parametros_manuales!D$13 -> 60.857233 | G14: =(datos_base!$C$3+datos_base!$C$19)*parametros_manuales!E$13 -> 60.857233 | H14: =(datos_base!$C$3+datos_base!$C$19)*parametros_manuales!F$13 -> 57.277396 | I14: =(datos_base!$C$3+datos_base!$C$19)*parametros_manuales!G$13 -> 53.697559 | J14: =(datos_base!$C$3+datos_base!$C$19)*parametros_manuales!H$13 -> 57.277396 | K14: =(datos_base!$C$3+datos_base!$C$19)*parametros_manuales!I$13 -> 57.277396 | ... O14: =(datos_base!$C$3+datos_base!$C$19)*parametros_manuales!M$13 -> 78.75642 | P14: =SUM(D14:O14) -> 715.96745
A15: 2027 | B15: ABC 5 kg | C15: Terminado | D15: =(datos_base!$C$4+datos_base!$C$20)*parametros_manuales!B$14 -> 388.08589 | E15: =(datos_base!$C$4+datos_base!$C$20)*parametros_manuales!C$14 -> 310.46871 | F15: =(datos_base!$C$4+datos_base!$C$20)*parametros_manuales!D$14 -> 329.873 | G15: =(datos_base!$C$4+datos_base!$C$20)*parametros_manuales!E$14 -> 329.873 | H15: =(datos_base!$C$4+datos_base!$C$20)*parametros_manuales!F$14 -> 310.46871 | I15: =(datos_base!$C$4+datos_base!$C$20)*parametros_manuales!G$14 -> 291.06442 | J15: =(datos_base!$C$4+datos_base!$C$20)*parametros_manuales!H$14 -> 310.46871 | K15: =(datos_base!$C$4+datos_base!$C$20)*parametros_manuales!I$14 -> 310.46871 | ... O15: =(datos_base!$C$4+datos_base!$C$20)*parametros_manuales!M$14 -> 426.89448 | P15: =SUM(D15:O15) -> 3880.8589
A16: 2027 | B16: ABC 10 kg | C16: Terminado | D16: =(datos_base!$C$5+datos_base!$C$21)*parametros_manuales!B$15 -> 18.03273 | E16: =(datos_base!$C$5+datos_base!$C$21)*parametros_manuales!C$15 -> 14.426184 | F16: =(datos_base!$C$5+datos_base!$C$21)*parametros_manuales!D$15 -> 15.32782 | G16: =(datos_base!$C$5+datos_base!$C$21)*parametros_manuales!E$15 -> 15.32782 | H16: =(datos_base!$C$5+datos_base!$C$21)*parametros_manuales!F$15 -> 14.426184 | I16: =(datos_base!$C$5+datos_base!$C$21)*parametros_manuales!G$15 -> 13.524547 | J16: =(datos_base!$C$5+datos_base!$C$21)*parametros_manuales!H$15 -> 14.426184 | K16: =(datos_base!$C$5+datos_base!$C$21)*parametros_manuales!I$15 -> 14.426184 | ... O16: =(datos_base!$C$5+datos_base!$C$21)*parametros_manuales!M$15 -> 19.836003 | P16: =SUM(D16:O16) -> 180.3273
A17: 2027 | B17: Cilindros ABC 1 kg | C17: Cilindro | D17: =(datos_base!$C$9+datos_base!$C$23)*parametros_manuales!B$12 -> 0 | E17: =(datos_base!$C$9+datos_base!$C$23)*parametros_manuales!C$12 -> 0 | F17: =(datos_base!$C$9+datos_base!$C$23)*parametros_manuales!D$12 -> 0 | G17: =(datos_base!$C$9+datos_base!$C$23)*parametros_manuales!E$12 -> 0 | H17: =(datos_base!$C$9+datos_base!$C$23)*parametros_manuales!F$12 -> 0 | I17: =(datos_base!$C$9+datos_base!$C$23)*parametros_manuales!G$12 -> 0 | J17: =(datos_base!$C$9+datos_base!$C$23)*parametros_manuales!H$12 -> 0 | K17: =(datos_base!$C$9+datos_base!$C$23)*parametros_manuales!I$12 -> 0 | ... O17: =(datos_base!$C$9+datos_base!$C$23)*parametros_manuales!M$12 -> 0 | P17: =SUM(D17:O17) -> 0
A18: 2027 | B18: Cilindros ABC 2,5 kg | C18: Cilindro | D18: =(datos_base!$C$10+datos_base!$C$24)*parametros_manuales!B$13 -> 1.132 | E18: =(datos_base!$C$10+datos_base!$C$24)*parametros_manuales!C$13 -> 0.9056 | F18: =(datos_base!$C$10+datos_base!$C$24)*parametros_manuales!D$13 -> 0.9622 | G18: =(datos_base!$C$10+datos_base!$C$24)*parametros_manuales!E$13 -> 0.9622 | H18: =(datos_base!$C$10+datos_base!$C$24)*parametros_manuales!F$13 -> 0.9056 | I18: =(datos_base!$C$10+datos_base!$C$24)*parametros_manuales!G$13 -> 0.849 | J18: =(datos_base!$C$10+datos_base!$C$24)*parametros_manuales!H$13 -> 0.9056 | K18: =(datos_base!$C$10+datos_base!$C$24)*parametros_manuales!I$13 -> 0.9056 | ... O18: =(datos_base!$C$10+datos_base!$C$24)*parametros_manuales!M$13 -> 1.2452 | P18: =SUM(D18:O18) -> 11.32
A19: 2027 | B19: Cilindros ABC 5 kg | C19: Cilindro | D19: =(datos_base!$C$11+datos_base!$C$25)*parametros_manuales!B$14 -> 5.96 | E19: =(datos_base!$C$11+datos_base!$C$25)*parametros_manuales!C$14 -> 4.768 | F19: =(datos_base!$C$11+datos_base!$C$25)*parametros_manuales!D$14 -> 5.066 | G19: =(datos_base!$C$11+datos_base!$C$25)*parametros_manuales!E$14 -> 5.066 | H19: =(datos_base!$C$11+datos_base!$C$25)*parametros_manuales!F$14 -> 4.768 | I19: =(datos_base!$C$11+datos_base!$C$25)*parametros_manuales!G$14 -> 4.47 | J19: =(datos_base!$C$11+datos_base!$C$25)*parametros_manuales!H$14 -> 4.768 | K19: =(datos_base!$C$11+datos_base!$C$25)*parametros_manuales!I$14 -> 4.768 | ... O19: =(datos_base!$C$11+datos_base!$C$25)*parametros_manuales!M$14 -> 6.556 | P19: =SUM(D19:O19) -> 59.6
A20: 2027 | B20: Cilindros ABC 10 kg | C20: Cilindro | D20: =(datos_base!$C$12+datos_base!$C$26)*parametros_manuales!B$15 -> 0.416 | E20: =(datos_base!$C$12+datos_base!$C$26)*parametros_manuales!C$15 -> 0.3328 | F20: =(datos_base!$C$12+datos_base!$C$26)*parametros_manuales!D$15 -> 0.3536 | G20: =(datos_base!$C$12+datos_base!$C$26)*parametros_manuales!E$15 -> 0.3536 | H20: =(datos_base!$C$12+datos_base!$C$26)*parametros_manuales!F$15 -> 0.3328 | I20: =(datos_base!$C$12+datos_base!$C$26)*parametros_manuales!G$15 -> 0.312 | J20: =(datos_base!$C$12+datos_base!$C$26)*parametros_manuales!H$15 -> 0.3328 | K20: =(datos_base!$C$12+datos_base!$C$26)*parametros_manuales!I$15 -> 0.3328 | ... O20: =(datos_base!$C$12+datos_base!$C$26)*parametros_manuales!M$15 -> 0.4576 | P20: =SUM(D20:O20) -> 4.16
B21: Total recipientes | D21: =SUM(D13:D20) -> 1204.8998 | E21: =SUM(E13:E20) -> 927.93605 | F21: =SUM(F13:F20) -> 892.22418 | G21: =SUM(G13:G20) -> 862.23766 | H21: =SUM(H13:H20) -> 807.98997 | I21: =SUM(I13:I20) -> 783.7288 | J21: =SUM(J13:J20) -> 837.97649 | K21: =SUM(K13:K20) -> 837.97649 | ... P21: =SUM(P13:P20) -> 10849.538
A23: 2028 | B23: Producto | C23: Tipo | D23: Ene | E23: Feb | F23: Mar | G23: Abr | H23: May | I23: Jun | J23: Jul | K23: Ago | L23: Sep | M23: Oct | N23: Nov | O23: Dic | P23: Total anual
A24: 2028 | B24: ABC 1 kg | C24: Terminado | D24: =(datos_base!$D$2+datos_base!$D$18)*parametros_manuales!B$12 -> 822.20973 | E24: =(datos_base!$D$2+datos_base!$D$18)*parametros_manuales!C$12 -> 616.6573 | F24: =(datos_base!$D$2+datos_base!$D$18)*parametros_manuales!D$12 -> 548.13982 | G24: =(datos_base!$D$2+datos_base!$D$18)*parametros_manuales!E$12 -> 513.88108 | H24: =(datos_base!$D$2+datos_base!$D$18)*parametros_manuales!F$12 -> 479.62234 | I24: =(datos_base!$D$2+datos_base!$D$18)*parametros_manuales!G$12 -> 479.62234 | J24: =(datos_base!$D$2+datos_base!$D$18)*parametros_manuales!H$12 -> 513.88108 | K24: =(datos_base!$D$2+datos_base!$D$18)*parametros_manuales!I$12 -> 513.88108 | ... O24: =(datos_base!$D$2+datos_base!$D$18)*parametros_manuales!M$12 -> 822.20973 | P24: =SUM(D24:O24) -> 6851.7478
A25: 2028 | B25: ABC 2,5 kg | C25: Terminado | D25: =(datos_base!$D$3+datos_base!$D$19)*parametros_manuales!B$13 -> 99.758806 | E25: =(datos_base!$D$3+datos_base!$D$19)*parametros_manuales!C$13 -> 79.807045 | F25: =(datos_base!$D$3+datos_base!$D$19)*parametros_manuales!D$13 -> 84.794985 | G25: =(datos_base!$D$3+datos_base!$D$19)*parametros_manuales!E$13 -> 84.794985 | H25: =(datos_base!$D$3+datos_base!$D$19)*parametros_manuales!F$13 -> 79.807045 | I25: =(datos_base!$D$3+datos_base!$D$19)*parametros_manuales!G$13 -> 74.819104 | J25: =(datos_base!$D$3+datos_base!$D$19)*parametros_manuales!H$13 -> 79.807045 | K25: =(datos_base!$D$3+datos_base!$D$19)*parametros_manuales!I$13 -> 79.807045 | ... O25: =(datos_base!$D$3+datos_base!$D$19)*parametros_manuales!M$13 -> 109.73469 | P25: =SUM(D25:O25) -> 997.58806
A26: 2028 | B26: ABC 5 kg | C26: Terminado | D26: =(datos_base!$D$4+datos_base!$D$20)*parametros_manuales!B$14 -> 515.10576 | E26: =(datos_base!$D$4+datos_base!$D$20)*parametros_manuales!C$14 -> 412.08461 | F26: =(datos_base!$D$4+datos_base!$D$20)*parametros_manuales!D$14 -> 437.8399 | G26: =(datos_base!$D$4+datos_base!$D$20)*parametros_manuales!E$14 -> 437.8399 | H26: =(datos_base!$D$4+datos_base!$D$20)*parametros_manuales!F$14 -> 412.08461 | I26: =(datos_base!$D$4+datos_base!$D$20)*parametros_manuales!G$14 -> 386.32932 | J26: =(datos_base!$D$4+datos_base!$D$20)*parametros_manuales!H$14 -> 412.08461 | K26: =(datos_base!$D$4+datos_base!$D$20)*parametros_manuales!I$14 -> 412.08461 | ... O26: =(datos_base!$D$4+datos_base!$D$20)*parametros_manuales!M$14 -> 566.61634 | P26: =SUM(D26:O26) -> 5151.0576
A27: 2028 | B27: ABC 10 kg | C27: Terminado | D27: =(datos_base!$D$5+datos_base!$D$21)*parametros_manuales!B$15 -> 25.729878 | E27: =(datos_base!$D$5+datos_base!$D$21)*parametros_manuales!C$15 -> 20.583902 | F27: =(datos_base!$D$5+datos_base!$D$21)*parametros_manuales!D$15 -> 21.870396 | G27: =(datos_base!$D$5+datos_base!$D$21)*parametros_manuales!E$15 -> 21.870396 | H27: =(datos_base!$D$5+datos_base!$D$21)*parametros_manuales!F$15 -> 20.583902 | I27: =(datos_base!$D$5+datos_base!$D$21)*parametros_manuales!G$15 -> 19.297408 | J27: =(datos_base!$D$5+datos_base!$D$21)*parametros_manuales!H$15 -> 20.583902 | K27: =(datos_base!$D$5+datos_base!$D$21)*parametros_manuales!I$15 -> 20.583902 | ... O27: =(datos_base!$D$5+datos_base!$D$21)*parametros_manuales!M$15 -> 28.302866 | P27: =SUM(D27:O27) -> 257.29878
A28: 2028 | B28: Cilindros ABC 1 kg | C28: Cilindro | D28: =(datos_base!$D$9+datos_base!$D$23)*parametros_manuales!B$12 -> 919.488 | E28: =(datos_base!$D$9+datos_base!$D$23)*parametros_manuales!C$12 -> 689.616 | F28: =(datos_base!$D$9+datos_base!$D$23)*parametros_manuales!D$12 -> 612.992 | G28: =(datos_base!$D$9+datos_base!$D$23)*parametros_manuales!E$12 -> 574.68 | H28: =(datos_base!$D$9+datos_base!$D$23)*parametros_manuales!F$12 -> 536.368 | I28: =(datos_base!$D$9+datos_base!$D$23)*parametros_manuales!G$12 -> 536.368 | J28: =(datos_base!$D$9+datos_base!$D$23)*parametros_manuales!H$12 -> 574.68 | K28: =(datos_base!$D$9+datos_base!$D$23)*parametros_manuales!I$12 -> 574.68 | ... O28: =(datos_base!$D$9+datos_base!$D$23)*parametros_manuales!M$12 -> 919.488 | P28: =SUM(D28:O28) -> 7662.4
A29: 2028 | B29: Cilindros ABC 2,5 kg | C29: Cilindro | D29: =(datos_base!$D$10+datos_base!$D$24)*parametros_manuales!B$13 -> 31.98 | E29: =(datos_base!$D$10+datos_base!$D$24)*parametros_manuales!C$13 -> 25.584 | F29: =(datos_base!$D$10+datos_base!$D$24)*parametros_manuales!D$13 -> 27.183 | G29: =(datos_base!$D$10+datos_base!$D$24)*parametros_manuales!E$13 -> 27.183 | H29: =(datos_base!$D$10+datos_base!$D$24)*parametros_manuales!F$13 -> 25.584 | I29: =(datos_base!$D$10+datos_base!$D$24)*parametros_manuales!G$13 -> 23.985 | J29: =(datos_base!$D$10+datos_base!$D$24)*parametros_manuales!H$13 -> 25.584 | K29: =(datos_base!$D$10+datos_base!$D$24)*parametros_manuales!I$13 -> 25.584 | ... O29: =(datos_base!$D$10+datos_base!$D$24)*parametros_manuales!M$13 -> 35.178 | P29: =SUM(D29:O29) -> 319.8
A30: 2028 | B30: Cilindros ABC 5 kg | C30: Cilindro | D30: =(datos_base!$D$11+datos_base!$D$25)*parametros_manuales!B$14 -> 158.204 | E30: =(datos_base!$D$11+datos_base!$D$25)*parametros_manuales!C$14 -> 126.5632 | F30: =(datos_base!$D$11+datos_base!$D$25)*parametros_manuales!D$14 -> 134.4734 | G30: =(datos_base!$D$11+datos_base!$D$25)*parametros_manuales!E$14 -> 134.4734 | H30: =(datos_base!$D$11+datos_base!$D$25)*parametros_manuales!F$14 -> 126.5632 | I30: =(datos_base!$D$11+datos_base!$D$25)*parametros_manuales!G$14 -> 118.653 | J30: =(datos_base!$D$11+datos_base!$D$25)*parametros_manuales!H$14 -> 126.5632 | K30: =(datos_base!$D$11+datos_base!$D$25)*parametros_manuales!I$14 -> 126.5632 | ... O30: =(datos_base!$D$11+datos_base!$D$25)*parametros_manuales!M$14 -> 174.0244 | P30: =SUM(D30:O30) -> 1582.04
A31: 2028 | B31: Cilindros ABC 10 kg | C31: Cilindro | D31: =(datos_base!$D$12+datos_base!$D$26)*parametros_manuales!B$15 -> 9.888 | E31: =(datos_base!$D$12+datos_base!$D$26)*parametros_manuales!C$15 -> 7.9104 | F31: =(datos_base!$D$12+datos_base!$D$26)*parametros_manuales!D$15 -> 8.4048 | G31: =(datos_base!$D$12+datos_base!$D$26)*parametros_manuales!E$15 -> 8.4048 | H31: =(datos_base!$D$12+datos_base!$D$26)*parametros_manuales!F$15 -> 7.9104 | I31: =(datos_base!$D$12+datos_base!$D$26)*parametros_manuales!G$15 -> 7.416 | J31: =(datos_base!$D$12+datos_base!$D$26)*parametros_manuales!H$15 -> 7.9104 | K31: =(datos_base!$D$12+datos_base!$D$26)*parametros_manuales!I$15 -> 7.9104 | ... O31: =(datos_base!$D$12+datos_base!$D$26)*parametros_manuales!M$15 -> 10.8768 | P31: =SUM(D31:O31) -> 98.88
B32: Total recipientes | D32: =SUM(D24:D31) -> 2582.3642 | E32: =SUM(E24:E31) -> 1978.8065 | F32: =SUM(F24:F31) -> 1875.6983 | G32: =SUM(G24:G31) -> 1803.1276 | H32: =SUM(H24:H31) -> 1688.5235 | I32: =SUM(I24:I31) -> 1646.4902 | J32: =SUM(J24:J31) -> 1761.0942 | K32: =SUM(K24:K31) -> 1761.0942 | ... P32: =SUM(P24:P31) -> 22920.812
A34: 2029 | B34: Producto | C34: Tipo | D34: Ene | E34: Feb | F34: Mar | G34: Abr | H34: May | I34: Jun | J34: Jul | K34: Ago | L34: Sep | M34: Oct | N34: Nov | O34: Dic | P34: Total anual
A35: 2029 | B35: ABC 1 kg | C35: Terminado | D35: =(datos_base!$E$2+datos_base!$E$18)*parametros_manuales!B$12 -> 1016.0563 | E35: =(datos_base!$E$2+datos_base!$E$18)*parametros_manuales!C$12 -> 762.0422 | F35: =(datos_base!$E$2+datos_base!$E$18)*parametros_manuales!D$12 -> 677.37084 | G35: =(datos_base!$E$2+datos_base!$E$18)*parametros_manuales!E$12 -> 635.03517 | H35: =(datos_base!$E$2+datos_base!$E$18)*parametros_manuales!F$12 -> 592.69949 | I35: =(datos_base!$E$2+datos_base!$E$18)*parametros_manuales!G$12 -> 592.69949 | J35: =(datos_base!$E$2+datos_base!$E$18)*parametros_manuales!H$12 -> 635.03517 | K35: =(datos_base!$E$2+datos_base!$E$18)*parametros_manuales!I$12 -> 635.03517 | ... O35: =(datos_base!$E$2+datos_base!$E$18)*parametros_manuales!M$12 -> 1016.0563 | P35: =SUM(D35:O35) -> 8467.1355
A36: 2029 | B36: ABC 2,5 kg | C36: Terminado | D36: =(datos_base!$E$3+datos_base!$E$19)*parametros_manuales!B$13 -> 151.81582 | E36: =(datos_base!$E$3+datos_base!$E$19)*parametros_manuales!C$13 -> 121.45265 | F36: =(datos_base!$E$3+datos_base!$E$19)*parametros_manuales!D$13 -> 129.04344 | G36: =(datos_base!$E$3+datos_base!$E$19)*parametros_manuales!E$13 -> 129.04344 | H36: =(datos_base!$E$3+datos_base!$E$19)*parametros_manuales!F$13 -> 121.45265 | I36: =(datos_base!$E$3+datos_base!$E$19)*parametros_manuales!G$13 -> 113.86186 | J36: =(datos_base!$E$3+datos_base!$E$19)*parametros_manuales!H$13 -> 121.45265 | K36: =(datos_base!$E$3+datos_base!$E$19)*parametros_manuales!I$13 -> 121.45265 | ... O36: =(datos_base!$E$3+datos_base!$E$19)*parametros_manuales!M$13 -> 166.9974 | P36: =SUM(D36:O36) -> 1518.1582
A37: 2029 | B37: ABC 5 kg | C37: Terminado | D37: =(datos_base!$E$4+datos_base!$E$20)*parametros_manuales!B$14 -> 691.89553 | E37: =(datos_base!$E$4+datos_base!$E$20)*parametros_manuales!C$14 -> 553.51643 | F37: =(datos_base!$E$4+datos_base!$E$20)*parametros_manuales!D$14 -> 588.1112 | G37: =(datos_base!$E$4+datos_base!$E$20)*parametros_manuales!E$14 -> 588.1112 | H37: =(datos_base!$E$4+datos_base!$E$20)*parametros_manuales!F$14 -> 553.51643 | I37: =(datos_base!$E$4+datos_base!$E$20)*parametros_manuales!G$14 -> 518.92165 | J37: =(datos_base!$E$4+datos_base!$E$20)*parametros_manuales!H$14 -> 553.51643 | K37: =(datos_base!$E$4+datos_base!$E$20)*parametros_manuales!I$14 -> 553.51643 | ... O37: =(datos_base!$E$4+datos_base!$E$20)*parametros_manuales!M$14 -> 761.08508 | P37: =SUM(D37:O37) -> 6918.9553
A38: 2029 | B38: ABC 10 kg | C38: Terminado | D38: =(datos_base!$E$5+datos_base!$E$21)*parametros_manuales!B$15 -> 36.566049 | E38: =(datos_base!$E$5+datos_base!$E$21)*parametros_manuales!C$15 -> 29.25284 | F38: =(datos_base!$E$5+datos_base!$E$21)*parametros_manuales!D$15 -> 31.081142 | G38: =(datos_base!$E$5+datos_base!$E$21)*parametros_manuales!E$15 -> 31.081142 | H38: =(datos_base!$E$5+datos_base!$E$21)*parametros_manuales!F$15 -> 29.25284 | I38: =(datos_base!$E$5+datos_base!$E$21)*parametros_manuales!G$15 -> 27.424537 | J38: =(datos_base!$E$5+datos_base!$E$21)*parametros_manuales!H$15 -> 29.25284 | K38: =(datos_base!$E$5+datos_base!$E$21)*parametros_manuales!I$15 -> 29.25284 | ... O38: =(datos_base!$E$5+datos_base!$E$21)*parametros_manuales!M$15 -> 40.222654 | P38: =SUM(D38:O38) -> 365.66049
A39: 2029 | B39: Cilindros ABC 1 kg | C39: Cilindro | D39: =(datos_base!$E$9+datos_base!$E$23)*parametros_manuales!B$12 -> 3203.376 | E39: =(datos_base!$E$9+datos_base!$E$23)*parametros_manuales!C$12 -> 2402.532 | F39: =(datos_base!$E$9+datos_base!$E$23)*parametros_manuales!D$12 -> 2135.584 | G39: =(datos_base!$E$9+datos_base!$E$23)*parametros_manuales!E$12 -> 2002.11 | H39: =(datos_base!$E$9+datos_base!$E$23)*parametros_manuales!F$12 -> 1868.636 | I39: =(datos_base!$E$9+datos_base!$E$23)*parametros_manuales!G$12 -> 1868.636 | J39: =(datos_base!$E$9+datos_base!$E$23)*parametros_manuales!H$12 -> 2002.11 | K39: =(datos_base!$E$9+datos_base!$E$23)*parametros_manuales!I$12 -> 2002.11 | ... O39: =(datos_base!$E$9+datos_base!$E$23)*parametros_manuales!M$12 -> 3203.376 | P39: =SUM(D39:O39) -> 26694.8
A40: 2029 | B40: Cilindros ABC 2,5 kg | C40: Cilindro | D40: =(datos_base!$E$10+datos_base!$E$24)*parametros_manuales!B$13 -> 107.452 | E40: =(datos_base!$E$10+datos_base!$E$24)*parametros_manuales!C$13 -> 85.9616 | F40: =(datos_base!$E$10+datos_base!$E$24)*parametros_manuales!D$13 -> 91.3342 | G40: =(datos_base!$E$10+datos_base!$E$24)*parametros_manuales!E$13 -> 91.3342 | H40: =(datos_base!$E$10+datos_base!$E$24)*parametros_manuales!F$13 -> 85.9616 | I40: =(datos_base!$E$10+datos_base!$E$24)*parametros_manuales!G$13 -> 80.589 | J40: =(datos_base!$E$10+datos_base!$E$24)*parametros_manuales!H$13 -> 85.9616 | K40: =(datos_base!$E$10+datos_base!$E$24)*parametros_manuales!I$13 -> 85.9616 | ... O40: =(datos_base!$E$10+datos_base!$E$24)*parametros_manuales!M$13 -> 118.1972 | P40: =SUM(D40:O40) -> 1074.52
A41: 2029 | B41: Cilindros ABC 5 kg | C41: Cilindro | D41: =(datos_base!$E$11+datos_base!$E$25)*parametros_manuales!B$14 -> 532.2 | E41: =(datos_base!$E$11+datos_base!$E$25)*parametros_manuales!C$14 -> 425.76 | F41: =(datos_base!$E$11+datos_base!$E$25)*parametros_manuales!D$14 -> 452.37 | G41: =(datos_base!$E$11+datos_base!$E$25)*parametros_manuales!E$14 -> 452.37 | H41: =(datos_base!$E$11+datos_base!$E$25)*parametros_manuales!F$14 -> 425.76 | I41: =(datos_base!$E$11+datos_base!$E$25)*parametros_manuales!G$14 -> 399.15 | J41: =(datos_base!$E$11+datos_base!$E$25)*parametros_manuales!H$14 -> 425.76 | K41: =(datos_base!$E$11+datos_base!$E$25)*parametros_manuales!I$14 -> 425.76 | ... O41: =(datos_base!$E$11+datos_base!$E$25)*parametros_manuales!M$14 -> 585.42 | P41: =SUM(D41:O41) -> 5322
A42: 2029 | B42: Cilindros ABC 10 kg | C42: Cilindro | D42: =(datos_base!$E$12+datos_base!$E$26)*parametros_manuales!B$15 -> 32.812 | E42: =(datos_base!$E$12+datos_base!$E$26)*parametros_manuales!C$15 -> 26.2496 | F42: =(datos_base!$E$12+datos_base!$E$26)*parametros_manuales!D$15 -> 27.8902 | G42: =(datos_base!$E$12+datos_base!$E$26)*parametros_manuales!E$15 -> 27.8902 | H42: =(datos_base!$E$12+datos_base!$E$26)*parametros_manuales!F$15 -> 26.2496 | I42: =(datos_base!$E$12+datos_base!$E$26)*parametros_manuales!G$15 -> 24.609 | J42: =(datos_base!$E$12+datos_base!$E$26)*parametros_manuales!H$15 -> 26.2496 | K42: =(datos_base!$E$12+datos_base!$E$26)*parametros_manuales!I$15 -> 26.2496 | ... O42: =(datos_base!$E$12+datos_base!$E$26)*parametros_manuales!M$15 -> 36.0932 | P42: =SUM(D42:O42) -> 328.12
B43: Total recipientes | D43: =SUM(D35:D42) -> 5772.1737 | E43: =SUM(E35:E42) -> 4406.7673 | F43: =SUM(F35:F42) -> 4132.785 | G43: =SUM(G35:G42) -> 3956.9754 | H43: =SUM(H35:H42) -> 3703.5286 | I43: =SUM(I35:I42) -> 3625.8915 | J43: =SUM(J35:J42) -> 3879.3383 | K43: =SUM(K35:K42) -> 3879.3383 | ... P43: =SUM(P35:P42) -> 50689.35
...

Sheet Demanda puesto sin sobrestock
A1: Año 2026 | B1: Ene | C1: Feb | D1: Mar | E1: Abr | F1: May | G1: Jun | H1: Jul | I1: Ago | J1: Sep | K1: Oct | L1: Nov | M1: Dic | N1: Total anual | O1: Mes pico (u/mes) | P1: Demanda pico (u/h) | Q1: Mes pico
A2: =parametros_manuales!$B$19 -> Recepción de materia prima | B2: =(parametros_manuales!$D$19*('Plan mensual'!D2+IF(parametros_manuales!$H$19="Todos",'Plan mensual'!D6,0))+parametros_manuales!$E$19*('Plan mensual'!D3+IF(parametros_manuales!$H$19="Todos",'Plan mensual'!D7,0))+parametros_manuales!$F$19*('Plan mensual'!D4+IF(parametros_manuales!$H$19="Todos",'Plan mensual'!D8,0))+parametros_manuales!$G$19*('Plan mensual'!D5+IF(parametros_manuales!$H$19="Todos",'Plan mensual'!D9,0)))*parametros_manuales!$I$19*parametros_manuales!$J$19 -> 769.81204 | C2: =(parametros_manuales!$D$19*('Plan mensual'!E2+IF(parametros_manuales!$H$19="Todos",'Plan mensual'!E6,0))+parametros_manuales!$E$19*('Plan mensual'!E3+IF(parametros_manuales!$H$19="Todos",'Plan mensual'!E7,0))+parametros_manuales!$F$19*('Plan mensual'!E4+IF(parametros_manuales!$H$19="Todos",'Plan mensual'!E8,0))+parametros_manuales!$G$19*('Plan mensual'!E5+IF(parametros_manuales!$H$19="Todos",'Plan mensual'!E9,0)))*parametros_manuales!$I$19*parametros_manuales!$J$19 -> 590.77721 | D2: =(parametros_manuales!$D$19*('Plan mensual'!F2+IF(parametros_manuales!$H$19="Todos",'Plan mensual'!F6,0))+parametros_manuales!$E$19*('Plan mensual'!F3+IF(parametros_manuales!$H$19="Todos",'Plan mensual'!F7,0))+parametros_manuales!$F$19*('Plan mensual'!F4+IF(parametros_manuales!$H$19="Todos",'Plan mensual'!F8,0))+parametros_manuales!$G$19*('Plan mensual'!F5+IF(parametros_manuales!$H$19="Todos",'Plan mensual'!F9,0)))*parametros_manuales!$I$19*parametros_manuales!$J$19 -> 562.40803 | E2: =(parametros_manuales!$D$19*('Plan mensual'!G2+IF(parametros_manuales!$H$19="Todos",'Plan mensual'!G6,0))+parametros_manuales!$E$19*('Plan mensual'!G3+IF(parametros_manuales!$H$19="Todos",'Plan mensual'!G7,0))+parametros_manuales!$F$19*('Plan mensual'!G4+IF(parametros_manuales!$H$19="Todos",'Plan mensual'!G8,0))+parametros_manuales!$G$19*('Plan mensual'!G5+IF(parametros_manuales!$H$19="Todos",'Plan mensual'!G9,0)))*parametros_manuales!$I$19*parametros_manuales!$J$19 -> 541.51435 | F2: =(parametros_manuales!$D$19*('Plan mensual'!H2+IF(parametros_manuales!$H$19="Todos",'Plan mensual'!H6,0))+parametros_manuales!$E$19*('Plan mensual'!H3+IF(parametros_manuales!$H$19="Todos",'Plan mensual'!H7,0))+parametros_manuales!$F$19*('Plan mensual'!H4+IF(parametros_manuales!$H$19="Todos",'Plan mensual'!H8,0))+parametros_manuales!$G$19*('Plan mensual'!H5+IF(parametros_manuales!$H$19="Todos",'Plan mensual'!H9,0)))*parametros_manuales!$I$19*parametros_manuales!$J$19 -> 507.20248 | G2: =(parametros_manuales!$D$19*('Plan mensual'!I2+IF(parametros_manuales!$H$19="Todos",'Plan mensual'!I6,0))+parametros_manuales!$E$19*('Plan mensual'!I3+IF(parametros_manuales!$H$19="Todos",'Plan mensual'!I7,0))+parametros_manuales!$F$19*('Plan mensual'!I4+IF(parametros_manuales!$H$19="Todos",'Plan mensual'!I8,0))+parametros_manuales!$G$19*('Plan mensual'!I5+IF(parametros_manuales!$H$19="Todos",'Plan mensual'!I9,0)))*parametros_manuales!$I$19*parametros_manuales!$J$19 -> 493.7843 | H2: =(parametros_manuales!$D$19*('Plan mensual'!J2+IF(parametros_manuales!$H$19="Todos",'Plan mensual'!J6,0))+parametros_manuales!$E$19*('Plan mensual'!J3+IF(parametros_manuales!$H$19="Todos",'Plan mensual'!J7,0))+parametros_manuales!$F$19*('Plan mensual'!J4+IF(parametros_manuales!$H$19="Todos",'Plan mensual'!J8,0))+parametros_manuales!$G$19*('Plan mensual'!J5+IF(parametros_manuales!$H$19="Todos",'Plan mensual'!J9,0)))*parametros_manuales!$I$19*parametros_manuales!$J$19 -> 528.09617 | I2: =(parametros_manuales!$D$19*('Plan mensual'!K2+IF(parametros_manuales!$H$19="Todos",'Plan mensual'!K6,0))+parametros_manuales!$E$19*('Plan mensual'!K3+IF(parametros_manuales!$H$19="Todos",'Plan mensual'!K7,0))+parametros_manuales!$F$19*('Plan mensual'!K4+IF(parametros_manuales!$H$19="Todos",'Plan mensual'!K8,0))+parametros_manuales!$G$19*('Plan mensual'!K5+IF(parametros_manuales!$H$19="Todos",'Plan mensual'!K9,0)))*parametros_manuales!$I$19*parametros_manuales!$J$19 -> 528.09617 | ... M2: =(parametros_manuales!$D$19*('Plan mensual'!O2+IF(parametros_manuales!$H$19="Todos",'Plan mensual'!O6,0))+parametros_manuales!$E$19*('Plan mensual'!O3+IF(parametros_manuales!$H$19="Todos",'Plan mensual'!O7,0))+parametros_manuales!$F$19*('Plan mensual'!O4+IF(parametros_manuales!$H$19="Todos",'Plan mensual'!O8,0))+parametros_manuales!$G$19*('Plan mensual'!O5+IF(parametros_manuales!$H$19="Todos",'Plan mensual'!O9,0)))*parametros_manuales!$I$19*parametros_manuales!$J$19 -> 796.64841 | N2: =SUM(B2:M2) -> 6862.3731 | O2: =MAX(B2:M2) -> 796.64841 | P2: =O2/(parametros_manuales!$B$7) -> 5.3109894 | Q2: =IF(O2=0,"-",INDEX($B$1:$M$1,MATCH(O2,B2:M2,0))) -> Dic
