Workbook

Sheet Datos
A1: General
A2: Parámetro | B2: Unidad | C2: Valor | K2: Fuente
A3: Año de análisis | B3: año | C3: 2035 | K3: Año de diseño de la planta
A4: Semanas por mes | B4: sem | C4: 4 | K4: 20 días hábiles ÷ 5 (MP, hoja Volumenes)
A6: Pallet
A7: Parámetro | B7: Unidad | C7: Valor | K7: Fuente
A8: Largo | B8: mm | C8: 1200 | K8: ARLOG IRAM 10016 (MP - Abastecimiento y Almacenamiento, hoja Pallets PT)
A9: Ancho | B9: mm | C9: 1000 | K9: ARLOG IRAM 10016 (MP - Abastecimiento y Almacenamiento, hoja Pallets PT)
A10: Alto | B10: mm | C10: 145 | K10: ARLOG IRAM 10016 (MP - Abastecimiento y Almacenamiento, hoja Pallets PT)
A11: Tara | B11: kg | C11: 35 | K11: ARLOG IRAM 10016 (MP - Abastecimiento y Almacenamiento, hoja Pallets PT)
A12: Altura máxima con la carga | B12: mm | C12: 1600 | K12: Envolvedora EDOS, 1.000 a 1.700 mm (MP - Abastecimiento y Almacenamiento, hoja Pallets PT)
A13: Peso máximo de la carga | B13: kg | C13: 1100 | K13: EDOS 600 a 1.200 kg; ARLOG 1.500 kg (MP - Abastecimiento y Almacenamiento, hoja Pallets PT)
A14: Separador de cartón: espesor | B14: mm | C14: 3 | K14: MP - Abastecimiento y Almacenamiento, hoja Pallets PT (estimación)
A15: Separador de cartón: masa | B15: kg | C15: 0.6 | K15: MP - Abastecimiento y Almacenamiento, hoja Pallets PT (estimación)
A17: Matafuegos manuales en caja
A18: Parámetro | B18: Unidad | C18: 1 kg | D18: 2,5 kg | E18: 5 kg | F18: 10 kg | K18: Fuente
A19: Matafuegos por caja | B19: u | C19: 6 | D19: 1 | E19: 1 | F19: 1 | K19: ET's Matafuegos (MP - Abastecimiento y Almacenamiento, hoja Pallets PT, sección B)
A20: Caja: largo | B20: mm | C20: 265 | D20: 135 | E20: 165 | F20: 195 | K20: MP - Abastecimiento y Almacenamiento, hoja Pallets PT, sección B
A21: Caja: ancho | B21: mm | C21: 190 | D21: 135 | E21: 165 | F21: 195 | K21: MP - Abastecimiento y Almacenamiento, hoja Pallets PT, sección B
A22: Caja: alto | B22: mm | C22: 410 | D22: 435 | E22: 515 | F22: 685 | K22: MP - Abastecimiento y Almacenamiento, hoja Pallets PT, sección B
A23: Caja: tara | B23: kg | C23: 0.35 | D23: 0.25 | E23: 0.35 | F23: 0.5 | K23: MP - Abastecimiento y Almacenamiento, hoja Pallets PT, sección B (estimación)
A24: Matafuego lleno con accesorios | B24: kg | C24: 2.08 | D24: 4.63 | E24: 8.48 | F24: 16.23 | K24: MP - Abastecimiento y Almacenamiento, hoja Pallets PT, sección B
A26: Cilindros vendidos vacíos
A27: Parámetro | B27: Unidad | C27: 1 kg | D27: 2,5 kg | E27: 5 kg | F27: 10 kg | G27: 25 kg | H27: 50 kg | I27: 70 kg | J27: 100 kg | K27: Fuente
A28: Ø | B28: mm | C28: 76.2 | D28: 124 | E28: 153 | F28: 181.5 | G28: 276.5 | H28: 320 | I28: 390 | J28: 390 | K28: MP, hoja Geometria Acero
A29: Alto con tapón | B29: mm | C29: 297.5 | D29: 333 | E29: 414 | F29: 582 | G29: 672 | H29: 858 | I29: 908 | J29: 1128 | K29: MP, hoja Geometria Acero
A30: Masa | B30: kg | C30: 0.76 | D30: 1.48 | E30: 2.78 | F30: 5.48 | G30: 15.92 | H30: 23.3 | I30: 46.861763 | J30: 56.846317 | K30: MP, hoja Geometria Acero
A32: Rodantes terminados
A33: Parámetro | B33: Unidad | C33: 25 kg | D33: 50 kg | E33: 70 kg | F33: 100 kg | K33: Fuente
A34: Carro: largo | B34: mm | C34: 600 | D34: 700 | E34: 800 | F34: 800 | K34: MP - Abastecimiento y Almacenamiento, hoja Pallets PT, sección C
A35: Carro: ancho | B35: mm | C35: 550 | D35: 600 | E35: 700 | F35: 750 | K35: MP - Abastecimiento y Almacenamiento, hoja Pallets PT, sección C
A36: Peso cargado | B36: kg | C36: 55 | D36: 100 | E36: 140 | F36: 185 | K36: Ficha técnica Georgia ABC 90 (FLAMA_BOM, hoja Mercado)
A38: Camión: Sider GyL Full para balancín (carga por los laterales)
A39: Parámetro | B39: Unidad | C39: Valor | K39: Fuente
A40: Largo útil | B40: m | C40: 7.4 | K40: 7,50 m (GyL, agroads.com.ar/detalle.asp?clasi=957986) − 0,10 m (criterio)
A41: Ancho útil | B41: m | C41: 2.46 | K41: 2,60 m (GyL) − 0,14 m de parantes y lonas (criterio)
A42: Carga útil | B42: kg | C42: 12000 | K42: Balancín sider 7,50 m: 12/14 t (logisticashc.com.ar/nosotros/nuestra-flota)
A44: Furgón: Renault Master L3H2 (rodantes)
A45: Parámetro | B45: Unidad | C45: Valor | K45: Fuente
A46: Largo de carga | B46: m | C46: 3.857 | K46: vansdirect.co.uk, Renault Master dimensions
...

Sheet Produccion
A1: Producción anual (Proyecciones 5, hoja Indexado Dim Técnico)
A2: Año | B2: Term. 1 kg | C2: Term. 2,5 kg | D2: Term. 5 kg | E2: Term. 10 kg | F2: Term. 25 kg | G2: Term. 50 kg | H2: Term. 70 kg | I2: Term. 100 kg | J2: Cil. 1 kg | K2: Cil. 2,5 kg | L2: Cil. 5 kg | M2: Cil. 10 kg | N2: Cil. 25 kg | O2: Cil. 50 kg | P2: Cil. 70 kg | Q2: Cil. 100 kg
A3: 2026 | B3: 4178.7365 | C3: 295.03036 | D3: 2255.773 | E3: 91.833182 | F3: 34.051791 | G3: 74.913941 | H3: 16.34486 | I3: 10.896573 | J3: 0 | K3: 0 | L3: 0 | M3: 0 | N3: 0 | O3: 0 | P3: 0 | Q3: 0
A4: 2027 | B4: 5997.304 | C4: 709.72745 | D4: 3846.9789 | E4: 177.2473 | F4: 58.462147 | G4: 128.61672 | H4: 28.061831 | I4: 18.707887 | J4: 0 | K4: 0 | L4: 0 | M4: 0 | N4: 0 | O4: 0 | P4: 0 | Q4: 0
A5: 2028 | B5: 6851.7478 | C5: 986.86806 | D5: 5093.5376 | E5: 252.97878 | F5: 75.20854 | G5: 165.45879 | H5: 36.100099 | I5: 24.066733 | J5: 7662.4 | K5: 299.6 | L5: 1478.8 | M5: 90.4 | N5: 14.4 | O5: 31.8 | P5: 7 | Q5: 4.6
A6: 2029 | B6: 8467.1355 | C6: 1500.6382 | D6: 6823.1153 | E6: 358.02049 | F6: 100.52985 | G6: 221.16568 | H6: 48.254329 | I6: 32.169553 | J6: 26694.8 | K6: 1043.8 | L6: 5152 | M6: 315 | N6: 50.2 | O6: 110.8 | P6: 24.4 | Q6: 16
A7: 2030 | B7: 12680.633 | C7: 2312.6277 | D7: 10819.307 | E7: 602.71815 | F7: 155.876 | G7: 342.92721 | H7: 74.820482 | I7: 49.880321 | J7: 49434.8 | K7: 1933 | L7: 9540.8 | M7: 583.4 | N7: 93 | O7: 205.2 | P7: 45.2 | Q7: 29.6
A8: 2031 | B8: 15620.253 | C8: 3252.8699 | D8: 14605.964 | E8: 872.60503 | F8: 211.93448 | G8: 466.25586 | H8: 101.72855 | I8: 67.819034 | J8: 71680.2 | K8: 2803 | L8: 13834.2 | M8: 845.8 | N8: 135 | O8: 297.6 | P8: 65.4 | Q8: 42.8
A9: 2032 | B9: 20332.553 | C9: 4102.3155 | D9: 18877.76 | E9: 1127.1605 | F9: 272.66823 | G9: 599.87011 | H9: 130.88075 | I9: 87.253835 | J9: 101340.6 | K9: 3963 | L9: 19558.6 | M9: 1195.4 | N9: 191 | O9: 420.8 | P9: 92.2 | Q9: 60.4
A10: 2033 | B10: 25132.078 | C10: 5104.3066 | D10: 23368.186 | E10: 1395.4448 | F10: 337.84867 | G10: 743.26708 | H10: 162.16736 | I10: 108.11157 | J10: 131001 | K10: 5123 | L10: 25283 | M10: 1545 | N10: 247 | O10: 544 | P10: 119 | Q10: 78
A11: 2034 | B11: 28573.336 | C11: 6195.1862 | D11: 26967.725 | E11: 1612.3501 | F11: 393.62742 | G11: 865.98031 | H11: 188.94116 | I11: 125.96077 | J11: 146819.8 | K11: 5741.4 | L11: 28335.8 | M11: 1731.4 | N11: 277 | O11: 609.6 | P11: 133.4 | Q11: 87.6
A12: 2035 | B12: 32072.639 | C12: 7424.8584 | D12: 30750.779 | E12: 1840.8481 | F12: 453.27053 | G12: 997.19517 | H12: 217.56986 | I12: 145.04657 | J12: 170548 | K12: 6669 | L12: 32915 | M12: 2011 | N12: 322 | O12: 708 | P12: 155 | Q12: 102
A13: Año elegido | B13: =INDEX(B3:B12,MATCH(Datos!$C$3,$A$3:$A$12,0)) -> 32072.639 | C13: =INDEX(C3:C12,MATCH(Datos!$C$3,$A$3:$A$12,0)) -> 7424.8584 | D13: =INDEX(D3:D12,MATCH(Datos!$C$3,$A$3:$A$12,0)) -> 30750.779 | E13: =INDEX(E3:E12,MATCH(Datos!$C$3,$A$3:$A$12,0)) -> 1840.8481 | F13: =INDEX(F3:F12,MATCH(Datos!$C$3,$A$3:$A$12,0)) -> 453.27053 | G13: =INDEX(G3:G12,MATCH(Datos!$C$3,$A$3:$A$12,0)) -> 997.19517 | H13: =INDEX(H3:H12,MATCH(Datos!$C$3,$A$3:$A$12,0)) -> 217.56986 | I13: =INDEX(I3:I12,MATCH(Datos!$C$3,$A$3:$A$12,0)) -> 145.04657 | ... Q13: =INDEX(Q3:Q12,MATCH(Datos!$C$3,$A$3:$A$12,0)) -> 102
A14: Perfil | B14: 1 | C14: 2 | D14: 2 | E14: 2 | F14: 3 | G14: 3 | H14: 3 | I14: 3 | J14: 1 | K14: 2 | L14: 2 | M14: 2 | N14: 3 | O14: 3 | P14: 3 | Q14: 3
A16: Estacionalidad (Dimensionamiento Técnico FLAMA, DATOS-BASE filas 102 a 104)
A17: Perfil | B17: Ene | C17: Feb | D17: Mar | E17: Abr | F17: May | G17: Jun | H17: Jul | I17: Ago | J17: Sep | K17: Oct | L17: Nov | M17: Dic | N17: Total
A18: 1. Automovilístico | B18: 0.12 | C18: 0.09 | D18: 0.08 | E18: 0.075 | F18: 0.07 | G18: 0.07 | H18: 0.075 | I18: 0.075 | J18: 0.075 | K18: 0.075 | L18: 0.075 | M18: 0.12 | N18: =SUM(B18:M18) -> 1
A19: 2. Manual comercial | B19: 0.1 | C19: 0.08 | D19: 0.085 | E19: 0.085 | F19: 0.08 | G19: 0.075 | H19: 0.08 | I19: 0.08 | J19: 0.08 | K19: 0.075 | L19: 0.07 | M19: 0.11 | N19: =SUM(B19:M19) -> 1
A20: 3. Industrial sobre ruedas | B20: 0.085 | C20: 0.075 | D20: 0.09 | E20: 0.09 | F20: 0.09 | G20: 0.08 | H20: 0.09 | I20: 0.09 | J20: 0.085 | K20: 0.075 | L20: 0.07 | M20: 0.08 | N20: =SUM(B20:M20) -> 1
A22: Producción por semana del año elegido (u/semana = anual × % del mes ÷ semanas por mes)
A23: Mes | B23: Term. 1 kg | C23: Term. 2,5 kg | D23: Term. 5 kg | E23: Term. 10 kg | F23: Term. 25 kg | G23: Term. 50 kg | H23: Term. 70 kg | I23: Term. 100 kg | J23: Cil. 1 kg | K23: Cil. 2,5 kg | L23: Cil. 5 kg | M23: Cil. 10 kg | N23: Cil. 25 kg | O23: Cil. 50 kg | P23: Cil. 70 kg | Q23: Cil. 100 kg
A24: Ene | B24: =B$13*INDEX($B$18:$M$20,B$14,1)/Datos!$C$4 -> 962.17917 | C24: =C$13*INDEX($B$18:$M$20,C$14,1)/Datos!$C$4 -> 185.62146 | D24: =D$13*INDEX($B$18:$M$20,D$14,1)/Datos!$C$4 -> 768.76947 | E24: =E$13*INDEX($B$18:$M$20,E$14,1)/Datos!$C$4 -> 46.021202 | F24: =F$13*INDEX($B$18:$M$20,F$14,1)/Datos!$C$4 -> 9.6319988 | G24: =G$13*INDEX($B$18:$M$20,G$14,1)/Datos!$C$4 -> 21.190397 | H24: =H$13*INDEX($B$18:$M$20,H$14,1)/Datos!$C$4 -> 4.6233594 | I24: =I$13*INDEX($B$18:$M$20,I$14,1)/Datos!$C$4 -> 3.0822396 | ... Q24: =Q$13*INDEX($B$18:$M$20,Q$14,1)/Datos!$C$4 -> 2.1675
A25: Feb | B25: =B$13*INDEX($B$18:$M$20,B$14,2)/Datos!$C$4 -> 721.63438 | C25: =C$13*INDEX($B$18:$M$20,C$14,2)/Datos!$C$4 -> 148.49717 | D25: =D$13*INDEX($B$18:$M$20,D$14,2)/Datos!$C$4 -> 615.01557 | E25: =E$13*INDEX($B$18:$M$20,E$14,2)/Datos!$C$4 -> 36.816962 | F25: =F$13*INDEX($B$18:$M$20,F$14,2)/Datos!$C$4 -> 8.4988225 | G25: =G$13*INDEX($B$18:$M$20,G$14,2)/Datos!$C$4 -> 18.697409 | H25: =H$13*INDEX($B$18:$M$20,H$14,2)/Datos!$C$4 -> 4.0794348 | I25: =I$13*INDEX($B$18:$M$20,I$14,2)/Datos!$C$4 -> 2.7196232 | ... Q25: =Q$13*INDEX($B$18:$M$20,Q$14,2)/Datos!$C$4 -> 1.9125
A26: Mar | B26: =B$13*INDEX($B$18:$M$20,B$14,3)/Datos!$C$4 -> 641.45278 | C26: =C$13*INDEX($B$18:$M$20,C$14,3)/Datos!$C$4 -> 157.77824 | D26: =D$13*INDEX($B$18:$M$20,D$14,3)/Datos!$C$4 -> 653.45405 | E26: =E$13*INDEX($B$18:$M$20,E$14,3)/Datos!$C$4 -> 39.118022 | F26: =F$13*INDEX($B$18:$M$20,F$14,3)/Datos!$C$4 -> 10.198587 | G26: =G$13*INDEX($B$18:$M$20,G$14,3)/Datos!$C$4 -> 22.436891 | H26: =H$13*INDEX($B$18:$M$20,H$14,3)/Datos!$C$4 -> 4.8953218 | I26: =I$13*INDEX($B$18:$M$20,I$14,3)/Datos!$C$4 -> 3.2635478 | ... Q26: =Q$13*INDEX($B$18:$M$20,Q$14,3)/Datos!$C$4 -> 2.295
A27: Abr | B27: =B$13*INDEX($B$18:$M$20,B$14,4)/Datos!$C$4 -> 601.36198 | C27: =C$13*INDEX($B$18:$M$20,C$14,4)/Datos!$C$4 -> 157.77824 | D27: =D$13*INDEX($B$18:$M$20,D$14,4)/Datos!$C$4 -> 653.45405 | E27: =E$13*INDEX($B$18:$M$20,E$14,4)/Datos!$C$4 -> 39.118022 | F27: =F$13*INDEX($B$18:$M$20,F$14,4)/Datos!$C$4 -> 10.198587 | G27: =G$13*INDEX($B$18:$M$20,G$14,4)/Datos!$C$4 -> 22.436891 | H27: =H$13*INDEX($B$18:$M$20,H$14,4)/Datos!$C$4 -> 4.8953218 | I27: =I$13*INDEX($B$18:$M$20,I$14,4)/Datos!$C$4 -> 3.2635478 | ... Q27: =Q$13*INDEX($B$18:$M$20,Q$14,4)/Datos!$C$4 -> 2.295
A28: May | B28: =B$13*INDEX($B$18:$M$20,B$14,5)/Datos!$C$4 -> 561.27118 | C28: =C$13*INDEX($B$18:$M$20,C$14,5)/Datos!$C$4 -> 148.49717 | D28: =D$13*INDEX($B$18:$M$20,D$14,5)/Datos!$C$4 -> 615.01557 | E28: =E$13*INDEX($B$18:$M$20,E$14,5)/Datos!$C$4 -> 36.816962 | F28: =F$13*INDEX($B$18:$M$20,F$14,5)/Datos!$C$4 -> 10.198587 | G28: =G$13*INDEX($B$18:$M$20,G$14,5)/Datos!$C$4 -> 22.436891 | H28: =H$13*INDEX($B$18:$M$20,H$14,5)/Datos!$C$4 -> 4.8953218 | I28: =I$13*INDEX($B$18:$M$20,I$14,5)/Datos!$C$4 -> 3.2635478 | ... Q28: =Q$13*INDEX($B$18:$M$20,Q$14,5)/Datos!$C$4 -> 2.295
A29: Jun | B29: =B$13*INDEX($B$18:$M$20,B$14,6)/Datos!$C$4 -> 561.27118 | C29: =C$13*INDEX($B$18:$M$20,C$14,6)/Datos!$C$4 -> 139.2161 | D29: =D$13*INDEX($B$18:$M$20,D$14,6)/Datos!$C$4 -> 576.5771 | E29: =E$13*INDEX($B$18:$M$20,E$14,6)/Datos!$C$4 -> 34.515901 | F29: =F$13*INDEX($B$18:$M$20,F$14,6)/Datos!$C$4 -> 9.0654107 | G29: =G$13*INDEX($B$18:$M$20,G$14,6)/Datos!$C$4 -> 19.943903 | H29: =H$13*INDEX($B$18:$M$20,H$14,6)/Datos!$C$4 -> 4.3513971 | I29: =I$13*INDEX($B$18:$M$20,I$14,6)/Datos!$C$4 -> 2.9009314 | ... Q29: =Q$13*INDEX($B$18:$M$20,Q$14,6)/Datos!$C$4 -> 2.04
A30: Jul | B30: =B$13*INDEX($B$18:$M$20,B$14,7)/Datos!$C$4 -> 601.36198 | C30: =C$13*INDEX($B$18:$M$20,C$14,7)/Datos!$C$4 -> 148.49717 | D30: =D$13*INDEX($B$18:$M$20,D$14,7)/Datos!$C$4 -> 615.01557 | E30: =E$13*INDEX($B$18:$M$20,E$14,7)/Datos!$C$4 -> 36.816962 | F30: =F$13*INDEX($B$18:$M$20,F$14,7)/Datos!$C$4 -> 10.198587 | G30: =G$13*INDEX($B$18:$M$20,G$14,7)/Datos!$C$4 -> 22.436891 | H30: =H$13*INDEX($B$18:$M$20,H$14,7)/Datos!$C$4 -> 4.8953218 | I30: =I$13*INDEX($B$18:$M$20,I$14,7)/Datos!$C$4 -> 3.2635478 | ... Q30: =Q$13*INDEX($B$18:$M$20,Q$14,7)/Datos!$C$4 -> 2.295
A31: Ago | B31: =B$13*INDEX($B$18:$M$20,B$14,8)/Datos!$C$4 -> 601.36198 | C31: =C$13*INDEX($B$18:$M$20,C$14,8)/Datos!$C$4 -> 148.49717 | D31: =D$13*INDEX($B$18:$M$20,D$14,8)/Datos!$C$4 -> 615.01557 | E31: =E$13*INDEX($B$18:$M$20,E$14,8)/Datos!$C$4 -> 36.816962 | F31: =F$13*INDEX($B$18:$M$20,F$14,8)/Datos!$C$4 -> 10.198587 | G31: =G$13*INDEX($B$18:$M$20,G$14,8)/Datos!$C$4 -> 22.436891 | H31: =H$13*INDEX($B$18:$M$20,H$14,8)/Datos!$C$4 -> 4.8953218 | I31: =I$13*INDEX($B$18:$M$20,I$14,8)/Datos!$C$4 -> 3.2635478 | ... Q31: =Q$13*INDEX($B$18:$M$20,Q$14,8)/Datos!$C$4 -> 2.295
A32: Sep | B32: =B$13*INDEX($B$18:$M$20,B$14,9)/Datos!$C$4 -> 601.36198 | C32: =C$13*INDEX($B$18:$M$20,C$14,9)/Datos!$C$4 -> 148.49717 | D32: =D$13*INDEX($B$18:$M$20,D$14,9)/Datos!$C$4 -> 615.01557 | E32: =E$13*INDEX($B$18:$M$20,E$14,9)/Datos!$C$4 -> 36.816962 | F32: =F$13*INDEX($B$18:$M$20,F$14,9)/Datos!$C$4 -> 9.6319988 | G32: =G$13*INDEX($B$18:$M$20,G$14,9)/Datos!$C$4 -> 21.190397 | H32: =H$13*INDEX($B$18:$M$20,H$14,9)/Datos!$C$4 -> 4.6233594 | I32: =I$13*INDEX($B$18:$M$20,I$14,9)/Datos!$C$4 -> 3.0822396 | ... Q32: =Q$13*INDEX($B$18:$M$20,Q$14,9)/Datos!$C$4 -> 2.1675
A33: Oct | B33: =B$13*INDEX($B$18:$M$20,B$14,10)/Datos!$C$4 -> 601.36198 | C33: =C$13*INDEX($B$18:$M$20,C$14,10)/Datos!$C$4 -> 139.2161 | D33: =D$13*INDEX($B$18:$M$20,D$14,10)/Datos!$C$4 -> 576.5771 | E33: =E$13*INDEX($B$18:$M$20,E$14,10)/Datos!$C$4 -> 34.515901 | F33: =F$13*INDEX($B$18:$M$20,F$14,10)/Datos!$C$4 -> 8.4988225 | G33: =G$13*INDEX($B$18:$M$20,G$14,10)/Datos!$C$4 -> 18.697409 | H33: =H$13*INDEX($B$18:$M$20,H$14,10)/Datos!$C$4 -> 4.0794348 | I33: =I$13*INDEX($B$18:$M$20,I$14,10)/Datos!$C$4 -> 2.7196232 | ... Q33: =Q$13*INDEX($B$18:$M$20,Q$14,10)/Datos!$C$4 -> 1.9125
A34: Nov | B34: =B$13*INDEX($B$18:$M$20,B$14,11)/Datos!$C$4 -> 601.36198 | C34: =C$13*INDEX($B$18:$M$20,C$14,11)/Datos!$C$4 -> 129.93502 | D34: =D$13*INDEX($B$18:$M$20,D$14,11)/Datos!$C$4 -> 538.13863 | E34: =E$13*INDEX($B$18:$M$20,E$14,11)/Datos!$C$4 -> 32.214841 | F34: =F$13*INDEX($B$18:$M$20,F$14,11)/Datos!$C$4 -> 7.9322343 | G34: =G$13*INDEX($B$18:$M$20,G$14,11)/Datos!$C$4 -> 17.450916 | H34: =H$13*INDEX($B$18:$M$20,H$14,11)/Datos!$C$4 -> 3.8074725 | I34: =I$13*INDEX($B$18:$M$20,I$14,11)/Datos!$C$4 -> 2.538315 | ... Q34: =Q$13*INDEX($B$18:$M$20,Q$14,11)/Datos!$C$4 -> 1.785
A35: Dic | B35: =B$13*INDEX($B$18:$M$20,B$14,12)/Datos!$C$4 -> 962.17917 | C35: =C$13*INDEX($B$18:$M$20,C$14,12)/Datos!$C$4 -> 204.18361 | D35: =D$13*INDEX($B$18:$M$20,D$14,12)/Datos!$C$4 -> 845.64641 | E35: =E$13*INDEX($B$18:$M$20,E$14,12)/Datos!$C$4 -> 50.623322 | F35: =F$13*INDEX($B$18:$M$20,F$14,12)/Datos!$C$4 -> 9.0654107 | G35: =G$13*INDEX($B$18:$M$20,G$14,12)/Datos!$C$4 -> 19.943903 | H35: =H$13*INDEX($B$18:$M$20,H$14,12)/Datos!$C$4 -> 4.3513971 | I35: =I$13*INDEX($B$18:$M$20,I$14,12)/Datos!$C$4 -> 2.9009314 | ... Q35: =Q$13*INDEX($B$18:$M$20,Q$14,12)/Datos!$C$4 -> 2.04
A36: Semana pico | B36: =MAX(B24:B35) -> 962.17917 | C36: =MAX(C24:C35) -> 204.18361 | D36: =MAX(D24:D35) -> 845.64641 | E36: =MAX(E24:E35) -> 50.623322 | F36: =MAX(F24:F35) -> 10.198587 | G36: =MAX(G24:G35) -> 22.436891 | H36: =MAX(H24:H35) -> 4.8953218 | I36: =MAX(I24:I35) -> 3.2635478 | ... Q36: =MAX(Q24:Q35) -> 2.295

Sheet Pallet
A1: Matafuegos manuales en caja
B2: Unidad | C2: 1 kg | D2: 2,5 kg | E2: 5 kg | F2: 10 kg
A3: Peso por caja | B3: kg | C3: =Datos!$C$19*Datos!$C$24+Datos!$C$23 -> 12.83 | D3: =Datos!$D$19*Datos!$D$24+Datos!$D$23 -> 4.88 | E3: =Datos!$E$19*Datos!$E$24+Datos!$E$23 -> 8.83 | F3: =Datos!$F$19*Datos!$F$24+Datos!$F$23 -> 16.73
A4: Cajas a lo largo (1.200) | B4: u | C4: =IF(INT(Datos!$C$8/Datos!$C$20)*INT(Datos!$C$9/Datos!$C$21)>=INT(Datos!$C$8/Datos!$C$21)*INT(Datos!$C$9/Datos!$C$20),INT(Datos!$C$8/Datos!$C$20),INT(Datos!$C$8/Datos!$C$21)) -> 4 | D4: =IF(INT(Datos!$C$8/Datos!$D$20)*INT(Datos!$C$9/Datos!$D$21)>=INT(Datos!$C$8/Datos!$D$21)*INT(Datos!$C$9/Datos!$D$20),INT(Datos!$C$8/Datos!$D$20),INT(Datos!$C$8/Datos!$D$21)) -> 8 | E4: =IF(INT(Datos!$C$8/Datos!$E$20)*INT(Datos!$C$9/Datos!$E$21)>=INT(Datos!$C$8/Datos!$E$21)*INT(Datos!$C$9/Datos!$E$20),INT(Datos!$C$8/Datos!$E$20),INT(Datos!$C$8/Datos!$E$21)) -> 7 | F4: =IF(INT(Datos!$C$8/Datos!$F$20)*INT(Datos!$C$9/Datos!$F$21)>=INT(Datos!$C$8/Datos!$F$21)*INT(Datos!$C$9/Datos!$F$20),INT(Datos!$C$8/Datos!$F$20),INT(Datos!$C$8/Datos!$F$21)) -> 6
A5: Cajas a lo ancho (1.000) | B5: u | C5: =IF(INT(Datos!$C$8/Datos!$C$20)*INT(Datos!$C$9/Datos!$C$21)>=INT(Datos!$C$8/Datos!$C$21)*INT(Datos!$C$9/Datos!$C$20),INT(Datos!$C$9/Datos!$C$21),INT(Datos!$C$9/Datos!$C$20)) -> 5 | D5: =IF(INT(Datos!$C$8/Datos!$D$20)*INT(Datos!$C$9/Datos!$D$21)>=INT(Datos!$C$8/Datos!$D$21)*INT(Datos!$C$9/Datos!$D$20),INT(Datos!$C$9/Datos!$D$21),INT(Datos!$C$9/Datos!$D$20)) -> 7 | E5: =IF(INT(Datos!$C$8/Datos!$E$20)*INT(Datos!$C$9/Datos!$E$21)>=INT(Datos!$C$8/Datos!$E$21)*INT(Datos!$C$9/Datos!$E$20),INT(Datos!$C$9/Datos!$E$21),INT(Datos!$C$9/Datos!$E$20)) -> 6 | F5: =IF(INT(Datos!$C$8/Datos!$F$20)*INT(Datos!$C$9/Datos!$F$21)>=INT(Datos!$C$8/Datos!$F$21)*INT(Datos!$C$9/Datos!$F$20),INT(Datos!$C$9/Datos!$F$21),INT(Datos!$C$9/Datos!$F$20)) -> 5
A6: Cajas por capa | B6: u | C6: =C4*C5 -> 20 | D6: =D4*D5 -> 56 | E6: =E4*E5 -> 42 | F6: =F4*F5 -> 30
A7: Capas por altura | B7: u | C7: =INT((Datos!$C$12-Datos!$C$10)/Datos!$C$22) -> 3 | D7: =INT((Datos!$C$12-Datos!$C$10)/Datos!$D$22) -> 3 | E7: =INT((Datos!$C$12-Datos!$C$10)/Datos!$E$22) -> 2 | F7: =INT((Datos!$C$12-Datos!$C$10)/Datos!$F$22) -> 2
A8: Capas por peso | B8: u | C8: =INT(Datos!$C$13/(C6*C3)) -> 4 | D8: =INT(Datos!$C$13/(D6*D3)) -> 4 | E8: =INT(Datos!$C$13/(E6*E3)) -> 2 | F8: =INT(Datos!$C$13/(F6*F3)) -> 2
A9: Capas | B9: u | C9: =MIN(C7,C8) -> 3 | D9: =MIN(D7,D8) -> 3 | E9: =MIN(E7,E8) -> 2 | F9: =MIN(F7,F8) -> 2
A10: Cajas por pallet | B10: u | C10: =C6*C9 -> 60 | D10: =D6*D9 -> 168 | E10: =E6*E9 -> 84 | F10: =F6*F9 -> 60
A11: Matafuegos por pallet | B11: u | C11: =C10*Datos!$C$19 -> 360 | D11: =D10*Datos!$D$19 -> 168 | E11: =E10*Datos!$E$19 -> 84 | F11: =F10*Datos!$F$19 -> 60
A12: Peso del pallet | B12: kg | C12: =C10*C3+Datos!$C$11 -> 804.8 | D12: =D10*D3+Datos!$C$11 -> 854.84 | E12: =E10*E3+Datos!$C$11 -> 776.72 | F12: =F10*F3+Datos!$C$11 -> 1038.8
A13: Altura del pallet | B13: mm | C13: =Datos!$C$10+C9*Datos!$C$22 -> 1375 | D13: =Datos!$C$10+D9*Datos!$D$22 -> 1450 | E13: =Datos!$C$10+E9*Datos!$E$22 -> 1175 | F13: =Datos!$C$10+F9*Datos!$F$22 -> 1515
A15: Cilindros vendidos vacíos (parados, separador entre capas)
B16: Unidad | C16: 1 kg | D16: 2,5 kg | E16: 5 kg | F16: 10 kg | G16: 25 kg | H16: 50 kg | I16: 70 kg | J16: 100 kg
A17: Cilindros a lo largo (1.200) | B17: u | C17: =INT(Datos!$C$8/Datos!$C$28) -> 15 | D17: =INT(Datos!$C$8/Datos!$D$28) -> 9 | E17: =INT(Datos!$C$8/Datos!$E$28) -> 7 | F17: =INT(Datos!$C$8/Datos!$F$28) -> 6 | G17: =INT(Datos!$C$8/Datos!$G$28) -> 4 | H17: =INT(Datos!$C$8/Datos!$H$28) -> 3 | I17: =INT(Datos!$C$8/Datos!$I$28) -> 3 | J17: =INT(Datos!$C$8/Datos!$J$28) -> 3
A18: Cilindros a lo ancho (1.000) | B18: u | C18: =INT(Datos!$C$9/Datos!$C$28) -> 13 | D18: =INT(Datos!$C$9/Datos!$D$28) -> 8 | E18: =INT(Datos!$C$9/Datos!$E$28) -> 6 | F18: =INT(Datos!$C$9/Datos!$F$28) -> 5 | G18: =INT(Datos!$C$9/Datos!$G$28) -> 3 | H18: =INT(Datos!$C$9/Datos!$H$28) -> 3 | I18: =INT(Datos!$C$9/Datos!$I$28) -> 2 | J18: =INT(Datos!$C$9/Datos!$J$28) -> 2
A19: Cilindros por capa | B19: u | C19: =C17*C18 -> 195 | D19: =D17*D18 -> 72 | E19: =E17*E18 -> 42 | F19: =F17*F18 -> 30 | G19: =G17*G18 -> 12 | H19: =H17*H18 -> 9 | I19: =I17*I18 -> 6 | J19: =J17*J18 -> 6
A20: Capas por altura | B20: u | C20: =INT((Datos!$C$12-Datos!$C$10)/(Datos!$C$29+Datos!$C$14)) -> 4 | D20: =INT((Datos!$C$12-Datos!$C$10)/(Datos!$D$29+Datos!$C$14)) -> 4 | E20: =INT((Datos!$C$12-Datos!$C$10)/(Datos!$E$29+Datos!$C$14)) -> 3 | F20: =INT((Datos!$C$12-Datos!$C$10)/(Datos!$F$29+Datos!$C$14)) -> 2 | G20: =INT((Datos!$C$12-Datos!$C$10)/(Datos!$G$29+Datos!$C$14)) -> 2 | H20: =INT((Datos!$C$12-Datos!$C$10)/(Datos!$H$29+Datos!$C$14)) -> 1 | I20: =INT((Datos!$C$12-Datos!$C$10)/(Datos!$I$29+Datos!$C$14)) -> 1 | J20: =INT((Datos!$C$12-Datos!$C$10)/(Datos!$J$29+Datos!$C$14)) -> 1
A21: Capas por peso | B21: u | C21: =INT(Datos!$C$13/(C19*Datos!$C$30+Datos!$C$15)) -> 7 | D21: =INT(Datos!$C$13/(D19*Datos!$D$30+Datos!$C$15)) -> 10 | E21: =INT(Datos!$C$13/(E19*Datos!$E$30+Datos!$C$15)) -> 9 | F21: =INT(Datos!$C$13/(F19*Datos!$F$30+Datos!$C$15)) -> 6 | G21: =INT(Datos!$C$13/(G19*Datos!$G$30+Datos!$C$15)) -> 5 | H21: =INT(Datos!$C$13/(H19*Datos!$H$30+Datos!$C$15)) -> 5 | I21: =INT(Datos!$C$13/(I19*Datos!$I$30+Datos!$C$15)) -> 3 | J21: =INT(Datos!$C$13/(J19*Datos!$J$30+Datos!$C$15)) -> 3
A22: Capas | B22: u | C22: =MAX(1,MIN(C20,C21)) -> 4 | D22: =MAX(1,MIN(D20,D21)) -> 4 | E22: =MAX(1,MIN(E20,E21)) -> 3 | F22: =MAX(1,MIN(F20,F21)) -> 2 | G22: =MAX(1,MIN(G20,G21)) -> 2 | H22: =MAX(1,MIN(H20,H21)) -> 1 | I22: =MAX(1,MIN(I20,I21)) -> 1 | J22: =MAX(1,MIN(J20,J21)) -> 1
A23: Cilindros por pallet | B23: u | C23: =C19*C22 -> 780 | D23: =D19*D22 -> 288 | E23: =E19*E22 -> 126 | F23: =F19*F22 -> 60 | G23: =G19*G22 -> 24 | H23: =H19*H22 -> 9 | I23: =I19*I22 -> 6 | J23: =J19*J22 -> 6
A24: Peso del pallet | B24: kg | C24: =C23*Datos!$C$30+(C22+1)*Datos!$C$15+Datos!$C$11 -> 630.8 | D24: =D23*Datos!$D$30+(D22+1)*Datos!$C$15+Datos!$C$11 -> 464.24 | E24: =E23*Datos!$E$30+(E22+1)*Datos!$C$15+Datos!$C$11 -> 387.68 | F24: =F23*Datos!$F$30+(F22+1)*Datos!$C$15+Datos!$C$11 -> 365.6 | G24: =G23*Datos!$G$30+(G22+1)*Datos!$C$15+Datos!$C$11 -> 418.88 | H24: =H23*Datos!$H$30+(H22+1)*Datos!$C$15+Datos!$C$11 -> 245.9 | I24: =I23*Datos!$I$30+(I22+1)*Datos!$C$15+Datos!$C$11 -> 317.37058 | J24: =J23*Datos!$J$30+(J22+1)*Datos!$C$15+Datos!$C$11 -> 377.2779
A25: Altura del pallet | B25: mm | C25: =Datos!$C$10+C22*Datos!$C$29+(C22+1)*Datos!$C$14 -> 1350 | D25: =Datos!$C$10+D22*Datos!$D$29+(D22+1)*Datos!$C$14 -> 1492 | E25: =Datos!$C$10+E22*Datos!$E$29+(E22+1)*Datos!$C$14 -> 1399 | F25: =Datos!$C$10+F22*Datos!$F$29+(F22+1)*Datos!$C$14 -> 1318 | G25: =Datos!$C$10+G22*Datos!$G$29+(G22+1)*Datos!$C$14 -> 1498 | H25: =Datos!$C$10+H22*Datos!$H$29+(H22+1)*Datos!$C$14 -> 1009 | I25: =Datos!$C$10+I22*Datos!$I$29+(I22+1)*Datos!$C$14 -> 1059 | J25: =Datos!$C$10+J22*Datos!$J$29+(J22+1)*Datos!$C$14 -> 1279

Sheet Camion
A1: Sider GyL Full para balancín
B2: Unidad | C2: Valor
A3: Pallets a lo largo | B3: u | C3: =IF(INT(Datos!$C$40*1000/Datos!$C$9)*INT(Datos!$C$41*1000/Datos!$C$8)>=INT(Datos!$C$40*1000/Datos!$C$8)*INT(Datos!$C$41*1000/Datos!$C$9),INT(Datos!$C$40*1000/Datos!$C$9),INT(Datos!$C$40*1000/Datos!$C$8)) -> 7
A4: Pallets a lo ancho | B4: u | C4: =IF(INT(Datos!$C$40*1000/Datos!$C$9)*INT(Datos!$C$41*1000/Datos!$C$8)>=INT(Datos!$C$40*1000/Datos!$C$8)*INT(Datos!$C$41*1000/Datos!$C$9),INT(Datos!$C$41*1000/Datos!$C$8),INT(Datos!$C$41*1000/Datos!$C$9)) -> 2
A5: Pallets por camión | B5: u | C5: =C3*C4 -> 14
A7: Renault Master L3H2
B8: Unidad | C8: 25 kg | D8: 50 kg | E8: 70 kg | F8: 100 kg
A9: Carros en la zona delantera | B9: u | C9: =MAX(INT(ROUND((Datos!$C$46-Datos!$C$49-Datos!$C$50)/(Datos!$C$34/1000),6))*INT(ROUND(Datos!$C$47/(Datos!$C$35/1000),6)),INT(ROUND((Datos!$C$46-Datos!$C$49-Datos!$C$50)/(Datos!$C$35/1000),6))*INT(ROUND(Datos!$C$47/(Datos!$C$34/1000),6))) -> 9 | D9: =MAX(INT(ROUND((Datos!$C$46-Datos!$C$49-Datos!$C$50)/(Datos!$D$34/1000),6))*INT(ROUND(Datos!$C$47/(Datos!$D$35/1000),6)),INT(ROUND((Datos!$C$46-Datos!$C$49-Datos!$C$50)/(Datos!$D$35/1000),6))*INT(ROUND(Datos!$C$47/(Datos!$D$34/1000),6))) -> 6 | E9: =MAX(INT(ROUND((Datos!$C$46-Datos!$C$49-Datos!$C$50)/(Datos!$E$34/1000),6))*INT(ROUND(Datos!$C$47/(Datos!$E$35/1000),6)),INT(ROUND((Datos!$C$46-Datos!$C$49-Datos!$C$50)/(Datos!$E$35/1000),6))*INT(ROUND(Datos!$C$47/(Datos!$E$34/1000),6))) -> 6 | F9: =MAX(INT(ROUND((Datos!$C$46-Datos!$C$49-Datos!$C$50)/(Datos!$F$34/1000),6))*INT(ROUND(Datos!$C$47/(Datos!$F$35/1000),6)),INT(ROUND((Datos!$C$46-Datos!$C$49-Datos!$C$50)/(Datos!$F$35/1000),6))*INT(ROUND(Datos!$C$47/(Datos!$F$34/1000),6))) -> 6
A10: Carros entre los pasos de rueda | B10: u | C10: =MAX(INT(ROUND(Datos!$C$49/(Datos!$C$34/1000),6))*INT(ROUND(Datos!$C$48/(Datos!$C$35/1000),6)),INT(ROUND(Datos!$C$49/(Datos!$C$35/1000),6))*INT(ROUND(Datos!$C$48/(Datos!$C$34/1000),6))) -> 2 | D10: =MAX(INT(ROUND(Datos!$C$49/(Datos!$D$34/1000),6))*INT(ROUND(Datos!$C$48/(Datos!$D$35/1000),6)),INT(ROUND(Datos!$C$49/(Datos!$D$35/1000),6))*INT(ROUND(Datos!$C$48/(Datos!$D$34/1000),6))) -> 2 | E10: =MAX(INT(ROUND(Datos!$C$49/(Datos!$E$34/1000),6))*INT(ROUND(Datos!$C$48/(Datos!$E$35/1000),6)),INT(ROUND(Datos!$C$49/(Datos!$E$35/1000),6))*INT(ROUND(Datos!$C$48/(Datos!$E$34/1000),6))) -> 1 | F10: =MAX(INT(ROUND(Datos!$C$49/(Datos!$F$34/1000),6))*INT(ROUND(Datos!$C$48/(Datos!$F$35/1000),6)),INT(ROUND(Datos!$C$49/(Datos!$F$35/1000),6))*INT(ROUND(Datos!$C$48/(Datos!$F$34/1000),6))) -> 1
A11: Carros en la zona trasera | B11: u | C11: =MAX(INT(ROUND(Datos!$C$50/(Datos!$C$34/1000),6))*INT(ROUND(Datos!$C$47/(Datos!$C$35/1000),6)),INT(ROUND(Datos!$C$50/(Datos!$C$35/1000),6))*INT(ROUND(Datos!$C$47/(Datos!$C$34/1000),6))) -> 3 | D11: =MAX(INT(ROUND(Datos!$C$50/(Datos!$D$34/1000),6))*INT(ROUND(Datos!$C$47/(Datos!$D$35/1000),6)),INT(ROUND(Datos!$C$50/(Datos!$D$35/1000),6))*INT(ROUND(Datos!$C$47/(Datos!$D$34/1000),6))) -> 2 | E11: =MAX(INT(ROUND(Datos!$C$50/(Datos!$E$34/1000),6))*INT(ROUND(Datos!$C$47/(Datos!$E$35/1000),6)),INT(ROUND(Datos!$C$50/(Datos!$E$35/1000),6))*INT(ROUND(Datos!$C$47/(Datos!$E$34/1000),6))) -> 0 | F11: =MAX(INT(ROUND(Datos!$C$50/(Datos!$F$34/1000),6))*INT(ROUND(Datos!$C$47/(Datos!$F$35/1000),6)),INT(ROUND(Datos!$C$50/(Datos!$F$35/1000),6))*INT(ROUND(Datos!$C$47/(Datos!$F$34/1000),6))) -> 0
A12: Carros por lugar | B12: u | C12: =SUM(C9:C11) -> 14 | D12: =SUM(D9:D11) -> 10 | E12: =SUM(E9:E11) -> 7 | F12: =SUM(F9:F11) -> 7
A13: Carros por peso | B13: u | C13: =INT(Datos!$C$51/Datos!$C$36) -> 28 | D13: =INT(Datos!$C$51/Datos!$D$36) -> 15 | E13: =INT(Datos!$C$51/Datos!$E$36) -> 11 | F13: =INT(Datos!$C$51/Datos!$F$36) -> 8
A14: Carros por furgón | B14: u | C14: =MIN(C12,C13) -> 14 | D14: =MIN(D12,D13) -> 10 | E14: =MIN(E12,E13) -> 7 | F14: =MIN(F12,F13) -> 7

Sheet Escenarios
A1: Matafuegos manuales en caja (sider)
B2: Unidad | C2: 1. Todo 1 kg | D2: 2. Todo 2,5 kg | E2: 3. Todo 5 kg | F2: 4. Todo 10 kg | G2: 5. Mix 2,5 + 5 + 10
A3: Unidades por pallet | B3: u | C3: =Pallet!C11 -> 360 | D3: =Pallet!D11 -> 168 | E3: =Pallet!E11 -> 84 | F3: =Pallet!F11 -> 60 | G3: por tipo
A4: Peso del pallet | B4: kg | C4: =Pallet!C12 -> 804.8 | D4: =Pallet!D12 -> 854.84 | E4: =Pallet!E12 -> 776.72 | F4: =Pallet!F12 -> 1038.8 | G4: por tipo
A5: Pallets por camión | B5: u | C5: =IF(C4=0,0,MIN(Camion!$C$5,INT(Datos!$C$42/C4))) -> 14 | D5: =IF(D4=0,0,MIN(Camion!$C$5,INT(Datos!$C$42/D4))) -> 14 | E5: =IF(E4=0,0,MIN(Camion!$C$5,INT(Datos!$C$42/E4))) -> 14 | F5: =IF(F4=0,0,MIN(Camion!$C$5,INT(Datos!$C$42/F4))) -> 11 | G5: =$F$28 -> 14
A6: Unidades por viaje | B6: u | C6: =C5*C3 -> 5040 | D6: =D5*D3 -> 2352 | E6: =E5*E3 -> 1176 | F6: =F5*F3 -> 660 | G6: =$F$29 -> 1236
A7: Viajes por semana
A8: Ene | B8: viajes | C8: =IF(C$6=0,0,Produccion!B24/C$6) -> 0.19090857 | D8: =IF(D$6=0,0,Produccion!C24/D$6) -> 0.078920689 | E8: =IF(E$6=0,0,Produccion!D24/E$6) -> 0.65371553 | F8: =IF(F$6=0,0,Produccion!E24/F$6) -> 0.069729094 | G8: =IF($F$28=0,0,(IF(Pallet!D11=0,0,Produccion!C24/Pallet!D11)+IF(Pallet!E11=0,0,Produccion!D24/Pallet!E11)+IF(Pallet!F11=0,0,Produccion!E24/Pallet!F11))/$F$28) -> 0.78742337
A9: Feb | B9: viajes | C9: =IF(C$6=0,0,Produccion!B25/C$6) -> 0.14318142 | D9: =IF(D$6=0,0,Produccion!C25/D$6) -> 0.063136551 | E9: =IF(E$6=0,0,Produccion!D25/E$6) -> 0.52297243 | F9: =IF(F$6=0,0,Produccion!E25/F$6) -> 0.055783275 | G9: =IF($F$28=0,0,(IF(Pallet!D11=0,0,Produccion!C25/Pallet!D11)+IF(Pallet!E11=0,0,Produccion!D25/Pallet!E11)+IF(Pallet!F11=0,0,Produccion!E25/Pallet!F11))/$F$28) -> 0.62993869
A10: Mar | B10: viajes | C10: =IF(C$6=0,0,Produccion!B26/C$6) -> 0.12727238 | D10: =IF(D$6=0,0,Produccion!C26/D$6) -> 0.067082586 | E10: =IF(E$6=0,0,Produccion!D26/E$6) -> 0.5556582 | F10: =IF(F$6=0,0,Produccion!E26/F$6) -> 0.05926973 | G10: =IF($F$28=0,0,(IF(Pallet!D11=0,0,Produccion!C26/Pallet!D11)+IF(Pallet!E11=0,0,Produccion!D26/Pallet!E11)+IF(Pallet!F11=0,0,Produccion!E26/Pallet!F11))/$F$28) -> 0.66930986
A11: Abr | B11: viajes | C11: =IF(C$6=0,0,Produccion!B27/C$6) -> 0.11931785 | D11: =IF(D$6=0,0,Produccion!C27/D$6) -> 0.067082586 | E11: =IF(E$6=0,0,Produccion!D27/E$6) -> 0.5556582 | F11: =IF(F$6=0,0,Produccion!E27/F$6) -> 0.05926973 | G11: =IF($F$28=0,0,(IF(Pallet!D11=0,0,Produccion!C27/Pallet!D11)+IF(Pallet!E11=0,0,Produccion!D27/Pallet!E11)+IF(Pallet!F11=0,0,Produccion!E27/Pallet!F11))/$F$28) -> 0.66930986
A12: May | B12: viajes | C12: =IF(C$6=0,0,Produccion!B28/C$6) -> 0.11136333 | D12: =IF(D$6=0,0,Produccion!C28/D$6) -> 0.063136551 | E12: =IF(E$6=0,0,Produccion!D28/E$6) -> 0.52297243 | F12: =IF(F$6=0,0,Produccion!E28/F$6) -> 0.055783275 | G12: =IF($F$28=0,0,(IF(Pallet!D11=0,0,Produccion!C28/Pallet!D11)+IF(Pallet!E11=0,0,Produccion!D28/Pallet!E11)+IF(Pallet!F11=0,0,Produccion!E28/Pallet!F11))/$F$28) -> 0.62993869
A13: Jun | B13: viajes | C13: =IF(C$6=0,0,Produccion!B29/C$6) -> 0.11136333 | D13: =IF(D$6=0,0,Produccion!C29/D$6) -> 0.059190517 | E13: =IF(E$6=0,0,Produccion!D29/E$6) -> 0.49028665 | F13: =IF(F$6=0,0,Produccion!E29/F$6) -> 0.05229682 | G13: =IF($F$28=0,0,(IF(Pallet!D11=0,0,Produccion!C29/Pallet!D11)+IF(Pallet!E11=0,0,Produccion!D29/Pallet!E11)+IF(Pallet!F11=0,0,Produccion!E29/Pallet!F11))/$F$28) -> 0.59056753
A14: Jul | B14: viajes | C14: =IF(C$6=0,0,Produccion!B30/C$6) -> 0.11931785 | D14: =IF(D$6=0,0,Produccion!C30/D$6) -> 0.063136551 | E14: =IF(E$6=0,0,Produccion!D30/E$6) -> 0.52297243 | F14: =IF(F$6=0,0,Produccion!E30/F$6) -> 0.055783275 | G14: =IF($F$28=0,0,(IF(Pallet!D11=0,0,Produccion!C30/Pallet!D11)+IF(Pallet!E11=0,0,Produccion!D30/Pallet!E11)+IF(Pallet!F11=0,0,Produccion!E30/Pallet!F11))/$F$28) -> 0.62993869
A15: Ago | B15: viajes | C15: =IF(C$6=0,0,Produccion!B31/C$6) -> 0.11931785 | D15: =IF(D$6=0,0,Produccion!C31/D$6) -> 0.063136551 | E15: =IF(E$6=0,0,Produccion!D31/E$6) -> 0.52297243 | F15: =IF(F$6=0,0,Produccion!E31/F$6) -> 0.055783275 | G15: =IF($F$28=0,0,(IF(Pallet!D11=0,0,Produccion!C31/Pallet!D11)+IF(Pallet!E11=0,0,Produccion!D31/Pallet!E11)+IF(Pallet!F11=0,0,Produccion!E31/Pallet!F11))/$F$28) -> 0.62993869
A16: Sep | B16: viajes | C16: =IF(C$6=0,0,Produccion!B32/C$6) -> 0.11931785 | D16: =IF(D$6=0,0,Produccion!C32/D$6) -> 0.063136551 | E16: =IF(E$6=0,0,Produccion!D32/E$6) -> 0.52297243 | F16: =IF(F$6=0,0,Produccion!E32/F$6) -> 0.055783275 | G16: =IF($F$28=0,0,(IF(Pallet!D11=0,0,Produccion!C32/Pallet!D11)+IF(Pallet!E11=0,0,Produccion!D32/Pallet!E11)+IF(Pallet!F11=0,0,Produccion!E32/Pallet!F11))/$F$28) -> 0.62993869
A17: Oct | B17: viajes | C17: =IF(C$6=0,0,Produccion!B33/C$6) -> 0.11931785 | D17: =IF(D$6=0,0,Produccion!C33/D$6) -> 0.059190517 | E17: =IF(E$6=0,0,Produccion!D33/E$6) -> 0.49028665 | F17: =IF(F$6=0,0,Produccion!E33/F$6) -> 0.05229682 | G17: =IF($F$28=0,0,(IF(Pallet!D11=0,0,Produccion!C33/Pallet!D11)+IF(Pallet!E11=0,0,Produccion!D33/Pallet!E11)+IF(Pallet!F11=0,0,Produccion!E33/Pallet!F11))/$F$28) -> 0.59056753
A18: Nov | B18: viajes | C18: =IF(C$6=0,0,Produccion!B34/C$6) -> 0.11931785 | D18: =IF(D$6=0,0,Produccion!C34/D$6) -> 0.055244482 | E18: =IF(E$6=0,0,Produccion!D34/E$6) -> 0.45760087 | F18: =IF(F$6=0,0,Produccion!E34/F$6) -> 0.048810366 | G18: =IF($F$28=0,0,(IF(Pallet!D11=0,0,Produccion!C34/Pallet!D11)+IF(Pallet!E11=0,0,Produccion!D34/Pallet!E11)+IF(Pallet!F11=0,0,Produccion!E34/Pallet!F11))/$F$28) -> 0.55119636
A19: Dic | B19: viajes | C19: =IF(C$6=0,0,Produccion!B35/C$6) -> 0.19090857 | D19: =IF(D$6=0,0,Produccion!C35/D$6) -> 0.086812758 | E19: =IF(E$6=0,0,Produccion!D35/E$6) -> 0.71908709 | F19: =IF(F$6=0,0,Produccion!E35/F$6) -> 0.076702003 | G19: =IF($F$28=0,0,(IF(Pallet!D11=0,0,Produccion!C35/Pallet!D11)+IF(Pallet!E11=0,0,Produccion!D35/Pallet!E11)+IF(Pallet!F11=0,0,Produccion!E35/Pallet!F11))/$F$28) -> 0.86616571
A20: Mes pico | B20: viajes | C20: =MAX(C8:C19) -> 0.19090857 | D20: =MAX(D8:D19) -> 0.086812758 | E20: =MAX(E8:E19) -> 0.71908709 | F20: =MAX(F8:F19) -> 0.076702003 | G20: =MAX(G8:G19) -> 0.86616571
A21: Frecuencia (mes pico) | C21: =IF(C20=0,"-",IF(C20>=1,ROUNDUP(C20,0)&" por semana",IF(INT(1/C20)=1,"1 por semana","1 cada "&INT(1/C20)&" semanas"))) -> 1 cada 5 semanas | D21: =IF(D20=0,"-",IF(D20>=1,ROUNDUP(D20,0)&" por semana",IF(INT(1/D20)=1,"1 por semana","1 cada "&INT(1/D20)&" semanas"))) -> 1 cada 11 semanas | E21: =IF(E20=0,"-",IF(E20>=1,ROUNDUP(E20,0)&" por semana",IF(INT(1/E20)=1,"1 por semana","1 cada "&INT(1/E20)&" semanas"))) -> 1 por semana | F21: =IF(F20=0,"-",IF(F20>=1,ROUNDUP(F20,0)&" por semana",IF(INT(1/F20)=1,"1 por semana","1 cada "&INT(1/F20)&" semanas"))) -> 1 cada 13 semanas | G21: =IF(G20=0,"-",IF(G20>=1,ROUNDUP(G20,0)&" por semana",IF(INT(1/G20)=1,"1 por semana","1 cada "&INT(1/G20)&" semanas"))) -> 1 por semana
A22: Carga del vehículo | B22: % | C22: =IF(C20=0,0,IF(C20>=1,C20/ROUNDUP(C20,0),C20*INT(1/C20))) -> 0.95454283 | D22: =IF(D20=0,0,IF(D20>=1,D20/ROUNDUP(D20,0),D20*INT(1/D20))) -> 0.95494034 | E22: =IF(E20=0,0,IF(E20>=1,E20/ROUNDUP(E20,0),E20*INT(1/E20))) -> 0.71908709 | F22: =IF(F20=0,0,IF(F20>=1,F20/ROUNDUP(F20,0),F20*INT(1/F20))) -> 0.99712604 | G22: =IF(G20=0,0,IF(G20>=1,G20/ROUNDUP(G20,0),G20*INT(1/G20))) -> 0.86616571
A24: 5. Mix: pallets de cada tipo en el camión
B25: Unidad | C25: 2,5 kg | D25: 5 kg | E25: 10 kg | F25: Total
A26: Pallets por semana (pico) | B26: pallets | C26: =IF(Pallet!D11=0,0,Produccion!C36/Pallet!D11) -> 1.2153786 | D26: =IF(Pallet!E11=0,0,Produccion!D36/Pallet!E11) -> 10.067219 | E26: =IF(Pallet!F11=0,0,Produccion!E36/Pallet!F11) -> 0.84372204 | F26: =SUM(C26:E26) -> 12.12632
A27: Participación | B27: % | C27: =IF($F26=0,0,C26/$F26) -> 0.1002265 | D27: =IF($F26=0,0,D26/$F26) -> 0.83019575 | E27: =IF($F26=0,0,E26/$F26) -> 0.069577749 | F27: =SUM(C27:E27) -> 1
A28: Pallets en el camión | B28: pallets | C28: =ROUND(SUM($C27:C27)*$F28,0) -> 1 | D28: =ROUND(SUM($C27:D27)*$F28,0)-ROUND(SUM($C27:C27)*$F28,0) -> 12 | E28: =ROUND(SUM($C27:E27)*$F28,0)-ROUND(SUM($C27:D27)*$F28,0) -> 1 | F28: =IF(F26=0,0,MIN(Camion!$C$5,INT(Datos!$C$42/(C27*Pallet!D12+D27*Pallet!E12+E27*Pallet!F12)))) -> 14
A29: Unidades en el camión | B29: u | C29: =C28*Pallet!D11 -> 168 | D29: =D28*Pallet!E11 -> 1008 | E29: =E28*Pallet!F11 -> 60 | F29: =SUM(C29:E29) -> 1236
A30: Peso en el camión | B30: kg | C30: =C28*Pallet!D12 -> 854.84 | D30: =D28*Pallet!E12 -> 9320.64 | E30: =E28*Pallet!F12 -> 1038.8 | F30: =SUM(C30:E30) -> 11214.28
A33: Rodantes (Master L3H2)
B34: Unidad | C34: 1. Todo 25 kg | D34: 2. Todo 50 kg | E34: 3. Todo 70 kg | F34: 4. Todo 100 kg | G34: 5. Mix 25 a 100
A35: Carros por furgón | B35: u | C35: =Camion!C14 -> 14 | D35: =Camion!D14 -> 10 | E35: =Camion!E14 -> 7 | F35: =Camion!F14 -> 7 | G35: =$G$58 -> 9
A36: Unidades por viaje | B36: u | C36: =C35 -> 14 | D36: =D35 -> 10 | E36: =E35 -> 7 | F36: =F35 -> 7 | G36: =G35 -> 9
A37: Viajes por semana
A38: Ene | B38: viajes | C38: =IF(C$36=0,0,Produccion!F24/C$36) -> 0.68799992 | D38: =IF(D$36=0,0,Produccion!G24/D$36) -> 2.1190397 | E38: =IF(E$36=0,0,Produccion!H24/E$36) -> 0.66047992 | F38: =IF(F$36=0,0,Produccion!I24/F$36) -> 0.44031995 | G38: =IF($G$58=0,0,(Produccion!F24+Produccion!G24+Produccion!H24+Produccion!I24)/$G$58) -> 4.2808884
A39: Feb | B39: viajes | C39: =IF(C$36=0,0,Produccion!F25/C$36) -> 0.60705875 | D39: =IF(D$36=0,0,Produccion!G25/D$36) -> 1.8697409 | E39: =IF(E$36=0,0,Produccion!H25/E$36) -> 0.5827764 | F39: =IF(F$36=0,0,Produccion!I25/F$36) -> 0.3885176 | G39: =IF($G$58=0,0,(Produccion!F25+Produccion!G25+Produccion!H25+Produccion!I25)/$G$58) -> 3.7772544
A40: Mar | B40: viajes | C40: =IF(C$36=0,0,Produccion!F26/C$36) -> 0.7284705 | D40: =IF(D$36=0,0,Produccion!G26/D$36) -> 2.2436891 | E40: =IF(E$36=0,0,Produccion!H26/E$36) -> 0.69933168 | F40: =IF(F$36=0,0,Produccion!I26/F$36) -> 0.46622112 | G40: =IF($G$58=0,0,(Produccion!F26+Produccion!G26+Produccion!H26+Produccion!I26)/$G$58) -> 4.5327053
A41: Abr | B41: viajes | C41: =IF(C$36=0,0,Produccion!F27/C$36) -> 0.7284705 | D41: =IF(D$36=0,0,Produccion!G27/D$36) -> 2.2436891 | E41: =IF(E$36=0,0,Produccion!H27/E$36) -> 0.69933168 | F41: =IF(F$36=0,0,Produccion!I27/F$36) -> 0.46622112 | G41: =IF($G$58=0,0,(Produccion!F27+Produccion!G27+Produccion!H27+Produccion!I27)/$G$58) -> 4.5327053
A42: May | B42: viajes | C42: =IF(C$36=0,0,Produccion!F28/C$36) -> 0.7284705 | D42: =IF(D$36=0,0,Produccion!G28/D$36) -> 2.2436891 | E42: =IF(E$36=0,0,Produccion!H28/E$36) -> 0.69933168 | F42: =IF(F$36=0,0,Produccion!I28/F$36) -> 0.46622112 | G42: =IF($G$58=0,0,(Produccion!F28+Produccion!G28+Produccion!H28+Produccion!I28)/$G$58) -> 4.5327053
A43: Jun | B43: viajes | C43: =IF(C$36=0,0,Produccion!F29/C$36) -> 0.64752933 | D43: =IF(D$36=0,0,Produccion!G29/D$36) -> 1.9943903 | E43: =IF(E$36=0,0,Produccion!H29/E$36) -> 0.62162816 | F43: =IF(F$36=0,0,Produccion!I29/F$36) -> 0.41441877 | G43: =IF($G$58=0,0,(Produccion!F29+Produccion!G29+Produccion!H29+Produccion!I29)/$G$58) -> 4.0290714
...
