Workbook

Sheet Links
A1: Links de los IMPORTRANGE
A2: Pegar en B el link de cada Google Sheet: todos los IMPORTRANGE lo leen de acá.
A3: Archivo | B3: Link | C3: Qué se importa
A4: Aprovechamiento Recargas Planta Comercial | B4: PEGAR ACÁ EL LINK DEL GOOGLE SHEET | C4: Lo que trae la hoja Importados
A5: Aprovechamiento Recargas Planta Industrial | B5: PEGAR ACÁ EL LINK DEL GOOGLE SHEET | C5: Lo que trae la hoja Importados

Sheet Resumen
A1: Recargas — logística de las dos plantas (mes pico de 2035)
A2: Desarrollo y fuentes en el Word de justificación de recargas · § 10
A4: Concepto | B4: Comercial | C4: Industrial | D4: De dónde sale
A5: Recargas del año 2035 (u) | B5: =Importados!$N$22 -> 206230.15 | C5: =Importados!$N$56 -> 107197.37 | D5: Importados
A6: Mes pico | B6: =Cálculo!B6 -> Dic | C6: =Cálculo!C6 -> Dic | D6: Cálculo, punto 1
A7: Llegan por día en el mes pico (u) | B7: =Cálculo!F30 -> 1061.9436 | C7: =Cálculo!I30 -> 552.29771 | D7: Cálculo, punto 2
A8: Sustitutos que salen por día (u) | B8: =Cálculo!G30 -> 409.32481 | C8: =Cálculo!J30 -> 213.04298 | D8: Cálculo, punto 2
A9: Stock de sustitutos (u) | B9: =Importados!$P$22 -> 1498 | C9: =Importados!$P$56 -> 785 | D9: Aprovechamiento, paso 3
A10: Paradas por día | B10: =Cálculo!E44 -> 203.87382 | C10: =Cálculo!I44 -> 105.68545 | D10: Cálculo, punto 3
A11: Viajes por día | B11: =Cálculo!B61 -> 25 | C11: =Cálculo!C61 -> 13 | D11: Cálculo, punto 4
A12: Camiones | B12: =Cálculo!B63 -> 14 | C12: =Cálculo!C63 -> 8 | D12: Cálculo, punto 4
A13: Ocupación de la flota | B13: =Cálculo!B64 -> 0.89046945 | C13: =Cálculo!C64 -> 0.80862012 | D13: Cálculo, punto 4
A14: Posiciones del pulmón | B14: =Cálculo!E74 -> 55 | C14: =Cálculo!I74 -> 29 | D14: Cálculo, punto 5
A15: Superficie del pulmón (m²) | B15: =Cálculo!E75 -> 132 | C15: =Cálculo!I75 -> 69.6 | D15: Cálculo, punto 5
A16: Jaulas A y B a tener | B16: =Cálculo!E77 -> 140 | C16: =Cálculo!I77 -> 81 | D16: Cálculo, punto 5

Sheet Supuestos
A1: Supuestos de logística
A2: Demanda, estacionalidad, mix, lote y sustitutos vienen de Importados · § 10
A3: 1. Camión | B3: Valor | C3: Fuente / criterio
A4: Vehículo | B4: Iveco Daily 55C17 con caja de baranda rebatible | C4: Word de recargas · § 10.1
A5: Carga útil (kg) | B5: 2000 | C5: Word de recargas: aprox. 2 t
A6: Posiciones de jaula 1,2 × 1,0 m en la caja | B6: 6 | C6: 2 × 3 en caja de 3,7 × 2,1 m · § 10.1
A7: Personas a bordo (chofer + ayudante) | B7: 2 | C7: Retiro y colocación de sustitutos · § 10.1
A8: Peso por persona (kg) | B8: 75 | C8: Masa normalizada por ocupante (Dir. 2007/46/CE)
A9: Peso de una jaula (kg) | B9: 75 | C9: Jaula plegable 1,2 × 1,0 m (Palletower Hypacage)
A10: Tara de las jaulas (kg) | B10: =B6*B9 -> 450 | C10: Posiciones × peso de jaula
A11: Carga neta por viaje (kg) | B11: =B5-B7*B8-B10 -> 1400 | C11: Carga útil − personas − jaulas
A12: Precio del camión con caja (ARS) | C12: A cotizar
A14: 2. Recorrido | B14: Valor | C14: Fuente / criterio
A15: Turnos de logística por día | B15: 2 | C15: Los mismos de la planta (Ley 11.544) · § 10.2
A16: Ida y vuelta planta ↔ zona de clientes (h por viaje) | B16: 1.5 | C16: 2 × 25 km (TomTom 2024) · § 10.2
A17: Tiempo fijo por parada (min) | B17: 20 | C17: Criterio · § 10.2
A18: Manejo entre paradas (min) | B18: 15 | C18: 5 km a 20 km/h (TomTom 2024) · § 10.2
A19: Ocupación máxima de la flota | B19: 0.9 | C19: El mismo límite de los puestos · § 8
A21: 3. Pulmón | B21: Valor | C21: Fuente / criterio
A22: Días de llegada que esperan en recepción | B22: 0.5 | C22: Entra en el turno siguiente · § 10.3
A23: Días de recargados que esperan el recorrido | B23: 0.5 | C23: Sale en el turno siguiente · § 10.3
A24: Factor de jaulas a medio llenar | B24: 1.15 | C24: Jaulas por cliente y agente · § 10.3
A25: Jaulas vacías de reserva (% de las ocupadas) | B25: 0.15 | C25: Criterio · § 10.3
A26: Niveles de la estantería de sustitutos | B26: 3 | C26: Criterio · § 10.3
A27: Jaulas vacías apiladas por posición | B27: 4 | C27: Hypacage: apilable de a 4
A28: Superficie por posición con pasillo (m²) | B28: =1.2*1*2 -> 2.4 | C28: Pasillo compartido por dos filas

Sheet Importados
A1: Importados de los Aprovechamientos de recargas (IMPORTRANGE; el link va en la hoja Links)
A3: Planta comercial
A4: Tipo: perfil mensual de recargas (% del año) | B4: Ene | C4: Feb | D4: Mar | E4: Abr | F4: May | G4: Jun | H4: Jul | I4: Ago | J4: Sep | K4: Oct | L4: Nov | M4: Dic | N4: Recargas 2035 (u) | O4: Lleva sustituto (1 = sí) | P4: Stock de sustitutos 2035 (u) | Q4: Automotor | R4: Edificios | S4: Educación | T4: Hoteles | U4: Industrias / almacenes | V4: Salud | W4: Supermercados | X4: Total mix
A5: ABC 1 kg | B5: =IFERROR(__xludf.DUMMYFUNCTION("IMPORTRANGE(Links!$B$4,""parametros_recargas!E55:P72"")"),0.119877958433184) -> 0.11987796 | C5: =IFERROR(__xludf.DUMMYFUNCTION("""COMPUTED_VALUE"""),0.0954780457654631) -> 0.095478046 | D5: =IFERROR(__xludf.DUMMYFUNCTION("""COMPUTED_VALUE"""),0.0711264175844748) -> 0.071126418 | E5: =IFERROR(__xludf.DUMMYFUNCTION("""COMPUTED_VALUE"""),0.0711264175844748) -> 0.071126418 | F5: =IFERROR(__xludf.DUMMYFUNCTION("""COMPUTED_VALUE"""),0.0711747020712071) -> 0.071174702 | G5: =IFERROR(__xludf.DUMMYFUNCTION("""COMPUTED_VALUE"""),0.0711747020712071) -> 0.071174702 | H5: =IFERROR(__xludf.DUMMYFUNCTION("""COMPUTED_VALUE"""),0.0710911890912281) -> 0.071091189 | I5: =IFERROR(__xludf.DUMMYFUNCTION("""COMPUTED_VALUE"""),0.0711747020712071) -> 0.071174702 | J5: =IFERROR(__xludf.DUMMYFUNCTION("""COMPUTED_VALUE"""),0.0711681740744643) -> 0.071168174 | K5: =IFERROR(__xludf.DUMMYFUNCTION("""COMPUTED_VALUE"""),0.0711681740744643) -> 0.071168174 | L5: =IFERROR(__xludf.DUMMYFUNCTION("""COMPUTED_VALUE"""),0.0955198022554526) -> 0.095519802 | M5: =IFERROR(__xludf.DUMMYFUNCTION("""COMPUTED_VALUE"""),0.119919714923173) -> 0.11991971 | N5: =IFERROR(__xludf.DUMMYFUNCTION("IMPORTRANGE(Links!$B$4,""datos_base!K2:K18"")"),108842.626397553) -> 108842.63 | O5: =IFERROR(__xludf.DUMMYFUNCTION("IMPORTRANGE(Links!$B$4,""sobrestock_sustitutos!B30:B46"")"),0) -> 0 | P5: =IFERROR(__xludf.DUMMYFUNCTION("IMPORTRANGE(Links!$B$4,""sobrestock_sustitutos!K51:K67"")"),0) -> 0 | Q5: =IFERROR(__xludf.DUMMYFUNCTION("IMPORTRANGE(Links!$B$4,""PROY_Indexado!B57:H73"")"),2251135) -> 2251135 | R5: =IFERROR(__xludf.DUMMYFUNCTION("""COMPUTED_VALUE"""),0) -> 0 | S5: =IFERROR(__xludf.DUMMYFUNCTION("""COMPUTED_VALUE"""),0) -> 0 | T5: =IFERROR(__xludf.DUMMYFUNCTION("""COMPUTED_VALUE"""),3578.5) -> 3578.5 | U5: =IFERROR(__xludf.DUMMYFUNCTION("""COMPUTED_VALUE"""),0) -> 0 | V5: =IFERROR(__xludf.DUMMYFUNCTION("""COMPUTED_VALUE"""),0) -> 0 | W5: =IFERROR(__xludf.DUMMYFUNCTION("""COMPUTED_VALUE"""),530) -> 530 | X5: =SUM(Q5:W5) -> 2255243.5
A6: ABC 2,5 kg | B6: =IFERROR(__xludf.DUMMYFUNCTION("""COMPUTED_VALUE"""),0.0599939658092665) -> 0.059993966 | C6: =IFERROR(__xludf.DUMMYFUNCTION("""COMPUTED_VALUE"""),0.0599939658092665) -> 0.059993966 | D6: =IFERROR(__xludf.DUMMYFUNCTION("""COMPUTED_VALUE"""),0.0823418371052526) -> 0.082341837 | E6: =IFERROR(__xludf.DUMMYFUNCTION("""COMPUTED_VALUE"""),0.0958991878073455) -> 0.095899188 | F6: =IFERROR(__xludf.DUMMYFUNCTION("""COMPUTED_VALUE"""),0.10379748734495) -> 0.10379749 | G6: =IFERROR(__xludf.DUMMYFUNCTION("""COMPUTED_VALUE"""),0.102624553445736) -> 0.10262455 | H6: =IFERROR(__xludf.DUMMYFUNCTION("""COMPUTED_VALUE"""),0.0742053590647476) -> 0.074205359 | I6: =IFERROR(__xludf.DUMMYFUNCTION("""COMPUTED_VALUE"""),0.0870020477881409) -> 0.087002048 | J6: =IFERROR(__xludf.DUMMYFUNCTION("""COMPUTED_VALUE"""),0.0871913152503224) -> 0.087191315 | K6: =IFERROR(__xludf.DUMMYFUNCTION("""COMPUTED_VALUE"""),0.0871913152503224) -> 0.087191315 | L6: =IFERROR(__xludf.DUMMYFUNCTION("""COMPUTED_VALUE"""),0.0792930157127176) -> 0.079293016 | M6: =IFERROR(__xludf.DUMMYFUNCTION("""COMPUTED_VALUE"""),0.0804659496119317) -> 0.08046595 | N6: =IFERROR(__xludf.DUMMYFUNCTION("""COMPUTED_VALUE"""),9216.54014430766) -> 9216.5401 | O6: =IFERROR(__xludf.DUMMYFUNCTION("""COMPUTED_VALUE"""),1) -> 1 | P6: =IFERROR(__xludf.DUMMYFUNCTION("""COMPUTED_VALUE"""),146) -> 146 | Q6: =IFERROR(__xludf.DUMMYFUNCTION("""COMPUTED_VALUE"""),0) -> 0 | R6: =IFERROR(__xludf.DUMMYFUNCTION("""COMPUTED_VALUE"""),100435.9) -> 100435.9 | S6: =IFERROR(__xludf.DUMMYFUNCTION("""COMPUTED_VALUE"""),14173.8) -> 14173.8 | T6: =IFERROR(__xludf.DUMMYFUNCTION("""COMPUTED_VALUE"""),45655.1) -> 45655.1 | U6: =IFERROR(__xludf.DUMMYFUNCTION("""COMPUTED_VALUE"""),0) -> 0 | V6: =IFERROR(__xludf.DUMMYFUNCTION("""COMPUTED_VALUE"""),7336.9) -> 7336.9 | W6: =IFERROR(__xludf.DUMMYFUNCTION("""COMPUTED_VALUE"""),6153) -> 6153 | X6: =SUM(Q6:W6) -> 173754.7
A7: ABC 5 kg | B7: =IFERROR(__xludf.DUMMYFUNCTION("""COMPUTED_VALUE"""),0.0667556231939292) -> 0.066755623 | C7: =IFERROR(__xludf.DUMMYFUNCTION("""COMPUTED_VALUE"""),0.0651024266252983) -> 0.065102427 | D7: =IFERROR(__xludf.DUMMYFUNCTION("""COMPUTED_VALUE"""),0.0817858344236914) -> 0.081785834 | E7: =IFERROR(__xludf.DUMMYFUNCTION("""COMPUTED_VALUE"""),0.0997196200427302) -> 0.09971962 | F7: =IFERROR(__xludf.DUMMYFUNCTION("""COMPUTED_VALUE"""),0.100089910575874) -> 0.10008991 | G7: =IFERROR(__xludf.DUMMYFUNCTION("""COMPUTED_VALUE"""),0.0988243995547109) -> 0.0988244 | H7: =IFERROR(__xludf.DUMMYFUNCTION("""COMPUTED_VALUE"""),0.0797892781627565) -> 0.079789278 | I7: =IFERROR(__xludf.DUMMYFUNCTION("""COMPUTED_VALUE"""),0.0795925746996675) -> 0.079592575 | J7: =IFERROR(__xludf.DUMMYFUNCTION("""COMPUTED_VALUE"""),0.0807139532651435) -> 0.080713953 | K7: =IFERROR(__xludf.DUMMYFUNCTION("""COMPUTED_VALUE"""),0.0807139532651435) -> 0.080713953 | L7: =IFERROR(__xludf.DUMMYFUNCTION("""COMPUTED_VALUE"""),0.0819968593006307) -> 0.081996859 | M7: =IFERROR(__xludf.DUMMYFUNCTION("""COMPUTED_VALUE"""),0.0849155668904246) -> 0.084915567 | N7: =IFERROR(__xludf.DUMMYFUNCTION("""COMPUTED_VALUE"""),56059.2707104735) -> 56059.271 | O7: =IFERROR(__xludf.DUMMYFUNCTION("""COMPUTED_VALUE"""),1) -> 1 | P7: =IFERROR(__xludf.DUMMYFUNCTION("""COMPUTED_VALUE"""),855) -> 855 | Q7: =IFERROR(__xludf.DUMMYFUNCTION("""COMPUTED_VALUE"""),69628) -> 69628 | R7: =IFERROR(__xludf.DUMMYFUNCTION("""COMPUTED_VALUE"""),732591.4) -> 732591.4 | S7: =IFERROR(__xludf.DUMMYFUNCTION("""COMPUTED_VALUE"""),52786.7) -> 52786.7 | T7: =IFERROR(__xludf.DUMMYFUNCTION("""COMPUTED_VALUE"""),8847.8) -> 8847.8 | U7: =IFERROR(__xludf.DUMMYFUNCTION("""COMPUTED_VALUE"""),113431.7) -> 113431.7 | V7: =IFERROR(__xludf.DUMMYFUNCTION("""COMPUTED_VALUE"""),46903.8) -> 46903.8 | W7: =IFERROR(__xludf.DUMMYFUNCTION("""COMPUTED_VALUE"""),5342) -> 5342 | X7: =SUM(Q7:W7) -> 1029531.4
A8: ABC 10 kg | B8: =IFERROR(__xludf.DUMMYFUNCTION("""COMPUTED_VALUE"""),0.064612341974598) -> 0.064612342 | C8: =IFERROR(__xludf.DUMMYFUNCTION("""COMPUTED_VALUE"""),0.064612341974598) -> 0.064612342 | D8: =IFERROR(__xludf.DUMMYFUNCTION("""COMPUTED_VALUE"""),0.0831857089056497) -> 0.083185709 | E8: =IFERROR(__xludf.DUMMYFUNCTION("""COMPUTED_VALUE"""),0.101329540689849) -> 0.10132954 | F8: =IFERROR(__xludf.DUMMYFUNCTION("""COMPUTED_VALUE"""),0.10227719847342) -> 0.1022772 | G8: =IFERROR(__xludf.DUMMYFUNCTION("""COMPUTED_VALUE"""),0.0993233886074831) -> 0.099323389 | H8: =IFERROR(__xludf.DUMMYFUNCTION("""COMPUTED_VALUE"""),0.078066397641533) -> 0.078066398 | I8: =IFERROR(__xludf.DUMMYFUNCTION("""COMPUTED_VALUE"""),0.078743869594065) -> 0.07874387 | J8: =IFERROR(__xludf.DUMMYFUNCTION("""COMPUTED_VALUE"""),0.081697679460002) -> 0.081697679 | K8: =IFERROR(__xludf.DUMMYFUNCTION("""COMPUTED_VALUE"""),0.081697679460002) -> 0.081697679 | L8: =IFERROR(__xludf.DUMMYFUNCTION("""COMPUTED_VALUE"""),0.0807500216764314) -> 0.080750022 | M8: =IFERROR(__xludf.DUMMYFUNCTION("""COMPUTED_VALUE"""),0.0837038315423683) -> 0.083703832 | N8: =IFERROR(__xludf.DUMMYFUNCTION("""COMPUTED_VALUE"""),3319.32790518283) -> 3319.3279 | O8: =IFERROR(__xludf.DUMMYFUNCTION("""COMPUTED_VALUE"""),1) -> 1 | P8: =IFERROR(__xludf.DUMMYFUNCTION("""COMPUTED_VALUE"""),53) -> 53 | Q8: =IFERROR(__xludf.DUMMYFUNCTION("""COMPUTED_VALUE"""),0) -> 0 | R8: =IFERROR(__xludf.DUMMYFUNCTION("""COMPUTED_VALUE"""),44900.8) -> 44900.8 | S8: =IFERROR(__xludf.DUMMYFUNCTION("""COMPUTED_VALUE"""),5673.3) -> 5673.3 | T8: =IFERROR(__xludf.DUMMYFUNCTION("""COMPUTED_VALUE"""),2123.5) -> 2123.5 | U8: =IFERROR(__xludf.DUMMYFUNCTION("""COMPUTED_VALUE"""),0) -> 0 | V8: =IFERROR(__xludf.DUMMYFUNCTION("""COMPUTED_VALUE"""),6270.5) -> 6270.5 | W8: =IFERROR(__xludf.DUMMYFUNCTION("""COMPUTED_VALUE"""),0) -> 0 | X8: =SUM(Q8:W8) -> 58968.1
A9: Agua 10 l | B9: =IFERROR(__xludf.DUMMYFUNCTION("""COMPUTED_VALUE"""),0.0670768247329043) -> 0.067076825 | C9: =IFERROR(__xludf.DUMMYFUNCTION("""COMPUTED_VALUE"""),0.0670768247329043) -> 0.067076825 | D9: =IFERROR(__xludf.DUMMYFUNCTION("""COMPUTED_VALUE"""),0.0827868661277296) -> 0.082786866 | E9: =IFERROR(__xludf.DUMMYFUNCTION("""COMPUTED_VALUE"""),0.0993493196011858) -> 0.09934932 | F9: =IFERROR(__xludf.DUMMYFUNCTION("""COMPUTED_VALUE"""),0.0999705290370024) -> 0.099970529 | G9: =IFERROR(__xludf.DUMMYFUNCTION("""COMPUTED_VALUE"""),0.0970461916480882) -> 0.097046192 | H9: =IFERROR(__xludf.DUMMYFUNCTION("""COMPUTED_VALUE"""),0.0788828581851096) -> 0.078882858 | I9: =IFERROR(__xludf.DUMMYFUNCTION("""COMPUTED_VALUE"""),0.0790330223001652) -> 0.079033022 | J9: =IFERROR(__xludf.DUMMYFUNCTION("""COMPUTED_VALUE"""),0.0817739112794073) -> 0.081773911 | K9: =IFERROR(__xludf.DUMMYFUNCTION("""COMPUTED_VALUE"""),0.0817739112794073) -> 0.081773911 | L9: =IFERROR(__xludf.DUMMYFUNCTION("""COMPUTED_VALUE"""),0.0811527018435908) -> 0.081152702 | M9: =IFERROR(__xludf.DUMMYFUNCTION("""COMPUTED_VALUE"""),0.084077039232505) -> 0.084077039 | N9: =IFERROR(__xludf.DUMMYFUNCTION("""COMPUTED_VALUE"""),4686.14321768856) -> 4686.1432 | O9: =IFERROR(__xludf.DUMMYFUNCTION("""COMPUTED_VALUE"""),1) -> 1 | P9: =IFERROR(__xludf.DUMMYFUNCTION("""COMPUTED_VALUE"""),73) -> 73 | Q9: =IFERROR(__xludf.DUMMYFUNCTION("""COMPUTED_VALUE"""),0) -> 0 | R9: =IFERROR(__xludf.DUMMYFUNCTION("""COMPUTED_VALUE"""),56716.8) -> 56716.8 | S9: =IFERROR(__xludf.DUMMYFUNCTION("""COMPUTED_VALUE"""),4876.4) -> 4876.4 | T9: =IFERROR(__xludf.DUMMYFUNCTION("""COMPUTED_VALUE"""),1415.6) -> 1415.6 | U9: =IFERROR(__xludf.DUMMYFUNCTION("""COMPUTED_VALUE"""),12568.5) -> 12568.5 | V9: =IFERROR(__xludf.DUMMYFUNCTION("""COMPUTED_VALUE"""),8958.8) -> 8958.8 | W9: =IFERROR(__xludf.DUMMYFUNCTION("""COMPUTED_VALUE"""),562) -> 562 | X9: =SUM(Q9:W9) -> 85098.1
A10: AFFF 10 l | B10: =IFERROR(__xludf.DUMMYFUNCTION("""COMPUTED_VALUE"""),0.0833333333333333) -> 0.083333333 | C10: =IFERROR(__xludf.DUMMYFUNCTION("""COMPUTED_VALUE"""),0.0833333333333333) -> 0.083333333 | D10: =IFERROR(__xludf.DUMMYFUNCTION("""COMPUTED_VALUE"""),0.0833333333333333) -> 0.083333333 | E10: =IFERROR(__xludf.DUMMYFUNCTION("""COMPUTED_VALUE"""),0.0833333333333333) -> 0.083333333 | F10: =IFERROR(__xludf.DUMMYFUNCTION("""COMPUTED_VALUE"""),0.0833333333333333) -> 0.083333333 | G10: =IFERROR(__xludf.DUMMYFUNCTION("""COMPUTED_VALUE"""),0.0833333333333333) -> 0.083333333 | H10: =IFERROR(__xludf.DUMMYFUNCTION("""COMPUTED_VALUE"""),0.0833333333333333) -> 0.083333333 | I10: =IFERROR(__xludf.DUMMYFUNCTION("""COMPUTED_VALUE"""),0.0833333333333333) -> 0.083333333 | ... M10: =IFERROR(__xludf.DUMMYFUNCTION("""COMPUTED_VALUE"""),0.0833333333333333) -> 0.083333333 | N10: =IFERROR(__xludf.DUMMYFUNCTION("""COMPUTED_VALUE"""),889.694438407785) -> 889.69444 | O10: =IFERROR(__xludf.DUMMYFUNCTION("""COMPUTED_VALUE"""),1) -> 1 | P10: =IFERROR(__xludf.DUMMYFUNCTION("""COMPUTED_VALUE"""),12) -> 12 | Q10: =IFERROR(__xludf.DUMMYFUNCTION("""COMPUTED_VALUE"""),0) -> 0 | R10: =IFERROR(__xludf.DUMMYFUNCTION("""COMPUTED_VALUE"""),0) -> 0 | S10: =IFERROR(__xludf.DUMMYFUNCTION("""COMPUTED_VALUE"""),0) -> 0 | T10: =IFERROR(__xludf.DUMMYFUNCTION("""COMPUTED_VALUE"""),0) -> 0 | U10: =IFERROR(__xludf.DUMMYFUNCTION("""COMPUTED_VALUE"""),15671.5) -> 15671.5 | V10: =IFERROR(__xludf.DUMMYFUNCTION("""COMPUTED_VALUE"""),0) -> 0 | W10: =IFERROR(__xludf.DUMMYFUNCTION("""COMPUTED_VALUE"""),0) -> 0 | X10: =SUM(Q10:W10) -> 15671.5
A11: AFFF 50 l s/ruedas | B11: =IFERROR(__xludf.DUMMYFUNCTION("""COMPUTED_VALUE"""),0.0833333333333333) -> 0.083333333 | C11: =IFERROR(__xludf.DUMMYFUNCTION("""COMPUTED_VALUE"""),0.0833333333333333) -> 0.083333333 | D11: =IFERROR(__xludf.DUMMYFUNCTION("""COMPUTED_VALUE"""),0.0833333333333333) -> 0.083333333 | E11: =IFERROR(__xludf.DUMMYFUNCTION("""COMPUTED_VALUE"""),0.0833333333333333) -> 0.083333333 | F11: =IFERROR(__xludf.DUMMYFUNCTION("""COMPUTED_VALUE"""),0.0833333333333333) -> 0.083333333 | G11: =IFERROR(__xludf.DUMMYFUNCTION("""COMPUTED_VALUE"""),0.0833333333333333) -> 0.083333333 | H11: =IFERROR(__xludf.DUMMYFUNCTION("""COMPUTED_VALUE"""),0.0833333333333333) -> 0.083333333 | I11: =IFERROR(__xludf.DUMMYFUNCTION("""COMPUTED_VALUE"""),0.0833333333333333) -> 0.083333333 | ... M11: =IFERROR(__xludf.DUMMYFUNCTION("""COMPUTED_VALUE"""),0.0833333333333333) -> 0.083333333 | N11: =IFERROR(__xludf.DUMMYFUNCTION("""COMPUTED_VALUE"""),463.773030017405) -> 463.77303 | O11: =IFERROR(__xludf.DUMMYFUNCTION("""COMPUTED_VALUE"""),1) -> 1 | P11: =IFERROR(__xludf.DUMMYFUNCTION("""COMPUTED_VALUE"""),6) -> 6 | Q11: =IFERROR(__xludf.DUMMYFUNCTION("""COMPUTED_VALUE"""),0) -> 0 | R11: =IFERROR(__xludf.DUMMYFUNCTION("""COMPUTED_VALUE"""),0) -> 0 | S11: =IFERROR(__xludf.DUMMYFUNCTION("""COMPUTED_VALUE"""),0) -> 0 | T11: =IFERROR(__xludf.DUMMYFUNCTION("""COMPUTED_VALUE"""),0) -> 0 | U11: =IFERROR(__xludf.DUMMYFUNCTION("""COMPUTED_VALUE"""),9151.4) -> 9151.4 | V11: =IFERROR(__xludf.DUMMYFUNCTION("""COMPUTED_VALUE"""),0) -> 0 | W11: =IFERROR(__xludf.DUMMYFUNCTION("""COMPUTED_VALUE"""),0) -> 0 | X11: =SUM(Q11:W11) -> 9151.4
A12: BC 5 kg | B12: =IFERROR(__xludf.DUMMYFUNCTION("""COMPUTED_VALUE"""),0.0833333333333333) -> 0.083333333 | C12: =IFERROR(__xludf.DUMMYFUNCTION("""COMPUTED_VALUE"""),0.0833333333333333) -> 0.083333333 | D12: =IFERROR(__xludf.DUMMYFUNCTION("""COMPUTED_VALUE"""),0.0833333333333333) -> 0.083333333 | E12: =IFERROR(__xludf.DUMMYFUNCTION("""COMPUTED_VALUE"""),0.0833333333333333) -> 0.083333333 | F12: =IFERROR(__xludf.DUMMYFUNCTION("""COMPUTED_VALUE"""),0.0833333333333333) -> 0.083333333 | G12: =IFERROR(__xludf.DUMMYFUNCTION("""COMPUTED_VALUE"""),0.0833333333333333) -> 0.083333333 | H12: =IFERROR(__xludf.DUMMYFUNCTION("""COMPUTED_VALUE"""),0.0833333333333333) -> 0.083333333 | I12: =IFERROR(__xludf.DUMMYFUNCTION("""COMPUTED_VALUE"""),0.0833333333333333) -> 0.083333333 | ... M12: =IFERROR(__xludf.DUMMYFUNCTION("""COMPUTED_VALUE"""),0.0833333333333333) -> 0.083333333 | N12: =IFERROR(__xludf.DUMMYFUNCTION("""COMPUTED_VALUE"""),268.09876141114) -> 268.09876 | O12: =IFERROR(__xludf.DUMMYFUNCTION("""COMPUTED_VALUE"""),1) -> 1 | P12: =IFERROR(__xludf.DUMMYFUNCTION("""COMPUTED_VALUE"""),4) -> 4 | Q12: =IFERROR(__xludf.DUMMYFUNCTION("""COMPUTED_VALUE"""),0) -> 0 | R12: =IFERROR(__xludf.DUMMYFUNCTION("""COMPUTED_VALUE"""),0) -> 0 | S12: =IFERROR(__xludf.DUMMYFUNCTION("""COMPUTED_VALUE"""),0) -> 0 | T12: =IFERROR(__xludf.DUMMYFUNCTION("""COMPUTED_VALUE"""),0) -> 0 | U12: =IFERROR(__xludf.DUMMYFUNCTION("""COMPUTED_VALUE"""),4634.7) -> 4634.7 | V12: =IFERROR(__xludf.DUMMYFUNCTION("""COMPUTED_VALUE"""),0) -> 0 | W12: =IFERROR(__xludf.DUMMYFUNCTION("""COMPUTED_VALUE"""),0) -> 0 | X12: =SUM(Q12:W12) -> 4634.7
A13: Sales K 6 l | B13: =IFERROR(__xludf.DUMMYFUNCTION("""COMPUTED_VALUE"""),0.0695355190499093) -> 0.069535519 | C13: =IFERROR(__xludf.DUMMYFUNCTION("""COMPUTED_VALUE"""),0.0695355190499093) -> 0.069535519 | D13: =IFERROR(__xludf.DUMMYFUNCTION("""COMPUTED_VALUE"""),0.0838248196490894) -> 0.08382482 | E13: =IFERROR(__xludf.DUMMYFUNCTION("""COMPUTED_VALUE"""),0.0948339806026096) -> 0.094833981 | F13: =IFERROR(__xludf.DUMMYFUNCTION("""COMPUTED_VALUE"""),0.0972184056200527) -> 0.097218406 | G13: =IFERROR(__xludf.DUMMYFUNCTION("""COMPUTED_VALUE"""),0.0952240073446056) -> 0.095224007 | H13: =IFERROR(__xludf.DUMMYFUNCTION("""COMPUTED_VALUE"""),0.0780009399043672) -> 0.07800094 | I13: =IFERROR(__xludf.DUMMYFUNCTION("""COMPUTED_VALUE"""),0.0813247334874215) -> 0.081324733 | J13: =IFERROR(__xludf.DUMMYFUNCTION("""COMPUTED_VALUE"""),0.0833191317628686) -> 0.083319132 | K13: =IFERROR(__xludf.DUMMYFUNCTION("""COMPUTED_VALUE"""),0.0833191317628686) -> 0.083319132 | L13: =IFERROR(__xludf.DUMMYFUNCTION("""COMPUTED_VALUE"""),0.0809347067454255) -> 0.080934707 | M13: =IFERROR(__xludf.DUMMYFUNCTION("""COMPUTED_VALUE"""),0.0829291050208727) -> 0.082929105 | N13: =IFERROR(__xludf.DUMMYFUNCTION("""COMPUTED_VALUE"""),2310.99407344162) -> 2310.9941 | O13: =IFERROR(__xludf.DUMMYFUNCTION("""COMPUTED_VALUE"""),1) -> 1 | P13: =IFERROR(__xludf.DUMMYFUNCTION("""COMPUTED_VALUE"""),35) -> 35 | Q13: =IFERROR(__xludf.DUMMYFUNCTION("""COMPUTED_VALUE"""),0) -> 0 | R13: =IFERROR(__xludf.DUMMYFUNCTION("""COMPUTED_VALUE"""),20087.2) -> 20087.2 | S13: =IFERROR(__xludf.DUMMYFUNCTION("""COMPUTED_VALUE"""),4459) -> 4459 | T13: =IFERROR(__xludf.DUMMYFUNCTION("""COMPUTED_VALUE"""),3539.1) -> 3539.1 | U13: =IFERROR(__xludf.DUMMYFUNCTION("""COMPUTED_VALUE"""),8169.7) -> 8169.7 | V13: =IFERROR(__xludf.DUMMYFUNCTION("""COMPUTED_VALUE"""),2804.4) -> 2804.4 | W13: =IFERROR(__xludf.DUMMYFUNCTION("""COMPUTED_VALUE"""),0) -> 0 | X13: =SUM(Q13:W13) -> 39059.4
A14: CO₂ 2 kg | B14: =IFERROR(__xludf.DUMMYFUNCTION("""COMPUTED_VALUE"""),0.0616150736413202) -> 0.061615074 | C14: =IFERROR(__xludf.DUMMYFUNCTION("""COMPUTED_VALUE"""),0.0616150736413202) -> 0.061615074 | D14: =IFERROR(__xludf.DUMMYFUNCTION("""COMPUTED_VALUE"""),0.0829453490803136) -> 0.082945349 | E14: =IFERROR(__xludf.DUMMYFUNCTION("""COMPUTED_VALUE"""),0.103007646651263) -> 0.10300765 | F14: =IFERROR(__xludf.DUMMYFUNCTION("""COMPUTED_VALUE"""),0.103425871740429) -> 0.10342587 | G14: =IFERROR(__xludf.DUMMYFUNCTION("""COMPUTED_VALUE"""),0.102109899624234) -> 0.1021099 | H14: =IFERROR(__xludf.DUMMYFUNCTION("""COMPUTED_VALUE"""),0.0801282894274162) -> 0.080128289 | I14: =IFERROR(__xludf.DUMMYFUNCTION("""COMPUTED_VALUE"""),0.079881877158212) -> 0.079881877 | J14: =IFERROR(__xludf.DUMMYFUNCTION("""COMPUTED_VALUE"""),0.081197849274407) -> 0.081197849 | K14: =IFERROR(__xludf.DUMMYFUNCTION("""COMPUTED_VALUE"""),0.081197849274407) -> 0.081197849 | L14: =IFERROR(__xludf.DUMMYFUNCTION("""COMPUTED_VALUE"""),0.080779624185241) -> 0.080779624 | M14: =IFERROR(__xludf.DUMMYFUNCTION("""COMPUTED_VALUE"""),0.082095596301436) -> 0.082095596 | N14: =IFERROR(__xludf.DUMMYFUNCTION("""COMPUTED_VALUE"""),12606.7299522508) -> 12606.73 | O14: =IFERROR(__xludf.DUMMYFUNCTION("""COMPUTED_VALUE"""),1) -> 1 | P14: =IFERROR(__xludf.DUMMYFUNCTION("""COMPUTED_VALUE"""),199) -> 199 | Q14: =IFERROR(__xludf.DUMMYFUNCTION("""COMPUTED_VALUE"""),0) -> 0 | R14: =IFERROR(__xludf.DUMMYFUNCTION("""COMPUTED_VALUE"""),183147.8) -> 183147.8 | S14: =IFERROR(__xludf.DUMMYFUNCTION("""COMPUTED_VALUE"""),19050.2) -> 19050.2 | T14: =IFERROR(__xludf.DUMMYFUNCTION("""COMPUTED_VALUE"""),3539.1) -> 3539.1 | U14: =IFERROR(__xludf.DUMMYFUNCTION("""COMPUTED_VALUE"""),6402.2) -> 6402.2 | V14: =IFERROR(__xludf.DUMMYFUNCTION("""COMPUTED_VALUE"""),10549.9) -> 10549.9 | W14: =IFERROR(__xludf.DUMMYFUNCTION("""COMPUTED_VALUE"""),0) -> 0 | X14: =SUM(Q14:W14) -> 222689.2
A15: CO₂ 5 kg | B15: =IFERROR(__xludf.DUMMYFUNCTION("""COMPUTED_VALUE"""),0.0761848278176029) -> 0.076184828 | C15: =IFERROR(__xludf.DUMMYFUNCTION("""COMPUTED_VALUE"""),0.0761848278176029) -> 0.076184828 | D15: =IFERROR(__xludf.DUMMYFUNCTION("""COMPUTED_VALUE"""),0.0826686065765467) -> 0.082668607 | E15: =IFERROR(__xludf.DUMMYFUNCTION("""COMPUTED_VALUE"""),0.0916518877640263) -> 0.091651888 | F15: =IFERROR(__xludf.DUMMYFUNCTION("""COMPUTED_VALUE"""),0.0931955183643168) -> 0.093195518 | G15: =IFERROR(__xludf.DUMMYFUNCTION("""COMPUTED_VALUE"""),0.0888541224858191) -> 0.088854122 | H15: =IFERROR(__xludf.DUMMYFUNCTION("""COMPUTED_VALUE"""),0.0784912986070083) -> 0.078491299 | I15: =IFERROR(__xludf.DUMMYFUNCTION("""COMPUTED_VALUE"""),0.0795725784486681) -> 0.079572578 | J15: =IFERROR(__xludf.DUMMYFUNCTION("""COMPUTED_VALUE"""),0.0829855493601231) -> 0.082985549 | K15: =IFERROR(__xludf.DUMMYFUNCTION("""COMPUTED_VALUE"""),0.0829855493601231) -> 0.082985549 | L15: =IFERROR(__xludf.DUMMYFUNCTION("""COMPUTED_VALUE"""),0.0814419187598326) -> 0.081441919 | M15: =IFERROR(__xludf.DUMMYFUNCTION("""COMPUTED_VALUE"""),0.0857833146383303) -> 0.085783315 | N15: =IFERROR(__xludf.DUMMYFUNCTION("""COMPUTED_VALUE"""),4308.38387982745) -> 4308.3839 | O15: =IFERROR(__xludf.DUMMYFUNCTION("""COMPUTED_VALUE"""),1) -> 1 | P15: =IFERROR(__xludf.DUMMYFUNCTION("""COMPUTED_VALUE"""),64) -> 64 | Q15: =IFERROR(__xludf.DUMMYFUNCTION("""COMPUTED_VALUE"""),0) -> 0 | R15: =IFERROR(__xludf.DUMMYFUNCTION("""COMPUTED_VALUE"""),25995.2) -> 25995.2 | S15: =IFERROR(__xludf.DUMMYFUNCTION("""COMPUTED_VALUE"""),891.8) -> 891.8 | T15: =IFERROR(__xludf.DUMMYFUNCTION("""COMPUTED_VALUE"""),1769.6) -> 1769.6 | U15: =IFERROR(__xludf.DUMMYFUNCTION("""COMPUTED_VALUE"""),32678.6) -> 32678.6 | V15: =IFERROR(__xludf.DUMMYFUNCTION("""COMPUTED_VALUE"""),11830.5) -> 11830.5 | W15: =IFERROR(__xludf.DUMMYFUNCTION("""COMPUTED_VALUE"""),2530) -> 2530 | X15: =SUM(Q15:W15) -> 75695.7
A16: HCFC/HFC 5 kg | B16: =IFERROR(__xludf.DUMMYFUNCTION("""COMPUTED_VALUE"""),0.0890943915723948) -> 0.089094392 | C16: =IFERROR(__xludf.DUMMYFUNCTION("""COMPUTED_VALUE"""),0.0890943915723948) -> 0.089094392 | D16: =IFERROR(__xludf.DUMMYFUNCTION("""COMPUTED_VALUE"""),0.0833333333333333) -> 0.083333333 | E16: =IFERROR(__xludf.DUMMYFUNCTION("""COMPUTED_VALUE"""),0.0833333333333333) -> 0.083333333 | F16: =IFERROR(__xludf.DUMMYFUNCTION("""COMPUTED_VALUE"""),0.0833333333333333) -> 0.083333333 | G16: =IFERROR(__xludf.DUMMYFUNCTION("""COMPUTED_VALUE"""),0.0775722750942719) -> 0.077572275 | H16: =IFERROR(__xludf.DUMMYFUNCTION("""COMPUTED_VALUE"""),0.0775722750942719) -> 0.077572275 | I16: =IFERROR(__xludf.DUMMYFUNCTION("""COMPUTED_VALUE"""),0.0775722750942719) -> 0.077572275 | J16: =IFERROR(__xludf.DUMMYFUNCTION("""COMPUTED_VALUE"""),0.0833333333333333) -> 0.083333333 | K16: =IFERROR(__xludf.DUMMYFUNCTION("""COMPUTED_VALUE"""),0.0833333333333333) -> 0.083333333 | L16: =IFERROR(__xludf.DUMMYFUNCTION("""COMPUTED_VALUE"""),0.0833333333333333) -> 0.083333333 | M16: =IFERROR(__xludf.DUMMYFUNCTION("""COMPUTED_VALUE"""),0.0890943915723948) -> 0.089094392 | N16: =IFERROR(__xludf.DUMMYFUNCTION("""COMPUTED_VALUE"""),705.316446113659) -> 705.31645 | O16: =IFERROR(__xludf.DUMMYFUNCTION("""COMPUTED_VALUE"""),1) -> 1 | P16: =IFERROR(__xludf.DUMMYFUNCTION("""COMPUTED_VALUE"""),11) -> 11 | Q16: =IFERROR(__xludf.DUMMYFUNCTION("""COMPUTED_VALUE"""),0) -> 0 | R16: =IFERROR(__xludf.DUMMYFUNCTION("""COMPUTED_VALUE"""),0) -> 0 | S16: =IFERROR(__xludf.DUMMYFUNCTION("""COMPUTED_VALUE"""),0) -> 0 | T16: =IFERROR(__xludf.DUMMYFUNCTION("""COMPUTED_VALUE"""),0) -> 0 | U16: =IFERROR(__xludf.DUMMYFUNCTION("""COMPUTED_VALUE"""),9269.4) -> 9269.4 | V16: =IFERROR(__xludf.DUMMYFUNCTION("""COMPUTED_VALUE"""),2425.5) -> 2425.5 | W16: =IFERROR(__xludf.DUMMYFUNCTION("""COMPUTED_VALUE"""),0) -> 0 | X16: =SUM(Q16:W16) -> 11694.9
A17: Clase D 9 l | B17: =IFERROR(__xludf.DUMMYFUNCTION("""COMPUTED_VALUE"""),0.0833333333333333) -> 0.083333333 | C17: =IFERROR(__xludf.DUMMYFUNCTION("""COMPUTED_VALUE"""),0.0833333333333333) -> 0.083333333 | D17: =IFERROR(__xludf.DUMMYFUNCTION("""COMPUTED_VALUE"""),0.0833333333333333) -> 0.083333333 | E17: =IFERROR(__xludf.DUMMYFUNCTION("""COMPUTED_VALUE"""),0.0833333333333333) -> 0.083333333 | F17: =IFERROR(__xludf.DUMMYFUNCTION("""COMPUTED_VALUE"""),0.0833333333333333) -> 0.083333333 | G17: =IFERROR(__xludf.DUMMYFUNCTION("""COMPUTED_VALUE"""),0.0833333333333333) -> 0.083333333 | H17: =IFERROR(__xludf.DUMMYFUNCTION("""COMPUTED_VALUE"""),0.0833333333333333) -> 0.083333333 | I17: =IFERROR(__xludf.DUMMYFUNCTION("""COMPUTED_VALUE"""),0.0833333333333333) -> 0.083333333 | ... M17: =IFERROR(__xludf.DUMMYFUNCTION("""COMPUTED_VALUE"""),0.0833333333333333) -> 0.083333333 | N17: =IFERROR(__xludf.DUMMYFUNCTION("""COMPUTED_VALUE"""),242.151440335721) -> 242.15144 | O17: =IFERROR(__xludf.DUMMYFUNCTION("""COMPUTED_VALUE"""),1) -> 1 | P17: =IFERROR(__xludf.DUMMYFUNCTION("""COMPUTED_VALUE"""),4) -> 4 | Q17: =IFERROR(__xludf.DUMMYFUNCTION("""COMPUTED_VALUE"""),0) -> 0 | R17: =IFERROR(__xludf.DUMMYFUNCTION("""COMPUTED_VALUE"""),0) -> 0 | S17: =IFERROR(__xludf.DUMMYFUNCTION("""COMPUTED_VALUE"""),0) -> 0 | T17: =IFERROR(__xludf.DUMMYFUNCTION("""COMPUTED_VALUE"""),0) -> 0 | U17: =IFERROR(__xludf.DUMMYFUNCTION("""COMPUTED_VALUE"""),3535) -> 3535 | V17: =IFERROR(__xludf.DUMMYFUNCTION("""COMPUTED_VALUE"""),0) -> 0 | W17: =IFERROR(__xludf.DUMMYFUNCTION("""COMPUTED_VALUE"""),0) -> 0 | X17: =SUM(Q17:W17) -> 3535
A18: ABC 25 kg s/ruedas | B18: =IFERROR(__xludf.DUMMYFUNCTION("""COMPUTED_VALUE"""),0.0741713639081832) -> 0.074171364 | C18: =IFERROR(__xludf.DUMMYFUNCTION("""COMPUTED_VALUE"""),0.0741713639081832) -> 0.074171364 | D18: =IFERROR(__xludf.DUMMYFUNCTION("""COMPUTED_VALUE"""),0.0826308825789044) -> 0.082630883 | E18: =IFERROR(__xludf.DUMMYFUNCTION("""COMPUTED_VALUE"""),0.0938477438743188) -> 0.093847744 | F18: =IFERROR(__xludf.DUMMYFUNCTION("""COMPUTED_VALUE"""),0.0943031990696216) -> 0.094303199 | G18: =IFERROR(__xludf.DUMMYFUNCTION("""COMPUTED_VALUE"""),0.0905972862319092) -> 0.090597286 | H18: =IFERROR(__xludf.DUMMYFUNCTION("""COMPUTED_VALUE"""),0.0782229570370311) -> 0.078222957 | I18: =IFERROR(__xludf.DUMMYFUNCTION("""COMPUTED_VALUE"""),0.0788873099187785) -> 0.07888731 | J18: =IFERROR(__xludf.DUMMYFUNCTION("""COMPUTED_VALUE"""),0.0825932227564908) -> 0.082593223 | K18: =IFERROR(__xludf.DUMMYFUNCTION("""COMPUTED_VALUE"""),0.0825932227564908) -> 0.082593223 | L18: =IFERROR(__xludf.DUMMYFUNCTION("""COMPUTED_VALUE"""),0.082137767561188) -> 0.082137768 | M18: =IFERROR(__xludf.DUMMYFUNCTION("""COMPUTED_VALUE"""),0.0858436803989003) -> 0.08584368 | N18: =IFERROR(__xludf.DUMMYFUNCTION("""COMPUTED_VALUE"""),577.776131502584) -> 577.77613 | O18: =IFERROR(__xludf.DUMMYFUNCTION("""COMPUTED_VALUE"""),1) -> 1 | P18: =IFERROR(__xludf.DUMMYFUNCTION("""COMPUTED_VALUE"""),9) -> 9 | Q18: =IFERROR(__xludf.DUMMYFUNCTION("""COMPUTED_VALUE"""),0) -> 0 | R18: =IFERROR(__xludf.DUMMYFUNCTION("""COMPUTED_VALUE"""),4431) -> 4431 | S18: =IFERROR(__xludf.DUMMYFUNCTION("""COMPUTED_VALUE"""),199.2) -> 199.2 | T18: =IFERROR(__xludf.DUMMYFUNCTION("""COMPUTED_VALUE"""),177) -> 177 | U18: =IFERROR(__xludf.DUMMYFUNCTION("""COMPUTED_VALUE"""),4055.3) -> 4055.3 | V18: =IFERROR(__xludf.DUMMYFUNCTION("""COMPUTED_VALUE"""),1364.4) -> 1364.4 | W18: =IFERROR(__xludf.DUMMYFUNCTION("""COMPUTED_VALUE"""),0) -> 0 | X18: =SUM(Q18:W18) -> 10226.9
A19: ABC 50 kg s/ruedas | B19: =IFERROR(__xludf.DUMMYFUNCTION("""COMPUTED_VALUE"""),0.0741714575622674) -> 0.074171458 | C19: =IFERROR(__xludf.DUMMYFUNCTION("""COMPUTED_VALUE"""),0.0741714575622674) -> 0.074171458 | D19: =IFERROR(__xludf.DUMMYFUNCTION("""COMPUTED_VALUE"""),0.08263095051887) -> 0.082630951 | E19: =IFERROR(__xludf.DUMMYFUNCTION("""COMPUTED_VALUE"""),0.0938477343304375) -> 0.093847734 | F19: =IFERROR(__xludf.DUMMYFUNCTION("""COMPUTED_VALUE"""),0.0943030721576538) -> 0.094303072 | G19: =IFERROR(__xludf.DUMMYFUNCTION("""COMPUTED_VALUE"""),0.0905972613831472) -> 0.090597261 | H19: =IFERROR(__xludf.DUMMYFUNCTION("""COMPUTED_VALUE"""),0.0782232108709845) -> 0.078223211 | I19: =IFERROR(__xludf.DUMMYFUNCTION("""COMPUTED_VALUE"""),0.0788872954792544) -> 0.078887295 | J19: =IFERROR(__xludf.DUMMYFUNCTION("""COMPUTED_VALUE"""),0.082593106253761) -> 0.082593106 | K19: =IFERROR(__xludf.DUMMYFUNCTION("""COMPUTED_VALUE"""),0.082593106253761) -> 0.082593106 | L19: =IFERROR(__xludf.DUMMYFUNCTION("""COMPUTED_VALUE"""),0.0821377684265447) -> 0.082137768 | M19: =IFERROR(__xludf.DUMMYFUNCTION("""COMPUTED_VALUE"""),0.0858435792010512) -> 0.085843579 | N19: =IFERROR(__xludf.DUMMYFUNCTION("""COMPUTED_VALUE"""),1271.10748852936) -> 1271.1075 | O19: =IFERROR(__xludf.DUMMYFUNCTION("""COMPUTED_VALUE"""),1) -> 1 | P19: =IFERROR(__xludf.DUMMYFUNCTION("""COMPUTED_VALUE"""),19) -> 19 | Q19: =IFERROR(__xludf.DUMMYFUNCTION("""COMPUTED_VALUE"""),0) -> 0 | R19: =IFERROR(__xludf.DUMMYFUNCTION("""COMPUTED_VALUE"""),9748.2) -> 9748.2 | S19: =IFERROR(__xludf.DUMMYFUNCTION("""COMPUTED_VALUE"""),438.3) -> 438.3 | T19: =IFERROR(__xludf.DUMMYFUNCTION("""COMPUTED_VALUE"""),389.3) -> 389.3 | U19: =IFERROR(__xludf.DUMMYFUNCTION("""COMPUTED_VALUE"""),8921.8) -> 8921.8 | V19: =IFERROR(__xludf.DUMMYFUNCTION("""COMPUTED_VALUE"""),3001.6) -> 3001.6 | W19: =IFERROR(__xludf.DUMMYFUNCTION("""COMPUTED_VALUE"""),0) -> 0 | X19: =SUM(Q19:W19) -> 22499.2
A20: ABC 70 kg s/ruedas | B20: =IFERROR(__xludf.DUMMYFUNCTION("""COMPUTED_VALUE"""),0.0741714711262728) -> 0.074171471 | C20: =IFERROR(__xludf.DUMMYFUNCTION("""COMPUTED_VALUE"""),0.0741714711262728) -> 0.074171471 | D20: =IFERROR(__xludf.DUMMYFUNCTION("""COMPUTED_VALUE"""),0.0826308668449537) -> 0.082630867 | E20: =IFERROR(__xludf.DUMMYFUNCTION("""COMPUTED_VALUE"""),0.0938479481909226) -> 0.093847948 | F20: =IFERROR(__xludf.DUMMYFUNCTION("""COMPUTED_VALUE"""),0.0943030828496681) -> 0.094303083 | G20: =IFERROR(__xludf.DUMMYFUNCTION("""COMPUTED_VALUE"""),0.0905972288565807) -> 0.090597229 | H20: =IFERROR(__xludf.DUMMYFUNCTION("""COMPUTED_VALUE"""),0.0782233613395939) -> 0.078223361 | I20: =IFERROR(__xludf.DUMMYFUNCTION("""COMPUTED_VALUE"""),0.0788871138035579) -> 0.078887114 | J20: =IFERROR(__xludf.DUMMYFUNCTION("""COMPUTED_VALUE"""),0.0825929677966453) -> 0.082592968 | K20: =IFERROR(__xludf.DUMMYFUNCTION("""COMPUTED_VALUE"""),0.0825929677966453) -> 0.082592968 | L20: =IFERROR(__xludf.DUMMYFUNCTION("""COMPUTED_VALUE"""),0.0821378331378998) -> 0.082137833 | M20: =IFERROR(__xludf.DUMMYFUNCTION("""COMPUTED_VALUE"""),0.0858436871309872) -> 0.085843687 | N20: =IFERROR(__xludf.DUMMYFUNCTION("""COMPUTED_VALUE"""),277.332543143421) -> 277.33254 | O20: =IFERROR(__xludf.DUMMYFUNCTION("""COMPUTED_VALUE"""),1) -> 1 | P20: =IFERROR(__xludf.DUMMYFUNCTION("""COMPUTED_VALUE"""),5) -> 5 | Q20: =IFERROR(__xludf.DUMMYFUNCTION("""COMPUTED_VALUE"""),0) -> 0 | R20: =IFERROR(__xludf.DUMMYFUNCTION("""COMPUTED_VALUE"""),2126.9) -> 2126.9 | S20: =IFERROR(__xludf.DUMMYFUNCTION("""COMPUTED_VALUE"""),95.6) -> 95.6 | T20: =IFERROR(__xludf.DUMMYFUNCTION("""COMPUTED_VALUE"""),84.9) -> 84.9 | U20: =IFERROR(__xludf.DUMMYFUNCTION("""COMPUTED_VALUE"""),1946.6) -> 1946.6 | V20: =IFERROR(__xludf.DUMMYFUNCTION("""COMPUTED_VALUE"""),654.9) -> 654.9 | W20: =IFERROR(__xludf.DUMMYFUNCTION("""COMPUTED_VALUE"""),0) -> 0 | X20: =SUM(Q20:W20) -> 4908.9
A21: ABC 100 kg s/ruedas | B21: =IFERROR(__xludf.DUMMYFUNCTION("""COMPUTED_VALUE"""),0.0741721346584101) -> 0.074172135 | C21: =IFERROR(__xludf.DUMMYFUNCTION("""COMPUTED_VALUE"""),0.0741721346584101) -> 0.074172135 | D21: =IFERROR(__xludf.DUMMYFUNCTION("""COMPUTED_VALUE"""),0.0826312550911103) -> 0.082631255 | E21: =IFERROR(__xludf.DUMMYFUNCTION("""COMPUTED_VALUE"""),0.0938475454254633) -> 0.093847545 | F21: =IFERROR(__xludf.DUMMYFUNCTION("""COMPUTED_VALUE"""),0.0943026800842088) -> 0.09430268 | G21: =IFERROR(__xludf.DUMMYFUNCTION("""COMPUTED_VALUE"""),0.0905968260911214) -> 0.090596826 | H21: =IFERROR(__xludf.DUMMYFUNCTION("""COMPUTED_VALUE"""),0.0782234917229329) -> 0.078223492 | I21: =IFERROR(__xludf.DUMMYFUNCTION("""COMPUTED_VALUE"""),0.0788869863240794) -> 0.078886986 | J21: =IFERROR(__xludf.DUMMYFUNCTION("""COMPUTED_VALUE"""),0.0825928403171668) -> 0.08259284 | K21: =IFERROR(__xludf.DUMMYFUNCTION("""COMPUTED_VALUE"""),0.0825928403171668) -> 0.08259284 | L21: =IFERROR(__xludf.DUMMYFUNCTION("""COMPUTED_VALUE"""),0.0821377056584213) -> 0.082137706 | M21: =IFERROR(__xludf.DUMMYFUNCTION("""COMPUTED_VALUE"""),0.0858435596515087) -> 0.08584356 | N21: =IFERROR(__xludf.DUMMYFUNCTION("""COMPUTED_VALUE"""),184.888361725934) -> 184.88836 | O21: =IFERROR(__xludf.DUMMYFUNCTION("""COMPUTED_VALUE"""),1) -> 1 | P21: =IFERROR(__xludf.DUMMYFUNCTION("""COMPUTED_VALUE"""),3) -> 3 | Q21: =IFERROR(__xludf.DUMMYFUNCTION("""COMPUTED_VALUE"""),0) -> 0 | R21: =IFERROR(__xludf.DUMMYFUNCTION("""COMPUTED_VALUE"""),1417.9) -> 1417.9 | S21: =IFERROR(__xludf.DUMMYFUNCTION("""COMPUTED_VALUE"""),63.8) -> 63.8 | T21: =IFERROR(__xludf.DUMMYFUNCTION("""COMPUTED_VALUE"""),56.6) -> 56.6 | U21: =IFERROR(__xludf.DUMMYFUNCTION("""COMPUTED_VALUE"""),1297.7) -> 1297.7 | V21: =IFERROR(__xludf.DUMMYFUNCTION("""COMPUTED_VALUE"""),436.6) -> 436.6 | W21: =IFERROR(__xludf.DUMMYFUNCTION("""COMPUTED_VALUE"""),0) -> 0 | X21: =SUM(Q21:W21) -> 3272.6
A22: Toda la planta | B22: =IFERROR(__xludf.DUMMYFUNCTION("""COMPUTED_VALUE"""),0.094685974590863) -> 0.094685975 | C22: =IFERROR(__xludf.DUMMYFUNCTION("""COMPUTED_VALUE"""),0.0813589828439731) -> 0.081358983 | D22: =IFERROR(__xludf.DUMMYFUNCTION("""COMPUTED_VALUE"""),0.0763711312806997) -> 0.076371131 | E22: =IFERROR(__xludf.DUMMYFUNCTION("""COMPUTED_VALUE"""),0.084183445923961) -> 0.084183446 | F22: =IFERROR(__xludf.DUMMYFUNCTION("""COMPUTED_VALUE"""),0.0847815688752799) -> 0.084781569 | G22: =IFERROR(__xludf.DUMMYFUNCTION("""COMPUTED_VALUE"""),0.0840164331631308) -> 0.084016433 | H22: =IFERROR(__xludf.DUMMYFUNCTION("""COMPUTED_VALUE"""),0.0748812526033842) -> 0.074881253 | I22: =IFERROR(__xludf.DUMMYFUNCTION("""COMPUTED_VALUE"""),0.0755102802186843) -> 0.07551028 | J22: =IFERROR(__xludf.DUMMYFUNCTION("""COMPUTED_VALUE"""),0.0761652663624608) -> 0.076165266 | K22: =IFERROR(__xludf.DUMMYFUNCTION("""COMPUTED_VALUE"""),0.0761652663624608) -> 0.076165266 | L22: =IFERROR(__xludf.DUMMYFUNCTION("""COMPUTED_VALUE"""),0.0888941351580317) -> 0.088894135 | M22: =IFERROR(__xludf.DUMMYFUNCTION("""COMPUTED_VALUE"""),0.102986262617071) -> 0.10298626 | N22: =SUM(N5:N21) -> 206230.15 | P22: =SUM(P5:P21) -> 1498
A23: Lote por cliente (u.) | Q23: =IFERROR(__xludf.DUMMYFUNCTION("IMPORTRANGE(Links!$B$4,""sobrestock_sustitutos!B18:H18"")"),9) -> 9 | R23: =IFERROR(__xludf.DUMMYFUNCTION("""COMPUTED_VALUE"""),15) -> 15 | S23: =IFERROR(__xludf.DUMMYFUNCTION("""COMPUTED_VALUE"""),12) -> 12 | T23: =IFERROR(__xludf.DUMMYFUNCTION("""COMPUTED_VALUE"""),11) -> 11 | U23: =IFERROR(__xludf.DUMMYFUNCTION("""COMPUTED_VALUE"""),10) -> 10 | V23: =IFERROR(__xludf.DUMMYFUNCTION("""COMPUTED_VALUE"""),61) -> 61 | W23: =IFERROR(__xludf.DUMMYFUNCTION("""COMPUTED_VALUE"""),6) -> 6
A24: Días hábiles por mes | B24: =IFERROR(__xludf.DUMMYFUNCTION("IMPORTRANGE(Links!$B$4,""parametros_recargas!B2"")"),20) -> 20
A25: Horas productivas por turno | B25: =IFERROR(__xludf.DUMMYFUNCTION("IMPORTRANGE(Links!$B$4,""parametros_recargas!B5"")"),7.5) -> 7.5
A27: Rubro: estacionalidad (% del año) | B27: Ene | C27: Feb | D27: Mar | E27: Abr | F27: May | G27: Jun | H27: Jul | I27: Ago | J27: Sep | K27: Oct | L27: Nov | M27: Dic
A28: Automotor | B28: =IFERROR(__xludf.DUMMYFUNCTION("IMPORTRANGE(Links!$B$4,""parametros_recargas!E35:P41"")"),0.12) -> 0.12 | C28: =IFERROR(__xludf.DUMMYFUNCTION("""COMPUTED_VALUE"""),0.0955555555555556) -> 0.095555556 | D28: =IFERROR(__xludf.DUMMYFUNCTION("""COMPUTED_VALUE"""),0.0711111111111111) -> 0.071111111 | E28: =IFERROR(__xludf.DUMMYFUNCTION("""COMPUTED_VALUE"""),0.0711111111111111) -> 0.071111111 | F28: =IFERROR(__xludf.DUMMYFUNCTION("""COMPUTED_VALUE"""),0.0711111111111111) -> 0.071111111 | G28: =IFERROR(__xludf.DUMMYFUNCTION("""COMPUTED_VALUE"""),0.0711111111111111) -> 0.071111111 | H28: =IFERROR(__xludf.DUMMYFUNCTION("""COMPUTED_VALUE"""),0.0711111111111111) -> 0.071111111 | I28: =IFERROR(__xludf.DUMMYFUNCTION("""COMPUTED_VALUE"""),0.0711111111111111) -> 0.071111111 | J28: =IFERROR(__xludf.DUMMYFUNCTION("""COMPUTED_VALUE"""),0.0711111111111111) -> 0.071111111 | K28: =IFERROR(__xludf.DUMMYFUNCTION("""COMPUTED_VALUE"""),0.0711111111111111) -> 0.071111111 | L28: =IFERROR(__xludf.DUMMYFUNCTION("""COMPUTED_VALUE"""),0.0955555555555556) -> 0.095555556 | M28: =IFERROR(__xludf.DUMMYFUNCTION("""COMPUTED_VALUE"""),0.12) -> 0.12
A29: Edificios | B29: =IFERROR(__xludf.DUMMYFUNCTION("""COMPUTED_VALUE"""),0.0540540540540541) -> 0.054054054 | C29: =IFERROR(__xludf.DUMMYFUNCTION("""COMPUTED_VALUE"""),0.0540540540540541) -> 0.054054054 | D29: =IFERROR(__xludf.DUMMYFUNCTION("""COMPUTED_VALUE"""),0.0810810810810811) -> 0.081081081 | E29: =IFERROR(__xludf.DUMMYFUNCTION("""COMPUTED_VALUE"""),0.108108108108108) -> 0.10810811 | F29: =IFERROR(__xludf.DUMMYFUNCTION("""COMPUTED_VALUE"""),0.108108108108108) -> 0.10810811 | G29: =IFERROR(__xludf.DUMMYFUNCTION("""COMPUTED_VALUE"""),0.108108108108108) -> 0.10810811 | H29: =IFERROR(__xludf.DUMMYFUNCTION("""COMPUTED_VALUE"""),0.0810810810810811) -> 0.081081081 | I29: =IFERROR(__xludf.DUMMYFUNCTION("""COMPUTED_VALUE"""),0.0810810810810811) -> 0.081081081 | J29: =IFERROR(__xludf.DUMMYFUNCTION("""COMPUTED_VALUE"""),0.0810810810810811) -> 0.081081081 | K29: =IFERROR(__xludf.DUMMYFUNCTION("""COMPUTED_VALUE"""),0.0810810810810811) -> 0.081081081 | L29: =IFERROR(__xludf.DUMMYFUNCTION("""COMPUTED_VALUE"""),0.0810810810810811) -> 0.081081081 | M29: =IFERROR(__xludf.DUMMYFUNCTION("""COMPUTED_VALUE"""),0.0810810810810811) -> 0.081081081
A30: Educación | B30: =IFERROR(__xludf.DUMMYFUNCTION("""COMPUTED_VALUE"""),0.10126582278481) -> 0.10126582 | C30: =IFERROR(__xludf.DUMMYFUNCTION("""COMPUTED_VALUE"""),0.10126582278481) -> 0.10126582 | D30: =IFERROR(__xludf.DUMMYFUNCTION("""COMPUTED_VALUE"""),0.10126582278481) -> 0.10126582 | E30: =IFERROR(__xludf.DUMMYFUNCTION("""COMPUTED_VALUE"""),0.0759493670886076) -> 0.075949367 | F30: =IFERROR(__xludf.DUMMYFUNCTION("""COMPUTED_VALUE"""),0.0759493670886076) -> 0.075949367 | G30: =IFERROR(__xludf.DUMMYFUNCTION("""COMPUTED_VALUE"""),0.0759493670886076) -> 0.075949367 | H30: =IFERROR(__xludf.DUMMYFUNCTION("""COMPUTED_VALUE"""),0.0886075949367089) -> 0.088607595 | I30: =IFERROR(__xludf.DUMMYFUNCTION("""COMPUTED_VALUE"""),0.0759493670886076) -> 0.075949367 | J30: =IFERROR(__xludf.DUMMYFUNCTION("""COMPUTED_VALUE"""),0.0759493670886076) -> 0.075949367 | K30: =IFERROR(__xludf.DUMMYFUNCTION("""COMPUTED_VALUE"""),0.0759493670886076) -> 0.075949367 | L30: =IFERROR(__xludf.DUMMYFUNCTION("""COMPUTED_VALUE"""),0.0759493670886076) -> 0.075949367 | M30: =IFERROR(__xludf.DUMMYFUNCTION("""COMPUTED_VALUE"""),0.0759493670886076) -> 0.075949367
A31: Hoteles | B31: =IFERROR(__xludf.DUMMYFUNCTION("""COMPUTED_VALUE"""),0.0526315789473684) -> 0.052631579 | C31: =IFERROR(__xludf.DUMMYFUNCTION("""COMPUTED_VALUE"""),0.0526315789473684) -> 0.052631579 | D31: =IFERROR(__xludf.DUMMYFUNCTION("""COMPUTED_VALUE"""),0.0789473684210526) -> 0.078947368 | E31: =IFERROR(__xludf.DUMMYFUNCTION("""COMPUTED_VALUE"""),0.0789473684210526) -> 0.078947368 | F31: =IFERROR(__xludf.DUMMYFUNCTION("""COMPUTED_VALUE"""),0.105263157894737) -> 0.10526316 | G31: =IFERROR(__xludf.DUMMYFUNCTION("""COMPUTED_VALUE"""),0.105263157894737) -> 0.10526316 | H31: =IFERROR(__xludf.DUMMYFUNCTION("""COMPUTED_VALUE"""),0.0526315789473684) -> 0.052631579 | I31: =IFERROR(__xludf.DUMMYFUNCTION("""COMPUTED_VALUE"""),0.105263157894737) -> 0.10526316 | J31: =IFERROR(__xludf.DUMMYFUNCTION("""COMPUTED_VALUE"""),0.105263157894737) -> 0.10526316 | K31: =IFERROR(__xludf.DUMMYFUNCTION("""COMPUTED_VALUE"""),0.105263157894737) -> 0.10526316 | L31: =IFERROR(__xludf.DUMMYFUNCTION("""COMPUTED_VALUE"""),0.0789473684210526) -> 0.078947368 | M31: =IFERROR(__xludf.DUMMYFUNCTION("""COMPUTED_VALUE"""),0.0789473684210526) -> 0.078947368
A32: Industrias / almacenes | B32: =IFERROR(__xludf.DUMMYFUNCTION("""COMPUTED_VALUE"""),0.0833333333333333) -> 0.083333333 | C32: =IFERROR(__xludf.DUMMYFUNCTION("""COMPUTED_VALUE"""),0.0833333333333333) -> 0.083333333 | D32: =IFERROR(__xludf.DUMMYFUNCTION("""COMPUTED_VALUE"""),0.0833333333333333) -> 0.083333333 | E32: =IFERROR(__xludf.DUMMYFUNCTION("""COMPUTED_VALUE"""),0.0833333333333333) -> 0.083333333 | F32: =IFERROR(__xludf.DUMMYFUNCTION("""COMPUTED_VALUE"""),0.0833333333333333) -> 0.083333333 | G32: =IFERROR(__xludf.DUMMYFUNCTION("""COMPUTED_VALUE"""),0.0833333333333333) -> 0.083333333 | H32: =IFERROR(__xludf.DUMMYFUNCTION("""COMPUTED_VALUE"""),0.0833333333333333) -> 0.083333333 | I32: =IFERROR(__xludf.DUMMYFUNCTION("""COMPUTED_VALUE"""),0.0833333333333333) -> 0.083333333 | ... M32: =IFERROR(__xludf.DUMMYFUNCTION("""COMPUTED_VALUE"""),0.0833333333333333) -> 0.083333333
A33: Salud | B33: =IFERROR(__xludf.DUMMYFUNCTION("""COMPUTED_VALUE"""),0.111111111111111) -> 0.11111111 | C33: =IFERROR(__xludf.DUMMYFUNCTION("""COMPUTED_VALUE"""),0.111111111111111) -> 0.11111111 | D33: =IFERROR(__xludf.DUMMYFUNCTION("""COMPUTED_VALUE"""),0.0833333333333333) -> 0.083333333 | E33: =IFERROR(__xludf.DUMMYFUNCTION("""COMPUTED_VALUE"""),0.0833333333333333) -> 0.083333333 | F33: =IFERROR(__xludf.DUMMYFUNCTION("""COMPUTED_VALUE"""),0.0833333333333333) -> 0.083333333 | G33: =IFERROR(__xludf.DUMMYFUNCTION("""COMPUTED_VALUE"""),0.0555555555555556) -> 0.055555556 | H33: =IFERROR(__xludf.DUMMYFUNCTION("""COMPUTED_VALUE"""),0.0555555555555556) -> 0.055555556 | I33: =IFERROR(__xludf.DUMMYFUNCTION("""COMPUTED_VALUE"""),0.0555555555555556) -> 0.055555556 | J33: =IFERROR(__xludf.DUMMYFUNCTION("""COMPUTED_VALUE"""),0.0833333333333333) -> 0.083333333 | K33: =IFERROR(__xludf.DUMMYFUNCTION("""COMPUTED_VALUE"""),0.0833333333333333) -> 0.083333333 | L33: =IFERROR(__xludf.DUMMYFUNCTION("""COMPUTED_VALUE"""),0.0833333333333333) -> 0.083333333 | M33: =IFERROR(__xludf.DUMMYFUNCTION("""COMPUTED_VALUE"""),0.111111111111111) -> 0.11111111
A34: Supermercados | B34: =IFERROR(__xludf.DUMMYFUNCTION("""COMPUTED_VALUE"""),0.0555555555555556) -> 0.055555556 | C34: =IFERROR(__xludf.DUMMYFUNCTION("""COMPUTED_VALUE"""),0.0555555555555556) -> 0.055555556 | D34: =IFERROR(__xludf.DUMMYFUNCTION("""COMPUTED_VALUE"""),0.0833333333333333) -> 0.083333333 | E34: =IFERROR(__xludf.DUMMYFUNCTION("""COMPUTED_VALUE"""),0.0833333333333333) -> 0.083333333 | F34: =IFERROR(__xludf.DUMMYFUNCTION("""COMPUTED_VALUE"""),0.111111111111111) -> 0.11111111 | G34: =IFERROR(__xludf.DUMMYFUNCTION("""COMPUTED_VALUE"""),0.111111111111111) -> 0.11111111 | H34: =IFERROR(__xludf.DUMMYFUNCTION("""COMPUTED_VALUE"""),0.111111111111111) -> 0.11111111 | I34: =IFERROR(__xludf.DUMMYFUNCTION("""COMPUTED_VALUE"""),0.111111111111111) -> 0.11111111 | J34: =IFERROR(__xludf.DUMMYFUNCTION("""COMPUTED_VALUE"""),0.0833333333333333) -> 0.083333333 | K34: =IFERROR(__xludf.DUMMYFUNCTION("""COMPUTED_VALUE"""),0.0833333333333333) -> 0.083333333 | L34: =IFERROR(__xludf.DUMMYFUNCTION("""COMPUTED_VALUE"""),0.0555555555555556) -> 0.055555556 | M34: =IFERROR(__xludf.DUMMYFUNCTION("""COMPUTED_VALUE"""),0.0555555555555556) -> 0.055555556
A37: Planta industrial
A38: Tipo: perfil mensual de recargas (% del año) | B38: Ene | C38: Feb | D38: Mar | E38: Abr | F38: May | G38: Jun | H38: Jul | I38: Ago | J38: Sep | K38: Oct | L38: Nov | M38: Dic | N38: Recargas 2035 (u) | O38: Lleva sustituto (1 = sí) | P38: Stock de sustitutos 2035 (u) | Q38: Automotor | R38: Edificios | S38: Educación | T38: Hoteles | U38: Industrias / almacenes | V38: Salud | W38: Supermercados | X38: Total mix
A39: ABC 1 kg | B39: =IFERROR(__xludf.DUMMYFUNCTION("IMPORTRANGE(Links!$B$5,""parametros_recargas!E55:P72"")"),0.119895289559294) -> 0.11989529 | C39: =IFERROR(__xludf.DUMMYFUNCTION("""COMPUTED_VALUE"""),0.0954891339827875) -> 0.095489134 | D39: =IFERROR(__xludf.DUMMYFUNCTION("""COMPUTED_VALUE"""),0.071124604952686) -> 0.071124605 | E39: =IFERROR(__xludf.DUMMYFUNCTION("""COMPUTED_VALUE"""),0.071124604952686) -> 0.071124605 | F39: =IFERROR(__xludf.DUMMYFUNCTION("""COMPUTED_VALUE"""),0.0711662314990906) -> 0.071166231 | G39: =IFERROR(__xludf.DUMMYFUNCTION("""COMPUTED_VALUE"""),0.0711662314990906) -> 0.071166231 | H39: =IFERROR(__xludf.DUMMYFUNCTION("""COMPUTED_VALUE"""),0.0710984243903592) -> 0.071098424 | I39: =IFERROR(__xludf.DUMMYFUNCTION("""COMPUTED_VALUE"""),0.0711662314990906) -> 0.071166231 | J39: =IFERROR(__xludf.DUMMYFUNCTION("""COMPUTED_VALUE"""),0.0711585085070517) -> 0.071158509 | K39: =IFERROR(__xludf.DUMMYFUNCTION("""COMPUTED_VALUE"""),0.0711585085070517) -> 0.071158509 | L39: =IFERROR(__xludf.DUMMYFUNCTION("""COMPUTED_VALUE"""),0.0955230375371532) -> 0.095523038 | M39: =IFERROR(__xludf.DUMMYFUNCTION("""COMPUTED_VALUE"""),0.119929193113659) -> 0.11992919 | N39: =IFERROR(__xludf.DUMMYFUNCTION("IMPORTRANGE(Links!$B$5,""datos_base!K2:K18"")"),56575.8368575054) -> 56575.837 | O39: =IFERROR(__xludf.DUMMYFUNCTION("IMPORTRANGE(Links!$B$5,""sobrestock_sustitutos!B30:B46"")"),0) -> 0 | P39: =IFERROR(__xludf.DUMMYFUNCTION("IMPORTRANGE(Links!$B$5,""sobrestock_sustitutos!K51:K67"")"),0) -> 0 | Q39: =IFERROR(__xludf.DUMMYFUNCTION("IMPORTRANGE(Links!$B$5,""PROY_Indexado!B57:H73"")"),1188664) -> 1188664 | R39: =IFERROR(__xludf.DUMMYFUNCTION("""COMPUTED_VALUE"""),0) -> 0 | S39: =IFERROR(__xludf.DUMMYFUNCTION("""COMPUTED_VALUE"""),0) -> 0 | T39: =IFERROR(__xludf.DUMMYFUNCTION("""COMPUTED_VALUE"""),1533.8) -> 1533.8 | U39: =IFERROR(__xludf.DUMMYFUNCTION("""COMPUTED_VALUE"""),0) -> 0 | V39: =IFERROR(__xludf.DUMMYFUNCTION("""COMPUTED_VALUE"""),0) -> 0 | W39: =IFERROR(__xludf.DUMMYFUNCTION("""COMPUTED_VALUE"""),331) -> 331 | X39: =SUM(Q39:W39) -> 1190528.8
A40: ABC 2,5 kg | B40: =IFERROR(__xludf.DUMMYFUNCTION("""COMPUTED_VALUE"""),0.0608346558815601) -> 0.060834656 | C40: =IFERROR(__xludf.DUMMYFUNCTION("""COMPUTED_VALUE"""),0.0608346558815601) -> 0.060834656 | D40: =IFERROR(__xludf.DUMMYFUNCTION("""COMPUTED_VALUE"""),0.082643351275423) -> 0.082643351 | E40: =IFERROR(__xludf.DUMMYFUNCTION("""COMPUTED_VALUE"""),0.0953382202836263) -> 0.09533822 | F40: =IFERROR(__xludf.DUMMYFUNCTION("""COMPUTED_VALUE"""),0.103308847602848) -> 0.10330885 | G40: =IFERROR(__xludf.DUMMYFUNCTION("""COMPUTED_VALUE"""),0.10204440072004) -> 0.1020444 | H40: =IFERROR(__xludf.DUMMYFUNCTION("""COMPUTED_VALUE"""),0.0745034484311485) -> 0.074503448 | I40: =IFERROR(__xludf.DUMMYFUNCTION("""COMPUTED_VALUE"""),0.0869418857625907) -> 0.086941886 | J40: =IFERROR(__xludf.DUMMYFUNCTION("""COMPUTED_VALUE"""),0.0870568354792096) -> 0.087056835 | K40: =IFERROR(__xludf.DUMMYFUNCTION("""COMPUTED_VALUE"""),0.0870568354792096) -> 0.087056835 | L40: =IFERROR(__xludf.DUMMYFUNCTION("""COMPUTED_VALUE"""),0.0790862081599875) -> 0.079086208 | M40: =IFERROR(__xludf.DUMMYFUNCTION("""COMPUTED_VALUE"""),0.080350655042796) -> 0.080350655 | N40: =IFERROR(__xludf.DUMMYFUNCTION("""COMPUTED_VALUE"""),4790.71011839089) -> 4790.7101 | O40: =IFERROR(__xludf.DUMMYFUNCTION("""COMPUTED_VALUE"""),1) -> 1 | P40: =IFERROR(__xludf.DUMMYFUNCTION("""COMPUTED_VALUE"""),76) -> 76 | Q40: =IFERROR(__xludf.DUMMYFUNCTION("""COMPUTED_VALUE"""),0) -> 0 | R40: =IFERROR(__xludf.DUMMYFUNCTION("""COMPUTED_VALUE"""),51231.6) -> 51231.6 | S40: =IFERROR(__xludf.DUMMYFUNCTION("""COMPUTED_VALUE"""),8719.2) -> 8719.2 | T40: =IFERROR(__xludf.DUMMYFUNCTION("""COMPUTED_VALUE"""),23764.4) -> 23764.4 | U40: =IFERROR(__xludf.DUMMYFUNCTION("""COMPUTED_VALUE"""),0) -> 0 | V40: =IFERROR(__xludf.DUMMYFUNCTION("""COMPUTED_VALUE"""),4173.4) -> 4173.4 | W40: =IFERROR(__xludf.DUMMYFUNCTION("""COMPUTED_VALUE"""),3794) -> 3794 | X40: =SUM(Q40:W40) -> 91682.6
A41: ABC 5 kg | B41: =IFERROR(__xludf.DUMMYFUNCTION("""COMPUTED_VALUE"""),0.0669778155176287) -> 0.066977816 | C41: =IFERROR(__xludf.DUMMYFUNCTION("""COMPUTED_VALUE"""),0.0652614335824934) -> 0.065261434 | D41: =IFERROR(__xludf.DUMMYFUNCTION("""COMPUTED_VALUE"""),0.0819248891202413) -> 0.081924889 | E41: =IFERROR(__xludf.DUMMYFUNCTION("""COMPUTED_VALUE"""),0.0996461832727322) -> 0.099646183 | F41: =IFERROR(__xludf.DUMMYFUNCTION("""COMPUTED_VALUE"""),0.100150076298148) -> 0.10015008 | G41: =IFERROR(__xludf.DUMMYFUNCTION("""COMPUTED_VALUE"""),0.0987344570187928) -> 0.098734457 | H41: =IFERROR(__xludf.DUMMYFUNCTION("""COMPUTED_VALUE"""),0.0795692614778467) -> 0.079569261 | I41: =IFERROR(__xludf.DUMMYFUNCTION("""COMPUTED_VALUE"""),0.0794428932919701) -> 0.079442893 | J41: =IFERROR(__xludf.DUMMYFUNCTION("""COMPUTED_VALUE"""),0.0806840028465543) -> 0.080684003 | K41: =IFERROR(__xludf.DUMMYFUNCTION("""COMPUTED_VALUE"""),0.0806840028465543) -> 0.080684003 | L41: =IFERROR(__xludf.DUMMYFUNCTION("""COMPUTED_VALUE"""),0.0818964917562743) -> 0.081896492 | M41: =IFERROR(__xludf.DUMMYFUNCTION("""COMPUTED_VALUE"""),0.0850284929707643) -> 0.085028493 | N41: =IFERROR(__xludf.DUMMYFUNCTION("""COMPUTED_VALUE"""),29139.3203107948) -> 29139.32 | O41: =IFERROR(__xludf.DUMMYFUNCTION("""COMPUTED_VALUE"""),1) -> 1 | P41: =IFERROR(__xludf.DUMMYFUNCTION("""COMPUTED_VALUE"""),446) -> 446 | Q41: =IFERROR(__xludf.DUMMYFUNCTION("""COMPUTED_VALUE"""),36760) -> 36760 | R41: =IFERROR(__xludf.DUMMYFUNCTION("""COMPUTED_VALUE"""),373689.5) -> 373689.5 | S41: =IFERROR(__xludf.DUMMYFUNCTION("""COMPUTED_VALUE"""),32472.3) -> 32472.3 | T41: =IFERROR(__xludf.DUMMYFUNCTION("""COMPUTED_VALUE"""),6552.8) -> 6552.8 | U41: =IFERROR(__xludf.DUMMYFUNCTION("""COMPUTED_VALUE"""),44086.3) -> 44086.3 | V41: =IFERROR(__xludf.DUMMYFUNCTION("""COMPUTED_VALUE"""),26680.3) -> 26680.3 | W41: =IFERROR(__xludf.DUMMYFUNCTION("""COMPUTED_VALUE"""),3289) -> 3289 | X41: =SUM(Q41:W41) -> 523530.2
A42: ABC 10 kg | B42: =IFERROR(__xludf.DUMMYFUNCTION("""COMPUTED_VALUE"""),0.0656624516770873) -> 0.065662452 | C42: =IFERROR(__xludf.DUMMYFUNCTION("""COMPUTED_VALUE"""),0.0656624516770873) -> 0.065662452 | D42: =IFERROR(__xludf.DUMMYFUNCTION("""COMPUTED_VALUE"""),0.0834634227222184) -> 0.083463423 | E42: =IFERROR(__xludf.DUMMYFUNCTION("""COMPUTED_VALUE"""),0.100292059397134) -> 0.10029206 | F42: =IFERROR(__xludf.DUMMYFUNCTION("""COMPUTED_VALUE"""),0.101604548245527) -> 0.10160455 | G42: =IFERROR(__xludf.DUMMYFUNCTION("""COMPUTED_VALUE"""),0.0984624354955731) -> 0.098462435 | H42: =IFERROR(__xludf.DUMMYFUNCTION("""COMPUTED_VALUE"""),0.0776078419879838) -> 0.077607842 | I42: =IFERROR(__xludf.DUMMYFUNCTION("""COMPUTED_VALUE"""),0.0788318405488818) -> 0.078831841 | J42: =IFERROR(__xludf.DUMMYFUNCTION("""COMPUTED_VALUE"""),0.0819739532988352) -> 0.081973953 | K42: =IFERROR(__xludf.DUMMYFUNCTION("""COMPUTED_VALUE"""),0.0819739532988352) -> 0.081973953 | L42: =IFERROR(__xludf.DUMMYFUNCTION("""COMPUTED_VALUE"""),0.0806614644504421) -> 0.080661464 | M42: =IFERROR(__xludf.DUMMYFUNCTION("""COMPUTED_VALUE"""),0.0838035772003955) -> 0.083803577 | N42: =IFERROR(__xludf.DUMMYFUNCTION("""COMPUTED_VALUE"""),1725.36955653994) -> 1725.3696 | O42: =IFERROR(__xludf.DUMMYFUNCTION("""COMPUTED_VALUE"""),1) -> 1 | P42: =IFERROR(__xludf.DUMMYFUNCTION("""COMPUTED_VALUE"""),28) -> 28 | Q42: =IFERROR(__xludf.DUMMYFUNCTION("""COMPUTED_VALUE"""),0) -> 0 | R42: =IFERROR(__xludf.DUMMYFUNCTION("""COMPUTED_VALUE"""),22903.5) -> 22903.5 | S42: =IFERROR(__xludf.DUMMYFUNCTION("""COMPUTED_VALUE"""),3490) -> 3490 | T42: =IFERROR(__xludf.DUMMYFUNCTION("""COMPUTED_VALUE"""),1572.7) -> 1572.7 | U42: =IFERROR(__xludf.DUMMYFUNCTION("""COMPUTED_VALUE"""),0) -> 0 | V42: =IFERROR(__xludf.DUMMYFUNCTION("""COMPUTED_VALUE"""),3566.9) -> 3566.9 | W42: =IFERROR(__xludf.DUMMYFUNCTION("""COMPUTED_VALUE"""),0) -> 0 | X42: =SUM(Q42:W42) -> 31533.1
A43: Agua 10 l | B43: =IFERROR(__xludf.DUMMYFUNCTION("""COMPUTED_VALUE"""),0.0671288961017088) -> 0.067128896 | C43: =IFERROR(__xludf.DUMMYFUNCTION("""COMPUTED_VALUE"""),0.0671288961017088) -> 0.067128896 | D43: =IFERROR(__xludf.DUMMYFUNCTION("""COMPUTED_VALUE"""),0.082960331994099) -> 0.082960332 | E43: =IFERROR(__xludf.DUMMYFUNCTION("""COMPUTED_VALUE"""),0.0994555948834204) -> 0.099455595 | F43: =IFERROR(__xludf.DUMMYFUNCTION("""COMPUTED_VALUE"""),0.100324801949947) -> 0.1003248 | G43: =IFERROR(__xludf.DUMMYFUNCTION("""COMPUTED_VALUE"""),0.0970172977837637) -> 0.097017298 | H43: =IFERROR(__xludf.DUMMYFUNCTION("""COMPUTED_VALUE"""),0.0783455208911489) -> 0.078345521 | I43: =IFERROR(__xludf.DUMMYFUNCTION("""COMPUTED_VALUE"""),0.078747564791717) -> 0.078747565 | J43: =IFERROR(__xludf.DUMMYFUNCTION("""COMPUTED_VALUE"""),0.0818305013673391) -> 0.081830501 | K43: =IFERROR(__xludf.DUMMYFUNCTION("""COMPUTED_VALUE"""),0.0818305013673391) -> 0.081830501 | L43: =IFERROR(__xludf.DUMMYFUNCTION("""COMPUTED_VALUE"""),0.0809612943008125) -> 0.080961294 | M43: =IFERROR(__xludf.DUMMYFUNCTION("""COMPUTED_VALUE"""),0.0842687984669957) -> 0.084268798 | N43: =IFERROR(__xludf.DUMMYFUNCTION("""COMPUTED_VALUE"""),2435.83311933763) -> 2435.8331 | O43: =IFERROR(__xludf.DUMMYFUNCTION("""COMPUTED_VALUE"""),1) -> 1 | P43: =IFERROR(__xludf.DUMMYFUNCTION("""COMPUTED_VALUE"""),39) -> 39 | Q43: =IFERROR(__xludf.DUMMYFUNCTION("""COMPUTED_VALUE"""),0) -> 0 | R43: =IFERROR(__xludf.DUMMYFUNCTION("""COMPUTED_VALUE"""),28930.8) -> 28930.8 | S43: =IFERROR(__xludf.DUMMYFUNCTION("""COMPUTED_VALUE"""),2999.8) -> 2999.8 | T43: =IFERROR(__xludf.DUMMYFUNCTION("""COMPUTED_VALUE"""),1048.4) -> 1048.4 | U43: =IFERROR(__xludf.DUMMYFUNCTION("""COMPUTED_VALUE"""),4377.3) -> 4377.3 | V43: =IFERROR(__xludf.DUMMYFUNCTION("""COMPUTED_VALUE"""),5096) -> 5096 | W43: =IFERROR(__xludf.DUMMYFUNCTION("""COMPUTED_VALUE"""),346) -> 346 | X43: =SUM(Q43:W43) -> 42798.3
A44: AFFF 10 l | B44: =IFERROR(__xludf.DUMMYFUNCTION("""COMPUTED_VALUE"""),0.0833333333333333) -> 0.083333333 | C44: =IFERROR(__xludf.DUMMYFUNCTION("""COMPUTED_VALUE"""),0.0833333333333333) -> 0.083333333 | D44: =IFERROR(__xludf.DUMMYFUNCTION("""COMPUTED_VALUE"""),0.0833333333333333) -> 0.083333333 | E44: =IFERROR(__xludf.DUMMYFUNCTION("""COMPUTED_VALUE"""),0.0833333333333333) -> 0.083333333 | F44: =IFERROR(__xludf.DUMMYFUNCTION("""COMPUTED_VALUE"""),0.0833333333333333) -> 0.083333333 | G44: =IFERROR(__xludf.DUMMYFUNCTION("""COMPUTED_VALUE"""),0.0833333333333333) -> 0.083333333 | H44: =IFERROR(__xludf.DUMMYFUNCTION("""COMPUTED_VALUE"""),0.0833333333333333) -> 0.083333333 | I44: =IFERROR(__xludf.DUMMYFUNCTION("""COMPUTED_VALUE"""),0.0833333333333333) -> 0.083333333 | ... M44: =IFERROR(__xludf.DUMMYFUNCTION("""COMPUTED_VALUE"""),0.0833333333333333) -> 0.083333333 | N44: =IFERROR(__xludf.DUMMYFUNCTION("""COMPUTED_VALUE"""),462.458588756731) -> 462.45859 | O44: =IFERROR(__xludf.DUMMYFUNCTION("""COMPUTED_VALUE"""),1) -> 1 | P44: =IFERROR(__xludf.DUMMYFUNCTION("""COMPUTED_VALUE"""),6) -> 6 | Q44: =IFERROR(__xludf.DUMMYFUNCTION("""COMPUTED_VALUE"""),0) -> 0 | R44: =IFERROR(__xludf.DUMMYFUNCTION("""COMPUTED_VALUE"""),0) -> 0 | S44: =IFERROR(__xludf.DUMMYFUNCTION("""COMPUTED_VALUE"""),0) -> 0 | T44: =IFERROR(__xludf.DUMMYFUNCTION("""COMPUTED_VALUE"""),0) -> 0 | U44: =IFERROR(__xludf.DUMMYFUNCTION("""COMPUTED_VALUE"""),6232.7) -> 6232.7 | V44: =IFERROR(__xludf.DUMMYFUNCTION("""COMPUTED_VALUE"""),0) -> 0 | W44: =IFERROR(__xludf.DUMMYFUNCTION("""COMPUTED_VALUE"""),0) -> 0 | X44: =SUM(Q44:W44) -> 6232.7
...

Sheet Cálculo
A1: Logística en el mes pico de 2035 (las dos plantas lado a lado)
A2: Cada planta en su mes pico · § 10
A4: 1. Mes pico | B4: Comercial | C4: Industrial
A5: N° del mes pico (mayor % de Toda la planta) | B5: =MATCH(MAX(Importados!$B$22:$M$22),Importados!$B$22:$M$22,0) -> 12 | C5: =MATCH(MAX(Importados!$B$56:$M$56),Importados!$B$56:$M$56,0) -> 12
A6: Mes pico | B6: =INDEX(Importados!$B$4:$M$4,B5) -> Dic | C6: =INDEX(Importados!$B$38:$M$38,C5) -> Dic
A7: % de las recargas del año en el mes pico | B7: =INDEX(Importados!$B$22:$M$22,B5) -> 0.10298626 | C7: =INDEX(Importados!$B$56:$M$56,C5) -> 0.10304314
A8: Días hábiles por mes | B8: =Importados!$B$24 -> 20 | C8: =Importados!$B$58 -> 20
A9: Horas productivas por turno | B9: =Importados!$B$25 -> 7.5 | C9: =Importados!$B$59 -> 7.5
A11: 2. Por tipo | B11: Peso lleno (kg) | C11: u. por jaula | D11: Jaula | E11: Rodante (1 = sí) | F11: Comercial | I11: Industrial | M11: Fuente del peso
A12: Tipo | F12: u/día | G12: Sustitutos por día | H12: Jaulas por día | I12: u/día | J12: Sustitutos por día | K12: Jaulas por día | M12: § 10.3
A13: ABC 1 kg | B13: 1.9 | C13: 72 | D13: A | E13: 0 | F13: =Importados!$N$5*INDEX(Importados!$B$5:$M$5,$B$5)/$B$8 -> 652.61884 | G13: =F13*Importados!$O$5 -> 0 | H13: =F13/$C13 -> 9.0641505 | I13: =Importados!$N$39*INDEX(Importados!$B$39:$M$39,$C$5)/$C$8 -> 339.25472 | J13: =I13*Importados!$O$39 -> 0 | K13: =I13/$C13 -> 4.7118712 | M13: BOM FLAMA
