Workbook

Sheet Resumen
A1: BALANCEO DE LÍNEA SINCRONIZADO — FLAMA (manuales, carros y recargas)
A2: Con la mezcla real de modelos del mes elegido: cuánto carga cada puesto, cada cuántos días pasa cada formato por cada máquina, cuánto se hace por vez y cuánto stock queda entre puestos y en los almacenes.
A3: Año (2026 a 2035) | C3: 2035
A4: Mes (1 a 12; vacío = mes pico de producción de manuales)
A5: Mes de cálculo | C5: =IF(C4="",Carga!$N$8,C4) -> 1 | D5: =Carga!B4 -> Ene 2035
A7: CÓMO SE LEE (una hoja por paso; solo se tocan las celdas amarillas y verdes)
A8: Hoja | B8: Qué pregunta responde | F8: Qué mirar
A9: Parametros | B9: Qué supuestos y criterios se usan y de dónde sale cada número. | F9: Amarillos (criterios) y columna G (fuente).
A10: Carga (paso 1) | B10: ¿Cuánto hay que hacer por día y cuánto carga cada puesto con esa mezcla? | F10: Aprovechamiento y cuello de cada línea.
A11: Lotes (paso 2) | B11: ¿Cuánto cortar o prensar de cada formato antes de cambiar? | F11: Frecuencia, tanda y pulmón de cada formato.
A12: Rueda (paso 3) | B12: ¿Qué formato pasa cada día por cada puesto de la ola? | F12: Calendario de 20 días: nada arriba de 100 %.
A13: Pulmones (paso 4) | B13: ¿Cuánto material queda esperando y cuántos m² hay que reservar? | F13: Sección 1: total a reservar.
A14: Datos | B14: Valores pegados de las planillas de aprovechamiento. | F14: No se lee.
A16: 1) PRODUCCIÓN DEL MES DE CÁLCULO
A17: Línea | B17: Unidades por mes | C17: Unidades por día | D17: Mes pico de la línea | E17: Terminados por día | F17: Cilindros vacíos por día
A18: Manuales (recipientes, con sobrestock) | B18: =Carga!F18*DIAS -> 25601.631 | C18: =Carga!F18 -> 1280.0815 | D18: =Carga!O8 -> Ene | E18: =Carga!D18 -> 324.76052 | F18: =Carga!E18 -> 955.32102
A19: Carros (recipientes) | B19: =Carga!E26*DIAS -> 264.12238 | C19: =Carga!E26 -> 13.206119 | D19: =Carga!O9 -> Mar | E19: =Carga!C26 -> 7.7123991 | F19: =Carga!D26 -> 5.49372
A20: Recargas (equipos) | B20: =Carga!B29 -> 10822.075 | C20: =Carga!D29 -> 541.10377 | D20: =Carga!O10 -> Dic | E20: — | F20: —
A22: 2) BALANCEO DE CADA LÍNEA
A23: Línea | B23: Cuello de botella | C23: Aprovech. del cuello (mes de cálculo) | D23: Eficiencia de balanceo | E23: Aprovech. máximo con los cambios de la rueda | F23: Aprovech. del cuello en el mes pico de la línea | G23: Mes pico | H23: Estado
A24: Manuales | B24: =Carga!$C$66 -> Soldadura longitudinal — 2,5 a 10 kg | C24: =Carga!$C$67 -> 0.79491735 | D24: =Carga!$C$69 -> 0.77801978 | E24: =MAX(Rueda!Y8:Y29,Lotes!L22:L23,Lotes!H42) -> 0.81209623 | F24: =IF(MES=Carga!$N$8,MAX(Rueda!Y8:Y29,Lotes!L22:L23,Lotes!H42),"Dejar C4 vacío") -> 0.81209623 | G24: =Carga!O8 -> Ene | H24: =IF(MAX(E24,IF(ISNUMBER(F24),F24,0))<=UMBRAL,"OK","Revisar") -> OK
A25: Carros | B25: =Carga!$C$95 -> Soldadura de accesorios | C25: =Carga!$C$96 -> 0.49512771 | D25: =Carga!$C$99 -> 0.45693569 | E25: =Carga!$C$96 -> 0.49512771 | F25: =Carga!$C$97 -> 0.5230764 | G25: =Carga!O9 -> Mar | H25: =IF(MAX(E25,IF(ISNUMBER(F25),F25,0))<=UMBRAL,"OK","Revisar") -> OK
A26: Recargas | B26: {=INDEX(Carga!B104:B126,MATCH(MAX(Carga!H104:H126),Carga!H104:H126,0))} -> Ensayo de pérdidas | C26: =MAX(Carga!H104:H126) -> 0.80163521 | D26: — | E26: =MAX(Carga!H104:H126) -> 0.80163521 | F26: =MAX(Carga!I104:I126) -> 0.87268181 | G26: =Carga!O10 -> Dic | H26: =IF(MAX(E26,IF(ISNUMBER(F26),F26,0))<=UMBRAL,"OK","Revisar") -> OK
A28: 3) PLAN SINCRONIZADO: cada cuántos días pasa cada formato por cada máquina y cuánto se hace por vez
A29: Formato | B29: Por día | C29: Ola: cada (días) | D29: Ola: lote (recipientes) | E29: Guillotina: cada (días) | F29: Guillotina: hojas por tanda | G29: Embutidora: cada (días) | H29: Embutidora: piezas por tanda (cúpula o fondo) | I29: Pulmón de desarrollos (cuerpos) | J29: Supermercado (cúpulas + fondos)
A30: Manuales 1 kg | B30: =Rueda!C35 -> 911.79288 | C30: =Rueda!H35 -> 1 | D30: =Rueda!J35 -> 911.79288 | E30: =Lotes!O8 -> 1 | F30: =Lotes!P8 -> 21 | G30: =Lotes!J30 -> 4 | H30: =Lotes!K30 -> 3647.1715 | I30: =Lotes!W8 -> 909.13615 | J30: =Lotes!O30+Lotes!O31 -> 8132.6058
A31: Manuales 2,5 kg | B31: =Rueda!C36 -> 63.568523 | C31: =Rueda!H36 -> 1 | D31: =Rueda!J36 -> 63.568523 | E31: =Lotes!O9 -> 8 | F31: =Lotes!P9 -> 19 | G31: =Lotes!J32 -> 16 | H31: =Lotes!K32 -> 1017.0964 | I31: =Lotes!W9 -> 511.54499 | J31: =Lotes!O32+Lotes!O33 -> 2142.1727
A32: Manuales 5 kg | B32: =Rueda!C37 -> 287.33696 | C32: =Rueda!H37 -> 1 | D32: =Rueda!J37 -> 287.33696 | E32: =Lotes!O10 -> 1 | F32: =Lotes!P10 -> 24 | G32: =Lotes!J34 -> 8 | H32: =Lotes!K34 -> 2298.6957 | I32: =Lotes!W10 -> 292.59739 | J32: =Lotes!O34+Lotes!O35 -> 4976.3616
A33: Manuales 10 kg | B33: =Rueda!C38 -> 17.383176 | C33: =Rueda!H38 -> 2 | D33: =Rueda!J38 -> 34.766353 | E33: =Lotes!O11 -> 16 | F33: =Lotes!P11 -> 19 | G33: =Lotes!J36 -> 16 | H33: =Lotes!K36 -> 278.13082 | I33: =Lotes!W11 -> 284.74891 | J33: =Lotes!O36+Lotes!O37 -> 589.59546
A34: Carros 25 kg (hoja 3,2) | B34: =Lotes!E12 -> 3.3035698 | C34: — | D34: — | E34: =Lotes!O12 -> 4 | F34: =Lotes!P12 -> 2 | G34: — | H34: — | I34: =Lotes!W12 -> 18.364297 | J34: —
A35: Carros 50 kg (hoja 3,2) | B35: =Lotes!E13 -> 7.2608495 | C35: — | D35: — | E35: =Lotes!O13 -> 4 | F35: =Lotes!P13 -> 5 | G35: — | H35: — | I35: =Lotes!W13 -> 30.709477 | J35: —
A36: Carros 70 + 100 kg (hoja mixta 4,75) | B36: =Lotes!E14 -> 2.6416998 | C36: — | D36: — | E36: =Lotes!O14 -> 4 | F36: =Lotes!P14 -> 3 | G36: — | H36: — | I36: =Lotes!W14 -> 12.224544 | J36: —
A37: Ola = del cilindrado al embalaje todos los puestos corren el formato el mismo día. Guillotina y embutidora hacen tandas más largas y guardan lo que sobra en el pulmón de desarrollos y en el supermercado.
A39: 4) MÁQUINAS CON CAMBIO DE FORMATO CARO
A40: Recurso | B40: Cambios por día | C40: Min de cambio por día | D40: Aprovech. con cambios | E40: Estado
A41: Guillotina 1 (manuales + carros) | B41: =Lotes!H22 -> 2.9375 | C41: =Lotes!I22 -> 44.0625 | D41: =Lotes!L22 -> 0.65422385 | E41: =Lotes!M22 -> OK
A42: Guillotina 2 (manuales + carros) | B42: =Lotes!H23 -> 2.9375 | C42: =Lotes!I23 -> 14.6875 | D42: =Lotes!L23 -> 0.37584488 | E42: =Lotes!M23 -> OK
A43: Operario de corte (si atiende G1 y G2) | B43: — | C43: — | D43: =Lotes!L24 -> 1.0300687 | E43: =Lotes!M24 -> Hacen falta 2 operarios
A44: Embutidora (8 matrices) | B44: =Lotes!F42 -> 1 | C44: =Lotes!G42 -> 90 | D44: =Lotes!H42 -> 0.47928342 | E44: =Lotes!K42 -> OK
A45: Soldadura longitudinal 2,5 a 10 kg (cuello) | B45: =Rueda!W12 -> 2.5 | C45: =Rueda!X12 -> 25 | D45: =Rueda!Y12 -> 0.81209623 | E45: =Rueda!Z12 -> OK
...

Sheet Parametros
A1: PARÁMETROS — los supuestos y datos que usa todo el libro
A2: Amarillo = criterio del grupo (se puede cambiar) · Verde = dato de las planillas o de los Words (se puede corregir) · Blanco = fórmula. La columna G dice de dónde sale cada valor.
A3: ▶ Solo se tocan las celdas amarillas y verdes. Los nombres (DIAS, R_CORRIDA, S_G1…) son los que usan las fórmulas de las otras hojas.
A5: 1) JORNADA Y CAPACIDAD
A6: Parámetro | B6: Valor | C6: Unidad | G6: Fuente / criterio | H6: Nombre
A7: Días hábiles por mes | B7: 20 | C7: días | G7: Aprovechamiento Manuales / Carros / Recargas, parametros B2 | H7: DIAS
A8: Horas por turno | B8: 8 | C8: h | G8: parametros B3 de las planillas de aprovechamiento | H8: H_TURNO
A9: Refrigerio y pausas por turno | B9: 30 | C9: min | G9: parametros B4 de las planillas de aprovechamiento | H9: REFRIG
A10: Minutos productivos por turno | B10: =H_TURNO*60-REFRIG -> 450 | C10: min | G10: Horas × 60 − refrigerio (= 450 min = 7,5 h productivas) | H10: MIN_TURNO
A11: Horas productivas por mes (1 turno) | B11: =DIAS*MIN_TURNO/60 -> 150 | C11: h | G11: Días × horas productivas (= 150 h, igual que las planillas) | H11: HORAS_MES
A12: Umbral de aprovechamiento | B12: 0.9 | C12: % | G12: Límite duro del grupo (Word de recargas § 8), el mismo de las planillas | H12: UMBRAL
A14: 2) LOTES: cuánto seguir procesando antes de cambiar de formato
A15: Parámetro | B15: Valor | C15: Unidad | G15: Fuente / criterio | H15: Nombre
A16: Base de la rueda (cada cuántos días se repite el ciclo más corto) | B16: 1 | C16: días | G16: Criterio: rueda diaria; las frecuencias son 1, 2, 4, 8 o 16 días (potencias de 2 para que encajen) | H16: BASE
A17: Relación mínima corrida / cambio | B17: 3 | C17: veces | G17: Criterio del «punto de seguir procesando»: cada tanda tiene que durar al menos 3 veces lo que el cambio. Así el cambio nunca pasa del 25 % del tiempo de la tanda. Subirlo agranda los lotes y los pulmones | H17: R_CORRIDA
A18: Frecuencia máxima (cobertura máxima de un lote) | B18: 16 | C18: días | G18: Criterio: ningún lote cubre más de 16 días hábiles (menos de un mes), para no inmovilizar stock ni perder FIFO | H18: K_MAX
A20: 3) CAMBIOS DE FORMATO Y GUILLOTINAS
A21: Parámetro | B21: Valor | C21: Unidad | G21: Fuente / criterio | H21: Nombre
A22: Guillotina 1: programa del tope y primera pieza por formato | B22: 5 | C22: min | G22: parametros_manuales C53 (5 min por cambio) | H22: S_G1_PROG
A23: Guillotina 1: traer y devolver el paquete de chapa (máquina parada) | B23: 10 | C23: min | G23: Word de carros, puesto 2: 2 viajes de 5 min por paquete. Es tiempo inoperativo de la G1 | H23: S_G1_PAQ
A24: Guillotina 1: tiempo total de cambio de formato | B24: =S_G1_PROG+S_G1_PAQ -> 15 | C24: min | G24: Suma de las dos filas de arriba | H24: S_G1
A25: Guillotina 2: cambio de tope por formato | B25: 5 | C25: min | G25: parametros_manuales C54 | H25: S_G2
A26: Embutidora: cambio de matriz | B26: 90 | C26: min | G26: parametros_manuales C55 de la planilla de aprovechamiento (90 min). El Word de manuales dice «unos 120 minutos». Con 120: el 5 kg pasa a prensarse cada 16 días, la prensa queda en 50 % y los pulmones de manuales suben unos 15 m² (ver Guía). | H26: S_EMB
A27: Alistamiento de cada guillotina al empezar el turno | B27: 10 | C27: min/turno | G27: SUPUESTO: encender, verificar barreras fotoeléctricas y tope, calentar el hidráulico y preparar ventosas y EPP. Si el Excel original de PCP tiene el tpr de la guillotina, poner ese. | H27: ALIST_G
A28: Desalistamiento de cada guillotina al terminar el turno | B28: 10 | C28: min/turno | G28: SUPUESTO: limpiar la mesa de bolas, llevar las orillas al contenedor de scrap, ordenar los carros y apagar. Si el Excel original de PCP tiene el tdl, poner ese. | H28: DESALIST_G
A29: Rendimiento del operario de corte | B29: 0.85 | C29: % | G29: SUPUESTO: el tiempo por corte (0,3 min) y por hoja (2 min) es manual; como en los otros puestos (tiempo tipo = (tpr + tdl + ta) ÷ rendimiento), se divide por el rendimiento (15 % de suplementos por fatiga y necesidades). | H29: REND_CORTE
A30: Guillotina 1: tiras y piezas de accesorios de carros | B30: 8.6 | C30: min/día | G30: parametros_manuales G53 (W-CAR: placas 1,7 + patas 1,9 + 5,0 min/día en el pico) | H30: TIRAS_CARROS
A31: Guillotina 1: resto de los cortes de accesorios de carros | B31: 36.2 | C31: min/día | G31: Word de carros, puesto 2, tabla de tiempo en el pico: tiras de 40 mm 10,1 + tiras para triángulos 8,1 + piezas de accesorios a largo 18,0. La planilla solo tenía las placas y las patas (fila 23). | H31: TIRAS_EXTRA
A33: 4) PULMONES ENTRE PUESTOS
A34: Parámetro | B34: Valor | C34: Unidad | G34: Fuente / criterio | H34: Nombre
A35: Protección antes del cuello de botella (soldadura longitudinal 2,5 a 10 kg) | B35: 1 | C35: h | G35: Pulmones 2035: la protección de 1 h va solo antes del cuello (virolas de 2,5 a 10 kg). Lotes!W la sigue sumando al pulmón de cada tanda, que queda como referencia por formato (Figura 6) | H35: H_PROT
A36: Protección antes del marcapasos (soldadura circunferencial), en las dos ramas | B36: 3.75 | C36: h | G36: Medio turno (Word de manuales). Va en las cúpulas con cuello y los cuerpos bordoneados. Si se baja a 1 h, esos dos pulmones bajan a la mitad | H36: H_PROT_MARC
A37: Stock de seguridad del supermercado de cúpulas y fondos | B37: 1 | C37: días | G37: Criterio: 1 día de consumo de cada pieza por si la prensa se demora en volver al formato | H37: SS_SUPER
A38: Hojas en el pulmón de franjas (mesa elevadora 2, entre G1 y G2) | B38: 2 | C38: hojas | G38: Layout rev. 10: mesa elevadora 2 como pulmón de franjas; la G2 empieza con la primera hoja | H38: N_HOJAS_FRANJA
A39: Contenedores vacíos en retorno por pulmón | B39: 1 | C39: u | G39: Ya no se usa: desde Pulmones 2035 los vacíos vuelven en los carros de tránsito (sección 10) | H39: CONT_RET
A40: Carga útil del carro de plataforma de desarrollos | B40: 300 | C40: kg | G40: Ya no se usa: desde Pulmones 2035 los desarrollos van en bandejas (sección 7) | H40: CARGA_PLAT
A42: 5) PRODUCTO TERMINADO Y ALMACÉN
A43: Parámetro | B43: Valor | C43: Unidad | G43: Fuente / criterio | H43: Nombre
A44: Stock de seguridad de producto terminado (manuales) | B44: 5 | C44: días de venta | G44: Criterio: una semana hábil de venta promedio del modelo | H44: SS_PT
A45: Niveles de rack de pallets en el almacén de PT | B45: 3 | C45: niveles | G45: Criterio: rack selectivo de 3 niveles (el autoelevador Heli CPCD50 tiene torre de 3 a 6 m) | H45: PT_NIV
...

Sheet Carga
A1: PASO 1 — CUÁNTO HAY QUE HACER Y CUÁNTO CARGA CADA PUESTO (mes de cálculo)
A2: Producción del mes por modelo (plan con sobrestock) y carga de cada puesto de manuales, carros y recargas. Carga = Σ unidades del modelo × tiempo del modelo. Aprovechamiento = carga ÷ (máquinas × turnos × 450 min).
A3: ▶ Mirá la columna V de manuales, P y Q de carros e H e I de recargas (aprovechamiento) y el cuello marcado. Ninguno debe pasar el 90 %.
A4: Mes | B4: {=INDEX($B$7:$M$7,1,MES)&" "&ANIO} -> Ene 2035
A6: 1) PRODUCCIÓN DE CADA LÍNEA POR MES (para encontrar el mes pico)
A7: Línea | B7: Ene | C7: Feb | D7: Mar | E7: Abr | F7: May | G7: Jun | H7: Jul | I7: Ago | J7: Sep | K7: Oct | L7: Nov | M7: Dic | N7: Mes pico (n.°) | O7: Mes pico
A8: Manuales (recipientes, con sobrestock) | B8: =SUMPRODUCT($B$14:$B$17,Datos!E$173:E$176) -> 25601.631 | C8: =SUMPRODUCT($B$14:$B$17,Datos!F$173:F$176) -> 24783.212 | D8: =SUMPRODUCT($B$14:$B$17,Datos!G$173:G$176) -> 23166.215 | E8: =SUMPRODUCT($B$14:$B$17,Datos!H$173:H$176) -> 22153.112 | F8: =SUMPRODUCT($B$14:$B$17,Datos!I$173:I$176) -> 20730.799 | G8: =SUMPRODUCT($B$14:$B$17,Datos!J$173:J$176) -> 20321.589 | H8: =SUMPRODUCT($B$14:$B$17,Datos!K$173:K$176) -> 21743.902 | I8: =SUMPRODUCT($B$14:$B$17,Datos!L$173:L$176) -> 24783.212 | ... M8: =SUMPRODUCT($B$14:$B$17,Datos!P$173:P$176) -> 25601.631 | N8: =MATCH(MAX(B8:M8),B8:M8,0) -> 1 | O8: =INDEX($B$7:$M$7,1,N8) -> Ene
A9: Carros (recipientes) | B9: =SUMIFS(Datos!E$90:E$169,Datos!$A$90:$A$169,ANIO) -> 264.12238 | C9: =SUMIFS(Datos!F$90:F$169,Datos!$A$90:$A$169,ANIO) -> 233.04916 | D9: =SUMIFS(Datos!G$90:G$169,Datos!$A$90:$A$169,ANIO) -> 279.65899 | E9: =SUMIFS(Datos!H$90:H$169,Datos!$A$90:$A$169,ANIO) -> 279.65899 | F9: =SUMIFS(Datos!I$90:I$169,Datos!$A$90:$A$169,ANIO) -> 279.65899 | G9: =SUMIFS(Datos!J$90:J$169,Datos!$A$90:$A$169,ANIO) -> 248.58577 | H9: =SUMIFS(Datos!K$90:K$169,Datos!$A$90:$A$169,ANIO) -> 279.65899 | I9: =SUMIFS(Datos!L$90:L$169,Datos!$A$90:$A$169,ANIO) -> 279.65899 | ... M9: =SUMIFS(Datos!P$90:P$169,Datos!$A$90:$A$169,ANIO) -> 248.58577 | N9: =MATCH(MAX(B9:M9),B9:M9,0) -> 3 | O9: =INDEX($B$7:$M$7,1,N9) -> Mar
A10: Recargas (equipos recibidos) | B10: =SUMIFS(Datos!C$312:C$541,Datos!$A$312:$A$541,"Recepción y registro",Datos!$B$312:$B$541,ANIO) -> 10822.075 | C10: =SUMIFS(Datos!D$312:D$541,Datos!$A$312:$A$541,"Recepción y registro",Datos!$B$312:$B$541,ANIO) -> 9391.2625 | D10: =SUMIFS(Datos!E$312:E$541,Datos!$A$312:$A$541,"Recepción y registro",Datos!$B$312:$B$541,ANIO) -> 8906.0301 | E10: =SUMIFS(Datos!F$312:F$541,Datos!$A$312:$A$541,"Recepción y registro",Datos!$B$312:$B$541,ANIO) -> 9801.73 | F10: =SUMIFS(Datos!G$312:G$541,Datos!$A$312:$A$541,"Recepción y registro",Datos!$B$312:$B$541,ANIO) -> 9879.3585 | G10: =SUMIFS(Datos!H$312:H$541,Datos!$A$312:$A$541,"Recepción y registro",Datos!$B$312:$B$541,ANIO) -> 9758.7033 | H10: =SUMIFS(Datos!I$312:I$541,Datos!$A$312:$A$541,"Recepción y registro",Datos!$B$312:$B$541,ANIO) -> 8689.6915 | I10: =SUMIFS(Datos!J$312:J$541,Datos!$A$312:$A$541,"Recepción y registro",Datos!$B$312:$B$541,ANIO) -> 8770.0961 | ... M10: =SUMIFS(Datos!N$312:N$541,Datos!$A$312:$A$541,"Recepción y registro",Datos!$B$312:$B$541,ANIO) -> 11781.204 | N10: =MATCH(MAX(B10:M10),B10:M10,0) -> 12 | O10: =INDEX($B$7:$M$7,1,N10) -> Dic
A12: 2) MANUALES — QUÉ HAY QUE HACER POR DÍA EN EL MES DE CÁLCULO
A13: Modelo | B13: Producción del año (u) | C13: % del año que se hace este mes | D13: Terminados por día | E13: Cilindros vacíos por día | F13: Recipientes por día | G13: Mezcla | H13: Ventas del mes (u) | I13: Sobrestock del mes (u)
A14: 1 kg | B14: =SUMIFS(Datos!$Q$7:$Q$86,Datos!$A$7:$A$86,ANIO,Datos!$D$7:$D$86,$A14) -> 202620.64 | C14: {=INDEX(Datos!$E$173:$P$173,1,MES)} -> 0.09 | D14: =SUMIFS(Datos!$Q$7:$Q$86,Datos!$A$7:$A$86,ANIO,Datos!$D$7:$D$86,$A14,Datos!$C$7:$C$86,"Terminado")*C14/DIAS -> 144.32688 | E14: =SUMIFS(Datos!$Q$7:$Q$86,Datos!$A$7:$A$86,ANIO,Datos!$D$7:$D$86,$A14,Datos!$C$7:$C$86,"Cilindro")*C14/DIAS -> 767.466 | F14: =D14+E14 -> 911.79288 | G14: =IF($F$18=0,0,F14/$F$18) -> 0.71229281 | H14: {=SUMIFS(INDEX(Datos!$E$7:$P$86,0,MES),Datos!$A$7:$A$86,ANIO,Datos!$D$7:$D$86,$A14)} -> 24314.477 | I14: =F14*DIAS-H14 -> -6078.6192
A15: 2,5 kg | B15: =SUMIFS(Datos!$Q$7:$Q$86,Datos!$A$7:$A$86,ANIO,Datos!$D$7:$D$86,$A15) -> 14126.338 | C15: {=INDEX(Datos!$E$174:$P$174,1,MES)} -> 0.09 | D15: =SUMIFS(Datos!$Q$7:$Q$86,Datos!$A$7:$A$86,ANIO,Datos!$D$7:$D$86,$A15,Datos!$C$7:$C$86,"Terminado")*C15/DIAS -> 33.464063 | E15: =SUMIFS(Datos!$Q$7:$Q$86,Datos!$A$7:$A$86,ANIO,Datos!$D$7:$D$86,$A15,Datos!$C$7:$C$86,"Cilindro")*C15/DIAS -> 30.10446 | F15: =D15+E15 -> 63.568523 | G15: =IF($F$18=0,0,F15/$F$18) -> 0.049659745 | H15: {=SUMIFS(INDEX(Datos!$E$7:$P$86,0,MES),Datos!$A$7:$A$86,ANIO,Datos!$D$7:$D$86,$A15)} -> 1412.6338 | I15: =F15*DIAS-H15 -> -141.26338
A16: 5 kg | B16: =SUMIFS(Datos!$Q$7:$Q$86,Datos!$A$7:$A$86,ANIO,Datos!$D$7:$D$86,$A16) -> 63852.659 | C16: {=INDEX(Datos!$E$175:$P$175,1,MES)} -> 0.09 | D16: =SUMIFS(Datos!$Q$7:$Q$86,Datos!$A$7:$A$86,ANIO,Datos!$D$7:$D$86,$A16,Datos!$C$7:$C$86,"Terminado")*C16/DIAS -> 138.6674 | E16: =SUMIFS(Datos!$Q$7:$Q$86,Datos!$A$7:$A$86,ANIO,Datos!$D$7:$D$86,$A16,Datos!$C$7:$C$86,"Cilindro")*C16/DIAS -> 148.66956 | F16: =D16+E16 -> 287.33696 | G16: =IF($F$18=0,0,F16/$F$18) -> 0.2244677 | H16: {=SUMIFS(INDEX(Datos!$E$7:$P$86,0,MES),Datos!$A$7:$A$86,ANIO,Datos!$D$7:$D$86,$A16)} -> 6385.2659 | I16: =F16*DIAS-H16 -> -638.52659
A17: 10 kg | B17: =SUMIFS(Datos!$Q$7:$Q$86,Datos!$A$7:$A$86,ANIO,Datos!$D$7:$D$86,$A17) -> 3862.9281 | C17: {=INDEX(Datos!$E$176:$P$176,1,MES)} -> 0.09 | D17: =SUMIFS(Datos!$Q$7:$Q$86,Datos!$A$7:$A$86,ANIO,Datos!$D$7:$D$86,$A17,Datos!$C$7:$C$86,"Terminado")*C17/DIAS -> 8.3021764 | E17: =SUMIFS(Datos!$Q$7:$Q$86,Datos!$A$7:$A$86,ANIO,Datos!$D$7:$D$86,$A17,Datos!$C$7:$C$86,"Cilindro")*C17/DIAS -> 9.081 | F17: =D17+E17 -> 17.383176 | G17: =IF($F$18=0,0,F17/$F$18) -> 0.013579741 | H17: {=SUMIFS(INDEX(Datos!$E$7:$P$86,0,MES),Datos!$A$7:$A$86,ANIO,Datos!$D$7:$D$86,$A17)} -> 386.29281 | I17: =F17*DIAS-H17 -> -38.629281
A18: Total | B18: =SUM(B14:B17) -> 284462.56 | C18: =IF(B18=0,0,F18*DIAS/B18) -> 0.09 | D18: =SUM(D14:D17) -> 324.76052 | E18: =SUM(E14:E17) -> 955.32102 | F18: =SUM(F14:F17) -> 1280.0815 | G18: =SUM(G14:G17) -> 1 | H18: =SUM(H14:H17) -> 32498.669 | I18: =SUM(I14:I17) -> -6897.0384
A19: Sobrestock del mes: positivo = se fabrica de más para guardar; negativo = sale del stock hecho antes (ver Pulmones, sección 4).
A20: 3) CARROS — QUÉ HAY QUE HACER POR DÍA EN EL MES DE CÁLCULO
A21: Modelo | B21: Producción del año (u) | C21: Terminados por día | D21: Cilindros vacíos por día | E21: Carros por día | F21: Mezcla
A22: 25 kg | B22: =SUMIFS(Datos!$Q$90:$Q$169,Datos!$A$90:$A$169,ANIO,Datos!$D$90:$D$169,$A22) -> 777.31053 | C22: {=SUMIFS(INDEX(Datos!$E$90:$P$169,0,MES),Datos!$A$90:$A$169,ANIO,Datos!$D$90:$D$169,$A22,Datos!$C$90:$C$169,"Terminado")/DIAS} -> 1.9280998 | D22: {=SUMIFS(INDEX(Datos!$E$90:$P$169,0,MES),Datos!$A$90:$A$169,ANIO,Datos!$D$90:$D$169,$A22,Datos!$C$90:$C$169,"Cilindro")/DIAS} -> 1.37547 | E22: =C22+D22 -> 3.3035698 | F22: =IF($E$26=0,0,E22/$E$26) -> 0.25015447
A23: 50 kg | B23: =SUMIFS(Datos!$Q$90:$Q$169,Datos!$A$90:$A$169,ANIO,Datos!$D$90:$D$169,$A23) -> 1708.4352 | C23: {=SUMIFS(INDEX(Datos!$E$90:$P$169,0,MES),Datos!$A$90:$A$169,ANIO,Datos!$D$90:$D$169,$A23,Datos!$C$90:$C$169,"Terminado")/DIAS} -> 4.2414795 | D23: {=SUMIFS(INDEX(Datos!$E$90:$P$169,0,MES),Datos!$A$90:$A$169,ANIO,Datos!$D$90:$D$169,$A23,Datos!$C$90:$C$169,"Cilindro")/DIAS} -> 3.01937 | E23: =C23+D23 -> 7.2608495 | F23: =IF($E$26=0,0,E23/$E$26) -> 0.54980948
A24: 70 kg | B24: =SUMIFS(Datos!$Q$90:$Q$169,Datos!$A$90:$A$169,ANIO,Datos!$D$90:$D$169,$A24) -> 374.12986 | C24: {=SUMIFS(INDEX(Datos!$E$90:$P$169,0,MES),Datos!$A$90:$A$169,ANIO,Datos!$D$90:$D$169,$A24,Datos!$C$90:$C$169,"Terminado")/DIAS} -> 0.92569189 | D24: {=SUMIFS(INDEX(Datos!$E$90:$P$169,0,MES),Datos!$A$90:$A$169,ANIO,Datos!$D$90:$D$169,$A24,Datos!$C$90:$C$169,"Cilindro")/DIAS} -> 0.66436 | E24: =C24+D24 -> 1.5900519 | F24: =IF($E$26=0,0,E24/$E$26) -> 0.12040266
A25: 100 kg | B25: =SUMIFS(Datos!$Q$90:$Q$169,Datos!$A$90:$A$169,ANIO,Datos!$D$90:$D$169,$A25) -> 247.44657 | C25: {=SUMIFS(INDEX(Datos!$E$90:$P$169,0,MES),Datos!$A$90:$A$169,ANIO,Datos!$D$90:$D$169,$A25,Datos!$C$90:$C$169,"Terminado")/DIAS} -> 0.61712793 | D25: {=SUMIFS(INDEX(Datos!$E$90:$P$169,0,MES),Datos!$A$90:$A$169,ANIO,Datos!$D$90:$D$169,$A25,Datos!$C$90:$C$169,"Cilindro")/DIAS} -> 0.43452 | E25: =C25+D25 -> 1.0516479 | F25: =IF($E$26=0,0,E25/$E$26) -> 0.079633382
A26: Total | B26: =SUM(B22:B25) -> 3107.3221 | C26: =SUM(C22:C25) -> 7.7123991 | D26: =SUM(D22:D25) -> 5.49372 | E26: =SUM(E22:E25) -> 13.206119 | F26: =SUM(F22:F25) -> 1
A28: 4) RECARGAS
A29: Equipos que entran en el mes (recargas y altas de sustitutos) | B29: {=INDEX(B10:M10,1,MES)} -> 10822.075 | C29: por día → | D29: =B29/DIAS -> 541.10377
A32: 5) MANUALES — CARGA POR PUESTO Y POR MODELO
A33: N° | B33: Puesto | C33: Rama | D33: Alcance | E33: Piezas por recipiente | F33: % que pasa | G33: t 1 kg (s/pieza) | H33: t 2,5 kg | I33: t 5 kg | J33: t 10 kg | K33: Piezas/día 1 kg | L33: 2,5 kg | M33: 5 kg | N33: 10 kg | O33: Carga propia (min/día) | P33: Carga de carros (min/día) | Q33: Carga total (min/día) | R33: Máq. | S33: Turnos | T33: Capacidad (min/día) | U33: Disponib. (planilla) | V33: Aprovech. | W33: Cuello | X33: Nota
A34: 1 | B34: Recepción de materia prima | C34: Abastecimiento | D34: Todos | E34: 1 | F34: 1 | G34: 60 | H34: 60 | I34: 60 | J34: 60 | K34: =IF(G34>0,IF($D34="Terminados",$D$14,$F$14)*$E34*$F34,0) -> 911.79288 | L34: =IF(H34>0,IF($D34="Terminados",$D$15,$F$15)*$E34*$F34,0) -> 63.568523 | M34: =IF(I34>0,IF($D34="Terminados",$D$16,$F$16)*$E34*$F34,0) -> 287.33696 | N34: =IF(J34>0,IF($D34="Terminados",$D$17,$F$17)*$E34*$F34,0) -> 17.383176 | O34: =SUMPRODUCT(G34:J34,K34:N34)/60 -> 1280.0815 | P34: 0 | Q34: =O34+P34 -> 1280.0815 | R34: {=INDEX(Datos!$B$187:$K$187,1,ANIO-2025)} -> 2 | S34: {=INDEX(Datos!$L$187:$U$187,1,ANIO-2025)} -> 2 | T34: =R34*S34*MIN_TURNO -> 1800 | U34: 1 | V34: =IF(T34=0,0,Q34/(T34*U34)) -> 0.71115641 | W34: =IF(V34=MAX($V$34:$V$59),"◀ cuello","")
A35: 2 | B35: Corte de chapa — 1.er corte en franjas (guillotina 1, manuales + carros) | C35: Cuerpo | D35: Todos | E35: 1 | F35: 1 | G35: 4.9333333 | H35: 8.2222222 | I35: 11 | J35: 14 | K35: =IF(G35>0,IF($D35="Terminados",$D$14,$F$14)*$E35*$F35,0) -> 911.79288 | L35: =IF(H35>0,IF($D35="Terminados",$D$15,$F$15)*$E35*$F35,0) -> 63.568523 | M35: =IF(I35>0,IF($D35="Terminados",$D$16,$F$16)*$E35*$F35,0) -> 287.33696 | N35: =IF(J35>0,IF($D35="Terminados",$D$17,$F$17)*$E35*$F35,0) -> 17.383176 | O35: =SUMPRODUCT(G35:J35,K35:N35)/60 -> 140.4154 | P35: =Lotes!$H$16 -> 10.572102 | Q35: =O35+P35 -> 150.9875 | R35: {=INDEX(Datos!$B$188:$K$188,1,ANIO-2025)} -> 1 | S35: {=INDEX(Datos!$L$188:$U$188,1,ANIO-2025)} -> 1 | T35: =R35*S35*MIN_TURNO -> 450 | U35: 0.97422222 | V35: =IF(T35=0,0,Q35/(T35*U35)) -> 0.34440579 | W35: =IF(V35=MAX($V$34:$V$59),"◀ cuello","") | X35: Tiempo por modelo de parametros_manuales (filas 124 a 127). La carga de carros (cuerpos) viene de Lotes; las tiras de accesorios están en la disponibilidad.
A36: 3 | B36: Corte de chapa — 2.º corte en piezas (guillotina 2, manuales + carros) | C36: Cuerpo | D36: Todos | E36: 1 | F36: 1 | G36: 3.3333333 | H36: 4.2222222 | I36: 9.5 | J36: 12 | K36: =IF(G36>0,IF($D36="Terminados",$D$14,$F$14)*$E36*$F36,0) -> 911.79288 | L36: =IF(H36>0,IF($D36="Terminados",$D$15,$F$15)*$E36*$F36,0) -> 63.568523 | M36: =IF(I36>0,IF($D36="Terminados",$D$16,$F$16)*$E36*$F36,0) -> 287.33696 | N36: =IF(J36>0,IF($D36="Terminados",$D$17,$F$17)*$E36*$F36,0) -> 17.383176 | O36: =SUMPRODUCT(G36:J36,K36:N36)/60 -> 104.10015 | P36: =Lotes!$I$16 -> 10.176136 | Q36: =O36+P36 -> 114.27629 | R36: {=INDEX(Datos!$B$189:$K$189,1,ANIO-2025)} -> 1 | S36: {=INDEX(Datos!$L$189:$U$189,1,ANIO-2025)} -> 1 | T36: =R36*S36*MIN_TURNO -> 450 | U36: 0.99333333 | V36: =IF(T36=0,0,Q36/(T36*U36)) -> 0.25565166 | W36: =IF(V36=MAX($V$34:$V$59),"◀ cuello","") | X36: Ídem: segundo corte (piezas).
A37: 4 | B37: Corte de disco y embutido (cúpula y fondo) | C37: Fondo y cúpula | D37: Todos | E37: 2 | F37: 1 | G37: 8 | H37: 8 | I37: 8 | J37: 8 | K37: =IF(G37>0,IF($D37="Terminados",$D$14,$F$14)*$E37*$F37,0) -> 1823.5858 | L37: =IF(H37>0,IF($D37="Terminados",$D$15,$F$15)*$E37*$F37,0) -> 127.13705 | M37: =IF(I37>0,IF($D37="Terminados",$D$16,$F$16)*$E37*$F37,0) -> 574.67393 | N37: =IF(J37>0,IF($D37="Terminados",$D$17,$F$17)*$E37*$F37,0) -> 34.766353 | O37: =SUMPRODUCT(G37:J37,K37:N37)/60 -> 341.35508 | P37: 0 | Q37: =O37+P37 -> 341.35508 | R37: {=INDEX(Datos!$B$190:$K$190,1,ANIO-2025)} -> 1 | S37: {=INDEX(Datos!$L$190:$U$190,1,ANIO-2025)} -> 2 | T37: =R37*S37*MIN_TURNO -> 900 | U37: 0.68 | V37: =IF(T37=0,0,Q37/(T37*U37)) -> 0.55776973 | W37: =IF(V37=MAX($V$34:$V$59),"◀ cuello","") | X37: 2 piezas por recipiente (cúpula y fondo). Los cambios de matriz se calculan en Lotes, sección 2.
A38: 5 | B38: Preparación de cuello | C38: Cúpula | D38: Todos | E38: 1 | F38: 1 | G38: 60 | H38: 60 | I38: 60 | J38: 60 | K38: =IF(G38>0,IF($D38="Terminados",$D$14,$F$14)*$E38*$F38,0) -> 911.79288 | L38: =IF(H38>0,IF($D38="Terminados",$D$15,$F$15)*$E38*$F38,0) -> 63.568523 | M38: =IF(I38>0,IF($D38="Terminados",$D$16,$F$16)*$E38*$F38,0) -> 287.33696 | N38: =IF(J38>0,IF($D38="Terminados",$D$17,$F$17)*$E38*$F38,0) -> 17.383176 | O38: =SUMPRODUCT(G38:J38,K38:N38)/60 -> 1280.0815 | P38: 0 | Q38: =O38+P38 -> 1280.0815 | R38: {=INDEX(Datos!$B$191:$K$191,1,ANIO-2025)} -> 2 | S38: {=INDEX(Datos!$L$191:$U$191,1,ANIO-2025)} -> 2 | T38: =R38*S38*MIN_TURNO -> 1800 | U38: 1 | V38: =IF(T38=0,0,Q38/(T38*U38)) -> 0.71115641 | W38: =IF(V38=MAX($V$34:$V$59),"◀ cuello","")
A39: 6 | B39: Marcado del cuerpo (manuales + carros) | C39: Cuerpo | D39: Todos | E39: 1 | F39: 1 | G39: 20 | H39: 20 | I39: 20 | J39: 20 | K39: =IF(G39>0,IF($D39="Terminados",$D$14,$F$14)*$E39*$F39,0) -> 911.79288 | L39: =IF(H39>0,IF($D39="Terminados",$D$15,$F$15)*$E39*$F39,0) -> 63.568523 | M39: =IF(I39>0,IF($D39="Terminados",$D$16,$F$16)*$E39*$F39,0) -> 287.33696 | N39: =IF(J39>0,IF($D39="Terminados",$D$17,$F$17)*$E39*$F39,0) -> 17.383176 | O39: =SUMPRODUCT(G39:J39,K39:N39)/60 -> 426.69385 | P39: =H76+K76 -> 24.601689 | Q39: =O39+P39 -> 451.29554 | R39: {=INDEX(Datos!$B$192:$K$192,1,ANIO-2025)} -> 2 | S39: {=INDEX(Datos!$L$192:$U$192,1,ANIO-2025)} -> 1 | T39: =R39*S39*MIN_TURNO -> 900 | U39: 1 | V39: =IF(T39=0,0,Q39/(T39*U39)) -> 0.50143948 | W39: =IF(V39=MAX($V$34:$V$59),"◀ cuello","") | X39: Antes: numerado de cúpula. Ahora marca el desarrollo plano de manuales (20 s) y de carros (1,5 a 1,8 min, Carga fila 76) entre la guillotina 2 y el cilindrado, tomando del pulmón de desarrollos. 2 puestos en 1 turno: uno fijo para el 1 kg y otro para 2,5 / 5 / 10 kg y carros (Datos fila 192). Cambio de formato 15 min (Rueda fila 9).
A40: 7 | B40: Soldadura del cuello a la cúpula | C40: Cúpula | D40: Todos | E40: 1 | F40: 1 | G40: 25 | H40: 25 | I40: 25 | J40: 25 | K40: =IF(G40>0,IF($D40="Terminados",$D$14,$F$14)*$E40*$F40,0) -> 911.79288 | L40: =IF(H40>0,IF($D40="Terminados",$D$15,$F$15)*$E40*$F40,0) -> 63.568523 | M40: =IF(I40>0,IF($D40="Terminados",$D$16,$F$16)*$E40*$F40,0) -> 287.33696 | N40: =IF(J40>0,IF($D40="Terminados",$D$17,$F$17)*$E40*$F40,0) -> 17.383176 | O40: =SUMPRODUCT(G40:J40,K40:N40)/60 -> 533.36731 | P40: 0 | Q40: =O40+P40 -> 533.36731 | R40: {=INDEX(Datos!$B$193:$K$193,1,ANIO-2025)} -> 1 | S40: {=INDEX(Datos!$L$193:$U$193,1,ANIO-2025)} -> 2 | T40: =R40*S40*MIN_TURNO -> 900 | U40: 0.97333333 | V40: =IF(T40=0,0,Q40/(T40*U40)) -> 0.60886679 | W40: =IF(V40=MAX($V$34:$V$59),"◀ cuello","")
A41: 8 | B41: Cilindrado | C41: Cuerpo | D41: Todos | E41: 1 | F41: 1 | G41: 15 | H41: 15 | I41: 15 | J41: 15 | K41: =IF(G41>0,IF($D41="Terminados",$D$14,$F$14)*$E41*$F41,0) -> 911.79288 | L41: =IF(H41>0,IF($D41="Terminados",$D$15,$F$15)*$E41*$F41,0) -> 63.568523 | M41: =IF(I41>0,IF($D41="Terminados",$D$16,$F$16)*$E41*$F41,0) -> 287.33696 | N41: =IF(J41>0,IF($D41="Terminados",$D$17,$F$17)*$E41*$F41,0) -> 17.383176 | O41: =SUMPRODUCT(G41:J41,K41:N41)/60 -> 320.02038 | P41: 0 | Q41: =O41+P41 -> 320.02038 | R41: {=INDEX(Datos!$B$194:$K$194,1,ANIO-2025)} -> 1 | S41: {=INDEX(Datos!$L$194:$U$194,1,ANIO-2025)} -> 1 | T41: =R41*S41*MIN_TURNO -> 450 | U41: 0.98666667 | V41: =IF(T41=0,0,Q41/(T41*U41)) -> 0.72076663 | W41: =IF(V41=MAX($V$34:$V$59),"◀ cuello","") | X41: Layout rev. 10: roladora propia para el 1 kg; en Rueda se toman 2 máquinas.
A42: 9 | B42: Soldadura longitudinal — 2,5 a 10 kg | C42: Cuerpo | D42: Todos | E42: 1 | F42: 1 | G42: 0 | H42: 115 | I42: 115 | J42: 115 | K42: =IF(G42>0,IF($D42="Terminados",$D$14,$F$14)*$E42*$F42,0) -> 0 | L42: =IF(H42>0,IF($D42="Terminados",$D$15,$F$15)*$E42*$F42,0) -> 63.568523 | M42: =IF(I42>0,IF($D42="Terminados",$D$16,$F$16)*$E42*$F42,0) -> 287.33696 | N42: =IF(J42>0,IF($D42="Terminados",$D$17,$F$17)*$E42*$F42,0) -> 17.383176 | O42: =SUMPRODUCT(G42:J42,K42:N42)/60 -> 705.88661 | P42: 0 | Q42: =O42+P42 -> 705.88661 | R42: {=INDEX(Datos!$B$195:$K$195,1,ANIO-2025)} -> 1 | S42: {=INDEX(Datos!$L$195:$U$195,1,ANIO-2025)} -> 2 | T42: =R42*S42*MIN_TURNO -> 900 | U42: 0.98666667 | V42: =IF(T42=0,0,Q42/(T42*U42)) -> 0.79491735 | W42: =IF(V42=MAX($V$34:$V$59),"◀ cuello","") -> ◀ cuello | X42: Solo 2,5 a 10 kg (115 s por cuerpo): es el cuello de la línea.
A43: 10 | B43: Soldadura longitudinal TIG — 1 kg | C43: Cuerpo | D43: Todos | E43: 1 | F43: 1 | G43: 30 | H43: 0 | I43: 0 | J43: 0 | K43: =IF(G43>0,IF($D43="Terminados",$D$14,$F$14)*$E43*$F43,0) -> 911.79288 | L43: =IF(H43>0,IF($D43="Terminados",$D$15,$F$15)*$E43*$F43,0) -> 0 | M43: =IF(I43>0,IF($D43="Terminados",$D$16,$F$16)*$E43*$F43,0) -> 0 | N43: =IF(J43>0,IF($D43="Terminados",$D$17,$F$17)*$E43*$F43,0) -> 0 | O43: =SUMPRODUCT(G43:J43,K43:N43)/60 -> 455.89644 | P43: 0 | Q43: =O43+P43 -> 455.89644 | R43: {=INDEX(Datos!$B$196:$K$196,1,ANIO-2025)} -> 1 | S43: {=INDEX(Datos!$L$196:$U$196,1,ANIO-2025)} -> 2 | T43: =R43*S43*MIN_TURNO -> 900 | U43: 1 | V43: =IF(T43=0,0,Q43/(T43*U43)) -> 0.5065516 | W43: =IF(V43=MAX($V$34:$V$59),"◀ cuello","") | X43: Exclusivo del 1 kg: no tiene cambios de formato.
A44: 11 | B44: Encastre de fondo | C44: Unión cuerpo + fondo | D44: Todos | E44: 1 | F44: 1 | G44: 30 | H44: 30 | I44: 30 | J44: 30 | K44: =IF(G44>0,IF($D44="Terminados",$D$14,$F$14)*$E44*$F44,0) -> 911.79288 | L44: =IF(H44>0,IF($D44="Terminados",$D$15,$F$15)*$E44*$F44,0) -> 63.568523 | M44: =IF(I44>0,IF($D44="Terminados",$D$16,$F$16)*$E44*$F44,0) -> 287.33696 | N44: =IF(J44>0,IF($D44="Terminados",$D$17,$F$17)*$E44*$F44,0) -> 17.383176 | O44: =SUMPRODUCT(G44:J44,K44:N44)/60 -> 640.04077 | P44: 0 | Q44: =O44+P44 -> 640.04077 | R44: {=INDEX(Datos!$B$197:$K$197,1,ANIO-2025)} -> 1 | S44: {=INDEX(Datos!$L$197:$U$197,1,ANIO-2025)} -> 2 | T44: =R44*S44*MIN_TURNO -> 900 | U44: 0.98222222 | V44: =IF(T44=0,0,Q44/(T44*U44)) -> 0.72402802 | W44: =IF(V44=MAX($V$34:$V$59),"◀ cuello","")
A45: 12 | B45: Bordoneado | C45: Cuerpo con fondo | D45: Todos | E45: 1 | F45: 1 | G45: 20 | H45: 20 | I45: 20 | J45: 20 | K45: =IF(G45>0,IF($D45="Terminados",$D$14,$F$14)*$E45*$F45,0) -> 911.79288 | L45: =IF(H45>0,IF($D45="Terminados",$D$15,$F$15)*$E45*$F45,0) -> 63.568523 | M45: =IF(I45>0,IF($D45="Terminados",$D$16,$F$16)*$E45*$F45,0) -> 287.33696 | N45: =IF(J45>0,IF($D45="Terminados",$D$17,$F$17)*$E45*$F45,0) -> 17.383176 | O45: =SUMPRODUCT(G45:J45,K45:N45)/60 -> 426.69385 | P45: 0 | Q45: =O45+P45 -> 426.69385 | R45: {=INDEX(Datos!$B$198:$K$198,1,ANIO-2025)} -> 1 | S45: {=INDEX(Datos!$L$198:$U$198,1,ANIO-2025)} -> 2 | T45: =R45*S45*MIN_TURNO -> 900 | U45: 0.98222222 | V45: =IF(T45=0,0,Q45/(T45*U45)) -> 0.48268535 | W45: =IF(V45=MAX($V$34:$V$59),"◀ cuello","")
...

Sheet Lotes
A1: PASO 2 — CUÁNTO HACER POR VEZ EN LAS MÁQUINAS CON CAMBIO CARO (guillotinas y embutidora)
A2: Regla del «punto de seguir procesando»: una tanda tiene que durar al menos 3 veces lo que lleva el cambio de formato (el cambio nunca pasa del 25 % de la tanda). Si el formato se consume más lento, se corta o se prensa cada varios días y lo que sobra queda en un pulmón.
A3: ▶ Guillotinas: columnas O (cada cuántos días), P (hojas por tanda) y W (pulmón). Embutidora: J (cada cuántos días), K (piezas por tanda) y O (supermercado). Capacidad en las filas 22 a 24 y 42.
A4: Mes | B4: =Carga!B4 -> Ene 2035
A6: 1) GUILLOTINAS G1 (franjas) Y G2 (piezas) — compartidas por manuales y carros
A7: Formato | B7: Línea | C7: Hoja (mm) | D7: Cuerpos por hoja | E7: Cuerpos por día | F7: G1 (min/cuerpo) | G7: G2 (min/cuerpo) | H7: Corrida G1 (min/día) = E × F | I7: Corte G2 (min/día) = E × G | J7: Frec. mínima (días) = 3 × cambio ÷ H | K7: Frec. del modelo en la ola (días) | L7: Tope por espacio (días) | M7: Frec. calculada (días) | N7: Frec. elegida (vacío = calculada) | O7: Frec. final (días) | P7: Hojas por tanda | Q7: Cuerpos por tanda | R7: Cobertura (días) | S7: Corrida de la tanda en G1 (min) | T7: Cambio ÷ tanda | U7: Cambios por día | V7: Fase (día) | W7: Pulmón de desarrollos (cuerpos) | X7: kg por hoja | Y7: Paquete de chapa (kg) | Z7: Lectura
A8: Manuales 1 kg | B8: Manuales | C8: 1.220 × 2.440 × 0,9 | D8: 45 | E8: =Carga!$F$14 -> 911.79288 | F8: =Carga!G$35/60 -> 0.082222222 | G8: =Carga!G$36/60 -> 0.055555556 | H8: =E8*F8 -> 74.969636 | I8: =E8*G8 -> 50.65516 | J8: =IF(H8=0,0,R_CORRIDA*S_G1/H8) -> 0.60024301 | K8: =Rueda!$H$35 -> 1 | L8: =K_MAX -> 16 | M8: =MAX(K8,MIN(MIN(K_MAX,BASE*2^MAX(0,ROUNDUP(LOG(MAX(1,(MAX(J8,K8))/BASE),2)-0.000001,0))),MIN(K_MAX,BASE*2^MAX(0,ROUNDDOWN(LOG(MAX(BASE,L8)/BASE,2)+0.000001,0))))) -> 1 | O8: =IF(N8="",M8,N8) -> 1 | P8: =ROUNDUP(E8*O8/D8,0) -> 21 | Q8: =P8*D8 -> 945 | R8: =IF(E8=0,0,Q8/E8) -> 1.0364196 | S8: =Q8*F8 -> 77.7 | T8: =IF(S8+S_G1=0,0,S_G1/(S_G1+S8)) -> 0.1618123 | U8: =IF(E8=0,0,1/O8) -> 1 | V8: 0 | W8: =IF(Q8=0,0,Q8*(1-E8*S8/(Q8*MIN_TURNO))+E8*H_PROT*60/MIN_TURNO) -> 909.13615 | X8: 21.0311 | Y8: =P8*X8 -> 441.6531 | Z8: =IF(E8=0,"Sin producción este mes",IF(O8<=BASE,"Se corta todos los días: "&P8&" hojas","Se corta cada "&O8&" días: "&P8&" hojas por tanda; entre tandas sale del pulmón")) -> Se corta todos los días: 21 hojas
A9: Manuales 2,5 kg | B9: Manuales | C9: 1.220 × 2.440 × 1,25 | D9: 27 | E9: =Carga!$F$15 -> 63.568523 | F9: =Carga!H$35/60 -> 0.13703704 | G9: =Carga!H$36/60 -> 0.07037037 | H9: =E9*F9 -> 8.711242 | I9: =E9*G9 -> 4.4733405 | J9: =IF(H9=0,0,R_CORRIDA*S_G1/H9) -> 5.1657387 | K9: =Rueda!$H$36 -> 1 | L9: =K_MAX -> 16 | M9: =MAX(K9,MIN(MIN(K_MAX,BASE*2^MAX(0,ROUNDUP(LOG(MAX(1,(MAX(J9,K9))/BASE),2)-0.000001,0))),MIN(K_MAX,BASE*2^MAX(0,ROUNDDOWN(LOG(MAX(BASE,L9)/BASE,2)+0.000001,0))))) -> 8 | O9: =IF(N9="",M9,N9) -> 8 | P9: =ROUNDUP(E9*O9/D9,0) -> 19 | Q9: =P9*D9 -> 513 | R9: =IF(E9=0,0,Q9/E9) -> 8.0700318 | S9: =Q9*F9 -> 70.3 | T9: =IF(S9+S_G1=0,0,S_G1/(S_G1+S9)) -> 0.17584994 | U9: =IF(E9=0,0,1/O9) -> 0.125 | V9: 0 | W9: =IF(Q9=0,0,Q9*(1-E9*S9/(Q9*MIN_TURNO))+E9*H_PROT*60/MIN_TURNO) -> 511.54499 | X9: 29.2098 | Y9: =P9*X9 -> 554.9862 | Z9: =IF(E9=0,"Sin producción este mes",IF(O9<=BASE,"Se corta todos los días: "&P9&" hojas","Se corta cada "&O9&" días: "&P9&" hojas por tanda; entre tandas sale del pulmón")) -> Se corta cada 8 días: 19 hojas por tanda; entre tandas sale del pulmón
A10: Manuales 5 kg | B10: Manuales | C10: 1.000 × 2.000 × 1,6 | D10: 12 | E10: =Carga!$F$16 -> 287.33696 | F10: =Carga!I$35/60 -> 0.18333333 | G10: =Carga!I$36/60 -> 0.15833333 | H10: =E10*F10 -> 52.678443 | I10: =E10*G10 -> 45.495019 | J10: =IF(H10=0,0,R_CORRIDA*S_G1/H10) -> 0.85423936 | K10: =Rueda!$H$37 -> 1 | L10: =K_MAX -> 16 | M10: =MAX(K10,MIN(MIN(K_MAX,BASE*2^MAX(0,ROUNDUP(LOG(MAX(1,(MAX(J10,K10))/BASE),2)-0.000001,0))),MIN(K_MAX,BASE*2^MAX(0,ROUNDDOWN(LOG(MAX(BASE,L10)/BASE,2)+0.000001,0))))) -> 1 | O10: =IF(N10="",M10,N10) -> 1 | P10: =ROUNDUP(E10*O10/D10,0) -> 24 | Q10: =P10*D10 -> 288 | R10: =IF(E10=0,0,Q10/E10) -> 1.0023075 | S10: =Q10*F10 -> 52.8 | T10: =IF(S10+S_G1=0,0,S_G1/(S_G1+S10)) -> 0.22123894 | U10: =IF(E10=0,0,1/O10) -> 1 | V10: 0 | W10: =IF(Q10=0,0,Q10*(1-E10*S10/(Q10*MIN_TURNO))+E10*H_PROT*60/MIN_TURNO) -> 292.59739 | X10: 25.12 | Y10: =P10*X10 -> 602.88 | Z10: =IF(E10=0,"Sin producción este mes",IF(O10<=BASE,"Se corta todos los días: "&P10&" hojas","Se corta cada "&O10&" días: "&P10&" hojas por tanda; entre tandas sale del pulmón")) -> Se corta todos los días: 24 hojas
A11: Manuales 10 kg | B11: Manuales | C11: 1.500 × 3.000 × 2,0 | D11: 15 | E11: =Carga!$F$17 -> 17.383176 | F11: =Carga!J$35/60 -> 0.23333333 | G11: =Carga!J$36/60 -> 0.2 | H11: =E11*F11 -> 4.0560745 | I11: =E11*G11 -> 3.4766353 | J11: =IF(H11=0,0,R_CORRIDA*S_G1/H11) -> 11.094471 | K11: =Rueda!$H$38 -> 2 | L11: =K_MAX -> 16 | M11: =MAX(K11,MIN(MIN(K_MAX,BASE*2^MAX(0,ROUNDUP(LOG(MAX(1,(MAX(J11,K11))/BASE),2)-0.000001,0))),MIN(K_MAX,BASE*2^MAX(0,ROUNDDOWN(LOG(MAX(BASE,L11)/BASE,2)+0.000001,0))))) -> 16 | O11: =IF(N11="",M11,N11) -> 16 | P11: =ROUNDUP(E11*O11/D11,0) -> 19 | Q11: =P11*D11 -> 285 | R11: =IF(E11=0,0,Q11/E11) -> 16.395162 | S11: =Q11*F11 -> 66.5 | T11: =IF(S11+S_G1=0,0,S_G1/(S_G1+S11)) -> 0.18404908 | U11: =IF(E11=0,0,1/O11) -> 0.0625 | V11: 2 | W11: =IF(Q11=0,0,Q11*(1-E11*S11/(Q11*MIN_TURNO))+E11*H_PROT*60/MIN_TURNO) -> 284.74891 | X11: 70.65 | Y11: =P11*X11 -> 1342.35 | Z11: =IF(E11=0,"Sin producción este mes",IF(O11<=BASE,"Se corta todos los días: "&P11&" hojas","Se corta cada "&O11&" días: "&P11&" hojas por tanda; entre tandas sale del pulmón")) -> Se corta cada 16 días: 19 hojas por tanda; entre tandas sale del pulmón
A12: Carros 25 kg (hoja 3,2) | B12: Carros | C12: 1.500 × 3.000 × 3,2 | D12: 9 | E12: =Carga!$E$22 -> 3.3035698 | F12: 0.57649171 | G12: 0.63903315 | H12: =E12*F12 -> 1.9044806 | I12: =E12*G12 -> 2.1110906 | J12: =IF(H12=0,0,R_CORRIDA*S_G1/H12) -> 23.62849 | K12: =BASE -> 1 | L12: 4 | M12: =MAX(K12,MIN(MIN(K_MAX,BASE*2^MAX(0,ROUNDUP(LOG(MAX(1,(MAX(J12,K12))/BASE),2)-0.000001,0))),MIN(K_MAX,BASE*2^MAX(0,ROUNDDOWN(LOG(MAX(BASE,L12)/BASE,2)+0.000001,0))))) -> 4 | O12: =IF(N12="",M12,N12) -> 4 | P12: =ROUNDUP(E12*O12/D12,0) -> 2 | Q12: =P12*D12 -> 18 | R12: =IF(E12=0,0,Q12/E12) -> 5.4486514 | S12: =Q12*F12 -> 10.376851 | T12: =IF(S12+S_G1=0,0,S_G1/(S_G1+S12)) -> 0.59108989 | U12: =IF(E12=0,0,1/O12) -> 0.25 | V12: 1 | W12: =IF(Q12=0,0,Q12*(1-E12*S12/(Q12*MIN_TURNO))+E12*H_PROT*60/MIN_TURNO) -> 18.364297 | X12: 113.04 | Y12: =P12*X12 -> 226.08 | Z12: =IF(E12=0,"Sin producción este mes",IF(O12<=BASE,"Se corta todos los días: "&P12&" hojas","Se corta cada "&O12&" días: "&P12&" hojas por tanda; entre tandas sale del pulmón")) -> Se corta cada 4 días: 2 hojas por tanda; entre tandas sale del pulmón
A13: Carros 50 kg (hoja 3,2) | B13: Carros | C13: 1.500 × 3.000 × 3,2 | D13: 6 | E13: =Carga!$E$23 -> 7.2608495 | F13: 0.53430939 | G13: 0.59685083 | H13: =E13*F13 -> 3.8795401 | I13: =E13*G13 -> 4.333644 | J13: =IF(H13=0,0,R_CORRIDA*S_G1/H13) -> 11.599313 | K13: =BASE -> 1 | L13: 4 | M13: =MAX(K13,MIN(MIN(K_MAX,BASE*2^MAX(0,ROUNDUP(LOG(MAX(1,(MAX(J13,K13))/BASE),2)-0.000001,0))),MIN(K_MAX,BASE*2^MAX(0,ROUNDDOWN(LOG(MAX(BASE,L13)/BASE,2)+0.000001,0))))) -> 4 | O13: =IF(N13="",M13,N13) -> 4 | P13: =ROUNDUP(E13*O13/D13,0) -> 5 | Q13: =P13*D13 -> 30 | R13: =IF(E13=0,0,Q13/E13) -> 4.131748 | S13: =Q13*F13 -> 16.029282 | T13: =IF(S13+S_G1=0,0,S_G1/(S_G1+S13)) -> 0.48341435 | U13: =IF(E13=0,0,1/O13) -> 0.25 | V13: 2 | W13: =IF(Q13=0,0,Q13*(1-E13*S13/(Q13*MIN_TURNO))+E13*H_PROT*60/MIN_TURNO) -> 30.709477 | X13: 113.04 | Y13: =P13*X13 -> 565.2 | Z13: =IF(E13=0,"Sin producción este mes",IF(O13<=BASE,"Se corta todos los días: "&P13&" hojas","Se corta cada "&O13&" días: "&P13&" hojas por tanda; entre tandas sale del pulmón")) -> Se corta cada 4 días: 5 hojas por tanda; entre tandas sale del pulmón
A14: Carros 70 + 100 kg (hoja mixta 4,75) | B14: Carros | C14: 1.500 × 3.000 × 4,75 | D14: 4 | E14: =Carga!$E$24+Carga!$E$25 -> 2.6416998 | F14: 1.8125 | G14: 1.4125 | H14: =E14*F14 -> 4.7880809 | I14: =E14*G14 -> 3.731401 | J14: =IF(H14=0,0,R_CORRIDA*S_G1/H14) -> 9.3983374 | K14: =BASE -> 1 | L14: 4 | M14: =MAX(K14,MIN(MIN(K_MAX,BASE*2^MAX(0,ROUNDUP(LOG(MAX(1,(MAX(J14,K14))/BASE),2)-0.000001,0))),MIN(K_MAX,BASE*2^MAX(0,ROUNDDOWN(LOG(MAX(BASE,L14)/BASE,2)+0.000001,0))))) -> 4 | O14: =IF(N14="",M14,N14) -> 4 | P14: =ROUNDUP(E14*O14/D14,0) -> 3 | Q14: =P14*D14 -> 12 | R14: =IF(E14=0,0,Q14/E14) -> 4.5425298 | S14: =Q14*F14 -> 21.75 | T14: =IF(S14+S_G1=0,0,S_G1/(S_G1+S14)) -> 0.40816327 | U14: =IF(E14=0,0,1/O14) -> 0.25 | V14: 3 | W14: =IF(Q14=0,0,Q14*(1-E14*S14/(Q14*MIN_TURNO))+E14*H_PROT*60/MIN_TURNO) -> 12.224544 | X14: 167.7937 | Y14: =P14*X14 -> 503.3811 | Z14: =IF(E14=0,"Sin producción este mes",IF(O14<=BASE,"Se corta todos los días: "&P14&" hojas","Se corta cada "&O14&" días: "&P14&" hojas por tanda; entre tandas sale del pulmón")) -> Se corta cada 4 días: 3 hojas por tanda; entre tandas sale del pulmón
A15: Carros: tiras y piezas de accesorios (fijo por día) | H15: =TIRAS_CARROS+TIRAS_EXTRA -> 44.8 | I15: 0
A16: Subtotal carros (cuerpos) | H16: =SUM(H12:H14) -> 10.572102 | I16: =SUM(I12:I14) -> 10.176136
A17: Subtotal manuales | H17: =SUM(H8:H11) -> 140.4154 | I17: =SUM(I8:I11) -> 104.10015
A18: Total | U18: =SUM(U8:U14) -> 2.9375 | W18: =SUM(W8:W14) -> 2059.3258
A20: Capacidad de las guillotinas con cambios, alistamiento y rendimiento del operario
A21: Recurso | B21: Máq. | C21: Turnos | D21: Capacidad (min/día) | E21: Corte manuales (min/día) | F21: Corte carros + accesorios (min/día) | G21: Corte ÷ rendimiento (min/día) | H21: Cambios por día | I21: Min de cambio por día | J21: Alistamiento + desalistamiento (min/día) | K21: Carga total (min/día) | L21: Aprovech. | M21: Estado
A22: Guillotina 1 — franjas (Ermaksan HGS 2600-6) | B22: =Carga!R35 -> 1 | C22: =Carga!S35 -> 1 | D22: =B22*C22*MIN_TURNO -> 450 | E22: =H17 -> 140.4154 | F22: =H16+H15 -> 55.372102 | G22: =(E22+F22)/REND_CORTE -> 230.33823 | H22: =U18 -> 2.9375 | I22: =H22*S_G1 -> 44.0625 | J22: =B22*C22*(ALIST_G+DESALIST_G) -> 20 | K22: =G22+I22+J22 -> 294.40073 | L22: =K22/D22 -> 0.65422385 | M22: =IF(L22<=UMBRAL,"OK","Pasa el umbral") -> OK
A23: Guillotina 2 — piezas (QC12Y 6 × 2500) | B23: =Carga!R36 -> 1 | C23: =Carga!S36 -> 1 | D23: =B23*C23*MIN_TURNO -> 450 | E23: =I17 -> 104.10015 | F23: =I16 -> 10.176136 | G23: =(E23+F23)/REND_CORTE -> 134.44269 | H23: =U18 -> 2.9375 | I23: =H23*S_G2 -> 14.6875 | J23: =B23*C23*(ALIST_G+DESALIST_G) -> 20 | K23: =G23+I23+J23 -> 169.13019 | L23: =K23/D23 -> 0.37584488 | M23: =IF(L23<=UMBRAL,"OK","Pasa el umbral") -> OK
A24: Operario de corte, si una persona atiende G1 y G2 | D24: =MIN_TURNO*MAX(C22,C23) -> 450 | K24: =K22+K23 -> 463.53093 | L24: =K24/D24 -> 1.0300687 | M24: =IF(L24<=UMBRAL,"OK con 1 operario","Hacen falta 2 operarios") -> Hacen falta 2 operarios
A25: Carga = (cortes + manipulación por hoja) ÷ rendimiento del operario (85 %) + cambios de formato (15 min G1: programa 5 + traer y devolver el paquete 10; 5 min G2) + 20 min por turno de alistamiento y desalistamiento.
A28: 2) EMBUTIDORA — 8 matrices (cúpula y fondo de cada modelo), cambio de 90 min: trabaja contra un supermercado
A29: Matriz | B29: Modelo | C29: Pieza | D29: Piezas por día | E29: s por golpe | F29: Corrida (min/día) = D × E ÷ 60 | G29: Frec. mínima (días) = 3 × cambio ÷ F | H29: Frec. calculada (días) | I29: Frec. elegida (vacío = calculada) | J29: Frec. final (días) | K29: Piezas por tanda = D × J | L29: Prensa por tanda (min) | M29: Cambio ÷ tanda | N29: Fase (día) | O29: Supermercado máximo (piezas) | P29: Cajones como máximo (plan, Pulmones filas 22–23) | Q29: Pallets en el rack (12 cajones, un modelo) | R29: kg de fleje por pieza | S29: Rollo de fleje = tanda (kg) | T29: Lectura
A30: C1 | B30: 1 kg | C30: Cúpula | D30: =Carga!K$37/Carga!$E$37 -> 911.79288 | E30: =Carga!G$37 -> 8 | F30: =D30*E30/60 -> 121.57238 | G30: =IF(F30=0,0,R_CORRIDA*S_EMB/F30) -> 2.2208991 | H30: =MIN(K_MAX,BASE*2^MAX(0,ROUNDUP(LOG(MAX(1,(G30)/BASE),2)-0.000001,0))) -> 4 | J30: =IF(I30="",H30,I30) -> 4 | K30: =D30*J30 -> 3647.1715 | L30: =K30*E30/60 -> 486.28953 | M30: =IF(L30+S_EMB=0,0,S_EMB/(S_EMB+L30)) -> 0.1561715 | N30: 0 | O30: =K30*(1-IF($D$42=0,0,F30/$D$42))+D30*SS_SUPER -> 4066.3029 | P30: =IF(Pulmones!$H$23=0,0,ROUNDUP(Pulmones!$H$23/Parametros!$B$67,0)) -> 15 | Q30: =IF(P30=0,0,ROUNDUP(P30/PAL_CAJ,0)) -> 2 | R30: 0.059694404 | S30: =K30*R30 -> 217.71573 | T30: =IF(D30=0,"Sin producción este mes","Se prensa cada "&J30&" días: "&FIXED(K30,0)&" piezas en "&FIXED(L30/60,1)&" h") -> Se prensa cada 4 días: 3,647 piezas en 8.1 h
A31: F1 | B31: 1 kg | C31: Fondo | D31: =Carga!K$37/Carga!$E$37 -> 911.79288 | E31: =Carga!G$37 -> 8 | F31: =D31*E31/60 -> 121.57238 | G31: =IF(F31=0,0,R_CORRIDA*S_EMB/F31) -> 2.2208991 | H31: =MIN(K_MAX,BASE*2^MAX(0,ROUNDUP(LOG(MAX(1,(G31)/BASE),2)-0.000001,0))) -> 4 | J31: =IF(I31="",H31,I31) -> 4 | K31: =D31*J31 -> 3647.1715 | L31: =K31*E31/60 -> 486.28953 | M31: =IF(L31+S_EMB=0,0,S_EMB/(S_EMB+L31)) -> 0.1561715 | N31: 1 | O31: =K31*(1-IF($D$42=0,0,F31/$D$42))+D31*SS_SUPER -> 4066.3029 | P31: =IF(Pulmones!$H$22=0,0,ROUNDUP(Pulmones!$H$22/Parametros!$B$66,0)) -> 14 | Q31: =IF(P31=0,0,ROUNDUP(P31/PAL_CAJ,0)) -> 2 | R31: 0.069216049 | S31: =K31*R31 -> 252.4428 | T31: =IF(D31=0,"Sin producción este mes","Se prensa cada "&J31&" días: "&FIXED(K31,0)&" piezas en "&FIXED(L31/60,1)&" h") -> Se prensa cada 4 días: 3,647 piezas en 8.1 h
A32: C2,5 | B32: 2,5 kg | C32: Cúpula | D32: =Carga!L$37/Carga!$E$37 -> 63.568523 | E32: =Carga!H$37 -> 8 | F32: =D32*E32/60 -> 8.4758031 | G32: =IF(F32=0,0,R_CORRIDA*S_EMB/F32) -> 31.855389 | H32: =MIN(K_MAX,BASE*2^MAX(0,ROUNDUP(LOG(MAX(1,(G32)/BASE),2)-0.000001,0))) -> 16 | J32: =IF(I32="",H32,I32) -> 16 | K32: =D32*J32 -> 1017.0964 | L32: =K32*E32/60 -> 135.61285 | M32: =IF(L32+S_EMB=0,0,S_EMB/(S_EMB+L32)) -> 0.39891345 | N32: 6 | O32: =K32*(1-IF($D$42=0,0,F32/$D$42))+D32*SS_SUPER -> 1071.0863 | P32: =IF(Pulmones!$I$23=0,0,ROUNDUP(Pulmones!$I$23/Parametros!$C$67,0)) -> 8 | Q32: =IF(P32=0,0,ROUNDUP(P32/PAL_CAJ,0)) -> 1 | R32: 0.2532172 | S32: =K32*R32 -> 257.5463 | T32: =IF(D32=0,"Sin producción este mes","Se prensa cada "&J32&" días: "&FIXED(K32,0)&" piezas en "&FIXED(L32/60,1)&" h") -> Se prensa cada 16 días: 1,017 piezas en 2.3 h
A33: F2,5 | B33: 2,5 kg | C33: Fondo | D33: =Carga!L$37/Carga!$E$37 -> 63.568523 | E33: =Carga!H$37 -> 8 | F33: =D33*E33/60 -> 8.4758031 | G33: =IF(F33=0,0,R_CORRIDA*S_EMB/F33) -> 31.855389 | H33: =MIN(K_MAX,BASE*2^MAX(0,ROUNDUP(LOG(MAX(1,(G33)/BASE),2)-0.000001,0))) -> 16 | J33: =IF(I33="",H33,I33) -> 16 | K33: =D33*J33 -> 1017.0964 | L33: =K33*E33/60 -> 135.61285 | M33: =IF(L33+S_EMB=0,0,S_EMB/(S_EMB+L33)) -> 0.39891345 | N33: 7 | O33: =K33*(1-IF($D$42=0,0,F33/$D$42))+D33*SS_SUPER -> 1071.0863 | P33: =IF(Pulmones!$I$22=0,0,ROUNDUP(Pulmones!$I$22/Parametros!$C$66,0)) -> 8 | Q33: =IF(P33=0,0,ROUNDUP(P33/PAL_CAJ,0)) -> 1 | R33: 0.20517047 | S33: =K33*R33 -> 208.67814 | T33: =IF(D33=0,"Sin producción este mes","Se prensa cada "&J33&" días: "&FIXED(K33,0)&" piezas en "&FIXED(L33/60,1)&" h") -> Se prensa cada 16 días: 1,017 piezas en 2.3 h
A34: C5 | B34: 5 kg | C34: Cúpula | D34: =Carga!M$37/Carga!$E$37 -> 287.33696 | E34: =Carga!I$37 -> 8 | F34: =D34*E34/60 -> 38.311595 | G34: =IF(F34=0,0,R_CORRIDA*S_EMB/F34) -> 7.0474747 | H34: =MIN(K_MAX,BASE*2^MAX(0,ROUNDUP(LOG(MAX(1,(G34)/BASE),2)-0.000001,0))) -> 8 | J34: =IF(I34="",H34,I34) -> 8 | K34: =D34*J34 -> 2298.6957 | L34: =K34*E34/60 -> 306.49276 | M34: =IF(L34+S_EMB=0,0,S_EMB/(S_EMB+L34)) -> 0.22699027 | N34: 2 | O34: =K34*(1-IF($D$42=0,0,F34/$D$42))+D34*SS_SUPER -> 2488.1808 | P34: =IF(Pulmones!$J$23=0,0,ROUNDUP(Pulmones!$J$23/Parametros!$D$67,0)) -> 55 | Q34: =IF(P34=0,0,ROUNDUP(P34/PAL_CAJ,0)) -> 5 | R34: 0.51398146 | S34: =K34*R34 -> 1181.487 | T34: =IF(D34=0,"Sin producción este mes","Se prensa cada "&J34&" días: "&FIXED(K34,0)&" piezas en "&FIXED(L34/60,1)&" h") -> Se prensa cada 8 días: 2,299 piezas en 5.1 h
A35: F5 | B35: 5 kg | C35: Fondo | D35: =Carga!M$37/Carga!$E$37 -> 287.33696 | E35: =Carga!I$37 -> 8 | F35: =D35*E35/60 -> 38.311595 | G35: =IF(F35=0,0,R_CORRIDA*S_EMB/F35) -> 7.0474747 | H35: =MIN(K_MAX,BASE*2^MAX(0,ROUNDUP(LOG(MAX(1,(G35)/BASE),2)-0.000001,0))) -> 8 | J35: =IF(I35="",H35,I35) -> 8 | K35: =D35*J35 -> 2298.6957 | L35: =K35*E35/60 -> 306.49276 | M35: =IF(L35+S_EMB=0,0,S_EMB/(S_EMB+L35)) -> 0.22699027 | N35: 3 | O35: =K35*(1-IF($D$42=0,0,F35/$D$42))+D35*SS_SUPER -> 2488.1808 | P35: =IF(Pulmones!$J$22=0,0,ROUNDUP(Pulmones!$J$22/Parametros!$D$66,0)) -> 41 | Q35: =IF(P35=0,0,ROUNDUP(P35/PAL_CAJ,0)) -> 4 | R35: 0.38562709 | S35: =K35*R35 -> 886.43934 | T35: =IF(D35=0,"Sin producción este mes","Se prensa cada "&J35&" días: "&FIXED(K35,0)&" piezas en "&FIXED(L35/60,1)&" h") -> Se prensa cada 8 días: 2,299 piezas en 5.1 h
A36: C10 | B36: 10 kg | C36: Cúpula | D36: =Carga!N$37/Carga!$E$37 -> 17.383176 | E36: =Carga!J$37 -> 8 | F36: =D36*E36/60 -> 2.3177568 | G36: =IF(F36=0,0,R_CORRIDA*S_EMB/F36) -> 116.49194 | H36: =MIN(K_MAX,BASE*2^MAX(0,ROUNDUP(LOG(MAX(1,(G36)/BASE),2)-0.000001,0))) -> 16 | J36: =IF(I36="",H36,I36) -> 16 | K36: =D36*J36 -> 278.13082 | L36: =K36*E36/60 -> 37.08411 | M36: =IF(L36+S_EMB=0,0,S_EMB/(S_EMB+L36)) -> 0.7081924 | N36: 14 | O36: =K36*(1-IF($D$42=0,0,F36/$D$42))+D36*SS_SUPER -> 294.79773 | P36: =IF(Pulmones!$K$23=0,0,ROUNDUP(Pulmones!$K$23/Parametros!$E$67,0)) -> 2 | Q36: =IF(P36=0,0,ROUNDUP(P36/PAL_CAJ,0)) -> 1 | R36: 0.88096644 | S36: =K36*R36 -> 245.02392 | T36: =IF(D36=0,"Sin producción este mes","Se prensa cada "&J36&" días: "&FIXED(K36,0)&" piezas en "&FIXED(L36/60,1)&" h") -> Se prensa cada 16 días: 278 piezas en 0.6 h
A37: F10 | B37: 10 kg | C37: Fondo | D37: =Carga!N$37/Carga!$E$37 -> 17.383176 | E37: =Carga!J$37 -> 8 | F37: =D37*E37/60 -> 2.3177568 | G37: =IF(F37=0,0,R_CORRIDA*S_EMB/F37) -> 116.49194 | H37: =MIN(K_MAX,BASE*2^MAX(0,ROUNDUP(LOG(MAX(1,(G37)/BASE),2)-0.000001,0))) -> 16 | J37: =IF(I37="",H37,I37) -> 16 | K37: =D37*J37 -> 278.13082 | L37: =K37*E37/60 -> 37.08411 | M37: =IF(L37+S_EMB=0,0,S_EMB/(S_EMB+L37)) -> 0.7081924 | N37: 15 | O37: =K37*(1-IF($D$42=0,0,F37/$D$42))+D37*SS_SUPER -> 294.79773 | P37: =IF(Pulmones!$K$22=0,0,ROUNDUP(Pulmones!$K$22/Parametros!$E$66,0)) -> 2 | Q37: =IF(P37=0,0,ROUNDUP(P37/PAL_CAJ,0)) -> 1 | R37: 0.6437 | S37: =K37*R37 -> 179.03281 | T37: =IF(D37=0,"Sin producción este mes","Se prensa cada "&J37&" días: "&FIXED(K37,0)&" piezas en "&FIXED(L37/60,1)&" h") -> Se prensa cada 16 días: 278 piezas en 0.6 h
A38: Total | F38: =SUM(F30:F37) -> 341.35508 | O38: =SUM(O30:O37) -> 15840.735 | P38: =SUM(P30:P37) -> 145 | Q38: =SUM(Q30:Q37) -> 17
A39: Supermercado = tanda × (1 − consumo ÷ ritmo de la prensa) + 1 día de seguridad. Cúpula y fondo de un mismo modelo se prensan en días seguidos (fases) para que lleguen juntos y ningún día pase la capacidad.
A41: Recurso | B41: Máq. | C41: Turnos | D41: Capacidad (min/día) | E41: Golpes (min/día) | F41: Cambios por día | G41: Min de cambio por día | H41: Aprovech. con cambios | I41: Aprovech. de la planilla | J41: Cambios por mes | K41: Estado
A42: Prensa Sangiacomo | B42: =Carga!R37 -> 1 | C42: =Carga!S37 -> 2 | D42: =B42*C42*MIN_TURNO -> 900 | E42: =F38 -> 341.35508 | F42: =SUMPRODUCT(--(D30:D37>0),1/J30:J37) -> 1 | G42: =F42*S_EMB -> 90 | H42: =(E42+G42)/D42 -> 0.47928342 | I42: =Carga!V37 -> 0.55776973 | J42: =F42*DIAS -> 20 | K42: =IF(H42<=UMBRAL,"OK","Pasa el umbral") -> OK
A43: La planilla de aprovechamiento supone 32 cambios por mes (4 cúpulas y 4 fondos por semana). Con la regla de la corrida mínima quedan menos cambios y la disponibilidad sube.

Sheet Rueda
A1: PASO 3 — LA RUEDA: qué formato pasa cada día por cada puesto (ola del cilindrado al embalaje)
A2: Marcapasos: soldadura circunferencial, donde se juntan el cuerpo con fondo y la cúpula con cuello. Todos los puestos de la ola corren el mismo formato el mismo día, uno detrás del otro: así los pulmones entre ellos quedan chicos.
A3: ▶ Sección 2: cada cuántos días pasa cada modelo (columna H). Sección 3: el calendario de 20 días; ninguna celda de carga debe pasar el 100 %.
A4: Mes | B4: =Carga!B4 -> Ene 2035
A6: 1) PUESTOS DE LA OLA: cambios de formato y aprovechamiento con la rueda
A7: N° | B7: Puesto | C7: Cambio (min) | D7: ¿Cambia por formato? | E7: 1 kg en máquina propia | F7: Máq. | G7: Turnos | H7: Capacidad (min/día) | I7: Carga (min/día) | J7: Carga del 1 kg (min/día) | K7: Corrida 1 kg (min/día) | L7: Corrida 2,5 kg | M7: Corrida 5 kg | N7: Corrida 10 kg | O7: Frec. mín. 1 kg (días) | P7: Frec. mín. 2,5 kg | Q7: Frec. mín. 5 kg | R7: Frec. mín. 10 kg | S7: Frec. máx. 1 kg (días) | T7: Frec. máx. 2,5 kg | U7: Frec. máx. 5 kg | V7: Frec. máx. 10 kg | W7: Cambios por día | X7: Min de cambio por día | Y7: Aprovech. con la rueda | Z7: Estado | AA7: Nota
A8: 5 | B8: =Carga!B38 -> Preparación de cuello | C8: 0 | D8: No | E8: No | F8: =Carga!R38 -> 2 | G8: =Carga!S38 -> 2 | H8: =F8*G8*MIN_TURNO -> 1800 | I8: =Carga!Q38 -> 1280.0815 | J8: =Carga!K38*Carga!G38/60 -> 911.79288 | K8: =Carga!K38*Carga!G38/60 -> 911.79288 | L8: =Carga!L38*Carga!H38/60 -> 63.568523 | M8: =Carga!M38*Carga!I38/60 -> 287.33696 | N8: =Carga!N38*Carga!J38/60 -> 17.383176 | O8: =IF(OR($D8="No",K8=0,AND($E8="Sí",$F8>=2)),0,R_CORRIDA*$C8/K8) -> 0 | P8: =IF(OR($D8="No",L8=0,FALSE()),0,R_CORRIDA*$C8/L8) -> 0 | Q8: =IF(OR($D8="No",M8=0,FALSE()),0,R_CORRIDA*$C8/M8) -> 0 | R8: =IF(OR($D8="No",N8=0,FALSE()),0,R_CORRIDA*$C8/N8) -> 0 | S8: =IF(OR($D8="No",K8=0),99,MAX(0,IF(AND($E8="Sí",$F8>=2),99*K8,$H8*UMBRAL-($I8-K8)-$C8*COUNTIF($K8:$N8,">0")))/K8) -> 99 | T8: =IF(OR($D8="No",L8=0),99,MAX(0,IF(AND($E8="Sí",$F8>=2),($F8-1)*$G8*MIN_TURNO*UMBRAL-($I8-$J8-L8)-$C8*(COUNTIF($K8:$N8,">0")-1),$H8*UMBRAL-($I8-L8)-$C8*COUNTIF($K8:$N8,">0")))/L8) -> 99 | U8: =IF(OR($D8="No",M8=0),99,MAX(0,IF(AND($E8="Sí",$F8>=2),($F8-1)*$G8*MIN_TURNO*UMBRAL-($I8-$J8-M8)-$C8*(COUNTIF($K8:$N8,">0")-1),$H8*UMBRAL-($I8-M8)-$C8*COUNTIF($K8:$N8,">0")))/M8) -> 99 | V8: =IF(OR($D8="No",N8=0),99,MAX(0,IF(AND($E8="Sí",$F8>=2),($F8-1)*$G8*MIN_TURNO*UMBRAL-($I8-$J8-N8)-$C8*(COUNTIF($K8:$N8,">0")-1),$H8*UMBRAL-($I8-N8)-$C8*COUNTIF($K8:$N8,">0")))/N8) -> 99 | W8: =IF(OR($D8="No",K8=0,AND($E8="Sí",$F8>=2)),0,1/$H$35)+IF(OR($D8="No",L8=0),0,1/$H$36)+IF(OR($D8="No",M8=0),0,1/$H$37)+IF(OR($D8="No",N8=0),0,1/$H$38) -> 0 | X8: =W8*C8 -> 0 | Y8: =IF(H8=0,0,IF(AND(E8="Sí",F8>=2),MAX(J8/(G8*MIN_TURNO),(I8-J8+X8)/((F8-1)*G8*MIN_TURNO)),(I8+X8)/H8)) -> 0.71115641 | Z8: =IF(Y8<=UMBRAL,"OK","Pasa el umbral") -> OK
A9: 6 | B9: =Carga!B39 -> Marcado del cuerpo (manuales + carros) | C9: 15 | D9: Sí | E9: Sí | F9: =Carga!R39 -> 2 | G9: =Carga!S39 -> 1 | H9: =F9*G9*MIN_TURNO -> 900 | I9: =Carga!Q39 -> 451.29554 | J9: =Carga!K39*Carga!G39/60 -> 303.93096 | K9: =Carga!K39*Carga!G39/60 -> 303.93096 | L9: =Carga!L39*Carga!H39/60 -> 21.189508 | M9: =Carga!M39*Carga!I39/60 -> 95.778988 | N9: =Carga!N39*Carga!J39/60 -> 5.7943921 | O9: 0 | P9: 0 | Q9: 0 | R9: 0 | S9: 99 | T9: 99 | U9: 99 | V9: 99 | W9: =IF(AND($E9="Sí",$F9>=2),0,Lotes!$U$8)+SUM(Lotes!$U$9:$U$14) -> 1.9375 | X9: =W9*C9 -> 29.0625 | Y9: =IF(H9=0,0,(I9+X9)/H9) -> 0.53373115 | Z9: =IF(Y9<=UMBRAL,"OK","Pasa el umbral") -> OK | AA9: Marcado unificado: trabaja desde el pulmón de desarrollos, así que no limita la frecuencia de la ola (O a V fijos). Cambia cuando cambia la tanda de la guillotina: cambios por día = Lotes columna U (manuales 2,5 a 10 kg y carros; el 1 kg tiene puesto propio). Aprovechamiento como un solo puesto: carga total + cambios ÷ capacidad de todas las máquinas.
A10: 7 | B10: =Carga!B40 -> Soldadura del cuello a la cúpula | C10: 15 | D10: Sí | E10: No | F10: =Carga!R40 -> 1 | G10: =Carga!S40 -> 2 | H10: =F10*G10*MIN_TURNO -> 900 | I10: =Carga!Q40 -> 533.36731 | J10: =Carga!K40*Carga!G40/60 -> 379.9137 | K10: =Carga!K40*Carga!G40/60 -> 379.9137 | L10: =Carga!L40*Carga!H40/60 -> 26.486885 | M10: =Carga!M40*Carga!I40/60 -> 119.72374 | N10: =Carga!N40*Carga!J40/60 -> 7.2429901 | O10: =IF(OR($D10="No",K10=0,AND($E10="Sí",$F10>=2)),0,R_CORRIDA*$C10/K10) -> 0.11844795 | P10: =IF(OR($D10="No",L10=0,FALSE()),0,R_CORRIDA*$C10/L10) -> 1.6989541 | Q10: =IF(OR($D10="No",M10=0,FALSE()),0,R_CORRIDA*$C10/M10) -> 0.37586532 | R10: =IF(OR($D10="No",N10=0,FALSE()),0,R_CORRIDA*$C10/N10) -> 6.2129037 | S10: =IF(OR($D10="No",K10=0),99,MAX(0,IF(AND($E10="Sí",$F10>=2),99*K10,$H10*UMBRAL-($I10-K10)-$C10*COUNTIF($K10:$N10,">0")))/K10) -> 1.5702155 | T10: =IF(OR($D10="No",L10=0),99,MAX(0,IF(AND($E10="Sí",$F10>=2),($F10-1)*$G10*MIN_TURNO*UMBRAL-($I10-$J10-L10)-$C10*(COUNTIF($K10:$N10,">0")-1),$H10*UMBRAL-($I10-L10)-$C10*COUNTIF($K10:$N10,">0")))/L10) -> 9.1788665 | U10: =IF(OR($D10="No",M10=0),99,MAX(0,IF(AND($E10="Sí",$F10>=2),($F10-1)*$G10*MIN_TURNO*UMBRAL-($I10-$J10-M10)-$C10*(COUNTIF($K10:$N10,">0")-1),$H10*UMBRAL-($I10-M10)-$C10*COUNTIF($K10:$N10,">0")))/M10) -> 2.8094381 | V10: =IF(OR($D10="No",N10=0),99,MAX(0,IF(AND($E10="Sí",$F10>=2),($F10-1)*$G10*MIN_TURNO*UMBRAL-($I10-$J10-N10)-$C10*(COUNTIF($K10:$N10,">0")-1),$H10*UMBRAL-($I10-N10)-$C10*COUNTIF($K10:$N10,">0")))/N10) -> 30.90929 | W10: =IF(OR($D10="No",K10=0,AND($E10="Sí",$F10>=2)),0,1/$H$35)+IF(OR($D10="No",L10=0),0,1/$H$36)+IF(OR($D10="No",M10=0),0,1/$H$37)+IF(OR($D10="No",N10=0),0,1/$H$38) -> 3.5 | X10: =W10*C10 -> 52.5 | Y10: =IF(H10=0,0,IF(AND(E10="Sí",F10>=2),MAX(J10/(G10*MIN_TURNO),(I10-J10+X10)/((F10-1)*G10*MIN_TURNO)),(I10+X10)/H10)) -> 0.65096368 | Z10: =IF(Y10<=UMBRAL,"OK","Pasa el umbral") -> OK
