Workbook

Sheet Resumen
A1: MATERIA PRIMA 2035 — cómo se pide, cuánto se guarda y cómo se dispone en el almacén
A2: Paquetes y rollos atados al balanceo limpio (Balanceo2035.xlsx), stock de las 125 MP con el pico de producción y almacén dimensionado con la estantería que menos lugar ocupa.
A3: ▶ Una hoja por paso: Chapa_fleje → Stock_MP → Almacenes → Pedidos → Equipos. Datos = valores pegados.
A5: 1) LO PRINCIPAL
A6: Concepto | B6: Antes (v10) | C6: Ahora | D6: Hoja
A7: Superficie del almacén de MP (m²) | B7: =Datos!D47 -> 207.49 | C7: =Almacenes!G33 -> 221.7636 | D7: Almacenes
A8: Chapa y flejes (m²) | B8: =Almacenes!H19 -> 101.16 | C8: =Almacenes!G19+Almacenes!G20 -> 117.6236 | D8: Chapa_fleje 2 y 5
A9: Chapa: pilas | B9: — | C9: =Chapa_fleje!K24 -> 7 | D9: Chapa_fleje 2
A10: Chapa: alto máximo de una pila (m) | B10: 1.2 | C10: =MAX(Chapa_fleje!M18:M23) -> 2.4969 | D10: Chapa_fleje 2
A11: Flejes: rack + estación de volteo (m²) | B11: — | C11: =Chapa_fleje!G72 -> 25.56 | D11: Chapa_fleje 5
A12: Flejes: módulos de rack | B12: 3 cunas | C12: =Chapa_fleje!G68 -> 2 | D12: Chapa_fleje 5
A13: Apilador con pinza («volteador») | B13: — | C13: =Chapa_fleje!L52 -> Tymbia M103070075 en apilador eléctrico de 2,5 t | D13: Chapa_fleje 4
A14: Equipos de almacén, con IVA | B14: 20477058 | C14: =Equipos!G32 -> 21644111 | D14: Equipos
A15: Pedidos por año (todos los proveedores) | B15: — | C15: =Pedidos!D45 -> 596 | D15: Pedidos
A16: MP al pie de los puestos (m², sin cambios) | B16: 35.5 | C16: =Datos!D48 -> 35.5 | D16: Datos
A17: Antes = Balanceo_Sincronizado v10 y Almacenamiento_MP (almacén + fabricación propia + demarcación, con cunas; sin los equipos de la línea).
A19: 2) PAQUETE Y ROLLO DE CADA FORMATO (= una tanda del balanceo)
A20: Material | B20: Bulto (hojas o kg) | C20: Se pide cada (días) | D20: Stock máximo (bultos)
A21: =Chapa_fleje!A7&" · "&Chapa_fleje!B7 -> MP-01 · Hoja LAF 0,9 × 1220 × 2440 mm (cuerpo 1 kg) | B21: ="Paquete de "&Chapa_fleje!L7&" hojas ("&TEXT(Chapa_fleje!M7,"#,##0")&" kg)" -> Paquete de 21 hojas (442 kg) | C21: =Chapa_fleje!T7 -> 20 | D21: =Chapa_fleje!V7 -> 21
A22: =Chapa_fleje!A8&" · "&Chapa_fleje!B8 -> MP-02 · Hoja LAF 1,25 × 1220 × 2440 mm | B22: ="Paquete de "&Chapa_fleje!L8&" hojas ("&TEXT(Chapa_fleje!M8,"#,##0")&" kg)" -> Paquete de 19 hojas (555 kg) | C22: =Chapa_fleje!T8 -> 20 | D22: =Chapa_fleje!V8 -> 4
A23: =Chapa_fleje!A9&" · "&Chapa_fleje!B9 -> MP-03 · Hoja LAF 1,6 × 1000 × 2000 mm | B23: ="Paquete de "&Chapa_fleje!L9&" hojas ("&TEXT(Chapa_fleje!M9,"#,##0")&" kg)" -> Paquete de 24 hojas (603 kg) | C23: =Chapa_fleje!T9 -> 20 | D23: =Chapa_fleje!V9 -> 23
A24: =Chapa_fleje!A10&" · "&Chapa_fleje!B10 -> MP-04 · Hoja LAF 2,0 × 1500 × 3000 mm | B24: ="Paquete de "&Chapa_fleje!L10&" hojas ("&TEXT(Chapa_fleje!M10,"#,##0")&" kg)" -> Paquete de 19 hojas (1,342 kg) | C24: =Chapa_fleje!T10 -> 20 | D24: =Chapa_fleje!V10 -> 3
A25: =Chapa_fleje!A11&" · "&Chapa_fleje!B11 -> MP-11 · Hoja LAC 3,2 × 1500 × 3000 mm | B25: ="Paquete de "&Chapa_fleje!L11&" hojas ("&TEXT(Chapa_fleje!M11,"#,##0")&" kg)" -> Paquete de 7 hojas (791 kg) | C25: =Chapa_fleje!T11 -> 20 | D25: =Chapa_fleje!V11 -> 6
A26: =Chapa_fleje!A12&" · "&Chapa_fleje!B12 -> MP-12 · Hoja LAC 4,75 × 1500 × 3000 mm | B26: ="Paquete de "&Chapa_fleje!L12&" hojas ("&TEXT(Chapa_fleje!M12,"#,##0")&" kg)" -> Paquete de 3 hojas (503 kg) | C26: =Chapa_fleje!T12 -> 20 | D26: =Chapa_fleje!V12 -> 6
A27: =Chapa_fleje!A34&" · "&Chapa_fleje!B34 -> MP-05 · Fleje LAF 0,9 × 93,05 mm (cúpula 1 kg) | B27: ="Rollo de "&TEXT(Chapa_fleje!M34,"#,##0")&" kg · Ø "&TEXT(Chapa_fleje!N34,"#,##0") -> Rollo de 218 kg · Ø 798 | C27: =Chapa_fleje!T34 -> 20 | D27: =Chapa_fleje!V34 -> 6
A28: =Chapa_fleje!A35&" · "&Chapa_fleje!B35 -> MP-13 · Fleje LAF 0,9 × 100,6 mm (fondo 1 kg) | B28: ="Rollo de "&TEXT(Chapa_fleje!M35,"#,##0")&" kg · Ø "&TEXT(Chapa_fleje!N35,"#,##0") -> Rollo de 252 kg · Ø 816 | C28: =Chapa_fleje!T35 -> 20 | D28: =Chapa_fleje!V35 -> 6
A29: =Chapa_fleje!A36&" · "&Chapa_fleje!B36 -> MP-06 · Fleje LAF 1,25 × 162,1 mm (cúpula 2,5 kg) | B29: ="Rollo de "&TEXT(Chapa_fleje!M36,"#,##0")&" kg · Ø "&TEXT(Chapa_fleje!N36,"#,##0") -> Rollo de 258 kg · Ø 718 | C29: =Chapa_fleje!T36 -> 10 | D29: =Chapa_fleje!V36 -> 2
A30: =Chapa_fleje!A37&" · "&Chapa_fleje!B37 -> MP-14 · Fleje LAF 1,25 × 146,1 mm (fondo 2,5 kg) | B30: ="Rollo de "&TEXT(Chapa_fleje!M37,"#,##0")&" kg · Ø "&TEXT(Chapa_fleje!N37,"#,##0") -> Rollo de 209 kg · Ø 700 | C30: =Chapa_fleje!T37 -> 10 | D30: =Chapa_fleje!V37 -> 2
A31: =Chapa_fleje!A38&" · "&Chapa_fleje!B38 -> MP-07 · Fleje LAF 1,6 × 204,2 mm (cúpula 5 kg) | B31: ="Rollo de "&TEXT(Chapa_fleje!M38,"#,##0")&" kg · Ø "&TEXT(Chapa_fleje!N38,"#,##0") -> Rollo de 1,181 kg · Ø 1,094 | C31: =Chapa_fleje!T38 -> 10 | D31: =Chapa_fleje!V38 -> 3
A32: =Chapa_fleje!A39&" · "&Chapa_fleje!B39 -> MP-08 · Fleje LAF 1,6 × 177,2 mm (fondo 5 kg) | B32: ="Rollo de "&TEXT(Chapa_fleje!M39,"#,##0")&" kg · Ø "&TEXT(Chapa_fleje!N39,"#,##0") -> Rollo de 886 kg · Ø 1,034 | C32: =Chapa_fleje!T39 -> 10 | D32: =Chapa_fleje!V39 -> 3
A33: =Chapa_fleje!A40&" · "&Chapa_fleje!B40 -> MP-09 · Fleje LAF 2,0 × 238,7 mm (cúpula 10 kg) | B33: ="Rollo de "&TEXT(Chapa_fleje!M40,"#,##0")&" kg · Ø "&TEXT(Chapa_fleje!N40,"#,##0") -> Rollo de 245 kg · Ø 652 | C33: =Chapa_fleje!T40 -> 10 | D33: =Chapa_fleje!V40 -> 2
A34: =Chapa_fleje!A41&" · "&Chapa_fleje!B41 -> MP-10 · Fleje LAF 2,0 × 205 mm (fondo 10 kg) | B34: ="Rollo de "&TEXT(Chapa_fleje!M41,"#,##0")&" kg · Ø "&TEXT(Chapa_fleje!N41,"#,##0") -> Rollo de 179 kg · Ø 632 | C34: =Chapa_fleje!T41 -> 10 | D34: =Chapa_fleje!V41 -> 2
A36: 3) CONTROLES
A37: Control | B37: Valor | C37: Estado | D37: Debe dar
A38: Paquetes que pasan la mesa elevadora o el autoelevador | B38: =COUNTIF(Chapa_fleje!X7:X12,"<>OK") -> 0 | C38: =IF(B38=0,"OK","Revisar") -> OK | D38: 0
A39: Pilas con más carga que el piso (t/m²) | B39: =MAX(Chapa_fleje!O18:O23) -> 3.61728 | C39: =IF(B39<=Q_PISO,"OK","Revisar") -> OK | D39: ≤ Q_PISO
A40: Pilas que pasan la altura del autoelevador (m) | B40: =MAX(Chapa_fleje!M18:M23) -> 2.4969 | C40: =IF(B40*1000<=H_ELEV,"OK","Revisar") -> OK | D40: ≤ H_ELEV
A41: Presión máxima en los tacos (MPa) | B41: =MAX(Chapa_fleje!P18:P23) -> 0.24859268 | C41: =IF(B41<=SIG_MAD,"OK","Revisar") -> OK | D41: ≤ SIG_MAD
A42: Rollos que pasan el desbobinador | B42: =COUNTIF(Chapa_fleje!X34:X41,"<>OK") -> 0 | C42: =IF(B42=0,"OK","Revisar") -> OK | D42: 0
A43: Lugares de rack de flejes que faltan | B43: =MAX(0,Chapa_fleje!K65-Chapa_fleje!G69) -> 0 | C43: =IF(B43=0,"OK","Revisar") -> OK | D43: 0
...

Sheet Datos
A1: DATOS IMPORTADOS (valores pegados)
A2: Del balanceo limpio Balanceo2035.xlsx (hoja Lotes y Carga, enero 2035) y del MRP (FLAMA_MRP, POLITICA_STOCK, tal como estaba en Balanceo_Sincronizado_FLAMA_2035 v10, hoja Stock_MP). Si cambian, volver a pegar.
A3: ▶ Esta hoja no se lee: guarda los datos. Verde = dato.
A5: 1) GUILLOTINA — tandas del balanceo (Balanceo2035.xlsx, Lotes filas 8 a 14)
A6: Fila Lotes | B6: Formato | C6: Cuerpos por hoja | D6: Cuerpos por día | E6: Cada (días) | F6: Hojas por tanda
A7: 8 | B7: Manuales 1 kg | C7: 45 | D7: 911.79288 | E7: 1 | F7: 21
A8: 9 | B8: Manuales 2,5 kg | C8: 27 | D8: 63.568523 | E8: 8 | F8: 19
A9: 10 | B9: Manuales 5 kg | C9: 12 | D9: 287.33696 | E9: 1 | F9: 24
A10: 11 | B10: Manuales 10 kg | C10: 15 | D10: 17.383176 | E10: 16 | F10: 19
A11: 12 | B11: Carros 25 kg (hoja 3,2) | C11: 9 | D11: 3.3035698 | E11: 4 | F11: 2
A12: 13 | B12: Carros 50 kg (hoja 3,2) | C12: 6 | D12: 7.2608495 | E12: 4 | F12: 5
A13: 14 | B13: Carros 70 + 100 kg (hoja mixta 4,75) | C13: 4 | D13: 2.6416998 | E13: 4 | F13: 3
A15: 2) EMBUTIDORA — tandas del balanceo (Lotes filas 30 a 37)
A16: Fila Lotes | B16: Matriz | C16: Modelo | D16: Piezas por día | E16: Cada (días) | F16: Piezas por tanda | G16: Piezas del año
A17: 30 | B17: C1 | C17: 1 kg | D17: 911.79288 | E17: 4 | F17: 3647.1715 | G17: 202620.64
A18: 31 | B18: F1 | C18: 1 kg | D18: 911.79288 | E18: 4 | F18: 3647.1715 | G18: 202620.64
A19: 32 | B19: C2,5 | C19: 2,5 kg | D19: 63.568523 | E19: 16 | F19: 1017.0964 | G19: 14126.338
A20: 33 | B20: F2,5 | C20: 2,5 kg | D20: 63.568523 | E20: 16 | F20: 1017.0964 | G20: 14126.338
A21: 34 | B21: C5 | C21: 5 kg | D21: 287.33696 | E21: 8 | F21: 2298.6957 | G21: 63852.659
A22: 35 | B22: F5 | C22: 5 kg | D22: 287.33696 | E22: 8 | F22: 2298.6957 | G22: 63852.659
A23: 36 | B23: C10 | C23: 10 kg | D23: 17.383176 | E23: 16 | F23: 278.13082 | G23: 3862.928
A24: 37 | B24: F10 | C24: 10 kg | D24: 17.383176 | E24: 16 | F24: 278.13082 | G24: 3862.928
A25: Piezas del año = recipientes del año de cada modelo (Balanceo2035, Carga B14:B17).
A27: 3) PRODUCCIÓN DE CADA MES (Balanceo2035, Carga filas 8 a 10) — para el factor de pico
A28: Línea | B28: Ene | C28: Feb | D28: Mar | E28: Abr | F28: May | G28: Jun | H28: Jul | I28: Ago | J28: Sep | K28: Oct | L28: Nov | M28: Dic
A29: Manuales | B29: 25601.631 | C29: 24783.212 | D29: 23166.215 | E29: 22153.112 | F29: 20730.799 | G29: 20321.589 | H29: 21743.902 | I29: 24783.212 | J29: 24783.212 | K29: 25192.421 | L29: 25601.631 | M29: 25601.631
A30: Carros | B30: 264.12238 | C30: 233.04916 | D30: 279.65899 | E30: 279.65899 | F30: 279.65899 | G30: 248.58577 | H30: 279.65899 | I30: 279.65899 | J30: 264.12238 | K30: 233.04916 | L30: 217.51255 | M30: 248.58577
A31: Recargas | B31: 10822.075 | C31: 9391.2625 | D31: 8906.0301 | E31: 9801.73 | F31: 9879.3585 | G31: 9758.7033 | H31: 8689.6915 | I31: 8770.0961 | J31: 8876.5519 | K31: 8876.5519 | L31: 10229.736 | M31: 11781.204
A33: 4) ALMACÉN DE MP ANTES DE ESTE ANÁLISIS (Balanceo_Sincronizado v10, Stock_MP sección 1)
A34: Almacén | C34: Lugares | D34: m²
A35: Calle de chapa (carros) | C35: 2 | D35: 6.66
A36: Cantilever de caños y barras | C36: 2 | D36: 4
A37: Chapa y fleje (manuales) | C37: 21 | D37: 94.5
A38: Depósito de polvo químico | C38: 8 | D38: 8
A39: Embalaje | C39: 27 | D39: 33.21
A40: Identificación | C40: 7 | D40: 3.5
A41: Insumos de montaje (manuales) | C41: 19 | D41: 23.37
A42: Insumos de recargas | C42: 7 | D42: 8.61
A43: Insumos de soldadura y superficie | C43: 5 | D43: 6.15
A44: Jaula de gases | C44: 7 | D44: 7
...

Sheet Parametros
A1: PARÁMETROS — supuestos y criterios del almacén de MP
A2: Amarillo = criterio (se puede cambiar). Verde = dato. Blanco = fórmula. La columna E es el nombre que usan las fórmulas.
A3: ▶ Solo se tocan las celdas amarillas.
A5: 1) CONSUMO DEL DÍA PICO
A6: Parámetro | B6: Valor | C6: Unidad | D6: Fuente / criterio | E6: Nombre
A7: Días hábiles por año | B7: 240 | C7: días | D7: Balanceo: 20 días por mes × 12 | E7: DIAS_ANIO
A8: Factor de pico de manuales (mes pico ÷ mes promedio) | B8: =MAX(Datos!B29:M29)/AVERAGE(Datos!B29:M29) -> 1.08 | C8: × | D8: Producción con sobrestock (no ventas): enero | E8: FAC_MAN
A9: Factor de pico de carros | B9: =MAX(Datos!B30:M30)/AVERAGE(Datos!B30:M30) -> 1.08 | C9: × | D9: Marzo | E9: FAC_CAR
A10: Factor de pico de recargas | B10: =MAX(Datos!B31:M31)/AVERAGE(Datos!B31:M31) -> 1.2210295 | C10: × | D10: Diciembre | E10: FAC_REC
A12: 2) AUTOELEVADOR Y PISO (limitan la altura de las pilas de chapa)
A13: Parámetro | B13: Valor | C13: Unidad | D13: Fuente / criterio | E13: Nombre
A14: Altura de elevación del autoelevador | B14: 3000 | C14: mm | D14: Heli CPCD50. El autoelevador lleva mástil de 4,5 m porque lo pide el rack de PT (Word de PT); para las pilas de chapa se mantiene 3 m como tope de trabajo: con 4,5 m las pilas no cambian (casi todas entran en una) | E14: H_ELEV
A15: Capacidad nominal del autoelevador | B15: 5000 | C15: kg | D15: Heli CPCD50 (Words de manuales y carros) | E15: CAP_AUTO
A16: Centro de carga de la capacidad nominal | B16: 600 | C16: mm | D16: Heli CPCD50 (lectura-specs.com) | E16: CC_AUTO
A17: Capacidad de la mesa elevadora de la guillotina | B17: 3000 | C17: kg | D17: Word de manuales: mesa de tijera de 3 t | E17: CAP_MESA
A18: Carga admisible del piso del almacén | B18: 5 | C18: t/m² | D18: SUPUESTO: losa industrial común. Confirmar con el cálculo del piso; si es menor, las pilas bajan solas | E18: Q_PISO
A19: Alto máximo de una pila ÷ su lado menor | B19: 3 | C19: × | D19: Criterio de estabilidad de pilas sueltas: no más de 3 veces la base más angosta | E19: REL_PILA
A21: 3) PAQUETES DE CHAPA
A22: Parámetro | B22: Valor | C22: Unidad | D22: Fuente / criterio | E22: Nombre
A23: Densidad del acero | B23: 7.85 | C23: kg/dm³ | D23: Acero al carbono | E23: DENS
A24: Alto del taco de madera bajo cada paquete | B24: 100 | C24: mm | D24: Las uñas del CPCD50 (≈ 50 mm) entran sin rozar la hoja de abajo (especificación de compra) | E24: H_TACO
A25: Tacos por paquete | B25: 3 | C25: u | D25: A lo ancho del paquete, alineados en columna en la pila | E25: N_TACO
A26: Ancho de apoyo de cada taco | B26: 100 | C26: mm | D26: Taco de 100 × 100 mm | E26: A_TACO
A27: Compresión admisible de la madera (perpendicular a la fibra) | B27: 2 | C27: MPa | D27: SUPUESTO conservador para pino o eucalipto seco | E27: SIG_MAD
A28: Separación entre pilas | B28: 0.5 | C28: m | D28: Para leer la etiqueta, cortar flejes y que no se toquen las uñas | E28: SEP_PILA
A29: Ancho de la calle del autoelevador | B29: 5 | C29: m | D29: Word de carros: radio de giro 2,93 m + fondo del paquete + margen | E29: CALLE
A31: 4) FLEJES: RACK SELECTIVO + ZONA DE ARMADO CON EL APILADOR DE PINZA
A32: Parámetro | B32: Valor | C32: Unidad | D32: Fuente / criterio | E32: Nombre
A33: Diámetro interior del rollo | B33: 508 | C33: mm | D33: Estándar de 20" (Compra de chapa y fleje) | E33: DI_ROLLO
A34: Peso máximo del rollo que admite el desbobinador | B34: 1350 | C34: kg | D34: SUPUESTO (Compra de chapa y fleje): confirmar con Cena | E34: CAP_DESB
A35: Carga máxima por posición de pallet en los niveles altos | B35: 1000 | C35: kg | D35: Rack de 2.000 kg por nivel con 2 pallets de frente (módulo R1) | E35: KG_POS
A36: Alto útil de un nivel del rack de flejes | B36: 700 | C36: mm | D36: Pallet (150 mm) + pila de rollos; largueros cada 750 mm | E36: H_NIV
A37: Niveles del rack de flejes (piso + 3 largueros) | B37: 4 | C37: u | D37: Los rollos acostados son bajos: con largueros a 0,75 / 1,50 / 2,25 m el último queda a 2,25 m, dentro de los 3 m del autoelevador y del bastidor | E37: NIV_FLEJE
A38: Separador de madera entre rollos (y bajo el primero) | B38: 25 | C38: mm | D38: Listón: la paleta de la pinza baja hasta el borde de abajo del rollo sin tocar el de abajo ni el pallet | E38: SEP_ROLLO
A39: Alto máximo de la pila de rollos ÷ Ø exterior | B39: 1 | C39: × | D39: Estabilidad: la pila no más alta que su diámetro | E39: REL_ROLLO
A40: Posiciones de pallet por nivel de un módulo | B40: 2 | C40: u | D40: Módulo de 2,30 m | E40: POS_NIV
A41: Niveles por módulo (piso + 2 largueros) | B41: 3 | C41: u | D41: Rack de 3 m: el CPCD50 llega con holgura al 2.º larguero | E41: NIV
A42: Frente de un módulo | B42: 2.3 | C42: m | D42: Rack selectivo de 2,30 m | E42: MOD_FRENTE
A43: Fondo del rack | B43: 1.1 | C43: m | D43: Pallet de 1.000 de fondo + 100 mm | E43: MOD_FONDO
A44: Superficie de la zona de armado (pallet en el piso + brazos de la pinza + maniobra) | B44: 9 | C44: m² | D44: SUPUESTO: 3 × 3 m al lado del rack de flejes; ahí la pinza arma y desarma los pallets | E44: M2_VOLTEO
...

Sheet Chapa_fleje
A1: CHAPA Y FLEJE — el paquete y el rollo son una tanda del balanceo, y cómo se guardan
A2: Paquete de hojas = tanda de corte de la guillotina; rollo de fleje = tanda de la matriz. Tandas y frecuencias del balanceo limpio (Datos 1 y 2). Las pilas de chapa suben hasta lo que permiten el autoelevador, el piso y la estabilidad.
A3: ▶ Sección 1 (paquete, pedido y stock), 2 (pilas), 3 (rollos), 4 (rack de flejes) y 5 (volteador y superficie).
A5: 1) HOJAS: UN PAQUETE = UNA TANDA DE CORTE
A6: Código | B6: Material | C6: Proveedor | D6: Espesor (mm) | E6: Ancho (mm) | F6: Largo (mm) | G6: kg por hoja | H6: Hojas por día | I6: Hojas por tanda | J6: Se corta cada (días) | K6: Paquete elegido (vacío = tanda) | L6: Paquete (hojas) | M6: Peso del paquete (kg) | N6: Alto del paquete (mm) | O6: Días que dura | P6: Plazo mín. | Q6: Plazo máx. | R6: Consumo promedio (hojas/día) | S6: Seguridad (paquetes) | T6: Días entre pedidos | U6: Paquetes por pedido | V6: Stock máximo (paquetes) | W6: Stock máximo (t) | X6: Control de peso
A7: MP-01 | B7: =Datos!B52 -> Hoja LAF 0,9 × 1220 × 2440 mm (cuerpo 1 kg) | C7: =Datos!D52 -> Hierros Parrotta | D7: 0.9 | E7: 1220 | F7: 2440 | G7: =DENS*D7*E7*F7/1000000 -> 21.031092 | H7: =Datos!D7/Datos!C7 -> 20.262064 | I7: =Datos!F7 -> 21 | J7: =Datos!E7 -> 1 | L7: =IF(K7="",I7,K7) -> 21 | M7: =L7*G7 -> 441.65293 | N7: =L7*D7+H_TACO -> 118.9 | O7: =IF(H7=0,0,L7/H7) -> 1.0364196 | P7: =Datos!G52 -> 10 | Q7: =Datos!H52 -> 10 | R7: =Datos!E52/DIAS_ANIO -> 18.761171 | S7: =MAX(1,ROUNDUP(MAX(0,H7*Q7-R7*(P7+Q7)/2)/L7,0)) -> 1 | T7: =VLOOKUP(C7,Pedidos!$A$7:$C$60,3,FALSE()) -> 20 | U7: =ROUNDUP(H7*T7/L7,0) -> 20 | V7: =S7+U7 -> 21 | W7: =V7*M7/1000 -> 9.2747116 | X7: =IF(M7<=MIN(CAP_MESA,CAP_AUTO),"OK","Pasa la mesa") -> OK
A8: MP-02 | B8: =Datos!B53 -> Hoja LAF 1,25 × 1220 × 2440 mm | C8: =Datos!D53 -> Pradecon | D8: 1.25 | E8: 1220 | F8: 2440 | G8: =DENS*D8*E8*F8/1000000 -> 29.20985 | H8: =Datos!D8/Datos!C8 -> 2.3543897 | I8: =Datos!F8 -> 19 | J8: =Datos!E8 -> 8 | L8: =IF(K8="",I8,K8) -> 19 | M8: =L8*G8 -> 554.98715 | N8: =L8*D8+H_TACO -> 123.75 | O8: =IF(H8=0,0,L8/H8) -> 8.0700318 | P8: =Datos!G53 -> 7 | Q8: =Datos!H53 -> 10 | R8: =Datos!E53/DIAS_ANIO -> 2.1799917 | S8: =MAX(1,ROUNDUP(MAX(0,H8*Q8-R8*(P8+Q8)/2)/L8,0)) -> 1 | T8: =VLOOKUP(C8,Pedidos!$A$7:$C$60,3,FALSE()) -> 20 | U8: =ROUNDUP(H8*T8/L8,0) -> 3 | V8: =S8+U8 -> 4 | W8: =V8*M8/1000 -> 2.2199486 | X8: =IF(M8<=MIN(CAP_MESA,CAP_AUTO),"OK","Pasa la mesa") -> OK
A9: MP-03 | B9: =Datos!B54 -> Hoja LAF 1,6 × 1000 × 2000 mm | C9: =Datos!D54 -> Pradecon | D9: 1.6 | E9: 1000 | F9: 2000 | G9: =DENS*D9*E9*F9/1000000 -> 25.12 | H9: =Datos!D9/Datos!C9 -> 23.944747 | I9: =Datos!F9 -> 24 | J9: =Datos!E9 -> 1 | L9: =IF(K9="",I9,K9) -> 24 | M9: =L9*G9 -> 602.88 | N9: =L9*D9+H_TACO -> 138.4 | O9: =IF(H9=0,0,L9/H9) -> 1.0023075 | P9: =Datos!G54 -> 7 | Q9: =Datos!H54 -> 10 | R9: =Datos!E54/DIAS_ANIO -> 22.171063 | S9: =MAX(1,ROUNDUP(MAX(0,H9*Q9-R9*(P9+Q9)/2)/L9,0)) -> 3 | T9: =VLOOKUP(C9,Pedidos!$A$7:$C$60,3,FALSE()) -> 20 | U9: =ROUNDUP(H9*T9/L9,0) -> 20 | V9: =S9+U9 -> 23 | W9: =V9*M9/1000 -> 13.86624 | X9: =IF(M9<=MIN(CAP_MESA,CAP_AUTO),"OK","Pasa la mesa") -> OK
A10: MP-04 | B10: =Datos!B55 -> Hoja LAF 2,0 × 1500 × 3000 mm | C10: =Datos!D55 -> Pradecon | D10: 2 | E10: 1500 | F10: 3000 | G10: =DENS*D10*E10*F10/1000000 -> 70.65 | H10: =Datos!D10/Datos!C10 -> 1.1588784 | I10: =Datos!F10 -> 19 | J10: =Datos!E10 -> 16 | L10: =IF(K10="",I10,K10) -> 19 | M10: =L10*G10 -> 1342.35 | N10: =L10*D10+H_TACO -> 138 | O10: =IF(H10=0,0,L10/H10) -> 16.395162 | P10: =Datos!G55 -> 7 | Q10: =Datos!H55 -> 10 | R10: =Datos!E55/DIAS_ANIO -> 1.0730375 | S10: =MAX(1,ROUNDUP(MAX(0,H10*Q10-R10*(P10+Q10)/2)/L10,0)) -> 1 | T10: =VLOOKUP(C10,Pedidos!$A$7:$C$60,3,FALSE()) -> 20 | U10: =ROUNDUP(H10*T10/L10,0) -> 2 | V10: =S10+U10 -> 3 | W10: =V10*M10/1000 -> 4.02705 | X10: =IF(M10<=MIN(CAP_MESA,CAP_AUTO),"OK","Pasa la mesa") -> OK
A11: MP-11 | B11: =Datos!B64 -> Hoja LAC 3,2 × 1500 × 3000 mm | C11: =Datos!D64 -> Pradecon | D11: 3.2 | E11: 1500 | F11: 3000 | G11: =DENS*D11*E11*F11/1000000 -> 113.04 | H11: =Datos!D11/Datos!C11+Datos!D12/Datos!C12 -> 1.5772049 | I11: =Datos!F11+Datos!F12 -> 7 | J11: =Datos!E11 -> 4 | L11: =IF(K11="",I11,K11) -> 7 | M11: =L11*G11 -> 791.28 | N11: =L11*D11+H_TACO -> 122.4 | O11: =IF(H11=0,0,L11/H11) -> 4.4382312 | P11: =Datos!G64 -> 7 | Q11: =Datos!H64 -> 10 | R11: =Datos!E64/DIAS_ANIO -> 1.4563125 | S11: =MAX(1,ROUNDUP(MAX(0,H11*Q11-R11*(P11+Q11)/2)/L11,0)) -> 1 | T11: =VLOOKUP(C11,Pedidos!$A$7:$C$60,3,FALSE()) -> 20 | U11: =ROUNDUP(H11*T11/L11,0) -> 5 | V11: =S11+U11 -> 6 | W11: =V11*M11/1000 -> 4.74768 | X11: =IF(M11<=MIN(CAP_MESA,CAP_AUTO),"OK","Pasa la mesa") -> OK
A12: MP-12 | B12: =Datos!B65 -> Hoja LAC 4,75 × 1500 × 3000 mm | C12: =Datos!D65 -> Pradecon | D12: 4.75 | E12: 1500 | F12: 3000 | G12: =DENS*D12*E12*F12/1000000 -> 167.79375 | H12: =Datos!D13/Datos!C13 -> 0.66042495 | I12: =Datos!F13 -> 3 | J12: =Datos!E13 -> 4 | L12: =IF(K12="",I12,K12) -> 3 | M12: =L12*G12 -> 503.38125 | N12: =L12*D12+H_TACO -> 114.25 | O12: =IF(H12=0,0,L12/H12) -> 4.5425298 | P12: =Datos!G65 -> 7 | Q12: =Datos!H65 -> 10 | R12: =Datos!E65/DIAS_ANIO -> 0.69009167 | S12: =MAX(1,ROUNDUP(MAX(0,H12*Q12-R12*(P12+Q12)/2)/L12,0)) -> 1 | T12: =VLOOKUP(C12,Pedidos!$A$7:$C$60,3,FALSE()) -> 20 | U12: =ROUNDUP(H12*T12/L12,0) -> 5 | V12: =S12+U12 -> 6 | W12: =V12*M12/1000 -> 3.0202875 | X12: =IF(M12<=MIN(CAP_MESA,CAP_AUTO),"OK","Pasa la mesa") -> OK
B13: Total | V13: =SUM(V7:V12) -> 63 | W13: =SUM(W7:W12) -> 37.155918
A14: Hojas por día = cuerpos por día ÷ cuerpos por hoja (MP-11: 25 y 50 kg comparten la hoja de 3,2). Seguridad = (hojas por día × plazo máx. − promedio × plazo medio) ÷ paquete, mínimo 1. Pedido = lo que falta hasta el máximo; en promedio, hojas por día × días entre pedidos.
A16: 2) PILAS DE CHAPA EN EL PISO: lo más alto que permiten el autoelevador, el piso y la estabilidad
A17: Código | B17: Formato (mm) | C17: Paquetes en el stock máx. | D17: Alto del paquete (mm) | E17: Peso del paquete (kg) | F17: Base (m²) | G17: Máx. por altura del autoelevador | H17: Máx. por estabilidad | I17: Máx. por carga del piso | J17: Máx. por pila | K17: Pilas | L17: Paquetes por pila | M17: Alto de la pila (m) | N17: Peso de la pila (t) | O17: Carga en el piso (t/m²) | P17: Presión en los tacos (MPa) | Q17: Control tacos | R17: Centro de carga (mm) | S17: Capacidad del autoelevador a ese centro (kg) | T17: Control autoelevador | U17: Frente con separación (m) | V17: Fondo con separación (m) | W17: m² de las pilas | X17: Qué limita
A18: =A7 -> MP-01 | B18: =TEXT(F7,"#,##0")&" × "&TEXT(E7,"#,##0") -> 2,440 × 1,220 | C18: =V7 -> 21 | D18: =N7 -> 118.9 | E18: =M7 -> 441.65293 | F18: =E7*F7/1000000 -> 2.9768 | G18: =INT(H_ELEV/D18) -> 25 | H18: =INT(REL_PILA*MIN(E7,F7)/D18) -> 30 | I18: =INT(Q_PISO*F18*1000/E18) -> 33 | J18: =MAX(1,MIN(G18,H18,I18)) -> 25 | K18: =MAX(1,ROUNDUP(C18/J18,0)) -> 1 | L18: =ROUNDUP(C18/K18,0) -> 21 | M18: =L18*D18/1000 -> 2.4969 | N18: =L18*E18/1000 -> 9.2747116 | O18: =N18/F18 -> 3.115665 | P18: =L18*E18*9.81/(N_TACO*A_TACO/1000*E7/1000)/1000000 -> 0.24859268 | Q18: =IF(P18<=SIG_MAD,"OK","Revisar") -> OK | R18: =E7/2 -> 610 | S18: =CAP_AUTO*CC_AUTO/MAX(CC_AUTO,R18) -> 4918.0328 | T18: =IF(E18<=S18,"OK","No levanta") -> OK | U18: =F7/1000+SEP_PILA -> 2.94 | V18: =E7/1000+SEP_PILA -> 1.72 | W18: =K18*U18*(V18+CALLE/2) -> 12.4068 | X18: =IF(C18<=J18,"Entra en 1 pila",IF(J18=G18,"Altura del autoelevador",IF(J18=I18,"Carga del piso","Estabilidad"))) -> Entra en 1 pila
A19: =A8 -> MP-02 | B19: =TEXT(F8,"#,##0")&" × "&TEXT(E8,"#,##0") -> 2,440 × 1,220 | C19: =V8 -> 4 | D19: =N8 -> 123.75 | E19: =M8 -> 554.98715 | F19: =E8*F8/1000000 -> 2.9768 | G19: =INT(H_ELEV/D19) -> 24 | H19: =INT(REL_PILA*MIN(E8,F8)/D19) -> 29 | I19: =INT(Q_PISO*F19*1000/E19) -> 26 | J19: =MAX(1,MIN(G19,H19,I19)) -> 24 | K19: =MAX(1,ROUNDUP(C19/J19,0)) -> 1 | L19: =ROUNDUP(C19/K19,0) -> 4 | M19: =L19*D19/1000 -> 0.495 | N19: =L19*E19/1000 -> 2.2199486 | O19: =N19/F19 -> 0.74575 | P19: =L19*E19*9.81/(N_TACO*A_TACO/1000*E8/1000)/1000000 -> 0.059501901 | Q19: =IF(P19<=SIG_MAD,"OK","Revisar") -> OK | R19: =E8/2 -> 610 | S19: =CAP_AUTO*CC_AUTO/MAX(CC_AUTO,R19) -> 4918.0328 | T19: =IF(E19<=S19,"OK","No levanta") -> OK | U19: =F8/1000+SEP_PILA -> 2.94 | V19: =E8/1000+SEP_PILA -> 1.72 | W19: =K19*U19*(V19+CALLE/2) -> 12.4068 | X19: =IF(C19<=J19,"Entra en 1 pila",IF(J19=G19,"Altura del autoelevador",IF(J19=I19,"Carga del piso","Estabilidad"))) -> Entra en 1 pila
A20: =A9 -> MP-03 | B20: =TEXT(F9,"#,##0")&" × "&TEXT(E9,"#,##0") -> 2,000 × 1,000 | C20: =V9 -> 23 | D20: =N9 -> 138.4 | E20: =M9 -> 602.88 | F20: =E9*F9/1000000 -> 2 | G20: =INT(H_ELEV/D20) -> 21 | H20: =INT(REL_PILA*MIN(E9,F9)/D20) -> 21 | I20: =INT(Q_PISO*F20*1000/E20) -> 16 | J20: =MAX(1,MIN(G20,H20,I20)) -> 16 | K20: =MAX(1,ROUNDUP(C20/J20,0)) -> 2 | L20: =ROUNDUP(C20/K20,0) -> 12 | M20: =L20*D20/1000 -> 1.6608 | N20: =L20*E20/1000 -> 7.23456 | O20: =N20/F20 -> 3.61728 | P20: =L20*E20*9.81/(N_TACO*A_TACO/1000*E9/1000)/1000000 -> 0.23657011 | Q20: =IF(P20<=SIG_MAD,"OK","Revisar") -> OK | R20: =E9/2 -> 500 | S20: =CAP_AUTO*CC_AUTO/MAX(CC_AUTO,R20) -> 5000 | T20: =IF(E20<=S20,"OK","No levanta") -> OK | U20: =F9/1000+SEP_PILA -> 2.5 | V20: =E9/1000+SEP_PILA -> 1.5 | W20: =K20*U20*(V20+CALLE/2) -> 20 | X20: =IF(C20<=J20,"Entra en 1 pila",IF(J20=G20,"Altura del autoelevador",IF(J20=I20,"Carga del piso","Estabilidad"))) -> Carga del piso
A21: =A10 -> MP-04 | B21: =TEXT(F10,"#,##0")&" × "&TEXT(E10,"#,##0") -> 3,000 × 1,500 | C21: =V10 -> 3 | D21: =N10 -> 138 | E21: =M10 -> 1342.35 | F21: =E10*F10/1000000 -> 4.5 | G21: =INT(H_ELEV/D21) -> 21 | H21: =INT(REL_PILA*MIN(E10,F10)/D21) -> 32 | I21: =INT(Q_PISO*F21*1000/E21) -> 16 | J21: =MAX(1,MIN(G21,H21,I21)) -> 16 | K21: =MAX(1,ROUNDUP(C21/J21,0)) -> 1 | L21: =ROUNDUP(C21/K21,0) -> 3 | M21: =L21*D21/1000 -> 0.414 | N21: =L21*E21/1000 -> 4.02705 | O21: =N21/F21 -> 0.8949 | P21: =L21*E21*9.81/(N_TACO*A_TACO/1000*E10/1000)/1000000 -> 0.08778969 | Q21: =IF(P21<=SIG_MAD,"OK","Revisar") -> OK | R21: =E10/2 -> 750 | S21: =CAP_AUTO*CC_AUTO/MAX(CC_AUTO,R21) -> 4000 | T21: =IF(E21<=S21,"OK","No levanta") -> OK | U21: =F10/1000+SEP_PILA -> 3.5 | V21: =E10/1000+SEP_PILA -> 2 | W21: =K21*U21*(V21+CALLE/2) -> 15.75 | X21: =IF(C21<=J21,"Entra en 1 pila",IF(J21=G21,"Altura del autoelevador",IF(J21=I21,"Carga del piso","Estabilidad"))) -> Entra en 1 pila
A22: =A11 -> MP-11 | B22: =TEXT(F11,"#,##0")&" × "&TEXT(E11,"#,##0") -> 3,000 × 1,500 | C22: =V11 -> 6 | D22: =N11 -> 122.4 | E22: =M11 -> 791.28 | F22: =E11*F11/1000000 -> 4.5 | G22: =INT(H_ELEV/D22) -> 24 | H22: =INT(REL_PILA*MIN(E11,F11)/D22) -> 36 | I22: =INT(Q_PISO*F22*1000/E22) -> 28 | J22: =MAX(1,MIN(G22,H22,I22)) -> 24 | K22: =MAX(1,ROUNDUP(C22/J22,0)) -> 1 | L22: =ROUNDUP(C22/K22,0) -> 6 | M22: =L22*D22/1000 -> 0.7344 | N22: =L22*E22/1000 -> 4.74768 | O22: =N22/F22 -> 1.05504 | P22: =L22*E22*9.81/(N_TACO*A_TACO/1000*E11/1000)/1000000 -> 0.10349942 | Q22: =IF(P22<=SIG_MAD,"OK","Revisar") -> OK | R22: =E11/2 -> 750 | S22: =CAP_AUTO*CC_AUTO/MAX(CC_AUTO,R22) -> 4000 | T22: =IF(E22<=S22,"OK","No levanta") -> OK | U22: =F11/1000+SEP_PILA -> 3.5 | V22: =E11/1000+SEP_PILA -> 2 | W22: =K22*U22*(V22+CALLE/2) -> 15.75 | X22: =IF(C22<=J22,"Entra en 1 pila",IF(J22=G22,"Altura del autoelevador",IF(J22=I22,"Carga del piso","Estabilidad"))) -> Entra en 1 pila
A23: =A12 -> MP-12 | B23: =TEXT(F12,"#,##0")&" × "&TEXT(E12,"#,##0") -> 3,000 × 1,500 | C23: =V12 -> 6 | D23: =N12 -> 114.25 | E23: =M12 -> 503.38125 | F23: =E12*F12/1000000 -> 4.5 | G23: =INT(H_ELEV/D23) -> 26 | H23: =INT(REL_PILA*MIN(E12,F12)/D23) -> 39 | I23: =INT(Q_PISO*F23*1000/E23) -> 44 | J23: =MAX(1,MIN(G23,H23,I23)) -> 26 | K23: =MAX(1,ROUNDUP(C23/J23,0)) -> 1 | L23: =ROUNDUP(C23/K23,0) -> 6 | M23: =L23*D23/1000 -> 0.6855 | N23: =L23*E23/1000 -> 3.0202875 | O23: =N23/F23 -> 0.671175 | P23: =L23*E23*9.81/(N_TACO*A_TACO/1000*E12/1000)/1000000 -> 0.065842267 | Q23: =IF(P23<=SIG_MAD,"OK","Revisar") -> OK | R23: =E12/2 -> 750 | S23: =CAP_AUTO*CC_AUTO/MAX(CC_AUTO,R23) -> 4000 | T23: =IF(E23<=S23,"OK","No levanta") -> OK | U23: =F12/1000+SEP_PILA -> 3.5 | V23: =E12/1000+SEP_PILA -> 2 | W23: =K23*U23*(V23+CALLE/2) -> 15.75 | X23: =IF(C23<=J23,"Entra en 1 pila",IF(J23=G23,"Altura del autoelevador",IF(J23=I23,"Carga del piso","Estabilidad"))) -> Entra en 1 pila
A24: Total | K24: =SUM(K18:K23) -> 7 | W24: =SUM(W18:W23) -> 92.0636
B26: Frente total de las pilas (m) | E26: =SUMPRODUCT(K18:K23,U18:U23) -> 21.38
B27: Solo el piso de las pilas, sin calle (m²) | E27: =SUMPRODUCT(K18:K23,U18:U23,V18:V23) -> 38.6136
B28: Calle compartida: la mitad que le toca a la chapa (m²) | E28: =E26*CALLE/2 -> 53.45
B29: Superficie de la chapa (pilas + media calle, mismo criterio que los racks) (m²) | E29: =E27+E28 -> 92.0636
A30: Una pila por formato si entra; si no, varias. Siempre se toma el paquete de arriba. Al recibir, el remanente se pasa arriba de la entrega nueva (FIFO por colada). Los tacos van alineados en columna: el peso baja por los tacos y la hoja no se dobla.
A32: 3) FLEJES: UN ROLLO = UNA TANDA DE LA MATRIZ
A33: Código | B33: Material | C33: Proveedor | D33: Espesor (mm) | E33: Ancho (mm) | F33: Matriz (fila Datos) | G33: kg de fleje por pieza | H33: Piezas por día | I33: kg por día | J33: Tanda (piezas) | K33: Se prensa cada (días) | L33: Tandas por rollo | M33: Peso del rollo (kg) | N33: Ø exterior (mm) | O33: Días que dura | P33: Plazo mín. | Q33: Plazo máx. | R33: Consumo promedio (kg/día) | S33: Seguridad (rollos) | T33: Días entre pedidos | U33: Rollos por pedido | V33: Stock máximo (rollos) | W33: Stock máximo (t) | X33: Control desbobinador
A34: MP-05 | B34: =Datos!B56 -> Fleje LAF 0,9 × 93,05 mm (cúpula 1 kg) | C34: =Datos!D56 -> Pradecon | D34: 0.9 | E34: 93.05 | F34: =Datos!B17 -> C1 | G34: =Datos!E56/Datos!G17 -> 0.059694403 | H34: =Datos!D17 -> 911.79288 | I34: =H34*G34 -> 54.428931 | J34: =Datos!F17 -> 3647.1715 | K34: =Datos!E17 -> 4 | L34: 1 | M34: =J34*G34*L34 -> 217.71572 | N34: =SQRT(DI_ROLLO^2+4*M34/(PI()*E34*DENS/1000000)) -> 798.4772 | O34: =M34/I34 -> 4 | P34: =Datos!G56 -> 7 | Q34: =Datos!H56 -> 10 | R34: =Datos!E56/DIAS_ANIO -> 50.397158 | S34: =MAX(1,ROUNDUP(MAX(0,I34*Q34-R34*(P34+Q34)/2)/M34,0)) -> 1 | T34: =VLOOKUP(C34,Pedidos!$A$7:$C$60,3,FALSE()) -> 20 | U34: =ROUNDUP(I34*T34/M34,0) -> 5 | V34: =S34+U34 -> 6 | W34: =V34*M34/1000 -> 1.3062943 | X34: =IF(M34<=CAP_DESB,"OK","Pasa el desbobinador") -> OK
A35: MP-13 | B35: =Datos!B57 -> Fleje LAF 0,9 × 100,6 mm (fondo 1 kg) | C35: =Datos!D57 -> Pradecon | D35: 0.9 | E35: 100.6 | F35: =Datos!B18 -> F1 | G35: =Datos!E57/Datos!G18 -> 0.069216049 | H35: =Datos!D18 -> 911.79288 | I35: =H35*G35 -> 63.1107 | J35: =Datos!F18 -> 3647.1715 | K35: =Datos!E18 -> 4 | L35: 1 | M35: =J35*G35*L35 -> 252.4428 | N35: =SQRT(DI_ROLLO^2+4*M35/(PI()*E35*DENS/1000000)) -> 815.52092 | O35: =M35/I35 -> 4 | P35: =Datos!G57 -> 7 | Q35: =Datos!H57 -> 10 | R35: =Datos!E57/DIAS_ANIO -> 58.435833 | S35: =MAX(1,ROUNDUP(MAX(0,I35*Q35-R35*(P35+Q35)/2)/M35,0)) -> 1 | T35: =VLOOKUP(C35,Pedidos!$A$7:$C$60,3,FALSE()) -> 20 | U35: =ROUNDUP(I35*T35/M35,0) -> 5 | V35: =S35+U35 -> 6 | W35: =V35*M35/1000 -> 1.5146568 | X35: =IF(M35<=CAP_DESB,"OK","Pasa el desbobinador") -> OK
A36: MP-06 | B36: =Datos!B58 -> Fleje LAF 1,25 × 162,1 mm (cúpula 2,5 kg) | C36: =Datos!D58 -> Pacheco Chapas | D36: 1.25 | E36: 162.1 | F36: =Datos!B19 -> C2,5 | G36: =Datos!E58/Datos!G19 -> 0.25321722 | H36: =Datos!D19 -> 63.568523 | I36: =H36*G36 -> 16.096645 | J36: =Datos!F19 -> 1017.0964 | K36: =Datos!E19 -> 16 | L36: 1 | M36: =J36*G36*L36 -> 257.54631 | N36: =SQRT(DI_ROLLO^2+4*M36/(PI()*E36*DENS/1000000)) -> 718.16644 | O36: =M36/I36 -> 16 | P36: =Datos!G58 -> 7 | Q36: =Datos!H58 -> 10 | R36: =Datos!E58/DIAS_ANIO -> 14.9043 | S36: =MAX(1,ROUNDUP(MAX(0,I36*Q36-R36*(P36+Q36)/2)/M36,0)) -> 1 | T36: =VLOOKUP(C36,Pedidos!$A$7:$C$60,3,FALSE()) -> 10 | U36: =ROUNDUP(I36*T36/M36,0) -> 1 | V36: =S36+U36 -> 2 | W36: =V36*M36/1000 -> 0.51509262 | X36: =IF(M36<=CAP_DESB,"OK","Pasa el desbobinador") -> OK
A37: MP-14 | B37: =Datos!B59 -> Fleje LAF 1,25 × 146,1 mm (fondo 2,5 kg) | C37: =Datos!D59 -> Pacheco Chapas | D37: 1.25 | E37: 146.1 | F37: =Datos!B20 -> F2,5 | G37: =Datos!E59/Datos!G20 -> 0.20517044 | H37: =Datos!D20 -> 63.568523 | I37: =H37*G37 -> 13.042382 | J37: =Datos!F20 -> 1017.0964 | K37: =Datos!E20 -> 16 | L37: 1 | M37: =J37*G37*L37 -> 208.67811 | N37: =SQRT(DI_ROLLO^2+4*M37/(PI()*E37*DENS/1000000)) -> 699.80896 | O37: =M37/I37 -> 16 | P37: =Datos!G59 -> 7 | Q37: =Datos!H59 -> 10 | R37: =Datos!E59/DIAS_ANIO -> 12.076279 | S37: =MAX(1,ROUNDUP(MAX(0,I37*Q37-R37*(P37+Q37)/2)/M37,0)) -> 1 | T37: =VLOOKUP(C37,Pedidos!$A$7:$C$60,3,FALSE()) -> 10 | U37: =ROUNDUP(I37*T37/M37,0) -> 1 | V37: =S37+U37 -> 2 | W37: =V37*M37/1000 -> 0.41735622 | X37: =IF(M37<=CAP_DESB,"OK","Pasa el desbobinador") -> OK
A38: MP-07 | B38: =Datos!B60 -> Fleje LAF 1,6 × 204,2 mm (cúpula 5 kg) | C38: =Datos!D60 -> Pacheco Chapas | D38: 1.6 | E38: 204.2 | F38: =Datos!B21 -> C5 | G38: =Datos!E60/Datos!G21 -> 0.51398145 | H38: =Datos!D21 -> 287.33696 | I38: =H38*G38 -> 147.68587 | J38: =Datos!F21 -> 2298.6957 | K38: =Datos!E21 -> 8 | L38: 1 | M38: =J38*G38*L38 -> 1181.4869 | N38: =SQRT(DI_ROLLO^2+4*M38/(PI()*E38*DENS/1000000)) -> 1093.8553 | O38: =M38/I38 -> 8 | P38: =Datos!G60 -> 7 | Q38: =Datos!H60 -> 10 | R38: =Datos!E60/DIAS_ANIO -> 136.74617 | S38: =MAX(1,ROUNDUP(MAX(0,I38*Q38-R38*(P38+Q38)/2)/M38,0)) -> 1 | T38: =VLOOKUP(C38,Pedidos!$A$7:$C$60,3,FALSE()) -> 10 | U38: =ROUNDUP(I38*T38/M38,0) -> 2 | V38: =S38+U38 -> 3 | W38: =V38*M38/1000 -> 3.5444608 | X38: =IF(M38<=CAP_DESB,"OK","Pasa el desbobinador") -> OK
A39: MP-08 | B39: =Datos!B61 -> Fleje LAF 1,6 × 177,2 mm (fondo 5 kg) | C39: =Datos!D61 -> Pacheco Chapas | D39: 1.6 | E39: 177.2 | F39: =Datos!B22 -> F5 | G39: =Datos!E61/Datos!G22 -> 0.38562709 | H39: =Datos!D22 -> 287.33696 | I39: =H39*G39 -> 110.80492 | J39: =Datos!F22 -> 2298.6957 | K39: =Datos!E22 -> 8 | L39: 1 | M39: =J39*G39*L39 -> 886.43934 | N39: =SQRT(DI_ROLLO^2+4*M39/(PI()*E39*DENS/1000000)) -> 1034.1406 | O39: =M39/I39 -> 8 | P39: =Datos!G61 -> 7 | Q39: =Datos!H61 -> 10 | R39: =Datos!E61/DIAS_ANIO -> 102.59715 | S39: =MAX(1,ROUNDUP(MAX(0,I39*Q39-R39*(P39+Q39)/2)/M39,0)) -> 1 | T39: =VLOOKUP(C39,Pedidos!$A$7:$C$60,3,FALSE()) -> 10 | U39: =ROUNDUP(I39*T39/M39,0) -> 2 | V39: =S39+U39 -> 3 | W39: =V39*M39/1000 -> 2.659318 | X39: =IF(M39<=CAP_DESB,"OK","Pasa el desbobinador") -> OK
A40: MP-09 | B40: =Datos!B62 -> Fleje LAF 2,0 × 238,7 mm (cúpula 10 kg) | C40: =Datos!D62 -> Pacheco Chapas | D40: 2 | E40: 238.7 | F40: =Datos!B23 -> C10 | G40: =Datos!E62/Datos!G23 -> 0.88096646 | H40: =Datos!D23 -> 17.383176 | I40: =H40*G40 -> 15.313995 | J40: =Datos!F23 -> 278.13082 | K40: =Datos!E23 -> 16 | L40: 1 | M40: =J40*G40*L40 -> 245.02392 | N40: =SQRT(DI_ROLLO^2+4*M40/(PI()*E40*DENS/1000000)) -> 651.58055 | O40: =M40/I40 -> 16 | P40: =Datos!G62 -> 7 | Q40: =Datos!H62 -> 10 | R40: =Datos!E62/DIAS_ANIO -> 14.179625 | S40: =MAX(1,ROUNDUP(MAX(0,I40*Q40-R40*(P40+Q40)/2)/M40,0)) -> 1 | T40: =VLOOKUP(C40,Pedidos!$A$7:$C$60,3,FALSE()) -> 10 | U40: =ROUNDUP(I40*T40/M40,0) -> 1 | V40: =S40+U40 -> 2 | W40: =V40*M40/1000 -> 0.49004785 | X40: =IF(M40<=CAP_DESB,"OK","Pasa el desbobinador") -> OK
A41: MP-10 | B41: =Datos!B63 -> Fleje LAF 2,0 × 205 mm (fondo 10 kg) | C41: =Datos!D63 -> Pacheco Chapas | D41: 2 | E41: 205 | F41: =Datos!B24 -> F10 | G41: =Datos!E63/Datos!G24 -> 0.64370006 | H41: =Datos!D24 -> 17.383176 | I41: =H41*G41 -> 11.189552 | J41: =Datos!F24 -> 278.13082 | K41: =Datos!E24 -> 16 | L41: 1 | M41: =J41*G41*L41 -> 179.03283 | N41: =SQRT(DI_ROLLO^2+4*M41/(PI()*E41*DENS/1000000)) -> 632.23008 | O41: =M41/I41 -> 16 | P41: =Datos!G63 -> 7 | Q41: =Datos!H63 -> 10 | R41: =Datos!E63/DIAS_ANIO -> 10.360696 | S41: =MAX(1,ROUNDUP(MAX(0,I41*Q41-R41*(P41+Q41)/2)/M41,0)) -> 1 | T41: =VLOOKUP(C41,Pedidos!$A$7:$C$60,3,FALSE()) -> 10 | U41: =ROUNDUP(I41*T41/M41,0) -> 1 | V41: =S41+U41 -> 2 | W41: =V41*M41/1000 -> 0.35806566 | X41: =IF(M41<=CAP_DESB,"OK","Pasa el desbobinador") -> OK
B42: Total | V42: =SUM(V34:V41) -> 26 | W42: =SUM(W34:W41) -> 10.805292
A43: kg por pieza = consumo del año del MRP ÷ piezas del año (incluye el esqueleto entre discos). Ø exterior = √(Øint² + 4 × peso ÷ (π × ancho × densidad)).
A45: 4) APILADOR CON PINZA GIRATORIA («volteador»): el rollo más pesado y el más grande fijan el equipo
...

Sheet Casquetes
A1: CASQUETES DE CARROS — cómo vienen las cúpulas y los fondos (como Fadesa)
A2: Compra nacional en contenedores, ≈ 40 días de demora, se pide según la demanda. Acá se dimensiona el contenedor: cuántas cúpulas y fondos entran, cuánto pesa y cada cuánto se pide.
A3: ▶ Columna N: casquetes por contenedor. Columna S: peso. Columna V: contenedores por pedido.
A5: 1) CÓMO LO HACE FADESA (consulta a Pablo Delmas)
A6: Casquetes de 10", 12" y 15" × 3,20 mm y 15" × 4,75 mm: las pulgadas son el diámetro. Son los mismos tres de FLAMA (MP-15, MP-16 y MP-17).
A7: Vienen en contenedores e ingresan según la necesidad, atada a la demanda (los pedidos). Demora: unos 40 días. Proveedor: NOVA Ruedas. Contenedor retornable.
A8: Antes (MRP y Word de carros): importados de China, pallet de 400 / 300 / 150 u, contenedor de 20' cada 50 días hábiles y 54 a 68 días hábiles de plazo. Se corrige.
A10: 2) SUPUESTOS DEL CONTENEDOR Y DEL PEDIDO
A11: Parámetro | B11: Valor | C11: Unidad | D11: Nombre | E11: Fuente / criterio
A12: Demora del proveedor | B12: 40 | C12: días corridos | D12: CQ_PLAZO | E12: Fadesa: «40 días aproximadamente la demora»
A13: Variación de la demora (±) | B13: 5 | C13: días corridos | D13: CQ_VAR | E13: Supuesto
A14: Plazo mínimo | B14: =ROUND((CQ_PLAZO-CQ_VAR)*5/7,0) -> 25 | C14: días hábiles | D14: CQ_PMIN | E14: 5 días hábiles por cada 7 corridos
A15: Plazo máximo | B15: =ROUND((CQ_PLAZO+CQ_VAR)*5/7,0) -> 32 | C15: días hábiles | D15: CQ_PMAX | E15: Ídem
A16: Días entre pedidos | B16: 20 | C16: días hábiles | D16: CQ_CADA | E16: Un pedido por mes con las tres medidas; se pide solo lo que falta (como Fadesa, según demanda)
A17: Contenedor: largo interior | B17: 1160 | C17: mm | D17: CQ_LARGO | E17: Contenedor metálico de 1.200 × 1.000 (la base del pallet de flejes), paredes de 20 mm
A18: Contenedor: ancho interior | B18: 960 | C18: mm | D18: CQ_ANCHO | E18: Ídem
A19: Alto útil de carga | B19: 800 | C19: mm | D19: CQ_ALTO | E19: Con el contenedor en el piso, la pieza de arriba queda a ≈ 0,95 m: se saca a mano sin agacharse ni subir
A20: Base del contenedor (patas, entrada de uñas) | B20: 150 | C20: mm | D20: CQ_BASE | E20: Supuesto
A21: Peso bruto máximo | B21: 1000 | C21: kg | D21: CQ_KG | E21: Rack de 2.000 kg por nivel con 2 contenedores; mismo límite que el pallet de flejes
A22: Tara del contenedor | B22: 120 | C22: kg | D22: CQ_TARA | E22: Contenedor metálico apilable, supuesto
A23: Alto del borde recto del casquete (pollera) | B23: 20 | C23: mm | D23: CQ_POLL | E23: Supuesto: el tramo cilíndrico del borde, antes de que empiece la curva; es lo que encastra en el cuerpo. Medir en una muestra
A25: 3) CUÁNTO ENTRA EN UN CONTENEDOR — columnas anidadas, mitad cúpulas y mitad fondos
A26: Código | B26: Casquete | C26: Ø (mm) | D26: Profundidad (mm) | E26: Espesor (mm) | F26: Peso (kg) | G26: Paso de anidado (mm) | H26: Columnas a lo largo | I26: Columnas a lo ancho | J26: Columnas | K26: Piezas por columna | L26: Por alto | M26: Por peso | N26: Por contenedor | O26: Cúpulas | P26: Fondos | Q26: Manda | R26: Alto de la carga (mm) | S26: Peso bruto (kg) | T26: Consumo pico (u/día) | U26: Días que dura (pico) | V26: Contenedores por pedido | W26: Stock máx. (contenedores)
A27: MP-15 | B27: Casquete 10" × 3,2 (carro 25 kg) | C27: 276.5 | D27: 87 | E27: 3.2 | F27: 2.44 | G27: =CQ_POLL+E27 -> 23.2 | H27: =INT(CQ_LARGO/C27) -> 4 | I27: =INT(CQ_ANCHO/C27) -> 3 | J27: =H27*I27 -> 12 | K27: =1+INT((CQ_ALTO-D27)/G27) -> 31 | L27: =J27*K27 -> 372 | M27: =INT((CQ_KG-CQ_TARA)/F27) -> 360 | N27: =2*INT(MIN(L27,M27)/2) -> 360 | O27: =N27/2 -> 180 | P27: =N27/2 -> 180 | Q27: =IF(L27<=M27,"El alto","El peso") -> El peso | R27: =D27+(ROUNDUP(N27/J27,0)-1)*G27 -> 759.8 | S27: =N27*F27+CQ_TARA -> 998.4 | T27: =INDEX(Stock_MP!$H:$H,MATCH($A27,Stock_MP!$B:$B,0)) -> 6.9957945 | U27: =N27/T27 -> 51.459488 | V27: =INDEX(Stock_MP!$P:$P,MATCH($A27,Stock_MP!$B:$B,0)) -> 1 | W27: =INDEX(Stock_MP!$S:$S,MATCH($A27,Stock_MP!$B:$B,0))/N27 -> 1.1090394
A28: MP-16 | B28: Casquete 12" × 3,2 (carro 50 kg) | C28: 320 | D28: 105 | E28: 3.2 | F28: 3.36 | G28: =CQ_POLL+E28 -> 23.2 | H28: =INT(CQ_LARGO/C28) -> 3 | I28: =INT(CQ_ANCHO/C28) -> 3 | J28: =H28*I28 -> 9 | K28: =1+INT((CQ_ALTO-D28)/G28) -> 30 | L28: =J28*K28 -> 270 | M28: =INT((CQ_KG-CQ_TARA)/F28) -> 261 | N28: =2*INT(MIN(L28,M28)/2) -> 260 | O28: =N28/2 -> 130 | P28: =N28/2 -> 130 | Q28: =IF(L28<=M28,"El alto","El peso") -> El peso | R28: =D28+(ROUNDUP(N28/J28,0)-1)*G28 -> 754.6 | S28: =N28*F28+CQ_TARA -> 993.6 | T28: =INDEX(Stock_MP!$H:$H,MATCH($A28,Stock_MP!$B:$B,0)) -> 15.375915 | U28: =N28/T28 -> 16.909563 | V28: =INDEX(Stock_MP!$P:$P,MATCH($A28,Stock_MP!$B:$B,0)) -> 2 | W28: =INDEX(Stock_MP!$S:$S,MATCH($A28,Stock_MP!$B:$B,0))/N28 -> 2.3318306
A29: MP-17 | B29: Casquete 15" × 4,75 (carros 70 y 100 kg) | C29: 390 | D29: 105 | E29: 4.75 | F29: 6.64 | G29: =CQ_POLL+E29 -> 24.75 | H29: =INT(CQ_LARGO/C29) -> 2 | I29: =INT(CQ_ANCHO/C29) -> 2 | J29: =H29*I29 -> 4 | K29: =1+INT((CQ_ALTO-D29)/G29) -> 29 | L29: =J29*K29 -> 116 | M29: =INT((CQ_KG-CQ_TARA)/F29) -> 132 | N29: =2*INT(MIN(L29,M29)/2) -> 116 | O29: =N29/2 -> 58 | P29: =N29/2 -> 58 | Q29: =IF(L29<=M29,"El alto","El peso") -> El alto | R29: =D29+(ROUNDUP(N29/J29,0)-1)*G29 -> 798 | S29: =N29*F29+CQ_TARA -> 890.24 | T29: =INDEX(Stock_MP!$H:$H,MATCH($A29,Stock_MP!$B:$B,0)) -> 5.5941885 | U29: =N29/T29 -> 20.735805 | V29: =INDEX(Stock_MP!$P:$P,MATCH($A29,Stock_MP!$B:$B,0)) -> 1 | W29: =INDEX(Stock_MP!$S:$S,MATCH($A29,Stock_MP!$B:$B,0))/N29 -> 1.2706001
A31: Ø y profundidad: Word de carros (tabla de piezas del carro; la profundidad del 15" es estimada). Peso: Word de carros, recepción. Ø = diámetro del recipiente (el casquete encastra en el cuerpo).
A32: Cada columna lleva casquetes de una sola clase: las cúpulas (perforadas) en unas columnas y los fondos en otras, así no se mezclan. Si las columnas son impares, la del medio lleva fondos abajo y cúpulas arriba, con un cartón entre medio.
A33: El contenedor es retornable: se devuelve vacío en el camión del pedido siguiente, y es la unidad que se guarda en el rack y se baja al piso para ir sacando piezas.
A35: 4) PEDIDOS A NOVA RUEDAS EN EL AÑO — un pedido por mes con las tres medidas juntas; de cada una se piden solo los contenedores que faltan
A36: Concepto | B36: Ene | C36: Feb | D36: Mar | E36: Abr | F36: May | G36: Jun | H36: Jul | I36: Ago | J36: Sep | K36: Oct | L36: Nov | M36: Dic | N36: Año
A37: Recipientes de carros del mes (balanceo) | B37: =Datos!B30 -> 264.12238 | C37: =Datos!C30 -> 233.04916 | D37: =Datos!D30 -> 279.65899 | E37: =Datos!E30 -> 279.65899 | F37: =Datos!F30 -> 279.65899 | G37: =Datos!G30 -> 248.58577 | H37: =Datos!H30 -> 279.65899 | I37: =Datos!I30 -> 279.65899 | ... M37: =Datos!M30 -> 248.58577 | N37: =SUM(B37:M37) -> 3107.3221
A38: MP-15 · consumo del mes (u) | B38: =INDEX(Stock_MP!$F:$F,MATCH("MP-15",Stock_MP!$B:$B,0))*B$37/$N$37 -> 132.14279 | C38: =INDEX(Stock_MP!$F:$F,MATCH("MP-15",Stock_MP!$B:$B,0))*C$37/$N$37 -> 116.59658 | D38: =INDEX(Stock_MP!$F:$F,MATCH("MP-15",Stock_MP!$B:$B,0))*D$37/$N$37 -> 139.91589 | E38: =INDEX(Stock_MP!$F:$F,MATCH("MP-15",Stock_MP!$B:$B,0))*E$37/$N$37 -> 139.91589 | F38: =INDEX(Stock_MP!$F:$F,MATCH("MP-15",Stock_MP!$B:$B,0))*F$37/$N$37 -> 139.91589 | G38: =INDEX(Stock_MP!$F:$F,MATCH("MP-15",Stock_MP!$B:$B,0))*G$37/$N$37 -> 124.36968 | H38: =INDEX(Stock_MP!$F:$F,MATCH("MP-15",Stock_MP!$B:$B,0))*H$37/$N$37 -> 139.91589 | I38: =INDEX(Stock_MP!$F:$F,MATCH("MP-15",Stock_MP!$B:$B,0))*I$37/$N$37 -> 139.91589 | ... M38: =INDEX(Stock_MP!$F:$F,MATCH("MP-15",Stock_MP!$B:$B,0))*M$37/$N$37 -> 124.36968 | N38: =SUM(B38:M38) -> 1554.621
A39: MP-15 · contenedores en el pedido | B39: =MAX(0,ROUNDUP((INDEX(Stock_MP!$L:$L,MATCH("MP-15",Stock_MP!$B:$B,0))+SUM($B38:C38)-(INDEX(Stock_MP!$L:$L,MATCH("MP-15",Stock_MP!$B:$B,0))+$B38)-$N$27*0)/$N$27,0)) -> 1 | C39: =MAX(0,ROUNDUP((INDEX(Stock_MP!$L:$L,MATCH("MP-15",Stock_MP!$B:$B,0))+SUM($B38:D38)-(INDEX(Stock_MP!$L:$L,MATCH("MP-15",Stock_MP!$B:$B,0))+$B38)-$N$27*SUM($A39:B39))/$N$27,0)) -> 0 | D39: =MAX(0,ROUNDUP((INDEX(Stock_MP!$L:$L,MATCH("MP-15",Stock_MP!$B:$B,0))+SUM($B38:E38)-(INDEX(Stock_MP!$L:$L,MATCH("MP-15",Stock_MP!$B:$B,0))+$B38)-$N$27*SUM($A39:C39))/$N$27,0)) -> 1 | E39: =MAX(0,ROUNDUP((INDEX(Stock_MP!$L:$L,MATCH("MP-15",Stock_MP!$B:$B,0))+SUM($B38:F38)-(INDEX(Stock_MP!$L:$L,MATCH("MP-15",Stock_MP!$B:$B,0))+$B38)-$N$27*SUM($A39:D39))/$N$27,0)) -> 0 | F39: =MAX(0,ROUNDUP((INDEX(Stock_MP!$L:$L,MATCH("MP-15",Stock_MP!$B:$B,0))+SUM($B38:G38)-(INDEX(Stock_MP!$L:$L,MATCH("MP-15",Stock_MP!$B:$B,0))+$B38)-$N$27*SUM($A39:E39))/$N$27,0)) -> 0 | G39: =MAX(0,ROUNDUP((INDEX(Stock_MP!$L:$L,MATCH("MP-15",Stock_MP!$B:$B,0))+SUM($B38:H38)-(INDEX(Stock_MP!$L:$L,MATCH("MP-15",Stock_MP!$B:$B,0))+$B38)-$N$27*SUM($A39:F39))/$N$27,0)) -> 1 | H39: =MAX(0,ROUNDUP((INDEX(Stock_MP!$L:$L,MATCH("MP-15",Stock_MP!$B:$B,0))+SUM($B38:I38)-(INDEX(Stock_MP!$L:$L,MATCH("MP-15",Stock_MP!$B:$B,0))+$B38)-$N$27*SUM($A39:G39))/$N$27,0)) -> 0 | I39: =MAX(0,ROUNDUP((INDEX(Stock_MP!$L:$L,MATCH("MP-15",Stock_MP!$B:$B,0))+SUM($B38:J38)-(INDEX(Stock_MP!$L:$L,MATCH("MP-15",Stock_MP!$B:$B,0))+$B38)-$N$27*SUM($A39:H39))/$N$27,0)) -> 0 | J39: =MAX(0,ROUNDUP((INDEX(Stock_MP!$L:$L,MATCH("MP-15",Stock_MP!$B:$B,0))+SUM($B38:K38)-(INDEX(Stock_MP!$L:$L,MATCH("MP-15",Stock_MP!$B:$B,0))+$B38)-$N$27*SUM($A39:I39))/$N$27,0)) -> 1 | ... L39: =MAX(0,ROUNDUP((INDEX(Stock_MP!$L:$L,MATCH("MP-15",Stock_MP!$B:$B,0))+SUM($B38:M38)-(INDEX(Stock_MP!$L:$L,MATCH("MP-15",Stock_MP!$B:$B,0))+$B38)-$N$27*SUM($A39:K39))/$N$27,0)) -> 0 | M39: =MAX(0,ROUNDUP((INDEX(Stock_MP!$L:$L,MATCH("MP-15",Stock_MP!$B:$B,0))+(SUM($B38:$M38)+$B38)-(INDEX(Stock_MP!$L:$L,MATCH("MP-15",Stock_MP!$B:$B,0))+$B38)-$N$27*SUM($A39:L39))/$N$27,0)) -> 1 | N39: =SUM(B39:M39) -> 5
A40: MP-15 · stock a fin de mes (u) | B40: =(INDEX(Stock_MP!$L:$L,MATCH("MP-15",Stock_MP!$B:$B,0))+$B38)+$N$27*0-SUM($B38:B38) -> 39.25418 | C40: =(INDEX(Stock_MP!$L:$L,MATCH("MP-15",Stock_MP!$B:$B,0))+$B38)+$N$27*SUM($A39:B39)-SUM($B38:C38) -> 282.65761 | D40: =(INDEX(Stock_MP!$L:$L,MATCH("MP-15",Stock_MP!$B:$B,0))+$B38)+$N$27*SUM($A39:C39)-SUM($B38:D38) -> 142.74172 | E40: =(INDEX(Stock_MP!$L:$L,MATCH("MP-15",Stock_MP!$B:$B,0))+$B38)+$N$27*SUM($A39:D39)-SUM($B38:E38) -> 362.82583 | F40: =(INDEX(Stock_MP!$L:$L,MATCH("MP-15",Stock_MP!$B:$B,0))+$B38)+$N$27*SUM($A39:E39)-SUM($B38:F38) -> 222.90994 | G40: =(INDEX(Stock_MP!$L:$L,MATCH("MP-15",Stock_MP!$B:$B,0))+$B38)+$N$27*SUM($A39:F39)-SUM($B38:G38) -> 98.540255 | H40: =(INDEX(Stock_MP!$L:$L,MATCH("MP-15",Stock_MP!$B:$B,0))+$B38)+$N$27*SUM($A39:G39)-SUM($B38:H38) -> 318.62437 | I40: =(INDEX(Stock_MP!$L:$L,MATCH("MP-15",Stock_MP!$B:$B,0))+$B38)+$N$27*SUM($A39:H39)-SUM($B38:I38) -> 178.70848 | J40: =(INDEX(Stock_MP!$L:$L,MATCH("MP-15",Stock_MP!$B:$B,0))+$B38)+$N$27*SUM($A39:I39)-SUM($B38:J38) -> 46.56569 | ... M40: =(INDEX(Stock_MP!$L:$L,MATCH("MP-15",Stock_MP!$B:$B,0))+$B38)+$N$27*SUM($A39:L39)-SUM($B38:M38) -> 56.775965 | N40: =MIN(B40:M40) -> 39.25418
A42: MP-16 · consumo del mes (u) | B42: =INDEX(Stock_MP!$F:$F,MATCH("MP-16",Stock_MP!$B:$B,0))*B$37/$N$37 -> 290.43395 | C42: =INDEX(Stock_MP!$F:$F,MATCH("MP-16",Stock_MP!$B:$B,0))*C$37/$N$37 -> 256.26525 | D42: =INDEX(Stock_MP!$F:$F,MATCH("MP-16",Stock_MP!$B:$B,0))*D$37/$N$37 -> 307.5183 | E42: =INDEX(Stock_MP!$F:$F,MATCH("MP-16",Stock_MP!$B:$B,0))*E$37/$N$37 -> 307.5183 | F42: =INDEX(Stock_MP!$F:$F,MATCH("MP-16",Stock_MP!$B:$B,0))*F$37/$N$37 -> 307.5183 | G42: =INDEX(Stock_MP!$F:$F,MATCH("MP-16",Stock_MP!$B:$B,0))*G$37/$N$37 -> 273.3496 | H42: =INDEX(Stock_MP!$F:$F,MATCH("MP-16",Stock_MP!$B:$B,0))*H$37/$N$37 -> 307.5183 | I42: =INDEX(Stock_MP!$F:$F,MATCH("MP-16",Stock_MP!$B:$B,0))*I$37/$N$37 -> 307.5183 | ... M42: =INDEX(Stock_MP!$F:$F,MATCH("MP-16",Stock_MP!$B:$B,0))*M$37/$N$37 -> 273.3496 | N42: =SUM(B42:M42) -> 3416.87
A43: MP-16 · contenedores en el pedido | B43: =MAX(0,ROUNDUP((INDEX(Stock_MP!$L:$L,MATCH("MP-16",Stock_MP!$B:$B,0))+SUM($B42:C42)-(INDEX(Stock_MP!$L:$L,MATCH("MP-16",Stock_MP!$B:$B,0))+$B42)-$N$28*0)/$N$28,0)) -> 1 | C43: =MAX(0,ROUNDUP((INDEX(Stock_MP!$L:$L,MATCH("MP-16",Stock_MP!$B:$B,0))+SUM($B42:D42)-(INDEX(Stock_MP!$L:$L,MATCH("MP-16",Stock_MP!$B:$B,0))+$B42)-$N$28*SUM($A43:B43))/$N$28,0)) -> 2 | D43: =MAX(0,ROUNDUP((INDEX(Stock_MP!$L:$L,MATCH("MP-16",Stock_MP!$B:$B,0))+SUM($B42:E42)-(INDEX(Stock_MP!$L:$L,MATCH("MP-16",Stock_MP!$B:$B,0))+$B42)-$N$28*SUM($A43:C43))/$N$28,0)) -> 1 | E43: =MAX(0,ROUNDUP((INDEX(Stock_MP!$L:$L,MATCH("MP-16",Stock_MP!$B:$B,0))+SUM($B42:F42)-(INDEX(Stock_MP!$L:$L,MATCH("MP-16",Stock_MP!$B:$B,0))+$B42)-$N$28*SUM($A43:D43))/$N$28,0)) -> 1 | F43: =MAX(0,ROUNDUP((INDEX(Stock_MP!$L:$L,MATCH("MP-16",Stock_MP!$B:$B,0))+SUM($B42:G42)-(INDEX(Stock_MP!$L:$L,MATCH("MP-16",Stock_MP!$B:$B,0))+$B42)-$N$28*SUM($A43:E43))/$N$28,0)) -> 1 | G43: =MAX(0,ROUNDUP((INDEX(Stock_MP!$L:$L,MATCH("MP-16",Stock_MP!$B:$B,0))+SUM($B42:H42)-(INDEX(Stock_MP!$L:$L,MATCH("MP-16",Stock_MP!$B:$B,0))+$B42)-$N$28*SUM($A43:F43))/$N$28,0)) -> 1 | H43: =MAX(0,ROUNDUP((INDEX(Stock_MP!$L:$L,MATCH("MP-16",Stock_MP!$B:$B,0))+SUM($B42:I42)-(INDEX(Stock_MP!$L:$L,MATCH("MP-16",Stock_MP!$B:$B,0))+$B42)-$N$28*SUM($A43:G43))/$N$28,0)) -> 1 | I43: =MAX(0,ROUNDUP((INDEX(Stock_MP!$L:$L,MATCH("MP-16",Stock_MP!$B:$B,0))+SUM($B42:J42)-(INDEX(Stock_MP!$L:$L,MATCH("MP-16",Stock_MP!$B:$B,0))+$B42)-$N$28*SUM($A43:H43))/$N$28,0)) -> 2 | J43: =MAX(0,ROUNDUP((INDEX(Stock_MP!$L:$L,MATCH("MP-16",Stock_MP!$B:$B,0))+SUM($B42:K42)-(INDEX(Stock_MP!$L:$L,MATCH("MP-16",Stock_MP!$B:$B,0))+$B42)-$N$28*SUM($A43:I43))/$N$28,0)) -> 1 | ... L43: =MAX(0,ROUNDUP((INDEX(Stock_MP!$L:$L,MATCH("MP-16",Stock_MP!$B:$B,0))+SUM($B42:M42)-(INDEX(Stock_MP!$L:$L,MATCH("MP-16",Stock_MP!$B:$B,0))+$B42)-$N$28*SUM($A43:K43))/$N$28,0)) -> 2 | M43: =MAX(0,ROUNDUP((INDEX(Stock_MP!$L:$L,MATCH("MP-16",Stock_MP!$B:$B,0))+(SUM($B42:$M42)+$B42)-(INDEX(Stock_MP!$L:$L,MATCH("MP-16",Stock_MP!$B:$B,0))+$B42)-$N$28*SUM($A43:L43))/$N$28,0)) -> 1 | N43: =SUM(B43:M43) -> 14
A44: MP-16 · stock a fin de mes (u) | B44: =(INDEX(Stock_MP!$L:$L,MATCH("MP-16",Stock_MP!$B:$B,0))+$B42)+$N$28*0-SUM($B42:B42) -> 86.275967 | C44: =(INDEX(Stock_MP!$L:$L,MATCH("MP-16",Stock_MP!$B:$B,0))+$B42)+$N$28*SUM($A43:B43)-SUM($B42:C42) -> 90.010717 | D44: =(INDEX(Stock_MP!$L:$L,MATCH("MP-16",Stock_MP!$B:$B,0))+$B42)+$N$28*SUM($A43:C43)-SUM($B42:D42) -> 302.49242 | E44: =(INDEX(Stock_MP!$L:$L,MATCH("MP-16",Stock_MP!$B:$B,0))+$B42)+$N$28*SUM($A43:D43)-SUM($B42:E42) -> 254.97412 | F44: =(INDEX(Stock_MP!$L:$L,MATCH("MP-16",Stock_MP!$B:$B,0))+$B42)+$N$28*SUM($A43:E43)-SUM($B42:F42) -> 207.45582 | G44: =(INDEX(Stock_MP!$L:$L,MATCH("MP-16",Stock_MP!$B:$B,0))+$B42)+$N$28*SUM($A43:F43)-SUM($B42:G42) -> 194.10622 | H44: =(INDEX(Stock_MP!$L:$L,MATCH("MP-16",Stock_MP!$B:$B,0))+$B42)+$N$28*SUM($A43:G43)-SUM($B42:H42) -> 146.58792 | I44: =(INDEX(Stock_MP!$L:$L,MATCH("MP-16",Stock_MP!$B:$B,0))+$B42)+$N$28*SUM($A43:H43)-SUM($B42:I42) -> 99.069618 | J44: =(INDEX(Stock_MP!$L:$L,MATCH("MP-16",Stock_MP!$B:$B,0))+$B42)+$N$28*SUM($A43:I43)-SUM($B42:J42) -> 328.63567 | ... M44: =(INDEX(Stock_MP!$L:$L,MATCH("MP-16",Stock_MP!$B:$B,0))+$B42)+$N$28*SUM($A43:L43)-SUM($B42:M42) -> 339.83992 | N44: =MIN(B44:M44) -> 86.275967
A46: MP-17 · consumo del mes (u) | B46: =INDEX(Stock_MP!$F:$F,MATCH("MP-17",Stock_MP!$B:$B,0))*B$37/$N$37 -> 105.66801 | C46: =INDEX(Stock_MP!$F:$F,MATCH("MP-17",Stock_MP!$B:$B,0))*C$37/$N$37 -> 93.236475 | D46: =INDEX(Stock_MP!$F:$F,MATCH("MP-17",Stock_MP!$B:$B,0))*D$37/$N$37 -> 111.88377 | E46: =INDEX(Stock_MP!$F:$F,MATCH("MP-17",Stock_MP!$B:$B,0))*E$37/$N$37 -> 111.88377 | F46: =INDEX(Stock_MP!$F:$F,MATCH("MP-17",Stock_MP!$B:$B,0))*F$37/$N$37 -> 111.88377 | G46: =INDEX(Stock_MP!$F:$F,MATCH("MP-17",Stock_MP!$B:$B,0))*G$37/$N$37 -> 99.45224 | H46: =INDEX(Stock_MP!$F:$F,MATCH("MP-17",Stock_MP!$B:$B,0))*H$37/$N$37 -> 111.88377 | I46: =INDEX(Stock_MP!$F:$F,MATCH("MP-17",Stock_MP!$B:$B,0))*I$37/$N$37 -> 111.88377 | ... M46: =INDEX(Stock_MP!$F:$F,MATCH("MP-17",Stock_MP!$B:$B,0))*M$37/$N$37 -> 99.45224 | N46: =SUM(B46:M46) -> 1243.153
A47: MP-17 · contenedores en el pedido | B47: =MAX(0,ROUNDUP((INDEX(Stock_MP!$L:$L,MATCH("MP-17",Stock_MP!$B:$B,0))+SUM($B46:C46)-(INDEX(Stock_MP!$L:$L,MATCH("MP-17",Stock_MP!$B:$B,0))+$B46)-$N$29*0)/$N$29,0)) -> 1 | C47: =MAX(0,ROUNDUP((INDEX(Stock_MP!$L:$L,MATCH("MP-17",Stock_MP!$B:$B,0))+SUM($B46:D46)-(INDEX(Stock_MP!$L:$L,MATCH("MP-17",Stock_MP!$B:$B,0))+$B46)-$N$29*SUM($A47:B47))/$N$29,0)) -> 1 | D47: =MAX(0,ROUNDUP((INDEX(Stock_MP!$L:$L,MATCH("MP-17",Stock_MP!$B:$B,0))+SUM($B46:E46)-(INDEX(Stock_MP!$L:$L,MATCH("MP-17",Stock_MP!$B:$B,0))+$B46)-$N$29*SUM($A47:C47))/$N$29,0)) -> 1 | E47: =MAX(0,ROUNDUP((INDEX(Stock_MP!$L:$L,MATCH("MP-17",Stock_MP!$B:$B,0))+SUM($B46:F46)-(INDEX(Stock_MP!$L:$L,MATCH("MP-17",Stock_MP!$B:$B,0))+$B46)-$N$29*SUM($A47:D47))/$N$29,0)) -> 1 | F47: =MAX(0,ROUNDUP((INDEX(Stock_MP!$L:$L,MATCH("MP-17",Stock_MP!$B:$B,0))+SUM($B46:G46)-(INDEX(Stock_MP!$L:$L,MATCH("MP-17",Stock_MP!$B:$B,0))+$B46)-$N$29*SUM($A47:E47))/$N$29,0)) -> 1 | G47: =MAX(0,ROUNDUP((INDEX(Stock_MP!$L:$L,MATCH("MP-17",Stock_MP!$B:$B,0))+SUM($B46:H46)-(INDEX(Stock_MP!$L:$L,MATCH("MP-17",Stock_MP!$B:$B,0))+$B46)-$N$29*SUM($A47:F47))/$N$29,0)) -> 1 | H47: =MAX(0,ROUNDUP((INDEX(Stock_MP!$L:$L,MATCH("MP-17",Stock_MP!$B:$B,0))+SUM($B46:I46)-(INDEX(Stock_MP!$L:$L,MATCH("MP-17",Stock_MP!$B:$B,0))+$B46)-$N$29*SUM($A47:G47))/$N$29,0)) -> 1 | I47: =MAX(0,ROUNDUP((INDEX(Stock_MP!$L:$L,MATCH("MP-17",Stock_MP!$B:$B,0))+SUM($B46:J46)-(INDEX(Stock_MP!$L:$L,MATCH("MP-17",Stock_MP!$B:$B,0))+$B46)-$N$29*SUM($A47:H47))/$N$29,0)) -> 1 | J47: =MAX(0,ROUNDUP((INDEX(Stock_MP!$L:$L,MATCH("MP-17",Stock_MP!$B:$B,0))+SUM($B46:K46)-(INDEX(Stock_MP!$L:$L,MATCH("MP-17",Stock_MP!$B:$B,0))+$B46)-$N$29*SUM($A47:I47))/$N$29,0)) -> 1 | ... L47: =MAX(0,ROUNDUP((INDEX(Stock_MP!$L:$L,MATCH("MP-17",Stock_MP!$B:$B,0))+SUM($B46:M46)-(INDEX(Stock_MP!$L:$L,MATCH("MP-17",Stock_MP!$B:$B,0))+$B46)-$N$29*SUM($A47:K47))/$N$29,0)) -> 1 | M47: =MAX(0,ROUNDUP((INDEX(Stock_MP!$L:$L,MATCH("MP-17",Stock_MP!$B:$B,0))+(SUM($B46:$M46)+$B46)-(INDEX(Stock_MP!$L:$L,MATCH("MP-17",Stock_MP!$B:$B,0))+$B46)-$N$29*SUM($A47:L47))/$N$29,0)) -> 1 | N47: =SUM(B47:M47) -> 11
...

Sheet Stock_MP
A1: STOCK DE CADA MATERIA PRIMA — consumo pico, seguridad, pedido y stock máximo (las 125 MP)
A2: Una fila por MP. Consumo pico = producción con sobrestock (factor de la línea), no ventas. Chapa y fleje salen de Chapa_fleje (en paquetes y rollos enteros).
A3: ▶ Columnas M, N, O (cómo se compra), S (stock máximo), U (lugares) y V (cómo se guarda).
A5: Ref. | B5: Código | C5: Material | D5: UM | E5: Proveedor | F5: Consumo del año | G5: Consumo por día (prom.) | H5: Consumo por día (pico) | I5: Plazo mín. | J5: Plazo máx. | K5: Consumo mientras llega | L5: Stock de seguridad | M5: Unidad de compra | N5: Contenido | O5: Cada (días) | P5: Por pedido (unid. de compra) | Q5: Pedidos por año | R5: Almacén | S5: Stock máximo | T5: Cuánto entra en un lugar | U5: Lugares | V5: Cómo se guarda | W5: Línea
A6: =Datos!A52 -> P01 | B6: =Datos!C52 -> MP-01 | C6: =Datos!B52 -> Hoja LAF 0,9 × 1220 × 2440 mm (cuerpo 1 kg) | D6: =Datos!F52 -> hoja | E6: =Datos!D52 -> Hierros Parrotta | F6: =Datos!E52 -> 4502.681 | G6: =F6/DIAS_ANIO -> 18.761171 | H6: =Chapa_fleje!H7 -> 20.262064 | I6: =Datos!G52 -> 10 | J6: =Datos!H52 -> 10 | K6: =G6*(I6+J6)/2 -> 187.61171 | L6: =Chapa_fleje!S7*Chapa_fleje!L7 -> 21 | M6: ="Paquete de "&Chapa_fleje!L7&" hojas (1 tanda)" -> Paquete de 21 hojas (1 tanda) | N6: =Chapa_fleje!L7 -> 21 | O6: =Chapa_fleje!T7 -> 20 | P6: =Chapa_fleje!U7 -> 20 | Q6: =IF(P6*N6=0,0,F6/(P6*N6)) -> 10.720669 | R6: Chapa (pilas en el piso) | S6: =Chapa_fleje!V7*Chapa_fleje!L7 -> 441 | T6: — | U6: =Chapa_fleje!K18 -> 1 | V6: =IFERROR(VLOOKUP(R6,Almacenes!$A$19:$I$32,9,FALSE()),"") -> Paquete sobre sus 3 tacos, una pila por formato hasta el alto que permiten el autoelevador, el piso y la estabilidad (Chapa_fleje sección 2). Se toma el de arriba; al recibir, el remanente pasa arriba (FIFO por colada). Pilas demarcadas con su código, 2 filas enfrentadas sobre la calle. | W6: Manuales
A7: =Datos!A53 -> P02 | B7: =Datos!C53 -> MP-02 | C7: =Datos!B53 -> Hoja LAF 1,25 × 1220 × 2440 mm | D7: =Datos!F53 -> hoja | E7: =Datos!D53 -> Pradecon | F7: =Datos!E53 -> 523.198 | G7: =F7/DIAS_ANIO -> 2.1799917 | H7: =Chapa_fleje!H8 -> 2.3543897 | I7: =Datos!G53 -> 7 | J7: =Datos!H53 -> 10 | K7: =G7*(I7+J7)/2 -> 18.529929 | L7: =Chapa_fleje!S8*Chapa_fleje!L8 -> 19 | M7: ="Paquete de "&Chapa_fleje!L8&" hojas (1 tanda)" -> Paquete de 19 hojas (1 tanda) | N7: =Chapa_fleje!L8 -> 19 | O7: =Chapa_fleje!T8 -> 20 | P7: =Chapa_fleje!U8 -> 3 | Q7: =IF(P7*N7=0,0,F7/(P7*N7)) -> 9.1789123 | R7: Chapa (pilas en el piso) | S7: =Chapa_fleje!V8*Chapa_fleje!L8 -> 76 | T7: — | U7: =Chapa_fleje!K19 -> 1 | V7: =IFERROR(VLOOKUP(R7,Almacenes!$A$19:$I$32,9,FALSE()),"") -> Paquete sobre sus 3 tacos, una pila por formato hasta el alto que permiten el autoelevador, el piso y la estabilidad (Chapa_fleje sección 2). Se toma el de arriba; al recibir, el remanente pasa arriba (FIFO por colada). Pilas demarcadas con su código, 2 filas enfrentadas sobre la calle. | W7: Manuales
A8: =Datos!A54 -> P03 | B8: =Datos!C54 -> MP-03 | C8: =Datos!B54 -> Hoja LAF 1,6 × 1000 × 2000 mm | D8: =Datos!F54 -> hoja | E8: =Datos!D54 -> Pradecon | F8: =Datos!E54 -> 5321.055 | G8: =F8/DIAS_ANIO -> 22.171063 | H8: =Chapa_fleje!H9 -> 23.944747 | I8: =Datos!G54 -> 7 | J8: =Datos!H54 -> 10 | K8: =G8*(I8+J8)/2 -> 188.45403 | L8: =Chapa_fleje!S9*Chapa_fleje!L9 -> 72 | M8: ="Paquete de "&Chapa_fleje!L9&" hojas (1 tanda)" -> Paquete de 24 hojas (1 tanda) | N8: =Chapa_fleje!L9 -> 24 | O8: =Chapa_fleje!T9 -> 20 | P8: =Chapa_fleje!U9 -> 20 | Q8: =IF(P8*N8=0,0,F8/(P8*N8)) -> 11.085531 | R8: Chapa (pilas en el piso) | S8: =Chapa_fleje!V9*Chapa_fleje!L9 -> 552 | T8: — | U8: =Chapa_fleje!K20 -> 2 | V8: =IFERROR(VLOOKUP(R8,Almacenes!$A$19:$I$32,9,FALSE()),"") -> Paquete sobre sus 3 tacos, una pila por formato hasta el alto que permiten el autoelevador, el piso y la estabilidad (Chapa_fleje sección 2). Se toma el de arriba; al recibir, el remanente pasa arriba (FIFO por colada). Pilas demarcadas con su código, 2 filas enfrentadas sobre la calle. | W8: Manuales
A9: =Datos!A55 -> P04 | B9: =Datos!C55 -> MP-04 | C9: =Datos!B55 -> Hoja LAF 2,0 × 1500 × 3000 mm | D9: =Datos!F55 -> hoja | E9: =Datos!D55 -> Pradecon | F9: =Datos!E55 -> 257.529 | G9: =F9/DIAS_ANIO -> 1.0730375 | H9: =Chapa_fleje!H10 -> 1.1588784 | I9: =Datos!G55 -> 7 | J9: =Datos!H55 -> 10 | K9: =G9*(I9+J9)/2 -> 9.1208187 | L9: =Chapa_fleje!S10*Chapa_fleje!L10 -> 19 | M9: ="Paquete de "&Chapa_fleje!L10&" hojas (1 tanda)" -> Paquete de 19 hojas (1 tanda) | N9: =Chapa_fleje!L10 -> 19 | O9: =Chapa_fleje!T10 -> 20 | P9: =Chapa_fleje!U10 -> 2 | Q9: =IF(P9*N9=0,0,F9/(P9*N9)) -> 6.7770789 | R9: Chapa (pilas en el piso) | S9: =Chapa_fleje!V10*Chapa_fleje!L10 -> 57 | T9: — | U9: =Chapa_fleje!K21 -> 1 | V9: =IFERROR(VLOOKUP(R9,Almacenes!$A$19:$I$32,9,FALSE()),"") -> Paquete sobre sus 3 tacos, una pila por formato hasta el alto que permiten el autoelevador, el piso y la estabilidad (Chapa_fleje sección 2). Se toma el de arriba; al recibir, el remanente pasa arriba (FIFO por colada). Pilas demarcadas con su código, 2 filas enfrentadas sobre la calle. | W9: Manuales
