Workbook

Sheet Resumen
A1: PRODUCTO TERMINADO 2035 — cómo se guarda, cómo se despacha y la rama de pintura de carros
A2: Nuevos en caja y cilindros en pallets; carros terminados sueltos. Recargas queda afuera. Datos del balanceo limpio, palletizado_PT y el Word de carros.
A3: ▶ Una hoja por paso: Pallets → Stock_PT → Almacen_PT → Despacho → Pintura → Carro_manip → Equipos.
A5: 1) LO PRINCIPAL
A6: Concepto | B6: Antes | C6: Ahora | D6: Hoja
A7: Almacén de PT: rack + carros + andén (m²) | B7: =Almacen_PT!C42 -> 173.22 | C7: =Almacen_PT!B42 -> 183.686 | D7: Almacen_PT
A8: Pallets en el rack | B8: =Datos!B56 -> 99 | C8: =Almacen_PT!B7 -> 85 | D8: Stock_PT
A9: Módulos de rack (3 niveles) | B9: — | C9: =Almacen_PT!B15 -> 15 | D9: Almacen_PT
A10: Mástil del autoelevador | B10: 3 m | C10: =Almacen_PT!B12 -> Mástil de 4,5 m | D10: Almacen_PT
A11: Envíos al pintor | B11: Lote semanal | C11: ="Cada "&DIAS_PINT&" días" -> Cada 2 días | D11: Pintura
A12: Carros fuera de la línea después del secado (u) | B12: =Pintura!D32 -> 132.06 | C12: =Pintura!B32 -> 99 | D12: Pintura
A13: Juegos provisorios / carros de manipulación | B13: =Datos!B60 -> 177 | C13: =Carro_manip!B25 -> 18 | D13: Carro_manip
A14: Camión chico: viajes por semana en el pico | B14: — | C14: =Despacho!B25 -> 2.4706377 | D14: Despacho
A15: Sider: viajes por semana en el pico | B15: — | C15: =Despacho!B26 -> 1.2888695 | D15: Despacho
A16: Master: viajes por semana (clientes + pintor) | B16: — | C16: =Despacho!B27+Despacho!B28 -> 11.641441 | D16: Despacho
A17: Masters que hacen falta | B17: — | C17: =Despacho!G29 -> 1 | D17: Despacho
A18: Equipos con precio, con IVA | B18: — | C18: =Equipos!F13 -> 10088336 | D18: Equipos
A21: 2) LO QUE NO COINCIDÍA
A22: 1. El balanceo usa 400 / 167 / 90 / 40 por pallet igual para matafuegos y cilindros. Con cajas paradas son 360 / 168 / 84 / 60 y con cilindros parados 780 / 288 / 126 / 60 (palletizado_PT).
A23: 2. El Word de carros manda los recipientes al pintor sobre 177 juegos provisorios de eje y ruedas: se reemplazan por los carros de manipulación, que no salen de planta.
A24: 3. El balanceo junta los carros secos una semana antes de mandarlos a pintar (lote semanal): con envíos cada 2 días baja el stock en proceso de carros.
A25: 4. Con pallets de hasta 1,5 m el 2.º larguero queda a más de 3 m: el mástil estándar del Heli no llega.

Sheet Parametros
A1: PARÁMETROS — supuestos y criterios del almacén de PT, el despacho y la pintura
A2: Amarillo = criterio (se puede cambiar). Verde = dato. La columna E es el nombre que usan las fórmulas.
A3: ▶ Solo se tocan las celdas amarillas.
A5: 1) DÍAS Y STOCK
A6: Parámetro | B6: Valor | C6: Unidad | D6: Fuente / criterio | E6: Nombre
A7: Días hábiles por mes | B7: 20 | C7: días | D7: Balanceo2035, Parametros B7 | E7: DIAS
A8: Días hábiles por año | B8: =DIAS*12 -> 240 | C8: días | E8: DIAS_ANIO
A9: Seguridad de PT de manuales (nuevos y cilindros) | B9: 5 | C9: días de venta | D9: Balanceo2035, Parametros B44 (una semana hábil de venta promedio) | E9: SS_PT
A10: Stock de carros terminados y cilindros de carro | B10: 5 | C10: días de venta | D10: Balanceo2035, Parametros B47 (lote semanal; se libera y se despacha) | E10: DIAS_CAR
A12: 2) PALLET (ARLOG IRAM 10016) Y ARMADO — palletizado_PT
A13: Parámetro | B13: Valor | C13: Unidad | D13: Fuente / criterio | E13: Nombre
A14: Pallet: largo | B14: 1200 | C14: mm | D14: ARLOG 1.200 × 1.000 | E14: PAL_L
A15: Pallet: ancho | B15: 1000 | C15: mm | E15: PAL_A
A16: Pallet: alto | B16: 145 | C16: mm | E16: PAL_H
A17: Pallet: tara | B17: 35 | C17: kg | E17: PAL_TARA
A18: Alto máximo con la carga | B18: 1600 | C18: mm | D18: Envolvedora EDOS: 1.000 a 1.700 mm | E18: H_MAX
A19: Peso máximo de la carga | B19: 1100 | C19: kg | D19: EDOS 600 a 1.200 kg; ARLOG 1.500 kg | E19: KG_MAX
A20: Separador de cartón: espesor | B20: 3 | C20: mm | D20: Uno abajo, uno entre capas y la tapa | E20: SEP_E
A21: Separador de cartón: masa | B21: 0.6 | C21: kg | E21: SEP_KG
A23: 3) RACK DE PT
A24: Parámetro | B24: Valor | C24: Unidad | D24: Fuente / criterio | E24: Nombre
A25: Pallets por nivel de un módulo | B25: 2 | C25: u | D25: Módulo de 2,30 m (igual que MP) | E25: POS_NIV
A26: Niveles (piso + 2 largueros) | B26: 3 | C26: u | D26: Balanceo2035, Parametros B45 | E26: NIV_PT
A27: Carga por nivel del módulo | B27: 2000 | C27: kg | D27: Rack de 2.000 kg/nivel (módulo R1 de MP) | E27: KG_NIV
A28: Holgura sobre el pallet | B28: 150 | C28: mm | D28: Para entrar y sacar con las uñas | E28: HOLG_V
A29: Alto del larguero | B29: 100 | C29: mm | E29: LARG
A30: Margen para pasar el pallet por encima del larguero | B30: 0.2 | C30: m | E30: MARGEN_ELEV
A31: Elevación del mástil estándar del Heli CPCD50 | B31: 3 | C31: m | D31: Words de manuales y carros | E31: ELEV_STD
A32: Elevación del mástil opcional | B32: 4.5 | C32: m | D32: El balanceo dice torre de 3 a 6 m. Se propone 4,5 m | E32: ELEV_ALT
A33: Frente de un módulo | B33: 2.3 | C33: m | E33: MOD_FRENTE
A34: Fondo del rack | B34: 1.1 | C34: m | D34: Pallet de 1.200 de fondo con 50 mm de vuelo | E34: MOD_FONDO
A35: Ancho de la calle del autoelevador | B35: 5 | C35: m | D35: Word de carros (radio de giro 2,93 m + pallet + margen) | E35: CALLE
A36: Factor de circulación para lo que va en el piso | B36: 1.4 | C36: × | D36: Supuesto: pasillos entre carros, recipientes y pallets en el piso | E36: F_CIRC
A38: 4) PINTURA TERCERIZADA DE CARROS
A39: Parámetro | B39: Valor | C39: Unidad | D39: Fuente / criterio | E39: Nombre
A40: Días desde que salen de planta hasta que vuelven pintados | B40: 3 | C40: días hábiles | D40: Balanceo2035, Carga X87 y Word de carros | E40: PLAZO_PINT
A41: Días entre envíos al pintor (elegido) | B41: 2 | C41: días hábiles | D41: Ver hoja Pintura, sección 2: se compara 1, 2, 3 y 5 días | E41: DIAS_PINT
A42: Días que el pintado espera la carga de polvo (vuelve el envío entero) | B42: 2 | C42: días hábiles | D42: La Master trae de una vez los pintados de un envío (2 días) y la carga hace 14 por día. Las ruedas se ponen en el montaje (13). Igual que Pulmones-FLAMA2035 | E42: DIAS_PINTADOS
A44: 5) CARRO DE MANIPULACIÓN ADAPTABLE (de la salida de accesorios a la espera del pintor)
A45: Parámetro | B45: Valor | C45: Unidad | D45: Fuente / criterio | E45: Nombre
...

Sheet Pallets
A1: CUÁNTO VA EN CADA PALLET — nuevos en caja, cilindros vacíos y carros
A2: Pallet ARLOG 1.200 × 1.000. Las cajas van paradas con el matafuego parado adentro; los cilindros van parados con un cartón entre capas, tapa, esquineros y film.
A3: ▶ Fila 16: matafuegos por pallet. Fila 31: cilindros por pallet. Fila 37: carros por Master.
A5: 1) MATAFUEGOS NUEVOS EN CAJA (cajas paradas, en capas)
A6: Concepto | B6: Unidad | C6: 1 kg | D6: 2,5 kg | E6: 5 kg | F6: 10 kg
A7: Matafuegos por caja | B7: u | C7: =Datos!C33 -> 6 | D7: =Datos!D33 -> 1 | E7: =Datos!E33 -> 1 | F7: =Datos!F33 -> 1
A8: Peso de la caja llena | B8: kg | C8: =C7*Datos!C38+Datos!C37 -> 12.83 | D8: =D7*Datos!D38+Datos!D37 -> 4.88 | E8: =E7*Datos!E38+Datos!E37 -> 8.83 | F8: =F7*Datos!F38+Datos!F37 -> 16.73
A9: Cajas a lo largo (1.200) | B9: u | C9: =INT(PAL_L/Datos!C34) -> 4 | D9: =INT(PAL_L/Datos!D34) -> 8 | E9: =INT(PAL_L/Datos!E34) -> 7 | F9: =INT(PAL_L/Datos!F34) -> 6
A10: Cajas a lo ancho (1.000) | B10: u | C10: =INT(PAL_A/Datos!C35) -> 5 | D10: =INT(PAL_A/Datos!D35) -> 7 | E10: =INT(PAL_A/Datos!E35) -> 6 | F10: =INT(PAL_A/Datos!F35) -> 5
A11: Cajas por capa | B11: u | C11: =C9*C10 -> 20 | D11: =D9*D10 -> 56 | E11: =E9*E10 -> 42 | F11: =F9*F10 -> 30
A12: Capas por alto | B12: u | C12: =INT((H_MAX-PAL_H)/Datos!C36) -> 3 | D12: =INT((H_MAX-PAL_H)/Datos!D36) -> 3 | E12: =INT((H_MAX-PAL_H)/Datos!E36) -> 2 | F12: =INT((H_MAX-PAL_H)/Datos!F36) -> 2
A13: Capas por peso | B13: u | C13: =INT(KG_MAX/(C11*C8)) -> 4 | D13: =INT(KG_MAX/(D11*D8)) -> 4 | E13: =INT(KG_MAX/(E11*E8)) -> 2 | F13: =INT(KG_MAX/(F11*F8)) -> 2
A14: Capas | B14: u | C14: =MIN(C12,C13) -> 3 | D14: =MIN(D12,D13) -> 3 | E14: =MIN(E12,E13) -> 2 | F14: =MIN(F12,F13) -> 2
A15: Cajas por pallet | B15: u | C15: =C11*C14 -> 60 | D15: =D11*D14 -> 168 | E15: =E11*E14 -> 84 | F15: =F11*F14 -> 60
A16: Matafuegos por pallet | B16: u | C16: =C15*C7 -> 360 | D16: =D15*D7 -> 168 | E16: =E15*E7 -> 84 | F16: =F15*F7 -> 60
A17: Peso del pallet | B17: kg | C17: =C15*C8+PAL_TARA -> 804.8 | D17: =D15*D8+PAL_TARA -> 854.84 | E17: =E15*E8+PAL_TARA -> 776.72 | F17: =F15*F8+PAL_TARA -> 1038.8
A18: Alto del pallet | B18: mm | C18: =PAL_H+C14*Datos!C36 -> 1375 | D18: =PAL_H+D14*Datos!D36 -> 1450 | E18: =PAL_H+E14*Datos!E36 -> 1175 | F18: =PAL_H+F14*Datos!F36 -> 1515
A20: 2) CILINDROS VACÍOS (parados, cartón abajo, entre capas y arriba, esquineros y film)
A21: Concepto | B21: Unidad | C21: 1 kg | D21: 2,5 kg | E21: 5 kg | F21: 10 kg | G21: 25 kg | H21: 50 kg | I21: 70 kg | J21: 100 kg
A22: Ø | B22: mm | C22: =Datos!C39 -> 76.2 | D22: =Datos!D39 -> 124 | E22: =Datos!E39 -> 153 | F22: =Datos!F39 -> 181.5 | G22: =Datos!G39 -> 276.5 | H22: =Datos!H39 -> 320 | I22: =Datos!I39 -> 390 | J22: =Datos!J39 -> 390
A23: Alto con tapón | B23: mm | C23: =Datos!C40 -> 297.5 | D23: =Datos!D40 -> 333 | E23: =Datos!E40 -> 414 | F23: =Datos!F40 -> 582 | G23: =Datos!G40 -> 672 | H23: =Datos!H40 -> 858 | I23: =Datos!I40 -> 908 | J23: =Datos!J40 -> 1128
A24: Masa | B24: kg | C24: =Datos!C41 -> 0.76 | D24: =Datos!D41 -> 1.48 | E24: =Datos!E41 -> 2.78 | F24: =Datos!F41 -> 5.48 | G24: =Datos!G41 -> 15.92 | H24: =Datos!H41 -> 23.3 | I24: =Datos!I41 -> 46.86 | J24: =Datos!J41 -> 56.85
A25: Cilindros a lo largo (1.200) | B25: u | C25: =INT(PAL_L/C22) -> 15 | D25: =INT(PAL_L/D22) -> 9 | E25: =INT(PAL_L/E22) -> 7 | F25: =INT(PAL_L/F22) -> 6 | G25: =INT(PAL_L/G22) -> 4 | H25: =INT(PAL_L/H22) -> 3 | I25: =INT(PAL_L/I22) -> 3 | J25: =INT(PAL_L/J22) -> 3
A26: Cilindros a lo ancho (1.000) | B26: u | C26: =INT(PAL_A/C22) -> 13 | D26: =INT(PAL_A/D22) -> 8 | E26: =INT(PAL_A/E22) -> 6 | F26: =INT(PAL_A/F22) -> 5 | G26: =INT(PAL_A/G22) -> 3 | H26: =INT(PAL_A/H22) -> 3 | I26: =INT(PAL_A/I22) -> 2 | J26: =INT(PAL_A/J22) -> 2
A27: Cilindros por capa | B27: u | C27: =C25*C26 -> 195 | D27: =D25*D26 -> 72 | E27: =E25*E26 -> 42 | F27: =F25*F26 -> 30 | G27: =G25*G26 -> 12 | H27: =H25*H26 -> 9 | I27: =I25*I26 -> 6 | J27: =J25*J26 -> 6
A28: Capas por alto | B28: u | C28: =INT((H_MAX-PAL_H-SEP_E)/(C23+SEP_E)) -> 4 | D28: =INT((H_MAX-PAL_H-SEP_E)/(D23+SEP_E)) -> 4 | E28: =INT((H_MAX-PAL_H-SEP_E)/(E23+SEP_E)) -> 3 | F28: =INT((H_MAX-PAL_H-SEP_E)/(F23+SEP_E)) -> 2 | G28: =INT((H_MAX-PAL_H-SEP_E)/(G23+SEP_E)) -> 2 | H28: =INT((H_MAX-PAL_H-SEP_E)/(H23+SEP_E)) -> 1 | I28: =INT((H_MAX-PAL_H-SEP_E)/(I23+SEP_E)) -> 1 | J28: =INT((H_MAX-PAL_H-SEP_E)/(J23+SEP_E)) -> 1
A29: Capas por peso | B29: u | C29: =INT(KG_MAX/(C27*C24)) -> 7 | D29: =INT(KG_MAX/(D27*D24)) -> 10 | E29: =INT(KG_MAX/(E27*E24)) -> 9 | F29: =INT(KG_MAX/(F27*F24)) -> 6 | G29: =INT(KG_MAX/(G27*G24)) -> 5 | H29: =INT(KG_MAX/(H27*H24)) -> 5 | I29: =INT(KG_MAX/(I27*I24)) -> 3 | J29: =INT(KG_MAX/(J27*J24)) -> 3
A30: Capas | B30: u | C30: =MIN(C28,C29) -> 4 | D30: =MIN(D28,D29) -> 4 | E30: =MIN(E28,E29) -> 3 | F30: =MIN(F28,F29) -> 2 | G30: =MIN(G28,G29) -> 2 | H30: =MIN(H28,H29) -> 1 | I30: =MIN(I28,I29) -> 1 | J30: =MIN(J28,J29) -> 1
A31: Cilindros por pallet | B31: u | C31: =C27*C30 -> 780 | D31: =D27*D30 -> 288 | E31: =E27*E30 -> 126 | F31: =F27*F30 -> 60 | G31: =G27*G30 -> 24 | H31: =H27*H30 -> 9 | I31: =I27*I30 -> 6 | J31: =J27*J30 -> 6
A32: Peso del pallet | B32: kg | C32: =C31*C24+PAL_TARA+(C30+1)*SEP_KG -> 630.8 | D32: =D31*D24+PAL_TARA+(D30+1)*SEP_KG -> 464.24 | E32: =E31*E24+PAL_TARA+(E30+1)*SEP_KG -> 387.68 | F32: =F31*F24+PAL_TARA+(F30+1)*SEP_KG -> 365.6 | G32: =G31*G24+PAL_TARA+(G30+1)*SEP_KG -> 418.88 | H32: =H31*H24+PAL_TARA+(H30+1)*SEP_KG -> 245.9 | I32: =I31*I24+PAL_TARA+(I30+1)*SEP_KG -> 317.36 | J32: =J31*J24+PAL_TARA+(J30+1)*SEP_KG -> 377.3
A33: Alto del pallet | B33: mm | C33: =PAL_H+C30*C23+(C30+1)*SEP_E -> 1350 | D33: =PAL_H+D30*D23+(D30+1)*SEP_E -> 1492 | E33: =PAL_H+E30*E23+(E30+1)*SEP_E -> 1399 | F33: =PAL_H+F30*F23+(F30+1)*SEP_E -> 1318 | G33: =PAL_H+G30*G23+(G30+1)*SEP_E -> 1498 | H33: =PAL_H+H30*H23+(H30+1)*SEP_E -> 1009 | I33: =PAL_H+I30*I23+(I30+1)*SEP_E -> 1059 | J33: =PAL_H+J30*J23+(J30+1)*SEP_E -> 1279
A35: 3) CARROS TERMINADOS (sin caja, parados sobre sus ruedas en la Master, atados con cintas)
A36: Concepto | B36: Unidad | G36: 25 kg | H36: 50 kg | I36: 70 kg | J36: 100 kg
A37: Carros por Master | B37: u | G37: =Datos!G46 -> 14 | H37: =Datos!H46 -> 10 | I37: =Datos!I46 -> 7 | J37: =Datos!J46 -> 7
A38: Peso del carro cargado | B38: kg | G38: =Datos!G44 -> 55 | H38: =Datos!H44 -> 100 | I38: =Datos!I44 -> 140 | J38: =Datos!J44 -> 185
A40: Capas por alto: el pallet con la carga no pasa de H_MAX. Capas por peso: la carga no pasa de KG_MAX. Se toma la menor. En los cilindros se suma un cartón de 3 mm por capa más la tapa.

Sheet Stock_PT
A1: STOCK DE PRODUCTO TERMINADO — lo que deja el sobrestock, la seguridad y el pallet en armado
A2: La producción de manuales va más pareja que las ventas (sobrestock): el stock sube en los meses flojos y baja en el pico. Los carros se hacen mes a mes lo que se vende.
A3: ▶ Sección 2: stock máximo y pallets de cada producto. Sección 3: pallets en stock mes a mes.
A5: 1) VENTAS, PRODUCCIÓN Y ACUMULADO DE CADA MES (u)
A6: Ventas | B6: Ene | C6: Feb | D6: Mar | E6: Abr | F6: May | G6: Jun | H6: Jul | I6: Ago | J6: Sep | K6: Oct | L6: Nov | M6: Dic | N6: Año
A7: Nuevo 1 kg (en caja) | B7: =Datos!D7 -> 3848.7167 | C7: =Datos!E7 -> 2886.5375 | D7: =Datos!F7 -> 2565.8111 | E7: =Datos!G7 -> 2405.4479 | F7: =Datos!H7 -> 2245.0847 | G7: =Datos!I7 -> 2245.0847 | H7: =Datos!J7 -> 2405.4479 | I7: =Datos!K7 -> 2405.4479 | ... M7: =Datos!O7 -> 3848.7167 | N7: =SUM(B7:M7) -> 32072.639
A8: Nuevo 2,5 kg (en caja) | B8: =Datos!D8 -> 743.64584 | C8: =Datos!E8 -> 594.91668 | D8: =Datos!F8 -> 632.09897 | E8: =Datos!G8 -> 632.09897 | F8: =Datos!H8 -> 594.91668 | G8: =Datos!I8 -> 557.73438 | H8: =Datos!J8 -> 594.91668 | I8: =Datos!K8 -> 594.91668 | ... M8: =Datos!O8 -> 818.01043 | N8: =SUM(B8:M8) -> 7436.4584
A9: Nuevo 5 kg (en caja) | B9: =Datos!D9 -> 3081.4979 | C9: =Datos!E9 -> 2465.1983 | D9: =Datos!F9 -> 2619.2732 | E9: =Datos!G9 -> 2619.2732 | F9: =Datos!H9 -> 2465.1983 | G9: =Datos!I9 -> 2311.1234 | H9: =Datos!J9 -> 2465.1983 | I9: =Datos!K9 -> 2465.1983 | ... M9: =Datos!O9 -> 3389.6477 | N9: =SUM(B9:M9) -> 30814.979
A10: Nuevo 10 kg (en caja) | B10: =Datos!D10 -> 184.49281 | C10: =Datos!E10 -> 147.59425 | D10: =Datos!F10 -> 156.81889 | E10: =Datos!G10 -> 156.81889 | F10: =Datos!H10 -> 147.59425 | G10: =Datos!I10 -> 138.36961 | H10: =Datos!J10 -> 147.59425 | I10: =Datos!K10 -> 147.59425 | ... M10: =Datos!O10 -> 202.94209 | N10: =SUM(B10:M10) -> 1844.9281
A11: Cilindro 1 kg (manuales) | B11: =Datos!D11 -> 20465.76 | C11: =Datos!E11 -> 15349.32 | D11: =Datos!F11 -> 13643.84 | E11: =Datos!G11 -> 12791.1 | F11: =Datos!H11 -> 11938.36 | G11: =Datos!I11 -> 11938.36 | H11: =Datos!J11 -> 12791.1 | I11: =Datos!K11 -> 12791.1 | ... M11: =Datos!O11 -> 20465.76 | N11: =SUM(B11:M11) -> 170548
A12: Cilindro 2,5 kg (manuales) | B12: =Datos!D12 -> 668.988 | C12: =Datos!E12 -> 535.1904 | D12: =Datos!F12 -> 568.6398 | E12: =Datos!G12 -> 568.6398 | F12: =Datos!H12 -> 535.1904 | G12: =Datos!I12 -> 501.741 | H12: =Datos!J12 -> 535.1904 | I12: =Datos!K12 -> 535.1904 | ... M12: =Datos!O12 -> 735.8868 | N12: =SUM(B12:M12) -> 6689.88
A13: Cilindro 5 kg (manuales) | B13: =Datos!D13 -> 3303.768 | C13: =Datos!E13 -> 2643.0144 | D13: =Datos!F13 -> 2808.2028 | E13: =Datos!G13 -> 2808.2028 | F13: =Datos!H13 -> 2643.0144 | G13: =Datos!I13 -> 2477.826 | H13: =Datos!J13 -> 2643.0144 | I13: =Datos!K13 -> 2643.0144 | ... M13: =Datos!O13 -> 3634.1448 | N13: =SUM(B13:M13) -> 33037.68
A14: Cilindro 10 kg (manuales) | B14: =Datos!D14 -> 201.8 | C14: =Datos!E14 -> 161.44 | D14: =Datos!F14 -> 171.53 | E14: =Datos!G14 -> 171.53 | F14: =Datos!H14 -> 161.44 | G14: =Datos!I14 -> 151.35 | H14: =Datos!J14 -> 161.44 | I14: =Datos!K14 -> 161.44 | ... M14: =Datos!O14 -> 221.98 | N14: =SUM(B14:M14) -> 2018
A15: Carro 25 kg terminado | B15: =Datos!D15 -> 38.561995 | C15: =Datos!E15 -> 34.02529 | D15: =Datos!F15 -> 40.830348 | E15: =Datos!G15 -> 40.830348 | F15: =Datos!H15 -> 40.830348 | G15: =Datos!I15 -> 36.293643 | H15: =Datos!J15 -> 40.830348 | I15: =Datos!K15 -> 40.830348 | ... M15: =Datos!O15 -> 36.293643 | N15: =SUM(B15:M15) -> 453.67053
A16: Carro 50 kg terminado | B16: =Datos!D16 -> 84.82959 | C16: =Datos!E16 -> 74.849638 | D16: =Datos!F16 -> 89.819566 | E16: =Datos!G16 -> 89.819566 | F16: =Datos!H16 -> 89.819566 | G16: =Datos!I16 -> 79.839614 | H16: =Datos!J16 -> 89.819566 | I16: =Datos!K16 -> 89.819566 | ... M16: =Datos!O16 -> 79.839614 | N16: =SUM(B16:M16) -> 997.99517
A17: Carro 70 kg terminado | B17: =Datos!D17 -> 18.513838 | C17: =Datos!E17 -> 16.335739 | D17: =Datos!F17 -> 19.602887 | E17: =Datos!G17 -> 19.602887 | F17: =Datos!H17 -> 19.602887 | G17: =Datos!I17 -> 17.424788 | H17: =Datos!J17 -> 19.602887 | I17: =Datos!K17 -> 19.602887 | ... M17: =Datos!O17 -> 17.424788 | N17: =SUM(B17:M17) -> 217.80986
A18: Carro 100 kg terminado | B18: =Datos!D18 -> 12.342559 | C18: =Datos!E18 -> 10.890493 | D18: =Datos!F18 -> 13.068591 | E18: =Datos!G18 -> 13.068591 | F18: =Datos!H18 -> 13.068591 | G18: =Datos!I18 -> 11.616526 | H18: =Datos!J18 -> 13.068591 | I18: =Datos!K18 -> 13.068591 | ... M18: =Datos!O18 -> 11.616526 | N18: =SUM(B18:M18) -> 145.20657
... A22: Cilindro de carro 100 kg | B22: =Datos!D22 -> 8.6904 | C22: =Datos!E22 -> 7.668 | D22: =Datos!F22 -> 9.2016 | E22: =Datos!G22 -> 9.2016 | F22: =Datos!H22 -> 9.2016 | G22: =Datos!I22 -> 8.1792 | H22: =Datos!J22 -> 9.2016 | I22: =Datos!K22 -> 9.2016 | ... M22: =Datos!O22 -> 8.1792 | N22: =SUM(B22:M22) -> 102.24
A24: Producción | B24: Ene | C24: Feb | D24: Mar | E24: Abr | F24: May | G24: Jun | H24: Jul | I24: Ago | J24: Sep | K24: Oct | L24: Nov | M24: Dic | N24: Año
A25: Nuevo 1 kg (en caja) | B25: =Datos!$P$7*Datos!D$26 -> 2886.5375 | C25: =Datos!$P$7*Datos!E$26 -> 2886.5375 | D25: =Datos!$P$7*Datos!F$26 -> 2565.8111 | E25: =Datos!$P$7*Datos!G$26 -> 2405.4479 | F25: =Datos!$P$7*Datos!H$26 -> 2245.0847 | G25: =Datos!$P$7*Datos!I$26 -> 2245.0847 | H25: =Datos!$P$7*Datos!J$26 -> 2405.4479 | I25: =Datos!$P$7*Datos!K$26 -> 2886.5375 | ... M25: =Datos!$P$7*Datos!O$26 -> 2886.5375 | N25: =SUM(B25:M25) -> 32072.639
A26: Nuevo 2,5 kg (en caja) | B26: =Datos!$P$8*Datos!D$27 -> 669.28126 | C26: =Datos!$P$8*Datos!E$27 -> 594.91668 | D26: =Datos!$P$8*Datos!F$27 -> 632.09897 | E26: =Datos!$P$8*Datos!G$27 -> 632.09897 | F26: =Datos!$P$8*Datos!H$27 -> 594.91668 | G26: =Datos!$P$8*Datos!I$27 -> 557.73438 | H26: =Datos!$P$8*Datos!J$27 -> 594.91668 | I26: =Datos!$P$8*Datos!K$27 -> 594.91668 | ... M26: =Datos!$P$8*Datos!O$27 -> 669.28126 | N26: =SUM(B26:M26) -> 7436.4584
A27: Nuevo 5 kg (en caja) | B27: =Datos!$P$9*Datos!D$28 -> 2773.3481 | C27: =Datos!$P$9*Datos!E$28 -> 2465.1983 | D27: =Datos!$P$9*Datos!F$28 -> 2619.2732 | E27: =Datos!$P$9*Datos!G$28 -> 2619.2732 | F27: =Datos!$P$9*Datos!H$28 -> 2465.1983 | G27: =Datos!$P$9*Datos!I$28 -> 2311.1234 | H27: =Datos!$P$9*Datos!J$28 -> 2465.1983 | I27: =Datos!$P$9*Datos!K$28 -> 2465.1983 | ... M27: =Datos!$P$9*Datos!O$28 -> 2773.3481 | N27: =SUM(B27:M27) -> 30814.979
A28: Nuevo 10 kg (en caja) | B28: =Datos!$P$10*Datos!D$29 -> 166.04353 | C28: =Datos!$P$10*Datos!E$29 -> 147.59425 | D28: =Datos!$P$10*Datos!F$29 -> 156.81889 | E28: =Datos!$P$10*Datos!G$29 -> 156.81889 | F28: =Datos!$P$10*Datos!H$29 -> 147.59425 | G28: =Datos!$P$10*Datos!I$29 -> 138.36961 | H28: =Datos!$P$10*Datos!J$29 -> 147.59425 | I28: =Datos!$P$10*Datos!K$29 -> 147.59425 | ... M28: =Datos!$P$10*Datos!O$29 -> 166.04353 | N28: =SUM(B28:M28) -> 1844.9281
A29: Cilindro 1 kg (manuales) | B29: =Datos!$P$11*Datos!D$26 -> 15349.32 | C29: =Datos!$P$11*Datos!E$26 -> 15349.32 | D29: =Datos!$P$11*Datos!F$26 -> 13643.84 | E29: =Datos!$P$11*Datos!G$26 -> 12791.1 | F29: =Datos!$P$11*Datos!H$26 -> 11938.36 | G29: =Datos!$P$11*Datos!I$26 -> 11938.36 | H29: =Datos!$P$11*Datos!J$26 -> 12791.1 | I29: =Datos!$P$11*Datos!K$26 -> 15349.32 | ... M29: =Datos!$P$11*Datos!O$26 -> 15349.32 | N29: =SUM(B29:M29) -> 170548
A30: Cilindro 2,5 kg (manuales) | B30: =Datos!$P$12*Datos!D$27 -> 602.0892 | C30: =Datos!$P$12*Datos!E$27 -> 535.1904 | D30: =Datos!$P$12*Datos!F$27 -> 568.6398 | E30: =Datos!$P$12*Datos!G$27 -> 568.6398 | F30: =Datos!$P$12*Datos!H$27 -> 535.1904 | G30: =Datos!$P$12*Datos!I$27 -> 501.741 | H30: =Datos!$P$12*Datos!J$27 -> 535.1904 | I30: =Datos!$P$12*Datos!K$27 -> 535.1904 | ... M30: =Datos!$P$12*Datos!O$27 -> 602.0892 | N30: =SUM(B30:M30) -> 6689.88
A31: Cilindro 5 kg (manuales) | B31: =Datos!$P$13*Datos!D$28 -> 2973.3912 | C31: =Datos!$P$13*Datos!E$28 -> 2643.0144 | D31: =Datos!$P$13*Datos!F$28 -> 2808.2028 | E31: =Datos!$P$13*Datos!G$28 -> 2808.2028 | F31: =Datos!$P$13*Datos!H$28 -> 2643.0144 | G31: =Datos!$P$13*Datos!I$28 -> 2477.826 | H31: =Datos!$P$13*Datos!J$28 -> 2643.0144 | I31: =Datos!$P$13*Datos!K$28 -> 2643.0144 | ... M31: =Datos!$P$13*Datos!O$28 -> 2973.3912 | N31: =SUM(B31:M31) -> 33037.68
A32: Cilindro 10 kg (manuales) | B32: =Datos!$P$14*Datos!D$29 -> 181.62 | C32: =Datos!$P$14*Datos!E$29 -> 161.44 | D32: =Datos!$P$14*Datos!F$29 -> 171.53 | E32: =Datos!$P$14*Datos!G$29 -> 171.53 | F32: =Datos!$P$14*Datos!H$29 -> 161.44 | G32: =Datos!$P$14*Datos!I$29 -> 151.35 | H32: =Datos!$P$14*Datos!J$29 -> 161.44 | I32: =Datos!$P$14*Datos!K$29 -> 161.44 | ... M32: =Datos!$P$14*Datos!O$29 -> 181.62 | N32: =SUM(B32:M32) -> 2018
A33: Carro 25 kg terminado | B33: =B15 -> 38.561995 | C33: =C15 -> 34.02529 | D33: =D15 -> 40.830348 | E33: =E15 -> 40.830348 | F33: =F15 -> 40.830348 | G33: =G15 -> 36.293643 | H33: =H15 -> 40.830348 | I33: =I15 -> 40.830348 | ... M33: =M15 -> 36.293643 | N33: =SUM(B33:M33) -> 453.67053
A34: Carro 50 kg terminado | B34: =B16 -> 84.82959 | C34: =C16 -> 74.849638 | D34: =D16 -> 89.819566 | E34: =E16 -> 89.819566 | F34: =F16 -> 89.819566 | G34: =G16 -> 79.839614 | H34: =H16 -> 89.819566 | I34: =I16 -> 89.819566 | ... M34: =M16 -> 79.839614 | N34: =SUM(B34:M34) -> 997.99517
A35: Carro 70 kg terminado | B35: =B17 -> 18.513838 | C35: =C17 -> 16.335739 | D35: =D17 -> 19.602887 | E35: =E17 -> 19.602887 | F35: =F17 -> 19.602887 | G35: =G17 -> 17.424788 | H35: =H17 -> 19.602887 | I35: =I17 -> 19.602887 | ... M35: =M17 -> 17.424788 | N35: =SUM(B35:M35) -> 217.80986
A36: Carro 100 kg terminado | B36: =B18 -> 12.342559 | C36: =C18 -> 10.890493 | D36: =D18 -> 13.068591 | E36: =E18 -> 13.068591 | F36: =F18 -> 13.068591 | G36: =G18 -> 11.616526 | H36: =H18 -> 13.068591 | I36: =I18 -> 13.068591 | ... M36: =M18 -> 11.616526 | N36: =SUM(B36:M36) -> 145.20657
A37: Cilindro de carro 25 kg | B37: =B19 -> 27.5094 | C37: =C19 -> 24.273 | D37: =D19 -> 29.1276 | E37: =E19 -> 29.1276 | F37: =F19 -> 29.1276 | G37: =G19 -> 25.8912 | H37: =H19 -> 29.1276 | I37: =I19 -> 29.1276 | ... M37: =M19 -> 25.8912 | N37: =SUM(B37:M37) -> 323.64
A38: Cilindro de carro 50 kg | B38: =B20 -> 60.3874 | C38: =C20 -> 53.283 | D38: =D20 -> 63.9396 | E38: =E20 -> 63.9396 | F38: =F20 -> 63.9396 | G38: =G20 -> 56.8352 | H38: =H20 -> 63.9396 | I38: =I20 -> 63.9396 | ... M38: =M20 -> 56.8352 | N38: =SUM(B38:M38) -> 710.44
A39: Cilindro de carro 70 kg | B39: =B21 -> 13.2872 | C39: =C21 -> 11.724 | D39: =D21 -> 14.0688 | E39: =E21 -> 14.0688 | F39: =F21 -> 14.0688 | G39: =G21 -> 12.5056 | H39: =H21 -> 14.0688 | I39: =I21 -> 14.0688 | ... M39: =M21 -> 12.5056 | N39: =SUM(B39:M39) -> 156.32
A40: Cilindro de carro 100 kg | B40: =B22 -> 8.6904 | C40: =C22 -> 7.668 | D40: =D22 -> 9.2016 | E40: =E22 -> 9.2016 | F40: =F22 -> 9.2016 | G40: =G22 -> 8.1792 | H40: =H22 -> 9.2016 | I40: =I22 -> 9.2016 | ... M40: =M22 -> 8.1792 | N40: =SUM(B40:M40) -> 102.24
A42: Acumulado (producción − ventas) | B42: Ene | C42: Feb | D42: Mar | E42: Abr | F42: May | G42: Jun | H42: Jul | I42: Ago | J42: Sep | K42: Oct | L42: Nov | M42: Dic
A43: Nuevo 1 kg (en caja) | B43: =SUM($B25:B25)-SUM($B7:B7) -> -962.17917 | C43: =SUM($B25:C25)-SUM($B7:C7) -> -962.17917 | D43: =SUM($B25:D25)-SUM($B7:D7) -> -962.17917 | E43: =SUM($B25:E25)-SUM($B7:E7) -> -962.17917 | F43: =SUM($B25:F25)-SUM($B7:F7) -> -962.17917 | G43: =SUM($B25:G25)-SUM($B7:G7) -> -962.17917 | H43: =SUM($B25:H25)-SUM($B7:H7) -> -962.17917 | I43: =SUM($B25:I25)-SUM($B7:I7) -> -481.08959 | ... M43: =SUM($B25:M25)-SUM($B7:M7) -> 0
A44: Nuevo 2,5 kg (en caja) | B44: =SUM($B26:B26)-SUM($B8:B8) -> -74.364584 | C44: =SUM($B26:C26)-SUM($B8:C8) -> -74.364584 | D44: =SUM($B26:D26)-SUM($B8:D8) -> -74.364584 | E44: =SUM($B26:E26)-SUM($B8:E8) -> -74.364585 | F44: =SUM($B26:F26)-SUM($B8:F8) -> -74.364584 | G44: =SUM($B26:G26)-SUM($B8:G8) -> -74.364584 | H44: =SUM($B26:H26)-SUM($B8:H8) -> -74.364584 | I44: =SUM($B26:I26)-SUM($B8:I8) -> -74.364584 | ... M44: =SUM($B26:M26)-SUM($B8:M8) -> 0
A45: Nuevo 5 kg (en caja) | B45: =SUM($B27:B27)-SUM($B9:B9) -> -308.14979 | C45: =SUM($B27:C27)-SUM($B9:C9) -> -308.14979 | D45: =SUM($B27:D27)-SUM($B9:D9) -> -308.14979 | E45: =SUM($B27:E27)-SUM($B9:E9) -> -308.14979 | F45: =SUM($B27:F27)-SUM($B9:F9) -> -308.14979 | G45: =SUM($B27:G27)-SUM($B9:G9) -> -308.14979 | H45: =SUM($B27:H27)-SUM($B9:H9) -> -308.14979 | I45: =SUM($B27:I27)-SUM($B9:I9) -> -308.14979 | ... M45: =SUM($B27:M27)-SUM($B9:M9) -> 0
A46: Nuevo 10 kg (en caja) | B46: =SUM($B28:B28)-SUM($B10:B10) -> -18.449281 | C46: =SUM($B28:C28)-SUM($B10:C10) -> -18.449281 | D46: =SUM($B28:D28)-SUM($B10:D10) -> -18.449281 | E46: =SUM($B28:E28)-SUM($B10:E10) -> -18.449281 | F46: =SUM($B28:F28)-SUM($B10:F10) -> -18.449281 | G46: =SUM($B28:G28)-SUM($B10:G10) -> -18.449281 | H46: =SUM($B28:H28)-SUM($B10:H10) -> -18.449281 | I46: =SUM($B28:I28)-SUM($B10:I10) -> -18.449281 | ... M46: =SUM($B28:M28)-SUM($B10:M10) -> 0
...

Sheet Almacen_PT
A1: ALMACÉN DE PT — rack de pallets, carros en el piso, andén y la rama de pintura
A2: Rack selectivo de 3 niveles con los pallets de nuevos y cilindros; los carros terminados en el piso; el andén con lo que sale en el día.
A3: ▶ Fila 44: superficie total.
A5: 1) RACK DE PALLETS (nuevos en caja y cilindros)
A6: Concepto | B6: Valor | C6: Unidad | D6: Cómo sale
A7: Pallets en el rack | B7: =Stock_PT!L79+Stock_PT!L80+Stock_PT!L82 -> 85 | C7: pallets | D7: Stock_PT, sección 2
A8: Pallet más alto | B8: =MAX(Stock_PT!N63:N70,Stock_PT!N75:N78) -> 1515 | C8: mm
A9: Paso entre largueros | B9: =B8+HOLG_V+LARG -> 1765 | C9: mm | D9: Pallet + holgura + larguero
A10: Altura del último larguero | B10: =(NIV_PT-1)*B9/1000 -> 3.53 | C10: m
A11: Altura a la que tiene que levantar el autoelevador | B11: =B10+MARGEN_ELEV -> 3.73 | C11: m
A12: Mástil que hace falta | B12: =IF(B11<=ELEV_STD,"Estándar ("&ELEV_STD&" m)",IF(B11<=ELEV_ALT,"Mástil de "&SUBSTITUTE(TEXT(ELEV_ALT,"0.0"),".",",")&" m","No alcanza: bajar un nivel")) -> Mástil de 4,5 m
A13: Pallet más pesado | B13: =MAX(Stock_PT!M63:M70,Stock_PT!M75:M78) -> 1038.8 | C13: kg
A14: Pallets que van solo en el piso (más de la mitad de la carga del nivel) | B14: =SUMPRODUCT((Stock_PT!M63:M70>KG_NIV/POS_NIV)*Stock_PT!L63:L70)+SUMPRODUCT((Stock_PT!M75:M78>KG_NIV/POS_NIV)*Stock_PT!L75:L78) -> 3 | C14: pallets | D14: Los del 10 kg en caja (1.039 kg): dos juntos pasan los 2.000 kg del nivel
A15: Módulos de rack | B15: =MAX(ROUNDUP(B7/(POS_NIV*NIV_PT),0),ROUNDUP(B14/POS_NIV,0)) -> 15 | C15: u | D15: Lugares ÷ 6, y los pesados en el piso
A16: Lugares que da el rack | B16: =B15*POS_NIV*NIV_PT -> 90 | C16: u
A17: Alto del bastidor | B17: =CEILING(B10+0.4,0.5) -> 4 | C17: m | D17: Último larguero + guía para el pallet de arriba
A18: m² del rack con media calle | B18: =B15*MOD_FRENTE*(MOD_FONDO+CALLE/2) -> 124.2 | C18: m²
A20: 2) CARROS TERMINADOS EN EL PISO (5 días de venta del mes pico)
A21: Modelo | B21: Carros | C21: m² por carro | D21: Cómo sale
A22: 25 kg | B22: =Stock_PT!L71 -> 11 | C22: =Datos!G42*Datos!G43/1000000*F_CIRC -> 0.462 | D22: Largo × ancho del carro × F_CIRC
A23: 50 kg | B23: =Stock_PT!L72 -> 23 | C23: =Datos!H42*Datos!H43/1000000*F_CIRC -> 0.588 | D23: Largo × ancho del carro × F_CIRC
A24: 70 kg | B24: =Stock_PT!L73 -> 5 | C24: =Datos!I42*Datos!I43/1000000*F_CIRC -> 0.784 | D24: Largo × ancho del carro × F_CIRC
A25: 100 kg | B25: =Stock_PT!L74 -> 4 | C25: =Datos!J42*Datos!J43/1000000*F_CIRC -> 0.84 | D25: Largo × ancho del carro × F_CIRC
A26: m² de carros terminados | B26: =SUMPRODUCT(B22:B25,C22:C25) -> 25.886
A28: 3) ANDÉN (lo que sale en el día: un sider y un camión chico a la vez)
A29: Concepto | B29: Valor | C29: Unidad | D29: Cómo sale
A30: Lugares de pallet en el andén | B30: =Datos!B51+Datos!B50 -> 20 | C30: pallets
A31: m² del andén | B31: =B30*PAL_L*PAL_A/1000000*F_CIRC -> 33.6 | C31: m²
A33: 4) RAMA DE PINTURA Y CARROS DE MANIPULACIÓN
A34: Concepto | B34: Valor | C34: Unidad | D34: Cómo sale
A35: Espera del pintor (recipientes parados con taco) | B35: =Pintura!B33 -> 17.71 | C35: m² | D35: Pintura B33
A36: Pintados esperando la carga | B36: =Pintura!B34 -> 17.71 | C36: m² | D36: Pintura B34
A37: Carros de manipulación estacionados | B37: =Carro_manip!B27 -> 11.466 | C37: m² | D37: Carro_manip B27
A38: m² de la rama de pintura | B38: =SUM(B35:B37) -> 46.886
A40: 5) TOTAL
A41: Concepto | B41: Ahora | C41: Antes | D41: Nota
A42: Almacén de PT (rack + carros + andén) | B42: =B18+B26+B31 -> 183.686 | C42: =Datos!B57+Datos!B58 -> 173.22 | D42: Antes = manuales y cilindros (122,1) + carros liberados (51,1) del balanceo; sin reventa ni sustitutos
A43: Rama de pintura (espera, pintados, carros de manipulación) | B43: =B38 -> 46.886 | D43: En el balanceo está en los pulmones de carros
A44: Total | B44: =B42+B43 -> 230.572

Sheet Despacho
A1: DESPACHO — qué camión, cuántos por viaje y cada cuánto sale
A2: Vehículos propios. Nuevos en caja en el camión chico, cilindros en el sider, carros terminados y la pintura en la Master con rampa.
A3: ▶ Sección 2: viajes por semana en el pico, días fijos y vehículos que hacen falta.
A5: 1) MES A MES
A6: Concepto | B6: Ene | C6: Feb | D6: Mar | E6: Abr | F6: May | G6: Jun | H6: Jul | I6: Ago | J6: Sep | K6: Oct | L6: Nov | M6: Dic | N6: Año | O6: Pico
A7: Camión chico · nuevos en caja: pallets | B7: =SUMPRODUCT(Stock_PT!B7:B10/Stock_PT!$K$63:$K$66) -> 54.876722 | C7: =SUMPRODUCT(Stock_PT!C7:C10/Stock_PT!$K$63:$K$66) -> 43.366833 | D7: =SUMPRODUCT(Stock_PT!D7:D10/Stock_PT!$K$63:$K$66) -> 44.685219 | E7: =SUMPRODUCT(Stock_PT!E7:E10/Stock_PT!$K$63:$K$66) -> 44.239765 | F7: =SUMPRODUCT(Stock_PT!F7:F10/Stock_PT!$K$63:$K$66) -> 41.58502 | G7: =SUMPRODUCT(Stock_PT!G7:G10/Stock_PT!$K$63:$K$66) -> 39.375728 | H7: =SUMPRODUCT(Stock_PT!H7:H10/Stock_PT!$K$63:$K$66) -> 42.030473 | I7: =SUMPRODUCT(Stock_PT!I7:I10/Stock_PT!$K$63:$K$66) -> 42.030473 | ... M7: =SUMPRODUCT(Stock_PT!M7:M10/Stock_PT!$K$63:$K$66) -> 59.295306 | N7: =SUM(B7:M7) -> 530.94908 | O7: =MAX(B7:M7) -> 59.295306
A8: Camión chico · nuevos en caja: kg | B8: =SUMPRODUCT(Stock_PT!B7:B10/Stock_PT!$K$63:$K$66*Stock_PT!$M$63:$M$66) -> 44075.707 | C8: =SUMPRODUCT(Stock_PT!C7:C10/Stock_PT!$K$63:$K$66*Stock_PT!$M$63:$M$66) -> 34830.365 | D8: =SUMPRODUCT(Stock_PT!D7:D10/Stock_PT!$K$63:$K$66*Stock_PT!$M$63:$M$66) -> 35886.947 | E8: =SUMPRODUCT(Stock_PT!E7:E10/Stock_PT!$K$63:$K$66*Stock_PT!$M$63:$M$66) -> 35528.447 | F8: =SUMPRODUCT(Stock_PT!F7:F10/Stock_PT!$K$63:$K$66*Stock_PT!$M$63:$M$66) -> 33396.361 | G8: =SUMPRODUCT(Stock_PT!G7:G10/Stock_PT!$K$63:$K$66*Stock_PT!$M$63:$M$66) -> 31622.777 | H8: =SUMPRODUCT(Stock_PT!H7:H10/Stock_PT!$K$63:$K$66*Stock_PT!$M$63:$M$66) -> 33754.862 | I8: =SUMPRODUCT(Stock_PT!I7:I10/Stock_PT!$K$63:$K$66*Stock_PT!$M$63:$M$66) -> 33754.862 | ... M8: =SUMPRODUCT(Stock_PT!M7:M10/Stock_PT!$K$63:$K$66*Stock_PT!$M$63:$M$66) -> 47622.876 | N8: =SUM(B8:M8) -> 426417.04 | O8: =MAX(B8:M8) -> 47622.876
A9: Camión chico: viajes | B9: =MAX(B7/Datos!$B$50,B8/Datos!$C$50) -> 9.1461203 | C9: =MAX(C7/Datos!$B$50,C8/Datos!$C$50) -> 7.2278056 | D9: =MAX(D7/Datos!$B$50,D8/Datos!$C$50) -> 7.4475365 | E9: =MAX(E7/Datos!$B$50,E8/Datos!$C$50) -> 7.3732942 | F9: =MAX(F7/Datos!$B$50,F8/Datos!$C$50) -> 6.9308367 | G9: =MAX(G7/Datos!$B$50,G8/Datos!$C$50) -> 6.5626213 | H9: =MAX(H7/Datos!$B$50,H8/Datos!$C$50) -> 7.0050789 | I9: =MAX(I7/Datos!$B$50,I8/Datos!$C$50) -> 7.0050789 | ... M9: =MAX(M7/Datos!$B$50,M8/Datos!$C$50) -> 9.882551 | N9: =SUM(B9:M9) -> 88.491514 | O9: =MAX(B9:M9) -> 9.882551
A11: Sider · cilindros (manuales y de carro): pallets | B11: =SUMPRODUCT(Stock_PT!B11:B14/Stock_PT!$K$67:$K$70)+SUMPRODUCT(Stock_PT!B19:B22/Stock_PT!$K$75:$K$78) -> 69.663613 | C11: =SUMPRODUCT(Stock_PT!C11:C14/Stock_PT!$K$67:$K$70)+SUMPRODUCT(Stock_PT!C19:C22/Stock_PT!$K$75:$K$78) -> 55.367595 | D11: =SUMPRODUCT(Stock_PT!D11:D14/Stock_PT!$K$67:$K$70)+SUMPRODUCT(Stock_PT!D19:D22/Stock_PT!$K$75:$K$78) -> 56.809153 | E11: =SUMPRODUCT(Stock_PT!E11:E14/Stock_PT!$K$67:$K$70)+SUMPRODUCT(Stock_PT!E19:E22/Stock_PT!$K$75:$K$78) -> 55.715897 | F11: =SUMPRODUCT(Stock_PT!F11:F14/Stock_PT!$K$67:$K$70)+SUMPRODUCT(Stock_PT!F19:F22/Stock_PT!$K$75:$K$78) -> 53.027311 | G11: =SUMPRODUCT(Stock_PT!G11:G14/Stock_PT!$K$67:$K$70)+SUMPRODUCT(Stock_PT!G19:G22/Stock_PT!$K$75:$K$78) -> 50.076821 | H11: =SUMPRODUCT(Stock_PT!H11:H14/Stock_PT!$K$67:$K$70)+SUMPRODUCT(Stock_PT!H19:H22/Stock_PT!$K$75:$K$78) -> 54.120568 | I11: =SUMPRODUCT(Stock_PT!I11:I14/Stock_PT!$K$67:$K$70)+SUMPRODUCT(Stock_PT!I19:I22/Stock_PT!$K$75:$K$78) -> 54.120568 | ... M11: =SUMPRODUCT(Stock_PT!M11:M14/Stock_PT!$K$67:$K$70)+SUMPRODUCT(Stock_PT!M19:M22/Stock_PT!$K$75:$K$78) -> 72.176691 | N11: =SUM(B11:M11) -> 673.23329 | O11: =MAX(B11:M11) -> 72.176691
A12: Sider · cilindros: kg | B12: =SUMPRODUCT(Stock_PT!B11:B14/Stock_PT!$K$67:$K$70*Stock_PT!$M$67:$M$70)+SUMPRODUCT(Stock_PT!B19:B22/Stock_PT!$K$75:$K$78*Stock_PT!$M$75:$M$78) -> 32403.485 | C12: =SUMPRODUCT(Stock_PT!C11:C14/Stock_PT!$K$67:$K$70*Stock_PT!$M$67:$M$70)+SUMPRODUCT(Stock_PT!C19:C22/Stock_PT!$K$75:$K$78*Stock_PT!$M$75:$M$78) -> 25373.535 | D12: =SUMPRODUCT(Stock_PT!D11:D14/Stock_PT!$K$67:$K$70*Stock_PT!$M$67:$M$70)+SUMPRODUCT(Stock_PT!D19:D22/Stock_PT!$K$75:$K$78*Stock_PT!$M$75:$M$78) -> 25214.292 | E12: =SUMPRODUCT(Stock_PT!E11:E14/Stock_PT!$K$67:$K$70*Stock_PT!$M$67:$M$70)+SUMPRODUCT(Stock_PT!E19:E22/Stock_PT!$K$75:$K$78*Stock_PT!$M$75:$M$78) -> 24524.666 | F12: =SUMPRODUCT(Stock_PT!F11:F14/Stock_PT!$K$67:$K$70*Stock_PT!$M$67:$M$70)+SUMPRODUCT(Stock_PT!F19:F22/Stock_PT!$K$75:$K$78*Stock_PT!$M$75:$M$78) -> 23211.383 | G12: =SUMPRODUCT(Stock_PT!G11:G14/Stock_PT!$K$67:$K$70*Stock_PT!$M$67:$M$70)+SUMPRODUCT(Stock_PT!G19:G22/Stock_PT!$K$75:$K$78*Stock_PT!$M$75:$M$78) -> 22190.159 | H12: =SUMPRODUCT(Stock_PT!H11:H14/Stock_PT!$K$67:$K$70*Stock_PT!$M$67:$M$70)+SUMPRODUCT(Stock_PT!H19:H22/Stock_PT!$K$75:$K$78*Stock_PT!$M$75:$M$78) -> 23901.01 | I12: =SUMPRODUCT(Stock_PT!I11:I14/Stock_PT!$K$67:$K$70*Stock_PT!$M$67:$M$70)+SUMPRODUCT(Stock_PT!I19:I22/Stock_PT!$K$75:$K$78*Stock_PT!$M$75:$M$78) -> 23901.01 | ... M12: =SUMPRODUCT(Stock_PT!M11:M14/Stock_PT!$K$67:$K$70*Stock_PT!$M$67:$M$70)+SUMPRODUCT(Stock_PT!M19:M22/Stock_PT!$K$75:$K$78*Stock_PT!$M$75:$M$78) -> 33452.013 | N12: =SUM(B12:M12) -> 302413.34 | O12: =MAX(B12:M12) -> 33452.013
A13: Sider: viajes | B13: =MAX(B11/Datos!$B$51,B12/Datos!$C$51) -> 4.9759723 | C13: =MAX(C11/Datos!$B$51,C12/Datos!$C$51) -> 3.9548282 | D13: =MAX(D11/Datos!$B$51,D12/Datos!$C$51) -> 4.0577967 | E13: =MAX(E11/Datos!$B$51,E12/Datos!$C$51) -> 3.9797069 | F13: =MAX(F11/Datos!$B$51,F12/Datos!$C$51) -> 3.7876651 | G13: =MAX(G11/Datos!$B$51,G12/Datos!$C$51) -> 3.5769158 | H13: =MAX(H11/Datos!$B$51,H12/Datos!$C$51) -> 3.8657548 | I13: =MAX(I11/Datos!$B$51,I12/Datos!$C$51) -> 3.8657548 | ... M13: =MAX(M11/Datos!$B$51,M12/Datos!$C$51) -> 5.1554779 | N13: =SUM(B13:M13) -> 48.088092 | O13: =MAX(B13:M13) -> 5.1554779
A15: Master · carros terminados: cargas | B15: =SUMPRODUCT(Stock_PT!B15:B18/Stock_PT!$K$71:$K$74) -> 15.645444 | C15: =SUMPRODUCT(Stock_PT!C15:C18/Stock_PT!$K$71:$K$74) -> 13.804803 | D15: =SUMPRODUCT(Stock_PT!D15:D18/Stock_PT!$K$71:$K$74) -> 16.565764 | E15: =SUMPRODUCT(Stock_PT!E15:E18/Stock_PT!$K$71:$K$74) -> 16.565764 | F15: =SUMPRODUCT(Stock_PT!F15:F18/Stock_PT!$K$71:$K$74) -> 16.565764 | G15: =SUMPRODUCT(Stock_PT!G15:G18/Stock_PT!$K$71:$K$74) -> 14.725124 | H15: =SUMPRODUCT(Stock_PT!H15:H18/Stock_PT!$K$71:$K$74) -> 16.565764 | I15: =SUMPRODUCT(Stock_PT!I15:I18/Stock_PT!$K$71:$K$74) -> 16.565764 | ... M15: =SUMPRODUCT(Stock_PT!M15:M18/Stock_PT!$K$71:$K$74) -> 14.725124 | N15: =SUM(B15:M15) -> 184.06404 | O15: =MAX(B15:M15) -> 16.565764
A16: Master · carros terminados: kg | B16: =Stock_PT!B15*Datos!$G$44+Stock_PT!B16*Datos!$H$44+Stock_PT!B17*Datos!$I$44+Stock_PT!B18*Datos!$J$44 -> 15479.179 | C16: =Stock_PT!C15*Datos!$G$44+Stock_PT!C16*Datos!$H$44+Stock_PT!C17*Datos!$I$44+Stock_PT!C18*Datos!$J$44 -> 13658.099 | D16: =Stock_PT!D15*Datos!$G$44+Stock_PT!D16*Datos!$H$44+Stock_PT!D17*Datos!$I$44+Stock_PT!D18*Datos!$J$44 -> 16389.719 | E16: =Stock_PT!E15*Datos!$G$44+Stock_PT!E16*Datos!$H$44+Stock_PT!E17*Datos!$I$44+Stock_PT!E18*Datos!$J$44 -> 16389.719 | F16: =Stock_PT!F15*Datos!$G$44+Stock_PT!F16*Datos!$H$44+Stock_PT!F17*Datos!$I$44+Stock_PT!F18*Datos!$J$44 -> 16389.719 | G16: =Stock_PT!G15*Datos!$G$44+Stock_PT!G16*Datos!$H$44+Stock_PT!G17*Datos!$I$44+Stock_PT!G18*Datos!$J$44 -> 14568.639 | H16: =Stock_PT!H15*Datos!$G$44+Stock_PT!H16*Datos!$H$44+Stock_PT!H17*Datos!$I$44+Stock_PT!H18*Datos!$J$44 -> 16389.719 | I16: =Stock_PT!I15*Datos!$G$44+Stock_PT!I16*Datos!$H$44+Stock_PT!I17*Datos!$I$44+Stock_PT!I18*Datos!$J$44 -> 16389.719 | ... M16: =Stock_PT!M15*Datos!$G$44+Stock_PT!M16*Datos!$H$44+Stock_PT!M17*Datos!$I$44+Stock_PT!M18*Datos!$J$44 -> 14568.639 | N16: =SUM(B16:M16) -> 182107.99 | O16: =MAX(B16:M16) -> 16389.719
A17: Master a clientes: viajes | B17: =MAX(B15,B16/Datos!$C$52) -> 15.645444 | C17: =MAX(C15,C16/Datos!$C$52) -> 13.804803 | D17: =MAX(D15,D16/Datos!$C$52) -> 16.565764 | E17: =MAX(E15,E16/Datos!$C$52) -> 16.565764 | F17: =MAX(F15,F16/Datos!$C$52) -> 16.565764 | G17: =MAX(G15,G16/Datos!$C$52) -> 14.725124 | H17: =MAX(H15,H16/Datos!$C$52) -> 16.565764 | I17: =MAX(I15,I16/Datos!$C$52) -> 16.565764 | ... M17: =MAX(M15,M16/Datos!$C$52) -> 14.725124 | N17: =SUM(B17:M17) -> 184.06404 | O17: =MAX(B17:M17) -> 16.565764
A19: Master al pintor: cargas del mes | B19: =(Stock_PT!B33+Stock_PT!B37)/Datos!$G$46+(Stock_PT!B34+Stock_PT!B38)/Datos!$H$46+(Stock_PT!B35+Stock_PT!B39)/Datos!$I$46+(Stock_PT!B36+Stock_PT!B40)/Datos!$J$46 -> 26.788798 | C19: =(Stock_PT!C33+Stock_PT!C37)/Datos!$G$46+(Stock_PT!C34+Stock_PT!C38)/Datos!$H$46+(Stock_PT!C35+Stock_PT!C39)/Datos!$I$46+(Stock_PT!C36+Stock_PT!C40)/Datos!$J$46 -> 23.637175 | D19: =(Stock_PT!D33+Stock_PT!D37)/Datos!$G$46+(Stock_PT!D34+Stock_PT!D38)/Datos!$H$46+(Stock_PT!D35+Stock_PT!D39)/Datos!$I$46+(Stock_PT!D36+Stock_PT!D40)/Datos!$J$46 -> 28.36461 | E19: =(Stock_PT!E33+Stock_PT!E37)/Datos!$G$46+(Stock_PT!E34+Stock_PT!E38)/Datos!$H$46+(Stock_PT!E35+Stock_PT!E39)/Datos!$I$46+(Stock_PT!E36+Stock_PT!E40)/Datos!$J$46 -> 28.36461 | F19: =(Stock_PT!F33+Stock_PT!F37)/Datos!$G$46+(Stock_PT!F34+Stock_PT!F38)/Datos!$H$46+(Stock_PT!F35+Stock_PT!F39)/Datos!$I$46+(Stock_PT!F36+Stock_PT!F40)/Datos!$J$46 -> 28.36461 | G19: =(Stock_PT!G33+Stock_PT!G37)/Datos!$G$46+(Stock_PT!G34+Stock_PT!G38)/Datos!$H$46+(Stock_PT!G35+Stock_PT!G39)/Datos!$I$46+(Stock_PT!G36+Stock_PT!G40)/Datos!$J$46 -> 25.212986 | H19: =(Stock_PT!H33+Stock_PT!H37)/Datos!$G$46+(Stock_PT!H34+Stock_PT!H38)/Datos!$H$46+(Stock_PT!H35+Stock_PT!H39)/Datos!$I$46+(Stock_PT!H36+Stock_PT!H40)/Datos!$J$46 -> 28.36461 | I19: =(Stock_PT!I33+Stock_PT!I37)/Datos!$G$46+(Stock_PT!I34+Stock_PT!I38)/Datos!$H$46+(Stock_PT!I35+Stock_PT!I39)/Datos!$I$46+(Stock_PT!I36+Stock_PT!I40)/Datos!$J$46 -> 28.36461 | ... M19: =(Stock_PT!M33+Stock_PT!M37)/Datos!$G$46+(Stock_PT!M34+Stock_PT!M38)/Datos!$H$46+(Stock_PT!M35+Stock_PT!M39)/Datos!$I$46+(Stock_PT!M36+Stock_PT!M40)/Datos!$J$46 -> 25.212986 | N19: =SUM(B19:M19) -> 315.16233 | O19: =MAX(B19:M19) -> 28.36461
A20: Master al pintor: viajes (ida y vuelta) | B20: =ROUNDUP(B19/DIAS*DIAS_PINT,0)*DIAS/DIAS_PINT -> 30 | C20: =ROUNDUP(C19/DIAS*DIAS_PINT,0)*DIAS/DIAS_PINT -> 30 | D20: =ROUNDUP(D19/DIAS*DIAS_PINT,0)*DIAS/DIAS_PINT -> 30 | E20: =ROUNDUP(E19/DIAS*DIAS_PINT,0)*DIAS/DIAS_PINT -> 30 | F20: =ROUNDUP(F19/DIAS*DIAS_PINT,0)*DIAS/DIAS_PINT -> 30 | G20: =ROUNDUP(G19/DIAS*DIAS_PINT,0)*DIAS/DIAS_PINT -> 30 | H20: =ROUNDUP(H19/DIAS*DIAS_PINT,0)*DIAS/DIAS_PINT -> 30 | I20: =ROUNDUP(I19/DIAS*DIAS_PINT,0)*DIAS/DIAS_PINT -> 30 | ... M20: =ROUNDUP(M19/DIAS*DIAS_PINT,0)*DIAS/DIAS_PINT -> 30 | N20: =SUM(B20:M20) -> 360 | O20: =MAX(B20:M20) -> 30
A23: 2) VIAJES POR SEMANA EN EL MES PICO, DÍAS FIJOS Y VEHÍCULOS
A24: Vehículo · qué lleva | B24: Viajes por semana (pico) | C24: Salidas por semana | D24: Qué días | E24: Horas por viaje | F24: Horas por semana | G24: Vehículos | H24: Uso
A25: Camión chico · nuevos en caja | B25: =O9/(DIAS/5) -> 2.4706377 | C25: =ROUNDUP(B25,0) -> 3 | D25: =IF(C25=0,"—",CHOOSE(MIN(C25,5),"Miércoles","Martes y jueves","Lunes, miércoles y viernes","Lunes a jueves","Lunes a viernes")) -> Lunes, miércoles y viernes | E25: =H_CHICO -> 4 | F25: =B25*E25 -> 9.882551 | G25: =MAX(1,ROUNDUP(F25/(H_DIA*5),0)) -> 1 | H25: =F25/(G25*H_DIA*5) -> 0.24706377
A26: Sider · cilindros de manuales y de carro | B26: =O13/(DIAS/5) -> 1.2888695 | C26: =ROUNDUP(B26,0) -> 2 | D26: =IF(C26=0,"—",CHOOSE(MIN(C26,5),"Miércoles","Martes y jueves","Lunes, miércoles y viernes","Lunes a jueves","Lunes a viernes")) -> Martes y jueves | E26: =H_SIDER -> 6 | F26: =B26*E26 -> 7.7332169 | G26: =MAX(1,ROUNDUP(F26/(H_DIA*5),0)) -> 1 | H26: =F26/(G26*H_DIA*5) -> 0.19333042
A27: Master · carros terminados a clientes | B27: =O17/(DIAS/5) -> 4.141441 | C27: =ROUNDUP(B27,0) -> 5 | D27: =IF(C27=0,"—",CHOOSE(MIN(C27,5),"Miércoles","Martes y jueves","Lunes, miércoles y viernes","Lunes a jueves","Lunes a viernes")) -> Lunes a viernes | E27: =H_MCLI -> 4 | F27: =B27*E27 -> 16.565764
A28: Master · pintor (crudos de ida, pintados de vuelta) | B28: =O20/(DIAS/5) -> 7.5 | C28: =5/DIAS_PINT -> 2.5 | D28: ="Cada "&DIAS_PINT&" días hábiles, "&Pintura!B27&" viajes" -> Cada 2 días hábiles, 3 viajes | E28: =H_MPINT -> 2.5 | F28: =B28*E28 -> 18.75
A29: Master · total (clientes + pintor) | F29: =F27+F28 -> 35.315764 | G29: =MAX(1,ROUNDUP(F29/(H_DIA*5),0)) -> 1 | H29: =F29/(G29*H_DIA*5) -> 0.8828941
A31: Los pedidos se juntan hasta el día fijo de su vehículo ("se van entregando a medida"). Camión chico y sider salen en días distintos para no llenar el andén.
A32: Horas por viaje: supuestos (no hay distancias a clientes ni al pintor). Si cambian, se corrigen en Parametros sección 6.

Sheet Pintura
A1: RAMA INTERMEDIA: CARROS A LA PINTURA TERCERIZADA
A2: Recipientes de carro (terminados y cilindros que se venden) con los accesorios soldados, probados y secos. Van sin ruedas, atados en la Master; vuelven pintados en 3 días hábiles.
A3: ▶ Sección 2: cada cuántos días conviene mandar. Sección 3: lo que queda en planta y afuera.
A5: 1) CUÁNTOS RECIPIENTES VAN A PINTAR (mes pico de carros)
A6: Modelo | B6: Recipientes del mes pico (term. + cil.) | C6: Por día | D6: Por Master | E6: Cargas de Master por día | F6: kg por día (con accesorios) | G6: Largo (mm) | H6: Ancho (mm) | I6: m² en el piso (con circulación)
A7: 25 kg | B7: {=INDEX(Stock_PT!$B$33:$M$33,1,MES_P)+INDEX(Stock_PT!$B$37:$M$37,1,MES_P)} -> 69.957948 | C7: =B7/DIAS -> 3.4978974 | D7: =Datos!G46 -> 14 | E7: =C7/D7 -> 0.24984981 | F7: =C7*Datos!G45 -> 66.460051 | G7: =Datos!G42 -> 600 | H7: =Datos!G43 -> 550 | I7: =G7*H7/1000000*F_CIRC -> 0.462
A8: 50 kg | B8: {=INDEX(Stock_PT!$B$34:$M$34,1,MES_P)+INDEX(Stock_PT!$B$38:$M$38,1,MES_P)} -> 153.75917 | C8: =B8/DIAS -> 7.6879583 | D8: =Datos!H46 -> 10 | E8: =C8/D8 -> 0.76879583 | F8: =C8*Datos!H45 -> 199.88692 | G8: =Datos!H42 -> 700 | H8: =Datos!H43 -> 600 | I8: =G8*H8/1000000*F_CIRC -> 0.588
A9: 70 kg | B9: {=INDEX(Stock_PT!$B$35:$M$35,1,MES_P)+INDEX(Stock_PT!$B$39:$M$39,1,MES_P)} -> 33.671687 | C9: =B9/DIAS -> 1.6835844 | D9: =Datos!I46 -> 7 | E9: =C9/D9 -> 0.24051205 | F9: =C9*Datos!I45 -> 85.862802 | G9: =Datos!I42 -> 800 | H9: =Datos!I43 -> 700 | I9: =G9*H9/1000000*F_CIRC -> 0.784
A10: 100 kg | B10: {=INDEX(Stock_PT!$B$36:$M$36,1,MES_P)+INDEX(Stock_PT!$B$40:$M$40,1,MES_P)} -> 22.270191 | C10: =B10/DIAS -> 1.1135096 | D10: =Datos!J46 -> 7 | E10: =C10/D10 -> 0.1590728 | F10: =C10*Datos!J45 -> 67.924084 | G10: =Datos!J42 -> 800 | H10: =Datos!J43 -> 750 | I10: =G10*H10/1000000*F_CIRC -> 0.84
A11: Total | B11: =SUM(B7:B10) -> 279.65899 | C11: =SUM(C7:C10) -> 13.98295 | E11: =SUM(E7:E10) -> 1.4182305 | F11: =SUM(F7:F10) -> 420.13385 | I11: =SUMPRODUCT(C7:C10,I7:I10)/C11 -> 0.60014707 | J11: m² promedio
A13: Recipientes de carros por mes | B13: =SUM(Stock_PT!B33:B40) -> 264.12238 | C13: =SUM(Stock_PT!C33:C40) -> 233.04916 | D13: =SUM(Stock_PT!D33:D40) -> 279.65899 | E13: =SUM(Stock_PT!E33:E40) -> 279.65899 | F13: =SUM(Stock_PT!F33:F40) -> 279.65899 | G13: =SUM(Stock_PT!G33:G40) -> 248.58577 | H13: =SUM(Stock_PT!H33:H40) -> 279.65899 | I13: =SUM(Stock_PT!I33:I40) -> 279.65899 | ... M13: =SUM(Stock_PT!M33:M40) -> 248.58577
A14: Mes pico de carros | B14: =MATCH(MAX(B13:M13),B13:M13,0) -> 3 | C14: {=INDEX({"Ene","Feb","Mar","Abr","May","Jun","Jul","Ago","Sep","Oct","Nov","Dic"},1,B14)} -> Mar
A16: 2) CADA CUÁNTOS DÍAS CONVIENE MANDAR (la Master va con los crudos y vuelve con los pintados del envío anterior)
A17: Días entre envíos | B17: Recipientes por envío | C17: Cargas de Master por envío | D17: Viajes por envío | E17: Llenado de la Master | F17: Viajes por semana | G17: Espera máxima en planta (días) | H17: Recipientes esperando (máx.) | I17: Recipientes en el pintor | J17: m² de espera | K17: Elegida
A18: 1 | B18: =$C$11*A18 -> 13.98295 | C18: =$E$11*A18 -> 1.4182305 | D18: =ROUNDUP(C18,0) -> 2 | E18: =C18/D18 -> 0.70911524 | F18: =D18*5/A18 -> 10 | G18: =A18 -> 1 | H18: =$C$11*A18 -> 13.98295 | I18: =$C$11*PLAZO_PINT -> 41.948849 | J18: =H18*$I$11 -> 8.3918262 | K18: =IF(A18=DIAS_PINT,"Sí","")
A19: 2 | B19: =$C$11*A19 -> 27.965899 | C19: =$E$11*A19 -> 2.836461 | D19: =ROUNDUP(C19,0) -> 3 | E19: =C19/D19 -> 0.94548699 | F19: =D19*5/A19 -> 7.5 | G19: =A19 -> 2 | H19: =$C$11*A19 -> 27.965899 | I19: =$C$11*PLAZO_PINT -> 41.948849 | J19: =H19*$I$11 -> 16.783652 | K19: =IF(A19=DIAS_PINT,"Sí","") -> Sí
A20: 3 | B20: =$C$11*A20 -> 41.948849 | C20: =$E$11*A20 -> 4.2546915 | D20: =ROUNDUP(C20,0) -> 5 | E20: =C20/D20 -> 0.85093829 | F20: =D20*5/A20 -> 8.3333333 | G20: =A20 -> 3 | H20: =$C$11*A20 -> 41.948849 | I20: =$C$11*PLAZO_PINT -> 41.948849 | J20: =H20*$I$11 -> 25.175479 | K20: =IF(A20=DIAS_PINT,"Sí","")
A21: 5 | B21: =$C$11*A21 -> 69.914748 | C21: =$E$11*A21 -> 7.0911524 | D21: =ROUNDUP(C21,0) -> 8 | E21: =C21/D21 -> 0.88639405 | F21: =D21*5/A21 -> 8 | G21: =A21 -> 5 | H21: =$C$11*A21 -> 69.914748 | I21: =$C$11*PLAZO_PINT -> 41.948849 | J21: =H21*$I$11 -> 41.959131 | K21: =IF(A21=DIAS_PINT,"Sí","")
A22: 5 días = el lote semanal del balanceo y del Word de carros. Los viajes son de ida y vuelta: la Master deja los crudos y trae los pintados que salieron un envío antes.
A24: 3) CON LOS DÍAS ELEGIDOS (Parametros, DIAS_PINT)
A25: Concepto | B25: Valor | C25: Unidad | D25: Antes (balanceo)
A26: Días entre envíos | B26: =DIAS_PINT -> 2 | C26: días | D26: 5
A27: Viajes de la Master por envío | B27: {=INDEX(D18:D21,MATCH(DIAS_PINT,$A$18:$A$21,0))} -> 3 | C27: viajes
A28: Viajes de la Master por semana (ida y vuelta) | B28: {=INDEX(F18:F21,MATCH(DIAS_PINT,$A$18:$A$21,0))} -> 7.5 | C28: viajes
A29: Recipientes esperando el envío (máx.) | B29: =Datos!B78 -> 29 | C29: u | D29: =Datos!B61 -> 66.03
A30: Recipientes en el pintor | B30: =Datos!B79 -> 41 | C30: u | D30: =Datos!B62 -> 39.62
A31: Pintados esperando la carga de polvo (el envío entero) | B31: =Datos!B80 -> 29 | C31: u | D31: =Datos!B63 -> 26.41
A32: Total fuera de la línea (después del secado) | B32: =B29+B30+B31 -> 99 | C32: u | D32: =SUM(D29:D31) -> 132.06
A33: m² de la espera del pintor | B33: =Datos!B81 -> 17.71 | C33: m²
A34: m² de los pintados | B34: =Datos!B82 -> 17.71 | C34: m²
A36: Filas 29 a 34: los recipientes y m² son los del pulmón (Pulmones-FLAMA2035, hoja Carros: enero, por modelo y en filas llenas, iguales al Balanceo). La sección 2 compara frecuencias con el promedio del mes pico de carros y sirve para elegir cada cuántos días mandar.
A37: Al volver, se baja con el carro de manipulación por la rampa y espera sin ruedas, parado sobre el taco: vuelve el envío entero junto y la carga de polvo hace 14 por día. Las ruedas se ponen en el montaje (13).

Sheet Carro_manip
A1: CARRO DE MANIPULACIÓN ADAPTABLE — uno solo para los recipientes de 25, 50, 70 y 100 kg
A2: Reemplaza a los juegos provisorios de eje y ruedas. Lleva el recipiente de la salida de accesorios a la PH, al secado, a la espera del pintor y a la Master.
A3: ▶ Fila 25: cuántos hay que fabricar.
A5: 1) CÓMO ES (fabricación propia)
A6: Característica | B6: Valor | C6: Unidad | D6: Por qué
A7: Capacidad | B7: 250 | C7: kg | D7: El recipiente de 100 kg con accesorios lleno de agua en la PH pesa unos 175 kg (Word de carros: 157 kg el cuerpo lleno + accesorios). Margen 40 %.
A8: Diámetro que abraza la cuna en V | B8: 250 a 420 | C8: mm | D8: Recipientes de Ø 276,5 (25 kg), 320 (50 kg) y 390 (70 y 100 kg): la V se apoya en dos generatrices sin importar el Ø.
A9: Alto de la cuna (regulable con pasador, cada 50 mm) | B9: 350 a 750 | C9: mm | D9: La cuna toma el cuerpo arriba del centro de gravedad: cuerpos de 490 a 900 mm de alto.
A10: Nariz (placa donde apoya el fondo) | B10: 420 × 320 | C10: mm | D10: Entra por debajo del fondo de Ø 390 entre la pata y los triángulos; chapa de 6 mm.
A11: Ruedas | B11: Ø 300 × 50 | C11: mm | D11: Macizas, las del carro de 25 kg (Ruedar): suben la rampa de la Master.
A12: Ancho total | B12: 650 | C12: mm | D12: Pasa por puertas y entre los recipientes en la espera.
A13: Largo en planta (con el recipiente) | B13: 700 | C13: mm
A14: Alto de la manija | B14: 1300 | C14: mm | D14: Como el de la foto: se empuja parado, sin agacharse.
A15: Sujeción | B15: Cinta 50 mm con crique | D15: Abraza el cuerpo contra la cuna; se abre con una mano.
A16: Peso propio (estimado) | B16: 25 | C16: kg | D16: Caño de 1¼" × 2 mm, chapa de la nariz, eje y ruedas.
A18: 2) CUÁNTOS HACEN FALTA
A19: Concepto | B19: Valor | C19: Unidad | D19: Cómo sale
A20: Recipientes por día (mes pico) | B20: =Pintura!C11 -> 13.98295 | C20: u | D20: Hoja Pintura, C11
A21: Días que el recipiente está sobre el carro | B21: =DIAS_DOLLY -> 1 | C21: días | D21: De la salida de accesorios (8) al fin del secado (10)
A22: Carros en uso | B22: =B20*B21 -> 13.98295 | C22: u | D22: Ley de Little: lo que entra por día × días que tarda
A23: Reserva | B23: =B22*RES_DOLLY -> 1.398295 | C23: u | D23: Reparaciones y rechazados de la PH
A24: Para cargar y descargar la Master | B24: =DOLLY_CARGA -> 2 | C24: u
A25: Carros de manipulación a fabricar | B25: =ROUNDUP(B22+B23,0)+B24 -> 18 | C25: u
A26: Antes: juegos provisorios de eje y ruedas | B26: =Datos!B60 -> 177 | C26: juegos | D26: Word de carros: 354 ruedas y 177 ejes que viajaban al pintor
A27: m² para estacionarlos | B27: =B25*DOLLY_L*DOLLY_A*F_CIRC -> 11.466 | C27: m² | D27: Al lado de la salida de accesorios

Sheet Equipos
A1: EQUIPOS DEL ALMACÉN DE PT Y DE LA RAMA DE PINTURA
A2: Cantidades con fórmula; precios con IVA de la lista de MP. Lo que no tiene precio hay que cotizarlo. Los vehículos ya son de FLAMA.
A3: ▶ Fila del total.
A5: Equipo | B5: Para qué | C5: Id | D5: Cantidad | E5: Precio con IVA | F5: Subtotal | G5: Cómo sale la cantidad
A6: Rack selectivo 2.000 kg/nivel — módulo inicial | B6: Pallets de nuevos y cilindros | C6: R1I | D6: =IF(Almacen_PT!B15>0,1,0) -> 1 | E6: =IF(IFERROR(VLOOKUP(C6,PRECIOS,3,FALSE()),0)=0,"a cotizar",VLOOKUP(C6,PRECIOS,3,FALSE())) -> 856540 | F6: =IF(ISNUMBER(E6),D6*E6,0) -> 856540 | G6: 1 por fila de rack. Bastidor de 4 m: el precio es del de 3 m
A7: Rack selectivo 2.000 kg/nivel — módulo adicional | B7: Ídem | C7: R1A | D7: =MAX(0,Almacen_PT!B15-1) -> 14 | E7: =IF(IFERROR(VLOOKUP(C7,PRECIOS,3,FALSE()),0)=0,"a cotizar",VLOOKUP(C7,PRECIOS,3,FALSE())) -> 655590 | F7: =IF(ISNUMBER(E7),D7*E7,0) -> 9178260 | G7: Almacen_PT B15 − 1
A8: Mástil de 4,5 m para el Heli | B8: Llegar al 2.º larguero | C8: M45 | D8: =IF(Almacen_PT!B11>ELEV_STD,1,0) -> 1 | E8: =IF(IFERROR(VLOOKUP(C8,PRECIOS,3,FALSE()),0)=0,"a cotizar",VLOOKUP(C8,PRECIOS,3,FALSE())) -> a cotizar | F8: =IF(ISNUMBER(E8),D8*E8,0) -> 0 | G8: Almacen_PT B12
A9: Carro de manipulación adaptable | B9: Recipientes de carro de accesorios a la espera y a la Master | C9: CM | D9: =Carro_manip!B25 -> 18 | E9: =IF(IFERROR(VLOOKUP(C9,PRECIOS,3,FALSE()),0)=0,"a cotizar",VLOOKUP(C9,PRECIOS,3,FALSE())) -> a cotizar | F9: =IF(ISNUMBER(E9),D9*E9,0) -> 0 | G9: Carro_manip B25
A10: Cinta de amarre 50 mm con crique | B10: Atar los recipientes y los carros en la Master | C10: CC | D10: =CINTAS_MASTER*Despacho!G29 -> 8 | E10: =IF(IFERROR(VLOOKUP(C10,PRECIOS,3,FALSE()),0)=0,"a cotizar",VLOOKUP(C10,PRECIOS,3,FALSE())) -> a cotizar | F10: =IF(ISNUMBER(E10),D10*E10,0) -> 0 | G10: 8 por Master
A11: Taco de madera | B11: Apoyar el recipiente en la espera | C11: TM | D11: =ROUNDUP(Pintura!B29,0) -> 29 | E11: =IF(IFERROR(VLOOKUP(C11,PRECIOS,3,FALSE()),0)=0,"a cotizar",VLOOKUP(C11,PRECIOS,3,FALSE())) -> a cotizar | F11: =IF(ISNUMBER(E11),D11*E11,0) -> 0 | G11: Uno por recipiente esperando
A12: Cinta demarcatoria | B12: Rack, carros, andén, espera y pintados | C12: D1 | D12: 4 | E12: =IF(IFERROR(VLOOKUP(C12,PRECIOS,3,FALSE()),0)=0,"a cotizar",VLOOKUP(C12,PRECIOS,3,FALSE())) -> 13384 | F12: =IF(ISNUMBER(E12),D12*E12,0) -> 53536 | G12: Criterio
A13: Total con IVA (sin lo que hay que cotizar) | F13: =SUM(F6:F12) -> 10088336
A15: No incluye: envolvedora de pallets (ya está en el embalaje de manuales), vehículos (ya son de FLAMA, con su rampa), pallets descartables y film (consumibles).

Sheet Datos
A1: DATOS PEGADOS (balanceo limpio, palletizado_PT y Word de carros)
A2: Valores copiados de las planillas del proyecto. Si cambian, se vuelven a pegar acá; todo lo demás se recalcula.
A3: ▶ Esta hoja no se lee: solo guarda los datos.
A5: 1) VENTAS DE CADA MES 2035 (u) — Balanceo2035, Datos filas 79 a 86 y 162 a 169
A6: Producto | B6: Familia | C6: Modelo | D6: Ene | E6: Feb | F6: Mar | G6: Abr | H6: May | I6: Jun | J6: Jul | K6: Ago | L6: Sep | M6: Oct | N6: Nov | O6: Dic | P6: Año
A7: Nuevo 1 kg (en caja) | B7: Nuevos en caja | C7: 1 kg | D7: 3848.7167 | E7: 2886.5375 | F7: 2565.8111 | G7: 2405.4479 | H7: 2245.0847 | I7: 2245.0847 | J7: 2405.4479 | K7: 2405.4479 | L7: 2405.4479 | M7: 2405.4479 | N7: 2405.4479 | O7: 3848.7167 | P7: =SUM(D7:O7) -> 32072.639
A8: Nuevo 2,5 kg (en caja) | B8: Nuevos en caja | C8: 2,5 kg | D8: 743.64584 | E8: 594.91668 | F8: 632.09897 | G8: 632.09897 | H8: 594.91668 | I8: 557.73438 | J8: 594.91668 | K8: 594.91668 | L8: 594.91668 | M8: 557.73438 | N8: 520.55209 | O8: 818.01043 | P8: =SUM(D8:O8) -> 7436.4584
A9: Nuevo 5 kg (en caja) | B9: Nuevos en caja | C9: 5 kg | D9: 3081.4979 | E9: 2465.1983 | F9: 2619.2732 | G9: 2619.2732 | H9: 2465.1983 | I9: 2311.1234 | J9: 2465.1983 | K9: 2465.1983 | L9: 2465.1983 | M9: 2311.1234 | N9: 2157.0485 | O9: 3389.6477 | P9: =SUM(D9:O9) -> 30814.979
A10: Nuevo 10 kg (en caja) | B10: Nuevos en caja | C10: 10 kg | D10: 184.49281 | E10: 147.59425 | F10: 156.81889 | G10: 156.81889 | H10: 147.59425 | I10: 138.36961 | J10: 147.59425 | K10: 147.59425 | L10: 147.59425 | M10: 138.36961 | N10: 129.14497 | O10: 202.94209 | P10: =SUM(D10:O10) -> 1844.9281
A11: Cilindro 1 kg (manuales) | B11: Cilindros de manuales | C11: 1 kg | D11: 20465.76 | E11: 15349.32 | F11: 13643.84 | G11: 12791.1 | H11: 11938.36 | I11: 11938.36 | J11: 12791.1 | K11: 12791.1 | L11: 12791.1 | M11: 12791.1 | N11: 12791.1 | O11: 20465.76 | P11: =SUM(D11:O11) -> 170548
A12: Cilindro 2,5 kg (manuales) | B12: Cilindros de manuales | C12: 2,5 kg | D12: 668.988 | E12: 535.1904 | F12: 568.6398 | G12: 568.6398 | H12: 535.1904 | I12: 501.741 | J12: 535.1904 | K12: 535.1904 | L12: 535.1904 | M12: 501.741 | N12: 468.2916 | O12: 735.8868 | P12: =SUM(D12:O12) -> 6689.88
A13: Cilindro 5 kg (manuales) | B13: Cilindros de manuales | C13: 5 kg | D13: 3303.768 | E13: 2643.0144 | F13: 2808.2028 | G13: 2808.2028 | H13: 2643.0144 | I13: 2477.826 | J13: 2643.0144 | K13: 2643.0144 | L13: 2643.0144 | M13: 2477.826 | N13: 2312.6376 | O13: 3634.1448 | P13: =SUM(D13:O13) -> 33037.68
A14: Cilindro 10 kg (manuales) | B14: Cilindros de manuales | C14: 10 kg | D14: 201.8 | E14: 161.44 | F14: 171.53 | G14: 171.53 | H14: 161.44 | I14: 151.35 | J14: 161.44 | K14: 161.44 | L14: 161.44 | M14: 151.35 | N14: 141.26 | O14: 221.98 | P14: =SUM(D14:O14) -> 2018
A15: Carro 25 kg terminado | B15: Carros terminados | C15: 25 kg | D15: 38.561995 | E15: 34.02529 | F15: 40.830348 | G15: 40.830348 | H15: 40.830348 | I15: 36.293643 | J15: 40.830348 | K15: 40.830348 | L15: 38.561995 | M15: 34.02529 | N15: 31.756937 | O15: 36.293643 | P15: =SUM(D15:O15) -> 453.67053
A16: Carro 50 kg terminado | B16: Carros terminados | C16: 50 kg | D16: 84.82959 | E16: 74.849638 | F16: 89.819566 | G16: 89.819566 | H16: 89.819566 | I16: 79.839614 | J16: 89.819566 | K16: 89.819566 | L16: 84.82959 | M16: 74.849638 | N16: 69.859662 | O16: 79.839614 | P16: =SUM(D16:O16) -> 997.99517
A17: Carro 70 kg terminado | B17: Carros terminados | C17: 70 kg | D17: 18.513838 | E17: 16.335739 | F17: 19.602887 | G17: 19.602887 | H17: 19.602887 | I17: 17.424788 | J17: 19.602887 | K17: 19.602887 | L17: 18.513838 | M17: 16.335739 | N17: 15.24669 | O17: 17.424788 | P17: =SUM(D17:O17) -> 217.80986
A18: Carro 100 kg terminado | B18: Carros terminados | C18: 100 kg | D18: 12.342559 | E18: 10.890493 | F18: 13.068591 | G18: 13.068591 | H18: 13.068591 | I18: 11.616526 | J18: 13.068591 | K18: 13.068591 | L18: 12.342559 | M18: 10.890493 | N18: 10.16446 | O18: 11.616526 | P18: =SUM(D18:O18) -> 145.20657
... A22: Cilindro de carro 100 kg | B22: Cilindros de carros | C22: 100 kg | D22: 8.6904 | E22: 7.668 | F22: 9.2016 | G22: 9.2016 | H22: 9.2016 | I22: 8.1792 | J22: 9.2016 | K22: 9.2016 | L22: 8.6904 | M22: 7.668 | N22: 7.1568 | O22: 8.1792 | P22: =SUM(D22:O22) -> 102.24
A24: 2) PERFIL DE PRODUCCIÓN DE MANUALES (% del año que se fabrica cada mes, con sobrestock) — Balanceo2035, Datos filas 173 a 176
A25: Modelo | D25: Ene | E25: Feb | F25: Mar | G25: Abr | H25: May | I25: Jun | J25: Jul | K25: Ago | L25: Sep | M25: Oct | N25: Nov | O25: Dic | P25: Total
A26: 1 kg | D26: 0.09 | E26: 0.09 | F26: 0.08 | G26: 0.075 | H26: 0.07 | I26: 0.07 | J26: 0.075 | K26: 0.09 | L26: 0.09 | M26: 0.09 | N26: 0.09 | O26: 0.09 | P26: =SUM(D26:O26) -> 1
A27: 2,5 kg | D27: 0.09 | E27: 0.08 | F27: 0.085 | G27: 0.085 | H27: 0.08 | I27: 0.075 | J27: 0.08 | K27: 0.08 | L27: 0.08 | M27: 0.085 | N27: 0.09 | O27: 0.09 | P27: =SUM(D27:O27) -> 1
A28: 5 kg | D28: 0.09 | E28: 0.08 | F28: 0.085 | G28: 0.085 | H28: 0.08 | I28: 0.075 | J28: 0.08 | K28: 0.08 | L28: 0.08 | M28: 0.085 | N28: 0.09 | O28: 0.09 | P28: =SUM(D28:O28) -> 1
A29: 10 kg | D29: 0.09 | E29: 0.08 | F29: 0.085 | G29: 0.085 | H29: 0.08 | I29: 0.075 | J29: 0.08 | K29: 0.08 | L29: 0.08 | M29: 0.085 | N29: 0.09 | O29: 0.09 | P29: =SUM(D29:O29) -> 1
A30: Los carros se fabrican mes a mes lo que se vende (plan mensual de carros del balanceo): no tienen sobrestock.
A31: 3) CAJAS, CILINDROS Y CARROS — palletizado_PT (hoja Datos) y Word de carros
A32: Parámetro | B32: Unidad | C32: 1 kg | D32: 2,5 kg | E32: 5 kg | F32: 10 kg | G32: 25 kg | H32: 50 kg | I32: 70 kg | J32: 100 kg | K32: Fuente
A33: Matafuegos por caja | B33: u | C33: 6 | D33: 1 | E33: 1 | F33: 1 | K33: ET de matafuegos (palletizado_PT)
A34: Caja: largo | B34: mm | C34: 265 | D34: 135 | E34: 165 | F34: 195 | K34: palletizado_PT
A35: Caja: ancho | B35: mm | C35: 190 | D35: 135 | E35: 165 | F35: 195 | K35: palletizado_PT
A36: Caja: alto (el matafuego va parado) | B36: mm | C36: 410 | D36: 435 | E36: 515 | F36: 685 | K36: palletizado_PT
