Workbook

Sheet Indice
A1: Corte de chapa para cuerpos, cúpulas y fondos — Bobina, hojas, bobina madre y fleje a medida
A2: FLAMA S.A. — aprovechamiento, proceso y costos 2026–2035
A4: Hoja | B4: Contenido
A5: Supuestos | B5: Datos editables: parámetros, bobinas/stock, productividad, cotizaciones de acero recibidas, precio por espesor y forma de compra, y equipos por opción.
A6: Demanda | B6: Unidades por formato y año (terminados + cilindros), del Excel V2.
A7: Nesting | B7: Cuerpos y discos: piezas por hoja, por bobina y por fleje; aprovechamientos. Medidas y formatos editables.
A8: BobinaMadre | B8: Opción C: ancho de madre, patrones de corte longitudinal (tiras y % de uso) y cálculo anual por espesor.
A9: Bobinas | B9: Peso de bobina por SKU: recomendado según la demanda y ELEGIDO (editable), largo, días que dura y bobinas por año.
A10: Calculo | B10: Cálculo anual de toneladas, scrap, stock, horas y costos de cada opción.
A11: Proceso | B11: Cómo funciona cada opción: flujo, máquinas, materia prima, consumo, manejo y personal.
A12: Comparacion | B12: Resumen, valor actual, ranking, puntos de equilibrio, sensibilidades y gráficos.
A13: Decision | B13: Por qué se elige la opción D, con los números que la sostienen y cuándo habría que revisarla.
A14: Resumen D | B14: Todos los datos de la opción elegida año por año: costos, acero comprado, compras, stock, personal, equipos y proveedores.
A16: Colores
A17: 250 | B17: Azul con fondo amarillo: dato editable. Ej.: precio del scrap en USD/t.
A18: =1+1 -> 2 | B18: Negro: fórmula, no editar.
A19: =Supuestos!$C$84 -> 1.3561 | B19: Verde: vínculo a otra hoja (ej.: precio de hoja de 0,9 mm en USD/kg).
A21: Opciones
A22: • A — Bobina por formato: cuerpos desde bobinas de ancho estándar (línea de corte transversal); cúpulas y fondos desde flejes comprados cortados.
A23: • B — Hojas: todo desde hojas estándar; cuerpos en guillotina; discos desde tiras cargadas a mano en el balancín.
A24: • C — Bobina madre: una bobina ancha por espesor, corte longitudinal propio en flejes de cuerpo y de disco.
A25: • D — Hojas + fleje a medida: cuerpos desde hojas en guillotina; cúpulas y fondos desde bobinas angostas hechas a medida para cada disco.
A26: • Referencia: situación actual (cuerpos cortados a medida), solo para comparar.

Sheet Supuestos
A1: Supuestos editables
A2: Texto azul con fondo amarillo = dato editable. Todo lo demás se calcula.
A4: Concepto | B4: Valor | C4: Unidad | D4: Fuente / nota
A6: 1. Scrap y materia prima (los precios de acero están en la sección 7, tomados de las cotizaciones)
A7: Precio de venta del scrap | B7: 250 | C7: USD/t | D7: Ref.: acero reciclado $300–1.200/kg (Reaquila, mar-2026) con dólar ~$1.480 ≈ USD 0,20–0,80/kg.
A9: 2. Parámetros técnicos de corte
A10: Densidad del acero SAE 1010 | B10: 7.87 | C10: g/cm³ | D10: Planilla 'Dimensiones de chapa'.
A11: Margen mínimo de borde a lo ancho de la bobina | B11: 10 | C11: mm | D11: Bordes de laminación y tolerancia de ancho.
A12: Despunte de cabeza y cola de bobina | B12: 0.005 | C12: % | D12: Supuesto.
A13: Puente entre discos y al borde del fleje (s) | B13: 3 | C13: mm | D13: Supuesto (≈ 1,5–3 × espesor). Ancho de fleje = D + 2s; paso = D + s.
A14: ¿Mezclar 70 y 100 kg en la misma hoja? (SI/NO) | B14: SI | C14: SI/NO | D14: Solo opción hojas. Ver bloque en Nesting.
A16: 3. Financieros
A17: Tasa de descuento anual (USD) | B17: 0.12 | C17: % | D17: Igual a la Evaluación Económica del Excel V2 (12% real).
A18: Mantenimiento anual de equipos | B18: 0.03 | C18: % de la inversión | D18: SUPUESTO.
A20: 4. Bobinas y stock
A21: Año de referencia para recomendar pesos de bobina | B21: 2035 | C21: año | D21: Los pesos recomendados se calculan con el consumo de este año.
A22: Cobertura objetivo de una bobina | B22: 1 | C22: meses de consumo | D22: Criterio de recomendación: una bobina dura ~1 mes.
A23: Peso mínimo de bobina que se compra | B23: 0.5 | C23: t | D23: Mínimo razonable de un fraccionado.
A24: Diámetro exterior máximo de bobina aceptado | B24: 1500 | C24: mm | D24: Limita el peso según el ancho (bobinas angostas pesan poco).
A25: Diámetro interior de bobina | B25: 508 | C25: mm | D25: Estándar de mercado.
A26: Capacidad del desbobinador de la línea de corte transversal | B26: 10 | C26: t | D26: Especificar al comprar la línea.
A27: Capacidad del desbobinador de fleje del balancín (discos) | B27: 3 | C27: t | D27: Especificar al comprar.
A28: Capacidad del desbobinador de la cortadora longitudinal | B28: 14 | C28: t | D28: Pradecon: la bobina madre completa pesa 13–14 t.
A29: Cobertura máxima de stock por bobina | B29: 3 | C29: meses | D29: En años de poca demanda se compran bobinas más chicas: el stock por SKU no supera este consumo.
A30: Stock de seguridad | B30: 2 | C30: semanas de consumo | D30: Supuesto.
A31: Lote de compra de hojas / chapa a medida | B31: 1 | C31: meses de consumo | D31: Supuesto: compra mensual.
A32: Días hábiles por año | B32: 240 | C32: días | D32: 20 días/mes × 12 (Excel V2).
A34: 5. Productividad y mano de obra
A35: Línea de corte transversal: golpes efectivos por hora | B35: =20*60 -> 1200 | C35: golpes/h | D35: Supuesto.
A36: Guillotina: cortes efectivos por hora | B36: 180 | C36: cortes/h | D36: Supuesto (3 cortes/min con carga manual).
A37: Carga manual de una tira de hoja en el balancín (opción B) | B37: 15 | C37: s/tira | D37: Supuesto.
A38: Cambio de fleje en el desbobinador del balancín | B38: 15 | C38: min/fleje | D38: Supuesto.
A39: Cortadora longitudinal: velocidad efectiva | B39: 40 | C39: m/min | D39: Supuesto (máquinas de 60–120 m/min nominales).
A40: Cortadora: armado de cuchillas por bobina madre | B40: 45 | C40: min/bobina | D40: Supuesto (cambio de patrón).
A41: Operarios en la cortadora longitudinal | B41: 2 | C41: personas | D41: Supuesto.
A42: Horas productivas por operario y año | B42: 1800 | C42: h/año | D42: 150 h/mes × 12 (Excel V2).
A43: Costo mensual operario con cargas (P2) | B43: 1337922 | C43: ARS/mes | D43: Planilla 'Costo oportunidad operario-maquina', CCT 260/75 ago-2026.
A44: Horas por mes | B44: 150 | C44: h/mes | D44: Excel V2.
A45: Tipo de cambio | B45: 1420 | C45: ARS/USD | D45: Dólar BNA billete usado por Pradecon en sus presupuestos del 28/09/2026.
A46: Guillotina Molinari HG 6×3200 (referencia): precio sin IVA | B46: 36651584 | C46: ARS | D46: MercadoLibre, Molinari Maquinarias S.A.: $40,5 M con IVA 10,5%. Falta confirmar recorrido del tope trasero.
...

Sheet Demanda
A1: Demanda por formato (unidades/año)
A2: Fuente: Dimensionamiento_TecnicoV2.xlsx, hoja datos_base. Cada unidad lleva 1 cuerpo, 1 cúpula y 1 fondo (el 1 kg lleva cuerpo de tubo comprado).
A4: Matafuegos terminados
A5: Formato | B5: Línea | D5: 2026 | E5: 2027 | F5: 2028 | G5: 2029 | H5: 2030 | I5: 2031 | J5: 2032 | K5: 2033 | L5: 2034 | M5: 2035
A6: 1 kg | B6: Manual | D6: 4179 | E6: 5997 | F6: 6852 | G6: 8467 | H6: 12681 | I6: 15620 | J6: 20333 | K6: 25132 | L6: 28573 | M6: 32073
A7: 2,5 kg | B7: Manual | D7: 295 | E7: 709 | F7: 987 | G7: 1501 | H7: 2312 | I7: 3252 | J7: 4103 | K7: 5105 | L7: 6195 | M7: 7425
A8: 5 kg | B8: Manual | D8: 2256 | E8: 3847 | F8: 5094 | G8: 6823 | H8: 10819 | I8: 14606 | J8: 18878 | K8: 23368 | L8: 26968 | M8: 30751
A9: 10 kg | B9: Manual | D9: 92 | E9: 177 | F9: 253 | G9: 358 | H9: 603 | I9: 872 | J9: 1127 | K9: 1395 | L9: 1612 | M9: 1841
A10: 25 kg | B10: Rodante | D10: 34 | E10: 58 | F10: 76 | G10: 100 | H10: 156 | I10: 212 | J10: 273 | K10: 338 | L10: 393 | M10: 453
A11: 50 kg | B11: Rodante | D11: 75 | E11: 128 | F11: 166 | G11: 221 | H11: 343 | I11: 466 | J11: 599 | K11: 743 | L11: 866 | M11: 997
A12: 70 kg | B12: Rodante | D12: 16 | E12: 29 | F12: 36 | G12: 48 | H12: 74 | I12: 101 | J12: 131 | K12: 163 | L12: 189 | M12: 218
A13: 100 kg | B13: Rodante | D13: 11 | E13: 18 | F13: 24 | G13: 33 | H13: 50 | I13: 67 | J13: 87 | K13: 108 | L13: 126 | M13: 145
A14: TOTAL | D14: =SUM(D6:D13) -> 6958 | E14: =SUM(E6:E13) -> 10963 | F14: =SUM(F6:F13) -> 13488 | G14: =SUM(G6:G13) -> 17551 | H14: =SUM(H6:H13) -> 27038 | I14: =SUM(I6:I13) -> 35196 | J14: =SUM(J6:J13) -> 45531 | K14: =SUM(K6:K13) -> 56352 | ... M14: =SUM(M6:M13) -> 73903
A16: Cilindros vendidos vacíos
A17: Formato | B17: Línea | D17: 2026 | E17: 2027 | F17: 2028 | G17: 2029 | H17: 2030 | I17: 2031 | J17: 2032 | K17: 2033 | L17: 2034 | M17: 2035
A18: 1 kg | B18: Manual | D18: 0 | E18: 0 | F18: 7662 | G18: 26695 | H18: 49435 | I18: 71680 | J18: 101341 | K18: 131001 | L18: 146820 | M18: 170548
A19: 2,5 kg | B19: Manual | D19: 0 | E19: 0 | F19: 300 | G19: 1044 | H19: 1933 | I19: 2803 | J19: 3963 | K19: 5123 | L19: 5741 | M19: 6669
A20: 5 kg | B20: Manual | D20: 0 | E20: 0 | F20: 1479 | G20: 5152 | H20: 9541 | I20: 13834 | J20: 19559 | K20: 25283 | L20: 28336 | M20: 32915
A21: 10 kg | B21: Manual | D21: 0 | E21: 0 | F21: 90 | G21: 315 | H21: 583 | I21: 846 | J21: 1195 | K21: 1545 | L21: 1731 | M21: 2011
A22: 25 kg | B22: Rodante | D22: 0 | E22: 0 | F22: 14 | G22: 50 | H22: 93 | I22: 135 | J22: 191 | K22: 247 | L22: 277 | M22: 322
A23: 50 kg | B23: Rodante | D23: 0 | E23: 0 | F23: 32 | G23: 111 | H23: 205 | I23: 298 | J23: 421 | K23: 544 | L23: 610 | M23: 708
A24: 70 kg | B24: Rodante | D24: 0 | E24: 0 | F24: 7 | G24: 24 | H24: 45 | I24: 65 | J24: 92 | K24: 119 | L24: 133 | M24: 155
A25: 100 kg | B25: Rodante | D25: 0 | E25: 0 | F25: 5 | G25: 16 | H25: 30 | I25: 43 | J25: 60 | K25: 78 | L25: 88 | M25: 102
A26: TOTAL | D26: =SUM(D18:D25) -> 0 | E26: =SUM(E18:E25) -> 0 | F26: =SUM(F18:F25) -> 9589 | G26: =SUM(G18:G25) -> 33407 | H26: =SUM(H18:H25) -> 61865 | I26: =SUM(I18:I25) -> 89704 | J26: =SUM(J18:J25) -> 126822 | K26: =SUM(K18:K25) -> 163940 | ... M26: =SUM(M18:M25) -> 213430
A28: TOTAL UNIDADES A FABRICAR
A29: Formato | B29: Línea | D29: 2026 | E29: 2027 | F29: 2028 | G29: 2029 | H29: 2030 | I29: 2031 | J29: 2032 | K29: 2033 | L29: 2034 | M29: 2035
A30: 1 kg | B30: Manual | D30: =D6+D18 -> 4179 | E30: =E6+E18 -> 5997 | F30: =F6+F18 -> 14514 | G30: =G6+G18 -> 35162 | H30: =H6+H18 -> 62116 | I30: =I6+I18 -> 87300 | J30: =J6+J18 -> 121674 | K30: =K6+K18 -> 156133 | ... M30: =M6+M18 -> 202621
A31: 2,5 kg | B31: Manual | D31: =D7+D19 -> 295 | E31: =E7+E19 -> 709 | F31: =F7+F19 -> 1287 | G31: =G7+G19 -> 2545 | H31: =H7+H19 -> 4245 | I31: =I7+I19 -> 6055 | J31: =J7+J19 -> 8066 | K31: =K7+K19 -> 10228 | ... M31: =M7+M19 -> 14094
A32: 5 kg | B32: Manual | D32: =D8+D20 -> 2256 | E32: =E8+E20 -> 3847 | F32: =F8+F20 -> 6573 | G32: =G8+G20 -> 11975 | H32: =H8+H20 -> 20360 | I32: =I8+I20 -> 28440 | J32: =J8+J20 -> 38437 | K32: =K8+K20 -> 48651 | ... M32: =M8+M20 -> 63666
A33: 10 kg | B33: Manual | D33: =D9+D21 -> 92 | E33: =E9+E21 -> 177 | F33: =F9+F21 -> 343 | G33: =G9+G21 -> 673 | H33: =H9+H21 -> 1186 | I33: =I9+I21 -> 1718 | J33: =J9+J21 -> 2322 | K33: =K9+K21 -> 2940 | ... M33: =M9+M21 -> 3852
A34: 25 kg | B34: Rodante | D34: =D10+D22 -> 34 | E34: =E10+E22 -> 58 | F34: =F10+F22 -> 90 | G34: =G10+G22 -> 150 | H34: =H10+H22 -> 249 | I34: =I10+I22 -> 347 | J34: =J10+J22 -> 464 | K34: =K10+K22 -> 585 | ... M34: =M10+M22 -> 775
A35: 50 kg | B35: Rodante | D35: =D11+D23 -> 75 | E35: =E11+E23 -> 128 | F35: =F11+F23 -> 198 | G35: =G11+G23 -> 332 | H35: =H11+H23 -> 548 | I35: =I11+I23 -> 764 | J35: =J11+J23 -> 1020 | K35: =K11+K23 -> 1287 | ... M35: =M11+M23 -> 1705
A36: 70 kg | B36: Rodante | D36: =D12+D24 -> 16 | E36: =E12+E24 -> 29 | F36: =F12+F24 -> 43 | G36: =G12+G24 -> 72 | H36: =H12+H24 -> 119 | I36: =I12+I24 -> 166 | J36: =J12+J24 -> 223 | K36: =K12+K24 -> 282 | ... M36: =M12+M24 -> 373
A37: 100 kg | B37: Rodante | D37: =D13+D25 -> 11 | E37: =E13+E25 -> 18 | F37: =F13+F25 -> 29 | G37: =G13+G25 -> 49 | H37: =H13+H25 -> 80 | I37: =I13+I25 -> 110 | J37: =J13+J25 -> 147 | K37: =K13+K25 -> 186 | ... M37: =M13+M25 -> 247
A38: TOTAL | D38: =SUM(D30:D37) -> 6958 | E38: =SUM(E30:E37) -> 10963 | F38: =SUM(F30:F37) -> 23077 | G38: =SUM(G30:G37) -> 50958 | H38: =SUM(H30:H37) -> 88903 | I38: =SUM(I30:I37) -> 124900 | J38: =SUM(J30:J37) -> 172353 | K38: =SUM(K30:K37) -> 220292 | ... M38: =SUM(M30:M37) -> 287333
A40: Discos de rodantes (25–100 kg): se compran tercerizados embutidos, no entran en este análisis.

Sheet Nesting
A1: Nesting: cuántas piezas salen de cada hoja, bobina y fleje
A2: Editables: medidas de piezas, formato de hoja y ancho de bobina de cada formato.
A4: A) CUERPOS | H4: Hoja estándar + guillotina (opción B) | P4: Bobina de ancho estándar + línea de corte (opción A)
A5: Formato | B5: Línea | C5: Alto cuerpo (mm) | D5: Perímetro = largo desarrollo (mm) | E5: Espesor (mm) | F5: Acero | G5: Masa del desarrollo (kg) | H5: HOJA ancho (mm) | I5: HOJA largo (mm) | J5: Piezas orient. 1 | K5: Piezas orient. 2 | L5: Piezas por hoja | M5: Aprovech. hoja | N5: Masa hoja (kg) | O5: Cortes guillotina por hoja | P5: BOBINA ancho (mm) | Q5: Piezas a lo ancho (alto cruzado) | R5: Aprov. (alto cruzado) | S5: Piezas a lo ancho (perím. cruzado) | T5: Aprov. (perím. cruzado) | U5: Piezas por golpe | V5: Avance por golpe (mm) | W5: Aprovech. bobina | X5: Orientación
A6: 2,5 kg | B6: Manual | C6: 269.5 | D6: 385.5 | E6: 1.25 | F6: LAF | G6: =C6*D6*E6*Supuestos!$B$10/1000000 -> 1.02204 | H6: 1220 | I6: 2440 | J6: =INT(H6/C6)*INT(I6/D6) -> 24 | K6: =INT(H6/D6)*INT(I6/C6) -> 27 | L6: =MAX(J6,K6) -> 27 | M6: =L6*C6*D6/(H6*I6) -> 0.94231751 | N6: =H6*I6*E6*Supuestos!$B$10/1000000 -> 29.28427 | O6: =IF(J6>=K6,INT(H6/C6)*(1+INT(I6/D6)),INT(H6/D6)*(1+INT(I6/C6))) -> 30 | P6: 1220 | Q6: =INT((P6-Supuestos!$B$11)/C6) -> 4 | R6: =Q6*C6/P6 -> 0.88360656 | S6: =INT((P6-Supuestos!$B$11)/D6) -> 3 | T6: =S6*D6/P6 -> 0.94795082 | U6: =IF(R6>=T6,Q6,S6) -> 3 | V6: =IF(R6>=T6,D6,C6) -> 269.5 | W6: =MAX(R6,T6)*(1-Supuestos!$B$12) -> 0.94321107 | X6: =IF(R6>=T6,"Alto a lo ancho","Perímetro a lo ancho") -> Perímetro a lo ancho
A7: 5 kg | B7: Manual | C7: 330 | D7: 474.5 | E7: 1.6 | F7: LAF | G7: =C7*D7*E7*Supuestos!$B$10/1000000 -> 1.9717183 | H7: 1000 | I7: 2000 | J7: =INT(H7/C7)*INT(I7/D7) -> 12 | K7: =INT(H7/D7)*INT(I7/C7) -> 12 | L7: =MAX(J7,K7) -> 12 | M7: =L7*C7*D7/(H7*I7) -> 0.93951 | N7: =H7*I7*E7*Supuestos!$B$10/1000000 -> 25.184 | O7: =IF(J7>=K7,INT(H7/C7)*(1+INT(I7/D7)),INT(H7/D7)*(1+INT(I7/C7))) -> 15 | P7: 1000 | Q7: =INT((P7-Supuestos!$B$11)/C7) -> 3 | R7: =Q7*C7/P7 -> 0.99 | S7: =INT((P7-Supuestos!$B$11)/D7) -> 2 | T7: =S7*D7/P7 -> 0.949 | U7: =IF(R7>=T7,Q7,S7) -> 3 | V7: =IF(R7>=T7,D7,C7) -> 474.5 | W7: =MAX(R7,T7)*(1-Supuestos!$B$12) -> 0.98505 | X7: =IF(R7>=T7,"Alto a lo ancho","Perímetro a lo ancho") -> Alto a lo ancho
A8: 10 kg | B8: Manual | C8: 495 | D8: 563 | E8: 2 | F8: LAF | G8: =C8*D8*E8*Supuestos!$B$10/1000000 -> 4.3865019 | H8: 1500 | I8: 3000 | J8: =INT(H8/C8)*INT(I8/D8) -> 15 | K8: =INT(H8/D8)*INT(I8/C8) -> 12 | L8: =MAX(J8,K8) -> 15 | M8: =L8*C8*D8/(H8*I8) -> 0.92895 | N8: =H8*I8*E8*Supuestos!$B$10/1000000 -> 70.83 | O8: =IF(J8>=K8,INT(H8/C8)*(1+INT(I8/D8)),INT(H8/D8)*(1+INT(I8/C8))) -> 18 | P8: 1000 | Q8: =INT((P8-Supuestos!$B$11)/C8) -> 2 | R8: =Q8*C8/P8 -> 0.99 | S8: =INT((P8-Supuestos!$B$11)/D8) -> 1 | T8: =S8*D8/P8 -> 0.563 | U8: =IF(R8>=T8,Q8,S8) -> 2 | V8: =IF(R8>=T8,D8,C8) -> 563 | W8: =MAX(R8,T8)*(1-Supuestos!$B$12) -> 0.98505 | X8: =IF(R8>=T8,"Alto a lo ancho","Perímetro a lo ancho") -> Alto a lo ancho
A9: 25 kg | B9: Rodante | C9: 490 | D9: 858 | E9: 3.2 | F9: LAC | G9: =C9*D9*E9*Supuestos!$B$10/1000000 -> 10.587857 | H9: 1500 | I9: 3000 | J9: =INT(H9/C9)*INT(I9/D9) -> 9 | K9: =INT(H9/D9)*INT(I9/C9) -> 6 | L9: =MAX(J9,K9) -> 9 | M9: =L9*C9*D9/(H9*I9) -> 0.84084 | N9: =H9*I9*E9*Supuestos!$B$10/1000000 -> 113.328 | O9: =IF(J9>=K9,INT(H9/C9)*(1+INT(I9/D9)),INT(H9/D9)*(1+INT(I9/C9))) -> 12 | P9: 1500 | Q9: =INT((P9-Supuestos!$B$11)/C9) -> 3 | R9: =Q9*C9/P9 -> 0.98 | S9: =INT((P9-Supuestos!$B$11)/D9) -> 1 | T9: =S9*D9/P9 -> 0.572 | U9: =IF(R9>=T9,Q9,S9) -> 3 | V9: =IF(R9>=T9,D9,C9) -> 858 | W9: =MAX(R9,T9)*(1-Supuestos!$B$12) -> 0.9751 | X9: =IF(R9>=T9,"Alto a lo ancho","Perímetro a lo ancho") -> Alto a lo ancho
A10: 50 kg | B10: Rodante | C10: 640 | D10: 994 | E10: 3.2 | F10: LAC | G10: =C10*D10*E10*Supuestos!$B$10/1000000 -> 16.021053 | H10: 1500 | I10: 3000 | J10: =INT(H10/C10)*INT(I10/D10) -> 6 | K10: =INT(H10/D10)*INT(I10/C10) -> 4 | L10: =MAX(J10,K10) -> 6 | M10: =L10*C10*D10/(H10*I10) -> 0.84821333 | N10: =H10*I10*E10*Supuestos!$B$10/1000000 -> 113.328 | O10: =IF(J10>=K10,INT(H10/C10)*(1+INT(I10/D10)),INT(H10/D10)*(1+INT(I10/C10))) -> 8 | P10: 1500 | Q10: =INT((P10-Supuestos!$B$11)/C10) -> 2 | R10: =Q10*C10/P10 -> 0.85333333 | S10: =INT((P10-Supuestos!$B$11)/D10) -> 1 | T10: =S10*D10/P10 -> 0.66266667 | U10: =IF(R10>=T10,Q10,S10) -> 2 | V10: =IF(R10>=T10,D10,C10) -> 994 | W10: =MAX(R10,T10)*(1-Supuestos!$B$12) -> 0.84906667 | X10: =IF(R10>=T10,"Alto a lo ancho","Perímetro a lo ancho") -> Alto a lo ancho
A11: 70 kg | B11: Rodante | C11: 680 | D11: 1212 | E11: 4.75 | F11: LAC | G11: =C11*D11*E11*Supuestos!$B$10/1000000 -> 30.809161 | H11: 1500 | I11: 3000 | J11: =INT(H11/C11)*INT(I11/D11) -> 4 | K11: =INT(H11/D11)*INT(I11/C11) -> 4 | L11: =MAX(J11,K11) -> 4 | M11: =L11*C11*D11/(H11*I11) -> 0.73258667 | N11: =H11*I11*E11*Supuestos!$B$10/1000000 -> 168.22125 | O11: =IF(J11>=K11,INT(H11/C11)*(1+INT(I11/D11)),INT(H11/D11)*(1+INT(I11/C11))) -> 6 | P11: 1245 | Q11: =INT((P11-Supuestos!$B$11)/C11) -> 1 | R11: =Q11*C11/P11 -> 0.54618474 | S11: =INT((P11-Supuestos!$B$11)/D11) -> 1 | T11: =S11*D11/P11 -> 0.97349398 | U11: =IF(R11>=T11,Q11,S11) -> 1 | V11: =IF(R11>=T11,D11,C11) -> 680 | W11: =MAX(R11,T11)*(1-Supuestos!$B$12) -> 0.96862651 | X11: =IF(R11>=T11,"Alto a lo ancho","Perímetro a lo ancho") -> Perímetro a lo ancho
A12: 100 kg | B12: Rodante | C12: 900 | D12: 1212 | E12: 4.75 | F12: LAC | G12: =C12*D12*E12*Supuestos!$B$10/1000000 -> 40.776831 | H12: 1500 | I12: 3000 | J12: =INT(H12/C12)*INT(I12/D12) -> 2 | K12: =INT(H12/D12)*INT(I12/C12) -> 3 | L12: =MAX(J12,K12) -> 3 | M12: =L12*C12*D12/(H12*I12) -> 0.7272 | N12: =H12*I12*E12*Supuestos!$B$10/1000000 -> 168.22125 | O12: =IF(J12>=K12,INT(H12/C12)*(1+INT(I12/D12)),INT(H12/D12)*(1+INT(I12/C12))) -> 4 | P12: 1245 | Q12: =INT((P12-Supuestos!$B$11)/C12) -> 1 | R12: =Q12*C12/P12 -> 0.72289157 | S12: =INT((P12-Supuestos!$B$11)/D12) -> 1 | T12: =S12*D12/P12 -> 0.97349398 | U12: =IF(R12>=T12,Q12,S12) -> 1 | V12: =IF(R12>=T12,D12,C12) -> 900 | W12: =MAX(R12,T12)*(1-Supuestos!$B$12) -> 0.96862651 | X12: =IF(R12>=T12,"Alto a lo ancho","Perímetro a lo ancho") -> Perímetro a lo ancho
A14: Mezcla de 70 y 100 kg en la misma hoja (usa el formato de hoja del 70 kg)
A15: Cuerpos de 100 kg por hoja mixta | G15: 1
A16: Cuerpos de 70 kg por hoja mixta | G16: 3
A17: Largo ocupado (mm) | G17: =G15*C12+G16*C11 -> 2940
A18: ¿Entra? (perímetros a lo ancho, altos a lo largo, mismo espesor) | G18: =IF(AND(D11<=H11,D12<=H11,G17<=I11,E11=E12),"SI","NO") -> SI
A19: Aprovechamiento hoja mixta | G19: =(G15*C12*D12+G16*C11*D11)/(H11*I11) -> 0.79184
A20: Masa hoja mixta (kg) | G20: =N11 -> 168.22125
A21: Cortes por hoja mixta | G21: =1+G15+G16 -> 5
A22: Mezcla activa en el cálculo | G22: =IF(AND(Supuestos!$B$14="SI",G18="SI"),"SI","NO") -> SI
A24: B) CÚPULAS Y FONDOS (discos de manuales) | J24: Hoja estándar → tiras en guillotina → balancín (opción B)
A25: Formato | B25: Pieza | C25: Diámetro del disco (mm) | D25: Espesor (mm) | E25: Acero | F25: Masa del disco (kg) | G25: Ancho de fleje = D+2s (mm) | H25: Paso = D+s (mm) | I25: Aprovech. fleje (1 fila) | J25: HOJA ancho (mm) | K25: HOJA largo (mm) | L25: Tiras orient. 1 | M25: Discos/tira o.1 | N25: Piezas o.1 | O25: Tiras orient. 2 | P25: Discos/tira o.2 | Q25: Piezas o.2 | R25: Discos por hoja | S25: Aprovech. hoja | T25: Masa hoja (kg) | U25: Tiras por hoja | V25: Discos por tira | W25: FLEJE COMPRADO: ancho (mm) | X25: Aprovech. fleje comprado | Y25: Nota
A26: 1 kg | B26: Cúpula | C26: 108 | D26: 0.9 | E26: LAF | F26: =PI()*C26^2/4*D26*Supuestos!$B$10/1000000 -> 0.064886543 | G26: =C26+2*Supuestos!$B$13 -> 114 | H26: =C26+Supuestos!$B$13 -> 111 | I26: =PI()*C26^2/4/(G26*H26)*(1-Supuestos!$B$12) -> 0.72033189 | J26: 1220 | K26: 2440 | L26: =INT(J26/G26) -> 10 | M26: =INT((K26-Supuestos!$B$13)/H26) -> 21 | N26: =L26*M26 -> 210 | O26: =INT(K26/G26) -> 21 | P26: =INT((J26-Supuestos!$B$13)/H26) -> 10 | Q26: =O26*P26 -> 210 | R26: =MAX(N26,Q26) -> 210 | S26: =R26*PI()*C26^2/4/(J26*K26) -> 0.64625963 | T26: =J26*K26*D26*Supuestos!$B$10/1000000 -> 21.084674 | U26: =IF(N26>=Q26,L26,O26) -> 10 | V26: =IF(N26>=Q26,M26,P26) -> 21 | W26: 114 | X26: =IF(W26<C26,0,PI()*C26^2/4/(W26*H26)*(1-Supuestos!$B$12)) -> 0.72033189 | Y26: ESTIMADO: deducido de la masa de pieza del registro (0,0461 kg) / 0,71 (relación pieza/disco de las otras cúpulas). Confirmar. Fleje: estimado D+2s (Pradecon corta a medida sin cargo).
A27: 1 kg | B27: Fondo | C27: 100 | D27: 0.9 | E27: LAF | F27: =PI()*C27^2/4*D27*Supuestos!$B$10/1000000 -> 0.055629752 | G27: =C27+2*Supuestos!$B$13 -> 106 | H27: =C27+Supuestos!$B$13 -> 103 | I27: =PI()*C27^2/4/(G27*H27)*(1-Supuestos!$B$12) -> 0.71576403 | J27: 1000 | K27: 2000 | L27: =INT(J27/G27) -> 9 | M27: =INT((K27-Supuestos!$B$13)/H27) -> 19 | N27: =L27*M27 -> 171 | O27: =INT(K27/G27) -> 18 | P27: =INT((J27-Supuestos!$B$13)/H27) -> 9 | Q27: =O27*P27 -> 162 | R27: =MAX(N27,Q27) -> 171 | S27: =R27*PI()*C27^2/4/(J27*K27) -> 0.67151543 | T27: =J27*K27*D27*Supuestos!$B$10/1000000 -> 14.166 | U27: =IF(N27>=Q27,L27,O27) -> 9 | V27: =IF(N27>=Q27,M27,P27) -> 19 | W27: 106 | X27: =IF(W27<C27,0,PI()*C27^2/4/(W27*H27)*(1-Supuestos!$B$12)) -> 0.71576403 | Y27: ESTIMADO: deducido de la masa de pieza (0,0497 kg) / 0,90 (relación de los otros fondos). Confirmar. Fleje: estimado D+2s (Pradecon corta a medida sin cargo).
A28: 2,5 kg | B28: Cúpula | C28: 179 | D28: 1.25 | E28: LAF | F28: =PI()*C28^2/4*D28*Supuestos!$B$10/1000000 -> 0.24756012 | G28: =C28+2*Supuestos!$B$13 -> 185 | H28: =C28+Supuestos!$B$13 -> 182 | I28: =PI()*C28^2/4/(G28*H28)*(1-Supuestos!$B$12) -> 0.74366254 | J28: 1220 | K28: 2440 | L28: =INT(J28/G28) -> 6 | M28: =INT((K28-Supuestos!$B$13)/H28) -> 13 | N28: =L28*M28 -> 78 | O28: =INT(K28/G28) -> 13 | P28: =INT((J28-Supuestos!$B$13)/H28) -> 6 | Q28: =O28*P28 -> 78 | R28: =MAX(N28,Q28) -> 78 | S28: =R28*PI()*C28^2/4/(J28*K28) -> 0.65938777 | T28: =J28*K28*D28*Supuestos!$B$10/1000000 -> 29.28427 | U28: =IF(N28>=Q28,L28,O28) -> 6 | V28: =IF(N28>=Q28,M28,P28) -> 13 | W28: 200 | X28: =IF(W28<C28,0,PI()*C28^2/4/(W28*H28)*(1-Supuestos!$B$12)) -> 0.68788785 | Y28: Planilla 'Dimensiones de chapa'. Fleje: Pacheco Chapas.
A29: 2,5 kg | B29: Fondo | C29: 148 | D29: 1.25 | E29: LAF | F29: =PI()*C29^2/4*D29*Supuestos!$B$10/1000000 -> 0.16923807 | G29: =C29+2*Supuestos!$B$13 -> 154 | H29: =C29+Supuestos!$B$13 -> 151 | I29: =PI()*C29^2/4/(G29*H29)*(1-Supuestos!$B$12) -> 0.73610323 | J29: 1220 | K29: 2440 | L29: =INT(J29/G29) -> 7 | M29: =INT((K29-Supuestos!$B$13)/H29) -> 16 | N29: =L29*M29 -> 112 | O29: =INT(K29/G29) -> 15 | P29: =INT((J29-Supuestos!$B$13)/H29) -> 8 | Q29: =O29*P29 -> 120 | R29: =MAX(N29,Q29) -> 120 | S29: =R29*PI()*C29^2/4/(J29*K29) -> 0.6934975 | T29: =J29*K29*D29*Supuestos!$B$10/1000000 -> 29.28427 | U29: =IF(N29>=Q29,L29,O29) -> 15 | V29: =IF(N29>=Q29,M29,P29) -> 8 | W29: 200 | X29: =IF(W29<C29,0,PI()*C29^2/4/(W29*H29)*(1-Supuestos!$B$12)) -> 0.56679949 | Y29: Planilla 'Dimensiones de chapa'. Fleje: Pacheco Chapas.
A30: 5 kg | B30: Cúpula | C30: 221 | D30: 1.6 | E30: LAF | F30: =PI()*C30^2/4*D30*Supuestos!$B$10/1000000 -> 0.48302448 | G30: =C30+2*Supuestos!$B$13 -> 227 | H30: =C30+Supuestos!$B$13 -> 224 | I30: =PI()*C30^2/4/(G30*H30)*(1-Supuestos!$B$12) -> 0.75062605 | J30: 1220 | K30: 2440 | L30: =INT(J30/G30) -> 5 | M30: =INT((K30-Supuestos!$B$13)/H30) -> 10 | N30: =L30*M30 -> 50 | O30: =INT(K30/G30) -> 10 | P30: =INT((J30-Supuestos!$B$13)/H30) -> 5 | Q30: =O30*P30 -> 50 | R30: =MAX(N30,Q30) -> 50 | S30: =R30*PI()*C30^2/4/(J30*K30) -> 0.64430986 | T30: =J30*K30*D30*Supuestos!$B$10/1000000 -> 37.483866 | U30: =IF(N30>=Q30,L30,O30) -> 5 | V30: =IF(N30>=Q30,M30,P30) -> 10 | W30: 250 | X30: =IF(W30<C30,0,PI()*C30^2/4/(W30*H30)*(1-Supuestos!$B$12)) -> 0.68156846 | Y30: Planilla 'Dimensiones de chapa'. Fleje: Pacheco Chapas.
A31: 5 kg | B31: Fondo | C31: 177 | D31: 1.6 | E31: LAF | F31: =PI()*C31^2/4*D31*Supuestos!$B$10/1000000 -> 0.30983547 | G31: =C31+2*Supuestos!$B$13 -> 183 | H31: =C31+Supuestos!$B$13 -> 180 | I31: =PI()*C31^2/4/(G31*H31)*(1-Supuestos!$B$12) -> 0.74325168 | J31: 1000 | K31: 2000 | L31: =INT(J31/G31) -> 5 | M31: =INT((K31-Supuestos!$B$13)/H31) -> 11 | N31: =L31*M31 -> 55 | O31: =INT(K31/G31) -> 10 | P31: =INT((J31-Supuestos!$B$13)/H31) -> 5 | Q31: =O31*P31 -> 50 | R31: =MAX(N31,Q31) -> 55 | S31: =R31*PI()*C31^2/4/(J31*K31) -> 0.67665782 | T31: =J31*K31*D31*Supuestos!$B$10/1000000 -> 25.184 | U31: =IF(N31>=Q31,L31,O31) -> 5 | V31: =IF(N31>=Q31,M31,P31) -> 11 | W31: 200 | X31: =IF(W31<C31,0,PI()*C31^2/4/(W31*H31)*(1-Supuestos!$B$12)) -> 0.68007529 | Y31: Planilla 'Dimensiones de chapa'. Fleje: Pacheco Chapas.
A32: 10 kg | B32: Cúpula | C32: 258 | D32: 2 | E32: LAF | F32: =PI()*C32^2/4*D32*Supuestos!$B$10/1000000 -> 0.82287529 | G32: =C32+2*Supuestos!$B$13 -> 264 | H32: =C32+Supuestos!$B$13 -> 261 | I32: =PI()*C32^2/4/(G32*H32)*(1-Supuestos!$B$12) -> 0.75493218 | J32: 1500 | K32: 3000 | L32: =INT(J32/G32) -> 5 | M32: =INT((K32-Supuestos!$B$13)/H32) -> 11 | N32: =L32*M32 -> 55 | O32: =INT(K32/G32) -> 11 | P32: =INT((J32-Supuestos!$B$13)/H32) -> 5 | Q32: =O32*P32 -> 55 | R32: =MAX(N32,Q32) -> 55 | S32: =R32*PI()*C32^2/4/(J32*K32) -> 0.63896853 | T32: =J32*K32*D32*Supuestos!$B$10/1000000 -> 70.83 | U32: =IF(N32>=Q32,L32,O32) -> 5 | V32: =IF(N32>=Q32,M32,P32) -> 11 | W32: 300 | X32: =IF(W32<C32,0,PI()*C32^2/4/(W32*H32)*(1-Supuestos!$B$12)) -> 0.66434032 | Y32: Registro de referencia (FADESA) usa 1,6 mm en la cúpula del 10 kg; se toma 2,0 mm según tabla FLAMA. Editable. Fleje: Pacheco Chapas.
A33: 10 kg | B33: Fondo | C33: 205 | D33: 2 | E33: LAF | F33: =PI()*C33^2/4*D33*Supuestos!$B$10/1000000 -> 0.51952007 | G33: =C33+2*Supuestos!$B$13 -> 211 | H33: =C33+Supuestos!$B$13 -> 208 | I33: =PI()*C33^2/4/(G33*H33)*(1-Supuestos!$B$12) -> 0.74829853 | J33: 1500 | K33: 3000 | L33: =INT(J33/G33) -> 7 | M33: =INT((K33-Supuestos!$B$13)/H33) -> 14 | N33: =L33*M33 -> 98 | O33: =INT(K33/G33) -> 14 | P33: =INT((J33-Supuestos!$B$13)/H33) -> 7 | Q33: =O33*P33 -> 98 | R33: =MAX(N33,Q33) -> 98 | S33: =R33*PI()*C33^2/4/(J33*K33) -> 0.71880513 | T33: =J33*K33*D33*Supuestos!$B$10/1000000 -> 70.83 | U33: =IF(N33>=Q33,L33,O33) -> 7 | V33: =IF(N33>=Q33,M33,P33) -> 14 | W33: 249 | X33: =IF(W33<C33,0,PI()*C33^2/4/(W33*H33)*(1-Supuestos!$B$12)) -> 0.63410036 | Y33: Tabla FLAMA ('Dimensiones de chapa'). Fleje: Pacheco Chapas.
A35: Ancho de fleje D+2s (columna G) = el que cortan ustedes (opciones B y C). Ancho comprado (columna W) = el cotizado a Pacheco para A, D y referencia; si es más ancho que D+2s, baja el aprovechamiento. Los discos se cortan en una fila por fleje (troquel simple). Un troquel de 2 filas escalonadas mejora el aprovechamiento ~8–10 puntos; queda como mejora futura.

Sheet BobinaMadre
A1: Opción C — Bobina madre de ancho estándar + corte longitudinal propio
A2: Se compra una bobina ancha por espesor y se corta en flejes: de cuerpo (van a la línea de corte transversal) y de disco (van al balancín).
A3: Patrones y participaciones optimizados por programación lineal sobre la demanda 2026–2035 (mínimo acero comprado). Editables: ancho de madre, orientación, tiras por patrón y % de cada patrón.
A5: Grupo 0,9 mm
A6: Ancho de bobina madre (mm) | B6: 1220 | C6: Espesor (mm) | D6: =Nesting!$D$26 -> 0.9 | E6: Acero | F6: =Nesting!$E$26 -> LAF | G6: kg por metro de madre | H6: =B6*D6*Supuestos!$B$10/1000 -> 8.64126
A7: Tira (fleje) | B7: Orientación (1 = alto a lo ancho, 2 = perímetro a lo ancho) | C7: Ancho de tira (mm) | D7: Avance por unidad (mm) | E7: Patrón 1 (tiras) | F7: Patrón 2 (tiras) | G7: Patrón 3 (tiras) | H7: Tiras por metro de madre (ponderado)
A8: Cúpula 1 kg | B8: — | C8: =Nesting!$G$26 -> 114 | D8: =Nesting!$H$26 -> 111 | E8: 5 | F8: 10 | G8: 0 | H8: =E8*$E$10+F8*$F$10+G8*$G$10 -> 5.6395
A9: Fondo 1 kg | B9: — | C9: =Nesting!$G$27 -> 106 | D9: =Nesting!$H$27 -> 103 | E9: 6 | F9: 0 | G9: 0 | H9: =E9*$E$10+F9*$F$10+G9*$G$10 -> 5.2326
A10: Participación de cada patrón (% de los metros de madre) | E10: 0.8721 | F10: 0.1279 | G10: 0 | H10: =IF(ABS(SUM(E10:G10)-1)<0.001,"Suma 100% OK","REVISAR: no suma 100%") -> Suma 100% OK
A11: Ancho usado por patrón (mm) | E11: =SUMPRODUCT($C$8:$C$9,E8:E9) -> 1206 | F11: =SUMPRODUCT($C$8:$C$9,F8:F9) -> 1140 | G11: =SUMPRODUCT($C$8:$C$9,G8:G9) -> 0
A12: Orilla (scrap de borde) por patrón (mm) | E12: =IF(E11=0,0,$B$6-E11) -> 14 | F12: =IF(F11=0,0,$B$6-F11) -> 80 | G12: =IF(G11=0,0,$B$6-G11) -> 0
A13: ¿Entra en la madre? (orilla ≥ margen) | E13: =IF(E11=0,"sin uso",IF($B$6-E11>=Supuestos!$B$11,"OK","NO ENTRA")) -> OK | F13: =IF(F11=0,"sin uso",IF($B$6-F11>=Supuestos!$B$11,"OK","NO ENTRA")) -> OK | G13: =IF(G11=0,"sin uso",IF($B$6-G11>=Supuestos!$B$11,"OK","NO ENTRA")) -> sin uso
A15: Cálculo anual | D15: 2026 | E15: 2027 | F15: 2028 | G15: 2029 | H15: 2030 | I15: 2031 | J15: 2032 | K15: 2033 | L15: 2034 | M15: 2035
A16: Metros necesarios: Cúpula 1 kg | D16: =Calculo!D8*$D$8/1000 -> 463.869 | E16: =Calculo!E8*$D$8/1000 -> 665.667 | F16: =Calculo!F8*$D$8/1000 -> 1611.054 | G16: =Calculo!G8*$D$8/1000 -> 3902.982 | H16: =Calculo!H8*$D$8/1000 -> 6894.876 | I16: =Calculo!I8*$D$8/1000 -> 9690.3 | J16: =Calculo!J8*$D$8/1000 -> 13505.814 | K16: =Calculo!K8*$D$8/1000 -> 17330.763 | ... M16: =Calculo!M8*$D$8/1000 -> 22490.931
A17: Metros necesarios: Fondo 1 kg | D17: =Calculo!D8*$D$9/1000 -> 430.437 | E17: =Calculo!E8*$D$9/1000 -> 617.691 | F17: =Calculo!F8*$D$9/1000 -> 1494.942 | G17: =Calculo!G8*$D$9/1000 -> 3621.686 | H17: =Calculo!H8*$D$9/1000 -> 6397.948 | I17: =Calculo!I8*$D$9/1000 -> 8991.9 | J17: =Calculo!J8*$D$9/1000 -> 12532.422 | K17: =Calculo!K8*$D$9/1000 -> 16081.699 | ... M17: =Calculo!M8*$D$9/1000 -> 20869.963
A18: Metros de bobina madre a cortar | D18: =MAX(IF($H$8=0,IF(D16>0,1000000000000,0),D16/$H$8),IF($H$9=0,IF(D17>0,1000000000000,0),D17/$H$9)) -> 82.260635 | E18: =MAX(IF($H$8=0,IF(E16>0,1000000000000,0),E16/$H$8),IF($H$9=0,IF(E17>0,1000000000000,0),E17/$H$9)) -> 118.04667 | F18: =MAX(IF($H$8=0,IF(F16>0,1000000000000,0),F16/$H$8),IF($H$9=0,IF(F17>0,1000000000000,0),F17/$H$9)) -> 285.69774 | G18: =MAX(IF($H$8=0,IF(G16>0,1000000000000,0),G16/$H$8),IF($H$9=0,IF(G17>0,1000000000000,0),G17/$H$9)) -> 692.1389 | H18: =MAX(IF($H$8=0,IF(H16>0,1000000000000,0),H16/$H$8),IF($H$9=0,IF(H17>0,1000000000000,0),H17/$H$9)) -> 1222.7092 | I18: =MAX(IF($H$8=0,IF(I16>0,1000000000000,0),I16/$H$8),IF($H$9=0,IF(I17>0,1000000000000,0),I17/$H$9)) -> 1718.4383 | J18: =MAX(IF($H$8=0,IF(J16>0,1000000000000,0),J16/$H$8),IF($H$9=0,IF(J17>0,1000000000000,0),J17/$H$9)) -> 2395.0659 | K18: =MAX(IF($H$8=0,IF(K16>0,1000000000000,0),K16/$H$8),IF($H$9=0,IF(K17>0,1000000000000,0),K17/$H$9)) -> 3073.3668 | ... M18: =MAX(IF($H$8=0,IF(M16>0,1000000000000,0),M16/$H$8),IF($H$9=0,IF(M17>0,1000000000000,0),M17/$H$9)) -> 3988.4499
A19: Acero de madre comprado (t) | D19: =D18*$H$6/1000/(1-Supuestos!$B$12) -> 0.71440757 | E19: =E18*$H$6/1000/(1-Supuestos!$B$12) -> 1.0251979 | F19: =F18*$H$6/1000/(1-Supuestos!$B$12) -> 2.4811944 | G19: =G18*$H$6/1000/(1-Supuestos!$B$12) -> 6.0110072 | H19: =H18*$H$6/1000/(1-Supuestos!$B$12) -> 10.618842 | I19: =I18*$H$6/1000/(1-Supuestos!$B$12) -> 14.924092 | J19: =J18*$H$6/1000/(1-Supuestos!$B$12) -> 20.800389 | K19: =K18*$H$6/1000/(1-Supuestos!$B$12) -> 26.691217 | ... M19: =M18*$H$6/1000/(1-Supuestos!$B$12) -> 34.638425
A20: Acero neto en piezas del grupo (t) | D20: =Calculo!D31+Calculo!D32 -> 0.50363759 | E20: =Calculo!E31+Calculo!E32 -> 0.72273622 | F20: =Calculo!F31+Calculo!F32 -> 1.7491735 | G20: =Calculo!G31+Calculo!G32 -> 4.2375939 | H20: =Calculo!H31+Calculo!H32 -> 7.4859902 | I20: =Calculo!I31+Calculo!I32 -> 10.521073 | J20: =Calculo!J31+Calculo!J32 -> 14.6637 | K20: =Calculo!K31+Calculo!K32 -> 18.816571 | ... M20: =Calculo!M31+Calculo!M32 -> 24.419132
A21: Aprovechamiento del grupo | D21: =IF(D19=0,0,D20/D19) -> 0.70497236 | E21: =IF(E19=0,0,E20/E19) -> 0.70497236 | F21: =IF(F19=0,0,F20/F19) -> 0.70497236 | G21: =IF(G19=0,0,G20/G19) -> 0.70497236 | H21: =IF(H19=0,0,H20/H19) -> 0.70497236 | I21: =IF(I19=0,0,I20/I19) -> 0.70497236 | J21: =IF(J19=0,0,J20/J19) -> 0.70497236 | K21: =IF(K19=0,0,K20/K19) -> 0.70497236 | ... M21: =IF(M19=0,0,M20/M19) -> 0.70497236
A22: Bobinas madre por año | D22: =IF(Bobinas!$K$24=0,0,D19/Bobinas!$K$24) -> 0.23813586 | E22: =IF(Bobinas!$K$24=0,0,E19/Bobinas!$K$24) -> 0.34173265 | F22: =IF(Bobinas!$K$24=0,0,F19/Bobinas!$K$24) -> 0.82706481 | G22: =IF(Bobinas!$K$24=0,0,G19/Bobinas!$K$24) -> 2.0036691 | H22: =IF(Bobinas!$K$24=0,0,H19/Bobinas!$K$24) -> 3.539614 | I22: =IF(Bobinas!$K$24=0,0,I19/Bobinas!$K$24) -> 4.9746974 | J22: =IF(Bobinas!$K$24=0,0,J19/Bobinas!$K$24) -> 6.9334631 | K22: =IF(Bobinas!$K$24=0,0,K19/Bobinas!$K$24) -> 8.8970725 | ... M22: =IF(Bobinas!$K$24=0,0,M19/Bobinas!$K$24) -> 11.546142
A23: Flejes de disco generados por año | D23: =D22*($H$8+$H$9) -> 2.5890369 | E23: =E22*($H$8+$H$9) -> 3.7153515 | F23: =F22*($H$8+$H$9) -> 8.9919313 | G23: =G22*($H$8+$H$9) -> 21.784091 | H23: =H22*($H$8+$H$9) -> 38.483038 | I23: =I22*($H$8+$H$9) -> 54.085408 | J23: =J22*($H$8+$H$9) -> 75.381304 | K23: =K22*($H$8+$H$9) -> 96.729862 | ... M23: =M22*($H$8+$H$9) -> 125.53081
A24: Horas de corte longitudinal | D24: =D18/(Supuestos!$B$39*60)+D22*Supuestos!$B$40/60 -> 0.21287716 | E24: =E18/(Supuestos!$B$39*60)+E22*Supuestos!$B$40/60 -> 0.3054856 | F24: =F18/(Supuestos!$B$39*60)+F22*Supuestos!$B$40/60 -> 0.73933933 | G24: =G18/(Supuestos!$B$39*60)+G22*Supuestos!$B$40/60 -> 1.791143 | H24: =H18/(Supuestos!$B$39*60)+H22*Supuestos!$B$40/60 -> 3.1641727 | I24: =I18/(Supuestos!$B$39*60)+I22*Supuestos!$B$40/60 -> 4.447039 | J24: =J18/(Supuestos!$B$39*60)+J22*Supuestos!$B$40/60 -> 6.1980415 | K24: =K18/(Supuestos!$B$39*60)+K22*Supuestos!$B$40/60 -> 7.9533739 | ... M24: =M18/(Supuestos!$B$39*60)+M22*Supuestos!$B$40/60 -> 10.32146
A27: Grupo 1,25 mm
A28: Ancho de bobina madre (mm) | B28: 1000 | C28: Espesor (mm) | D28: =Nesting!$E$6 -> 1.25 | E28: Acero | F28: =Nesting!$F$6 -> LAF | G28: kg por metro de madre | H28: =B28*D28*Supuestos!$B$10/1000 -> 9.8375
A29: Tira (fleje) | B29: Orientación (1 = alto a lo ancho, 2 = perímetro a lo ancho) | C29: Ancho de tira (mm) | D29: Avance por unidad (mm) | E29: Patrón 1 (tiras) | F29: Patrón 2 (tiras) | G29: Patrón 3 (tiras) | H29: Tiras por metro de madre (ponderado)
A30: Cuerpo 2,5 kg | B30: 1 | C30: =IF(B30=1,Nesting!$C$6,Nesting!$D$6) -> 269.5 | D30: =IF(B30=1,Nesting!$D$6,Nesting!$C$6) -> 385.5 | E30: 1 | F30: 2 | G30: 3 | H30: =E30*$E$33+F30*$F$33+G30*$G$33 -> 2.3064
A31: Cúpula 2,5 kg | B31: — | C31: =Nesting!$G$28 -> 185 | D31: =Nesting!$H$28 -> 182 | E31: 3 | F31: 2 | G31: 0 | H31: =E31*$E$33+F31*$F$33+G31*$G$33 -> 1.0887
A32: Fondo 2,5 kg | B32: — | C32: =Nesting!$G$29 -> 154 | D32: =Nesting!$H$29 -> 151 | E32: 1 | F32: 0 | G32: 1 | H32: =E32*$E$33+F32*$F$33+G32*$G$33 -> 0.9034
A33: Participación de cada patrón (% de los metros de madre) | E33: 0.2985 | F33: 0.0966 | G33: 0.6049 | H33: =IF(ABS(SUM(E33:G33)-1)<0.001,"Suma 100% OK","REVISAR: no suma 100%") -> Suma 100% OK
A34: Ancho usado por patrón (mm) | E34: =SUMPRODUCT($C$30:$C$32,E30:E32) -> 978.5 | F34: =SUMPRODUCT($C$30:$C$32,F30:F32) -> 909 | G34: =SUMPRODUCT($C$30:$C$32,G30:G32) -> 962.5
A35: Orilla (scrap de borde) por patrón (mm) | E35: =IF(E34=0,0,$B$28-E34) -> 21.5 | F35: =IF(F34=0,0,$B$28-F34) -> 91 | G35: =IF(G34=0,0,$B$28-G34) -> 37.5
A36: ¿Entra en la madre? (orilla ≥ margen) | E36: =IF(E34=0,"sin uso",IF($B$28-E34>=Supuestos!$B$11,"OK","NO ENTRA")) -> OK | F36: =IF(F34=0,"sin uso",IF($B$28-F34>=Supuestos!$B$11,"OK","NO ENTRA")) -> OK | G36: =IF(G34=0,"sin uso",IF($B$28-G34>=Supuestos!$B$11,"OK","NO ENTRA")) -> OK
A38: Cálculo anual | D38: 2026 | E38: 2027 | F38: 2028 | G38: 2029 | H38: 2030 | I38: 2031 | J38: 2032 | K38: 2033 | L38: 2034 | M38: 2035
A39: Metros necesarios: Cuerpo 2,5 kg | D39: =Calculo!D9*$D$30/1000 -> 113.7225 | E39: =Calculo!E9*$D$30/1000 -> 273.3195 | F39: =Calculo!F9*$D$30/1000 -> 496.1385 | G39: =Calculo!G9*$D$30/1000 -> 981.0975 | H39: =Calculo!H9*$D$30/1000 -> 1636.4475 | I39: =Calculo!I9*$D$30/1000 -> 2334.2025 | J39: =Calculo!J9*$D$30/1000 -> 3109.443 | K39: =Calculo!K9*$D$30/1000 -> 3942.894 | ... M39: =Calculo!M9*$D$30/1000 -> 5433.237
A40: Metros necesarios: Cúpula 2,5 kg | D40: =Calculo!D9*$D$31/1000 -> 53.69 | E40: =Calculo!E9*$D$31/1000 -> 129.038 | F40: =Calculo!F9*$D$31/1000 -> 234.234 | G40: =Calculo!G9*$D$31/1000 -> 463.19 | H40: =Calculo!H9*$D$31/1000 -> 772.59 | I40: =Calculo!I9*$D$31/1000 -> 1102.01 | J40: =Calculo!J9*$D$31/1000 -> 1468.012 | K40: =Calculo!K9*$D$31/1000 -> 1861.496 | ... M40: =Calculo!M9*$D$31/1000 -> 2565.108
A41: Metros necesarios: Fondo 2,5 kg | D41: =Calculo!D9*$D$32/1000 -> 44.545 | E41: =Calculo!E9*$D$32/1000 -> 107.059 | F41: =Calculo!F9*$D$32/1000 -> 194.337 | G41: =Calculo!G9*$D$32/1000 -> 384.295 | H41: =Calculo!H9*$D$32/1000 -> 640.995 | I41: =Calculo!I9*$D$32/1000 -> 914.305 | J41: =Calculo!J9*$D$32/1000 -> 1217.966 | K41: =Calculo!K9*$D$32/1000 -> 1544.428 | ... M41: =Calculo!M9*$D$32/1000 -> 2128.194
A42: Metros de bobina madre a cortar | D42: =MAX(IF($H$30=0,IF(D39>0,1000000000000,0),D39/$H$30),IF($H$31=0,IF(D40>0,1000000000000,0),D40/$H$31),IF($H$32=0,IF(D41>0,1000000000000,0),D41/$H$32)) -> 49.315698 | E42: =MAX(IF($H$30=0,IF(E39>0,1000000000000,0),E39/$H$30),IF($H$31=0,IF(E40>0,1000000000000,0),E40/$H$31),IF($H$32=0,IF(E41>0,1000000000000,0),E41/$H$32)) -> 118.52485 | F42: =MAX(IF($H$30=0,IF(F39>0,1000000000000,0),F39/$H$30),IF($H$31=0,IF(F40>0,1000000000000,0),F40/$H$31),IF($H$32=0,IF(F41>0,1000000000000,0),F41/$H$32)) -> 215.15018 | G42: =MAX(IF($H$30=0,IF(G39>0,1000000000000,0),G39/$H$30),IF($H$31=0,IF(G40>0,1000000000000,0),G40/$H$31),IF($H$32=0,IF(G41>0,1000000000000,0),G41/$H$32)) -> 425.45237 | H42: =MAX(IF($H$30=0,IF(H39>0,1000000000000,0),H39/$H$30),IF($H$31=0,IF(H40>0,1000000000000,0),H40/$H$31),IF($H$32=0,IF(H41>0,1000000000000,0),H41/$H$32)) -> 709.64453 | I42: =MAX(IF($H$30=0,IF(I39>0,1000000000000,0),I39/$H$30),IF($H$31=0,IF(I40>0,1000000000000,0),I40/$H$31),IF($H$32=0,IF(I41>0,1000000000000,0),I41/$H$32)) -> 1012.2256 | J42: =MAX(IF($H$30=0,IF(J39>0,1000000000000,0),J39/$H$30),IF($H$31=0,IF(J40>0,1000000000000,0),J40/$H$31),IF($H$32=0,IF(J41>0,1000000000000,0),J41/$H$32)) -> 1348.4082 | K42: =MAX(IF($H$30=0,IF(K39>0,1000000000000,0),K39/$H$30),IF($H$31=0,IF(K40>0,1000000000000,0),K40/$H$31),IF($H$32=0,IF(K41>0,1000000000000,0),K41/$H$32)) -> 1709.8337 | ... M42: =MAX(IF($H$30=0,IF(M39>0,1000000000000,0),M39/$H$30),IF($H$31=0,IF(M40>0,1000000000000,0),M40/$H$31),IF($H$32=0,IF(M41>0,1000000000000,0),M41/$H$32)) -> 2356.1201
A43: Acero de madre comprado (t) | D43: =D42*$H$28/1000/(1-Supuestos!$B$12) -> 0.48758108 | E43: =E42*$H$28/1000/(1-Supuestos!$B$12) -> 1.1718474 | F43: =F42*$H$28/1000/(1-Supuestos!$B$12) -> 2.1271758 | G43: =G42*$H$28/1000/(1-Supuestos!$B$12) -> 4.2064198 | H43: =H42*$H$28/1000/(1-Supuestos!$B$12) -> 7.0162091 | I43: =I42*$H$28/1000/(1-Supuestos!$B$12) -> 10.007808 | J43: =J42*$H$28/1000/(1-Supuestos!$B$12) -> 13.331624 | K43: =K42*$H$28/1000/(1-Supuestos!$B$12) -> 16.905015 | ... M43: =M42*$H$28/1000/(1-Supuestos!$B$12) -> 23.294806
A44: Acero neto en piezas del grupo (t) | D44: =Calculo!D19+Calculo!D33+Calculo!D34 -> 0.42445727 | E44: =Calculo!E19+Calculo!E33+Calculo!E34 -> 1.0201363 | F44: =Calculo!F19+Calculo!F33+Calculo!F34 -> 1.8517848 | G44: =Calculo!G19+Calculo!G33+Calculo!G34 -> 3.6618432 | H44: =Calculo!H19+Calculo!H33+Calculo!H34 -> 6.1078682 | I44: =Calculo!I19+Calculo!I33+Calculo!I34 -> 8.7121653 | J44: =Calculo!J19+Calculo!J33+Calculo!J34 -> 11.605669 | K44: =Calculo!K19+Calculo!K33+Calculo!K34 -> 14.716437 | ... M44: =Calculo!M19+Calculo!M33+Calculo!M34 -> 20.278986
A45: Aprovechamiento del grupo | D45: =IF(D43=0,0,D44/D43) -> 0.87053679 | E45: =IF(E43=0,0,E44/E43) -> 0.87053679 | F45: =IF(F43=0,0,F44/F43) -> 0.87053679 | G45: =IF(G43=0,0,G44/G43) -> 0.87053679 | H45: =IF(H43=0,0,H44/H43) -> 0.87053679 | I45: =IF(I43=0,0,I44/I43) -> 0.87053679 | J45: =IF(J43=0,0,J44/J43) -> 0.87053679 | K45: =IF(K43=0,0,K44/K43) -> 0.87053679 | ... M45: =IF(M43=0,0,M44/M43) -> 0.87053679
...

Sheet Bobinas
A1: Peso de bobina por SKU: recomendado según la demanda y elegido (editable)
A2: Recomendado = consumo mensual del año de referencia × cobertura objetivo, redondeado a 0,5 t, entre el peso mínimo y el máximo que permiten el diámetro exterior y el desbobinador.
A4: Opción A — bobinas de cuerpo (ancho estándar) y flejes de disco (cortados por el proveedor)
A5: SKU | B5: Tipo | C5: Espesor (mm) | D5: Ancho (mm) | E5: kg por metro | F5: Consumo año de referencia (t) | G5: Consumo mensual (t) | H5: Máx. por diámetro exterior (t) | I5: Capacidad del desbobinador (t) | J5: PESO RECOMENDADO (t) | K5: PESO ELEGIDO (t) | L5: Largo de la bobina (m) | M5: Piezas por bobina | N5: Días que dura | O5: Bobinas por año
A6: Cuerpo 2,5 kg | B6: Bobina cuerpo | C6: =Nesting!$E$6 -> 1.25 | D6: =Nesting!$P$6 -> 1220 | E6: =D6*C6*Supuestos!$B$10/1000 -> 12.00175 | F6: {=INDEX(Calculo!$D$44:$M$44,MATCH(Supuestos!$B$21,Calculo!$D$4:$M$4,0))} -> 15.271907 | G6: =F6/12 -> 1.2726589 | H6: =D6*Supuestos!$B$49 -> 15.021034 | I6: =Supuestos!$B$26 -> 10 | J6: =MIN(ROUNDDOWN(MIN(H6,I6)*2,0)/2,MAX(Supuestos!$B$23,ROUNDUP(G6*Supuestos!$B$22*2,0)/2)) -> 1.5 | K6: 1.5 | L6: =K6*1000/E6 -> 124.98177 | M6: =L6*1000/Nesting!$V$6*Nesting!$U$6 -> 1391.2628 | N6: =IF(F6=0,0,K6/F6*Supuestos!$B$32) -> 23.572694 | O6: =IF(K6=0,0,F6/K6) -> 10.181271
A7: Cuerpo 5 kg | B7: Bobina cuerpo | C7: =Nesting!$E$7 -> 1.6 | D7: =Nesting!$P$7 -> 1000 | E7: =D7*C7*Supuestos!$B$10/1000 -> 12.592 | F7: {=INDEX(Calculo!$D$45:$M$45,MATCH(Supuestos!$B$21,Calculo!$D$4:$M$4,0))} -> 127.4366 | G7: =F7/12 -> 10.619716 | H7: =D7*Supuestos!$B$49 -> 12.312323 | I7: =Supuestos!$B$26 -> 10 | J7: =MIN(ROUNDDOWN(MIN(H7,I7)*2,0)/2,MAX(Supuestos!$B$23,ROUNDUP(G7*Supuestos!$B$22*2,0)/2)) -> 10 | K7: 10 | L7: =K7*1000/E7 -> 794.15502 | M7: =L7*1000/Nesting!$V$7*Nesting!$U$7 -> 5021.0012 | N7: =IF(F7=0,0,K7/F7*Supuestos!$B$32) -> 18.832895 | O7: =IF(K7=0,0,F7/K7) -> 12.74366
A8: Cuerpo 10 kg | B8: Bobina cuerpo | C8: =Nesting!$E$8 -> 2 | D8: =Nesting!$P$8 -> 1000 | E8: =D8*C8*Supuestos!$B$10/1000 -> 15.74 | F8: {=INDEX(Calculo!$D$46:$M$46,MATCH(Supuestos!$B$21,Calculo!$D$4:$M$4,0))} -> 17.153246 | G8: =F8/12 -> 1.4294372 | H8: =D8*Supuestos!$B$49 -> 12.312323 | I8: =Supuestos!$B$26 -> 10 | J8: =MIN(ROUNDDOWN(MIN(H8,I8)*2,0)/2,MAX(Supuestos!$B$23,ROUNDUP(G8*Supuestos!$B$22*2,0)/2)) -> 1.5 | K8: 1.5 | L8: =K8*1000/E8 -> 95.298602 | M8: =L8*1000/Nesting!$V$8*Nesting!$U$8 -> 338.53855 | N8: =IF(F8=0,0,K8/F8*Supuestos!$B$32) -> 20.987281 | O8: =IF(K8=0,0,F8/K8) -> 11.435498
A9: Cuerpo 25 kg | B9: Bobina cuerpo | C9: =Nesting!$E$9 -> 3.2 | D9: =Nesting!$P$9 -> 1500 | E9: =D9*C9*Supuestos!$B$10/1000 -> 37.776 | F9: {=INDEX(Calculo!$D$47:$M$47,MATCH(Supuestos!$B$21,Calculo!$D$4:$M$4,0))} -> 8.415126 | G9: =F9/12 -> 0.7012605 | H9: =D9*Supuestos!$B$49 -> 18.468484 | I9: =Supuestos!$B$26 -> 10 | J9: =MIN(ROUNDDOWN(MIN(H9,I9)*2,0)/2,MAX(Supuestos!$B$23,ROUNDUP(G9*Supuestos!$B$22*2,0)/2)) -> 1 | K9: 1 | L9: =K9*1000/E9 -> 26.471834 | M9: =L9*1000/Nesting!$V$9*Nesting!$U$9 -> 92.55886 | N9: =IF(F9=0,0,K9/F9*Supuestos!$B$32) -> 28.520072 | O9: =IF(K9=0,0,F9/K9) -> 8.415126
A10: Cuerpo 50 kg | B10: Bobina cuerpo | C10: =Nesting!$E$10 -> 3.2 | D10: =Nesting!$P$10 -> 1500 | E10: =D10*C10*Supuestos!$B$10/1000 -> 37.776 | F10: {=INDEX(Calculo!$D$48:$M$48,MATCH(Supuestos!$B$21,Calculo!$D$4:$M$4,0))} -> 32.171674 | G10: =F10/12 -> 2.6809728 | H10: =D10*Supuestos!$B$49 -> 18.468484 | I10: =Supuestos!$B$26 -> 10 | J10: =MIN(ROUNDDOWN(MIN(H10,I10)*2,0)/2,MAX(Supuestos!$B$23,ROUNDUP(G10*Supuestos!$B$22*2,0)/2)) -> 3 | K10: 3 | L10: =K10*1000/E10 -> 79.415502 | M10: =L10*1000/Nesting!$V$10*Nesting!$U$10 -> 159.78974 | N10: =IF(F10=0,0,K10/F10*Supuestos!$B$32) -> 22.379936 | O10: =IF(K10=0,0,F10/K10) -> 10.723891
A11: Cuerpo 70 kg | B11: Bobina cuerpo | C11: =Nesting!$E$11 -> 4.75 | D11: =Nesting!$P$11 -> 1245 | E11: =D11*C11*Supuestos!$B$10/1000 -> 46.541213 | F11: {=INDEX(Calculo!$D$49:$M$49,MATCH(Supuestos!$B$21,Calculo!$D$4:$M$4,0))} -> 11.864033 | G11: =F11/12 -> 0.98866944 | H11: =D11*Supuestos!$B$49 -> 15.328842 | I11: =Supuestos!$B$26 -> 10 | J11: =MIN(ROUNDDOWN(MIN(H11,I11)*2,0)/2,MAX(Supuestos!$B$23,ROUNDUP(G11*Supuestos!$B$22*2,0)/2)) -> 1 | K11: 1 | L11: =K11*1000/E11 -> 21.486333 | M11: =L11*1000/Nesting!$V$11*Nesting!$U$11 -> 31.597549 | N11: =IF(F11=0,0,K11/F11*Supuestos!$B$32) -> 20.229208 | O11: =IF(K11=0,0,F11/K11) -> 11.864033
A12: Cuerpo 100 kg | B12: Bobina cuerpo | C12: =Nesting!$E$12 -> 4.75 | D12: =Nesting!$P$12 -> 1245 | E12: =D12*C12*Supuestos!$B$10/1000 -> 46.541213 | F12: {=INDEX(Calculo!$D$50:$M$50,MATCH(Supuestos!$B$21,Calculo!$D$4:$M$4,0))} -> 10.398102 | G12: =F12/12 -> 0.8665085 | H12: =D12*Supuestos!$B$49 -> 15.328842 | I12: =Supuestos!$B$26 -> 10 | J12: =MIN(ROUNDDOWN(MIN(H12,I12)*2,0)/2,MAX(Supuestos!$B$23,ROUNDUP(G12*Supuestos!$B$22*2,0)/2)) -> 1 | K12: 1 | L12: =K12*1000/E12 -> 21.486333 | M12: =L12*1000/Nesting!$V$12*Nesting!$U$12 -> 23.873704 | N12: =IF(F12=0,0,K12/F12*Supuestos!$B$32) -> 23.081135 | O12: =IF(K12=0,0,F12/K12) -> 10.398102
A13: Fleje Cúpula 1 kg | B13: Fleje disco | C13: =Nesting!$D$26 -> 0.9 | D13: =Nesting!$W$26 -> 114 | E13: =D13*C13*Supuestos!$B$10/1000 -> 0.807462 | F13: {=INDEX(Calculo!$D$66:$M$66,MATCH(Supuestos!$B$21,Calculo!$D$4:$M$4,0))} -> 18.251831 | G13: =F13/12 -> 1.5209859 | H13: =D13*Supuestos!$B$49 -> 1.4036048 | I13: =Supuestos!$B$27 -> 3 | J13: =MIN(ROUNDDOWN(MIN(H13,I13)*2,0)/2,MAX(Supuestos!$B$23,ROUNDUP(G13*Supuestos!$B$22*2,0)/2)) -> 1 | K13: 1 | L13: =K13*1000/E13 -> 1238.4484 | M13: =L13*1000/Nesting!$H$26 -> 11157.193 | N13: =IF(F13=0,0,K13/F13*Supuestos!$B$32) -> 13.149365 | O13: =IF(K13=0,0,F13/K13) -> 18.251831
A14: Fleje Fondo 1 kg | B14: Fleje disco | C14: =Nesting!$D$27 -> 0.9 | D14: =Nesting!$W$27 -> 106 | E14: =D14*C14*Supuestos!$B$10/1000 -> 0.750798 | F14: {=INDEX(Calculo!$D$67:$M$67,MATCH(Supuestos!$B$21,Calculo!$D$4:$M$4,0))} -> 15.747866 | G14: =F14/12 -> 1.3123222 | H14: =D14*Supuestos!$B$49 -> 1.3051062 | I14: =Supuestos!$B$27 -> 3 | J14: =MIN(ROUNDDOWN(MIN(H14,I14)*2,0)/2,MAX(Supuestos!$B$23,ROUNDUP(G14*Supuestos!$B$22*2,0)/2)) -> 1 | K14: 1 | L14: =K14*1000/E14 -> 1331.9162 | M14: =L14*1000/Nesting!$H$27 -> 12931.225 | N14: =IF(F14=0,0,K14/F14*Supuestos!$B$32) -> 15.24016 | O14: =IF(K14=0,0,F14/K14) -> 15.747866
A15: Fleje Cúpula 2,5 kg | B15: Fleje disco | C15: =Nesting!$D$28 -> 1.25 | D15: =Nesting!$W$28 -> 200 | E15: =D15*C15*Supuestos!$B$10/1000 -> 1.9675 | F15: {=INDEX(Calculo!$D$68:$M$68,MATCH(Supuestos!$B$21,Calculo!$D$4:$M$4,0))} -> 5.072211 | G15: =F15/12 -> 0.42268425 | H15: =D15*Supuestos!$B$49 -> 2.4624646 | I15: =Supuestos!$B$27 -> 3 | J15: =MIN(ROUNDDOWN(MIN(H15,I15)*2,0)/2,MAX(Supuestos!$B$23,ROUNDUP(G15*Supuestos!$B$22*2,0)/2)) -> 0.5 | K15: 0.5 | L15: =K15*1000/E15 -> 254.12961 | M15: =L15*1000/Nesting!$H$28 -> 1396.3165 | N15: =IF(F15=0,0,K15/F15*Supuestos!$B$32) -> 23.658322 | O15: =IF(K15=0,0,F15/K15) -> 10.144422
A16: Fleje Fondo 2,5 kg | B16: Fleje disco | C16: =Nesting!$D$29 -> 1.25 | D16: =Nesting!$W$29 -> 200 | E16: =D16*C16*Supuestos!$B$10/1000 -> 1.9675 | F16: {=INDEX(Calculo!$D$69:$M$69,MATCH(Supuestos!$B$21,Calculo!$D$4:$M$4,0))} -> 4.208263 | G16: =F16/12 -> 0.35068858 | H16: =D16*Supuestos!$B$49 -> 2.4624646 | I16: =Supuestos!$B$27 -> 3 | J16: =MIN(ROUNDDOWN(MIN(H16,I16)*2,0)/2,MAX(Supuestos!$B$23,ROUNDUP(G16*Supuestos!$B$22*2,0)/2)) -> 0.5 | K16: 0.5 | L16: =K16*1000/E16 -> 254.12961 | M16: =L16*1000/Nesting!$H$29 -> 1682.9775 | N16: =IF(F16=0,0,K16/F16*Supuestos!$B$32) -> 28.515328 | O16: =IF(K16=0,0,F16/K16) -> 8.416526
A17: Fleje Cúpula 5 kg | B17: Fleje disco | C17: =Nesting!$D$30 -> 1.6 | D17: =Nesting!$W$30 -> 250 | E17: =D17*C17*Supuestos!$B$10/1000 -> 3.148 | F17: {=INDEX(Calculo!$D$70:$M$70,MATCH(Supuestos!$B$21,Calculo!$D$4:$M$4,0))} -> 45.119806 | G17: =F17/12 -> 3.7599839 | H17: =D17*Supuestos!$B$49 -> 3.0780807 | I17: =Supuestos!$B$27 -> 3 | J17: =MIN(ROUNDDOWN(MIN(H17,I17)*2,0)/2,MAX(Supuestos!$B$23,ROUNDUP(G17*Supuestos!$B$22*2,0)/2)) -> 3 | K17: 0.6 | L17: =K17*1000/E17 -> 190.5972 | M17: =L17*1000/Nesting!$H$30 -> 850.88038 | N17: =IF(F17=0,0,K17/F17*Supuestos!$B$32) -> 3.1915031 | O17: =IF(K17=0,0,F17/K17) -> 75.199677
A18: Fleje Fondo 5 kg | B18: Fleje disco | C18: =Nesting!$D$31 -> 1.6 | D18: =Nesting!$W$31 -> 200 | E18: =D18*C18*Supuestos!$B$10/1000 -> 2.5184 | F18: {=INDEX(Calculo!$D$71:$M$71,MATCH(Supuestos!$B$21,Calculo!$D$4:$M$4,0))} -> 29.00559 | G18: =F18/12 -> 2.4171325 | H18: =D18*Supuestos!$B$49 -> 2.4624646 | I18: =Supuestos!$B$27 -> 3 | J18: =MIN(ROUNDDOWN(MIN(H18,I18)*2,0)/2,MAX(Supuestos!$B$23,ROUNDUP(G18*Supuestos!$B$22*2,0)/2)) -> 2 | K18: 0.5 | L18: =K18*1000/E18 -> 198.53875 | M18: =L18*1000/Nesting!$H$31 -> 1102.9931 | N18: =IF(F18=0,0,K18/F18*Supuestos!$B$32) -> 4.1371336 | O18: =IF(K18=0,0,F18/K18) -> 58.011179
A19: Fleje Cúpula 10 kg | B19: Fleje disco | C19: =Nesting!$D$32 -> 2 | D19: =Nesting!$W$32 -> 300 | E19: =D19*C19*Supuestos!$B$10/1000 -> 4.722 | F19: {=INDEX(Calculo!$D$72:$M$72,MATCH(Supuestos!$B$21,Calculo!$D$4:$M$4,0))} -> 4.7712227 | G19: =F19/12 -> 0.39760189 | H19: =D19*Supuestos!$B$49 -> 3.6936968 | I19: =Supuestos!$B$27 -> 3 | J19: =MIN(ROUNDDOWN(MIN(H19,I19)*2,0)/2,MAX(Supuestos!$B$23,ROUNDUP(G19*Supuestos!$B$22*2,0)/2)) -> 0.5 | K19: 0.75 | L19: =K19*1000/E19 -> 158.831 | M19: =L19*1000/Nesting!$H$32 -> 608.54791 | N19: =IF(F19=0,0,K19/F19*Supuestos!$B$32) -> 37.726179 | O19: =IF(K19=0,0,F19/K19) -> 6.3616303
A20: Fleje Fondo 10 kg | B20: Fleje disco | C20: =Nesting!$D$33 -> 2 | D20: =Nesting!$W$33 -> 249 | E20: =D20*C20*Supuestos!$B$10/1000 -> 3.91926 | F20: {=INDEX(Calculo!$D$73:$M$73,MATCH(Supuestos!$B$21,Calculo!$D$4:$M$4,0))} -> 3.1559536 | G20: =F20/12 -> 0.26299613 | H20: =D20*Supuestos!$B$49 -> 3.0657684 | I20: =Supuestos!$B$27 -> 3 | J20: =MIN(ROUNDDOWN(MIN(H20,I20)*2,0)/2,MAX(Supuestos!$B$23,ROUNDUP(G20*Supuestos!$B$22*2,0)/2)) -> 0.5 | K20: 0.5 | L20: =K20*1000/E20 -> 127.5751 | M20: =L20*1000/Nesting!$H$33 -> 613.34184 | N20: =IF(F20=0,0,K20/F20*Supuestos!$B$32) -> 38.023373 | O20: =IF(K20=0,0,F20/K20) -> 6.3119072
A22: Opción C — bobinas madre (una por espesor)
A23: SKU | B23: Tipo | C23: Espesor (mm) | D23: Ancho (mm) | E23: kg por metro | F23: Consumo año de referencia (t) | G23: Consumo mensual (t) | H23: Máx. por diámetro exterior (t) | I23: Capacidad del desbobinador (t) | J23: PESO RECOMENDADO (t) | K23: PESO ELEGIDO (t) | L23: Largo de la bobina (m) | M23: Piezas por bobina | N23: Días hábiles que dura | O23: Bobinas por año
A24: Madre 0,9 mm | B24: Bobina madre | C24: =BobinaMadre!$D$6 -> 0.9 | D24: =BobinaMadre!$B$6 -> 1220 | E24: =D24*C24*Supuestos!$B$10/1000 -> 8.64126 | F24: {=INDEX(BobinaMadre!$D$19:$M$19,MATCH(Supuestos!$B$21,Calculo!$D$4:$M$4,0))} -> 34.638425 | G24: =F24/12 -> 2.8865354 | H24: =D24*Supuestos!$B$49 -> 15.021034 | I24: =Supuestos!$B$28 -> 14 | J24: =MIN(ROUNDDOWN(MIN(H24,I24)*2,0)/2,MAX(Supuestos!$B$23,ROUNDUP(G24*Supuestos!$B$22*2,0)/2)) -> 3 | K24: 3 | L24: =K24*1000/E24 -> 347.17159 | M24: según patrón | N24: =IF(F24=0,0,K24/F24*Supuestos!$B$32) -> 20.786165 | O24: =IF(K24=0,0,F24/K24) -> 11.546142
A25: Madre 1,25 mm | B25: Bobina madre | C25: =BobinaMadre!$D$28 -> 1.25 | D25: =BobinaMadre!$B$28 -> 1000 | E25: =D25*C25*Supuestos!$B$10/1000 -> 9.8375 | F25: {=INDEX(BobinaMadre!$D$43:$M$43,MATCH(Supuestos!$B$21,Calculo!$D$4:$M$4,0))} -> 23.294806 | G25: =F25/12 -> 1.9412338 | H25: =D25*Supuestos!$B$49 -> 12.312323 | I25: =Supuestos!$B$28 -> 14 | J25: =MIN(ROUNDDOWN(MIN(H25,I25)*2,0)/2,MAX(Supuestos!$B$23,ROUNDUP(G25*Supuestos!$B$22*2,0)/2)) -> 2 | K25: 2 | L25: =K25*1000/E25 -> 203.30368 | M25: según patrón | N25: =IF(F25=0,0,K25/F25*Supuestos!$B$32) -> 20.605452 | O25: =IF(K25=0,0,F25/K25) -> 11.647403
A26: Madre 1,6 mm | B26: Bobina madre | C26: =BobinaMadre!$D$52 -> 1.6 | D26: =BobinaMadre!$B$52 -> 1000 | E26: =D26*C26*Supuestos!$B$10/1000 -> 12.592 | F26: {=INDEX(BobinaMadre!$D$67:$M$67,MATCH(Supuestos!$B$21,Calculo!$D$4:$M$4,0))} -> 198.0715 | G26: =F26/12 -> 16.505958 | H26: =D26*Supuestos!$B$49 -> 12.312323 | I26: =Supuestos!$B$28 -> 14 | J26: =MIN(ROUNDDOWN(MIN(H26,I26)*2,0)/2,MAX(Supuestos!$B$23,ROUNDUP(G26*Supuestos!$B$22*2,0)/2)) -> 12 | K26: 12 | L26: =K26*1000/E26 -> 952.98602 | M26: según patrón | N26: =IF(F26=0,0,K26/F26*Supuestos!$B$32) -> 14.540204 | O26: =IF(K26=0,0,F26/K26) -> 16.505958
A27: Madre 2,0 mm | B27: Bobina madre | C27: =BobinaMadre!$D$76 -> 2 | D27: =BobinaMadre!$B$76 -> 1000 | E27: =D27*C27*Supuestos!$B$10/1000 -> 15.74 | F27: {=INDEX(BobinaMadre!$D$91:$M$91,MATCH(Supuestos!$B$21,Calculo!$D$4:$M$4,0))} -> 24.567812 | G27: =F27/12 -> 2.0473177 | H27: =D27*Supuestos!$B$49 -> 12.312323 | I27: =Supuestos!$B$28 -> 14 | J27: =MIN(ROUNDDOWN(MIN(H27,I27)*2,0)/2,MAX(Supuestos!$B$23,ROUNDUP(G27*Supuestos!$B$22*2,0)/2)) -> 2.5 | K27: 2.5 | L27: =K27*1000/E27 -> 158.831 | M27: según patrón | N27: =IF(F27=0,0,K27/F27*Supuestos!$B$32) -> 24.422199 | O27: =IF(K27=0,0,F27/K27) -> 9.8271248
A28: Madre 3,2 mm | B28: Bobina madre | C28: =BobinaMadre!$D$100 -> 3.2 | D28: =BobinaMadre!$B$100 -> 1500 | E28: =D28*C28*Supuestos!$B$10/1000 -> 37.776 | F28: {=INDEX(BobinaMadre!$D$113:$M$113,MATCH(Supuestos!$B$21,Calculo!$D$4:$M$4,0))} -> 40.613543 | G28: =F28/12 -> 3.3844619 | H28: =D28*Supuestos!$B$49 -> 18.468484 | I28: =Supuestos!$B$28 -> 14 | J28: =MIN(ROUNDDOWN(MIN(H28,I28)*2,0)/2,MAX(Supuestos!$B$23,ROUNDUP(G28*Supuestos!$B$22*2,0)/2)) -> 3.5 | K28: 3.5 | L28: =K28*1000/E28 -> 92.651419 | M28: según patrón | N28: =IF(F28=0,0,K28/F28*Supuestos!$B$32) -> 20.682756 | O28: =IF(K28=0,0,F28/K28) -> 11.603869
A29: Madre 4,75 mm | B29: Bobina madre | C29: =BobinaMadre!$D$122 -> 4.75 | D29: =BobinaMadre!$B$122 -> 1245 | E29: =D29*C29*Supuestos!$B$10/1000 -> 46.541213 | F29: {=INDEX(BobinaMadre!$D$133:$M$133,MATCH(Supuestos!$B$21,Calculo!$D$4:$M$4,0))} -> 22.262135 | G29: =F29/12 -> 1.8551779 | H29: =D29*Supuestos!$B$49 -> 15.328842 | I29: =Supuestos!$B$28 -> 14 | J29: =MIN(ROUNDDOWN(MIN(H29,I29)*2,0)/2,MAX(Supuestos!$B$23,ROUNDUP(G29*Supuestos!$B$22*2,0)/2)) -> 2 | K29: 2 | L29: =K29*1000/E29 -> 42.972666 | M29: según patrón | N29: =IF(F29=0,0,K29/F29*Supuestos!$B$32) -> 21.561274 | O29: =IF(K29=0,0,F29/K29) -> 11.131068
A31: • Cómo leerlo: si una bobina dura muy poco (pocos días) conviene subir el peso; si dura muchos meses, bajarlo para no inmovilizar stock.
A32: • El peso elegido es el máximo que se compra: en los primeros años, con poca demanda, el stock se calcula con bobinas más chicas (cobertura máxima en Supuestos).
A33: • Las bobinas angostas (flejes de disco) quedan limitadas por el diámetro exterior: a igual diámetro, un fleje de 200 mm pesa ~5 veces menos que una bobina de 1.000 mm.

Sheet Calculo
A1: Cálculo anual por opción
A2: No editar: todo sale de Supuestos, Demanda, Nesting, BobinaMadre y Bobinas.
A4: Concepto | B4: Espesor (mm) | C4: Acero | D4: 2026 | E4: 2027 | F4: 2028 | G4: 2029 | H4: 2030 | I4: 2031 | J4: 2032 | K4: 2033 | L4: 2034 | M4: 2035
A5: Período k (para descontar) | D5: 1 | E5: 2 | F5: 3 | G5: 4 | H5: 5 | I5: 6 | J5: 7 | K5: 8 | L5: 9 | M5: 10
A7: Unidades a fabricar
A8: 1 kg | D8: =Demanda!D30 -> 4179 | E8: =Demanda!E30 -> 5997 | F8: =Demanda!F30 -> 14514 | G8: =Demanda!G30 -> 35162 | H8: =Demanda!H30 -> 62116 | I8: =Demanda!I30 -> 87300 | J8: =Demanda!J30 -> 121674 | K8: =Demanda!K30 -> 156133 | ... M8: =Demanda!M30 -> 202621
A9: 2,5 kg | D9: =Demanda!D31 -> 295 | E9: =Demanda!E31 -> 709 | F9: =Demanda!F31 -> 1287 | G9: =Demanda!G31 -> 2545 | H9: =Demanda!H31 -> 4245 | I9: =Demanda!I31 -> 6055 | J9: =Demanda!J31 -> 8066 | K9: =Demanda!K31 -> 10228 | ... M9: =Demanda!M31 -> 14094
A10: 5 kg | D10: =Demanda!D32 -> 2256 | E10: =Demanda!E32 -> 3847 | F10: =Demanda!F32 -> 6573 | G10: =Demanda!G32 -> 11975 | H10: =Demanda!H32 -> 20360 | I10: =Demanda!I32 -> 28440 | J10: =Demanda!J32 -> 38437 | K10: =Demanda!K32 -> 48651 | ... M10: =Demanda!M32 -> 63666
A11: 10 kg | D11: =Demanda!D33 -> 92 | E11: =Demanda!E33 -> 177 | F11: =Demanda!F33 -> 343 | G11: =Demanda!G33 -> 673 | H11: =Demanda!H33 -> 1186 | I11: =Demanda!I33 -> 1718 | J11: =Demanda!J33 -> 2322 | K11: =Demanda!K33 -> 2940 | ... M11: =Demanda!M33 -> 3852
A12: 25 kg | D12: =Demanda!D34 -> 34 | E12: =Demanda!E34 -> 58 | F12: =Demanda!F34 -> 90 | G12: =Demanda!G34 -> 150 | H12: =Demanda!H34 -> 249 | I12: =Demanda!I34 -> 347 | J12: =Demanda!J34 -> 464 | K12: =Demanda!K34 -> 585 | ... M12: =Demanda!M34 -> 775
A13: 50 kg | D13: =Demanda!D35 -> 75 | E13: =Demanda!E35 -> 128 | F13: =Demanda!F35 -> 198 | G13: =Demanda!G35 -> 332 | H13: =Demanda!H35 -> 548 | I13: =Demanda!I35 -> 764 | J13: =Demanda!J35 -> 1020 | K13: =Demanda!K35 -> 1287 | ... M13: =Demanda!M35 -> 1705
A14: 70 kg | D14: =Demanda!D36 -> 16 | E14: =Demanda!E36 -> 29 | F14: =Demanda!F36 -> 43 | G14: =Demanda!G36 -> 72 | H14: =Demanda!H36 -> 119 | I14: =Demanda!I36 -> 166 | J14: =Demanda!J36 -> 223 | K14: =Demanda!K36 -> 282 | ... M14: =Demanda!M36 -> 373
A15: 100 kg | D15: =Demanda!D37 -> 11 | E15: =Demanda!E37 -> 18 | F15: =Demanda!F37 -> 29 | G15: =Demanda!G37 -> 49 | H15: =Demanda!H37 -> 80 | I15: =Demanda!I37 -> 110 | J15: =Demanda!J37 -> 147 | K15: =Demanda!K37 -> 186 | ... M15: =Demanda!M37 -> 247
A16: Total | D16: =SUM(D8:D15) -> 6958 | E16: =SUM(E8:E15) -> 10963 | F16: =SUM(F8:F15) -> 23077 | G16: =SUM(G8:G15) -> 50958 | H16: =SUM(H8:H15) -> 88903 | I16: =SUM(I8:I15) -> 124900 | J16: =SUM(J8:J15) -> 172353 | K16: =SUM(K8:K15) -> 220292 | ... M16: =SUM(M8:M15) -> 287333
A18: Acero neto en CUERPOS (t) — precio: chapa cortada a medida (referencia) | N18: USD/kg
A19: 2,5 kg | B19: =Nesting!$E$6 -> 1.25 | C19: =Nesting!$F$6 -> LAF | D19: =D9*Nesting!$G$6/1000 -> 0.3015018 | E19: =E9*Nesting!$G$6/1000 -> 0.72462637 | F19: =F9*Nesting!$G$6/1000 -> 1.3153655 | G19: =G9*Nesting!$G$6/1000 -> 2.6010918 | H19: =H9*Nesting!$G$6/1000 -> 4.3385598 | I19: =I9*Nesting!$G$6/1000 -> 6.1884523 | J19: =J9*Nesting!$G$6/1000 -> 8.2437747 | K19: =K9*Nesting!$G$6/1000 -> 10.453425 | ... M19: =M9*Nesting!$G$6/1000 -> 14.404632 | N19: {=INDEX(Supuestos!$F$84:$F$89,MATCH($B19,Supuestos!$A$84:$A$89,0))} -> 1.426
A20: 5 kg | B20: =Nesting!$E$7 -> 1.6 | C20: =Nesting!$F$7 -> LAF | D20: =D10*Nesting!$G$7/1000 -> 4.4481965 | E20: =E10*Nesting!$G$7/1000 -> 7.5852004 | F20: =F10*Nesting!$G$7/1000 -> 12.960105 | G20: =G10*Nesting!$G$7/1000 -> 23.611327 | H20: =H10*Nesting!$G$7/1000 -> 40.144185 | I20: =I10*Nesting!$G$7/1000 -> 56.075669 | J20: =J10*Nesting!$G$7/1000 -> 75.786937 | K20: =K10*Nesting!$G$7/1000 -> 95.926068 | ... M20: =M10*Nesting!$G$7/1000 -> 125.53142 | N20: {=INDEX(Supuestos!$F$84:$F$89,MATCH($B20,Supuestos!$A$84:$A$89,0))} -> 1.453
A21: 10 kg | B21: =Nesting!$E$8 -> 2 | C21: =Nesting!$F$8 -> LAF | D21: =D11*Nesting!$G$8/1000 -> 0.40355817 | E21: =E11*Nesting!$G$8/1000 -> 0.77641084 | F21: =F11*Nesting!$G$8/1000 -> 1.5045702 | G21: =G11*Nesting!$G$8/1000 -> 2.9521158 | H21: =H11*Nesting!$G$8/1000 -> 5.2023913 | I21: =I11*Nesting!$G$8/1000 -> 7.5360103 | J21: =J11*Nesting!$G$8/1000 -> 10.185457 | K21: =K11*Nesting!$G$8/1000 -> 12.896316 | ... M21: =M11*Nesting!$G$8/1000 -> 16.896805 | N21: {=INDEX(Supuestos!$F$84:$F$89,MATCH($B21,Supuestos!$A$84:$A$89,0))} -> 1.429
