Workbook

Sheet Resumen General
A1: RESUMEN GENERAL
A3: Indicador | B3: Valor | D3: Referencias
A4: Dotación año 10 (personas, con choferes) | B4: ='Servicios y Oficinas'!K42+'Almacen PT'!K105 -> 71 | D4: Dato | E4: Número azul = dato editable
A5: Máquinas de producción año 10 | B5: ='Resumen Capacidad'!K49+'Resumen Capacidad'!K228 -> 40 | E5: Pasa de manual a automática
A6: Máquinas de recargas año 10 | B6: ='Resumen Capacidad'!K299 -> 22 | E6: Agrega máquina
A7: Año del 2° turno | B7: ='Resumen Capacidad'!H50 -> 2032 | E7: Agrega turno
E8: Agrega operario
E9: Tercerizado
A11: Concepto | B11: 2026 | C11: 2027 | D11: 2028 | E11: 2029 | F11: 2030 | G11: 2031 | H11: 2032 | I11: 2033 | J11: 2034 | K11: 2035
A12: Demanda
A13: Matafuegos terminados (u) | B13: =SUM(datos_base!B3:B10) -> 6958 | C13: =SUM(datos_base!C3:C10) -> 10963 | D13: =SUM(datos_base!D3:D10) -> 13488 | E13: =SUM(datos_base!E3:E10) -> 17551 | F13: =SUM(datos_base!F3:F10) -> 27038 | G13: =SUM(datos_base!G3:G10) -> 35196 | H13: =SUM(datos_base!H3:H10) -> 45531 | I13: =SUM(datos_base!I3:I10) -> 56352 | ... K13: =SUM(datos_base!K3:K10) -> 73903
A14: Cilindros vendidos (u) | B14: =SUM(datos_base!B15:B22) -> 0 | C14: =SUM(datos_base!C15:C22) -> 0 | D14: =SUM(datos_base!D15:D22) -> 9589 | E14: =SUM(datos_base!E15:E22) -> 33407 | F14: =SUM(datos_base!F15:F22) -> 61865 | G14: =SUM(datos_base!G15:G22) -> 89704 | H14: =SUM(datos_base!H15:H22) -> 126822 | I14: =SUM(datos_base!I15:I22) -> 163940 | ... K14: =SUM(datos_base!K15:K22) -> 213430
A15: Recargas planta industrial (u) | B15: =datos_base!B73-datos_base!B66 -> 2338.1989 | C15: =datos_base!C73-datos_base!C66 -> 10498.783 | D15: =datos_base!D73-datos_base!D66 -> 21052.007 | E15: =datos_base!E73-datos_base!E66 -> 39050.558 | F15: =datos_base!F73-datos_base!F66 -> 57477.441 | G15: =datos_base!G73-datos_base!G66 -> 78232.252 | H15: =datos_base!H73-datos_base!H66 -> 97163.137 | I15: =datos_base!I73-datos_base!I66 -> 110459.95 | ... K15: =datos_base!K73-datos_base!K66 -> 127338.88
A16: Capacidad
A17: Turnos | B17: ='Resumen Capacidad'!B85 -> 1 | C17: ='Resumen Capacidad'!C85 -> 1 | D17: ='Resumen Capacidad'!D85 -> 1 | E17: ='Resumen Capacidad'!E85 -> 1 | F17: ='Resumen Capacidad'!F85 -> 1 | G17: ='Resumen Capacidad'!G85 -> 1 | H17: ='Resumen Capacidad'!H85 -> 2 | I17: ='Resumen Capacidad'!I85 -> 2 | ... K17: ='Resumen Capacidad'!K85 -> 2
A18: Máquinas producción 1–10 kg | B18: ='Resumen Capacidad'!B49 -> 19 | C18: ='Resumen Capacidad'!C49 -> 19 | D18: ='Resumen Capacidad'!D49 -> 19 | E18: ='Resumen Capacidad'!E49 -> 20 | F18: ='Resumen Capacidad'!F49 -> 24 | G18: ='Resumen Capacidad'!G49 -> 30 | H18: ='Resumen Capacidad'!H49 -> 30 | I18: ='Resumen Capacidad'!I49 -> 30 | ... K18: ='Resumen Capacidad'!K49 -> 31
A19: Máquinas línea de carros | B19: ='Resumen Capacidad'!B228 -> 8 | C19: ='Resumen Capacidad'!C228 -> 8 | D19: ='Resumen Capacidad'!D228 -> 8 | E19: ='Resumen Capacidad'!E228 -> 8 | F19: ='Resumen Capacidad'!F228 -> 8 | G19: ='Resumen Capacidad'!G228 -> 8 | H19: ='Resumen Capacidad'!H228 -> 8 | I19: ='Resumen Capacidad'!I228 -> 8 | ... K19: ='Resumen Capacidad'!K228 -> 9
A20: Guillotinas (corte de chapa) | B20: ='Resumen Capacidad'!B235 -> 1 | C20: ='Resumen Capacidad'!C235 -> 1 | D20: ='Resumen Capacidad'!D235 -> 1 | E20: ='Resumen Capacidad'!E235 -> 1 | F20: ='Resumen Capacidad'!F235 -> 1 | G20: ='Resumen Capacidad'!G235 -> 1 | H20: ='Resumen Capacidad'!H235 -> 1 | I20: ='Resumen Capacidad'!I235 -> 1 | ... K20: ='Resumen Capacidad'!K235 -> 1
A21: Máquinas recargas | B21: ='Resumen Capacidad'!B299 -> 17 | C21: ='Resumen Capacidad'!C299 -> 17 | D21: ='Resumen Capacidad'!D299 -> 17 | E21: ='Resumen Capacidad'!E299 -> 18 | F21: ='Resumen Capacidad'!F299 -> 19 | G21: ='Resumen Capacidad'!G299 -> 22 | H21: ='Resumen Capacidad'!H299 -> 22 | I21: ='Resumen Capacidad'!I299 -> 22 | ... K21: ='Resumen Capacidad'!K299 -> 22
A22: Ocupación pico máx. producción | B22: =MAX('Resumen Capacidad'!B5:B24) -> 0.23509265 | C22: =MAX('Resumen Capacidad'!C5:C24) -> 0.36805691 | D22: =MAX('Resumen Capacidad'!D5:D24) -> 0.78462444 | E22: =MAX('Resumen Capacidad'!E5:E24) -> 0.8045128 | F22: =MAX('Resumen Capacidad'!F5:F24) -> 0.84179365 | G22: =MAX('Resumen Capacidad'!G5:G24) -> 0.79461389 | H22: =MAX('Resumen Capacidad'!H5:H24) -> 0.85919407 | I22: =MAX('Resumen Capacidad'!I5:I24) -> 0.8866684 | ... K22: =MAX('Resumen Capacidad'!K5:K24) -> 0.87176973
A23: Dotación
A24: Producción 1–10 kg y carros (mañana) | B24: ='Dotacion Planta'!B102 -> 5 | C24: ='Dotacion Planta'!C102 -> 5 | D24: ='Dotacion Planta'!D102 -> 5 | E24: ='Dotacion Planta'!E102 -> 6 | F24: ='Dotacion Planta'!F102 -> 10 | G24: ='Dotacion Planta'!G102 -> 14 | H24: ='Dotacion Planta'!H102 -> 18 | I24: ='Dotacion Planta'!I102 -> 23 | ... K24: ='Dotacion Planta'!K102 -> 30
A25: Recargas (mañana) | B25: ='Dotacion Planta'!B103 -> 0 | C25: ='Dotacion Planta'!C103 -> 2 | D25: ='Dotacion Planta'!D103 -> 3 | E25: ='Dotacion Planta'!E103 -> 6 | F25: ='Dotacion Planta'!F103 -> 9 | G25: ='Dotacion Planta'!G103 -> 12 | H25: ='Dotacion Planta'!H103 -> 14 | I25: ='Dotacion Planta'!I103 -> 16 | ... K25: ='Dotacion Planta'!K103 -> 16
A26: Recargas (tarde: mostrador + recargas) | B26: ='Dotacion Planta'!B105 -> 0 | C26: ='Dotacion Planta'!C105 -> 0 | D26: ='Dotacion Planta'!D105 -> 0 | E26: ='Dotacion Planta'!E105 -> 0 | F26: ='Dotacion Planta'!F105 -> 0 | G26: ='Dotacion Planta'!G105 -> 0 | H26: ='Dotacion Planta'!H105 -> 2 | I26: ='Dotacion Planta'!I105 -> 2 | ... K26: ='Dotacion Planta'!K105 -> 2
A27: Turno tarde (pool de producción) | B27: ='Dotacion Planta'!B104 -> 0 | C27: ='Dotacion Planta'!C104 -> 0 | D27: ='Dotacion Planta'!D104 -> 0 | E27: ='Dotacion Planta'!E104 -> 0 | F27: ='Dotacion Planta'!F104 -> 0 | G27: ='Dotacion Planta'!G104 -> 0 | H27: ='Dotacion Planta'!H104 -> 1 | I27: ='Dotacion Planta'!I104 -> 2 | ... K27: ='Dotacion Planta'!K104 -> 6
A28: Encargados | B28: ='Dotacion Planta'!B106 -> 1 | C28: ='Dotacion Planta'!C106 -> 1 | D28: ='Dotacion Planta'!D106 -> 1 | E28: ='Dotacion Planta'!E106 -> 1 | F28: ='Dotacion Planta'!F106 -> 1 | G28: ='Dotacion Planta'!G106 -> 1 | H28: ='Dotacion Planta'!H106 -> 2 | I28: ='Dotacion Planta'!I106 -> 2 | ... K28: ='Dotacion Planta'!K106 -> 2
A29: Administración | B29: ='Servicios y Oficinas'!B29+'Servicios y Oficinas'!B30 -> 4 | C29: ='Servicios y Oficinas'!C29+'Servicios y Oficinas'!C30 -> 4 | D29: ='Servicios y Oficinas'!D29+'Servicios y Oficinas'!D30 -> 5 | E29: ='Servicios y Oficinas'!E29+'Servicios y Oficinas'!E30 -> 5 | F29: ='Servicios y Oficinas'!F29+'Servicios y Oficinas'!F30 -> 6 | G29: ='Servicios y Oficinas'!G29+'Servicios y Oficinas'!G30 -> 6 | H29: ='Servicios y Oficinas'!H29+'Servicios y Oficinas'!H30 -> 7 | I29: ='Servicios y Oficinas'!I29+'Servicios y Oficinas'!I30 -> 7 | ... K29: ='Servicios y Oficinas'!K29+'Servicios y Oficinas'!K30 -> 7
A30: Choferes de reparto | B30: ='Almacen PT'!B105 -> 2 | C30: ='Almacen PT'!C105 -> 2 | D30: ='Almacen PT'!D105 -> 2 | E30: ='Almacen PT'!E105 -> 3 | F30: ='Almacen PT'!F105 -> 4 | G30: ='Almacen PT'!G105 -> 5 | H30: ='Almacen PT'!H105 -> 6 | I30: ='Almacen PT'!I105 -> 7 | ... K30: ='Almacen PT'!K105 -> 8
A31: TOTAL PERSONAS | B31: =SUM(B24:B30) -> 12 | C31: =SUM(C24:C30) -> 14 | D31: =SUM(D24:D30) -> 16 | E31: =SUM(E24:E30) -> 21 | F31: =SUM(F24:F30) -> 30 | G31: =SUM(G24:G30) -> 38 | H31: =SUM(H24:H30) -> 50 | I31: =SUM(I24:I30) -> 59 | ... K31: =SUM(K24:K30) -> 71
A32: Horas extra por operario (h/año) | B32: ='Dotacion Planta'!B109 -> 0 | C32: ='Dotacion Planta'!C109 -> 0 | D32: ='Dotacion Planta'!D109 -> 13.573322 | E32: ='Dotacion Planta'!E109 -> 34.681861 | F32: ='Dotacion Planta'!F109 -> 32.097911 | G32: ='Dotacion Planta'!G109 -> 38.330056 | H32: ='Dotacion Planta'!H109 -> 37.306187 | I32: ='Dotacion Planta'!I109 -> 28.314623 | ... K32: ='Dotacion Planta'!K109 -> 21.867371
A33: Días de vacaciones promedio por persona | B33: ='Dotacion Planta'!B112 -> 14 | C33: ='Dotacion Planta'!C112 -> 14 | D33: ='Dotacion Planta'!D112 -> 14 | E33: ='Dotacion Planta'!E112 -> 14 | F33: ='Dotacion Planta'!F112 -> 14 | G33: ='Dotacion Planta'!G112 -> 16.121212 | H33: ='Dotacion Planta'!H112 -> 15.909091 | I33: ='Dotacion Planta'!I112 -> 15.884615 | ... K33: ='Dotacion Planta'!K112 -> 16.888889
A34: Horas de vacaciones de operarios (h/año) | B34: ='Dotacion Planta'!B111 -> 375 | C34: ='Dotacion Planta'!C111 -> 525 | D34: ='Dotacion Planta'!D111 -> 600 | E34: ='Dotacion Planta'!E111 -> 900 | F34: ='Dotacion Planta'!F111 -> 1425 | G34: ='Dotacion Planta'!G111 -> 2137.5 | H34: ='Dotacion Planta'!H111 -> 2887.5 | I34: ='Dotacion Planta'!I111 -> 3525 | ... K34: ='Dotacion Planta'!K111 -> 4762.5
A35: Stock
A36: Stock fabricado en oct–nov (u) | B36: ='Dotacion Planta'!B110 -> 792.21 | C36: ='Dotacion Planta'!C110 -> 1240.27 | D36: ='Dotacion Planta'!D110 -> 1765.1765 | E36: ='Dotacion Planta'!E110 -> 1771.7008 | F36: ='Dotacion Planta'!F110 -> 2810.6038 | G36: ='Dotacion Planta'!G110 -> 3950.6811 | H36: ='Dotacion Planta'!H110 -> 3738.0405 | I36: ='Dotacion Planta'!I110 -> 5096.5847 | ... K36: ='Dotacion Planta'!K110 -> 6343.1351
A37: Stock máximo de carros (u) | B37: ='Resumen Capacidad'!B198 -> 0 | C37: ='Resumen Capacidad'!C198 -> 0 | D37: ='Resumen Capacidad'!D198 -> 0 | E37: ='Resumen Capacidad'!E198 -> 0 | F37: ='Resumen Capacidad'!F198 -> 0 | G37: ='Resumen Capacidad'!G198 -> 0 | H37: ='Resumen Capacidad'!H198 -> 0 | I37: ='Resumen Capacidad'!I198 -> 0 | ... K37: ='Resumen Capacidad'!K198 -> 0
A38: Stock promedio de carros (u) | B38: ='Analisis de operaciones'!P2061 -> 0 | C38: ='Analisis de operaciones'!P2152 -> 0 | D38: ='Analisis de operaciones'!P2243 -> 0 | E38: ='Analisis de operaciones'!P2334 -> 0 | F38: ='Analisis de operaciones'!P2425 -> 0 | G38: ='Analisis de operaciones'!P2516 -> 0 | H38: ='Analisis de operaciones'!P2607 -> 0 | I38: ='Analisis de operaciones'!P2698 -> 0 | J38: ='Analisis de operaciones'!P2789 -> 0 | K38: ='Analisis de operaciones'!P2880 -> 0
A39: m² para el stock de carros | B39: ='Resumen Capacidad'!B199 -> 0 | C39: ='Resumen Capacidad'!C199 -> 0 | D39: ='Resumen Capacidad'!D199 -> 0 | E39: ='Resumen Capacidad'!E199 -> 0 | F39: ='Resumen Capacidad'!F199 -> 0 | G39: ='Resumen Capacidad'!G199 -> 0 | H39: ='Resumen Capacidad'!H199 -> 0 | I39: ='Resumen Capacidad'!I199 -> 0 | ... K39: ='Resumen Capacidad'!K199 -> 0
A40: Equipos de intercambio (flota, u) | B40: ='Almacen PT'!B85 -> 20 | C40: ='Almacen PT'!C85 -> 77 | D40: ='Almacen PT'!D85 -> 171 | E40: ='Almacen PT'!E85 -> 318 | F40: ='Almacen PT'!F85 -> 457 | G40: ='Almacen PT'!G85 -> 608 | H40: ='Almacen PT'!H85 -> 744 | I40: ='Almacen PT'!I85 -> 826 | ... K40: ='Almacen PT'!K85 -> 958
A41: Vehículos de reparto (milk run) | B41: ='Almacen PT'!B104 -> 2 | C41: ='Almacen PT'!C104 -> 2 | D41: ='Almacen PT'!D104 -> 2 | E41: ='Almacen PT'!E104 -> 3 | F41: ='Almacen PT'!F104 -> 4 | G41: ='Almacen PT'!G104 -> 5 | H41: ='Almacen PT'!H104 -> 6 | I41: ='Almacen PT'!I104 -> 7 | ... K41: ='Almacen PT'!K104 -> 8
A42: m² de almacén de PT + recargas de clientes | B42: ='Almacen PT'!B130 -> 36.878083 | C42: ='Almacen PT'!C130 -> 45.547648 | D42: ='Almacen PT'!D130 -> 56.933822 | E42: ='Almacen PT'!E130 -> 78.899847 | F42: ='Almacen PT'!F130 -> 120.92463 | G42: ='Almacen PT'!G130 -> 154.45928 | H42: ='Almacen PT'!H130 -> 182.85789 | I42: ='Almacen PT'!I130 -> 225.97466 | ... K42: ='Almacen PT'!K130 -> 273.64033

Sheet Parametros
B1: PERFILES DE ESTACIONALIDAD
A2: Perfil | B2: Enero | C2: Febrero | D2: marzo | E2: abril | F2: mayo | G2: junio | H2: julio | I2: agosto | J2: septiembre | K2: octubre | L2: noviembre | M2: diciembre | N2: Total | O2: Justificación del ajuste (sept. 2026)
A3: Automovilístico (1 kg) | B3: 0.12 | C3: 0.09 | D3: 0.08 | E3: 0.075 | F3: 0.07 | G3: 0.07 | H3: 0.075 | I3: 0.075 | J3: 0.075 | K3: 0.075 | L3: 0.075 | M3: 0.12 | N3: =SUM(B3:M3) -> 1
A4: Manual comercial (2,5 / 5 / 10 kg) | B4: 0.1 | C4: 0.08 | D4: 0.085 | E4: 0.085 | F4: 0.08 | G4: 0.075 | H4: 0.08 | I4: 0.08 | J4: 0.08 | K4: 0.075 | L4: 0.07 | M4: 0.11 | N4: =SUM(B4:M4) -> 1
A5: Industrial s/ruedas (25 – 100 kg) | B5: 0.085 | C5: 0.075 | D5: 0.09 | E5: 0.09 | F5: 0.09 | G5: 0.08 | H5: 0.09 | I5: 0.09 | J5: 0.085 | K5: 0.075 | L5: 0.07 | M5: 0.08 | N5: =SUM(B5:M5) -> 1
A6: Perfil ORIGINAL (referencia, reemplazado por el ajuste de arriba) → | B6: 0.16 | C6: 0.12 | D6: 0.09 | E6: 0.07 | F6: 0.05 | G6: 0.04 | H6: 0.05 | I6: 0.05 | J6: 0.06 | K6: 0.05 | L6: 0.04 | M6: 0.22 | N6: =SUM(B6:M6) -> 1
B7: 0.1 | C7: 0.08 | D7: 0.09 | E7: 0.09 | F7: 0.08 | G7: 0.07 | H7: 0.08 | I7: 0.08 | J7: 0.08 | K7: 0.06 | L7: 0.05 | M7: 0.14 | N7: =SUM(B7:M7) -> 1
B8: 0.08 | C8: 0.07 | D8: 0.09 | E8: 0.09 | F8: 0.09 | G8: 0.08 | H8: 0.09 | I8: 0.09 | J8: 0.08 | K8: 0.07 | L8: 0.06 | M8: 0.11 | N8: =SUM(B8:M8) -> 1
B9: MATRIZ POR TIPO
A10: Tipo | B10: Enero | C10: Febrero | D10: marzo | E10: abril | F10: mayo | G10: junio | H10: julio | I10: agosto | J10: septiembre | K10: octubre | L10: noviembre | M10: diciembre | N10: Total
A11: ABC 1 kg | B11: =B3 -> 0.12 | C11: =C3 -> 0.09 | D11: =D3 -> 0.08 | E11: =E3 -> 0.075 | F11: =F3 -> 0.07 | G11: =G3 -> 0.07 | H11: =H3 -> 0.075 | I11: =I3 -> 0.075 | ... M11: =M3 -> 0.12 | N11: =SUM(B11:M11) -> 1
A12: ABC 2,5 kg | B12: =B4 -> 0.1 | C12: =C4 -> 0.08 | D12: =D4 -> 0.085 | E12: =E4 -> 0.085 | F12: =F4 -> 0.08 | G12: =G4 -> 0.075 | H12: =H4 -> 0.08 | I12: =I4 -> 0.08 | ... M12: =M4 -> 0.11 | N12: =SUM(B12:M12) -> 1
A13: ABC 5 kg | B13: =B4 -> 0.1 | C13: =C4 -> 0.08 | D13: =D4 -> 0.085 | E13: =E4 -> 0.085 | F13: =F4 -> 0.08 | G13: =G4 -> 0.075 | H13: =H4 -> 0.08 | I13: =I4 -> 0.08 | ... M13: =M4 -> 0.11 | N13: =SUM(B13:M13) -> 1
A14: ABC 10 kg | B14: =B4 -> 0.1 | C14: =C4 -> 0.08 | D14: =D4 -> 0.085 | E14: =E4 -> 0.085 | F14: =F4 -> 0.08 | G14: =G4 -> 0.075 | H14: =H4 -> 0.08 | I14: =I4 -> 0.08 | ... M14: =M4 -> 0.11 | N14: =SUM(B14:M14) -> 1
A15: ABC 25 kg s/ruedas | B15: =B5 -> 0.085 | C15: =C5 -> 0.075 | D15: =D5 -> 0.09 | E15: =E5 -> 0.09 | F15: =F5 -> 0.09 | G15: =G5 -> 0.08 | H15: =H5 -> 0.09 | I15: =I5 -> 0.09 | ... M15: =M5 -> 0.08 | N15: =SUM(B15:M15) -> 1
A16: ABC 50 kg s/ruedas | B16: =B5 -> 0.085 | C16: =C5 -> 0.075 | D16: =D5 -> 0.09 | E16: =E5 -> 0.09 | F16: =F5 -> 0.09 | G16: =G5 -> 0.08 | H16: =H5 -> 0.09 | I16: =I5 -> 0.09 | ... M16: =M5 -> 0.08 | N16: =SUM(B16:M16) -> 1
A17: ABC 70 kg s/ruedas | B17: =B5 -> 0.085 | C17: =C5 -> 0.075 | D17: =D5 -> 0.09 | E17: =E5 -> 0.09 | F17: =F5 -> 0.09 | G17: =G5 -> 0.08 | H17: =H5 -> 0.09 | I17: =I5 -> 0.09 | ... M17: =M5 -> 0.08 | N17: =SUM(B17:M17) -> 1
A18: ABC 100 kg s/ruedas | B18: =B5 -> 0.085 | C18: =C5 -> 0.075 | D18: =D5 -> 0.09 | E18: =E5 -> 0.09 | F18: =F5 -> 0.09 | G18: =G5 -> 0.08 | H18: =H5 -> 0.09 | I18: =I5 -> 0.09 | ... M18: =M5 -> 0.08 | N18: =SUM(B18:M18) -> 1
A19: Cilindros ABC 1 kg | B19: =B3 -> 0.12 | C19: =C3 -> 0.09 | D19: =D3 -> 0.08 | E19: =E3 -> 0.075 | F19: =F3 -> 0.07 | G19: =G3 -> 0.07 | H19: =H3 -> 0.075 | I19: =I3 -> 0.075 | ... M19: =M3 -> 0.12 | N19: =SUM(B19:M19) -> 1
A20: Cilindros ABC 2,5 kg | B20: =B4 -> 0.1 | C20: =C4 -> 0.08 | D20: =D4 -> 0.085 | E20: =E4 -> 0.085 | F20: =F4 -> 0.08 | G20: =G4 -> 0.075 | H20: =H4 -> 0.08 | I20: =I4 -> 0.08 | ... M20: =M4 -> 0.11 | N20: =SUM(B20:M20) -> 1
A21: Cilindros ABC 5 kg | B21: =B4 -> 0.1 | C21: =C4 -> 0.08 | D21: =D4 -> 0.085 | E21: =E4 -> 0.085 | F21: =F4 -> 0.08 | G21: =G4 -> 0.075 | H21: =H4 -> 0.08 | I21: =I4 -> 0.08 | ... M21: =M4 -> 0.11 | N21: =SUM(B21:M21) -> 1
A22: Cilindros ABC 10 kg | B22: =B4 -> 0.1 | C22: =C4 -> 0.08 | D22: =D4 -> 0.085 | E22: =E4 -> 0.085 | F22: =F4 -> 0.08 | G22: =G4 -> 0.075 | H22: =H4 -> 0.08 | I22: =I4 -> 0.08 | ... M22: =M4 -> 0.11 | N22: =SUM(B22:M22) -> 1
A23: Cilindros ABC 25 kg | B23: =B5 -> 0.085 | C23: =C5 -> 0.075 | D23: =D5 -> 0.09 | E23: =E5 -> 0.09 | F23: =F5 -> 0.09 | G23: =G5 -> 0.08 | H23: =H5 -> 0.09 | I23: =I5 -> 0.09 | ... M23: =M5 -> 0.08 | N23: =SUM(B23:M23) -> 1
A24: Cilindros ABC 50 kg | B24: =B5 -> 0.085 | C24: =C5 -> 0.075 | D24: =D5 -> 0.09 | E24: =E5 -> 0.09 | F24: =F5 -> 0.09 | G24: =G5 -> 0.08 | H24: =H5 -> 0.09 | I24: =I5 -> 0.09 | ... M24: =M5 -> 0.08 | N24: =SUM(B24:M24) -> 1
A25: Cilindros ABC 70 kg | B25: =B5 -> 0.085 | C25: =C5 -> 0.075 | D25: =D5 -> 0.09 | E25: =E5 -> 0.09 | F25: =F5 -> 0.09 | G25: =G5 -> 0.08 | H25: =H5 -> 0.09 | I25: =I5 -> 0.09 | ... M25: =M5 -> 0.08 | N25: =SUM(B25:M25) -> 1
A26: Cilindros ABC 100 kg | B26: =B5 -> 0.085 | C26: =C5 -> 0.075 | D26: =D5 -> 0.09 | E26: =E5 -> 0.09 | F26: =F5 -> 0.09 | G26: =G5 -> 0.08 | H26: =H5 -> 0.09 | I26: =I5 -> 0.09 | ... M26: =M5 -> 0.08 | N26: =SUM(B26:M26) -> 1
B36: CAPACIDAD REAL POR PUESTO — ÍNDICE MAESTRO (Tiempo Total de Operación PCP + líneas Firesafer)
A37: Días hábiles/mes: | B37: 20 | C37: Horas/día (1 turno): | D37: 8 | E37: Horas productivas/mes: | F37: =B37*J37 -> 150 | G37: Refrigerio (min/turno) — CCT 260/75 art. 20: | H37: 30 | I37: Horas productivas/turno: | J37: =D37-H37/60 -> 7.5
A38: Puesto | B38: Proceso | C38: Máquina | D38: ta — T. operación (seg/u) | E38: u/seg | F38: u/min | G38: Cap. nominal (u/h) | H38: tpr — Preparación (seg/unid) | I38: tdl — Desalist. (seg/unid) | J38: Rendim. (n) | K38: Tt operación (seg/u) | L38: Tiempo tipo (seg/u) | M38: Cap. real (u/h) | N38: Cap. real (u/mes) | O38: APLICA | P38: Cambio de matriz (min/cambio) | Q38: N° cambios/mes (est.) | R38: Pérdida por cambios (h/mes) | S38: Disponibilidad (cambios) | T38: Observaciones
A39: Preparación de cuello | B39: Punzonado del alojamiento de válvula y preparación de la boca en la cúpula | C39: https://www.pannier.com/es/marking/stamp-marking-machines/benchtop-presses/ | D39: =1/E39 -> 60 | E39: =F39/60 -> 0.016666667 | F39: 1 | G39: 240 | H39: 20 | I39: 10 | J39: 0.85 | K39: =I39+H39+3600/G39 -> 45 | L39: =K39/J39 -> 52.941176 | M39: =3600/L39*S39 -> 68 | N39: =$F$37*M39 -> 10200 | O39: 1,2.5,5,10 | P39: 0 | Q39: 0 | R39: =P39*Q39/60 -> 0 | S39: =MAX(0,1-R39/$F$37) -> 1
A40: Soldadura circunferencial cuello | B40: Soldadura del asiento de válvula a la cúpula (plato indexado) | C40: Soldadura manual | D40: =1/E40 -> 60 | E40: =F40/60 -> 0.016666667 | F40: 1 | G40: 80 | H40: 10 | I40: 5 | J40: 0.7 | K40: =I40+H40+3600/G40 -> 60 | L40: =K40/J40 -> 85.714286 | M40: =3600/L40*S40 -> 40.88 | N40: =$F$37*M40 -> 6132 | O40: Manuales | P40: 15 | Q40: 16 | R40: =P40*Q40/60 -> 4 | S40: =MAX(0,1-R40/$F$37) -> 0.97333333
A41: Corte de disco y embutido (cúpula y fondo) | B41: Corte de disco y embutido profundo de cúpula y fondo (2 piezas por matafuego) | C41: https://www.directindustry.es/prod/sangiacomo-presse/product-16556-37404.html | D41: =1/E41 -> 10 | E41: =F41/60 -> 0.1 | F41: =60/10 -> 6 | G41: 1200 | H41: =30*60/1000 -> 1.8 | I41: =6*60/1000 -> 0.36 | J41: 0.85 | K41: =I41+H41+3600/G41 -> 5.16 | L41: =K41/J41 -> 6.0705882 | M41: =3600/L41*S41 -> 466.51163 | N41: =$F$37*M41 -> 69976.744 | O41: Manuales | P41: 120 | Q41: 16 | R41: =P41*Q41/60 -> 32 | S41: =MAX(0,1-R41/$F$37) -> 0.78666667
A42: Numerado de cuerpo | B42: Grabado/rolado del número de serie sobre el cuerpo | C42: https://www.pannier.com/es/marking/stamp-marking-machines/benchtop-presses/ | D42: =1/E42 -> 20 | E42: =F42/60 -> 0.05 | F42: 3 | G42: 240 | H42: 10 | I42: 5 | J42: 0.8 | K42: =I42+H42+3600/G42 -> 30 | L42: =K42/J42 -> 37.5 | M42: =3600/L42*S42 -> 96 | N42: =$F$37*M42 -> 14400 | O42: 2.5,5,10 | P42: 0 | Q42: 0 | R42: =P42*Q42/60 -> 0 | S42: =MAX(0,1-R42/$F$37) -> 1 | T42: Incluye el 1 kg: se graba la cúpula con cabezal numerador automático (IRAM 3523 5.1).
A43: Cilindrado | B43: Curvado de la chapa a forma cilíndrica (rodillos) | C43: FS-RM01 | D43: =1/E43 -> 80 | E43: =F43/60 -> 0.0125 | F43: =45/60 -> 0.75 | G43: 130 | H43: 5 | I43: 5 | J43: 0.85 | K43: =I43+H43+3600/G43 -> 37.692308 | L43: =K43/J43 -> 44.343891 | M43: =3600/L43*S43 -> 80.101224 | N43: =$F$37*M43 -> 12015.184 | O43: 2,5 a 10 | P43: 10 | Q43: 12 | R43: =P43*Q43/60 -> 2 | S43: =MAX(0,1-R43/$F$37) -> 0.98666667
A44: Soldadura longitudinal | B44: Soldadura MAG (ER70S-6) de la costura longitudinal del cuerpo | C44: Soldadura manual | D44: =1/E44 -> 120 | E44: =F44/60 -> 0.0083333333 | F44: 0.5 | G44: 40 | H44: 30 | I44: 15 | J44: 0.7 | K44: =I44+H44+3600/G44 -> 135 | L44: =K44/J44 -> 192.85714 | M44: =3600/L44*S44 -> 18.542222 | N44: =$F$37*M44 -> 2781.3333 | O44: 2,5 a 10 | P44: 5 | Q44: 12 | R44: =P44*Q44/60 -> 1 | S44: =MAX(0,1-R44/$F$37) -> 0.99333333 | T44: Automática desde el año 1 (IRAM 3523 3.2.4.2).
A45: Encastre de fondo | B45: Reducción/encastre del extremo para alojar el fondo | C45: Prensa Hidráulica Motorizada | D45: =1/E45 -> 30 | E45: =F45/60 -> 0.033333333 | F45: 2 | G45: 120 | H45: 15 | I45: 5 | J45: 0.85 | K45: =I45+H45+3600/G45 -> 50 | L45: =K45/J45 -> 58.823529 | M45: =3600/L45*S45 -> 60.656 | N45: =$F$37*M45 -> 9098.4 | O45: Manuales | P45: 5 | Q45: 16 | R45: =P45*Q45/60 -> 1.3333333 | S45: =MAX(0,1-R45/$F$37) -> 0.99111111
A46: Bordoneado | B46: Bordoneado/rebordeado del cuerpo y del aro de base | C46: Bordoneadora Pilman | D46: =1/E46 -> 45 | E46: =F46/60 -> 0.022222222 | F46: =60/45 -> 1.3333333 | G46: 600 | H46: 5 | I46: 5 | J46: 0.85 | K46: =I46+H46+3600/G46 -> 16 | L46: =K46/J46 -> 18.823529 | M46: =3600/L46*S46 -> 187.425 | N46: =$F$37*M46 -> 28113.75 | O46: Manuales | P46: 15 | Q46: 12 | R46: =P46*Q46/60 -> 3 | S46: =MAX(0,1-R46/$F$37) -> 0.98
A47: Soldadura circunferencial (cúpula y fondo) | B47: Soldadura circunferencial segmentada cúpula–cuerpo–fondo | C47: Soldadura manual | D47: =1/E47 -> 200 | E47: =F47/60 -> 0.005 | F47: 0.3 | G47: 30 | H47: 30 | I47: 5 | J47: 0.7 | K47: =I47+H47+3600/G47 -> 155 | L47: =K47/J47 -> 221.42857 | M47: =3600/L47*S47 -> 15.969032 | N47: =$F$37*M47 -> 2395.3548 | O47: Manuales | P47: 10 | Q47: 16 | R47: =P47*Q47/60 -> 2.6666667 | S47: =MAX(0,1-R47/$F$37) -> 0.98222222 | T47: Automática desde el año 1 (IRAM 3523 3.2.4.2).
A48: Prueba hidráulica | B48: Ensayo hidráulico a presión (tanque multiposición) | C48: Yukon M-000200 | D48: 120 | E48: =F48/60 -> 0.0083333333 | F48: 0.5 | G48: 30 | H48: 10 | I48: 5 | J48: 0.85 | K48: =I48+H48+3600/G48 -> 135 | L48: =K48/J48 -> 158.82353 | M48: =3600/L48*S48 -> 22.465185 | N48: =$F$37*M48 -> 3369.7778 | O48: Manuales | P48: 5 | Q48: 16 | R48: =P48*Q48/60 -> 1.3333333 | S48: =MAX(0,1-R48/$F$37) -> 0.99111111
A49: Granallado | B49: Granallado centrífugo S330/S390 (línea power & free) CyM | C49: G-100 (Blastair) | D49: =1/E49 -> 30 | E49: =F49/60 -> 0.033333333 | F49: 2 | G49: 200 | H49: 10 | I49: 15 | J49: 0.85 | K49: =I49+H49+3600/G49 -> 43 | L49: =K49/J49 -> 50.588235 | M49: =3600/L49*S49 -> 71.162791 | N49: =$F$37*M49 -> 10674.419 | O49: Manuales | P49: 0 | Q49: 16 | R49: =P49*Q49/60 -> 0 | S49: =MAX(0,1-R49/$F$37) -> 1
...

Sheet Resumen Capacidad
A1: RESUMEN DE CAPACIDAD Y DECISIONES DE MÁQUINA (pico mensual por año)
A2: Ocupación pico = demanda del mes pico ÷ (cap. real × máquinas × turnos del puesto). Sin color = solo cambió la demanda.
A4: Puesto | B4: 2026 | C4: 2027 | D4: 2028 | E4: 2029 | F4: 2030 | G4: 2031 | H4: 2032 | I4: 2033 | J4: 2034 | K4: 2035
A5: Preparación de cuello | B5: =MAX('Analisis de operaciones'!C11:N11) -> 0.077667647 | C5: =MAX('Analisis de operaciones'!C194:N194) -> 0.1215951 | D5: =MAX('Analisis de operaciones'!C377:N377) -> 0.25921667 | E5: =MAX('Analisis de operaciones'!C560:N560) -> 0.57751667 | F5: =MAX('Analisis de operaciones'!C743:N743) -> 0.50445735 | G5: =MAX('Analisis de operaciones'!C926:N926) -> 0.70879559 | H5: =MAX('Analisis de operaciones'!C1109:N1109) -> 0.48950074 | I5: =MAX('Analisis de operaciones'!C1292:N1292) -> 0.62588358 | J5: =MAX('Analisis de operaciones'!C1475:N1475) -> 0.70615907 | K5: =MAX('Analisis de operaciones'!C1658:N1658) -> 0.81597647
A6: Soldadura circunferencial cuello (rosca) | B6: =MAX('Analisis de operaciones'!C21:N21) -> 0.12919276 | C6: =MAX('Analisis de operaciones'!C204:N204) -> 0.2022619 | D6: =MAX('Analisis de operaciones'!C387:N387) -> 0.43118232 | E6: =MAX('Analisis de operaciones'!C570:N570) -> 0.4354092 | F6: =MAX('Analisis de operaciones'!C753:N753) -> 0.76065466 | G6: =MAX('Analisis de operaciones'!C936:N936) -> 0.53438479 | H6: =MAX('Analisis de operaciones'!C1119:N1119) -> 0.73810207 | I6: =MAX('Analisis de operaciones'!C1302:N1302) -> 0.47187464 | J6: =MAX('Analisis de operaciones'!C1485:N1485) -> 0.53239703 | K6: =MAX('Analisis de operaciones'!C1668:N1668) -> 0.61519205
A7: Corte de disco y embutido (cúpula y fondo) | B7: =MAX('Analisis de operaciones'!C31:N31) -> 0.022642094 | C7: =MAX('Analisis de operaciones'!C214:N214) -> 0.035448062 | D7: =MAX('Analisis de operaciones'!C397:N397) -> 0.075568249 | E7: =MAX('Analisis de operaciones'!C580:N580) -> 0.16836079 | F7: =MAX('Analisis de operaciones'!C763:N763) -> 0.29412429 | G7: =MAX('Analisis de operaciones'!C946:N946) -> 0.41326387 | H7: =MAX('Analisis de operaciones'!C1129:N1129) -> 0.57080764 | I7: =MAX('Analisis de operaciones'!C1312:N1312) -> 0.7298439 | J7: =MAX('Analisis de operaciones'!C1495:N1495) -> 0.82345329 | K7: =MAX('Analisis de operaciones'!C1678:N1678) -> 0.47575577
A8: Numerado de cuerpo | B8: =MAX('Analisis de operaciones'!C41:N41) -> 0.055014583 | C8: =MAX('Analisis de operaciones'!C224:N224) -> 0.086129861 | D8: =MAX('Analisis de operaciones'!C407:N407) -> 0.18361181 | E8: =MAX('Analisis de operaciones'!C590:N590) -> 0.40907431 | F8: =MAX('Analisis de operaciones'!C773:N773) -> 0.71464792 | G8: =MAX('Analisis de operaciones'!C956:N956) -> 0.50206354 | H8: =MAX('Analisis de operaciones'!C1139:N1139) -> 0.69345937 | I8: =MAX('Analisis de operaciones'!C1322:N1322) -> 0.8866684 | J8: =MAX('Analisis de operaciones'!C1505:N1505) -> 0.50019601 | K8: =MAX('Analisis de operaciones'!C1688:N1688) -> 0.57798333
A9: Cilindrado | B9: =MAX('Analisis de operaciones'!C51:N51) -> 0.024196884 | C9: =MAX('Analisis de operaciones'!C234:N234) -> 0.043331006 | D9: =MAX('Analisis de operaciones'!C417:N417) -> 0.075099143 | E9: =MAX('Analisis de operaciones'!C600:N600) -> 0.13909317 | F9: =MAX('Analisis de operaciones'!C783:N783) -> 0.23611874 | G9: =MAX('Analisis de operaciones'!C966:N966) -> 0.33153301 | H9: =MAX('Analisis de operaciones'!C1149:N1149) -> 0.44699691 | I9: =MAX('Analisis de operaciones'!C1332:N1332) -> 0.56595806 | J9: =MAX('Analisis de operaciones'!C1515:N1515) -> 0.6461932 | K9: =MAX('Analisis de operaciones'!C1698:N1698) -> 0.74716461
A10: Soldadura longitudinal | B10: =MAX('Analisis de operaciones'!C61:N61) -> 0.034258343 | C10: =MAX('Analisis de operaciones'!C244:N244) -> 0.061348746 | D10: =MAX('Analisis de operaciones'!C427:N427) -> 0.10632659 | E10: =MAX('Analisis de operaciones'!C610:N610) -> 0.19693038 | F10: =MAX('Analisis de operaciones'!C793:N793) -> 0.33430076 | G10: =MAX('Analisis de operaciones'!C976:N976) -> 0.46938985 | H10: =MAX('Analisis de operaciones'!C1159:N1159) -> 0.63286553 | I10: =MAX('Analisis de operaciones'!C1342:N1342) -> 0.80129266 | J10: =MAX('Analisis de operaciones'!C1525:N1525) -> 0.45744544 | K10: =MAX('Analisis de operaciones'!C1708:N1708) -> 0.52892393
A11: Encastre de fondo | B11: =MAX('Analisis de operaciones'!C71:N71) -> 0.087071353 | C11: =MAX('Analisis de operaciones'!C254:N254) -> 0.13631737 | D11: =MAX('Analisis de operaciones'!C437:N437) -> 0.29060164 | E11: =MAX('Analisis de operaciones'!C620:N620) -> 0.64744021 | F11: =MAX('Analisis de operaciones'!C803:N803) -> 0.56553515 | G11: =MAX('Analisis de operaciones'!C986:N986) -> 0.79461389 | H11: =MAX('Analisis de operaciones'!C1169:N1169) -> 0.54876764 | I11: =MAX('Analisis de operaciones'!C1352:N1352) -> 0.7016632 | J11: =MAX('Analisis de operaciones'!C1535:N1535) -> 0.79165815 | K11: =MAX('Analisis de operaciones'!C1718:N1718) -> 0.60984789
A12: Bordoneado | B12: =MAX('Analisis de operaciones'!C81:N81) -> 0.028178738 | C12: =MAX('Analisis de operaciones'!C264:N264) -> 0.044116135 | D12: =MAX('Analisis de operaciones'!C447:N447) -> 0.094046863 | E12: =MAX('Analisis de operaciones'!C630:N630) -> 0.20952986 | F12: =MAX('Analisis de operaciones'!C813:N813) -> 0.36604615 | G12: =MAX('Analisis de operaciones'!C996:N996) -> 0.51431879 | H12: =MAX('Analisis de operaciones'!C1179:N1179) -> 0.71038655 | I12: =MAX('Analisis de operaciones'!C1362:N1362) -> 0.45415588 | J12: =MAX('Analisis de operaciones'!C1545:N1545) -> 0.51240567 | K12: =MAX('Analisis de operaciones'!C1728:N1728) -> 0.59209177 | N12: Pasa de manual a automática
A13: Soldadura circunferencial (cúpula y fondo) | B13: =MAX('Analisis de operaciones'!C91:N91) -> 0.082978255 | C13: =MAX('Analisis de operaciones'!C274:N274) -> 0.12990929 | D13: =MAX('Analisis de operaciones'!C457:N457) -> 0.27694088 | E13: =MAX('Analisis de operaciones'!C640:N640) -> 0.61700499 | F13: =MAX('Analisis de operaciones'!C823:N823) -> 0.53895016 | G13: =MAX('Analisis de operaciones'!C1006:N1006) -> 0.75726024 | H13: =MAX('Analisis de operaciones'!C1189:N1189) -> 0.52297087 | I13: =MAX('Analisis de operaciones'!C1372:N1372) -> 0.66867904 | J13: =MAX('Analisis de operaciones'!C1555:N1555) -> 0.75444345 | K13: =MAX('Analisis de operaciones'!C1738:N1738) -> 0.87176973 | N13: Agrega máquina
A14: Prueba hidráulica | B14: =MAX('Analisis de operaciones'!C101:N101) -> 0.23509265 | C14: =MAX('Analisis de operaciones'!C284:N284) -> 0.36805691 | D14: =MAX('Analisis de operaciones'!C467:N467) -> 0.78462444 | E14: =MAX('Analisis de operaciones'!C650:N650) -> 0.45320815 | F14: =MAX('Analisis de operaciones'!C833:N833) -> 0.79174921 | G14: =MAX('Analisis de operaciones'!C1016:N1016) -> 0.55622972 | H14: =MAX('Analisis de operaciones'!C1199:N1199) -> 0.7682747 | I14: =MAX('Analisis de operaciones'!C1382:N1382) -> 0.49116424 | J14: =MAX('Analisis de operaciones'!C1565:N1565) -> 0.5541607 | K14: =MAX('Analisis de operaciones'!C1748:N1748) -> 0.64034028 | N14: Agrega turno
A15: Granallado | B15: =MAX('Analisis de operaciones'!C111:N111) -> 0.027236144 | C15: =MAX('Analisis de operaciones'!C294:N294) -> 0.048773617 | D15: =MAX('Analisis de operaciones'!C477:N477) -> 0.084532004 | E15: =MAX('Analisis de operaciones'!C660:N660) -> 0.15656403 | F15: =MAX('Analisis de operaciones'!C843:N843) -> 0.26577654 | G15: =MAX('Analisis de operaciones'!C1026:N1026) -> 0.37317536 | H15: =MAX('Analisis de operaciones'!C1209:N1209) -> 0.50314216 | I15: =MAX('Analisis de operaciones'!C1392:N1392) -> 0.63704547 | J15: =MAX('Analisis de operaciones'!C1575:N1575) -> 0.72735858 | K15: =MAX('Analisis de operaciones'!C1758:N1758) -> 0.84101255 | N15: Agrega operario (puesto manual)
A16: Detección de defectos (CC) | B16: =MAX('Analisis de operaciones'!C121:N121) -> 0.027507292 | C16: =MAX('Analisis de operaciones'!C304:N304) -> 0.043064931 | D16: =MAX('Analisis de operaciones'!C487:N487) -> 0.091805903 | E16: =MAX('Analisis de operaciones'!C670:N670) -> 0.20453715 | F16: =MAX('Analisis de operaciones'!C853:N853) -> 0.35732396 | G16: =MAX('Analisis de operaciones'!C1036:N1036) -> 0.50206354 | H16: =MAX('Analisis de operaciones'!C1219:N1219) -> 0.69345937 | I16: =MAX('Analisis de operaciones'!C1402:N1402) -> 0.8866684 | J16: =MAX('Analisis de operaciones'!C1585:N1585) -> 0.50019601 | K16: =MAX('Analisis de operaciones'!C1768:N1768) -> 0.57798333 | N16: Tercerizado
A17: Corrección de defectos | B17: =MAX('Analisis de operaciones'!C1841:N1841) -> 0.012874161 | C17: =MAX('Analisis de operaciones'!C1863:N1863) -> 0.020155559 | D17: =MAX('Analisis de operaciones'!C1885:N1885) -> 0.042967661 | E17: =MAX('Analisis de operaciones'!C1907:N1907) -> 0.095728953 | F17: =MAX('Analisis de operaciones'!C1929:N1929) -> 0.16723734 | G17: =MAX('Analisis de operaciones'!C1951:N1951) -> 0.2349794 | H17: =MAX('Analisis de operaciones'!C1973:N1973) -> 0.32455786 | I17: =MAX('Analisis de operaciones'!C1995:N1995) -> 0.41498494 | J17: =MAX('Analisis de operaciones'!C2017:N2017) -> 0.46821068 | K17: =MAX('Analisis de operaciones'!C2039:N2039) -> 0.54102385 | N17: Sin color: solo cambió la demanda
A18: Pintura + Horno (cil. 1–10 kg; carros tercerizados) | B18: =IF(B42=0,"Tercerizado",MAX('Analisis de operaciones'!C131:N131)) -> Tercerizado | C18: =IF(C42=0,"Tercerizado",MAX('Analisis de operaciones'!C314:N314)) -> Tercerizado | D18: =IF(D42=0,"Tercerizado",MAX('Analisis de operaciones'!C497:N497)) -> Tercerizado | E18: =IF(E42=0,"Tercerizado",MAX('Analisis de operaciones'!C680:N680)) -> 0.28871009 | F18: =IF(F42=0,"Tercerizado",MAX('Analisis de operaciones'!C863:N863)) -> 0.50437307 | G18: =IF(G42=0,"Tercerizado",MAX('Analisis de operaciones'!C1046:N1046)) -> 0.70867716 | H18: =IF(H42=0,"Tercerizado",MAX('Analisis de operaciones'!C1229:N1229)) -> 0.48941895 | I18: =IF(I42=0,"Tercerizado",MAX('Analisis de operaciones'!C1412:N1412)) -> 0.625779 | J18: =IF(J42=0,"Tercerizado",MAX('Analisis de operaciones'!C1595:N1595)) -> 0.70604108 | K18: =IF(K42=0,"Tercerizado",MAX('Analisis de operaciones'!C1778:N1778)) -> 0.81584013
A19: Carga de polvo | B19: =MAX('Analisis de operaciones'!C141:N141) -> 0.091129261 | C19: =MAX('Analisis de operaciones'!C324:N324) -> 0.14320281 | D19: =MAX('Analisis de operaciones'!C507:N507) -> 0.17582418 | E19: =MAX('Analisis de operaciones'!C690:N690) -> 0.2284214 | F19: =MAX('Analisis de operaciones'!C873:N873) -> 0.35154451 | G19: =MAX('Analisis de operaciones'!C1056:N1056) -> 0.45713668 | H19: =MAX('Analisis de operaciones'!C1239:N1239) -> 0.59144697 | I19: =MAX('Analisis de operaciones'!C1422:N1422) -> 0.73201705 | J19: =MAX('Analisis de operaciones'!C1605:N1605) -> 0.84315641 | K19: =MAX('Analisis de operaciones'!C1788:N1788) -> 0.47979995
A20: Ensamblaje | B20: =MAX('Analisis de operaciones'!C151:N151) -> 0.21821429 | C20: =MAX('Analisis de operaciones'!C334:N334) -> 0.34290741 | D20: =MAX('Analisis de operaciones'!C517:N517) -> 0.42102116 | E20: =MAX('Analisis de operaciones'!C700:N700) -> 0.54696825 | F20: =MAX('Analisis de operaciones'!C883:N883) -> 0.84179365 | G20: =MAX('Analisis de operaciones'!C1066:N1066) -> 0.54732011 | H20: =MAX('Analisis de operaciones'!C1249:N1249) -> 0.70812698 | I20: =MAX('Analisis de operaciones'!C1432:N1432) -> 0.87642857 | J20: =MAX('Analisis de operaciones'!C1615:N1615) -> 0.50474669 | K20: =MAX('Analisis de operaciones'!C1798:N1798) -> 0.57445437
A21: Presurización | B21: =MAX('Analisis de operaciones'!C161:N161) -> 0.13238333 | C21: =MAX('Analisis de operaciones'!C344:N344) -> 0.20803049 | D21: =MAX('Analisis de operaciones'!C527:N527) -> 0.25541951 | E21: =MAX('Analisis de operaciones'!C710:N710) -> 0.33182741 | F21: =MAX('Analisis de operaciones'!C893:N893) -> 0.51068815 | G21: =MAX('Analisis de operaciones'!C1076:N1076) -> 0.66408173 | H21: =MAX('Analisis de operaciones'!C1259:N1259) -> 0.85919407 | I21: =MAX('Analisis de operaciones'!C1442:N1442) -> 0.5317 | J21: =MAX('Analisis de operaciones'!C1625:N1625) -> 0.61242599 | K21: =MAX('Analisis de operaciones'!C1808:N1808) -> 0.69700463
A22: Etiquetado | B22: =MAX('Analisis de operaciones'!C171:N171) -> 0.12001786 | C22: =MAX('Analisis de operaciones'!C354:N354) -> 0.18859907 | D22: =MAX('Analisis de operaciones'!C537:N537) -> 0.23156164 | E22: =MAX('Analisis de operaciones'!C720:N720) -> 0.30083254 | F22: =MAX('Analisis de operaciones'!C903:N903) -> 0.46298651 | G22: =MAX('Analisis de operaciones'!C1086:N1086) -> 0.60205212 | H22: =MAX('Analisis de operaciones'!C1269:N1269) -> 0.77893968 | I22: =MAX('Analisis de operaciones'!C1452:N1452) -> 0.48203571 | J22: =MAX('Analisis de operaciones'!C1635:N1635) -> 0.55522136 | K22: =MAX('Analisis de operaciones'!C1818:N1818) -> 0.6318998
A23: Embalaje y palletizado | B23: =MAX('Analisis de operaciones'!C181:N181) -> 0.10819535 | C23: =MAX('Analisis de operaciones'!C364:N364) -> 0.16938873 | D23: =MAX('Analisis de operaciones'!C547:N547) -> 0.36110322 | E23: =MAX('Analisis de operaciones'!C730:N730) -> 0.8045128 | F23: =MAX('Analisis de operaciones'!C913:N913) -> 0.70273712 | G23: =MAX('Analisis de operaciones'!C1096:N1096) -> 0.65826109 | H23: =MAX('Analisis de operaciones'!C1279:N1279) -> 0.45460115 | I23: =MAX('Analisis de operaciones'!C1462:N1462) -> 0.5812604 | J23: =MAX('Analisis de operaciones'!C1645:N1645) -> 0.65581254 | K23: =MAX('Analisis de operaciones'!C1828:N1828) -> 0.75780037
A24: Cortadora de plasma (1kg) | B24: =MAX('Analisis de operaciones'!C1851:N1851) -> 0.044449003 | C24: =MAX('Analisis de operaciones'!C1873:N1873) -> 0.063785755 | D24: =MAX('Analisis de operaciones'!C1895:N1895) -> 0.15437493 | E24: =MAX('Analisis de operaciones'!C1917:N1917) -> 0.37399278 | F24: =MAX('Analisis de operaciones'!C1939:N1939) -> 0.660683 | G24: =MAX('Analisis de operaciones'!C1961:N1961) -> 0.4642735 | H24: =MAX('Analisis de operaciones'!C1983:N1983) -> 0.6470792 | I24: =MAX('Analisis de operaciones'!C2005:N2005) -> 0.83033694 | J24: =MAX('Analisis de operaciones'!C2027:N2027) -> 0.46638215 | K24: =MAX('Analisis de operaciones'!C2049:N2049) -> 0.53878329
A26: MÁQUINAS
A28: Puesto | B28: 2026 | C28: 2027 | D28: 2028 | E28: 2029 | F28: 2030 | G28: 2031 | H28: 2032 | I28: 2033 | J28: 2034 | K28: 2035
A29: Preparación de cuello | B29: =MAX(1,B133) -> 1 | C29: =MAX(B29,C133) -> 1 | D29: =MAX(C29,D133) -> 1 | E29: =MAX(D29,E133) -> 1 | F29: =MAX(E29,F133) -> 2 | G29: =MAX(F29,G133) -> 2 | H29: =MAX(G29,H133) -> 2 | I29: =MAX(H29,I133) -> 2 | J29: =MAX(I29,J133) -> 2 | K29: =MAX(J29,K133) -> 2
A30: Soldadura circunferencial cuello (rosca) | B30: =MAX(1,B134) -> 1 | C30: =IF(AND(C55="Automática",B55="Manual"),C134,MAX(B30,C134)) -> 1 | D30: =IF(AND(D55="Automática",C55="Manual"),D134,MAX(C30,D134)) -> 1 | E30: =IF(AND(E55="Automática",D55="Manual"),E134,MAX(D30,E134)) -> 1 | F30: =IF(AND(F55="Automática",E55="Manual"),F134,MAX(E30,F134)) -> 1 | G30: =IF(AND(G55="Automática",F55="Manual"),G134,MAX(F30,G134)) -> 2 | H30: =IF(AND(H55="Automática",G55="Manual"),H134,MAX(G30,H134)) -> 2 | I30: =IF(AND(I55="Automática",H55="Manual"),I134,MAX(H30,I134)) -> 2 | J30: =IF(AND(J55="Automática",I55="Manual"),J134,MAX(I30,J134)) -> 2 | K30: =IF(AND(K55="Automática",J55="Manual"),K134,MAX(J30,K134)) -> 2
A31: Corte de disco y embutido (cúpula y fondo) | B31: =MAX(1,B135) -> 1 | C31: =MAX(B31,C135) -> 1 | D31: =MAX(C31,D135) -> 1 | E31: =MAX(D31,E135) -> 1 | F31: =MAX(E31,F135) -> 1 | G31: =MAX(F31,G135) -> 1 | H31: =MAX(G31,H135) -> 1 | I31: =MAX(H31,I135) -> 1 | J31: =MAX(I31,J135) -> 1 | K31: =MAX(J31,K135) -> 1
A32: Numerado de cuerpo | B32: =MAX(1,B136) -> 1 | C32: =MAX(B32,C136) -> 1 | D32: =MAX(C32,D136) -> 1 | E32: =MAX(D32,E136) -> 1 | F32: =MAX(E32,F136) -> 1 | G32: =MAX(F32,G136) -> 2 | H32: =MAX(G32,H136) -> 2 | I32: =MAX(H32,I136) -> 2 | J32: =MAX(I32,J136) -> 2 | K32: =MAX(J32,K136) -> 2
A33: Cilindrado | B33: =MAX(1,B137) -> 1 | C33: =MAX(B33,C137) -> 1 | D33: =MAX(C33,D137) -> 1 | E33: =MAX(D33,E137) -> 1 | F33: =MAX(E33,F137) -> 1 | G33: =MAX(F33,G137) -> 1 | H33: =MAX(G33,H137) -> 1 | I33: =MAX(H33,I137) -> 1 | J33: =MAX(I33,J137) -> 1 | K33: =MAX(J33,K137) -> 1
A34: Soldadura longitudinal | B34: =MAX(1,B138) -> 1 | C34: =MAX(B34,C138) -> 1 | D34: =MAX(C34,D138) -> 1 | E34: =MAX(D34,E138) -> 1 | F34: =MAX(E34,F138) -> 1 | G34: =MAX(F34,G138) -> 1 | H34: =MAX(G34,H138) -> 1 | I34: =MAX(H34,I138) -> 1 | J34: =MAX(I34,J138) -> 1 | K34: =MAX(J34,K138) -> 1
A35: Encastre de fondo | B35: =MAX(1,B139) -> 1 | C35: =MAX(B35,C139) -> 1 | D35: =MAX(C35,D139) -> 1 | E35: =MAX(D35,E139) -> 1 | F35: =MAX(E35,F139) -> 2 | G35: =MAX(F35,G139) -> 2 | H35: =MAX(G35,H139) -> 2 | I35: =MAX(H35,I139) -> 2 | J35: =MAX(I35,J139) -> 2 | K35: =MAX(J35,K139) -> 3
A36: Bordoneado | B36: =MAX(1,B140) -> 1 | C36: =MAX(B36,C140) -> 1 | D36: =MAX(C36,D140) -> 1 | E36: =MAX(D36,E140) -> 1 | F36: =MAX(E36,F140) -> 1 | G36: =MAX(F36,G140) -> 1 | H36: =MAX(G36,H140) -> 1 | I36: =MAX(H36,I140) -> 1 | J36: =MAX(I36,J140) -> 1 | K36: =MAX(J36,K140) -> 1
A37: Soldadura circunferencial (cúpula y fondo) | B37: =MAX(1,B141) -> 1 | C37: =MAX(B37,C141) -> 1 | D37: =MAX(C37,D141) -> 1 | E37: =MAX(D37,E141) -> 1 | F37: =MAX(E37,F141) -> 2 | G37: =MAX(F37,G141) -> 2 | H37: =MAX(G37,H141) -> 2 | I37: =MAX(H37,I141) -> 2 | J37: =MAX(I37,J141) -> 2 | K37: =MAX(J37,K141) -> 2
A38: Prueba hidráulica | B38: =MAX(1,B142) -> 1 | C38: =IF(AND(C58="Automática",B58="Manual"),C142,MAX(B38,C142)) -> 1 | D38: =IF(AND(D58="Automática",C58="Manual"),D142,MAX(C38,D142)) -> 1 | E38: =IF(AND(E58="Automática",D58="Manual"),E142,MAX(D38,E142)) -> 1 | F38: =IF(AND(F58="Automática",E58="Manual"),F142,MAX(E38,F142)) -> 1 | G38: =IF(AND(G58="Automática",F58="Manual"),G142,MAX(F38,G142)) -> 2 | H38: =IF(AND(H58="Automática",G58="Manual"),H142,MAX(G38,H142)) -> 2 | I38: =IF(AND(I58="Automática",H58="Manual"),I142,MAX(H38,I142)) -> 2 | J38: =IF(AND(J58="Automática",I58="Manual"),J142,MAX(I38,J142)) -> 2 | K38: =IF(AND(K58="Automática",J58="Manual"),K142,MAX(J38,K142)) -> 2
A39: Granallado | B39: =MAX(1,B143) -> 1 | C39: =MAX(B39,C143) -> 1 | D39: =MAX(C39,D143) -> 1 | E39: =MAX(D39,E143) -> 1 | F39: =MAX(E39,F143) -> 1 | G39: =MAX(F39,G143) -> 1 | H39: =MAX(G39,H143) -> 1 | I39: =MAX(H39,I143) -> 1 | J39: =MAX(I39,J143) -> 1 | K39: =MAX(J39,K143) -> 1
A40: Detección de defectos (CC) | B40: =MAX(1,B144) -> 1 | C40: =MAX(B40,C144) -> 1 | D40: =MAX(C40,D144) -> 1 | E40: =MAX(D40,E144) -> 1 | F40: =MAX(E40,F144) -> 1 | G40: =MAX(F40,G144) -> 1 | H40: =MAX(G40,H144) -> 1 | I40: =MAX(H40,I144) -> 1 | J40: =MAX(I40,J144) -> 1 | K40: =MAX(J40,K144) -> 1
A41: Corrección de defectos | B41: =MAX(1,B145) -> 1 | C41: =MAX(B41,C145) -> 1 | D41: =MAX(C41,D145) -> 1 | E41: =MAX(D41,E145) -> 1 | F41: =MAX(E41,F145) -> 1 | G41: =MAX(F41,G145) -> 1 | H41: =MAX(G41,H145) -> 1 | I41: =MAX(H41,I145) -> 1 | J41: =MAX(I41,J145) -> 1 | K41: =MAX(J41,K145) -> 1
A42: Pintura + Horno (cil. 1–10 kg) | B42: =IF(B$28<$B$51,0,MAX(1,B146)) -> 0 | C42: =IF(C$28<$B$51,0,MAX(1,B42,C146)) -> 0 | D42: =IF(D$28<$B$51,0,MAX(1,C42,D146)) -> 0 | E42: =IF(E$28<$B$51,0,MAX(1,D42,E146)) -> 1 | F42: =IF(F$28<$B$51,0,MAX(1,E42,F146)) -> 1 | G42: =IF(G$28<$B$51,0,MAX(1,F42,G146)) -> 1 | H42: =IF(H$28<$B$51,0,MAX(1,G42,H146)) -> 1 | I42: =IF(I$28<$B$51,0,MAX(1,H42,I146)) -> 1 | J42: =IF(J$28<$B$51,0,MAX(1,I42,J146)) -> 1 | K42: =IF(K$28<$B$51,0,MAX(1,J42,K146)) -> 1
A43: Carga de polvo | B43: =MAX(1,B147) -> 1 | C43: =MAX(B43,C147) -> 1 | D43: =MAX(C43,D147) -> 1 | E43: =MAX(D43,E147) -> 1 | F43: =MAX(E43,F147) -> 1 | G43: =MAX(F43,G147) -> 1 | H43: =MAX(G43,H147) -> 1 | I43: =MAX(H43,I147) -> 1 | J43: =MAX(I43,J147) -> 1 | K43: =MAX(J43,K147) -> 1
...

Sheet Dotacion Planta
A1: DOTACIÓN DE PLANTA — producción 1–10 kg, recargas y línea de carros
A2: Personas = horas-hombre del mes pico ÷ horas por operario. Horas-hombre de un puesto = demanda ÷ cap. real × coef. hombre–máquina. Los carros los hace el plantel de producción (especializado); el de recargas solo hace recargas. Reparto de carros por mes: Parametros fila 70.
A4: PARÁMETROS | B4: Valor
A5: Stock oct–nov para diciembre (1 = sí, 0 = no) | B5: 1
A6: Rendimiento de un operario de producción en recargas | B6: 0.9 | C6: Menos práctica en el puesto.
A7: Ocupación objetivo por operario | B7: =Parametros!$B$67 -> 0.9 | C7: Parametros B67.
A8: Horas por operario al mes (1 turno) | B8: =Parametros!$F$37 -> 150 | C8: Parametros F37 (20 días × 7,5 h).
A9: Horas efectivas por operario (h/mes) | B9: =B8*B7*(1-B14) -> 130.95 | C9: Horas × ocupación × (1 − ausentismo).
A10: Horas extra permitidas por operario (h/mes) | B10: 30 | C10: Dec. 484/00: máx. 30 h/mes.
A11: Horas máximas por operario en el mes pico (h/mes) | B11: =B9+B10 -> 160.95 | C11: Efectivas + extra.
A12: Tope de horas extra por año (h) | B12: 200 | C12: Dec. 484/00: máx. 200 h/año.
A13: Plantel mínimo de producción (arranque) | B13: =Parametros!$B$68 -> 5 | C13: Parametros B68.
A14: Ausentismo (enfermedad, licencias) | B14: 0.03 | C14: Se descuenta de las horas de todos los meses.
A15: Particulares 1 kg que vienen a la tarde (mostrador) | B15: 0.4 | C15: Con 2 turnos el mostrador atiende mañana y tarde: 60 % mañana / 40 % tarde. Con 1 turno, todo a la mañana.
A16: COEFICIENTE HOMBRE–MÁQUINA (horas de operario por hora de máquina; 0,5 = un operario atiende 2 máquinas)
A17: Puesto | B17: Manual | C17: Automática
A18: Preparación de cuello | B18: 1 | C18: —
A19: Soldadura circunferencial cuello (rosca) | B19: 1 | C19: 0.5 | D19: La máquina suelda sola; el operario carga la pieza siguiente.
A20: Corte de disco y embutido (cúpula y fondo) | B20: 1 | C20: —
A21: Numerado de cuerpo | B21: 1 | C21: —
A22: Cilindrado | B22: 1 | C22: —
A23: Soldadura longitudinal | B23: 1 | C23: 0.5 | D23: Ciclo automático; el operario carga el cuerpo siguiente.
A24: Encastre de fondo | B24: 1 | C24: —
A25: Bordoneado | B25: 1 | C25: —
A26: Soldadura circunferencial (cúpula y fondo) | B26: 1 | C26: 0.5 | D26: Gira y suelda sola; 1 operario atiende 2 cabezales.
A27: Prueba hidráulica | B27: 1 | C27: 0.5 | D27: Sostenimiento automático; el operario atiende el secado.
A28: Granallado | B28: 0.5 | C28: — | D28: Ciclo automático; cuelga el lote siguiente.
A29: Detección de defectos (CC) | B29: 1 | C29: —
A30: Corrección de defectos | B30: 1 | C30: —
A31: Pintura + Horno | B31: 0.5 | C31: — | D31: Línea continua; compartido con granallado.
A32: Carga de polvo | B32: 0.5 | C32: — | D32: Dosifica por peso; atiende la presurización.
A33: Ensamblaje | B33: 1 | C33: —
A34: Presurización | B34: 1 | C34: —
A35: Etiquetado | B35: 1 | C35: —
A36: Embalaje y palletizado | B36: 1 | C36: —
A37: Cortadora de plasma (1kg) | B37: 0.5 | C37: — | D37: CNC; el operario descarga y atiende otro puesto.
A38: Carros — cilindrado de chapa | B38: 1 | C38: —
A39: Carros — punteo, refuerzo y estructura del carro | B39: 1 | C39: —
A40: Carros — soldadura longitudinal | B40: 0.5 | C40: —
A41: Carros — soldadura circunferencial fondo y cúpula | B41: 0.5 | C41: — | D41: preguntar si es por tiempo o por actividad
...

Sheet Analisis Recargas
A1: ANÁLISIS DE CAPACIDAD — RECARGAS PLANTA INDUSTRIAL
A2: Horas por mes de 1 turno (Parametros Recargas F4) | B2: ='Parametros Recargas'!$F$4 -> 150 | D2: Carga (u/h) = Σ (demanda de la familia × % que pasa por el puesto) ÷ horas del mes. N° máq. = máx(año anterior; REDONDEAR.MAS(pico ÷ (cap. × turnos de planta × umbral))).
D3: Turnos del puesto = 2 solo si con 1 turno supera el umbral. h-hombre por u = coef. hombre–máquina ÷ cap. real.
A4: AÑO 2026
A5: Demanda por tipo (u. eq./mes) | B5: Familia | C5: Ene | D5: Feb | E5: Mar | F5: Abr | G5: May | H5: Jun | I5: Jul | J5: Ago | K5: Sep | L5: Oct | M5: Nov | N5: Dic | O5: Total
A6: =datos_base!$A$55 -> ABC 1 kg | B6: Polvo ABC | C6: =datos_base!$B$55*'Parametros Recargas'!D$33*'Parametros Recargas'!$Q$33 -> 119.0499 | D6: =datos_base!$B$55*'Parametros Recargas'!E$33*'Parametros Recargas'!$Q$33 -> 92.85892 | E6: =datos_base!$B$55*'Parametros Recargas'!F$33*'Parametros Recargas'!$Q$33 -> 92.85892 | F6: =datos_base!$B$55*'Parametros Recargas'!G$33*'Parametros Recargas'!$Q$33 -> 92.85892 | G6: =datos_base!$B$55*'Parametros Recargas'!H$33*'Parametros Recargas'!$Q$33 -> 92.85892 | H6: =datos_base!$B$55*'Parametros Recargas'!I$33*'Parametros Recargas'!$Q$33 -> 92.85892 | I6: =datos_base!$B$55*'Parametros Recargas'!J$33*'Parametros Recargas'!$Q$33 -> 92.85892 | J6: =datos_base!$B$55*'Parametros Recargas'!K$33*'Parametros Recargas'!$Q$33 -> 92.85892 | ... N6: =datos_base!$B$55*'Parametros Recargas'!O$33*'Parametros Recargas'!$Q$33 -> 142.85988 | O6: =SUM(C6:N6) -> 1190.499
A7: =datos_base!$A$56 -> ABC 2,5 kg | B7: Polvo ABC | C7: =datos_base!$B$56*'Parametros Recargas'!D$34*'Parametros Recargas'!$Q$34 -> 10.169059 | D7: =datos_base!$B$56*'Parametros Recargas'!E$34*'Parametros Recargas'!$Q$34 -> 9.0391639 | E7: =datos_base!$B$56*'Parametros Recargas'!F$34*'Parametros Recargas'!$Q$34 -> 9.6041117 | F7: =datos_base!$B$56*'Parametros Recargas'!G$34*'Parametros Recargas'!$Q$34 -> 9.0391639 | G7: =datos_base!$B$56*'Parametros Recargas'!H$34*'Parametros Recargas'!$Q$34 -> 8.4742162 | H7: =datos_base!$B$56*'Parametros Recargas'!I$34*'Parametros Recargas'!$Q$34 -> 7.9092684 | I7: =datos_base!$B$56*'Parametros Recargas'!J$34*'Parametros Recargas'!$Q$34 -> 9.0391639 | J7: =datos_base!$B$56*'Parametros Recargas'!K$34*'Parametros Recargas'!$Q$34 -> 9.6041117 | ... N7: =datos_base!$B$56*'Parametros Recargas'!O$34*'Parametros Recargas'!$Q$34 -> 12.42885 | O7: =SUM(C7:N7) -> 112.98955
A8: =datos_base!$A$57 -> ABC 5 kg | B8: Polvo ABC | C8: =datos_base!$B$57*'Parametros Recargas'!D$35*'Parametros Recargas'!$Q$35 -> 60.089896 | D8: =datos_base!$B$57*'Parametros Recargas'!E$35*'Parametros Recargas'!$Q$35 -> 53.413241 | E8: =datos_base!$B$57*'Parametros Recargas'!F$35*'Parametros Recargas'!$Q$35 -> 56.751569 | F8: =datos_base!$B$57*'Parametros Recargas'!G$35*'Parametros Recargas'!$Q$35 -> 53.413241 | G8: =datos_base!$B$57*'Parametros Recargas'!H$35*'Parametros Recargas'!$Q$35 -> 50.074914 | H8: =datos_base!$B$57*'Parametros Recargas'!I$35*'Parametros Recargas'!$Q$35 -> 46.736586 | I8: =datos_base!$B$57*'Parametros Recargas'!J$35*'Parametros Recargas'!$Q$35 -> 53.413241 | J8: =datos_base!$B$57*'Parametros Recargas'!K$35*'Parametros Recargas'!$Q$35 -> 56.751569 | ... N8: =datos_base!$B$57*'Parametros Recargas'!O$35*'Parametros Recargas'!$Q$35 -> 73.443207 | O8: =SUM(C8:N8) -> 667.66552
A9: =datos_base!$A$58 -> ABC 10 kg | B9: Polvo ABC | C9: =datos_base!$B$58*'Parametros Recargas'!D$36*'Parametros Recargas'!$Q$36 -> 3.6362091 | D9: =datos_base!$B$58*'Parametros Recargas'!E$36*'Parametros Recargas'!$Q$36 -> 3.2321859 | E9: =datos_base!$B$58*'Parametros Recargas'!F$36*'Parametros Recargas'!$Q$36 -> 3.4341975 | F9: =datos_base!$B$58*'Parametros Recargas'!G$36*'Parametros Recargas'!$Q$36 -> 3.2321859 | G9: =datos_base!$B$58*'Parametros Recargas'!H$36*'Parametros Recargas'!$Q$36 -> 3.0301743 | H9: =datos_base!$B$58*'Parametros Recargas'!I$36*'Parametros Recargas'!$Q$36 -> 2.8281626 | I9: =datos_base!$B$58*'Parametros Recargas'!J$36*'Parametros Recargas'!$Q$36 -> 3.2321859 | J9: =datos_base!$B$58*'Parametros Recargas'!K$36*'Parametros Recargas'!$Q$36 -> 3.4341975 | ... N9: =datos_base!$B$58*'Parametros Recargas'!O$36*'Parametros Recargas'!$Q$36 -> 4.4442556 | O9: =SUM(C9:N9) -> 40.402324
A10: =datos_base!$A$69 -> ABC 25 kg s/ruedas | B10: Polvo ABC | C10: =datos_base!$B$69*'Parametros Recargas'!D$37*'Parametros Recargas'!$Q$37 -> 1.8489199 | D10: =datos_base!$B$69*'Parametros Recargas'!E$37*'Parametros Recargas'!$Q$37 -> 1.4791359 | E10: =datos_base!$B$69*'Parametros Recargas'!F$37*'Parametros Recargas'!$Q$37 -> 1.5715819 | F10: =datos_base!$B$69*'Parametros Recargas'!G$37*'Parametros Recargas'!$Q$37 -> 1.5715819 | G10: =datos_base!$B$69*'Parametros Recargas'!H$37*'Parametros Recargas'!$Q$37 -> 1.4791359 | H10: =datos_base!$B$69*'Parametros Recargas'!I$37*'Parametros Recargas'!$Q$37 -> 1.3866899 | I10: =datos_base!$B$69*'Parametros Recargas'!J$37*'Parametros Recargas'!$Q$37 -> 1.6640279 | J10: =datos_base!$B$69*'Parametros Recargas'!K$37*'Parametros Recargas'!$Q$37 -> 1.4791359 | ... N10: =datos_base!$B$69*'Parametros Recargas'!O$37*'Parametros Recargas'!$Q$37 -> 1.6640279 | O10: =SUM(C10:N10) -> 18.489199
A11: =datos_base!$A$70 -> ABC 50 kg s/ruedas | B11: Polvo ABC | C11: =datos_base!$B$70*'Parametros Recargas'!D$38*'Parametros Recargas'!$Q$38 -> 4.0059931 | D11: =datos_base!$B$70*'Parametros Recargas'!E$38*'Parametros Recargas'!$Q$38 -> 3.2047945 | E11: =datos_base!$B$70*'Parametros Recargas'!F$38*'Parametros Recargas'!$Q$38 -> 3.4050941 | F11: =datos_base!$B$70*'Parametros Recargas'!G$38*'Parametros Recargas'!$Q$38 -> 3.4050941 | G11: =datos_base!$B$70*'Parametros Recargas'!H$38*'Parametros Recargas'!$Q$38 -> 3.2047945 | H11: =datos_base!$B$70*'Parametros Recargas'!I$38*'Parametros Recargas'!$Q$38 -> 3.0044948 | I11: =datos_base!$B$70*'Parametros Recargas'!J$38*'Parametros Recargas'!$Q$38 -> 3.6053938 | J11: =datos_base!$B$70*'Parametros Recargas'!K$38*'Parametros Recargas'!$Q$38 -> 3.2047945 | ... N11: =datos_base!$B$70*'Parametros Recargas'!O$38*'Parametros Recargas'!$Q$38 -> 3.6053938 | O11: =SUM(C11:N11) -> 40.059931
A12: =datos_base!$A$71 -> ABC 70 kg s/ruedas | B12: Polvo ABC | C12: =datos_base!$B$71*'Parametros Recargas'!D$39*'Parametros Recargas'!$Q$39 -> 0.82174217 | D12: =datos_base!$B$71*'Parametros Recargas'!E$39*'Parametros Recargas'!$Q$39 -> 0.65739374 | E12: =datos_base!$B$71*'Parametros Recargas'!F$39*'Parametros Recargas'!$Q$39 -> 0.69848085 | F12: =datos_base!$B$71*'Parametros Recargas'!G$39*'Parametros Recargas'!$Q$39 -> 0.69848085 | G12: =datos_base!$B$71*'Parametros Recargas'!H$39*'Parametros Recargas'!$Q$39 -> 0.65739374 | H12: =datos_base!$B$71*'Parametros Recargas'!I$39*'Parametros Recargas'!$Q$39 -> 0.61630663 | I12: =datos_base!$B$71*'Parametros Recargas'!J$39*'Parametros Recargas'!$Q$39 -> 0.73956796 | J12: =datos_base!$B$71*'Parametros Recargas'!K$39*'Parametros Recargas'!$Q$39 -> 0.65739374 | ... N12: =datos_base!$B$71*'Parametros Recargas'!O$39*'Parametros Recargas'!$Q$39 -> 0.73956796 | O12: =SUM(C12:N12) -> 8.2174217
A13: =datos_base!$A$72 -> ABC 100 kg s/ruedas | B13: Polvo ABC | C13: =datos_base!$B$72*'Parametros Recargas'!D$40*'Parametros Recargas'!$Q$40 -> 0.61630663 | D13: =datos_base!$B$72*'Parametros Recargas'!E$40*'Parametros Recargas'!$Q$40 -> 0.4930453 | E13: =datos_base!$B$72*'Parametros Recargas'!F$40*'Parametros Recargas'!$Q$40 -> 0.52386064 | F13: =datos_base!$B$72*'Parametros Recargas'!G$40*'Parametros Recargas'!$Q$40 -> 0.52386064 | G13: =datos_base!$B$72*'Parametros Recargas'!H$40*'Parametros Recargas'!$Q$40 -> 0.4930453 | H13: =datos_base!$B$72*'Parametros Recargas'!I$40*'Parametros Recargas'!$Q$40 -> 0.46222997 | I13: =datos_base!$B$72*'Parametros Recargas'!J$40*'Parametros Recargas'!$Q$40 -> 0.55467597 | J13: =datos_base!$B$72*'Parametros Recargas'!K$40*'Parametros Recargas'!$Q$40 -> 0.4930453 | ... N13: =datos_base!$B$72*'Parametros Recargas'!O$40*'Parametros Recargas'!$Q$40 -> 0.55467597 | O13: =SUM(C13:N13) -> 6.1630663
A14: =datos_base!$A$62 -> BC 5 kg | B14: Polvo BC | C14: =datos_base!$B$62*'Parametros Recargas'!D$41*'Parametros Recargas'!$Q$41 -> 0.21570732 | D14: =datos_base!$B$62*'Parametros Recargas'!E$41*'Parametros Recargas'!$Q$41 -> 0.19173984 | E14: =datos_base!$B$62*'Parametros Recargas'!F$41*'Parametros Recargas'!$Q$41 -> 0.20372358 | F14: =datos_base!$B$62*'Parametros Recargas'!G$41*'Parametros Recargas'!$Q$41 -> 0.19173984 | G14: =datos_base!$B$62*'Parametros Recargas'!H$41*'Parametros Recargas'!$Q$41 -> 0.1797561 | H14: =datos_base!$B$62*'Parametros Recargas'!I$41*'Parametros Recargas'!$Q$41 -> 0.16777236 | I14: =datos_base!$B$62*'Parametros Recargas'!J$41*'Parametros Recargas'!$Q$41 -> 0.19173984 | J14: =datos_base!$B$62*'Parametros Recargas'!K$41*'Parametros Recargas'!$Q$41 -> 0.20372358 | ... N14: =datos_base!$B$62*'Parametros Recargas'!O$41*'Parametros Recargas'!$Q$41 -> 0.26364228 | O14: =SUM(C14:N14) -> 2.396748
A15: =datos_base!$A$68 -> Clase D 9 l | B15: Polvo Clase D | C15: =datos_base!$B$68*'Parametros Recargas'!D$42*'Parametros Recargas'!$Q$42 -> 0.21570732 | D15: =datos_base!$B$68*'Parametros Recargas'!E$42*'Parametros Recargas'!$Q$42 -> 0.19173984 | E15: =datos_base!$B$68*'Parametros Recargas'!F$42*'Parametros Recargas'!$Q$42 -> 0.20372358 | F15: =datos_base!$B$68*'Parametros Recargas'!G$42*'Parametros Recargas'!$Q$42 -> 0.19173984 | G15: =datos_base!$B$68*'Parametros Recargas'!H$42*'Parametros Recargas'!$Q$42 -> 0.1797561 | H15: =datos_base!$B$68*'Parametros Recargas'!I$42*'Parametros Recargas'!$Q$42 -> 0.16777236 | I15: =datos_base!$B$68*'Parametros Recargas'!J$42*'Parametros Recargas'!$Q$42 -> 0.19173984 | J15: =datos_base!$B$68*'Parametros Recargas'!K$42*'Parametros Recargas'!$Q$42 -> 0.20372358 | ... N15: =datos_base!$B$68*'Parametros Recargas'!O$42*'Parametros Recargas'!$Q$42 -> 0.26364228 | O15: =SUM(C15:N15) -> 2.396748
A16: =datos_base!$A$59 -> Agua 10 l | B16: Líquidos | C16: =datos_base!$B$59*'Parametros Recargas'!D$43*'Parametros Recargas'!$Q$43 -> 4.8996377 | D16: =datos_base!$B$59*'Parametros Recargas'!E$43*'Parametros Recargas'!$Q$43 -> 4.3552335 | E16: =datos_base!$B$59*'Parametros Recargas'!F$43*'Parametros Recargas'!$Q$43 -> 4.6274356 | F16: =datos_base!$B$59*'Parametros Recargas'!G$43*'Parametros Recargas'!$Q$43 -> 4.3552335 | G16: =datos_base!$B$59*'Parametros Recargas'!H$43*'Parametros Recargas'!$Q$43 -> 4.0830314 | H16: =datos_base!$B$59*'Parametros Recargas'!I$43*'Parametros Recargas'!$Q$43 -> 3.8108293 | I16: =datos_base!$B$59*'Parametros Recargas'!J$43*'Parametros Recargas'!$Q$43 -> 4.3552335 | J16: =datos_base!$B$59*'Parametros Recargas'!K$43*'Parametros Recargas'!$Q$43 -> 4.6274356 | ... N16: =datos_base!$B$59*'Parametros Recargas'!O$43*'Parametros Recargas'!$Q$43 -> 5.9884461 | O16: =SUM(C16:N16) -> 54.440419
A17: =datos_base!$A$60 -> AFFF 10 l | B17: Líquidos | C17: =datos_base!$B$60*'Parametros Recargas'!D$44*'Parametros Recargas'!$Q$44 -> 0.70875263 | D17: =datos_base!$B$60*'Parametros Recargas'!E$44*'Parametros Recargas'!$Q$44 -> 0.63000233 | E17: =datos_base!$B$60*'Parametros Recargas'!F$44*'Parametros Recargas'!$Q$44 -> 0.66937748 | F17: =datos_base!$B$60*'Parametros Recargas'!G$44*'Parametros Recargas'!$Q$44 -> 0.63000233 | G17: =datos_base!$B$60*'Parametros Recargas'!H$44*'Parametros Recargas'!$Q$44 -> 0.59062719 | H17: =datos_base!$B$60*'Parametros Recargas'!I$44*'Parametros Recargas'!$Q$44 -> 0.55125204 | I17: =datos_base!$B$60*'Parametros Recargas'!J$44*'Parametros Recargas'!$Q$44 -> 0.63000233 | J17: =datos_base!$B$60*'Parametros Recargas'!K$44*'Parametros Recargas'!$Q$44 -> 0.66937748 | ... N17: =datos_base!$B$60*'Parametros Recargas'!O$44*'Parametros Recargas'!$Q$44 -> 0.86625321 | O17: =SUM(C17:N17) -> 7.8750292
A18: =datos_base!$A$63 -> Sales K 6 l | B18: Líquidos | C18: =datos_base!$B$63*'Parametros Recargas'!D$45*'Parametros Recargas'!$Q$45 -> 2.5268572 | D18: =datos_base!$B$63*'Parametros Recargas'!E$45*'Parametros Recargas'!$Q$45 -> 2.2460953 | E18: =datos_base!$B$63*'Parametros Recargas'!F$45*'Parametros Recargas'!$Q$45 -> 2.3864762 | F18: =datos_base!$B$63*'Parametros Recargas'!G$45*'Parametros Recargas'!$Q$45 -> 2.2460953 | G18: =datos_base!$B$63*'Parametros Recargas'!H$45*'Parametros Recargas'!$Q$45 -> 2.1057143 | H18: =datos_base!$B$63*'Parametros Recargas'!I$45*'Parametros Recargas'!$Q$45 -> 1.9653334 | I18: =datos_base!$B$63*'Parametros Recargas'!J$45*'Parametros Recargas'!$Q$45 -> 2.2460953 | J18: =datos_base!$B$63*'Parametros Recargas'!K$45*'Parametros Recargas'!$Q$45 -> 2.3864762 | ... N18: =datos_base!$B$63*'Parametros Recargas'!O$45*'Parametros Recargas'!$Q$45 -> 3.088381 | O18: =SUM(C18:N18) -> 28.076191
A19: =datos_base!$A$61 -> AFFF 50 l s/ruedas | B19: Líquidos | C19: =datos_base!$B$61*'Parametros Recargas'!D$46*'Parametros Recargas'!$Q$46 -> 1.1298955 | D19: =datos_base!$B$61*'Parametros Recargas'!E$46*'Parametros Recargas'!$Q$46 -> 0.90391639 | E19: =datos_base!$B$61*'Parametros Recargas'!F$46*'Parametros Recargas'!$Q$46 -> 0.96041117 | F19: =datos_base!$B$61*'Parametros Recargas'!G$46*'Parametros Recargas'!$Q$46 -> 0.96041117 | G19: =datos_base!$B$61*'Parametros Recargas'!H$46*'Parametros Recargas'!$Q$46 -> 0.90391639 | H19: =datos_base!$B$61*'Parametros Recargas'!I$46*'Parametros Recargas'!$Q$46 -> 0.84742162 | I19: =datos_base!$B$61*'Parametros Recargas'!J$46*'Parametros Recargas'!$Q$46 -> 1.0169059 | J19: =datos_base!$B$61*'Parametros Recargas'!K$46*'Parametros Recargas'!$Q$46 -> 0.90391639 | ... N19: =datos_base!$B$61*'Parametros Recargas'!O$46*'Parametros Recargas'!$Q$46 -> 1.0169059 | O19: =SUM(C19:N19) -> 11.298955
