Workbook

Sheet datos_base
A1: Matafuegos terminados | B1: 2026 | C1: 2027 | D1: 2028 | E1: 2029 | F1: 2030 | G1: 2031 | H1: 2032 | I1: 2033 | J1: 2034 | K1: 2035
A2: ABC 1 kg | B2: 4179 | C2: 5997 | D2: 6852 | E2: 8467 | F2: 12681 | G2: 15620 | H2: 20333 | I2: 25132 | J2: 28573 | K2: 32073
A3: ABC 2,5 kg | B3: 295 | C3: 709 | D3: 987 | E3: 1501 | F3: 2312 | G3: 3252 | H3: 4103 | I3: 5105 | J3: 6195 | K3: 7425
A4: ABC 5 kg | B4: 2256 | C4: 3847 | D4: 5094 | E4: 6823 | F4: 10819 | G4: 14606 | H4: 18878 | I4: 23368 | J4: 26968 | K4: 30751
A5: ABC 10 kg | B5: 92 | C5: 177 | D5: 253 | E5: 358 | F5: 603 | G5: 872 | H5: 1127 | I5: 1395 | J5: 1612 | K5: 1841
A6: Total terminados | B6: =SUM(B2:B5) -> 6822 | C6: =SUM(C2:C5) -> 10730 | D6: =SUM(D2:D5) -> 13186 | E6: =SUM(E2:E5) -> 17149 | F6: =SUM(F2:F5) -> 26415 | G6: =SUM(G2:G5) -> 34350 | H6: =SUM(H2:H5) -> 44441 | I6: =SUM(I2:I5) -> 55000 | ... K6: =SUM(K2:K5) -> 72090
A8: Cilindros vendidos vacíos | B8: 2026 | C8: 2027 | D8: 2028 | E8: 2029 | F8: 2030 | G8: 2031 | H8: 2032 | I8: 2033 | J8: 2034 | K8: 2035
A9: Cilindros ABC 1 kg | B9: 0 | C9: 0 | D9: 7662 | E9: 26695 | F9: 49435 | G9: 71680 | H9: 101341 | I9: 131001 | J9: 146820 | K9: 170548
A10: Cilindros ABC 2,5 kg | B10: 0 | C10: 0 | D10: 300 | E10: 1044 | F10: 1933 | G10: 2803 | H10: 3963 | I10: 5123 | J10: 5741 | K10: 6669
A11: Cilindros ABC 5 kg | B11: 0 | C11: 0 | D11: 1479 | E11: 5152 | F11: 9541 | G11: 13834 | H11: 19559 | I11: 25283 | J11: 28336 | K11: 32915
A12: Cilindros ABC 10 kg | B12: 0 | C12: 0 | D12: 90 | E12: 315 | F12: 583 | G12: 846 | H12: 1195 | I12: 1545 | J12: 1731 | K12: 2011
A13: Total cilindros | B13: =SUM(B9:B12) -> 0 | C13: =SUM(C9:C12) -> 0 | D13: =SUM(D9:D12) -> 9531 | E13: =SUM(E9:E12) -> 33206 | F13: =SUM(F9:F12) -> 61492 | G13: =SUM(G9:G12) -> 89163 | H13: =SUM(H9:H12) -> 126058 | I13: =SUM(I9:I12) -> 162952 | ... K13: =SUM(K9:K12) -> 212143
A15: Total recipientes a fabricar | B15: =B6+B13 -> 6822 | C15: =C6+C13 -> 10730 | D15: =D6+D13 -> 22717 | E15: =E6+E13 -> 50355 | F15: =F6+F13 -> 87907 | G15: =G6+G13 -> 123513 | H15: =H6+H13 -> 170499 | I15: =I6+I13 -> 217952 | ... K15: =K6+K13 -> 284233

Sheet parametros_manuales
A1: Parámetro | B1: Valor | C1: Nota
A2: Días hábiles por mes | B2: 20 | C2: Excel original, Parametros B37
A3: Horas por día (1 turno) | B3: 8 | C3: Excel original, Parametros D37
A4: Refrigerio (min/turno) | B4: 30 | C4: Excel original, Parametros H37
A5: Horas productivas por turno | B5: =B3-B4/60 -> 7.5 | C5: Horas/día − refrigerio
A6: Turnos por día | B6: 1 | C6: Un solo turno (editable)
A7: Horas productivas por mes | B7: =B2*B5*B6 -> 150 | C7: Días × horas productivas × turnos
A8: Umbral de aprovechamiento (solo para resaltar) | B8: 0.9 | C8: Las celdas de aprovechamiento que lo superan se pintan de rojo
A10: ESTACIONALIDAD (% de la demanda anual por mes)
A11: Modelo | B11: Ene | C11: Feb | D11: Mar | E11: Abr | F11: May | G11: Jun | H11: Jul | I11: Ago | J11: Sep | K11: Oct | L11: Nov | M11: Dic | N11: Total
A12: 1 kg | B12: 0.12 | C12: 0.09 | D12: 0.08 | E12: 0.075 | F12: 0.07 | G12: 0.07 | H12: 0.075 | I12: 0.075 | J12: 0.075 | K12: 0.075 | L12: 0.075 | M12: 0.12 | N12: =SUM(B12:M12) -> 1 | O12: Perfil automovilístico (Excel original, Parametros fila 3)
A13: 2,5 kg | B13: 0.1 | C13: 0.08 | D13: 0.085 | E13: 0.085 | F13: 0.08 | G13: 0.075 | H13: 0.08 | I13: 0.08 | J13: 0.08 | K13: 0.075 | L13: 0.07 | M13: 0.11 | N13: =SUM(B13:M13) -> 1 | O13: Perfil manual comercial (Excel original, Parametros fila 4)
A14: 5 kg | B14: 0.1 | C14: 0.08 | D14: 0.085 | E14: 0.085 | F14: 0.08 | G14: 0.075 | H14: 0.08 | I14: 0.08 | J14: 0.08 | K14: 0.075 | L14: 0.07 | M14: 0.11 | N14: =SUM(B14:M14) -> 1
A15: 10 kg | B15: 0.1 | C15: 0.08 | D15: 0.085 | E15: 0.085 | F15: 0.08 | G15: 0.075 | H15: 0.08 | I15: 0.08 | J15: 0.08 | K15: 0.075 | L15: 0.07 | M15: 0.11 | N15: =SUM(B15:M15) -> 1
A17: CAPACIDAD POR PUESTO
A18: N° | B18: Puesto | C18: Máquina | D18: 1 kg | E18: 2,5 kg | F18: 5 kg | G18: 10 kg | H18: Alcance | I18: Piezas por unidad | J18: % que pasa | K18: Tiempo tipo (s/u) | L18: Disponibilidad | M18: Cap. real (u/h) | N18: Cap. real (u/mes) | O18: SUPOSICIONES
A19: 1 | B19: Recepción de materia prima | C19: Autoelevador Heli CPCD50 + micrómetro | D19: 1 | E19: 1 | F19: 1 | G19: 1 | H19: Todos | I19: 1 | J19: 1 | K19: 60 | L19: =F51 -> 1 | M19: =IF(K19>0,3600/K19*L19,0) -> 60 | N19: =M19*$B$7 -> 9000 | O19: 25 min x pallet de 20 hojas en carros (1,25 min x hoja)
A20: 2 | B20: Corte de chapa (guillotina) — 2,5 a 10 kg | C20: Guillotina hidráulica Cena serie O 3.200 mm | D20: 0 | E20: 1 | F20: 1 | G20: 1 | H20: Todos | I20: 1 | J20: 1 | K20: 90 | L20: =F52 -> 0.99333333 | M20: =IF(K20>0,3600/K20*L20,0) -> 39.733333 | N20: =M20*$B$7 -> 5960 | O20: ref carros - 1,2/1,5 min x cuerpo (+ CORTES + TIEMPO)
A21: 3 | B21: Corte de tubo — 1 kg | C21: Cortadora láser de tubo Leapion 1,5 kW | D21: 1 | E21: 0 | F21: 0 | G21: 0 | H21: Todos | I21: 1 | J21: 1 | K21: 30 | L21: =F53 -> 1 | M21: =IF(K21>0,3600/K21*L21,0) -> 120 | N21: =M21*$B$7 -> 18000 | O21: 10 minutos por tubo de 6m (en cada tubo entran 23 cuerpos)
A22: 4 | B22: Corte de disco y embutido (cúpula y fondo) | C22: Prensa embutidora Sangiacomo + alimentador Cena PRE-1 | D22: 1 | E22: 1 | F22: 1 | G22: 1 | H22: Todos | I22: 2 | J22: 1 | K22: 8 | L22: =F54 -> 0.68 | M22: =IF(K22>0,3600/K22*L22,0) -> 306 | N22: =M22*$B$7 -> 45900 | O22: Son 10c segundos contemplando cupula y fondo
A23: 5 | B23: Preparación de cuello | C23: Prensa de banco Pannier MarkFirst MB-21 | D23: 1 | E23: 1 | F23: 1 | G23: 1 | H23: Todos | I23: 1 | J23: 1 | K23: 60 | L23: =F55 -> 1 | M23: =IF(K23>0,3600/K23*L23,0) -> 60 | N23: =M23*$B$7 -> 9000
A24: 6 | B24: Numerado de cúpula | C24: Micropercusión Pannier ADP120160D Deep Marker | D24: 1 | E24: 1 | F24: 1 | G24: 1 | H24: Todos | I24: 1 | J24: 1 | K24: 20 | L24: =F56 -> 1 | M24: =IF(K24>0,3600/K24*L24,0) -> 180 | N24: =M24*$B$7 -> 27000
A25: 7 | B25: Soldadura del cuello a la cúpula | C25: Firesafer FS-HFM1 (versión manual) | D25: 1 | E25: 1 | F25: 1 | G25: 1 | H25: Todos | I25: 1 | J25: 1 | K25: 25 | L25: =F57 -> 0.97333333 | M25: =IF(K25>0,3600/K25*L25,0) -> 140.16 | N25: =M25*$B$7 -> 21024
A26: 8 | B26: Cilindrado | C26: Roladora Firesafer FS-RM01 | D26: 0 | E26: 1 | F26: 1 | G26: 1 | H26: Todos | I26: 1 | J26: 1 | K26: 80 | L26: =F58 -> 0.98666667 | M26: =IF(K26>0,3600/K26*L26,0) -> 44.4 | N26: =M26*$B$7 -> 6660
A27: 9 | B27: Soldadura longitudinal | C27: Soldadora longitudinal Firesafer | D27: 0 | E27: 1 | F27: 1 | G27: 1 | H27: Todos | I27: 1 | J27: 1 | K27: 115 | L27: =F59 -> 0.98666667 | M27: =IF(K27>0,3600/K27*L27,0) -> 30.886957 | N27: =M27*$B$7 -> 4633.0435
A28: 10 | B28: Encastre de fondo | C28: Prensa hidráulica motorizada Del Fabro 30 t | D28: 1 | E28: 1 | F28: 1 | G28: 1 | H28: Todos | I28: 1 | J28: 1 | K28: 30 | L28: =F60 -> 0.98222222 | M28: =IF(K28>0,3600/K28*L28,0) -> 117.86667 | N28: =M28*$B$7 -> 17680
A29: 11 | B29: Bordoneado | C29: Bordoneadora motorizada Pilman SWM-400 | D29: 1 | E29: 1 | F29: 1 | G29: 1 | H29: Todos | I29: 1 | J29: 1 | K29: 20 | L29: =F61 -> 0.98222222 | M29: =IF(K29>0,3600/K29*L29,0) -> 176.8 | N29: =M29*$B$7 -> 26520
A30: 12 | B30: Soldadura circunferencial de cúpula y fondo | C30: Soldadora circunferencial Firesafer | D30: 1 | E30: 1 | F30: 1 | G30: 1 | H30: Todos | I30: 1 | J30: 1 | K30: 60 | L30: =F62 -> 0.98222222 | M30: =IF(K30>0,3600/K30*L30,0) -> 58.933333 | N30: =M30*$B$7 -> 8840
A31: 13 | B31: Control de calidad — Espesor | C31: Medidor de espesores Melisam MR017 | D31: 1 | E31: 1 | F31: 1 | G31: 1 | H31: Todos | I31: 1 | J31: 0.02 | K31: 120 | L31: =F63 -> 1 | M31: =IF(K31>0,3600/K31*L31,0) -> 30 | N31: =M31*$B$7 -> 4500
A32: 14 | B32: Prueba hidráulica | C32: Banco Firesafer FS-JD12A | D32: 1 | E32: 1 | F32: 1 | G32: 1 | H32: Todos | I32: 1 | J32: 1 | K32: 60 | L32: =F64 -> 0.98222222 | M32: =IF(K32>0,3600/K32*L32,0) -> 58.933333 | N32: =M32*$B$7 -> 8840
A33: 15 | B33: Secado | C33: Secadora de cilindros Yukon | D33: 1 | E33: 1 | F33: 1 | G33: 1 | H33: Todos | I33: 1 | J33: 1 | K33: 120 | L33: =F65 -> 1 | M33: =IF(K33>0,3600/K33*L33,0) -> 30 | N33: =M33*$B$7 -> 4500 | O33: las 4 maquinas sirven para secado de carros
A34: 16 | B34: Granallado | C34: Granalladora de rodillos AirBlast G-100 | D34: 1 | E34: 1 | F34: 1 | G34: 1 | H34: Todos | I34: 1 | J34: 1 | K34: 30 | L34: =F66 -> 1 | M34: =IF(K34>0,3600/K34*L34,0) -> 120 | N34: =M34*$B$7 -> 18000
A35: 17 | B35: Detección de defectos | C35: Mesa de inspección con iluminación | D35: 1 | E35: 1 | F35: 1 | G35: 1 | H35: Todos | I35: 1 | J35: 1 | K35: 20 | L35: =F67 -> 1 | M35: =IF(K35>0,3600/K35*L35,0) -> 180 | N35: =M35*$B$7 -> 27000
A36: 18 | B36: Corrección de defectos | C36: Amoladora 115 mm + machos y calibres | D36: 1 | E36: 1 | F36: 1 | G36: 1 | H36: Todos | I36: 1 | J36: 0.05 | K36: 180 | L36: =F68 -> 1 | M36: =IF(K36>0,3600/K36*L36,0) -> 20 | N36: =M36*$B$7 -> 3000
A37: 19 | B37: Pintura en polvo + horno | C37: Línea de pintura en polvo Firesafer | D37: 1 | E37: 1 | F37: 1 | G37: 1 | H37: Todos | I37: 1 | J37: 1 | K37: 25 | L37: =F69 -> 0.94666667 | M37: =IF(K37>0,3600/K37*L37,0) -> 136.32 | N37: =M37*$B$7 -> 20448
A38: 20 | B38: Carga de polvo | C38: Cargadora Firesafer FS-A10 / Yukon M-000121 | D38: 1 | E38: 1 | F38: 1 | G38: 1 | H38: Terminados | I38: 1 | J38: 1 | K38: 45 | L38: =F70 -> 1 | M38: =IF(K38>0,3600/K38*L38,0) -> 80 | N38: =M38*$B$7 -> 12000
A39: 21 | B39: Ensamblaje | C39: Puesto manual con llave dinamométrica | D39: 1 | E39: 1 | F39: 1 | G39: 1 | H39: Terminados | I39: 1 | J39: 1 | K39: 100 | L39: =F71 -> 0.98222222 | M39: =IF(K39>0,3600/K39*L39,0) -> 35.36 | N39: =M39*$B$7 -> 5304
A40: 22 | B40: Presurización | C40: Pinza neumática Yukon M-000150 + pack N₂ | D40: 1 | E40: 1 | F40: 1 | G40: 1 | H40: Terminados | I40: 1 | J40: 1 | K40: 30 | L40: =F72 -> 1 | M40: =IF(K40>0,3600/K40*L40,0) -> 120 | N40: =M40*$B$7 -> 18000
A41: 23 | B41: Control de calidad — Ensayo de pérdidas | C41: Tanque de inmersión de acero inoxidable | D41: 1 | E41: 1 | F41: 1 | G41: 1 | H41: Terminados | I41: 1 | J41: 1 | K41: 55 | L41: =F73 -> 1 | M41: =IF(K41>0,3600/K41*L41,0) -> 65.454545 | N41: =M41*$B$7 -> 9818.1818
A42: 24 | B42: Etiquetado | C42: Dispensador de etiquetas + impresora Zebra ZD421 | D42: 1 | E42: 1 | F42: 1 | G42: 1 | H42: Terminados | I42: 1 | J42: 1 | K42: 60 | L42: =F74 -> 1 | M42: =IF(K42>0,3600/K42*L42,0) -> 60 | N42: =M42*$B$7 -> 9000
...

Sheet Plan mensual
A1: 2026 | B1: Producto | C1: Tipo | D1: Ene | E1: Feb | F1: Mar | G1: Abr | H1: May | I1: Jun | J1: Jul | K1: Ago | L1: Sep | M1: Oct | N1: Nov | O1: Dic | P1: Total anual
A2: 2026 | B2: ABC 1 kg | C2: Terminado | D2: =datos_base!$B$2*parametros_manuales!B$12 -> 501.48 | E2: =datos_base!$B$2*parametros_manuales!C$12 -> 376.11 | F2: =datos_base!$B$2*parametros_manuales!D$12 -> 334.32 | G2: =datos_base!$B$2*parametros_manuales!E$12 -> 313.425 | H2: =datos_base!$B$2*parametros_manuales!F$12 -> 292.53 | I2: =datos_base!$B$2*parametros_manuales!G$12 -> 292.53 | J2: =datos_base!$B$2*parametros_manuales!H$12 -> 313.425 | K2: =datos_base!$B$2*parametros_manuales!I$12 -> 313.425 | ... O2: =datos_base!$B$2*parametros_manuales!M$12 -> 501.48 | P2: =SUM(D2:O2) -> 4179
A3: 2026 | B3: ABC 2,5 kg | C3: Terminado | D3: =datos_base!$B$3*parametros_manuales!B$13 -> 29.5 | E3: =datos_base!$B$3*parametros_manuales!C$13 -> 23.6 | F3: =datos_base!$B$3*parametros_manuales!D$13 -> 25.075 | G3: =datos_base!$B$3*parametros_manuales!E$13 -> 25.075 | H3: =datos_base!$B$3*parametros_manuales!F$13 -> 23.6 | I3: =datos_base!$B$3*parametros_manuales!G$13 -> 22.125 | J3: =datos_base!$B$3*parametros_manuales!H$13 -> 23.6 | K3: =datos_base!$B$3*parametros_manuales!I$13 -> 23.6 | ... O3: =datos_base!$B$3*parametros_manuales!M$13 -> 32.45 | P3: =SUM(D3:O3) -> 295
A4: 2026 | B4: ABC 5 kg | C4: Terminado | D4: =datos_base!$B$4*parametros_manuales!B$14 -> 225.6 | E4: =datos_base!$B$4*parametros_manuales!C$14 -> 180.48 | F4: =datos_base!$B$4*parametros_manuales!D$14 -> 191.76 | G4: =datos_base!$B$4*parametros_manuales!E$14 -> 191.76 | H4: =datos_base!$B$4*parametros_manuales!F$14 -> 180.48 | I4: =datos_base!$B$4*parametros_manuales!G$14 -> 169.2 | J4: =datos_base!$B$4*parametros_manuales!H$14 -> 180.48 | K4: =datos_base!$B$4*parametros_manuales!I$14 -> 180.48 | ... O4: =datos_base!$B$4*parametros_manuales!M$14 -> 248.16 | P4: =SUM(D4:O4) -> 2256
A5: 2026 | B5: ABC 10 kg | C5: Terminado | D5: =datos_base!$B$5*parametros_manuales!B$15 -> 9.2 | E5: =datos_base!$B$5*parametros_manuales!C$15 -> 7.36 | F5: =datos_base!$B$5*parametros_manuales!D$15 -> 7.82 | G5: =datos_base!$B$5*parametros_manuales!E$15 -> 7.82 | H5: =datos_base!$B$5*parametros_manuales!F$15 -> 7.36 | I5: =datos_base!$B$5*parametros_manuales!G$15 -> 6.9 | J5: =datos_base!$B$5*parametros_manuales!H$15 -> 7.36 | K5: =datos_base!$B$5*parametros_manuales!I$15 -> 7.36 | ... O5: =datos_base!$B$5*parametros_manuales!M$15 -> 10.12 | P5: =SUM(D5:O5) -> 92
A6: 2026 | B6: Cilindros ABC 1 kg | C6: Cilindro | D6: =datos_base!$B$9*parametros_manuales!B$12 -> 0 | E6: =datos_base!$B$9*parametros_manuales!C$12 -> 0 | F6: =datos_base!$B$9*parametros_manuales!D$12 -> 0 | G6: =datos_base!$B$9*parametros_manuales!E$12 -> 0 | H6: =datos_base!$B$9*parametros_manuales!F$12 -> 0 | I6: =datos_base!$B$9*parametros_manuales!G$12 -> 0 | J6: =datos_base!$B$9*parametros_manuales!H$12 -> 0 | K6: =datos_base!$B$9*parametros_manuales!I$12 -> 0 | ... O6: =datos_base!$B$9*parametros_manuales!M$12 -> 0 | P6: =SUM(D6:O6) -> 0
A7: 2026 | B7: Cilindros ABC 2,5 kg | C7: Cilindro | D7: =datos_base!$B$10*parametros_manuales!B$13 -> 0 | E7: =datos_base!$B$10*parametros_manuales!C$13 -> 0 | F7: =datos_base!$B$10*parametros_manuales!D$13 -> 0 | G7: =datos_base!$B$10*parametros_manuales!E$13 -> 0 | H7: =datos_base!$B$10*parametros_manuales!F$13 -> 0 | I7: =datos_base!$B$10*parametros_manuales!G$13 -> 0 | J7: =datos_base!$B$10*parametros_manuales!H$13 -> 0 | K7: =datos_base!$B$10*parametros_manuales!I$13 -> 0 | ... O7: =datos_base!$B$10*parametros_manuales!M$13 -> 0 | P7: =SUM(D7:O7) -> 0
A8: 2026 | B8: Cilindros ABC 5 kg | C8: Cilindro | D8: =datos_base!$B$11*parametros_manuales!B$14 -> 0 | E8: =datos_base!$B$11*parametros_manuales!C$14 -> 0 | F8: =datos_base!$B$11*parametros_manuales!D$14 -> 0 | G8: =datos_base!$B$11*parametros_manuales!E$14 -> 0 | H8: =datos_base!$B$11*parametros_manuales!F$14 -> 0 | I8: =datos_base!$B$11*parametros_manuales!G$14 -> 0 | J8: =datos_base!$B$11*parametros_manuales!H$14 -> 0 | K8: =datos_base!$B$11*parametros_manuales!I$14 -> 0 | ... O8: =datos_base!$B$11*parametros_manuales!M$14 -> 0 | P8: =SUM(D8:O8) -> 0
A9: 2026 | B9: Cilindros ABC 10 kg | C9: Cilindro | D9: =datos_base!$B$12*parametros_manuales!B$15 -> 0 | E9: =datos_base!$B$12*parametros_manuales!C$15 -> 0 | F9: =datos_base!$B$12*parametros_manuales!D$15 -> 0 | G9: =datos_base!$B$12*parametros_manuales!E$15 -> 0 | H9: =datos_base!$B$12*parametros_manuales!F$15 -> 0 | I9: =datos_base!$B$12*parametros_manuales!G$15 -> 0 | J9: =datos_base!$B$12*parametros_manuales!H$15 -> 0 | K9: =datos_base!$B$12*parametros_manuales!I$15 -> 0 | ... O9: =datos_base!$B$12*parametros_manuales!M$15 -> 0 | P9: =SUM(D9:O9) -> 0
B10: Total recipientes | D10: =SUM(D2:D9) -> 765.78 | E10: =SUM(E2:E9) -> 587.55 | F10: =SUM(F2:F9) -> 558.975 | G10: =SUM(G2:G9) -> 538.08 | H10: =SUM(H2:H9) -> 503.97 | I10: =SUM(I2:I9) -> 490.755 | J10: =SUM(J2:J9) -> 524.865 | K10: =SUM(K2:K9) -> 524.865 | ... P10: =SUM(P2:P9) -> 6822
A12: 2027 | B12: Producto | C12: Tipo | D12: Ene | E12: Feb | F12: Mar | G12: Abr | H12: May | I12: Jun | J12: Jul | K12: Ago | L12: Sep | M12: Oct | N12: Nov | O12: Dic | P12: Total anual
A13: 2027 | B13: ABC 1 kg | C13: Terminado | D13: =datos_base!$C$2*parametros_manuales!B$12 -> 719.64 | E13: =datos_base!$C$2*parametros_manuales!C$12 -> 539.73 | F13: =datos_base!$C$2*parametros_manuales!D$12 -> 479.76 | G13: =datos_base!$C$2*parametros_manuales!E$12 -> 449.775 | H13: =datos_base!$C$2*parametros_manuales!F$12 -> 419.79 | I13: =datos_base!$C$2*parametros_manuales!G$12 -> 419.79 | J13: =datos_base!$C$2*parametros_manuales!H$12 -> 449.775 | K13: =datos_base!$C$2*parametros_manuales!I$12 -> 449.775 | ... O13: =datos_base!$C$2*parametros_manuales!M$12 -> 719.64 | P13: =SUM(D13:O13) -> 5997
A14: 2027 | B14: ABC 2,5 kg | C14: Terminado | D14: =datos_base!$C$3*parametros_manuales!B$13 -> 70.9 | E14: =datos_base!$C$3*parametros_manuales!C$13 -> 56.72 | F14: =datos_base!$C$3*parametros_manuales!D$13 -> 60.265 | G14: =datos_base!$C$3*parametros_manuales!E$13 -> 60.265 | H14: =datos_base!$C$3*parametros_manuales!F$13 -> 56.72 | I14: =datos_base!$C$3*parametros_manuales!G$13 -> 53.175 | J14: =datos_base!$C$3*parametros_manuales!H$13 -> 56.72 | K14: =datos_base!$C$3*parametros_manuales!I$13 -> 56.72 | ... O14: =datos_base!$C$3*parametros_manuales!M$13 -> 77.99 | P14: =SUM(D14:O14) -> 709
A15: 2027 | B15: ABC 5 kg | C15: Terminado | D15: =datos_base!$C$4*parametros_manuales!B$14 -> 384.7 | E15: =datos_base!$C$4*parametros_manuales!C$14 -> 307.76 | F15: =datos_base!$C$4*parametros_manuales!D$14 -> 326.995 | G15: =datos_base!$C$4*parametros_manuales!E$14 -> 326.995 | H15: =datos_base!$C$4*parametros_manuales!F$14 -> 307.76 | I15: =datos_base!$C$4*parametros_manuales!G$14 -> 288.525 | J15: =datos_base!$C$4*parametros_manuales!H$14 -> 307.76 | K15: =datos_base!$C$4*parametros_manuales!I$14 -> 307.76 | ... O15: =datos_base!$C$4*parametros_manuales!M$14 -> 423.17 | P15: =SUM(D15:O15) -> 3847
A16: 2027 | B16: ABC 10 kg | C16: Terminado | D16: =datos_base!$C$5*parametros_manuales!B$15 -> 17.7 | E16: =datos_base!$C$5*parametros_manuales!C$15 -> 14.16 | F16: =datos_base!$C$5*parametros_manuales!D$15 -> 15.045 | G16: =datos_base!$C$5*parametros_manuales!E$15 -> 15.045 | H16: =datos_base!$C$5*parametros_manuales!F$15 -> 14.16 | I16: =datos_base!$C$5*parametros_manuales!G$15 -> 13.275 | J16: =datos_base!$C$5*parametros_manuales!H$15 -> 14.16 | K16: =datos_base!$C$5*parametros_manuales!I$15 -> 14.16 | ... O16: =datos_base!$C$5*parametros_manuales!M$15 -> 19.47 | P16: =SUM(D16:O16) -> 177
A17: 2027 | B17: Cilindros ABC 1 kg | C17: Cilindro | D17: =datos_base!$C$9*parametros_manuales!B$12 -> 0 | E17: =datos_base!$C$9*parametros_manuales!C$12 -> 0 | F17: =datos_base!$C$9*parametros_manuales!D$12 -> 0 | G17: =datos_base!$C$9*parametros_manuales!E$12 -> 0 | H17: =datos_base!$C$9*parametros_manuales!F$12 -> 0 | I17: =datos_base!$C$9*parametros_manuales!G$12 -> 0 | J17: =datos_base!$C$9*parametros_manuales!H$12 -> 0 | K17: =datos_base!$C$9*parametros_manuales!I$12 -> 0 | ... O17: =datos_base!$C$9*parametros_manuales!M$12 -> 0 | P17: =SUM(D17:O17) -> 0
A18: 2027 | B18: Cilindros ABC 2,5 kg | C18: Cilindro | D18: =datos_base!$C$10*parametros_manuales!B$13 -> 0 | E18: =datos_base!$C$10*parametros_manuales!C$13 -> 0 | F18: =datos_base!$C$10*parametros_manuales!D$13 -> 0 | G18: =datos_base!$C$10*parametros_manuales!E$13 -> 0 | H18: =datos_base!$C$10*parametros_manuales!F$13 -> 0 | I18: =datos_base!$C$10*parametros_manuales!G$13 -> 0 | J18: =datos_base!$C$10*parametros_manuales!H$13 -> 0 | K18: =datos_base!$C$10*parametros_manuales!I$13 -> 0 | ... O18: =datos_base!$C$10*parametros_manuales!M$13 -> 0 | P18: =SUM(D18:O18) -> 0
A19: 2027 | B19: Cilindros ABC 5 kg | C19: Cilindro | D19: =datos_base!$C$11*parametros_manuales!B$14 -> 0 | E19: =datos_base!$C$11*parametros_manuales!C$14 -> 0 | F19: =datos_base!$C$11*parametros_manuales!D$14 -> 0 | G19: =datos_base!$C$11*parametros_manuales!E$14 -> 0 | H19: =datos_base!$C$11*parametros_manuales!F$14 -> 0 | I19: =datos_base!$C$11*parametros_manuales!G$14 -> 0 | J19: =datos_base!$C$11*parametros_manuales!H$14 -> 0 | K19: =datos_base!$C$11*parametros_manuales!I$14 -> 0 | ... O19: =datos_base!$C$11*parametros_manuales!M$14 -> 0 | P19: =SUM(D19:O19) -> 0
A20: 2027 | B20: Cilindros ABC 10 kg | C20: Cilindro | D20: =datos_base!$C$12*parametros_manuales!B$15 -> 0 | E20: =datos_base!$C$12*parametros_manuales!C$15 -> 0 | F20: =datos_base!$C$12*parametros_manuales!D$15 -> 0 | G20: =datos_base!$C$12*parametros_manuales!E$15 -> 0 | H20: =datos_base!$C$12*parametros_manuales!F$15 -> 0 | I20: =datos_base!$C$12*parametros_manuales!G$15 -> 0 | J20: =datos_base!$C$12*parametros_manuales!H$15 -> 0 | K20: =datos_base!$C$12*parametros_manuales!I$15 -> 0 | ... O20: =datos_base!$C$12*parametros_manuales!M$15 -> 0 | P20: =SUM(D20:O20) -> 0
B21: Total recipientes | D21: =SUM(D13:D20) -> 1192.94 | E21: =SUM(E13:E20) -> 918.37 | F21: =SUM(F13:F20) -> 882.065 | G21: =SUM(G13:G20) -> 852.08 | H21: =SUM(H13:H20) -> 798.43 | I21: =SUM(I13:I20) -> 774.765 | J21: =SUM(J13:J20) -> 828.415 | K21: =SUM(K13:K20) -> 828.415 | ... P21: =SUM(P13:P20) -> 10730
A23: 2028 | B23: Producto | C23: Tipo | D23: Ene | E23: Feb | F23: Mar | G23: Abr | H23: May | I23: Jun | J23: Jul | K23: Ago | L23: Sep | M23: Oct | N23: Nov | O23: Dic | P23: Total anual
A24: 2028 | B24: ABC 1 kg | C24: Terminado | D24: =datos_base!$D$2*parametros_manuales!B$12 -> 822.24 | E24: =datos_base!$D$2*parametros_manuales!C$12 -> 616.68 | F24: =datos_base!$D$2*parametros_manuales!D$12 -> 548.16 | G24: =datos_base!$D$2*parametros_manuales!E$12 -> 513.9 | H24: =datos_base!$D$2*parametros_manuales!F$12 -> 479.64 | I24: =datos_base!$D$2*parametros_manuales!G$12 -> 479.64 | J24: =datos_base!$D$2*parametros_manuales!H$12 -> 513.9 | K24: =datos_base!$D$2*parametros_manuales!I$12 -> 513.9 | ... O24: =datos_base!$D$2*parametros_manuales!M$12 -> 822.24 | P24: =SUM(D24:O24) -> 6852
A25: 2028 | B25: ABC 2,5 kg | C25: Terminado | D25: =datos_base!$D$3*parametros_manuales!B$13 -> 98.7 | E25: =datos_base!$D$3*parametros_manuales!C$13 -> 78.96 | F25: =datos_base!$D$3*parametros_manuales!D$13 -> 83.895 | G25: =datos_base!$D$3*parametros_manuales!E$13 -> 83.895 | H25: =datos_base!$D$3*parametros_manuales!F$13 -> 78.96 | I25: =datos_base!$D$3*parametros_manuales!G$13 -> 74.025 | J25: =datos_base!$D$3*parametros_manuales!H$13 -> 78.96 | K25: =datos_base!$D$3*parametros_manuales!I$13 -> 78.96 | ... O25: =datos_base!$D$3*parametros_manuales!M$13 -> 108.57 | P25: =SUM(D25:O25) -> 987
A26: 2028 | B26: ABC 5 kg | C26: Terminado | D26: =datos_base!$D$4*parametros_manuales!B$14 -> 509.4 | E26: =datos_base!$D$4*parametros_manuales!C$14 -> 407.52 | F26: =datos_base!$D$4*parametros_manuales!D$14 -> 432.99 | G26: =datos_base!$D$4*parametros_manuales!E$14 -> 432.99 | H26: =datos_base!$D$4*parametros_manuales!F$14 -> 407.52 | I26: =datos_base!$D$4*parametros_manuales!G$14 -> 382.05 | J26: =datos_base!$D$4*parametros_manuales!H$14 -> 407.52 | K26: =datos_base!$D$4*parametros_manuales!I$14 -> 407.52 | ... O26: =datos_base!$D$4*parametros_manuales!M$14 -> 560.34 | P26: =SUM(D26:O26) -> 5094
A27: 2028 | B27: ABC 10 kg | C27: Terminado | D27: =datos_base!$D$5*parametros_manuales!B$15 -> 25.3 | E27: =datos_base!$D$5*parametros_manuales!C$15 -> 20.24 | F27: =datos_base!$D$5*parametros_manuales!D$15 -> 21.505 | G27: =datos_base!$D$5*parametros_manuales!E$15 -> 21.505 | H27: =datos_base!$D$5*parametros_manuales!F$15 -> 20.24 | I27: =datos_base!$D$5*parametros_manuales!G$15 -> 18.975 | J27: =datos_base!$D$5*parametros_manuales!H$15 -> 20.24 | K27: =datos_base!$D$5*parametros_manuales!I$15 -> 20.24 | ... O27: =datos_base!$D$5*parametros_manuales!M$15 -> 27.83 | P27: =SUM(D27:O27) -> 253
A28: 2028 | B28: Cilindros ABC 1 kg | C28: Cilindro | D28: =datos_base!$D$9*parametros_manuales!B$12 -> 919.44 | E28: =datos_base!$D$9*parametros_manuales!C$12 -> 689.58 | F28: =datos_base!$D$9*parametros_manuales!D$12 -> 612.96 | G28: =datos_base!$D$9*parametros_manuales!E$12 -> 574.65 | H28: =datos_base!$D$9*parametros_manuales!F$12 -> 536.34 | I28: =datos_base!$D$9*parametros_manuales!G$12 -> 536.34 | J28: =datos_base!$D$9*parametros_manuales!H$12 -> 574.65 | K28: =datos_base!$D$9*parametros_manuales!I$12 -> 574.65 | ... O28: =datos_base!$D$9*parametros_manuales!M$12 -> 919.44 | P28: =SUM(D28:O28) -> 7662
A29: 2028 | B29: Cilindros ABC 2,5 kg | C29: Cilindro | D29: =datos_base!$D$10*parametros_manuales!B$13 -> 30 | E29: =datos_base!$D$10*parametros_manuales!C$13 -> 24 | F29: =datos_base!$D$10*parametros_manuales!D$13 -> 25.5 | G29: =datos_base!$D$10*parametros_manuales!E$13 -> 25.5 | H29: =datos_base!$D$10*parametros_manuales!F$13 -> 24 | I29: =datos_base!$D$10*parametros_manuales!G$13 -> 22.5 | J29: =datos_base!$D$10*parametros_manuales!H$13 -> 24 | K29: =datos_base!$D$10*parametros_manuales!I$13 -> 24 | ... O29: =datos_base!$D$10*parametros_manuales!M$13 -> 33 | P29: =SUM(D29:O29) -> 300
A30: 2028 | B30: Cilindros ABC 5 kg | C30: Cilindro | D30: =datos_base!$D$11*parametros_manuales!B$14 -> 147.9 | E30: =datos_base!$D$11*parametros_manuales!C$14 -> 118.32 | F30: =datos_base!$D$11*parametros_manuales!D$14 -> 125.715 | G30: =datos_base!$D$11*parametros_manuales!E$14 -> 125.715 | H30: =datos_base!$D$11*parametros_manuales!F$14 -> 118.32 | I30: =datos_base!$D$11*parametros_manuales!G$14 -> 110.925 | J30: =datos_base!$D$11*parametros_manuales!H$14 -> 118.32 | K30: =datos_base!$D$11*parametros_manuales!I$14 -> 118.32 | ... O30: =datos_base!$D$11*parametros_manuales!M$14 -> 162.69 | P30: =SUM(D30:O30) -> 1479
A31: 2028 | B31: Cilindros ABC 10 kg | C31: Cilindro | D31: =datos_base!$D$12*parametros_manuales!B$15 -> 9 | E31: =datos_base!$D$12*parametros_manuales!C$15 -> 7.2 | F31: =datos_base!$D$12*parametros_manuales!D$15 -> 7.65 | G31: =datos_base!$D$12*parametros_manuales!E$15 -> 7.65 | H31: =datos_base!$D$12*parametros_manuales!F$15 -> 7.2 | I31: =datos_base!$D$12*parametros_manuales!G$15 -> 6.75 | J31: =datos_base!$D$12*parametros_manuales!H$15 -> 7.2 | K31: =datos_base!$D$12*parametros_manuales!I$15 -> 7.2 | ... O31: =datos_base!$D$12*parametros_manuales!M$15 -> 9.9 | P31: =SUM(D31:O31) -> 90
B32: Total recipientes | D32: =SUM(D24:D31) -> 2561.98 | E32: =SUM(E24:E31) -> 1962.5 | F32: =SUM(F24:F31) -> 1858.375 | G32: =SUM(G24:G31) -> 1785.805 | H32: =SUM(H24:H31) -> 1672.22 | I32: =SUM(I24:I31) -> 1631.205 | J32: =SUM(J24:J31) -> 1744.79 | K32: =SUM(K24:K31) -> 1744.79 | ... P32: =SUM(P24:P31) -> 22717
A34: 2029 | B34: Producto | C34: Tipo | D34: Ene | E34: Feb | F34: Mar | G34: Abr | H34: May | I34: Jun | J34: Jul | K34: Ago | L34: Sep | M34: Oct | N34: Nov | O34: Dic | P34: Total anual
A35: 2029 | B35: ABC 1 kg | C35: Terminado | D35: =datos_base!$E$2*parametros_manuales!B$12 -> 1016.04 | E35: =datos_base!$E$2*parametros_manuales!C$12 -> 762.03 | F35: =datos_base!$E$2*parametros_manuales!D$12 -> 677.36 | G35: =datos_base!$E$2*parametros_manuales!E$12 -> 635.025 | H35: =datos_base!$E$2*parametros_manuales!F$12 -> 592.69 | I35: =datos_base!$E$2*parametros_manuales!G$12 -> 592.69 | J35: =datos_base!$E$2*parametros_manuales!H$12 -> 635.025 | K35: =datos_base!$E$2*parametros_manuales!I$12 -> 635.025 | ... O35: =datos_base!$E$2*parametros_manuales!M$12 -> 1016.04 | P35: =SUM(D35:O35) -> 8467
A36: 2029 | B36: ABC 2,5 kg | C36: Terminado | D36: =datos_base!$E$3*parametros_manuales!B$13 -> 150.1 | E36: =datos_base!$E$3*parametros_manuales!C$13 -> 120.08 | F36: =datos_base!$E$3*parametros_manuales!D$13 -> 127.585 | G36: =datos_base!$E$3*parametros_manuales!E$13 -> 127.585 | H36: =datos_base!$E$3*parametros_manuales!F$13 -> 120.08 | I36: =datos_base!$E$3*parametros_manuales!G$13 -> 112.575 | J36: =datos_base!$E$3*parametros_manuales!H$13 -> 120.08 | K36: =datos_base!$E$3*parametros_manuales!I$13 -> 120.08 | ... O36: =datos_base!$E$3*parametros_manuales!M$13 -> 165.11 | P36: =SUM(D36:O36) -> 1501
A37: 2029 | B37: ABC 5 kg | C37: Terminado | D37: =datos_base!$E$4*parametros_manuales!B$14 -> 682.3 | E37: =datos_base!$E$4*parametros_manuales!C$14 -> 545.84 | F37: =datos_base!$E$4*parametros_manuales!D$14 -> 579.955 | G37: =datos_base!$E$4*parametros_manuales!E$14 -> 579.955 | H37: =datos_base!$E$4*parametros_manuales!F$14 -> 545.84 | I37: =datos_base!$E$4*parametros_manuales!G$14 -> 511.725 | J37: =datos_base!$E$4*parametros_manuales!H$14 -> 545.84 | K37: =datos_base!$E$4*parametros_manuales!I$14 -> 545.84 | ... O37: =datos_base!$E$4*parametros_manuales!M$14 -> 750.53 | P37: =SUM(D37:O37) -> 6823
A38: 2029 | B38: ABC 10 kg | C38: Terminado | D38: =datos_base!$E$5*parametros_manuales!B$15 -> 35.8 | E38: =datos_base!$E$5*parametros_manuales!C$15 -> 28.64 | F38: =datos_base!$E$5*parametros_manuales!D$15 -> 30.43 | G38: =datos_base!$E$5*parametros_manuales!E$15 -> 30.43 | H38: =datos_base!$E$5*parametros_manuales!F$15 -> 28.64 | I38: =datos_base!$E$5*parametros_manuales!G$15 -> 26.85 | J38: =datos_base!$E$5*parametros_manuales!H$15 -> 28.64 | K38: =datos_base!$E$5*parametros_manuales!I$15 -> 28.64 | ... O38: =datos_base!$E$5*parametros_manuales!M$15 -> 39.38 | P38: =SUM(D38:O38) -> 358
A39: 2029 | B39: Cilindros ABC 1 kg | C39: Cilindro | D39: =datos_base!$E$9*parametros_manuales!B$12 -> 3203.4 | E39: =datos_base!$E$9*parametros_manuales!C$12 -> 2402.55 | F39: =datos_base!$E$9*parametros_manuales!D$12 -> 2135.6 | G39: =datos_base!$E$9*parametros_manuales!E$12 -> 2002.125 | H39: =datos_base!$E$9*parametros_manuales!F$12 -> 1868.65 | I39: =datos_base!$E$9*parametros_manuales!G$12 -> 1868.65 | J39: =datos_base!$E$9*parametros_manuales!H$12 -> 2002.125 | K39: =datos_base!$E$9*parametros_manuales!I$12 -> 2002.125 | ... O39: =datos_base!$E$9*parametros_manuales!M$12 -> 3203.4 | P39: =SUM(D39:O39) -> 26695
A40: 2029 | B40: Cilindros ABC 2,5 kg | C40: Cilindro | D40: =datos_base!$E$10*parametros_manuales!B$13 -> 104.4 | E40: =datos_base!$E$10*parametros_manuales!C$13 -> 83.52 | F40: =datos_base!$E$10*parametros_manuales!D$13 -> 88.74 | G40: =datos_base!$E$10*parametros_manuales!E$13 -> 88.74 | H40: =datos_base!$E$10*parametros_manuales!F$13 -> 83.52 | I40: =datos_base!$E$10*parametros_manuales!G$13 -> 78.3 | J40: =datos_base!$E$10*parametros_manuales!H$13 -> 83.52 | K40: =datos_base!$E$10*parametros_manuales!I$13 -> 83.52 | ... O40: =datos_base!$E$10*parametros_manuales!M$13 -> 114.84 | P40: =SUM(D40:O40) -> 1044
A41: 2029 | B41: Cilindros ABC 5 kg | C41: Cilindro | D41: =datos_base!$E$11*parametros_manuales!B$14 -> 515.2 | E41: =datos_base!$E$11*parametros_manuales!C$14 -> 412.16 | F41: =datos_base!$E$11*parametros_manuales!D$14 -> 437.92 | G41: =datos_base!$E$11*parametros_manuales!E$14 -> 437.92 | H41: =datos_base!$E$11*parametros_manuales!F$14 -> 412.16 | I41: =datos_base!$E$11*parametros_manuales!G$14 -> 386.4 | J41: =datos_base!$E$11*parametros_manuales!H$14 -> 412.16 | K41: =datos_base!$E$11*parametros_manuales!I$14 -> 412.16 | ... O41: =datos_base!$E$11*parametros_manuales!M$14 -> 566.72 | P41: =SUM(D41:O41) -> 5152
A42: 2029 | B42: Cilindros ABC 10 kg | C42: Cilindro | D42: =datos_base!$E$12*parametros_manuales!B$15 -> 31.5 | E42: =datos_base!$E$12*parametros_manuales!C$15 -> 25.2 | F42: =datos_base!$E$12*parametros_manuales!D$15 -> 26.775 | G42: =datos_base!$E$12*parametros_manuales!E$15 -> 26.775 | H42: =datos_base!$E$12*parametros_manuales!F$15 -> 25.2 | I42: =datos_base!$E$12*parametros_manuales!G$15 -> 23.625 | J42: =datos_base!$E$12*parametros_manuales!H$15 -> 25.2 | K42: =datos_base!$E$12*parametros_manuales!I$15 -> 25.2 | ... O42: =datos_base!$E$12*parametros_manuales!M$15 -> 34.65 | P42: =SUM(D42:O42) -> 315
B43: Total recipientes | D43: =SUM(D35:D42) -> 5738.74 | E43: =SUM(E35:E42) -> 4380.02 | F43: =SUM(F35:F42) -> 4104.365 | G43: =SUM(G35:G42) -> 3928.555 | H43: =SUM(H35:H42) -> 3676.78 | I43: =SUM(I35:I42) -> 3600.815 | J43: =SUM(J35:J42) -> 3852.59 | K43: =SUM(K35:K42) -> 3852.59 | ... P43: =SUM(P35:P42) -> 50355
...

Sheet Demanda puesto sin sobrestock
A1: Año 2026 | B1: Ene | C1: Feb | D1: Mar | E1: Abr | F1: May | G1: Jun | H1: Jul | I1: Ago | J1: Sep | K1: Oct | L1: Nov | M1: Dic | N1: Total anual | O1: Mes pico (u/mes) | P1: Demanda pico (u/h) | Q1: Mes pico
A2: =parametros_manuales!$B$19 -> Recepción de materia prima | B2: =(parametros_manuales!$D$19*('Plan mensual'!D2+IF(parametros_manuales!$H$19="Todos",'Plan mensual'!D6,0))+parametros_manuales!$E$19*('Plan mensual'!D3+IF(parametros_manuales!$H$19="Todos",'Plan mensual'!D7,0))+parametros_manuales!$F$19*('Plan mensual'!D4+IF(parametros_manuales!$H$19="Todos",'Plan mensual'!D8,0))+parametros_manuales!$G$19*('Plan mensual'!D5+IF(parametros_manuales!$H$19="Todos",'Plan mensual'!D9,0)))*parametros_manuales!$I$19*parametros_manuales!$J$19 -> 765.78 | C2: =(parametros_manuales!$D$19*('Plan mensual'!E2+IF(parametros_manuales!$H$19="Todos",'Plan mensual'!E6,0))+parametros_manuales!$E$19*('Plan mensual'!E3+IF(parametros_manuales!$H$19="Todos",'Plan mensual'!E7,0))+parametros_manuales!$F$19*('Plan mensual'!E4+IF(parametros_manuales!$H$19="Todos",'Plan mensual'!E8,0))+parametros_manuales!$G$19*('Plan mensual'!E5+IF(parametros_manuales!$H$19="Todos",'Plan mensual'!E9,0)))*parametros_manuales!$I$19*parametros_manuales!$J$19 -> 587.55 | D2: =(parametros_manuales!$D$19*('Plan mensual'!F2+IF(parametros_manuales!$H$19="Todos",'Plan mensual'!F6,0))+parametros_manuales!$E$19*('Plan mensual'!F3+IF(parametros_manuales!$H$19="Todos",'Plan mensual'!F7,0))+parametros_manuales!$F$19*('Plan mensual'!F4+IF(parametros_manuales!$H$19="Todos",'Plan mensual'!F8,0))+parametros_manuales!$G$19*('Plan mensual'!F5+IF(parametros_manuales!$H$19="Todos",'Plan mensual'!F9,0)))*parametros_manuales!$I$19*parametros_manuales!$J$19 -> 558.975 | E2: =(parametros_manuales!$D$19*('Plan mensual'!G2+IF(parametros_manuales!$H$19="Todos",'Plan mensual'!G6,0))+parametros_manuales!$E$19*('Plan mensual'!G3+IF(parametros_manuales!$H$19="Todos",'Plan mensual'!G7,0))+parametros_manuales!$F$19*('Plan mensual'!G4+IF(parametros_manuales!$H$19="Todos",'Plan mensual'!G8,0))+parametros_manuales!$G$19*('Plan mensual'!G5+IF(parametros_manuales!$H$19="Todos",'Plan mensual'!G9,0)))*parametros_manuales!$I$19*parametros_manuales!$J$19 -> 538.08 | F2: =(parametros_manuales!$D$19*('Plan mensual'!H2+IF(parametros_manuales!$H$19="Todos",'Plan mensual'!H6,0))+parametros_manuales!$E$19*('Plan mensual'!H3+IF(parametros_manuales!$H$19="Todos",'Plan mensual'!H7,0))+parametros_manuales!$F$19*('Plan mensual'!H4+IF(parametros_manuales!$H$19="Todos",'Plan mensual'!H8,0))+parametros_manuales!$G$19*('Plan mensual'!H5+IF(parametros_manuales!$H$19="Todos",'Plan mensual'!H9,0)))*parametros_manuales!$I$19*parametros_manuales!$J$19 -> 503.97 | G2: =(parametros_manuales!$D$19*('Plan mensual'!I2+IF(parametros_manuales!$H$19="Todos",'Plan mensual'!I6,0))+parametros_manuales!$E$19*('Plan mensual'!I3+IF(parametros_manuales!$H$19="Todos",'Plan mensual'!I7,0))+parametros_manuales!$F$19*('Plan mensual'!I4+IF(parametros_manuales!$H$19="Todos",'Plan mensual'!I8,0))+parametros_manuales!$G$19*('Plan mensual'!I5+IF(parametros_manuales!$H$19="Todos",'Plan mensual'!I9,0)))*parametros_manuales!$I$19*parametros_manuales!$J$19 -> 490.755 | H2: =(parametros_manuales!$D$19*('Plan mensual'!J2+IF(parametros_manuales!$H$19="Todos",'Plan mensual'!J6,0))+parametros_manuales!$E$19*('Plan mensual'!J3+IF(parametros_manuales!$H$19="Todos",'Plan mensual'!J7,0))+parametros_manuales!$F$19*('Plan mensual'!J4+IF(parametros_manuales!$H$19="Todos",'Plan mensual'!J8,0))+parametros_manuales!$G$19*('Plan mensual'!J5+IF(parametros_manuales!$H$19="Todos",'Plan mensual'!J9,0)))*parametros_manuales!$I$19*parametros_manuales!$J$19 -> 524.865 | I2: =(parametros_manuales!$D$19*('Plan mensual'!K2+IF(parametros_manuales!$H$19="Todos",'Plan mensual'!K6,0))+parametros_manuales!$E$19*('Plan mensual'!K3+IF(parametros_manuales!$H$19="Todos",'Plan mensual'!K7,0))+parametros_manuales!$F$19*('Plan mensual'!K4+IF(parametros_manuales!$H$19="Todos",'Plan mensual'!K8,0))+parametros_manuales!$G$19*('Plan mensual'!K5+IF(parametros_manuales!$H$19="Todos",'Plan mensual'!K9,0)))*parametros_manuales!$I$19*parametros_manuales!$J$19 -> 524.865 | ... M2: =(parametros_manuales!$D$19*('Plan mensual'!O2+IF(parametros_manuales!$H$19="Todos",'Plan mensual'!O6,0))+parametros_manuales!$E$19*('Plan mensual'!O3+IF(parametros_manuales!$H$19="Todos",'Plan mensual'!O7,0))+parametros_manuales!$F$19*('Plan mensual'!O4+IF(parametros_manuales!$H$19="Todos",'Plan mensual'!O8,0))+parametros_manuales!$G$19*('Plan mensual'!O5+IF(parametros_manuales!$H$19="Todos",'Plan mensual'!O9,0)))*parametros_manuales!$I$19*parametros_manuales!$J$19 -> 792.21 | N2: =SUM(B2:M2) -> 6822 | O2: =MAX(B2:M2) -> 792.21 | P2: =O2/(parametros_manuales!$B$7) -> 5.2814 | Q2: =IF(O2=0,"-",INDEX($B$1:$M$1,MATCH(O2,B2:M2,0))) -> Dic
A3: =parametros_manuales!$B$20 -> Corte de chapa (guillotina) — 2,5 a 10 kg | B3: =(parametros_manuales!$D$20*('Plan mensual'!D2+IF(parametros_manuales!$H$20="Todos",'Plan mensual'!D6,0))+parametros_manuales!$E$20*('Plan mensual'!D3+IF(parametros_manuales!$H$20="Todos",'Plan mensual'!D7,0))+parametros_manuales!$F$20*('Plan mensual'!D4+IF(parametros_manuales!$H$20="Todos",'Plan mensual'!D8,0))+parametros_manuales!$G$20*('Plan mensual'!D5+IF(parametros_manuales!$H$20="Todos",'Plan mensual'!D9,0)))*parametros_manuales!$I$20*parametros_manuales!$J$20 -> 264.3 | C3: =(parametros_manuales!$D$20*('Plan mensual'!E2+IF(parametros_manuales!$H$20="Todos",'Plan mensual'!E6,0))+parametros_manuales!$E$20*('Plan mensual'!E3+IF(parametros_manuales!$H$20="Todos",'Plan mensual'!E7,0))+parametros_manuales!$F$20*('Plan mensual'!E4+IF(parametros_manuales!$H$20="Todos",'Plan mensual'!E8,0))+parametros_manuales!$G$20*('Plan mensual'!E5+IF(parametros_manuales!$H$20="Todos",'Plan mensual'!E9,0)))*parametros_manuales!$I$20*parametros_manuales!$J$20 -> 211.44 | D3: =(parametros_manuales!$D$20*('Plan mensual'!F2+IF(parametros_manuales!$H$20="Todos",'Plan mensual'!F6,0))+parametros_manuales!$E$20*('Plan mensual'!F3+IF(parametros_manuales!$H$20="Todos",'Plan mensual'!F7,0))+parametros_manuales!$F$20*('Plan mensual'!F4+IF(parametros_manuales!$H$20="Todos",'Plan mensual'!F8,0))+parametros_manuales!$G$20*('Plan mensual'!F5+IF(parametros_manuales!$H$20="Todos",'Plan mensual'!F9,0)))*parametros_manuales!$I$20*parametros_manuales!$J$20 -> 224.655 | E3: =(parametros_manuales!$D$20*('Plan mensual'!G2+IF(parametros_manuales!$H$20="Todos",'Plan mensual'!G6,0))+parametros_manuales!$E$20*('Plan mensual'!G3+IF(parametros_manuales!$H$20="Todos",'Plan mensual'!G7,0))+parametros_manuales!$F$20*('Plan mensual'!G4+IF(parametros_manuales!$H$20="Todos",'Plan mensual'!G8,0))+parametros_manuales!$G$20*('Plan mensual'!G5+IF(parametros_manuales!$H$20="Todos",'Plan mensual'!G9,0)))*parametros_manuales!$I$20*parametros_manuales!$J$20 -> 224.655 | F3: =(parametros_manuales!$D$20*('Plan mensual'!H2+IF(parametros_manuales!$H$20="Todos",'Plan mensual'!H6,0))+parametros_manuales!$E$20*('Plan mensual'!H3+IF(parametros_manuales!$H$20="Todos",'Plan mensual'!H7,0))+parametros_manuales!$F$20*('Plan mensual'!H4+IF(parametros_manuales!$H$20="Todos",'Plan mensual'!H8,0))+parametros_manuales!$G$20*('Plan mensual'!H5+IF(parametros_manuales!$H$20="Todos",'Plan mensual'!H9,0)))*parametros_manuales!$I$20*parametros_manuales!$J$20 -> 211.44 | G3: =(parametros_manuales!$D$20*('Plan mensual'!I2+IF(parametros_manuales!$H$20="Todos",'Plan mensual'!I6,0))+parametros_manuales!$E$20*('Plan mensual'!I3+IF(parametros_manuales!$H$20="Todos",'Plan mensual'!I7,0))+parametros_manuales!$F$20*('Plan mensual'!I4+IF(parametros_manuales!$H$20="Todos",'Plan mensual'!I8,0))+parametros_manuales!$G$20*('Plan mensual'!I5+IF(parametros_manuales!$H$20="Todos",'Plan mensual'!I9,0)))*parametros_manuales!$I$20*parametros_manuales!$J$20 -> 198.225 | H3: =(parametros_manuales!$D$20*('Plan mensual'!J2+IF(parametros_manuales!$H$20="Todos",'Plan mensual'!J6,0))+parametros_manuales!$E$20*('Plan mensual'!J3+IF(parametros_manuales!$H$20="Todos",'Plan mensual'!J7,0))+parametros_manuales!$F$20*('Plan mensual'!J4+IF(parametros_manuales!$H$20="Todos",'Plan mensual'!J8,0))+parametros_manuales!$G$20*('Plan mensual'!J5+IF(parametros_manuales!$H$20="Todos",'Plan mensual'!J9,0)))*parametros_manuales!$I$20*parametros_manuales!$J$20 -> 211.44 | I3: =(parametros_manuales!$D$20*('Plan mensual'!K2+IF(parametros_manuales!$H$20="Todos",'Plan mensual'!K6,0))+parametros_manuales!$E$20*('Plan mensual'!K3+IF(parametros_manuales!$H$20="Todos",'Plan mensual'!K7,0))+parametros_manuales!$F$20*('Plan mensual'!K4+IF(parametros_manuales!$H$20="Todos",'Plan mensual'!K8,0))+parametros_manuales!$G$20*('Plan mensual'!K5+IF(parametros_manuales!$H$20="Todos",'Plan mensual'!K9,0)))*parametros_manuales!$I$20*parametros_manuales!$J$20 -> 211.44 | ... M3: =(parametros_manuales!$D$20*('Plan mensual'!O2+IF(parametros_manuales!$H$20="Todos",'Plan mensual'!O6,0))+parametros_manuales!$E$20*('Plan mensual'!O3+IF(parametros_manuales!$H$20="Todos",'Plan mensual'!O7,0))+parametros_manuales!$F$20*('Plan mensual'!O4+IF(parametros_manuales!$H$20="Todos",'Plan mensual'!O8,0))+parametros_manuales!$G$20*('Plan mensual'!O5+IF(parametros_manuales!$H$20="Todos",'Plan mensual'!O9,0)))*parametros_manuales!$I$20*parametros_manuales!$J$20 -> 290.73 | N3: =SUM(B3:M3) -> 2643 | O3: =MAX(B3:M3) -> 290.73 | P3: =O3/(parametros_manuales!$B$7) -> 1.9382 | Q3: =IF(O3=0,"-",INDEX($B$1:$M$1,MATCH(O3,B3:M3,0))) -> Dic
A4: =parametros_manuales!$B$21 -> Corte de tubo — 1 kg | B4: =(parametros_manuales!$D$21*('Plan mensual'!D2+IF(parametros_manuales!$H$21="Todos",'Plan mensual'!D6,0))+parametros_manuales!$E$21*('Plan mensual'!D3+IF(parametros_manuales!$H$21="Todos",'Plan mensual'!D7,0))+parametros_manuales!$F$21*('Plan mensual'!D4+IF(parametros_manuales!$H$21="Todos",'Plan mensual'!D8,0))+parametros_manuales!$G$21*('Plan mensual'!D5+IF(parametros_manuales!$H$21="Todos",'Plan mensual'!D9,0)))*parametros_manuales!$I$21*parametros_manuales!$J$21 -> 501.48 | C4: =(parametros_manuales!$D$21*('Plan mensual'!E2+IF(parametros_manuales!$H$21="Todos",'Plan mensual'!E6,0))+parametros_manuales!$E$21*('Plan mensual'!E3+IF(parametros_manuales!$H$21="Todos",'Plan mensual'!E7,0))+parametros_manuales!$F$21*('Plan mensual'!E4+IF(parametros_manuales!$H$21="Todos",'Plan mensual'!E8,0))+parametros_manuales!$G$21*('Plan mensual'!E5+IF(parametros_manuales!$H$21="Todos",'Plan mensual'!E9,0)))*parametros_manuales!$I$21*parametros_manuales!$J$21 -> 376.11 | D4: =(parametros_manuales!$D$21*('Plan mensual'!F2+IF(parametros_manuales!$H$21="Todos",'Plan mensual'!F6,0))+parametros_manuales!$E$21*('Plan mensual'!F3+IF(parametros_manuales!$H$21="Todos",'Plan mensual'!F7,0))+parametros_manuales!$F$21*('Plan mensual'!F4+IF(parametros_manuales!$H$21="Todos",'Plan mensual'!F8,0))+parametros_manuales!$G$21*('Plan mensual'!F5+IF(parametros_manuales!$H$21="Todos",'Plan mensual'!F9,0)))*parametros_manuales!$I$21*parametros_manuales!$J$21 -> 334.32 | E4: =(parametros_manuales!$D$21*('Plan mensual'!G2+IF(parametros_manuales!$H$21="Todos",'Plan mensual'!G6,0))+parametros_manuales!$E$21*('Plan mensual'!G3+IF(parametros_manuales!$H$21="Todos",'Plan mensual'!G7,0))+parametros_manuales!$F$21*('Plan mensual'!G4+IF(parametros_manuales!$H$21="Todos",'Plan mensual'!G8,0))+parametros_manuales!$G$21*('Plan mensual'!G5+IF(parametros_manuales!$H$21="Todos",'Plan mensual'!G9,0)))*parametros_manuales!$I$21*parametros_manuales!$J$21 -> 313.425 | F4: =(parametros_manuales!$D$21*('Plan mensual'!H2+IF(parametros_manuales!$H$21="Todos",'Plan mensual'!H6,0))+parametros_manuales!$E$21*('Plan mensual'!H3+IF(parametros_manuales!$H$21="Todos",'Plan mensual'!H7,0))+parametros_manuales!$F$21*('Plan mensual'!H4+IF(parametros_manuales!$H$21="Todos",'Plan mensual'!H8,0))+parametros_manuales!$G$21*('Plan mensual'!H5+IF(parametros_manuales!$H$21="Todos",'Plan mensual'!H9,0)))*parametros_manuales!$I$21*parametros_manuales!$J$21 -> 292.53 | G4: =(parametros_manuales!$D$21*('Plan mensual'!I2+IF(parametros_manuales!$H$21="Todos",'Plan mensual'!I6,0))+parametros_manuales!$E$21*('Plan mensual'!I3+IF(parametros_manuales!$H$21="Todos",'Plan mensual'!I7,0))+parametros_manuales!$F$21*('Plan mensual'!I4+IF(parametros_manuales!$H$21="Todos",'Plan mensual'!I8,0))+parametros_manuales!$G$21*('Plan mensual'!I5+IF(parametros_manuales!$H$21="Todos",'Plan mensual'!I9,0)))*parametros_manuales!$I$21*parametros_manuales!$J$21 -> 292.53 | H4: =(parametros_manuales!$D$21*('Plan mensual'!J2+IF(parametros_manuales!$H$21="Todos",'Plan mensual'!J6,0))+parametros_manuales!$E$21*('Plan mensual'!J3+IF(parametros_manuales!$H$21="Todos",'Plan mensual'!J7,0))+parametros_manuales!$F$21*('Plan mensual'!J4+IF(parametros_manuales!$H$21="Todos",'Plan mensual'!J8,0))+parametros_manuales!$G$21*('Plan mensual'!J5+IF(parametros_manuales!$H$21="Todos",'Plan mensual'!J9,0)))*parametros_manuales!$I$21*parametros_manuales!$J$21 -> 313.425 | I4: =(parametros_manuales!$D$21*('Plan mensual'!K2+IF(parametros_manuales!$H$21="Todos",'Plan mensual'!K6,0))+parametros_manuales!$E$21*('Plan mensual'!K3+IF(parametros_manuales!$H$21="Todos",'Plan mensual'!K7,0))+parametros_manuales!$F$21*('Plan mensual'!K4+IF(parametros_manuales!$H$21="Todos",'Plan mensual'!K8,0))+parametros_manuales!$G$21*('Plan mensual'!K5+IF(parametros_manuales!$H$21="Todos",'Plan mensual'!K9,0)))*parametros_manuales!$I$21*parametros_manuales!$J$21 -> 313.425 | ... M4: =(parametros_manuales!$D$21*('Plan mensual'!O2+IF(parametros_manuales!$H$21="Todos",'Plan mensual'!O6,0))+parametros_manuales!$E$21*('Plan mensual'!O3+IF(parametros_manuales!$H$21="Todos",'Plan mensual'!O7,0))+parametros_manuales!$F$21*('Plan mensual'!O4+IF(parametros_manuales!$H$21="Todos",'Plan mensual'!O8,0))+parametros_manuales!$G$21*('Plan mensual'!O5+IF(parametros_manuales!$H$21="Todos",'Plan mensual'!O9,0)))*parametros_manuales!$I$21*parametros_manuales!$J$21 -> 501.48 | N4: =SUM(B4:M4) -> 4179 | O4: =MAX(B4:M4) -> 501.48 | P4: =O4/(parametros_manuales!$B$7) -> 3.3432 | Q4: =IF(O4=0,"-",INDEX($B$1:$M$1,MATCH(O4,B4:M4,0))) -> Ene
A5: =parametros_manuales!$B$22 -> Corte de disco y embutido (cúpula y fondo) | B5: =(parametros_manuales!$D$22*('Plan mensual'!D2+IF(parametros_manuales!$H$22="Todos",'Plan mensual'!D6,0))+parametros_manuales!$E$22*('Plan mensual'!D3+IF(parametros_manuales!$H$22="Todos",'Plan mensual'!D7,0))+parametros_manuales!$F$22*('Plan mensual'!D4+IF(parametros_manuales!$H$22="Todos",'Plan mensual'!D8,0))+parametros_manuales!$G$22*('Plan mensual'!D5+IF(parametros_manuales!$H$22="Todos",'Plan mensual'!D9,0)))*parametros_manuales!$I$22*parametros_manuales!$J$22 -> 1531.56 | C5: =(parametros_manuales!$D$22*('Plan mensual'!E2+IF(parametros_manuales!$H$22="Todos",'Plan mensual'!E6,0))+parametros_manuales!$E$22*('Plan mensual'!E3+IF(parametros_manuales!$H$22="Todos",'Plan mensual'!E7,0))+parametros_manuales!$F$22*('Plan mensual'!E4+IF(parametros_manuales!$H$22="Todos",'Plan mensual'!E8,0))+parametros_manuales!$G$22*('Plan mensual'!E5+IF(parametros_manuales!$H$22="Todos",'Plan mensual'!E9,0)))*parametros_manuales!$I$22*parametros_manuales!$J$22 -> 1175.1 | D5: =(parametros_manuales!$D$22*('Plan mensual'!F2+IF(parametros_manuales!$H$22="Todos",'Plan mensual'!F6,0))+parametros_manuales!$E$22*('Plan mensual'!F3+IF(parametros_manuales!$H$22="Todos",'Plan mensual'!F7,0))+parametros_manuales!$F$22*('Plan mensual'!F4+IF(parametros_manuales!$H$22="Todos",'Plan mensual'!F8,0))+parametros_manuales!$G$22*('Plan mensual'!F5+IF(parametros_manuales!$H$22="Todos",'Plan mensual'!F9,0)))*parametros_manuales!$I$22*parametros_manuales!$J$22 -> 1117.95 | E5: =(parametros_manuales!$D$22*('Plan mensual'!G2+IF(parametros_manuales!$H$22="Todos",'Plan mensual'!G6,0))+parametros_manuales!$E$22*('Plan mensual'!G3+IF(parametros_manuales!$H$22="Todos",'Plan mensual'!G7,0))+parametros_manuales!$F$22*('Plan mensual'!G4+IF(parametros_manuales!$H$22="Todos",'Plan mensual'!G8,0))+parametros_manuales!$G$22*('Plan mensual'!G5+IF(parametros_manuales!$H$22="Todos",'Plan mensual'!G9,0)))*parametros_manuales!$I$22*parametros_manuales!$J$22 -> 1076.16 | F5: =(parametros_manuales!$D$22*('Plan mensual'!H2+IF(parametros_manuales!$H$22="Todos",'Plan mensual'!H6,0))+parametros_manuales!$E$22*('Plan mensual'!H3+IF(parametros_manuales!$H$22="Todos",'Plan mensual'!H7,0))+parametros_manuales!$F$22*('Plan mensual'!H4+IF(parametros_manuales!$H$22="Todos",'Plan mensual'!H8,0))+parametros_manuales!$G$22*('Plan mensual'!H5+IF(parametros_manuales!$H$22="Todos",'Plan mensual'!H9,0)))*parametros_manuales!$I$22*parametros_manuales!$J$22 -> 1007.94 | G5: =(parametros_manuales!$D$22*('Plan mensual'!I2+IF(parametros_manuales!$H$22="Todos",'Plan mensual'!I6,0))+parametros_manuales!$E$22*('Plan mensual'!I3+IF(parametros_manuales!$H$22="Todos",'Plan mensual'!I7,0))+parametros_manuales!$F$22*('Plan mensual'!I4+IF(parametros_manuales!$H$22="Todos",'Plan mensual'!I8,0))+parametros_manuales!$G$22*('Plan mensual'!I5+IF(parametros_manuales!$H$22="Todos",'Plan mensual'!I9,0)))*parametros_manuales!$I$22*parametros_manuales!$J$22 -> 981.51 | H5: =(parametros_manuales!$D$22*('Plan mensual'!J2+IF(parametros_manuales!$H$22="Todos",'Plan mensual'!J6,0))+parametros_manuales!$E$22*('Plan mensual'!J3+IF(parametros_manuales!$H$22="Todos",'Plan mensual'!J7,0))+parametros_manuales!$F$22*('Plan mensual'!J4+IF(parametros_manuales!$H$22="Todos",'Plan mensual'!J8,0))+parametros_manuales!$G$22*('Plan mensual'!J5+IF(parametros_manuales!$H$22="Todos",'Plan mensual'!J9,0)))*parametros_manuales!$I$22*parametros_manuales!$J$22 -> 1049.73 | I5: =(parametros_manuales!$D$22*('Plan mensual'!K2+IF(parametros_manuales!$H$22="Todos",'Plan mensual'!K6,0))+parametros_manuales!$E$22*('Plan mensual'!K3+IF(parametros_manuales!$H$22="Todos",'Plan mensual'!K7,0))+parametros_manuales!$F$22*('Plan mensual'!K4+IF(parametros_manuales!$H$22="Todos",'Plan mensual'!K8,0))+parametros_manuales!$G$22*('Plan mensual'!K5+IF(parametros_manuales!$H$22="Todos",'Plan mensual'!K9,0)))*parametros_manuales!$I$22*parametros_manuales!$J$22 -> 1049.73 | ... M5: =(parametros_manuales!$D$22*('Plan mensual'!O2+IF(parametros_manuales!$H$22="Todos",'Plan mensual'!O6,0))+parametros_manuales!$E$22*('Plan mensual'!O3+IF(parametros_manuales!$H$22="Todos",'Plan mensual'!O7,0))+parametros_manuales!$F$22*('Plan mensual'!O4+IF(parametros_manuales!$H$22="Todos",'Plan mensual'!O8,0))+parametros_manuales!$G$22*('Plan mensual'!O5+IF(parametros_manuales!$H$22="Todos",'Plan mensual'!O9,0)))*parametros_manuales!$I$22*parametros_manuales!$J$22 -> 1584.42 | N5: =SUM(B5:M5) -> 13644 | O5: =MAX(B5:M5) -> 1584.42 | P5: =O5/(parametros_manuales!$B$7) -> 10.5628 | Q5: =IF(O5=0,"-",INDEX($B$1:$M$1,MATCH(O5,B5:M5,0))) -> Dic
A6: =parametros_manuales!$B$23 -> Preparación de cuello | B6: =(parametros_manuales!$D$23*('Plan mensual'!D2+IF(parametros_manuales!$H$23="Todos",'Plan mensual'!D6,0))+parametros_manuales!$E$23*('Plan mensual'!D3+IF(parametros_manuales!$H$23="Todos",'Plan mensual'!D7,0))+parametros_manuales!$F$23*('Plan mensual'!D4+IF(parametros_manuales!$H$23="Todos",'Plan mensual'!D8,0))+parametros_manuales!$G$23*('Plan mensual'!D5+IF(parametros_manuales!$H$23="Todos",'Plan mensual'!D9,0)))*parametros_manuales!$I$23*parametros_manuales!$J$23 -> 765.78 | C6: =(parametros_manuales!$D$23*('Plan mensual'!E2+IF(parametros_manuales!$H$23="Todos",'Plan mensual'!E6,0))+parametros_manuales!$E$23*('Plan mensual'!E3+IF(parametros_manuales!$H$23="Todos",'Plan mensual'!E7,0))+parametros_manuales!$F$23*('Plan mensual'!E4+IF(parametros_manuales!$H$23="Todos",'Plan mensual'!E8,0))+parametros_manuales!$G$23*('Plan mensual'!E5+IF(parametros_manuales!$H$23="Todos",'Plan mensual'!E9,0)))*parametros_manuales!$I$23*parametros_manuales!$J$23 -> 587.55 | D6: =(parametros_manuales!$D$23*('Plan mensual'!F2+IF(parametros_manuales!$H$23="Todos",'Plan mensual'!F6,0))+parametros_manuales!$E$23*('Plan mensual'!F3+IF(parametros_manuales!$H$23="Todos",'Plan mensual'!F7,0))+parametros_manuales!$F$23*('Plan mensual'!F4+IF(parametros_manuales!$H$23="Todos",'Plan mensual'!F8,0))+parametros_manuales!$G$23*('Plan mensual'!F5+IF(parametros_manuales!$H$23="Todos",'Plan mensual'!F9,0)))*parametros_manuales!$I$23*parametros_manuales!$J$23 -> 558.975 | E6: =(parametros_manuales!$D$23*('Plan mensual'!G2+IF(parametros_manuales!$H$23="Todos",'Plan mensual'!G6,0))+parametros_manuales!$E$23*('Plan mensual'!G3+IF(parametros_manuales!$H$23="Todos",'Plan mensual'!G7,0))+parametros_manuales!$F$23*('Plan mensual'!G4+IF(parametros_manuales!$H$23="Todos",'Plan mensual'!G8,0))+parametros_manuales!$G$23*('Plan mensual'!G5+IF(parametros_manuales!$H$23="Todos",'Plan mensual'!G9,0)))*parametros_manuales!$I$23*parametros_manuales!$J$23 -> 538.08 | F6: =(parametros_manuales!$D$23*('Plan mensual'!H2+IF(parametros_manuales!$H$23="Todos",'Plan mensual'!H6,0))+parametros_manuales!$E$23*('Plan mensual'!H3+IF(parametros_manuales!$H$23="Todos",'Plan mensual'!H7,0))+parametros_manuales!$F$23*('Plan mensual'!H4+IF(parametros_manuales!$H$23="Todos",'Plan mensual'!H8,0))+parametros_manuales!$G$23*('Plan mensual'!H5+IF(parametros_manuales!$H$23="Todos",'Plan mensual'!H9,0)))*parametros_manuales!$I$23*parametros_manuales!$J$23 -> 503.97 | G6: =(parametros_manuales!$D$23*('Plan mensual'!I2+IF(parametros_manuales!$H$23="Todos",'Plan mensual'!I6,0))+parametros_manuales!$E$23*('Plan mensual'!I3+IF(parametros_manuales!$H$23="Todos",'Plan mensual'!I7,0))+parametros_manuales!$F$23*('Plan mensual'!I4+IF(parametros_manuales!$H$23="Todos",'Plan mensual'!I8,0))+parametros_manuales!$G$23*('Plan mensual'!I5+IF(parametros_manuales!$H$23="Todos",'Plan mensual'!I9,0)))*parametros_manuales!$I$23*parametros_manuales!$J$23 -> 490.755 | H6: =(parametros_manuales!$D$23*('Plan mensual'!J2+IF(parametros_manuales!$H$23="Todos",'Plan mensual'!J6,0))+parametros_manuales!$E$23*('Plan mensual'!J3+IF(parametros_manuales!$H$23="Todos",'Plan mensual'!J7,0))+parametros_manuales!$F$23*('Plan mensual'!J4+IF(parametros_manuales!$H$23="Todos",'Plan mensual'!J8,0))+parametros_manuales!$G$23*('Plan mensual'!J5+IF(parametros_manuales!$H$23="Todos",'Plan mensual'!J9,0)))*parametros_manuales!$I$23*parametros_manuales!$J$23 -> 524.865 | I6: =(parametros_manuales!$D$23*('Plan mensual'!K2+IF(parametros_manuales!$H$23="Todos",'Plan mensual'!K6,0))+parametros_manuales!$E$23*('Plan mensual'!K3+IF(parametros_manuales!$H$23="Todos",'Plan mensual'!K7,0))+parametros_manuales!$F$23*('Plan mensual'!K4+IF(parametros_manuales!$H$23="Todos",'Plan mensual'!K8,0))+parametros_manuales!$G$23*('Plan mensual'!K5+IF(parametros_manuales!$H$23="Todos",'Plan mensual'!K9,0)))*parametros_manuales!$I$23*parametros_manuales!$J$23 -> 524.865 | ... M6: =(parametros_manuales!$D$23*('Plan mensual'!O2+IF(parametros_manuales!$H$23="Todos",'Plan mensual'!O6,0))+parametros_manuales!$E$23*('Plan mensual'!O3+IF(parametros_manuales!$H$23="Todos",'Plan mensual'!O7,0))+parametros_manuales!$F$23*('Plan mensual'!O4+IF(parametros_manuales!$H$23="Todos",'Plan mensual'!O8,0))+parametros_manuales!$G$23*('Plan mensual'!O5+IF(parametros_manuales!$H$23="Todos",'Plan mensual'!O9,0)))*parametros_manuales!$I$23*parametros_manuales!$J$23 -> 792.21 | N6: =SUM(B6:M6) -> 6822 | O6: =MAX(B6:M6) -> 792.21 | P6: =O6/(parametros_manuales!$B$7) -> 5.2814 | Q6: =IF(O6=0,"-",INDEX($B$1:$M$1,MATCH(O6,B6:M6,0))) -> Dic
A7: =parametros_manuales!$B$24 -> Numerado de cúpula | B7: =(parametros_manuales!$D$24*('Plan mensual'!D2+IF(parametros_manuales!$H$24="Todos",'Plan mensual'!D6,0))+parametros_manuales!$E$24*('Plan mensual'!D3+IF(parametros_manuales!$H$24="Todos",'Plan mensual'!D7,0))+parametros_manuales!$F$24*('Plan mensual'!D4+IF(parametros_manuales!$H$24="Todos",'Plan mensual'!D8,0))+parametros_manuales!$G$24*('Plan mensual'!D5+IF(parametros_manuales!$H$24="Todos",'Plan mensual'!D9,0)))*parametros_manuales!$I$24*parametros_manuales!$J$24 -> 765.78 | C7: =(parametros_manuales!$D$24*('Plan mensual'!E2+IF(parametros_manuales!$H$24="Todos",'Plan mensual'!E6,0))+parametros_manuales!$E$24*('Plan mensual'!E3+IF(parametros_manuales!$H$24="Todos",'Plan mensual'!E7,0))+parametros_manuales!$F$24*('Plan mensual'!E4+IF(parametros_manuales!$H$24="Todos",'Plan mensual'!E8,0))+parametros_manuales!$G$24*('Plan mensual'!E5+IF(parametros_manuales!$H$24="Todos",'Plan mensual'!E9,0)))*parametros_manuales!$I$24*parametros_manuales!$J$24 -> 587.55 | D7: =(parametros_manuales!$D$24*('Plan mensual'!F2+IF(parametros_manuales!$H$24="Todos",'Plan mensual'!F6,0))+parametros_manuales!$E$24*('Plan mensual'!F3+IF(parametros_manuales!$H$24="Todos",'Plan mensual'!F7,0))+parametros_manuales!$F$24*('Plan mensual'!F4+IF(parametros_manuales!$H$24="Todos",'Plan mensual'!F8,0))+parametros_manuales!$G$24*('Plan mensual'!F5+IF(parametros_manuales!$H$24="Todos",'Plan mensual'!F9,0)))*parametros_manuales!$I$24*parametros_manuales!$J$24 -> 558.975 | E7: =(parametros_manuales!$D$24*('Plan mensual'!G2+IF(parametros_manuales!$H$24="Todos",'Plan mensual'!G6,0))+parametros_manuales!$E$24*('Plan mensual'!G3+IF(parametros_manuales!$H$24="Todos",'Plan mensual'!G7,0))+parametros_manuales!$F$24*('Plan mensual'!G4+IF(parametros_manuales!$H$24="Todos",'Plan mensual'!G8,0))+parametros_manuales!$G$24*('Plan mensual'!G5+IF(parametros_manuales!$H$24="Todos",'Plan mensual'!G9,0)))*parametros_manuales!$I$24*parametros_manuales!$J$24 -> 538.08 | F7: =(parametros_manuales!$D$24*('Plan mensual'!H2+IF(parametros_manuales!$H$24="Todos",'Plan mensual'!H6,0))+parametros_manuales!$E$24*('Plan mensual'!H3+IF(parametros_manuales!$H$24="Todos",'Plan mensual'!H7,0))+parametros_manuales!$F$24*('Plan mensual'!H4+IF(parametros_manuales!$H$24="Todos",'Plan mensual'!H8,0))+parametros_manuales!$G$24*('Plan mensual'!H5+IF(parametros_manuales!$H$24="Todos",'Plan mensual'!H9,0)))*parametros_manuales!$I$24*parametros_manuales!$J$24 -> 503.97 | G7: =(parametros_manuales!$D$24*('Plan mensual'!I2+IF(parametros_manuales!$H$24="Todos",'Plan mensual'!I6,0))+parametros_manuales!$E$24*('Plan mensual'!I3+IF(parametros_manuales!$H$24="Todos",'Plan mensual'!I7,0))+parametros_manuales!$F$24*('Plan mensual'!I4+IF(parametros_manuales!$H$24="Todos",'Plan mensual'!I8,0))+parametros_manuales!$G$24*('Plan mensual'!I5+IF(parametros_manuales!$H$24="Todos",'Plan mensual'!I9,0)))*parametros_manuales!$I$24*parametros_manuales!$J$24 -> 490.755 | H7: =(parametros_manuales!$D$24*('Plan mensual'!J2+IF(parametros_manuales!$H$24="Todos",'Plan mensual'!J6,0))+parametros_manuales!$E$24*('Plan mensual'!J3+IF(parametros_manuales!$H$24="Todos",'Plan mensual'!J7,0))+parametros_manuales!$F$24*('Plan mensual'!J4+IF(parametros_manuales!$H$24="Todos",'Plan mensual'!J8,0))+parametros_manuales!$G$24*('Plan mensual'!J5+IF(parametros_manuales!$H$24="Todos",'Plan mensual'!J9,0)))*parametros_manuales!$I$24*parametros_manuales!$J$24 -> 524.865 | I7: =(parametros_manuales!$D$24*('Plan mensual'!K2+IF(parametros_manuales!$H$24="Todos",'Plan mensual'!K6,0))+parametros_manuales!$E$24*('Plan mensual'!K3+IF(parametros_manuales!$H$24="Todos",'Plan mensual'!K7,0))+parametros_manuales!$F$24*('Plan mensual'!K4+IF(parametros_manuales!$H$24="Todos",'Plan mensual'!K8,0))+parametros_manuales!$G$24*('Plan mensual'!K5+IF(parametros_manuales!$H$24="Todos",'Plan mensual'!K9,0)))*parametros_manuales!$I$24*parametros_manuales!$J$24 -> 524.865 | ... M7: =(parametros_manuales!$D$24*('Plan mensual'!O2+IF(parametros_manuales!$H$24="Todos",'Plan mensual'!O6,0))+parametros_manuales!$E$24*('Plan mensual'!O3+IF(parametros_manuales!$H$24="Todos",'Plan mensual'!O7,0))+parametros_manuales!$F$24*('Plan mensual'!O4+IF(parametros_manuales!$H$24="Todos",'Plan mensual'!O8,0))+parametros_manuales!$G$24*('Plan mensual'!O5+IF(parametros_manuales!$H$24="Todos",'Plan mensual'!O9,0)))*parametros_manuales!$I$24*parametros_manuales!$J$24 -> 792.21 | N7: =SUM(B7:M7) -> 6822 | O7: =MAX(B7:M7) -> 792.21 | P7: =O7/(parametros_manuales!$B$7) -> 5.2814 | Q7: =IF(O7=0,"-",INDEX($B$1:$M$1,MATCH(O7,B7:M7,0))) -> Dic
