Workbook
Name Umbral_aprov: parametros_carros!$B$8

Sheet datos_base
A1: Carros terminados | B1: 2026 | C1: 2027 | D1: 2028 | E1: 2029 | F1: 2030 | G1: 2031 | H1: 2032 | I1: 2033 | J1: 2034 | K1: 2035
A2: Carro ABC 25 kg | B2: 34 | C2: 58 | D2: 76 | E2: 100 | F2: 156 | G2: 212 | H2: 273 | I2: 338 | J2: 393 | K2: 453
A3: Carro ABC 50 kg | B3: 75 | C3: 128 | D3: 166 | E3: 221 | F3: 343 | G3: 466 | H3: 599 | I3: 743 | J3: 866 | K3: 997
A4: Carro ABC 70 kg | B4: 16 | C4: 29 | D4: 36 | E4: 48 | F4: 74 | G4: 101 | H4: 131 | I4: 163 | J4: 189 | K4: 218
A5: Carro ABC 100 kg | B5: 11 | C5: 18 | D5: 24 | E5: 33 | F5: 50 | G5: 67 | H5: 87 | I5: 108 | J5: 126 | K5: 145
A6: Total terminados | B6: =SUM(B2:B5) -> 136 | C6: =SUM(C2:C5) -> 233 | D6: =SUM(D2:D5) -> 302 | E6: =SUM(E2:E5) -> 402 | F6: =SUM(F2:F5) -> 623 | G6: =SUM(G2:G5) -> 846 | H6: =SUM(H2:H5) -> 1090 | I6: =SUM(I2:I5) -> 1352 | ... K6: =SUM(K2:K5) -> 1813
A8: Cilindros vendidos vacíos | B8: 2026 | C8: 2027 | D8: 2028 | E8: 2029 | F8: 2030 | G8: 2031 | H8: 2032 | I8: 2033 | J8: 2034 | K8: 2035
A9: Cilindros ABC 25 kg | B9: 0 | C9: 0 | D9: 14 | E9: 50 | F9: 93 | G9: 135 | H9: 191 | I9: 247 | J9: 277 | K9: 322
A10: Cilindros ABC 50 kg | B10: 0 | C10: 0 | D10: 32 | E10: 111 | F10: 205 | G10: 298 | H10: 421 | I10: 544 | J10: 610 | K10: 708
A11: Cilindros ABC 70 kg | B11: 0 | C11: 0 | D11: 7 | E11: 24 | F11: 45 | G11: 65 | H11: 92 | I11: 119 | J11: 133 | K11: 155
A12: Cilindros ABC 100 kg | B12: 0 | C12: 0 | D12: 5 | E12: 16 | F12: 30 | G12: 43 | H12: 60 | I12: 78 | J12: 88 | K12: 102
A13: Total cilindros | B13: =SUM(B9:B12) -> 0 | C13: =SUM(C9:C12) -> 0 | D13: =SUM(D9:D12) -> 58 | E13: =SUM(E9:E12) -> 201 | F13: =SUM(F9:F12) -> 373 | G13: =SUM(G9:G12) -> 541 | H13: =SUM(H9:H12) -> 764 | I13: =SUM(I9:I12) -> 988 | ... K13: =SUM(K9:K12) -> 1287
A15: Total recipientes a fabricar | B15: =B6+B13 -> 136 | C15: =C6+C13 -> 233 | D15: =D6+D13 -> 360 | E15: =E6+E13 -> 603 | F15: =F6+F13 -> 996 | G15: =G6+G13 -> 1387 | H15: =H6+H13 -> 1854 | I15: =I6+I13 -> 2340 | ... K15: =K6+K13 -> 3100
A17: Total por modelo (terminados + cilindros) | B17: 2026 | C17: 2027 | D17: 2028 | E17: 2029 | F17: 2030 | G17: 2031 | H17: 2032 | I17: 2033 | J17: 2034 | K17: 2035
A18: Recipientes de 25 kg | B18: =B2+B9 -> 34 | C18: =C2+C9 -> 58 | D18: =D2+D9 -> 90 | E18: =E2+E9 -> 150 | F18: =F2+F9 -> 249 | G18: =G2+G9 -> 347 | H18: =H2+H9 -> 464 | I18: =I2+I9 -> 585 | ... K18: =K2+K9 -> 775
A19: Recipientes de 50 kg | B19: =B3+B10 -> 75 | C19: =C3+C10 -> 128 | D19: =D3+D10 -> 198 | E19: =E3+E10 -> 332 | F19: =F3+F10 -> 548 | G19: =G3+G10 -> 764 | H19: =H3+H10 -> 1020 | I19: =I3+I10 -> 1287 | ... K19: =K3+K10 -> 1705
A20: Recipientes de 70 kg | B20: =B4+B11 -> 16 | C20: =C4+C11 -> 29 | D20: =D4+D11 -> 43 | E20: =E4+E11 -> 72 | F20: =F4+F11 -> 119 | G20: =G4+G11 -> 166 | H20: =H4+H11 -> 223 | I20: =I4+I11 -> 282 | ... K20: =K4+K11 -> 373
A21: Recipientes de 100 kg | B21: =B5+B12 -> 11 | C21: =C5+C12 -> 18 | D21: =D5+D12 -> 29 | E21: =E5+E12 -> 49 | F21: =F5+F12 -> 80 | G21: =G5+G12 -> 110 | H21: =H5+H12 -> 147 | I21: =I5+I12 -> 186 | ... K21: =K5+K12 -> 247
A22: Total | B22: =SUM(B18:B21) -> 136 | C22: =SUM(C18:C21) -> 233 | D22: =SUM(D18:D21) -> 360 | E22: =SUM(E18:E21) -> 603 | F22: =SUM(F18:F21) -> 996 | G22: =SUM(G18:G21) -> 1387 | H22: =SUM(H18:H21) -> 1854 | I22: =SUM(I18:I21) -> 2340 | ... K22: =SUM(K18:K21) -> 3100
A24: Fuente: Dimensionamiento-Tecnico-FLAMA.xlsx, hoja DATOS-BASE: terminados filas 7 a 10 ('ABC 25/50/70/100 kg s/ruedas') y cilindros filas 19 a 22. Las recargas de carros (fila 38) no pasan por la línea de fabricación y no se incluyen.
A26: Datos de cada modelo (Word, Tabla 0) | B26: Ø (mm) | C26: Chapa (mm) | D26: Altura cuerpo (mm) | E26: Cuerpo vacío (kg) | F26: Lleno de agua (kg) | G26: Volumen interior (l) | H26: Carro vacío c/ruedas (kg) | I26: Carro terminado (kg) | J26: Manga mínima (m) | K26: Casquete
A27: Carro 25 kg | B27: 276.5 | C27: 3.2 | D27: 490 | E27: 10.6 | F27: 43 | G27: 35 | H27: 25 | I27: 53 | J27: 5 | K27: 10" (MP-15)
A28: Carro 50 kg | B28: 320 | C28: 3.2 | D28: 640 | E28: 16 | F28: 68 | G28: 60 | H28: 36 | I28: 90 | J28: 5 | K28: 12" (MP-16)
A29: Carro 70 kg | B29: 390 | C29: 4.75 | D29: 680 | E29: 30.7 | F29: 127 | G29: 93 | H29: 61 | I29: 136 | J29: 5 | K29: 15" (MP-17)
A30: Carro 100 kg | B30: 390 | C30: 4.75 | D30: 900 | E30: 40.7 | F30: 157 | G30: 118 | H30: 71 | I30: 179 | J30: 12 | K30: 15" (MP-17)
A32: Chapa LAC 1500 × 3000 mm: 3,2 mm (25 y 50 kg) y 4,75 mm (70 y 100 kg). Cupla M30 × 1,5 (25 y 50 kg) y 2½" BSP (70 y 100 kg). Prueba hidráulica a 4 MPa; presión de servicio 14 bar (N₂).

Sheet parametros_carros
A1: Parámetro | B1: Valor | C1: Nota
A2: Días hábiles por mes | B2: 20 | C2: Mismo valor que Manuales y que el Word (20 días por mes)
A3: Horas por día (1 turno) | B3: 8 | C3: Jornada de 8 h
A4: Refrigerio y pausas (min/turno) | B4: 30 | C4: Ajustado para que el turno productivo dé 410 min, como en el Word (ritmo pico = 410 min / 20 carros = 20,5 min por carro)
A5: Horas productivas por turno | B5: =B3-B4/60 -> 7.5 | C5: Horas/día − refrigerio y pausas (= 410 min)
A6: Turnos por día | B6: 1 | C6: Un solo turno (editable; los turnos por puesto se cargan en Resumen Capacidad)
A7: Horas productivas por mes | B7: =B2*B5*B6 -> 150 | C7: Días × horas productivas × turnos
A8: Umbral de aprovechamiento (solo para resaltar) | B8: 0.9 | C8: El Word toma 80 % del turno como límite para una persona. Las celdas que lo superan se pintan de rojo
A10: ESTACIONALIDAD (% de la demanda anual por mes)
A11: Modelo | B11: Ene | C11: Feb | D11: Mar | E11: Abr | F11: May | G11: Jun | H11: Jul | I11: Ago | J11: Sep | K11: Oct | L11: Nov | M11: Dic | N11: Total
A12: 25 kg | B12: 0.085 | C12: 0.075 | D12: 0.09 | E12: 0.09 | F12: 0.09 | G12: 0.08 | H12: 0.09 | I12: 0.09 | J12: 0.085 | K12: 0.075 | L12: 0.07 | M12: 0.08 | N12: =SUM(B12:M12) -> 1 | O12: Perfil 'Industrial s/ruedas (25 – 100 kg)' (FLAMA, DATOS-BASE fila 104), igual para los 4 modelos
A13: 50 kg | B13: 0.085 | C13: 0.075 | D13: 0.09 | E13: 0.09 | F13: 0.09 | G13: 0.08 | H13: 0.09 | I13: 0.09 | J13: 0.085 | K13: 0.075 | L13: 0.07 | M13: 0.08 | N13: =SUM(B13:M13) -> 1
A14: 70 kg | B14: 0.085 | C14: 0.075 | D14: 0.09 | E14: 0.09 | F14: 0.09 | G14: 0.08 | H14: 0.09 | I14: 0.09 | J14: 0.085 | K14: 0.075 | L14: 0.07 | M14: 0.08 | N14: =SUM(B14:M14) -> 1
A15: 100 kg | B15: 0.085 | C15: 0.075 | D15: 0.09 | E15: 0.09 | F15: 0.09 | G15: 0.08 | H15: 0.09 | I15: 0.09 | J15: 0.085 | K15: 0.075 | L15: 0.07 | M15: 0.08 | N15: =SUM(B15:M15) -> 1
A17: CAPACIDAD POR PUESTO (tiempos en minutos por recipiente, del Word)
A18: N° | B18: Puesto | C18: Máquina / equipo principal | D18: t 25 kg (min/u) | E18: t 50 kg (min/u) | F18: t 70 kg (min/u) | G18: t 100 kg (min/u) | H18: Alcance | I18: Tiempo ponderado (min/u) | J18: Disponibilidad | K18: Cap. real (u/h) | L18: Cap. real (u/mes) | M18: Control: min/día con el pico del Word | N18: Word: min/día pico | O18: SUPOSICIONES
A19: 1 | B19: Recepción de materia prima | C19: Autoelevador Heli CPCD50 K2 (compartido con manuales) + balanza de plataforma + medidor de espesores Melisam MR017 | D19: =(93+330+110+90+90)/400 -> 1.7825 | E19: =(93+330+110+90+90)/400 -> 1.7825 | F19: =(93+330+110+90+90)/400 -> 1.7825 | G19: =(93+330+110+90+90)/400 -> 1.7825 | H19: Todos | I19: =IF(H19="Todos",(D19*datos_base!$K$18+E19*datos_base!$K$19+F19*datos_base!$K$20+G19*datos_base!$K$21)/datos_base!$K$22,(D19*datos_base!$K$2+E19*datos_base!$K$3+F19*datos_base!$K$4+G19*datos_base!$K$5)/datos_base!$K$6) -> 1.7825 | J19: =H45 -> 0.95188889 | K19: =IF(I19>0,60/I19*J19,0) -> 32.041141 | L19: =K19*$B$7 -> 4806.1711 | M19: =5*D19+11*E19+3*F19+1*G19+F45 -> 57.3 | N19: 60 | O19: Tabla 4 del Word (min/mes en el pico de 400 carros): chapa 93 + casquetes 330 + polvo 110 + caño y barra 90 + otros insumos 90, repartidos por carro. La tabla suma 1.146 min/mes aunque el Word indica 1.199. Lo hace el operario de almacén
A20: 2 | B20: Corte de chapa (guillotina) | C20: Guillotina hidráulica CENA 8 × 3200, NC E21 (compartida con manuales) + mesa elevadora de tijera 3 t + ventosas | D20: =10.6/9+3.5/9+0.2+0.8 -> 2.5666667 | E20: =8.8/6+5.5/6+0.2+0.8 -> 3.3833333 | F20: =14.5/4+5*2/23+12.1*(2/3)/4+0.2+0.8 -> 7.0764493 | G20: =14.5/4+5*2/23+12.1*(2/3)/4+0.2+0.8 -> 7.0764493 | H20: Todos | I20: =IF(H20="Todos",(D20*datos_base!$K$18+E20*datos_base!$K$19+F20*datos_base!$K$20+G20*datos_base!$K$21)/datos_base!$K$22,(D20*datos_base!$K$2+E20*datos_base!$K$3+F20*datos_base!$K$4+G20*datos_base!$K$5)/datos_base!$K$6) -> 3.9177899 | J20: =H46 -> 0.93777778 | K20: =IF(I20>0,60/I20*J20,0) -> 14.361839 | L20: =K20*$B$7 -> 2154.2758 | M20: =5*D20+11*E20+3*F20+1*G20+F46 -> 106.3558 | N20: 107 | O20: Hoja 25 kg: 10,6 min / 9 cuerpos + tiras de patas 3,5 min / 9. Hoja 50 kg: 8,8 min / 6 + tiras de 40 mm 5,5 min / 6. Hoja mixta 70+100: 14,5 min / 4 + tiras de placas (5 min cada 23 placas, 2 por cuerpo) + tiras de triángulos (12,1 min en 2 de cada 3 hojas mixtas). Todos: pata 0,2 min + piezas de accesorios a largo 0,8 min (4 cortes de 0,2). Las hojas de 4,75 mm las cortan dos personas
A21: 2.1 | B21: Marcado del cuerpo | C21: Marcadora por micropercusión DTMAQ MPE 150130 + mesa con topes + punzón DPS | D21: 1.5 | E21: 1.5 | F21: 1.8 | G21: 1.8 | H21: Todos | I21: =IF(H21="Todos",(D21*datos_base!$K$18+E21*datos_base!$K$19+F21*datos_base!$K$20+G21*datos_base!$K$21)/datos_base!$K$22,(D21*datos_base!$K$2+E21*datos_base!$K$3+F21*datos_base!$K$4+G21*datos_base!$K$5)/datos_base!$K$6) -> 1.56 | J21: =H47 -> 0.98777778 | K21: =IF(I21>0,60/I21*J21,0) -> 37.991453 | L21: =K21*$B$7 -> 5698.7179 | M21: =5*D21+11*E21+3*F21+1*G21+F47 -> 36.7 | N21: 37 | O21: Tabla de secuencia del puesto 2.1: 1,5 min por cuerpo de 25 y 50 kg y 1,8 min en 70 y 100 kg (entre dos). Lo hace el operario de corte
A22: 3 | B22: Cilindrado | C22: Roladora hidráulica CNC de 4 rodillos W12 8 × 1500 (Anhui Runbang), exclusiva de carros | D22: 2.6 | E22: 2.8 | F22: =4.5+12/11.5 -> 5.5434783 | G22: =5+12/11.5 -> 6.0434783 | H22: Todos | I22: =IF(H22="Todos",(D22*datos_base!$K$18+E22*datos_base!$K$19+F22*datos_base!$K$20+G22*datos_base!$K$21)/datos_base!$K$22,(D22*datos_base!$K$2+E22*datos_base!$K$3+F22*datos_base!$K$4+G22*datos_base!$K$5)/datos_base!$K$6) -> 3.3385344 | J22: =H48 -> 0.96 | K22: =IF(I22>0,60/I22*J22,0) -> 17.25308 | L22: =K22*$B$7 -> 2587.962 | M22: =5*D22+11*E22+3*F22+1*G22+F48 -> 84.473913 | N22: 84 | O22: Ciclo por pieza: 2,6 / 2,8 / 4,5 / 5,0 min. En 70 y 100 kg se suma la tanda de tiras de refuerzo (12 min cada 23 placas = 11,5 cuerpos). No se comparte con manuales (rodillos grandes)
A23: 4 | B23: Punteo del cuerpo | C23: Virador de soldadura Serecon ZJ R-410 sobre base fija + MIG/MAG Pampa 300 | D23: 3 | E23: 3.3 | F23: =7.8+35/11.5+1 -> 11.843478 | G23: =8+35/11.5+1 -> 12.043478 | H23: Todos | I23: =IF(H23="Todos",(D23*datos_base!$K$18+E23*datos_base!$K$19+F23*datos_base!$K$20+G23*datos_base!$K$21)/datos_base!$K$22,(D23*datos_base!$K$2+E23*datos_base!$K$3+F23*datos_base!$K$4+G23*datos_base!$K$5)/datos_base!$K$6) -> 4.9496311 | J23: =H49 -> 0.98888889 | K23: =IF(I23>0,60/I23*J23,0) -> 11.987425 | L23: =K23*$B$7 -> 1798.1138 | M23: =5*D23+11*E23+3*F23+1*G23+F49 -> 103.87391 | N23: 104 | O23: 3,0 / 3,3 min; 70 y 100 kg con los dos refuerzos 7,8 / 8,0 min + corte de placas (35 min por tanda de 23 placas = 11,5 cuerpos) + 1 min de ayuda para sacar el cuerpo de la roladora
A24: 5 | B24: Soldadura longitudinal | C24: Soldadora longitudinal automática ZH-1300 (Dragon Welding) + fuente MIG-350IX + chiller SDL-1000 | D24: 3 | E24: 3.3 | F24: 3.9 | G24: 4.6 | H24: Todos | I24: =IF(H24="Todos",(D24*datos_base!$K$18+E24*datos_base!$K$19+F24*datos_base!$K$20+G24*datos_base!$K$21)/datos_base!$K$22,(D24*datos_base!$K$2+E24*datos_base!$K$3+F24*datos_base!$K$4+G24*datos_base!$K$5)/datos_base!$K$6) -> 3.4007742 | J24: =H50 -> 0.98222222 | K24: =IF(I24>0,60/I24*J24,0) -> 17.329387 | L24: =K24*$B$7 -> 2599.4081 | M24: =5*D24+11*E24+3*F24+1*G24+F50 -> 75.6 | N24: 76 | O24: Arco (490-900 mm a 500 mm/min en 3,2 mm y 350 mm/min en 4,75 mm) + 2 min de carga, mordazas, retiro e inspección. El mismo operario hace el punteo
A25: 6 | B25: Soldadura de cupla en la cúpula | C25: Posicionador VEVOR 30 kg sobre mesa Müller + soporte de torcha + MIG/MAG Pampa 300 | D25: 3.2 | E25: 3.2 | F25: 4 | G25: 4 | H25: Todos | I25: =IF(H25="Todos",(D25*datos_base!$K$18+E25*datos_base!$K$19+F25*datos_base!$K$20+G25*datos_base!$K$21)/datos_base!$K$22,(D25*datos_base!$K$2+E25*datos_base!$K$3+F25*datos_base!$K$4+G25*datos_base!$K$5)/datos_base!$K$6) -> 3.36 | J25: =H51 -> 0.98 | K25: =IF(I25>0,60/I25*J25,0) -> 17.5 | L25: =K25*$B$7 -> 2625 | M25: =5*D25+11*E25+3*F25+1*G25+F51 -> 76.2 | N25: 76 | O25: 3,2 min por cúpula con cupla M30 (25 y 50 kg) y 4,0 min con cupla 2½" (70 y 100 kg). El Word lo asigna al operario de punteo y soldadura longitudinal
A26: 7 | B26: Armado y soldadura circunferencial | C26: Virador de 1.000 kg (USA Tools) con soporte fijo de torcha X-Y-Z + MIG/MAG Pampa 300 | D26: 14.6 | E26: 15.2 | F26: 19.4 | G26: 19.4 | H26: Todos | I26: =IF(H26="Todos",(D26*datos_base!$K$18+E26*datos_base!$K$19+F26*datos_base!$K$20+G26*datos_base!$K$21)/datos_base!$K$22,(D26*datos_base!$K$2+E26*datos_base!$K$3+F26*datos_base!$K$4+G26*datos_base!$K$5)/datos_base!$K$6) -> 15.89 | J26: =H52 -> 0.98 | K26: =IF(I26>0,60/I26*J26,0) -> 3.7004405 | L26: =K26*$B$7 -> 555.06608 | M26: =5*D26+11*E26+3*F26+1*G26+F52 -> 326.8 | N26: 327 | O26: Encastre, punteo, soldadura automática (cilindro girando, torcha fija) e inspección de fondo y cúpula: 14,6 / 15,2 / 19,4 min. Puesto más cargado de la línea: operario propio
A27: 8 | B27: Soldadura de accesorios | C27: Virador de 1.000 kg + MIG/MAG Pampa 300 (soldadura manual) | D27: 15.7 | E27: 15.9 | F27: 17.6 | G27: 17.6 | H27: Todos | I27: =IF(H27="Todos",(D27*datos_base!$K$18+E27*datos_base!$K$19+F27*datos_base!$K$20+G27*datos_base!$K$21)/datos_base!$K$22,(D27*datos_base!$K$2+E27*datos_base!$K$3+F27*datos_base!$K$4+G27*datos_base!$K$5)/datos_base!$K$6) -> 16.19 | J27: =H53 -> 0.98 | K27: =IF(I27>0,60/I27*J27,0) -> 3.6318715 | L27: =K27*$B$7 -> 544.78073 | M27: =5*D27+11*E27+3*F27+1*G27+F53 -> 332.8 | N27: 333 | O27: Marcar posiciones, puntear y soldar manija, flejes, pata, triángulos y caño del eje: 15,7 / 15,9 / 17,6 min por carro. Operario propio
A28: 8.1 | B28: Fabricación de accesorios | C28: Sensitiva Bosch GCO 220 + prensa hidráulica 20 t + dobladora de caños 12 t + taladro de banco | D28: 11 | E28: 11 | F28: 11 | G28: 11 | H28: Todos | I28: =IF(H28="Todos",(D28*datos_base!$K$18+E28*datos_base!$K$19+F28*datos_base!$K$20+G28*datos_base!$K$21)/datos_base!$K$22,(D28*datos_base!$K$2+E28*datos_base!$K$3+F28*datos_base!$K$4+G28*datos_base!$K$5)/datos_base!$K$6) -> 11 | J28: =H54 -> 0.96666667 | K28: =IF(I28>0,60/I28*J28,0) -> 5.2727273 | L28: =K28*$B$7 -> 790.90909 | M28: =5*D28+11*E28+3*F28+1*G28+F54 -> 235 | N28: 235 | O28: 11,0 min por juego (manija, caño del eje, eje, 2 triángulos, 2 flejes y pata). El Word lo asigna al operario de cilindrado
A29: 9 | B29: Prueba hidráulica | C29: Máquina de prueba Yukon M-000200 + 2 bandejas de prueba + tanque y bomba | D29: =7.9+4*0.12 -> 8.38 | E29: =8.7+4*0.12 -> 9.18 | F29: =8.7+4*0.12 -> 9.18 | G29: =8.7+4*0.12 -> 9.18 | H29: Todos | I29: =IF(H29="Todos",(D29*datos_base!$K$18+E29*datos_base!$K$19+F29*datos_base!$K$20+G29*datos_base!$K$21)/datos_base!$K$22,(D29*datos_base!$K$2+E29*datos_base!$K$3+F29*datos_base!$K$4+G29*datos_base!$K$5)/datos_base!$K$6) -> 8.98 | J29: =H55 -> 0.97777778 | K29: =IF(I29>0,60/I29*J29,0) -> 6.5330364 | L29: =K29*$B$7 -> 979.95546 | M29: =5*D29+11*E29+3*F29+1*G29+F55 -> 189.6 | N29: 190 | O29: Estanquidad al 100 %: 7,9 min (25 kg) y 8,7 min (resto, con la ayuda para dar vuelta el cilindro y el juego provisorio) + expansión 4 min en la muestra (≈12 % del lote semanal)
A30: 10 | B30: Secado | C30: Secadora eléctrica Melisam MR011 (1 boca) | D30: 8 | E30: 10 | F30: 12 | G30: 14 | H30: Todos | I30: =IF(H30="Todos",(D30*datos_base!$K$18+E30*datos_base!$K$19+F30*datos_base!$K$20+G30*datos_base!$K$21)/datos_base!$K$22,(D30*datos_base!$K$2+E30*datos_base!$K$3+F30*datos_base!$K$4+G30*datos_base!$K$5)/datos_base!$K$6) -> 10.059355 | J30: =H56 -> 1 | K30: =IF(I30>0,60/I30*J30,0) -> 5.9645972 | L30: =K30*$B$7 -> 894.68958 | M30: =5*D30+11*E30+3*F30+1*G30+F56 -> 200 | N30: 200 | O30: Tiempo de máquina por modelo. El operario (el de prueba hidráulica) solo ocupa 2 min por carro: el secado corre solo
A31: 11 | B31: Pulmón de despacho y carga a pintura | C31: Autoelevador Heli CPCD50 + tarimas de carga con topes (2 operarios) | D31: 1.45 | E31: 1.45 | F31: 2.2 | G31: 2.2 | H31: Todos | I31: =IF(H31="Todos",(D31*datos_base!$K$18+E31*datos_base!$K$19+F31*datos_base!$K$20+G31*datos_base!$K$21)/datos_base!$K$22,(D31*datos_base!$K$2+E31*datos_base!$K$3+F31*datos_base!$K$4+G31*datos_base!$K$5)/datos_base!$K$6) -> 1.6 | J31: =H57 -> 0.99111111 | K31: =IF(I31>0,60/I31*J31,0) -> 37.166667 | L31: =K31*$B$7 -> 5575 | M31: =5*D31+11*E31+3*F31+1*G31+F57 -> 36 | N31: 36 | O31: Por cada uno de los 2 operarios (almacén y montaje): 5,8 min por tarima de 4 carros chicos y 4,4 min por tarima de 2 grandes
A32: 12 | B32: Recepción de pintados y cambio de juego | C32: Criques carrito 2 t + zorra de retorno (2 operarios). Pintura en polvo tercerizada | D32: =1.45+3/2 -> 2.95 | E32: =1.45+3/2 -> 2.95 | F32: =2.2+3.3/2 -> 3.85 | G32: =2.2+3.3/2 -> 3.85 | H32: Todos | I32: =IF(H32="Todos",(D32*datos_base!$K$18+E32*datos_base!$K$19+F32*datos_base!$K$20+G32*datos_base!$K$21)/datos_base!$K$22,(D32*datos_base!$K$2+E32*datos_base!$K$3+F32*datos_base!$K$4+G32*datos_base!$K$5)/datos_base!$K$6) -> 3.13 | J32: =H58 -> 0.99111111 | K32: =IF(I32>0,60/I32*J32,0) -> 18.998935 | L32: =K32*$B$7 -> 2849.8403 | M32: =5*D32+11*E32+3*F32+1*G32+F58 -> 66.6 | N32: =(180+153)/5 -> 66.6 | O32: Por operario: descarga igual que la carga (1,45 / 2,2 min) + la mitad del cambio de juego provisorio (3,0 / 3,3 min por carro). La pintura es tercerizada (3 días hábiles ida y vuelta; USD 13,5 / 20,3 / 27,5 / 32 por carro)
A33: 13 B | B33: Carga de polvo y presurización | C33: Cargadora de polvo por vacío Yukon M-000121 + balanza 300 kg + batería de N₂ + llave dinamométrica | D33: 8.3 | E33: 11.3 | F33: 13.8 | G33: 17.3 | H33: Terminados | I33: =IF(H33="Todos",(D33*datos_base!$K$18+E33*datos_base!$K$19+F33*datos_base!$K$20+G33*datos_base!$K$21)/datos_base!$K$22,(D33*datos_base!$K$2+E33*datos_base!$K$3+F33*datos_base!$K$4+G33*datos_base!$K$5)/datos_base!$K$6) -> 11.330888 | J33: =H59 -> 0.89333333 | K33: =IF(I33>0,60/I33*J33,0) -> 4.7304324 | L33: =K33*$B$7 -> 709.56486 | M33: =5*D33+11*E33+3*F33+1*G33+F59 -> 272.5 | N33: 273 | O33: Estación B: balanza, carga de polvo (≈5 s por kg), válvula, presurización a 14 bar y detector de fugas. Operario de carga
A34: 13 A-C / 15 | B34: Montaje, manga, precinto y etiquetado | C34: Puesto manual (estaciones A y C) + mesa de etiquetado | D34: =3.6+2.5 -> 6.1 | E34: =3.6+2.5 -> 6.1 | F34: =4.3+2.5 -> 6.8 | G34: =5.3+2.5 -> 7.8 | H34: Terminados | I34: =IF(H34="Todos",(D34*datos_base!$K$18+E34*datos_base!$K$19+F34*datos_base!$K$20+G34*datos_base!$K$21)/datos_base!$K$22,(D34*datos_base!$K$2+E34*datos_base!$K$3+F34*datos_base!$K$4+G34*datos_base!$K$5)/datos_base!$K$6) -> 6.3201324 | J34: =H60 -> 0.95333333 | K34: =IF(I34>0,60/I34*J34,0) -> 9.0504433 | L34: =K34*$B$7 -> 1357.5665 | M34: =5*D34+11*E34+3*F34+1*G34+F60 -> 146.8 | N34: 147 | O34: Estaciones A y C: 3,6 / 3,6 / 4,3 / 5,3 min + placa de características y traslado al depósito (puesto 15) 2,5 min. Operario de montaje
A35: 14-17 | B35: Calidad: pérdidas, inspección final, liberación y ensayos de lote | C35: Sala de pérdidas 5 × 5 m (21 °C) + recinto de descarga + Yukon M-000200 + balanza | D35: =1+8*3/100+3*0.25+1.5+0.3+4*0.25 -> 4.79 | E35: =1+8*3/100+3*0.25+1.5+0.3+4*0.25 -> 4.79 | F35: =1+8*3/100+3*0.25+1.5+0.3+4*0.25 -> 4.79 | G35: =1+8*3/100+3*0.25+1.5+0.3+4*0.25 -> 4.79 | H35: Terminados | I35: =IF(H35="Todos",(D35*datos_base!$K$18+E35*datos_base!$K$19+F35*datos_base!$K$20+G35*datos_base!$K$21)/datos_base!$K$22,(D35*datos_base!$K$2+E35*datos_base!$K$3+F35*datos_base!$K$4+G35*datos_base!$K$5)/datos_base!$K$6) -> 4.79 | J35: =H61 -> 0.62977778 | K35: =IF(I35>0,60/I35*J35,0) -> 7.8886569 | L35: =K35*$B$7 -> 1183.2985 | M35: =5*D35+11*E35+3*F35+1*G35+F61 -> 262.4 | N35: 262 | O35: Técnico de calidad, por carro: recepción de pintados 1 min + espesor 0,24; pérdidas 3 min × 25 % de muestra; inspección final 1,5; liberación 0,3; medidas 4 min × 25 %
A36: 16 | B36: Depósito de producto terminado y despacho | C36: Autoelevador + tarima de carga (2 operarios) | D36: 1.2 | E36: 1.2 | F36: 2 | G36: 2 | H36: Todos | I36: =IF(H36="Todos",(D36*datos_base!$K$18+E36*datos_base!$K$19+F36*datos_base!$K$20+G36*datos_base!$K$21)/datos_base!$K$22,(D36*datos_base!$K$2+E36*datos_base!$K$3+F36*datos_base!$K$4+G36*datos_base!$K$5)/datos_base!$K$6) -> 1.36 | J36: =H62 -> 0.97777778 | K36: =IF(I36>0,60/I36*J36,0) -> 43.137255 | L36: =K36*$B$7 -> 6470.5882 | M36: =5*D36+11*E36+3*F36+1*G36+F62 -> 37.2 | N36: =186/5 -> 37.2 | O36: Por cada uno de los 2 operarios: 1,2 min por carro chico y 2,0 min por carro grande
A38: Alcance: "Todos" = carros terminados + cilindros vendidos vacíos; "Terminados" = solo los que se cargan como matafuego (puestos 13 a 17, salvo el despacho).
A39: Tiempo ponderado = promedio de los 4 tiempos con la mezcla de modelos de 2035 (datos_base). Cap. real (u/h) = 60 / tiempo ponderado × disponibilidad. Cap. real (u/mes) = cap. real × horas productivas del mes.
A40: Control: carga en min/día con la mezcla del pico del Word (5 de 25 kg, 11 de 50 kg, 3 de 70 kg y 1 de 100 kg = 20 carros/día, más los tiempos fijos). Tiene que dar parecido a la columna del Word.
A41: Ocupación (Demanda por puesto y Resumen Capacidad) = (carga del mes pico + pérdida por cambios y tiempos fijos) / horas productivas del mes: es comparable con el '% del turno' del Word. En Resumen se divide por máquinas × turnos.
A42: Los puestos 11, 12 y 16 los hacen 2 operarios a la vez (almacén y montaje): el tiempo es el de cada uno. La guillotina y el autoelevador se comparten con la línea de manuales: su carga real es la suma de las dos planillas.
A43: DISPONIBILIDAD (cambios de modelo y tiempos fijos por día)
...

Sheet Plan mensual
A1: 2026 | B1: Producto | C1: Tipo | D1: Ene | E1: Feb | F1: Mar | G1: Abr | H1: May | I1: Jun | J1: Jul | K1: Ago | L1: Sep | M1: Oct | N1: Nov | O1: Dic | P1: Total anual
A2: 2026 | B2: Carro ABC 25 kg | C2: Terminado | D2: =datos_base!$B$2*parametros_carros!B$12 -> 2.89 | E2: =datos_base!$B$2*parametros_carros!C$12 -> 2.55 | F2: =datos_base!$B$2*parametros_carros!D$12 -> 3.06 | G2: =datos_base!$B$2*parametros_carros!E$12 -> 3.06 | H2: =datos_base!$B$2*parametros_carros!F$12 -> 3.06 | I2: =datos_base!$B$2*parametros_carros!G$12 -> 2.72 | J2: =datos_base!$B$2*parametros_carros!H$12 -> 3.06 | K2: =datos_base!$B$2*parametros_carros!I$12 -> 3.06 | ... O2: =datos_base!$B$2*parametros_carros!M$12 -> 2.72 | P2: =SUM(D2:O2) -> 34
A3: 2026 | B3: Carro ABC 50 kg | C3: Terminado | D3: =datos_base!$B$3*parametros_carros!B$13 -> 6.375 | E3: =datos_base!$B$3*parametros_carros!C$13 -> 5.625 | F3: =datos_base!$B$3*parametros_carros!D$13 -> 6.75 | G3: =datos_base!$B$3*parametros_carros!E$13 -> 6.75 | H3: =datos_base!$B$3*parametros_carros!F$13 -> 6.75 | I3: =datos_base!$B$3*parametros_carros!G$13 -> 6 | J3: =datos_base!$B$3*parametros_carros!H$13 -> 6.75 | K3: =datos_base!$B$3*parametros_carros!I$13 -> 6.75 | ... O3: =datos_base!$B$3*parametros_carros!M$13 -> 6 | P3: =SUM(D3:O3) -> 75
A4: 2026 | B4: Carro ABC 70 kg | C4: Terminado | D4: =datos_base!$B$4*parametros_carros!B$14 -> 1.36 | E4: =datos_base!$B$4*parametros_carros!C$14 -> 1.2 | F4: =datos_base!$B$4*parametros_carros!D$14 -> 1.44 | G4: =datos_base!$B$4*parametros_carros!E$14 -> 1.44 | H4: =datos_base!$B$4*parametros_carros!F$14 -> 1.44 | I4: =datos_base!$B$4*parametros_carros!G$14 -> 1.28 | J4: =datos_base!$B$4*parametros_carros!H$14 -> 1.44 | K4: =datos_base!$B$4*parametros_carros!I$14 -> 1.44 | ... O4: =datos_base!$B$4*parametros_carros!M$14 -> 1.28 | P4: =SUM(D4:O4) -> 16
A5: 2026 | B5: Carro ABC 100 kg | C5: Terminado | D5: =datos_base!$B$5*parametros_carros!B$15 -> 0.935 | E5: =datos_base!$B$5*parametros_carros!C$15 -> 0.825 | F5: =datos_base!$B$5*parametros_carros!D$15 -> 0.99 | G5: =datos_base!$B$5*parametros_carros!E$15 -> 0.99 | H5: =datos_base!$B$5*parametros_carros!F$15 -> 0.99 | I5: =datos_base!$B$5*parametros_carros!G$15 -> 0.88 | J5: =datos_base!$B$5*parametros_carros!H$15 -> 0.99 | K5: =datos_base!$B$5*parametros_carros!I$15 -> 0.99 | ... O5: =datos_base!$B$5*parametros_carros!M$15 -> 0.88 | P5: =SUM(D5:O5) -> 11
A6: 2026 | B6: Cilindros ABC 25 kg | C6: Cilindro | D6: =datos_base!$B$9*parametros_carros!B$12 -> 0 | E6: =datos_base!$B$9*parametros_carros!C$12 -> 0 | F6: =datos_base!$B$9*parametros_carros!D$12 -> 0 | G6: =datos_base!$B$9*parametros_carros!E$12 -> 0 | H6: =datos_base!$B$9*parametros_carros!F$12 -> 0 | I6: =datos_base!$B$9*parametros_carros!G$12 -> 0 | J6: =datos_base!$B$9*parametros_carros!H$12 -> 0 | K6: =datos_base!$B$9*parametros_carros!I$12 -> 0 | ... O6: =datos_base!$B$9*parametros_carros!M$12 -> 0 | P6: =SUM(D6:O6) -> 0
A7: 2026 | B7: Cilindros ABC 50 kg | C7: Cilindro | D7: =datos_base!$B$10*parametros_carros!B$13 -> 0 | E7: =datos_base!$B$10*parametros_carros!C$13 -> 0 | F7: =datos_base!$B$10*parametros_carros!D$13 -> 0 | G7: =datos_base!$B$10*parametros_carros!E$13 -> 0 | H7: =datos_base!$B$10*parametros_carros!F$13 -> 0 | I7: =datos_base!$B$10*parametros_carros!G$13 -> 0 | J7: =datos_base!$B$10*parametros_carros!H$13 -> 0 | K7: =datos_base!$B$10*parametros_carros!I$13 -> 0 | ... O7: =datos_base!$B$10*parametros_carros!M$13 -> 0 | P7: =SUM(D7:O7) -> 0
A8: 2026 | B8: Cilindros ABC 70 kg | C8: Cilindro | D8: =datos_base!$B$11*parametros_carros!B$14 -> 0 | E8: =datos_base!$B$11*parametros_carros!C$14 -> 0 | F8: =datos_base!$B$11*parametros_carros!D$14 -> 0 | G8: =datos_base!$B$11*parametros_carros!E$14 -> 0 | H8: =datos_base!$B$11*parametros_carros!F$14 -> 0 | I8: =datos_base!$B$11*parametros_carros!G$14 -> 0 | J8: =datos_base!$B$11*parametros_carros!H$14 -> 0 | K8: =datos_base!$B$11*parametros_carros!I$14 -> 0 | ... O8: =datos_base!$B$11*parametros_carros!M$14 -> 0 | P8: =SUM(D8:O8) -> 0
A9: 2026 | B9: Cilindros ABC 100 kg | C9: Cilindro | D9: =datos_base!$B$12*parametros_carros!B$15 -> 0 | E9: =datos_base!$B$12*parametros_carros!C$15 -> 0 | F9: =datos_base!$B$12*parametros_carros!D$15 -> 0 | G9: =datos_base!$B$12*parametros_carros!E$15 -> 0 | H9: =datos_base!$B$12*parametros_carros!F$15 -> 0 | I9: =datos_base!$B$12*parametros_carros!G$15 -> 0 | J9: =datos_base!$B$12*parametros_carros!H$15 -> 0 | K9: =datos_base!$B$12*parametros_carros!I$15 -> 0 | ... O9: =datos_base!$B$12*parametros_carros!M$15 -> 0 | P9: =SUM(D9:O9) -> 0
B10: Total recipientes | D10: =SUM(D2:D9) -> 11.56 | E10: =SUM(E2:E9) -> 10.2 | F10: =SUM(F2:F9) -> 12.24 | G10: =SUM(G2:G9) -> 12.24 | H10: =SUM(H2:H9) -> 12.24 | I10: =SUM(I2:I9) -> 10.88 | J10: =SUM(J2:J9) -> 12.24 | K10: =SUM(K2:K9) -> 12.24 | ... P10: =SUM(P2:P9) -> 136
A12: 2027 | B12: Producto | C12: Tipo | D12: Ene | E12: Feb | F12: Mar | G12: Abr | H12: May | I12: Jun | J12: Jul | K12: Ago | L12: Sep | M12: Oct | N12: Nov | O12: Dic | P12: Total anual
A13: 2027 | B13: Carro ABC 25 kg | C13: Terminado | D13: =datos_base!$C$2*parametros_carros!B$12 -> 4.93 | E13: =datos_base!$C$2*parametros_carros!C$12 -> 4.35 | F13: =datos_base!$C$2*parametros_carros!D$12 -> 5.22 | G13: =datos_base!$C$2*parametros_carros!E$12 -> 5.22 | H13: =datos_base!$C$2*parametros_carros!F$12 -> 5.22 | I13: =datos_base!$C$2*parametros_carros!G$12 -> 4.64 | J13: =datos_base!$C$2*parametros_carros!H$12 -> 5.22 | K13: =datos_base!$C$2*parametros_carros!I$12 -> 5.22 | ... O13: =datos_base!$C$2*parametros_carros!M$12 -> 4.64 | P13: =SUM(D13:O13) -> 58
A14: 2027 | B14: Carro ABC 50 kg | C14: Terminado | D14: =datos_base!$C$3*parametros_carros!B$13 -> 10.88 | E14: =datos_base!$C$3*parametros_carros!C$13 -> 9.6 | F14: =datos_base!$C$3*parametros_carros!D$13 -> 11.52 | G14: =datos_base!$C$3*parametros_carros!E$13 -> 11.52 | H14: =datos_base!$C$3*parametros_carros!F$13 -> 11.52 | I14: =datos_base!$C$3*parametros_carros!G$13 -> 10.24 | J14: =datos_base!$C$3*parametros_carros!H$13 -> 11.52 | K14: =datos_base!$C$3*parametros_carros!I$13 -> 11.52 | ... O14: =datos_base!$C$3*parametros_carros!M$13 -> 10.24 | P14: =SUM(D14:O14) -> 128
A15: 2027 | B15: Carro ABC 70 kg | C15: Terminado | D15: =datos_base!$C$4*parametros_carros!B$14 -> 2.465 | E15: =datos_base!$C$4*parametros_carros!C$14 -> 2.175 | F15: =datos_base!$C$4*parametros_carros!D$14 -> 2.61 | G15: =datos_base!$C$4*parametros_carros!E$14 -> 2.61 | H15: =datos_base!$C$4*parametros_carros!F$14 -> 2.61 | I15: =datos_base!$C$4*parametros_carros!G$14 -> 2.32 | J15: =datos_base!$C$4*parametros_carros!H$14 -> 2.61 | K15: =datos_base!$C$4*parametros_carros!I$14 -> 2.61 | ... O15: =datos_base!$C$4*parametros_carros!M$14 -> 2.32 | P15: =SUM(D15:O15) -> 29
A16: 2027 | B16: Carro ABC 100 kg | C16: Terminado | D16: =datos_base!$C$5*parametros_carros!B$15 -> 1.53 | E16: =datos_base!$C$5*parametros_carros!C$15 -> 1.35 | F16: =datos_base!$C$5*parametros_carros!D$15 -> 1.62 | G16: =datos_base!$C$5*parametros_carros!E$15 -> 1.62 | H16: =datos_base!$C$5*parametros_carros!F$15 -> 1.62 | I16: =datos_base!$C$5*parametros_carros!G$15 -> 1.44 | J16: =datos_base!$C$5*parametros_carros!H$15 -> 1.62 | K16: =datos_base!$C$5*parametros_carros!I$15 -> 1.62 | ... O16: =datos_base!$C$5*parametros_carros!M$15 -> 1.44 | P16: =SUM(D16:O16) -> 18
A17: 2027 | B17: Cilindros ABC 25 kg | C17: Cilindro | D17: =datos_base!$C$9*parametros_carros!B$12 -> 0 | E17: =datos_base!$C$9*parametros_carros!C$12 -> 0 | F17: =datos_base!$C$9*parametros_carros!D$12 -> 0 | G17: =datos_base!$C$9*parametros_carros!E$12 -> 0 | H17: =datos_base!$C$9*parametros_carros!F$12 -> 0 | I17: =datos_base!$C$9*parametros_carros!G$12 -> 0 | J17: =datos_base!$C$9*parametros_carros!H$12 -> 0 | K17: =datos_base!$C$9*parametros_carros!I$12 -> 0 | ... O17: =datos_base!$C$9*parametros_carros!M$12 -> 0 | P17: =SUM(D17:O17) -> 0
A18: 2027 | B18: Cilindros ABC 50 kg | C18: Cilindro | D18: =datos_base!$C$10*parametros_carros!B$13 -> 0 | E18: =datos_base!$C$10*parametros_carros!C$13 -> 0 | F18: =datos_base!$C$10*parametros_carros!D$13 -> 0 | G18: =datos_base!$C$10*parametros_carros!E$13 -> 0 | H18: =datos_base!$C$10*parametros_carros!F$13 -> 0 | I18: =datos_base!$C$10*parametros_carros!G$13 -> 0 | J18: =datos_base!$C$10*parametros_carros!H$13 -> 0 | K18: =datos_base!$C$10*parametros_carros!I$13 -> 0 | ... O18: =datos_base!$C$10*parametros_carros!M$13 -> 0 | P18: =SUM(D18:O18) -> 0
A19: 2027 | B19: Cilindros ABC 70 kg | C19: Cilindro | D19: =datos_base!$C$11*parametros_carros!B$14 -> 0 | E19: =datos_base!$C$11*parametros_carros!C$14 -> 0 | F19: =datos_base!$C$11*parametros_carros!D$14 -> 0 | G19: =datos_base!$C$11*parametros_carros!E$14 -> 0 | H19: =datos_base!$C$11*parametros_carros!F$14 -> 0 | I19: =datos_base!$C$11*parametros_carros!G$14 -> 0 | J19: =datos_base!$C$11*parametros_carros!H$14 -> 0 | K19: =datos_base!$C$11*parametros_carros!I$14 -> 0 | ... O19: =datos_base!$C$11*parametros_carros!M$14 -> 0 | P19: =SUM(D19:O19) -> 0
A20: 2027 | B20: Cilindros ABC 100 kg | C20: Cilindro | D20: =datos_base!$C$12*parametros_carros!B$15 -> 0 | E20: =datos_base!$C$12*parametros_carros!C$15 -> 0 | F20: =datos_base!$C$12*parametros_carros!D$15 -> 0 | G20: =datos_base!$C$12*parametros_carros!E$15 -> 0 | H20: =datos_base!$C$12*parametros_carros!F$15 -> 0 | I20: =datos_base!$C$12*parametros_carros!G$15 -> 0 | J20: =datos_base!$C$12*parametros_carros!H$15 -> 0 | K20: =datos_base!$C$12*parametros_carros!I$15 -> 0 | ... O20: =datos_base!$C$12*parametros_carros!M$15 -> 0 | P20: =SUM(D20:O20) -> 0
B21: Total recipientes | D21: =SUM(D13:D20) -> 19.805 | E21: =SUM(E13:E20) -> 17.475 | F21: =SUM(F13:F20) -> 20.97 | G21: =SUM(G13:G20) -> 20.97 | H21: =SUM(H13:H20) -> 20.97 | I21: =SUM(I13:I20) -> 18.64 | J21: =SUM(J13:J20) -> 20.97 | K21: =SUM(K13:K20) -> 20.97 | ... P21: =SUM(P13:P20) -> 233
A23: 2028 | B23: Producto | C23: Tipo | D23: Ene | E23: Feb | F23: Mar | G23: Abr | H23: May | I23: Jun | J23: Jul | K23: Ago | L23: Sep | M23: Oct | N23: Nov | O23: Dic | P23: Total anual
A24: 2028 | B24: Carro ABC 25 kg | C24: Terminado | D24: =datos_base!$D$2*parametros_carros!B$12 -> 6.46 | E24: =datos_base!$D$2*parametros_carros!C$12 -> 5.7 | F24: =datos_base!$D$2*parametros_carros!D$12 -> 6.84 | G24: =datos_base!$D$2*parametros_carros!E$12 -> 6.84 | H24: =datos_base!$D$2*parametros_carros!F$12 -> 6.84 | I24: =datos_base!$D$2*parametros_carros!G$12 -> 6.08 | J24: =datos_base!$D$2*parametros_carros!H$12 -> 6.84 | K24: =datos_base!$D$2*parametros_carros!I$12 -> 6.84 | ... O24: =datos_base!$D$2*parametros_carros!M$12 -> 6.08 | P24: =SUM(D24:O24) -> 76
A25: 2028 | B25: Carro ABC 50 kg | C25: Terminado | D25: =datos_base!$D$3*parametros_carros!B$13 -> 14.11 | E25: =datos_base!$D$3*parametros_carros!C$13 -> 12.45 | F25: =datos_base!$D$3*parametros_carros!D$13 -> 14.94 | G25: =datos_base!$D$3*parametros_carros!E$13 -> 14.94 | H25: =datos_base!$D$3*parametros_carros!F$13 -> 14.94 | I25: =datos_base!$D$3*parametros_carros!G$13 -> 13.28 | J25: =datos_base!$D$3*parametros_carros!H$13 -> 14.94 | K25: =datos_base!$D$3*parametros_carros!I$13 -> 14.94 | ... O25: =datos_base!$D$3*parametros_carros!M$13 -> 13.28 | P25: =SUM(D25:O25) -> 166
A26: 2028 | B26: Carro ABC 70 kg | C26: Terminado | D26: =datos_base!$D$4*parametros_carros!B$14 -> 3.06 | E26: =datos_base!$D$4*parametros_carros!C$14 -> 2.7 | F26: =datos_base!$D$4*parametros_carros!D$14 -> 3.24 | G26: =datos_base!$D$4*parametros_carros!E$14 -> 3.24 | H26: =datos_base!$D$4*parametros_carros!F$14 -> 3.24 | I26: =datos_base!$D$4*parametros_carros!G$14 -> 2.88 | J26: =datos_base!$D$4*parametros_carros!H$14 -> 3.24 | K26: =datos_base!$D$4*parametros_carros!I$14 -> 3.24 | ... O26: =datos_base!$D$4*parametros_carros!M$14 -> 2.88 | P26: =SUM(D26:O26) -> 36
A27: 2028 | B27: Carro ABC 100 kg | C27: Terminado | D27: =datos_base!$D$5*parametros_carros!B$15 -> 2.04 | E27: =datos_base!$D$5*parametros_carros!C$15 -> 1.8 | F27: =datos_base!$D$5*parametros_carros!D$15 -> 2.16 | G27: =datos_base!$D$5*parametros_carros!E$15 -> 2.16 | H27: =datos_base!$D$5*parametros_carros!F$15 -> 2.16 | I27: =datos_base!$D$5*parametros_carros!G$15 -> 1.92 | J27: =datos_base!$D$5*parametros_carros!H$15 -> 2.16 | K27: =datos_base!$D$5*parametros_carros!I$15 -> 2.16 | ... O27: =datos_base!$D$5*parametros_carros!M$15 -> 1.92 | P27: =SUM(D27:O27) -> 24
A28: 2028 | B28: Cilindros ABC 25 kg | C28: Cilindro | D28: =datos_base!$D$9*parametros_carros!B$12 -> 1.19 | E28: =datos_base!$D$9*parametros_carros!C$12 -> 1.05 | F28: =datos_base!$D$9*parametros_carros!D$12 -> 1.26 | G28: =datos_base!$D$9*parametros_carros!E$12 -> 1.26 | H28: =datos_base!$D$9*parametros_carros!F$12 -> 1.26 | I28: =datos_base!$D$9*parametros_carros!G$12 -> 1.12 | J28: =datos_base!$D$9*parametros_carros!H$12 -> 1.26 | K28: =datos_base!$D$9*parametros_carros!I$12 -> 1.26 | ... O28: =datos_base!$D$9*parametros_carros!M$12 -> 1.12 | P28: =SUM(D28:O28) -> 14
A29: 2028 | B29: Cilindros ABC 50 kg | C29: Cilindro | D29: =datos_base!$D$10*parametros_carros!B$13 -> 2.72 | E29: =datos_base!$D$10*parametros_carros!C$13 -> 2.4 | F29: =datos_base!$D$10*parametros_carros!D$13 -> 2.88 | G29: =datos_base!$D$10*parametros_carros!E$13 -> 2.88 | H29: =datos_base!$D$10*parametros_carros!F$13 -> 2.88 | I29: =datos_base!$D$10*parametros_carros!G$13 -> 2.56 | J29: =datos_base!$D$10*parametros_carros!H$13 -> 2.88 | K29: =datos_base!$D$10*parametros_carros!I$13 -> 2.88 | ... O29: =datos_base!$D$10*parametros_carros!M$13 -> 2.56 | P29: =SUM(D29:O29) -> 32
A30: 2028 | B30: Cilindros ABC 70 kg | C30: Cilindro | D30: =datos_base!$D$11*parametros_carros!B$14 -> 0.595 | E30: =datos_base!$D$11*parametros_carros!C$14 -> 0.525 | F30: =datos_base!$D$11*parametros_carros!D$14 -> 0.63 | G30: =datos_base!$D$11*parametros_carros!E$14 -> 0.63 | H30: =datos_base!$D$11*parametros_carros!F$14 -> 0.63 | I30: =datos_base!$D$11*parametros_carros!G$14 -> 0.56 | J30: =datos_base!$D$11*parametros_carros!H$14 -> 0.63 | K30: =datos_base!$D$11*parametros_carros!I$14 -> 0.63 | ... O30: =datos_base!$D$11*parametros_carros!M$14 -> 0.56 | P30: =SUM(D30:O30) -> 7
A31: 2028 | B31: Cilindros ABC 100 kg | C31: Cilindro | D31: =datos_base!$D$12*parametros_carros!B$15 -> 0.425 | E31: =datos_base!$D$12*parametros_carros!C$15 -> 0.375 | F31: =datos_base!$D$12*parametros_carros!D$15 -> 0.45 | G31: =datos_base!$D$12*parametros_carros!E$15 -> 0.45 | H31: =datos_base!$D$12*parametros_carros!F$15 -> 0.45 | I31: =datos_base!$D$12*parametros_carros!G$15 -> 0.4 | J31: =datos_base!$D$12*parametros_carros!H$15 -> 0.45 | K31: =datos_base!$D$12*parametros_carros!I$15 -> 0.45 | ... O31: =datos_base!$D$12*parametros_carros!M$15 -> 0.4 | P31: =SUM(D31:O31) -> 5
B32: Total recipientes | D32: =SUM(D24:D31) -> 30.6 | E32: =SUM(E24:E31) -> 27 | F32: =SUM(F24:F31) -> 32.4 | G32: =SUM(G24:G31) -> 32.4 | H32: =SUM(H24:H31) -> 32.4 | I32: =SUM(I24:I31) -> 28.8 | J32: =SUM(J24:J31) -> 32.4 | K32: =SUM(K24:K31) -> 32.4 | ... P32: =SUM(P24:P31) -> 360
A34: 2029 | B34: Producto | C34: Tipo | D34: Ene | E34: Feb | F34: Mar | G34: Abr | H34: May | I34: Jun | J34: Jul | K34: Ago | L34: Sep | M34: Oct | N34: Nov | O34: Dic | P34: Total anual
A35: 2029 | B35: Carro ABC 25 kg | C35: Terminado | D35: =datos_base!$E$2*parametros_carros!B$12 -> 8.5 | E35: =datos_base!$E$2*parametros_carros!C$12 -> 7.5 | F35: =datos_base!$E$2*parametros_carros!D$12 -> 9 | G35: =datos_base!$E$2*parametros_carros!E$12 -> 9 | H35: =datos_base!$E$2*parametros_carros!F$12 -> 9 | I35: =datos_base!$E$2*parametros_carros!G$12 -> 8 | J35: =datos_base!$E$2*parametros_carros!H$12 -> 9 | K35: =datos_base!$E$2*parametros_carros!I$12 -> 9 | ... O35: =datos_base!$E$2*parametros_carros!M$12 -> 8 | P35: =SUM(D35:O35) -> 100
A36: 2029 | B36: Carro ABC 50 kg | C36: Terminado | D36: =datos_base!$E$3*parametros_carros!B$13 -> 18.785 | E36: =datos_base!$E$3*parametros_carros!C$13 -> 16.575 | F36: =datos_base!$E$3*parametros_carros!D$13 -> 19.89 | G36: =datos_base!$E$3*parametros_carros!E$13 -> 19.89 | H36: =datos_base!$E$3*parametros_carros!F$13 -> 19.89 | I36: =datos_base!$E$3*parametros_carros!G$13 -> 17.68 | J36: =datos_base!$E$3*parametros_carros!H$13 -> 19.89 | K36: =datos_base!$E$3*parametros_carros!I$13 -> 19.89 | ... O36: =datos_base!$E$3*parametros_carros!M$13 -> 17.68 | P36: =SUM(D36:O36) -> 221
A37: 2029 | B37: Carro ABC 70 kg | C37: Terminado | D37: =datos_base!$E$4*parametros_carros!B$14 -> 4.08 | E37: =datos_base!$E$4*parametros_carros!C$14 -> 3.6 | F37: =datos_base!$E$4*parametros_carros!D$14 -> 4.32 | G37: =datos_base!$E$4*parametros_carros!E$14 -> 4.32 | H37: =datos_base!$E$4*parametros_carros!F$14 -> 4.32 | I37: =datos_base!$E$4*parametros_carros!G$14 -> 3.84 | J37: =datos_base!$E$4*parametros_carros!H$14 -> 4.32 | K37: =datos_base!$E$4*parametros_carros!I$14 -> 4.32 | ... O37: =datos_base!$E$4*parametros_carros!M$14 -> 3.84 | P37: =SUM(D37:O37) -> 48
A38: 2029 | B38: Carro ABC 100 kg | C38: Terminado | D38: =datos_base!$E$5*parametros_carros!B$15 -> 2.805 | E38: =datos_base!$E$5*parametros_carros!C$15 -> 2.475 | F38: =datos_base!$E$5*parametros_carros!D$15 -> 2.97 | G38: =datos_base!$E$5*parametros_carros!E$15 -> 2.97 | H38: =datos_base!$E$5*parametros_carros!F$15 -> 2.97 | I38: =datos_base!$E$5*parametros_carros!G$15 -> 2.64 | J38: =datos_base!$E$5*parametros_carros!H$15 -> 2.97 | K38: =datos_base!$E$5*parametros_carros!I$15 -> 2.97 | ... O38: =datos_base!$E$5*parametros_carros!M$15 -> 2.64 | P38: =SUM(D38:O38) -> 33
A39: 2029 | B39: Cilindros ABC 25 kg | C39: Cilindro | D39: =datos_base!$E$9*parametros_carros!B$12 -> 4.25 | E39: =datos_base!$E$9*parametros_carros!C$12 -> 3.75 | F39: =datos_base!$E$9*parametros_carros!D$12 -> 4.5 | G39: =datos_base!$E$9*parametros_carros!E$12 -> 4.5 | H39: =datos_base!$E$9*parametros_carros!F$12 -> 4.5 | I39: =datos_base!$E$9*parametros_carros!G$12 -> 4 | J39: =datos_base!$E$9*parametros_carros!H$12 -> 4.5 | K39: =datos_base!$E$9*parametros_carros!I$12 -> 4.5 | ... O39: =datos_base!$E$9*parametros_carros!M$12 -> 4 | P39: =SUM(D39:O39) -> 50
A40: 2029 | B40: Cilindros ABC 50 kg | C40: Cilindro | D40: =datos_base!$E$10*parametros_carros!B$13 -> 9.435 | E40: =datos_base!$E$10*parametros_carros!C$13 -> 8.325 | F40: =datos_base!$E$10*parametros_carros!D$13 -> 9.99 | G40: =datos_base!$E$10*parametros_carros!E$13 -> 9.99 | H40: =datos_base!$E$10*parametros_carros!F$13 -> 9.99 | I40: =datos_base!$E$10*parametros_carros!G$13 -> 8.88 | J40: =datos_base!$E$10*parametros_carros!H$13 -> 9.99 | K40: =datos_base!$E$10*parametros_carros!I$13 -> 9.99 | ... O40: =datos_base!$E$10*parametros_carros!M$13 -> 8.88 | P40: =SUM(D40:O40) -> 111
A41: 2029 | B41: Cilindros ABC 70 kg | C41: Cilindro | D41: =datos_base!$E$11*parametros_carros!B$14 -> 2.04 | E41: =datos_base!$E$11*parametros_carros!C$14 -> 1.8 | F41: =datos_base!$E$11*parametros_carros!D$14 -> 2.16 | G41: =datos_base!$E$11*parametros_carros!E$14 -> 2.16 | H41: =datos_base!$E$11*parametros_carros!F$14 -> 2.16 | I41: =datos_base!$E$11*parametros_carros!G$14 -> 1.92 | J41: =datos_base!$E$11*parametros_carros!H$14 -> 2.16 | K41: =datos_base!$E$11*parametros_carros!I$14 -> 2.16 | ... O41: =datos_base!$E$11*parametros_carros!M$14 -> 1.92 | P41: =SUM(D41:O41) -> 24
A42: 2029 | B42: Cilindros ABC 100 kg | C42: Cilindro | D42: =datos_base!$E$12*parametros_carros!B$15 -> 1.36 | E42: =datos_base!$E$12*parametros_carros!C$15 -> 1.2 | F42: =datos_base!$E$12*parametros_carros!D$15 -> 1.44 | G42: =datos_base!$E$12*parametros_carros!E$15 -> 1.44 | H42: =datos_base!$E$12*parametros_carros!F$15 -> 1.44 | I42: =datos_base!$E$12*parametros_carros!G$15 -> 1.28 | J42: =datos_base!$E$12*parametros_carros!H$15 -> 1.44 | K42: =datos_base!$E$12*parametros_carros!I$15 -> 1.44 | ... O42: =datos_base!$E$12*parametros_carros!M$15 -> 1.28 | P42: =SUM(D42:O42) -> 16
B43: Total recipientes | D43: =SUM(D35:D42) -> 51.255 | E43: =SUM(E35:E42) -> 45.225 | F43: =SUM(F35:F42) -> 54.27 | G43: =SUM(G35:G42) -> 54.27 | H43: =SUM(H35:H42) -> 54.27 | I43: =SUM(I35:I42) -> 48.24 | J43: =SUM(J35:J42) -> 54.27 | K43: =SUM(K35:K42) -> 54.27 | ... P43: =SUM(P35:P42) -> 603
...

Sheet Demanda por puesto
A1: Año 2026 — carga (h/mes) | B1: Ene | C1: Feb | D1: Mar | E1: Abr | F1: May | G1: Jun | H1: Jul | I1: Ago | J1: Sep | K1: Oct | L1: Nov | M1: Dic | N1: Total anual (h) | O1: Mes pico (h/mes) | P1: Ocupación pico (1 puesto, 1 turno, con fijos) | Q1: Mes pico
A2: =parametros_carros!$B$19 -> Recepción de materia prima | B2: =(parametros_carros!$D$19*('Plan mensual'!D2+IF(parametros_carros!$H$19="Todos",'Plan mensual'!D6,0))+parametros_carros!$E$19*('Plan mensual'!D3+IF(parametros_carros!$H$19="Todos",'Plan mensual'!D7,0))+parametros_carros!$F$19*('Plan mensual'!D4+IF(parametros_carros!$H$19="Todos",'Plan mensual'!D8,0))+parametros_carros!$G$19*('Plan mensual'!D5+IF(parametros_carros!$H$19="Todos",'Plan mensual'!D9,0)))/60 -> 0.34342833 | C2: =(parametros_carros!$D$19*('Plan mensual'!E2+IF(parametros_carros!$H$19="Todos",'Plan mensual'!E6,0))+parametros_carros!$E$19*('Plan mensual'!E3+IF(parametros_carros!$H$19="Todos",'Plan mensual'!E7,0))+parametros_carros!$F$19*('Plan mensual'!E4+IF(parametros_carros!$H$19="Todos",'Plan mensual'!E8,0))+parametros_carros!$G$19*('Plan mensual'!E5+IF(parametros_carros!$H$19="Todos",'Plan mensual'!E9,0)))/60 -> 0.303025 | D2: =(parametros_carros!$D$19*('Plan mensual'!F2+IF(parametros_carros!$H$19="Todos",'Plan mensual'!F6,0))+parametros_carros!$E$19*('Plan mensual'!F3+IF(parametros_carros!$H$19="Todos",'Plan mensual'!F7,0))+parametros_carros!$F$19*('Plan mensual'!F4+IF(parametros_carros!$H$19="Todos",'Plan mensual'!F8,0))+parametros_carros!$G$19*('Plan mensual'!F5+IF(parametros_carros!$H$19="Todos",'Plan mensual'!F9,0)))/60 -> 0.36363 | E2: =(parametros_carros!$D$19*('Plan mensual'!G2+IF(parametros_carros!$H$19="Todos",'Plan mensual'!G6,0))+parametros_carros!$E$19*('Plan mensual'!G3+IF(parametros_carros!$H$19="Todos",'Plan mensual'!G7,0))+parametros_carros!$F$19*('Plan mensual'!G4+IF(parametros_carros!$H$19="Todos",'Plan mensual'!G8,0))+parametros_carros!$G$19*('Plan mensual'!G5+IF(parametros_carros!$H$19="Todos",'Plan mensual'!G9,0)))/60 -> 0.36363 | F2: =(parametros_carros!$D$19*('Plan mensual'!H2+IF(parametros_carros!$H$19="Todos",'Plan mensual'!H6,0))+parametros_carros!$E$19*('Plan mensual'!H3+IF(parametros_carros!$H$19="Todos",'Plan mensual'!H7,0))+parametros_carros!$F$19*('Plan mensual'!H4+IF(parametros_carros!$H$19="Todos",'Plan mensual'!H8,0))+parametros_carros!$G$19*('Plan mensual'!H5+IF(parametros_carros!$H$19="Todos",'Plan mensual'!H9,0)))/60 -> 0.36363 | G2: =(parametros_carros!$D$19*('Plan mensual'!I2+IF(parametros_carros!$H$19="Todos",'Plan mensual'!I6,0))+parametros_carros!$E$19*('Plan mensual'!I3+IF(parametros_carros!$H$19="Todos",'Plan mensual'!I7,0))+parametros_carros!$F$19*('Plan mensual'!I4+IF(parametros_carros!$H$19="Todos",'Plan mensual'!I8,0))+parametros_carros!$G$19*('Plan mensual'!I5+IF(parametros_carros!$H$19="Todos",'Plan mensual'!I9,0)))/60 -> 0.32322667 | H2: =(parametros_carros!$D$19*('Plan mensual'!J2+IF(parametros_carros!$H$19="Todos",'Plan mensual'!J6,0))+parametros_carros!$E$19*('Plan mensual'!J3+IF(parametros_carros!$H$19="Todos",'Plan mensual'!J7,0))+parametros_carros!$F$19*('Plan mensual'!J4+IF(parametros_carros!$H$19="Todos",'Plan mensual'!J8,0))+parametros_carros!$G$19*('Plan mensual'!J5+IF(parametros_carros!$H$19="Todos",'Plan mensual'!J9,0)))/60 -> 0.36363 | I2: =(parametros_carros!$D$19*('Plan mensual'!K2+IF(parametros_carros!$H$19="Todos",'Plan mensual'!K6,0))+parametros_carros!$E$19*('Plan mensual'!K3+IF(parametros_carros!$H$19="Todos",'Plan mensual'!K7,0))+parametros_carros!$F$19*('Plan mensual'!K4+IF(parametros_carros!$H$19="Todos",'Plan mensual'!K8,0))+parametros_carros!$G$19*('Plan mensual'!K5+IF(parametros_carros!$H$19="Todos",'Plan mensual'!K9,0)))/60 -> 0.36363 | ... M2: =(parametros_carros!$D$19*('Plan mensual'!O2+IF(parametros_carros!$H$19="Todos",'Plan mensual'!O6,0))+parametros_carros!$E$19*('Plan mensual'!O3+IF(parametros_carros!$H$19="Todos",'Plan mensual'!O7,0))+parametros_carros!$F$19*('Plan mensual'!O4+IF(parametros_carros!$H$19="Todos",'Plan mensual'!O8,0))+parametros_carros!$G$19*('Plan mensual'!O5+IF(parametros_carros!$H$19="Todos",'Plan mensual'!O9,0)))/60 -> 0.32322667 | N2: =SUM(B2:M2) -> 4.0403333 | O2: =MAX(B2:M2) -> 0.36363 | P2: =IF(parametros_carros!$B$7=0,0,(O2+parametros_carros!$G$45)/parametros_carros!$B$7) -> 0.050535311 | Q2: =IF(O2=0,"-",INDEX($B$1:$M$1,MATCH(O2,B2:M2,0))) -> Mar
A3: =parametros_carros!$B$20 -> Corte de chapa (guillotina) | B3: =(parametros_carros!$D$20*('Plan mensual'!D2+IF(parametros_carros!$H$20="Todos",'Plan mensual'!D6,0))+parametros_carros!$E$20*('Plan mensual'!D3+IF(parametros_carros!$H$20="Todos",'Plan mensual'!D7,0))+parametros_carros!$F$20*('Plan mensual'!D4+IF(parametros_carros!$H$20="Todos",'Plan mensual'!D8,0))+parametros_carros!$G$20*('Plan mensual'!D5+IF(parametros_carros!$H$20="Todos",'Plan mensual'!D9,0)))/60 -> 0.75378113 | C3: =(parametros_carros!$D$20*('Plan mensual'!E2+IF(parametros_carros!$H$20="Todos",'Plan mensual'!E6,0))+parametros_carros!$E$20*('Plan mensual'!E3+IF(parametros_carros!$H$20="Todos",'Plan mensual'!E7,0))+parametros_carros!$F$20*('Plan mensual'!E4+IF(parametros_carros!$H$20="Todos",'Plan mensual'!E8,0))+parametros_carros!$G$20*('Plan mensual'!E5+IF(parametros_carros!$H$20="Todos",'Plan mensual'!E9,0)))/60 -> 0.665101 | D3: =(parametros_carros!$D$20*('Plan mensual'!F2+IF(parametros_carros!$H$20="Todos",'Plan mensual'!F6,0))+parametros_carros!$E$20*('Plan mensual'!F3+IF(parametros_carros!$H$20="Todos",'Plan mensual'!F7,0))+parametros_carros!$F$20*('Plan mensual'!F4+IF(parametros_carros!$H$20="Todos",'Plan mensual'!F8,0))+parametros_carros!$G$20*('Plan mensual'!F5+IF(parametros_carros!$H$20="Todos",'Plan mensual'!F9,0)))/60 -> 0.7981212 | E3: =(parametros_carros!$D$20*('Plan mensual'!G2+IF(parametros_carros!$H$20="Todos",'Plan mensual'!G6,0))+parametros_carros!$E$20*('Plan mensual'!G3+IF(parametros_carros!$H$20="Todos",'Plan mensual'!G7,0))+parametros_carros!$F$20*('Plan mensual'!G4+IF(parametros_carros!$H$20="Todos",'Plan mensual'!G8,0))+parametros_carros!$G$20*('Plan mensual'!G5+IF(parametros_carros!$H$20="Todos",'Plan mensual'!G9,0)))/60 -> 0.7981212 | F3: =(parametros_carros!$D$20*('Plan mensual'!H2+IF(parametros_carros!$H$20="Todos",'Plan mensual'!H6,0))+parametros_carros!$E$20*('Plan mensual'!H3+IF(parametros_carros!$H$20="Todos",'Plan mensual'!H7,0))+parametros_carros!$F$20*('Plan mensual'!H4+IF(parametros_carros!$H$20="Todos",'Plan mensual'!H8,0))+parametros_carros!$G$20*('Plan mensual'!H5+IF(parametros_carros!$H$20="Todos",'Plan mensual'!H9,0)))/60 -> 0.7981212 | G3: =(parametros_carros!$D$20*('Plan mensual'!I2+IF(parametros_carros!$H$20="Todos",'Plan mensual'!I6,0))+parametros_carros!$E$20*('Plan mensual'!I3+IF(parametros_carros!$H$20="Todos",'Plan mensual'!I7,0))+parametros_carros!$F$20*('Plan mensual'!I4+IF(parametros_carros!$H$20="Todos",'Plan mensual'!I8,0))+parametros_carros!$G$20*('Plan mensual'!I5+IF(parametros_carros!$H$20="Todos",'Plan mensual'!I9,0)))/60 -> 0.70944106 | H3: =(parametros_carros!$D$20*('Plan mensual'!J2+IF(parametros_carros!$H$20="Todos",'Plan mensual'!J6,0))+parametros_carros!$E$20*('Plan mensual'!J3+IF(parametros_carros!$H$20="Todos",'Plan mensual'!J7,0))+parametros_carros!$F$20*('Plan mensual'!J4+IF(parametros_carros!$H$20="Todos",'Plan mensual'!J8,0))+parametros_carros!$G$20*('Plan mensual'!J5+IF(parametros_carros!$H$20="Todos",'Plan mensual'!J9,0)))/60 -> 0.7981212 | I3: =(parametros_carros!$D$20*('Plan mensual'!K2+IF(parametros_carros!$H$20="Todos",'Plan mensual'!K6,0))+parametros_carros!$E$20*('Plan mensual'!K3+IF(parametros_carros!$H$20="Todos",'Plan mensual'!K7,0))+parametros_carros!$F$20*('Plan mensual'!K4+IF(parametros_carros!$H$20="Todos",'Plan mensual'!K8,0))+parametros_carros!$G$20*('Plan mensual'!K5+IF(parametros_carros!$H$20="Todos",'Plan mensual'!K9,0)))/60 -> 0.7981212 | ... M3: =(parametros_carros!$D$20*('Plan mensual'!O2+IF(parametros_carros!$H$20="Todos",'Plan mensual'!O6,0))+parametros_carros!$E$20*('Plan mensual'!O3+IF(parametros_carros!$H$20="Todos",'Plan mensual'!O7,0))+parametros_carros!$F$20*('Plan mensual'!O4+IF(parametros_carros!$H$20="Todos",'Plan mensual'!O8,0))+parametros_carros!$G$20*('Plan mensual'!O5+IF(parametros_carros!$H$20="Todos",'Plan mensual'!O9,0)))/60 -> 0.70944106 | N3: =SUM(B3:M3) -> 8.8680133 | O3: =MAX(B3:M3) -> 0.7981212 | P3: =IF(parametros_carros!$B$7=0,0,(O3+parametros_carros!$G$46)/parametros_carros!$B$7) -> 0.06754303 | Q3: =IF(O3=0,"-",INDEX($B$1:$M$1,MATCH(O3,B3:M3,0))) -> Mar
A4: =parametros_carros!$B$21 -> Marcado del cuerpo | B4: =(parametros_carros!$D$21*('Plan mensual'!D2+IF(parametros_carros!$H$21="Todos",'Plan mensual'!D6,0))+parametros_carros!$E$21*('Plan mensual'!D3+IF(parametros_carros!$H$21="Todos",'Plan mensual'!D7,0))+parametros_carros!$F$21*('Plan mensual'!D4+IF(parametros_carros!$H$21="Todos",'Plan mensual'!D8,0))+parametros_carros!$G$21*('Plan mensual'!D5+IF(parametros_carros!$H$21="Todos",'Plan mensual'!D9,0)))/60 -> 0.300475 | C4: =(parametros_carros!$D$21*('Plan mensual'!E2+IF(parametros_carros!$H$21="Todos",'Plan mensual'!E6,0))+parametros_carros!$E$21*('Plan mensual'!E3+IF(parametros_carros!$H$21="Todos",'Plan mensual'!E7,0))+parametros_carros!$F$21*('Plan mensual'!E4+IF(parametros_carros!$H$21="Todos",'Plan mensual'!E8,0))+parametros_carros!$G$21*('Plan mensual'!E5+IF(parametros_carros!$H$21="Todos",'Plan mensual'!E9,0)))/60 -> 0.265125 | D4: =(parametros_carros!$D$21*('Plan mensual'!F2+IF(parametros_carros!$H$21="Todos",'Plan mensual'!F6,0))+parametros_carros!$E$21*('Plan mensual'!F3+IF(parametros_carros!$H$21="Todos",'Plan mensual'!F7,0))+parametros_carros!$F$21*('Plan mensual'!F4+IF(parametros_carros!$H$21="Todos",'Plan mensual'!F8,0))+parametros_carros!$G$21*('Plan mensual'!F5+IF(parametros_carros!$H$21="Todos",'Plan mensual'!F9,0)))/60 -> 0.31815 | E4: =(parametros_carros!$D$21*('Plan mensual'!G2+IF(parametros_carros!$H$21="Todos",'Plan mensual'!G6,0))+parametros_carros!$E$21*('Plan mensual'!G3+IF(parametros_carros!$H$21="Todos",'Plan mensual'!G7,0))+parametros_carros!$F$21*('Plan mensual'!G4+IF(parametros_carros!$H$21="Todos",'Plan mensual'!G8,0))+parametros_carros!$G$21*('Plan mensual'!G5+IF(parametros_carros!$H$21="Todos",'Plan mensual'!G9,0)))/60 -> 0.31815 | F4: =(parametros_carros!$D$21*('Plan mensual'!H2+IF(parametros_carros!$H$21="Todos",'Plan mensual'!H6,0))+parametros_carros!$E$21*('Plan mensual'!H3+IF(parametros_carros!$H$21="Todos",'Plan mensual'!H7,0))+parametros_carros!$F$21*('Plan mensual'!H4+IF(parametros_carros!$H$21="Todos",'Plan mensual'!H8,0))+parametros_carros!$G$21*('Plan mensual'!H5+IF(parametros_carros!$H$21="Todos",'Plan mensual'!H9,0)))/60 -> 0.31815 | G4: =(parametros_carros!$D$21*('Plan mensual'!I2+IF(parametros_carros!$H$21="Todos",'Plan mensual'!I6,0))+parametros_carros!$E$21*('Plan mensual'!I3+IF(parametros_carros!$H$21="Todos",'Plan mensual'!I7,0))+parametros_carros!$F$21*('Plan mensual'!I4+IF(parametros_carros!$H$21="Todos",'Plan mensual'!I8,0))+parametros_carros!$G$21*('Plan mensual'!I5+IF(parametros_carros!$H$21="Todos",'Plan mensual'!I9,0)))/60 -> 0.2828 | H4: =(parametros_carros!$D$21*('Plan mensual'!J2+IF(parametros_carros!$H$21="Todos",'Plan mensual'!J6,0))+parametros_carros!$E$21*('Plan mensual'!J3+IF(parametros_carros!$H$21="Todos",'Plan mensual'!J7,0))+parametros_carros!$F$21*('Plan mensual'!J4+IF(parametros_carros!$H$21="Todos",'Plan mensual'!J8,0))+parametros_carros!$G$21*('Plan mensual'!J5+IF(parametros_carros!$H$21="Todos",'Plan mensual'!J9,0)))/60 -> 0.31815 | I4: =(parametros_carros!$D$21*('Plan mensual'!K2+IF(parametros_carros!$H$21="Todos",'Plan mensual'!K6,0))+parametros_carros!$E$21*('Plan mensual'!K3+IF(parametros_carros!$H$21="Todos",'Plan mensual'!K7,0))+parametros_carros!$F$21*('Plan mensual'!K4+IF(parametros_carros!$H$21="Todos",'Plan mensual'!K8,0))+parametros_carros!$G$21*('Plan mensual'!K5+IF(parametros_carros!$H$21="Todos",'Plan mensual'!K9,0)))/60 -> 0.31815 | ... M4: =(parametros_carros!$D$21*('Plan mensual'!O2+IF(parametros_carros!$H$21="Todos",'Plan mensual'!O6,0))+parametros_carros!$E$21*('Plan mensual'!O3+IF(parametros_carros!$H$21="Todos",'Plan mensual'!O7,0))+parametros_carros!$F$21*('Plan mensual'!O4+IF(parametros_carros!$H$21="Todos",'Plan mensual'!O8,0))+parametros_carros!$G$21*('Plan mensual'!O5+IF(parametros_carros!$H$21="Todos",'Plan mensual'!O9,0)))/60 -> 0.2828 | N4: =SUM(B4:M4) -> 3.535 | O4: =MAX(B4:M4) -> 0.31815 | P4: =IF(parametros_carros!$B$7=0,0,(O4+parametros_carros!$G$47)/parametros_carros!$B$7) -> 0.014343222 | Q4: =IF(O4=0,"-",INDEX($B$1:$M$1,MATCH(O4,B4:M4,0))) -> Mar
A5: =parametros_carros!$B$22 -> Cilindrado | B5: =(parametros_carros!$D$22*('Plan mensual'!D2+IF(parametros_carros!$H$22="Todos",'Plan mensual'!D6,0))+parametros_carros!$E$22*('Plan mensual'!D3+IF(parametros_carros!$H$22="Todos",'Plan mensual'!D7,0))+parametros_carros!$F$22*('Plan mensual'!D4+IF(parametros_carros!$H$22="Todos",'Plan mensual'!D8,0))+parametros_carros!$G$22*('Plan mensual'!D5+IF(parametros_carros!$H$22="Todos",'Plan mensual'!D9,0)))/60 -> 0.64256304 | C5: =(parametros_carros!$D$22*('Plan mensual'!E2+IF(parametros_carros!$H$22="Todos",'Plan mensual'!E6,0))+parametros_carros!$E$22*('Plan mensual'!E3+IF(parametros_carros!$H$22="Todos",'Plan mensual'!E7,0))+parametros_carros!$F$22*('Plan mensual'!E4+IF(parametros_carros!$H$22="Todos",'Plan mensual'!E8,0))+parametros_carros!$G$22*('Plan mensual'!E5+IF(parametros_carros!$H$22="Todos",'Plan mensual'!E9,0)))/60 -> 0.56696739 | D5: =(parametros_carros!$D$22*('Plan mensual'!F2+IF(parametros_carros!$H$22="Todos",'Plan mensual'!F6,0))+parametros_carros!$E$22*('Plan mensual'!F3+IF(parametros_carros!$H$22="Todos",'Plan mensual'!F7,0))+parametros_carros!$F$22*('Plan mensual'!F4+IF(parametros_carros!$H$22="Todos",'Plan mensual'!F8,0))+parametros_carros!$G$22*('Plan mensual'!F5+IF(parametros_carros!$H$22="Todos",'Plan mensual'!F9,0)))/60 -> 0.68036087 | E5: =(parametros_carros!$D$22*('Plan mensual'!G2+IF(parametros_carros!$H$22="Todos",'Plan mensual'!G6,0))+parametros_carros!$E$22*('Plan mensual'!G3+IF(parametros_carros!$H$22="Todos",'Plan mensual'!G7,0))+parametros_carros!$F$22*('Plan mensual'!G4+IF(parametros_carros!$H$22="Todos",'Plan mensual'!G8,0))+parametros_carros!$G$22*('Plan mensual'!G5+IF(parametros_carros!$H$22="Todos",'Plan mensual'!G9,0)))/60 -> 0.68036087 | F5: =(parametros_carros!$D$22*('Plan mensual'!H2+IF(parametros_carros!$H$22="Todos",'Plan mensual'!H6,0))+parametros_carros!$E$22*('Plan mensual'!H3+IF(parametros_carros!$H$22="Todos",'Plan mensual'!H7,0))+parametros_carros!$F$22*('Plan mensual'!H4+IF(parametros_carros!$H$22="Todos",'Plan mensual'!H8,0))+parametros_carros!$G$22*('Plan mensual'!H5+IF(parametros_carros!$H$22="Todos",'Plan mensual'!H9,0)))/60 -> 0.68036087 | G5: =(parametros_carros!$D$22*('Plan mensual'!I2+IF(parametros_carros!$H$22="Todos",'Plan mensual'!I6,0))+parametros_carros!$E$22*('Plan mensual'!I3+IF(parametros_carros!$H$22="Todos",'Plan mensual'!I7,0))+parametros_carros!$F$22*('Plan mensual'!I4+IF(parametros_carros!$H$22="Todos",'Plan mensual'!I8,0))+parametros_carros!$G$22*('Plan mensual'!I5+IF(parametros_carros!$H$22="Todos",'Plan mensual'!I9,0)))/60 -> 0.60476522 | H5: =(parametros_carros!$D$22*('Plan mensual'!J2+IF(parametros_carros!$H$22="Todos",'Plan mensual'!J6,0))+parametros_carros!$E$22*('Plan mensual'!J3+IF(parametros_carros!$H$22="Todos",'Plan mensual'!J7,0))+parametros_carros!$F$22*('Plan mensual'!J4+IF(parametros_carros!$H$22="Todos",'Plan mensual'!J8,0))+parametros_carros!$G$22*('Plan mensual'!J5+IF(parametros_carros!$H$22="Todos",'Plan mensual'!J9,0)))/60 -> 0.68036087 | I5: =(parametros_carros!$D$22*('Plan mensual'!K2+IF(parametros_carros!$H$22="Todos",'Plan mensual'!K6,0))+parametros_carros!$E$22*('Plan mensual'!K3+IF(parametros_carros!$H$22="Todos",'Plan mensual'!K7,0))+parametros_carros!$F$22*('Plan mensual'!K4+IF(parametros_carros!$H$22="Todos",'Plan mensual'!K8,0))+parametros_carros!$G$22*('Plan mensual'!K5+IF(parametros_carros!$H$22="Todos",'Plan mensual'!K9,0)))/60 -> 0.68036087 | ... M5: =(parametros_carros!$D$22*('Plan mensual'!O2+IF(parametros_carros!$H$22="Todos",'Plan mensual'!O6,0))+parametros_carros!$E$22*('Plan mensual'!O3+IF(parametros_carros!$H$22="Todos",'Plan mensual'!O7,0))+parametros_carros!$F$22*('Plan mensual'!O4+IF(parametros_carros!$H$22="Todos",'Plan mensual'!O8,0))+parametros_carros!$G$22*('Plan mensual'!O5+IF(parametros_carros!$H$22="Todos",'Plan mensual'!O9,0)))/60 -> 0.60476522 | N5: =SUM(B5:M5) -> 7.5595652 | O5: =MAX(B5:M5) -> 0.68036087 | P5: =IF(parametros_carros!$B$7=0,0,(O5+parametros_carros!$G$48)/parametros_carros!$B$7) -> 0.044535739 | Q5: =IF(O5=0,"-",INDEX($B$1:$M$1,MATCH(O5,B5:M5,0))) -> Mar
