Workbook
Name PiezasPilaEmb: Supuestos!$B$18
Name AltPila: Supuestos!$B$16
Name PalA: Supuestos!$B$9
Name DiasMes: Supuestos!$B$5
Name HuellaPallet: Supuestos!$B$20
Name NivBuffer: Supuestos!$B$19
Name UmbVol: Supuestos!$B$12
Name UmbCajon: Supuestos!$B$10
Name DiasRodante: Supuestos!$B$14
Name CoefCirc: Supuestos!$B$6
Name UmbLT: Supuestos!$B$11
Name DiasAnio: Supuestos!$B$4
Name NivPallet: Supuestos!$B$7
Name DiasManual: Supuestos!$B$13
Name KgPallet: Supuestos!$B$15
Name PalL: Supuestos!$B$8
Name AltPilaTubo: Supuestos!$B$17

Sheet Resumen
A1: Almacenamiento de materia prima — versión 5 (MRP nuevo)
A2: ="Política de stock del MRP, año 2035: stock máximo = stock de seguridad + una compra. Pallets en rack de "&NivPallet&" niveles. Circulación × "&CoefCirc&" en el área bruta. Cajón en el puesto si ocupa ≤ "&UmbCajon&" m²." -> Política de stock del MRP, año 2035: stock máximo = stock de seguridad + una compra. Pallets en rack de 4 niveles. Circulación × 1,5 en el área bruta. Cajón en el puesto si ocupa ≤ 0,1 m².
A3: ="Ítems del MRP: "&COUNTA(Dimensionamiento!B5:B119)&" · en almacén: "&COUNTIF(Dimensionamiento!U5:U119,"Almacén")&" · en puesto de trabajo (cajón): "&COUNTIF(Dimensionamiento!U5:U119,"Puesto de trabajo") -> Ítems del MRP: 115 · en almacén: 71 · en puesto de trabajo (cajón): 44
A4: Días de producción = cuántos días de consumo promedio cubre la sección llena hasta el stock máximo (de los ítems que están en almacén). «Se agota primero» es el ítem con menos días.
A6: Sección de almacén | B6: Ítems en almacén | C6: Ítems en puesto de trabajo | D6: Posiciones | E6: Área neta (m²) | F6: Área bruta (m²) | G6: % del total | H6: Días de producción — el que se agota primero | I6: Ítem que se agota primero | J6: Días de producción — promedio de la sección | K6: Tipo de almacenamiento | L6: Equipo de manejo
A7: Almacén de producto terminado | B7: =COUNTIFS(Dimensionamiento!$F$5:$F$119,A7,Dimensionamiento!$U$5:$U$119,"Almacén") -> 7 | C7: =COUNTIFS(Dimensionamiento!$F$5:$F$119,A7,Dimensionamiento!$U$5:$U$119,"Puesto de trabajo") -> 2 | D7: =SUMIF(Dimensionamiento!$F$5:$F$119,A7,Dimensionamiento!$V$5:$V$119) -> 17 | E7: =SUMIF(Dimensionamiento!$F$5:$F$119,A7,Dimensionamiento!$W$5:$W$119) -> 9.6 | F7: =SUMIF(Dimensionamiento!$F$5:$F$119,A7,Dimensionamiento!$X$5:$X$119) -> 14.4 | G7: =F7/$F$21 -> 0.043460782 | H7: =IFERROR(MINIFS(Dimensionamiento!$J$5:$J$119,Dimensionamiento!$F$5:$F$119,A7,Dimensionamiento!$U$5:$U$119,"Almacén",Dimensionamiento!$J$5:$J$119,">0"),0) -> 19.591249 | I7: {=IFERROR(INDEX(Dimensionamiento!$C$5:$C$119,MATCH(A7&"|Almacén|"&ROUND(H7,6),Dimensionamiento!$AA$5:$AA$119,0)),"—")} -> Matafuego AFFF 50 l (reventa) | J7: =IFERROR(AVERAGEIFS(Dimensionamiento!$J$5:$J$119,Dimensionamiento!$F$5:$F$119,A7,Dimensionamiento!$U$5:$U$119,"Almacén",Dimensionamiento!$J$5:$J$119,">0"),0) -> 30.938264 | K7: Rack selectivo de pallets (4 niveles) para equipos comprados para reventa. | L7: Autoelevador
A8: Calle de chapa (carros) | B8: =COUNTIFS(Dimensionamiento!$F$5:$F$119,A8,Dimensionamiento!$U$5:$U$119,"Almacén") -> 2 | C8: =COUNTIFS(Dimensionamiento!$F$5:$F$119,A8,Dimensionamiento!$U$5:$U$119,"Puesto de trabajo") -> 0 | D8: =SUMIF(Dimensionamiento!$F$5:$F$119,A8,Dimensionamiento!$V$5:$V$119) -> 3 | E8: =SUMIF(Dimensionamiento!$F$5:$F$119,A8,Dimensionamiento!$W$5:$W$119) -> 9 | F8: =SUMIF(Dimensionamiento!$F$5:$F$119,A8,Dimensionamiento!$X$5:$X$119) -> 13.5 | G8: =F8/$F$21 -> 0.040744483 | H8: =IFERROR(MINIFS(Dimensionamiento!$J$5:$J$119,Dimensionamiento!$F$5:$F$119,A8,Dimensionamiento!$U$5:$U$119,"Almacén",Dimensionamiento!$J$5:$J$119,">0"),0) -> 24.092614 | I8: {=IFERROR(INDEX(Dimensionamiento!$C$5:$C$119,MATCH(A8&"|Almacén|"&ROUND(H8,6),Dimensionamiento!$AA$5:$AA$119,0)),"—")} -> Hoja LAC 4,75 × 1500 × 3000 mm | J8: =IFERROR(AVERAGEIFS(Dimensionamiento!$J$5:$J$119,Dimensionamiento!$F$5:$F$119,A8,Dimensionamiento!$U$5:$U$119,"Almacén",Dimensionamiento!$J$5:$J$119,">0"),0) -> 26.149966 | K8: Hojas gruesas 1500 × 3000 en pilas en piso (2 de alto), junto al corte de los carros. | L8: Puente grúa o autoelevador con horquillas largas
A9: Cantilever de caños y barras | B9: =COUNTIFS(Dimensionamiento!$F$5:$F$119,A9,Dimensionamiento!$U$5:$U$119,"Almacén") -> 5 | C9: =COUNTIFS(Dimensionamiento!$F$5:$F$119,A9,Dimensionamiento!$U$5:$U$119,"Puesto de trabajo") -> 0 | D9: =SUMIF(Dimensionamiento!$F$5:$F$119,A9,Dimensionamiento!$V$5:$V$119) -> 11 | E9: =SUMIF(Dimensionamiento!$F$5:$F$119,A9,Dimensionamiento!$W$5:$W$119) -> 30 | F9: =SUMIF(Dimensionamiento!$F$5:$F$119,A9,Dimensionamiento!$X$5:$X$119) -> 45 | G9: =F9/$F$21 -> 0.13581494 | H9: =IFERROR(MINIFS(Dimensionamiento!$J$5:$J$119,Dimensionamiento!$F$5:$F$119,A9,Dimensionamiento!$U$5:$U$119,"Almacén",Dimensionamiento!$J$5:$J$119,">0"),0) -> 7.850104 | I9: {=IFERROR(INDEX(Dimensionamiento!$C$5:$C$119,MATCH(A9&"|Almacén|"&ROUND(H9,6),Dimensionamiento!$AA$5:$AA$119,0)),"—")} -> Caño c/costura Ø76,2 × 1,25 × 6 m (cuerpo 1 kg) | J9: =IFERROR(AVERAGEIFS(Dimensionamiento!$J$5:$J$119,Dimensionamiento!$F$5:$F$119,A9,Dimensionamiento!$U$5:$U$119,"Almacén",Dimensionamiento!$J$5:$J$119,">0"),0) -> 55.36197 | K9: Rack cantilever de 3 niveles para barras de 4 y 6 m. | L9: Autoelevador lateral o puente grúa
A10: Chapa y fleje (manuales) | B10: =COUNTIFS(Dimensionamiento!$F$5:$F$119,A10,Dimensionamiento!$U$5:$U$119,"Almacén") -> 10 | C10: =COUNTIFS(Dimensionamiento!$F$5:$F$119,A10,Dimensionamiento!$U$5:$U$119,"Puesto de trabajo") -> 0 | D10: =SUMIF(Dimensionamiento!$F$5:$F$119,A10,Dimensionamiento!$V$5:$V$119) -> 28 | E10: =SUMIF(Dimensionamiento!$F$5:$F$119,A10,Dimensionamiento!$W$5:$W$119) -> 38.6768 | F10: =SUMIF(Dimensionamiento!$F$5:$F$119,A10,Dimensionamiento!$X$5:$X$119) -> 58.0152 | G10: =F10/$F$21 -> 0.17509625 | H10: =IFERROR(MINIFS(Dimensionamiento!$J$5:$J$119,Dimensionamiento!$F$5:$F$119,A10,Dimensionamiento!$U$5:$U$119,"Almacén",Dimensionamiento!$J$5:$J$119,">0"),0) -> 12.690452 | I10: {=IFERROR(INDEX(Dimensionamiento!$C$5:$C$119,MATCH(A10&"|Almacén|"&ROUND(H10,6),Dimensionamiento!$AA$5:$AA$119,0)),"—")} -> Fleje LAF 1,6 × 200 mm (fondo 5 kg) | J10: =IFERROR(AVERAGEIFS(Dimensionamiento!$J$5:$J$119,Dimensionamiento!$F$5:$F$119,A10,Dimensionamiento!$U$5:$U$119,"Almacén",Dimensionamiento!$J$5:$J$119,">0"),0) -> 32.297827 | K10: Hojas en pilas en piso (2 de alto) y bobinas de fleje sobre pallet en piso (1 nivel). | L10: Puente grúa o autoelevador con pinza de bobina
A11: Depósito de polvo químico | B11: =COUNTIFS(Dimensionamiento!$F$5:$F$119,A11,Dimensionamiento!$U$5:$U$119,"Almacén") -> 4 | C11: =COUNTIFS(Dimensionamiento!$F$5:$F$119,A11,Dimensionamiento!$U$5:$U$119,"Puesto de trabajo") -> 1 | D11: =SUMIF(Dimensionamiento!$F$5:$F$119,A11,Dimensionamiento!$V$5:$V$119) -> 11 | E11: =SUMIF(Dimensionamiento!$F$5:$F$119,A11,Dimensionamiento!$W$5:$W$119) -> 8.4 | F11: =SUMIF(Dimensionamiento!$F$5:$F$119,A11,Dimensionamiento!$X$5:$X$119) -> 12.6 | G11: =F11/$F$21 -> 0.038028184 | H11: =IFERROR(MINIFS(Dimensionamiento!$J$5:$J$119,Dimensionamiento!$F$5:$F$119,A11,Dimensionamiento!$U$5:$U$119,"Almacén",Dimensionamiento!$J$5:$J$119,">0"),0) -> 7.3846125 | I11: {=IFERROR(INDEX(Dimensionamiento!$C$5:$C$119,MATCH(A11&"|Almacén|"&ROUND(H11,6),Dimensionamiento!$AA$5:$AA$119,0)),"—")} -> Polvo ABC 90 (carros y sus recargas) | J11: =IFERROR(AVERAGEIFS(Dimensionamiento!$J$5:$J$119,Dimensionamiento!$F$5:$F$119,A11,Dimensionamiento!$U$5:$U$119,"Almacén",Dimensionamiento!$J$5:$J$119,">0"),0) -> 45.260681 | K11: Zona seca y cerrada. Big bags de 1 t en rack pesado (4 niveles) y pallets de bolsas y pintura. | L11: Autoelevador
A12: Embalaje | B12: =COUNTIFS(Dimensionamiento!$F$5:$F$119,A12,Dimensionamiento!$U$5:$U$119,"Almacén") -> 6 | C12: =COUNTIFS(Dimensionamiento!$F$5:$F$119,A12,Dimensionamiento!$U$5:$U$119,"Puesto de trabajo") -> 4 | D12: =SUMIF(Dimensionamiento!$F$5:$F$119,A12,Dimensionamiento!$V$5:$V$119) -> 50 | E12: =SUMIF(Dimensionamiento!$F$5:$F$119,A12,Dimensionamiento!$W$5:$W$119) -> 22.2 | F12: =SUMIF(Dimensionamiento!$F$5:$F$119,A12,Dimensionamiento!$X$5:$X$119) -> 33.3 | G12: =F12/$F$21 -> 0.10050306 | H12: =IFERROR(MINIFS(Dimensionamiento!$J$5:$J$119,Dimensionamiento!$F$5:$F$119,A12,Dimensionamiento!$U$5:$U$119,"Almacén",Dimensionamiento!$J$5:$J$119,">0"),0) -> 15.640768 | I12: {=IFERROR(INDEX(Dimensionamiento!$C$5:$C$119,MATCH(A12&"|Almacén|"&ROUND(H12,6),Dimensionamiento!$AA$5:$AA$119,0)),"—")} -> Pallet de madera 1200 × 1000 | J12: =IFERROR(AVERAGEIFS(Dimensionamiento!$J$5:$J$119,Dimensionamiento!$F$5:$F$119,A12,Dimensionamiento!$U$5:$U$119,"Almacén",Dimensionamiento!$J$5:$J$119,">0"),0) -> 24.694584 | K12: Rack de pallets (4 niveles) para cajas plegadas; pallets de madera vacíos en pila en piso; rollos y cajas chicas en estantería. | L12: Autoelevador y zorra manual
A13: Identificación | B13: =COUNTIFS(Dimensionamiento!$F$5:$F$119,A13,Dimensionamiento!$U$5:$U$119,"Almacén") -> 5 | C13: =COUNTIFS(Dimensionamiento!$F$5:$F$119,A13,Dimensionamiento!$U$5:$U$119,"Puesto de trabajo") -> 11 | D13: =SUMIF(Dimensionamiento!$F$5:$F$119,A13,Dimensionamiento!$V$5:$V$119) -> 9 | E13: =SUMIF(Dimensionamiento!$F$5:$F$119,A13,Dimensionamiento!$W$5:$W$119) -> 3 | F13: =SUMIF(Dimensionamiento!$F$5:$F$119,A13,Dimensionamiento!$X$5:$X$119) -> 4.5 | G13: =F13/$F$21 -> 0.013581494 | H13: =IFERROR(MINIFS(Dimensionamiento!$J$5:$J$119,Dimensionamiento!$F$5:$F$119,A13,Dimensionamiento!$U$5:$U$119,"Almacén",Dimensionamiento!$J$5:$J$119,">0"),0) -> 24.365017 | I13: {=IFERROR(INDEX(Dimensionamiento!$C$5:$C$119,MATCH(A13&"|Almacén|"&ROUND(H13,6),Dimensionamiento!$AA$5:$AA$119,0)),"—")} -> Tarjeta de identificación AGC (CABA) | J13: =IFERROR(AVERAGEIFS(Dimensionamiento!$J$5:$J$119,Dimensionamiento!$F$5:$F$119,A13,Dimensionamiento!$U$5:$U$119,"Almacén",Dimensionamiento!$J$5:$J$119,">0"),0) -> 31.140164 | K13: Estantería de cajas (5 niveles) para etiquetas e impresos; sellos oficiales numerados en sector bajo llave. | L13: Manual
A14: Insumos de montaje (manuales) | B14: =COUNTIFS(Dimensionamiento!$F$5:$F$119,A14,Dimensionamiento!$U$5:$U$119,"Almacén") -> 11 | C14: =COUNTIFS(Dimensionamiento!$F$5:$F$119,A14,Dimensionamiento!$U$5:$U$119,"Puesto de trabajo") -> 5 | D14: =SUMIF(Dimensionamiento!$F$5:$F$119,A14,Dimensionamiento!$V$5:$V$119) -> 31 | E14: =SUMIF(Dimensionamiento!$F$5:$F$119,A14,Dimensionamiento!$W$5:$W$119) -> 13.8 | F14: =SUMIF(Dimensionamiento!$F$5:$F$119,A14,Dimensionamiento!$X$5:$X$119) -> 20.7 | G14: =F14/$F$21 -> 0.062474874 | H14: =IFERROR(MINIFS(Dimensionamiento!$J$5:$J$119,Dimensionamiento!$F$5:$F$119,A14,Dimensionamiento!$U$5:$U$119,"Almacén",Dimensionamiento!$J$5:$J$119,">0"),0) -> 31.425872 | I14: {=IFERROR(INDEX(Dimensionamiento!$C$5:$C$119,MATCH(A14&"|Almacén|"&ROUND(H14,6),Dimensionamiento!$AA$5:$AA$119,0)),"—")} -> Manguera con tobera ABC 5 kg | J14: =IFERROR(AVERAGEIFS(Dimensionamiento!$J$5:$J$119,Dimensionamiento!$F$5:$F$119,A14,Dimensionamiento!$U$5:$U$119,"Almacén",Dimensionamiento!$J$5:$J$119,">0"),0) -> 37.655169 | K14: Rack de pallets (4 niveles) para válvulas, manómetros, toberas, mangueras y soportes; estantería para juntas y tornillos. | L14: Autoelevador y zorra manual
A15: Insumos de recargas | B15: =COUNTIFS(Dimensionamiento!$F$5:$F$119,A15,Dimensionamiento!$U$5:$U$119,"Almacén") -> 7 | C15: =COUNTIFS(Dimensionamiento!$F$5:$F$119,A15,Dimensionamiento!$U$5:$U$119,"Puesto de trabajo") -> 7 | D15: =SUMIF(Dimensionamiento!$F$5:$F$119,A15,Dimensionamiento!$V$5:$V$119) -> 10 | E15: =SUMIF(Dimensionamiento!$F$5:$F$119,A15,Dimensionamiento!$W$5:$W$119) -> 9.6 | F15: =SUMIF(Dimensionamiento!$F$5:$F$119,A15,Dimensionamiento!$X$5:$X$119) -> 14.4 | G15: =F15/$F$21 -> 0.043460782 | H15: =IFERROR(MINIFS(Dimensionamiento!$J$5:$J$119,Dimensionamiento!$F$5:$F$119,A15,Dimensionamiento!$U$5:$U$119,"Almacén",Dimensionamiento!$J$5:$J$119,">0"),0) -> 20.218795 | I15: {=IFERROR(INDEX(Dimensionamiento!$C$5:$C$119,MATCH(A15&"|Almacén|"&ROUND(H15,6),Dimensionamiento!$AA$5:$AA$119,0)),"—")} -> Acetato de potasio Gastro K (recargas) | J15: =IFERROR(AVERAGEIFS(Dimensionamiento!$J$5:$J$119,Dimensionamiento!$F$5:$F$119,A15,Dimensionamiento!$U$5:$U$119,"Almacén",Dimensionamiento!$J$5:$J$119,">0"),0) -> 708.13881 | K15: Rack de pallets para bidones, cilindros y agentes líquidos (1 nivel los líquidos); estantería para rollos y bolsas chicas. | L15: Autoelevador y zorra manual
A16: Insumos de soldadura y superficie | B16: =COUNTIFS(Dimensionamiento!$F$5:$F$119,A16,Dimensionamiento!$U$5:$U$119,"Almacén") -> 2 | C16: =COUNTIFS(Dimensionamiento!$F$5:$F$119,A16,Dimensionamiento!$U$5:$U$119,"Puesto de trabajo") -> 5 | D16: =SUMIF(Dimensionamiento!$F$5:$F$119,A16,Dimensionamiento!$V$5:$V$119) -> 12 | E16: =SUMIF(Dimensionamiento!$F$5:$F$119,A16,Dimensionamiento!$W$5:$W$119) -> 4.8 | F16: =SUMIF(Dimensionamiento!$F$5:$F$119,A16,Dimensionamiento!$X$5:$X$119) -> 7.2 | G16: =F16/$F$21 -> 0.021730391 | H16: =IFERROR(MINIFS(Dimensionamiento!$J$5:$J$119,Dimensionamiento!$F$5:$F$119,A16,Dimensionamiento!$U$5:$U$119,"Almacén",Dimensionamiento!$J$5:$J$119,">0"),0) -> 37.638129 | I16: {=IFERROR(INDEX(Dimensionamiento!$C$5:$C$119,MATCH(A16&"|Almacén|"&ROUND(H16,6),Dimensionamiento!$AA$5:$AA$119,0)),"—")} -> Alambre MAG ER70S-6 Ø0,9 mm (manuales) | J16: =IFERROR(AVERAGEIFS(Dimensionamiento!$J$5:$J$119,Dimensionamiento!$F$5:$F$119,A16,Dimensionamiento!$U$5:$U$119,"Almacén",Dimensionamiento!$J$5:$J$119,">0"),0) -> 67.45048 | K16: Pallets de alambre, pintura y granalla en rack (4 niveles); discos y sprays en estantería. | L16: Autoelevador
A17: Jaula de gases | B17: =COUNTIFS(Dimensionamiento!$F$5:$F$119,A17,Dimensionamiento!$U$5:$U$119,"Almacén") -> 3 | C17: =COUNTIFS(Dimensionamiento!$F$5:$F$119,A17,Dimensionamiento!$U$5:$U$119,"Puesto de trabajo") -> 0 | D17: =SUMIF(Dimensionamiento!$F$5:$F$119,A17,Dimensionamiento!$V$5:$V$119) -> 12 | E17: =SUMIF(Dimensionamiento!$F$5:$F$119,A17,Dimensionamiento!$W$5:$W$119) -> 10.5 | F17: =SUMIF(Dimensionamiento!$F$5:$F$119,A17,Dimensionamiento!$X$5:$X$119) -> 15.75 | G17: =F17/$F$21 -> 0.04753523 | H17: =IFERROR(MINIFS(Dimensionamiento!$J$5:$J$119,Dimensionamiento!$F$5:$F$119,A17,Dimensionamiento!$U$5:$U$119,"Almacén",Dimensionamiento!$J$5:$J$119,">0"),0) -> 7.2670665 | I17: {=IFERROR(INDEX(Dimensionamiento!$C$5:$C$119,MATCH(A17&"|Almacén|"&ROUND(H17,6),Dimensionamiento!$AA$5:$AA$119,0)),"—")} -> Gas MAG Ar + 8 % CO₂ (Arcal 21) | J17: =IFERROR(AVERAGEIFS(Dimensionamiento!$J$5:$J$119,Dimensionamiento!$F$5:$F$119,A17,Dimensionamiento!$U$5:$U$119,"Almacén",Dimensionamiento!$J$5:$J$119,">0"),0) -> 10.196348 | K17: Jaula ventilada y segregada: baterías y packs de cilindros en piso (1 nivel). Evaluar tanque para el gas de soldadura. | L17: Zorra para cilindros / entrega del proveedor
A18: Rack de casquetes y cuplas (carros) | B18: =COUNTIFS(Dimensionamiento!$F$5:$F$119,A18,Dimensionamiento!$U$5:$U$119,"Almacén") -> 5 | C18: =COUNTIFS(Dimensionamiento!$F$5:$F$119,A18,Dimensionamiento!$U$5:$U$119,"Puesto de trabajo") -> 0 | D18: =SUMIF(Dimensionamiento!$F$5:$F$119,A18,Dimensionamiento!$V$5:$V$119) -> 11 | E18: =SUMIF(Dimensionamiento!$F$5:$F$119,A18,Dimensionamiento!$W$5:$W$119) -> 6 | F18: =SUMIF(Dimensionamiento!$F$5:$F$119,A18,Dimensionamiento!$X$5:$X$119) -> 9 | G18: =F18/$F$21 -> 0.027162989 | H18: =IFERROR(MINIFS(Dimensionamiento!$J$5:$J$119,Dimensionamiento!$F$5:$F$119,A18,Dimensionamiento!$U$5:$U$119,"Almacén",Dimensionamiento!$J$5:$J$119,">0"),0) -> 50.788789 | I18: {=IFERROR(INDEX(Dimensionamiento!$C$5:$C$119,MATCH(A18&"|Almacén|"&ROUND(H18,6),Dimensionamiento!$AA$5:$AA$119,0)),"—")} -> Cupla 2½" BSP (carros 70 y 100 kg) | J18: =IFERROR(AVERAGEIFS(Dimensionamiento!$J$5:$J$119,Dimensionamiento!$F$5:$F$119,A18,Dimensionamiento!$U$5:$U$119,"Almacén",Dimensionamiento!$J$5:$J$119,">0"),0) -> 60.230168 | K18: Rack de pallets (4 niveles) para casquetes importados y cuplas de los carros. | L18: Autoelevador
A19: Rack de insumos de montaje (carros) | B19: =COUNTIFS(Dimensionamiento!$F$5:$F$119,A19,Dimensionamiento!$U$5:$U$119,"Almacén") -> 4 | C19: =COUNTIFS(Dimensionamiento!$F$5:$F$119,A19,Dimensionamiento!$U$5:$U$119,"Puesto de trabajo") -> 9 | D19: =SUMIF(Dimensionamiento!$F$5:$F$119,A19,Dimensionamiento!$V$5:$V$119) -> 7 | E19: =SUMIF(Dimensionamiento!$F$5:$F$119,A19,Dimensionamiento!$W$5:$W$119) -> 4.8 | F19: =SUMIF(Dimensionamiento!$F$5:$F$119,A19,Dimensionamiento!$X$5:$X$119) -> 7.2 | G19: =F19/$F$21 -> 0.021730391 | H19: =IFERROR(MINIFS(Dimensionamiento!$J$5:$J$119,Dimensionamiento!$F$5:$F$119,A19,Dimensionamiento!$U$5:$U$119,"Almacén",Dimensionamiento!$J$5:$J$119,">0"),0) -> 25.016713 | I19: {=IFERROR(INDEX(Dimensionamiento!$C$5:$C$119,MATCH(A19&"|Almacén|"&ROUND(H19,6),Dimensionamiento!$AA$5:$AA$119,0)),"—")} -> Rueda Ø400 × 60, buje 1" (carros 70 y 100 kg) | J19: =IFERROR(AVERAGEIFS(Dimensionamiento!$J$5:$J$119,Dimensionamiento!$F$5:$F$119,A19,Dimensionamiento!$U$5:$U$119,"Almacén",Dimensionamiento!$J$5:$J$119,">0"),0) -> 61.871205 | K19: Rack de pallets (4 niveles) para ruedas, alambre y válvulas de carros; estantería para piezas chicas. | L19: Autoelevador y zorra manual
A20: Procesado: cuerpos cortados y cúpulas y fondos embutidos | B20: — | C20: — | D20: =Procesado!$N$29 -> 42 | E20: =Procesado!$P$29 -> 50.512 | F20: =Procesado!$Q$29 -> 75.768 | G20: =F20/$F$21 -> 0.22867615 | H20: =DiasRodante -> 5 | I20: Rodantes (por definición del colchón) | J20: =DiasManual -> 7 | K20: Pallets en piso (1 nivel) junto a la guillotina, el corte de tubo y el balancín de embutido. Los días son el colchón elegido: manuales (columna promedio) y rodantes (columna mínimo). Detalle en la hoja Procesado. | L20: Autoelevador o zorra; puente grúa para los cuerpos grandes
A21: TOTAL ALMACÉN | B21: =SUM(B7:B19) -> 71 | C21: =SUM(C7:C19) -> 44 | D21: =SUM(D7:D20) -> 254 | E21: =SUM(E7:E20) -> 220.8888 | F21: =SUM(F7:F20) -> 331.3332 | G21: =SUM(G7:G20) -> 1 | H21: =MIN(H7:H19) -> 7.2670665
A22: ="Puestos de trabajo (cajones): "&COUNTIF(Dimensionamiento!$U$5:$U$119,"Puesto de trabajo")&" ítems, unos "&TEXT(SUMIF(Dimensionamiento!$U$5:$U$119,"Puesto de trabajo",Dimensionamiento!$S$5:$S$119),"0.0")&" m² de estantería en total en toda la planta (no suman almacén)." -> Puestos de trabajo (cajones): 44 ítems, unos 1,5 m² de estantería en total en toda la planta (no suman almacén).
A23: Los gases usan un supuesto de 1,5 m² por paquete (dato a confirmar con el proveedor). La huella de cada ítem se puede cambiar en Dimensionamiento (columnas amarillas).
A25: Criticidad: plazo máximo × volumen (cantidad de ítems)
B26: Volumen alto | C26: Volumen bajo | D26: Total
A27: Plazo alto | B27: =COUNTIFS(Dimensionamiento!$L$5:$L$119,"Alto",Dimensionamiento!$N$5:$N$119,"Alto") -> 49 | C27: =COUNTIFS(Dimensionamiento!$L$5:$L$119,"Alto",Dimensionamiento!$N$5:$N$119,"Bajo") -> 47 | D27: =B27+C27 -> 96
A28: Plazo bajo | B28: =COUNTIFS(Dimensionamiento!$L$5:$L$119,"Bajo",Dimensionamiento!$N$5:$N$119,"Alto") -> 6 | C28: =COUNTIFS(Dimensionamiento!$L$5:$L$119,"Bajo",Dimensionamiento!$N$5:$N$119,"Bajo") -> 13 | D28: =B28+C28 -> 19
A29: Total | B29: =SUM(B27:B28) -> 55 | C29: =SUM(C27:C28) -> 60 | D29: =SUM(D27:D28) -> 115
A30: Plazo alto y volumen alto = criticidad Alta; uno solo = Media; ninguno = Baja. Los umbrales están en Supuestos.
A32: Los 10 ítems que más área ocupan en el almacén
A33: Ítem | B33: Sección | D33: Posiciones | E33: Área bruta (m²) | F33: Plazo máximo (días hábiles) | G33: Criticidad | H33: Días de producción del stock máx.
A34: {=INDEX(Dimensionamiento!$C$5:$C$119,MATCH(LARGE(Dimensionamiento!$Z$5:$Z$119,1),Dimensionamiento!$Z$5:$Z$119,0))} -> Caño c/costura Ø76,2 × 1,25 × 6 m (cuerpo 1 kg) | B34: {=INDEX(Dimensionamiento!$F$5:$F$119,MATCH(LARGE(Dimensionamiento!$Z$5:$Z$119,1),Dimensionamiento!$Z$5:$Z$119,0))} -> Cantilever de caños y barras | D34: {=INDEX(Dimensionamiento!$V$5:$V$119,MATCH(LARGE(Dimensionamiento!$Z$5:$Z$119,1),Dimensionamiento!$Z$5:$Z$119,0))} -> 5 | E34: {=INDEX(Dimensionamiento!$X$5:$X$119,MATCH(LARGE(Dimensionamiento!$Z$5:$Z$119,1),Dimensionamiento!$Z$5:$Z$119,0))} -> 15 | F34: {=INDEX(Dimensionamiento!$K$5:$K$119,MATCH(LARGE(Dimensionamiento!$Z$5:$Z$119,1),Dimensionamiento!$Z$5:$Z$119,0))} -> 1 | G34: {=INDEX(Dimensionamiento!$O$5:$O$119,MATCH(LARGE(Dimensionamiento!$Z$5:$Z$119,1),Dimensionamiento!$Z$5:$Z$119,0))} -> Media | H34: {=INDEX(Dimensionamiento!$J$5:$J$119,MATCH(LARGE(Dimensionamiento!$Z$5:$Z$119,1),Dimensionamiento!$Z$5:$Z$119,0))} -> 7.850104
A35: {=INDEX(Dimensionamiento!$C$5:$C$119,MATCH(LARGE(Dimensionamiento!$Z$5:$Z$119,2),Dimensionamiento!$Z$5:$Z$119,0))} -> Pallet de madera 1200 × 1000 | B35: {=INDEX(Dimensionamiento!$F$5:$F$119,MATCH(LARGE(Dimensionamiento!$Z$5:$Z$119,2),Dimensionamiento!$Z$5:$Z$119,0))} -> Embalaje | D35: {=INDEX(Dimensionamiento!$V$5:$V$119,MATCH(LARGE(Dimensionamiento!$Z$5:$Z$119,2),Dimensionamiento!$Z$5:$Z$119,0))} -> 7 | E35: {=INDEX(Dimensionamiento!$X$5:$X$119,MATCH(LARGE(Dimensionamiento!$Z$5:$Z$119,2),Dimensionamiento!$Z$5:$Z$119,0))} -> 12.6 | F35: {=INDEX(Dimensionamiento!$K$5:$K$119,MATCH(LARGE(Dimensionamiento!$Z$5:$Z$119,2),Dimensionamiento!$Z$5:$Z$119,0))} -> 5 | G35: {=INDEX(Dimensionamiento!$O$5:$O$119,MATCH(LARGE(Dimensionamiento!$Z$5:$Z$119,2),Dimensionamiento!$Z$5:$Z$119,0))} -> Baja | H35: {=INDEX(Dimensionamiento!$J$5:$J$119,MATCH(LARGE(Dimensionamiento!$Z$5:$Z$119,2),Dimensionamiento!$Z$5:$Z$119,0))} -> 15.640768
A36: {=INDEX(Dimensionamiento!$C$5:$C$119,MATCH(LARGE(Dimensionamiento!$Z$5:$Z$119,3),Dimensionamiento!$Z$5:$Z$119,0))} -> Caja de cartón simple ABC 1 kg | B36: {=INDEX(Dimensionamiento!$F$5:$F$119,MATCH(LARGE(Dimensionamiento!$Z$5:$Z$119,3),Dimensionamiento!$Z$5:$Z$119,0))} -> Embalaje | D36: {=INDEX(Dimensionamiento!$V$5:$V$119,MATCH(LARGE(Dimensionamiento!$Z$5:$Z$119,3),Dimensionamiento!$Z$5:$Z$119,0))} -> 28 | E36: {=INDEX(Dimensionamiento!$X$5:$X$119,MATCH(LARGE(Dimensionamiento!$Z$5:$Z$119,3),Dimensionamiento!$Z$5:$Z$119,0))} -> 12.6 | F36: {=INDEX(Dimensionamiento!$K$5:$K$119,MATCH(LARGE(Dimensionamiento!$Z$5:$Z$119,3),Dimensionamiento!$Z$5:$Z$119,0))} -> 10 | G36: {=INDEX(Dimensionamiento!$O$5:$O$119,MATCH(LARGE(Dimensionamiento!$Z$5:$Z$119,3),Dimensionamiento!$Z$5:$Z$119,0))} -> Alta | H36: {=INDEX(Dimensionamiento!$J$5:$J$119,MATCH(LARGE(Dimensionamiento!$Z$5:$Z$119,3),Dimensionamiento!$Z$5:$Z$119,0))} -> 19.324442
A37: {=INDEX(Dimensionamiento!$C$5:$C$119,MATCH(LARGE(Dimensionamiento!$Z$5:$Z$119,4),Dimensionamiento!$Z$5:$Z$119,0))} -> Fleje LAF 1,6 × 250 mm (cúpula 5 kg) | B37: {=INDEX(Dimensionamiento!$F$5:$F$119,MATCH(LARGE(Dimensionamiento!$Z$5:$Z$119,4),Dimensionamiento!$Z$5:$Z$119,0))} -> Chapa y fleje (manuales) | D37: {=INDEX(Dimensionamiento!$V$5:$V$119,MATCH(LARGE(Dimensionamiento!$Z$5:$Z$119,4),Dimensionamiento!$Z$5:$Z$119,0))} -> 5 | E37: {=INDEX(Dimensionamiento!$X$5:$X$119,MATCH(LARGE(Dimensionamiento!$Z$5:$Z$119,4),Dimensionamiento!$Z$5:$Z$119,0))} -> 9 | F37: {=INDEX(Dimensionamiento!$K$5:$K$119,MATCH(LARGE(Dimensionamiento!$Z$5:$Z$119,4),Dimensionamiento!$Z$5:$Z$119,0))} -> 10 | G37: {=INDEX(Dimensionamiento!$O$5:$O$119,MATCH(LARGE(Dimensionamiento!$Z$5:$Z$119,4),Dimensionamiento!$Z$5:$Z$119,0))} -> Alta | H37: {=INDEX(Dimensionamiento!$J$5:$J$119,MATCH(LARGE(Dimensionamiento!$Z$5:$Z$119,4),Dimensionamiento!$Z$5:$Z$119,0))} -> 14.331348
A38: {=INDEX(Dimensionamiento!$C$5:$C$119,MATCH(LARGE(Dimensionamiento!$Z$5:$Z$119,5),Dimensionamiento!$Z$5:$Z$119,0))} -> Hoja LAF 1,6 × 1000 × 2000 mm | B38: {=INDEX(Dimensionamiento!$F$5:$F$119,MATCH(LARGE(Dimensionamiento!$Z$5:$Z$119,5),Dimensionamiento!$Z$5:$Z$119,0))} -> Chapa y fleje (manuales) | D38: {=INDEX(Dimensionamiento!$V$5:$V$119,MATCH(LARGE(Dimensionamiento!$Z$5:$Z$119,5),Dimensionamiento!$Z$5:$Z$119,0))} -> 5 | E38: {=INDEX(Dimensionamiento!$X$5:$X$119,MATCH(LARGE(Dimensionamiento!$Z$5:$Z$119,5),Dimensionamiento!$Z$5:$Z$119,0))} -> 9 | F38: {=INDEX(Dimensionamiento!$K$5:$K$119,MATCH(LARGE(Dimensionamiento!$Z$5:$Z$119,5),Dimensionamiento!$Z$5:$Z$119,0))} -> 10 | G38: {=INDEX(Dimensionamiento!$O$5:$O$119,MATCH(LARGE(Dimensionamiento!$Z$5:$Z$119,5),Dimensionamiento!$Z$5:$Z$119,0))} -> Alta | H38: {=INDEX(Dimensionamiento!$J$5:$J$119,MATCH(LARGE(Dimensionamiento!$Z$5:$Z$119,5),Dimensionamiento!$Z$5:$Z$119,0))} -> 32.898733
A39: {=INDEX(Dimensionamiento!$C$5:$C$119,MATCH(LARGE(Dimensionamiento!$Z$5:$Z$119,6),Dimensionamiento!$Z$5:$Z$119,0))} -> Barra trefilada SAE 1045 1" × 6 m (eje 50 a 100 kg) | B39: {=INDEX(Dimensionamiento!$F$5:$F$119,MATCH(LARGE(Dimensionamiento!$Z$5:$Z$119,6),Dimensionamiento!$Z$5:$Z$119,0))} -> Cantilever de caños y barras | D39: {=INDEX(Dimensionamiento!$V$5:$V$119,MATCH(LARGE(Dimensionamiento!$Z$5:$Z$119,6),Dimensionamiento!$Z$5:$Z$119,0))} -> 1 | E39: {=INDEX(Dimensionamiento!$X$5:$X$119,MATCH(LARGE(Dimensionamiento!$Z$5:$Z$119,6),Dimensionamiento!$Z$5:$Z$119,0))} -> 7.5 | F39: {=INDEX(Dimensionamiento!$K$5:$K$119,MATCH(LARGE(Dimensionamiento!$Z$5:$Z$119,6),Dimensionamiento!$Z$5:$Z$119,0))} -> 10 | G39: {=INDEX(Dimensionamiento!$O$5:$O$119,MATCH(LARGE(Dimensionamiento!$Z$5:$Z$119,6),Dimensionamiento!$Z$5:$Z$119,0))} -> Media | H39: {=INDEX(Dimensionamiento!$J$5:$J$119,MATCH(LARGE(Dimensionamiento!$Z$5:$Z$119,6),Dimensionamiento!$Z$5:$Z$119,0))} -> 66.917659
A40: {=INDEX(Dimensionamiento!$C$5:$C$119,MATCH(LARGE(Dimensionamiento!$Z$5:$Z$119,7),Dimensionamiento!$Z$5:$Z$119,0))} -> Barra trefilada SAE 1045 3/4" × 4 m (eje 25 kg) | B40: {=INDEX(Dimensionamiento!$F$5:$F$119,MATCH(LARGE(Dimensionamiento!$Z$5:$Z$119,7),Dimensionamiento!$Z$5:$Z$119,0))} -> Cantilever de caños y barras | D40: {=INDEX(Dimensionamiento!$V$5:$V$119,MATCH(LARGE(Dimensionamiento!$Z$5:$Z$119,7),Dimensionamiento!$Z$5:$Z$119,0))} -> 1 | E40: {=INDEX(Dimensionamiento!$X$5:$X$119,MATCH(LARGE(Dimensionamiento!$Z$5:$Z$119,7),Dimensionamiento!$Z$5:$Z$119,0))} -> 7.5 | F40: {=INDEX(Dimensionamiento!$K$5:$K$119,MATCH(LARGE(Dimensionamiento!$Z$5:$Z$119,7),Dimensionamiento!$Z$5:$Z$119,0))} -> 10 | G40: {=INDEX(Dimensionamiento!$O$5:$O$119,MATCH(LARGE(Dimensionamiento!$Z$5:$Z$119,7),Dimensionamiento!$Z$5:$Z$119,0))} -> Media | H40: {=INDEX(Dimensionamiento!$J$5:$J$119,MATCH(LARGE(Dimensionamiento!$Z$5:$Z$119,7),Dimensionamiento!$Z$5:$Z$119,0))} -> 68.574131
A41: {=INDEX(Dimensionamiento!$C$5:$C$119,MATCH(LARGE(Dimensionamiento!$Z$5:$Z$119,8),Dimensionamiento!$Z$5:$Z$119,0))} -> Caño SAE 1010 1¼" × 2,0 × 6 m (caño del eje 50 a 100 kg) | B41: {=INDEX(Dimensionamiento!$F$5:$F$119,MATCH(LARGE(Dimensionamiento!$Z$5:$Z$119,8),Dimensionamiento!$Z$5:$Z$119,0))} -> Cantilever de caños y barras | D41: {=INDEX(Dimensionamiento!$V$5:$V$119,MATCH(LARGE(Dimensionamiento!$Z$5:$Z$119,8),Dimensionamiento!$Z$5:$Z$119,0))} -> 1 | E41: {=INDEX(Dimensionamiento!$X$5:$X$119,MATCH(LARGE(Dimensionamiento!$Z$5:$Z$119,8),Dimensionamiento!$Z$5:$Z$119,0))} -> 7.5 | F41: {=INDEX(Dimensionamiento!$K$5:$K$119,MATCH(LARGE(Dimensionamiento!$Z$5:$Z$119,8),Dimensionamiento!$Z$5:$Z$119,0))} -> 10 | G41: {=INDEX(Dimensionamiento!$O$5:$O$119,MATCH(LARGE(Dimensionamiento!$Z$5:$Z$119,8),Dimensionamiento!$Z$5:$Z$119,0))} -> Media | H41: {=INDEX(Dimensionamiento!$J$5:$J$119,MATCH(LARGE(Dimensionamiento!$Z$5:$Z$119,8),Dimensionamiento!$Z$5:$Z$119,0))} -> 67.740965
A42: {=INDEX(Dimensionamiento!$C$5:$C$119,MATCH(LARGE(Dimensionamiento!$Z$5:$Z$119,9),Dimensionamiento!$Z$5:$Z$119,0))} -> Caño SAE 1010 1" × 2,0 × 6 m (manija; caño del eje 25 kg) | B42: {=INDEX(Dimensionamiento!$F$5:$F$119,MATCH(LARGE(Dimensionamiento!$Z$5:$Z$119,9),Dimensionamiento!$Z$5:$Z$119,0))} -> Cantilever de caños y barras | D42: {=INDEX(Dimensionamiento!$V$5:$V$119,MATCH(LARGE(Dimensionamiento!$Z$5:$Z$119,9),Dimensionamiento!$Z$5:$Z$119,0))} -> 3 | E42: {=INDEX(Dimensionamiento!$X$5:$X$119,MATCH(LARGE(Dimensionamiento!$Z$5:$Z$119,9),Dimensionamiento!$Z$5:$Z$119,0))} -> 7.5 | F42: {=INDEX(Dimensionamiento!$K$5:$K$119,MATCH(LARGE(Dimensionamiento!$Z$5:$Z$119,9),Dimensionamiento!$Z$5:$Z$119,0))} -> 10 | G42: {=INDEX(Dimensionamiento!$O$5:$O$119,MATCH(LARGE(Dimensionamiento!$Z$5:$Z$119,9),Dimensionamiento!$Z$5:$Z$119,0))} -> Alta | H42: {=INDEX(Dimensionamiento!$J$5:$J$119,MATCH(LARGE(Dimensionamiento!$Z$5:$Z$119,9),Dimensionamiento!$Z$5:$Z$119,0))} -> 65.726988
A43: {=INDEX(Dimensionamiento!$C$5:$C$119,MATCH(LARGE(Dimensionamiento!$Z$5:$Z$119,10),Dimensionamiento!$Z$5:$Z$119,0))} -> Fleje LAF 1,6 × 200 mm (fondo 5 kg) | B43: {=INDEX(Dimensionamiento!$F$5:$F$119,MATCH(LARGE(Dimensionamiento!$Z$5:$Z$119,10),Dimensionamiento!$Z$5:$Z$119,0))} -> Chapa y fleje (manuales) | D43: {=INDEX(Dimensionamiento!$V$5:$V$119,MATCH(LARGE(Dimensionamiento!$Z$5:$Z$119,10),Dimensionamiento!$Z$5:$Z$119,0))} -> 4 | E43: {=INDEX(Dimensionamiento!$X$5:$X$119,MATCH(LARGE(Dimensionamiento!$Z$5:$Z$119,10),Dimensionamiento!$Z$5:$Z$119,0))} -> 7.2 | F43: {=INDEX(Dimensionamiento!$K$5:$K$119,MATCH(LARGE(Dimensionamiento!$Z$5:$Z$119,10),Dimensionamiento!$Z$5:$Z$119,0))} -> 10 | G43: {=INDEX(Dimensionamiento!$O$5:$O$119,MATCH(LARGE(Dimensionamiento!$Z$5:$Z$119,10),Dimensionamiento!$Z$5:$Z$119,0))} -> Alta | H43: {=INDEX(Dimensionamiento!$J$5:$J$119,MATCH(LARGE(Dimensionamiento!$Z$5:$Z$119,10),Dimensionamiento!$Z$5:$Z$119,0))} -> 12.690452

Sheet Supuestos
A1: Supuestos
A2: Azul sobre amarillo = se puede cambiar; todo el libro se recalcula. La política de stock (consumo, plazos, ciclo, unidad de compra) viene del MRP nuevo y se edita en la hoja Política de stock.
A3: Parámetro | B3: Valor | C3: Unidad | D3: Qué hace / fuente
A4: Días hábiles por año | B4: 240 | C4: días | D4: Igual que POLITICA_STOCK del MRP (consumo del año ÷ 240).
A5: Días hábiles por mes | B5: 20 | C5: días | D5: Igual que POLITICA_STOCK del MRP (mes pico ÷ 20).
A6: Coeficiente de circulación | B6: 1.5 | C6: × | D6: Pasillos y maniobra, solo en el área bruta (el layout todavía no está definido).
A7: Pallets apilados por posición (rack) | B7: 4 | C7: niveles | D7: Niveles de los pallets en rack.
A8: Pallet — largo | B8: 1.2 | C8: m | D8: Pallet 1200 × 1000.
A9: Pallet — ancho | B9: 1 | C9: m | D9: Pallet 1200 × 1000.
A10: Puesto de trabajo: superficie máxima para pasar a cajón | B10: 0.1 | C10: m² | D10: Si el stock máximo de un ítem ocupa menos que esto (sin redondear a lugares), se guarda en un cajón en el puesto de trabajo y no suma almacén. Se puede forzar por ítem en Dimensionamiento.
A11: Criticidad: plazo máximo alto desde | B11: 10 | C11: días hábiles | D11: Plazo de entrega máximo ≥ este valor = nivel alto (equivale a unos 15 días corridos).
A12: Criticidad: volumen alto desde el percentil | B12: 0.5 | C12: 0 a 1 | D12: El consumo anual del ítem se compara con el de los ítems de su misma unidad (kg, u, L, hoja, barra, m³). 0,5 = la mitad de arriba.
A13: Procesado: días de producción por adelantado — manuales | B13: 7 | C13: días | D13: Una semana de cuerpos cortados y de cúpulas y fondos embutidos para 1, 2,5, 5 y 10 kg.
A14: Procesado: días de producción por adelantado — rodantes | B14: 5 | C14: días | D14: Cuerpos cortados para 25, 50, 70 y 100 kg (sus cúpulas y fondos se compran).
A15: Procesado: carga máxima por pallet | B15: 1000 | C15: kg | D15: Supuesto.
... A19: Procesado: pallets apilados | B19: 1 | C19: niveles | D19: 1 = sin apilar pallets de piezas procesadas.
A20: Huella neta de un pallet | B20: =PalL*PalA -> 1.2 | C20: m² | D20: Cálculo.
A22: Cómo se calcula cada MP
A23: Política de stock (hoja Política de stock, igual que el MRP): consumo mientras llega el pedido = consumo promedio por día × plazo promedio; stock de seguridad = consumo por día del mes pico × plazo máximo − ese consumo; cantidad por pedido = consumo por día del mes pico × ciclo de pedido ÷ contenido de la unidad de compra, redondeado hacia arriba; stock máximo = stock de seguridad + cantidad por pedido.
A24: Lugares = stock máximo ÷ cuánto entra en un lugar (pallet, estantería, etc.). Área neta = lugares redondeados ÷ niveles × huella por lugar. Área bruta = área neta × coeficiente de circulación.
A25: Huella por lugar: 1,2 m² si viene en pallet; 2 m² si son big bags; hojas de chapa = medida de la hoja; barras en cantilever = 5 m²; estantería de cajas = 0,6 m²; gases = 1,5 m² por batería o pack (supuesto a confirmar). Se edita por ítem en Dimensionamiento.
A26: Ubicación: si el stock máximo ocupa menos que la superficie de «puesto de trabajo», el ítem va a un cajón en el puesto y no suma almacén. Los sellos oficiales numerados quedan siempre en almacén (sector bajo llave).
A27: Días de producción que dura un stock máximo = stock máximo ÷ consumo promedio por día. Para una sección se informa el ítem que antes se agota (mínimo) y el promedio de sus ítems.
A28: Procesado: cuerpos cortados (chapa y tubo) y cúpulas y fondos embutidos, por adelantado según los días de Supuestos; es un área separada de las materias primas.

Sheet Política de stock
A1: Política de stock — año 2035 (datos del MRP nuevo, hoja POLITICA_STOCK)
A2: Amarillo = dato del MRP que se puede cambiar (plazos, ciclo, contenido, almacén, capacidad por lugar). El resto se calcula con las mismas fórmulas del MRP. Cada cambio se refleja en Dimensionamiento y Resumen.
A4: Ref. | B4: Código | C4: Material | D4: UM | E4: Proveedor | F4: Consumo del año | G4: Consumo por día, promedio | H4: Consumo del mes pico | I4: Consumo por día, mes pico | J4: Plazo mínimo (días hábiles) | K4: Plazo máximo (días hábiles) | L4: De dónde sale el plazo | M4: Consumo mientras llega el pedido | N4: Stock de seguridad | O4: Punto de pedido | P4: Unidad de compra | Q4: Contenido de la unidad de compra | R4: Cada cuántos días se pide | S4: Cantidad por pedido (unidades de compra) | T4: Pedidos por año | U4: Stock máximo | V4: Almacén | W4: Cuánto entra en un lugar | X4: Lugares que ocupa el stock máximo
A5: P01 | B5: MP-01 | C5: Caño c/costura Ø76,2 × 1,25 × 6 m (cuerpo 1 kg) | D5: barra | E5: Metalpri / Prilux | F5: 8809.593 | G5: =F5/DiasAnio -> 36.706637 | H5: 1057.1512 | I5: =H5/DiasMes -> 52.85756 | J5: 1 | K5: 1 | L5: Cotización Comercial MID: entrega inmediata | M5: =G5*(J5+K5)/2 -> 36.706637 | N5: =MAX(0,I5*K5-M5) -> 16.150923 | O5: =M5+N5 -> 52.85756 | P5: Atado de 16 barras | Q5: 16 | R5: 5 | S5: =MAX(1,CEILING(I5*R5/Q5,1)) -> 17 | T5: =F5/(S5*Q5) -> 32.38821 | U5: =N5+S5*Q5 -> 288.15092 | V5: Cantilever de caños y barras | W5: 61 | X5: =U5/W5 -> 4.7237856
A6: P02 | B6: MP-02 | C6: Hoja LAF 1,25 × 1220 × 2440 mm | D6: hoja | E6: Pradecon | F6: 521.9948 | G6: =F6/DiasAnio -> 2.1749783 | H6: 57.4194 | I6: =H6/DiasMes -> 2.87097 | J6: 7 | K6: 10 | L6: Cotización Pradecon (plazo del fleje; para hojas no lo informa) | M6: =G6*(J6+K6)/2 -> 18.487316 | N6: =MAX(0,I6*K6-M6) -> 10.222384 | O6: =M6+N6 -> 28.7097 | P6: Paquete de 50 hojas | Q6: 50 | R6: 20 | S6: =MAX(1,CEILING(I6*R6/Q6,1)) -> 2 | T6: =F6/(S6*Q6) -> 5.219948 | U6: =N6+S6*Q6 -> 110.22238 | V6: Chapa y fleje (manuales) | W6: 136 | X6: =U6/W6 -> 0.81045871
A7: P03 | B7: MP-03 | C7: Hoja LAF 1,6 × 1000 × 2000 mm | D7: hoja | E7: Pradecon | F7: 5447.0534 | G7: =F7/DiasAnio -> 22.696056 | H7: 599.1759 | I7: =H7/DiasMes -> 29.958795 | J7: 7 | K7: 10 | L7: Cotización Pradecon (plazo del fleje; para hojas no lo informa) | M7: =G7*(J7+K7)/2 -> 192.91647 | N7: =MAX(0,I7*K7-M7) -> 106.67148 | O7: =M7+N7 -> 299.58795 | P7: Paquete de 80 hojas | Q7: 80 | R7: 20 | S7: =MAX(1,CEILING(I7*R7/Q7,1)) -> 8 | T7: =F7/(S7*Q7) -> 8.5110209 | U7: =N7+S7*Q7 -> 746.67148 | V7: Chapa y fleje (manuales) | W7: 158 | X7: =U7/W7 -> 4.7257688
A8: P04 | B8: MP-04 | C8: Hoja LAF 2,0 × 1500 × 3000 mm | D8: hoja | E8: Pradecon | F8: 256.9508 | G8: =F8/DiasAnio -> 1.0706283 | H8: 28.2646 | I8: =H8/DiasMes -> 1.41323 | J8: 7 | K8: 10 | L8: Cotización Pradecon (plazo del fleje; para hojas no lo informa) | M8: =G8*(J8+K8)/2 -> 9.1003408 | N8: =MAX(0,I8*K8-M8) -> 5.0319592 | O8: =M8+N8 -> 14.1323 | P8: Paquete de 20 hojas | Q8: 20 | R8: 20 | S8: =MAX(1,CEILING(I8*R8/Q8,1)) -> 2 | T8: =F8/(S8*Q8) -> 6.42377 | U8: =N8+S8*Q8 -> 45.031959 | V8: Chapa y fleje (manuales) | W8: 56 | X8: =U8/W8 -> 0.80414213
A9: P05 | B9: MP-05 | C9: Fleje LAF 0,9 × 114 mm (cúpula 1 kg) | D9: kg | E9: Pradecon | F9: 15992.883 | G9: =F9/DiasAnio -> 66.637015 | H9: 1919.146 | I9: =H9/DiasMes -> 95.9573 | J9: 7 | K9: 10 | L9: Cotización Pradecon: 7 a 10 días | M9: =G9*(J9+K9)/2 -> 566.41462 | N9: =MAX(0,I9*K9-M9) -> 393.15838 | O9: =M9+N9 -> 959.573 | P9: Rollo de 1.900 kg | Q9: 1900 | R9: 5 | S9: =MAX(1,CEILING(I9*R9/Q9,1)) -> 1 | T9: =F9/(S9*Q9) -> 8.4173071 | U9: =N9+S9*Q9 -> 2293.1584 | V9: Chapa y fleje (manuales) | W9: 1000 | X9: =U9/W9 -> 2.2931584
A10: P06 | B10: MP-13 | C10: Fleje LAF 1,25 × 135 mm (fondo 1 kg) | D10: kg | E10: Pradecon | F10: 30867.038 | G10: =F10/DiasAnio -> 128.61266 | H10: 3704.0446 | I10: =H10/DiasMes -> 185.20223 | J10: 7 | K10: 10 | L10: Cotización Pradecon: 7 a 10 días | M10: =G10*(J10+K10)/2 -> 1093.2076 | N10: =MAX(0,I10*K10-M10) -> 758.8147 | O10: =M10+N10 -> 1852.0223 | P10: Rollo de 1.900 kg | Q10: 1900 | R10: 5 | S10: =MAX(1,CEILING(I10*R10/Q10,1)) -> 1 | T10: =F10/(S10*Q10) -> 16.24581 | U10: =N10+S10*Q10 -> 2658.8147 | V10: Chapa y fleje (manuales) | W10: 1000 | X10: =U10/W10 -> 2.6588147
A11: P07 | B11: MP-06 | C11: Fleje LAF 1,25 × 200 mm (cúpula y fondo 2,5 kg) | D11: kg | E11: Pacheco Chapas | F11: 9210.5127 | G11: =F11/DiasAnio -> 38.377136 | H11: 1013.1564 | I11: =H11/DiasMes -> 50.65782 | J11: 7 | K11: 10 | L11: Cotización Pradecon (Pacheco cotizó el mismo fleje sin plazo) | M11: =G11*(J11+K11)/2 -> 326.20566 | N11: =MAX(0,I11*K11-M11) -> 180.37254 | O11: =M11+N11 -> 506.5782 | P11: Rollo de 492 kg | Q11: 492 | R11: 10 | S11: =MAX(1,CEILING(I11*R11/Q11,1)) -> 2 | T11: =F11/(S11*Q11) -> 9.3602771 | U11: =N11+S11*Q11 -> 1164.3725 | V11: Chapa y fleje (manuales) | W11: 492 | X11: =U11/W11 -> 2.3666109
A12: P08 | B12: MP-07 | C12: Fleje LAF 1,6 × 250 mm (cúpula 5 kg) | D12: kg | E12: Pacheco Chapas | F12: 45974.874 | G12: =F12/DiasAnio -> 191.56197 | H12: 5057.2361 | I12: =H12/DiasMes -> 252.86181 | J12: 7 | K12: 10 | L12: Cotización Pradecon (Pacheco cotizó el mismo fleje sin plazo) | M12: =G12*(J12+K12)/2 -> 1628.2768 | N12: =MAX(0,I12*K12-M12) -> 900.34126 | O12: =M12+N12 -> 2528.6181 | P12: Rollo de 615 kg | Q12: 615 | R12: 5 | S12: =MAX(1,CEILING(I12*R12/Q12,1)) -> 3 | T12: =F12/(S12*Q12) -> 24.918631 | U12: =N12+S12*Q12 -> 2745.3413 | V12: Chapa y fleje (manuales) | W12: 615 | X12: =U12/W12 -> 4.4639695
A13: P09 | B13: MP-08 | C13: Fleje LAF 1,6 × 200 mm (fondo 5 kg) | D13: kg | E13: Pacheco Chapas | F13: 29555.276 | G13: =F13/DiasAnio -> 123.14698 | H13: 3251.0804 | I13: =H13/DiasMes -> 162.55402 | J13: 7 | K13: 10 | L13: Cotización Pradecon (Pacheco cotizó el mismo fleje sin plazo) | M13: =G13*(J13+K13)/2 -> 1046.7494 | N13: =MAX(0,I13*K13-M13) -> 578.79083 | O13: =M13+N13 -> 1625.5402 | P13: Rollo de 492 kg | Q13: 492 | R13: 5 | S13: =MAX(1,CEILING(I13*R13/Q13,1)) -> 2 | T13: =F13/(S13*Q13) -> 30.03585 | U13: =N13+S13*Q13 -> 1562.7908 | V13: Chapa y fleje (manuales) | W13: 492 | X13: =U13/W13 -> 3.1764041
A14: P10 | B14: MP-09 | C14: Fleje LAF 1,6 × 300 mm (cúpula 10 kg) | D14: kg | E14: Pacheco Chapas | F14: 3790.4662 | G14: =F14/DiasAnio -> 15.793609 | H14: 416.9513 | I14: =H14/DiasMes -> 20.847565 | J14: 7 | K14: 10 | L14: Cotización Pradecon (Pacheco cotizó el mismo fleje sin plazo) | M14: =G14*(J14+K14)/2 -> 134.24568 | N14: =MAX(0,I14*K14-M14) -> 74.229972 | O14: =M14+N14 -> 208.47565 | P14: Rollo de 590 kg | Q14: 590 | R14: 20 | S14: =MAX(1,CEILING(I14*R14/Q14,1)) -> 1 | T14: =F14/(S14*Q14) -> 6.424519 | U14: =N14+S14*Q14 -> 664.22997 | V14: Chapa y fleje (manuales) | W14: 738 | X14: =U14/W14 -> 0.90004061
A15: P11 | B15: MP-10 | C15: Fleje LAF 2,0 × 249 mm (fondo 10 kg) | D15: kg | E15: Pacheco Chapas | F15: 3134.033 | G15: =F15/DiasAnio -> 13.058471 | H15: 344.7436 | I15: =H15/DiasMes -> 17.23718 | J15: 7 | K15: 10 | L15: Cotización Pradecon (Pacheco cotizó el mismo fleje sin plazo) | M15: =G15*(J15+K15)/2 -> 110.997 | N15: =MAX(0,I15*K15-M15) -> 61.374798 | O15: =M15+N15 -> 172.3718 | P15: Rollo de 498 kg | Q15: 498 | R15: 20 | S15: =MAX(1,CEILING(I15*R15/Q15,1)) -> 1 | T15: =F15/(S15*Q15) -> 6.293239 | U15: =N15+S15*Q15 -> 559.3748 | V15: Chapa y fleje (manuales) | W15: 498 | X15: =U15/W15 -> 1.1232426
A16: P12 | B16: MP-11 | C16: Hoja LAC 3,2 × 1500 × 3000 mm | D16: hoja | E16: Pradecon | F16: 370.5515 | G16: =F16/DiasAnio -> 1.5439646 | H16: 33.3496 | I16: =H16/DiasMes -> 1.66748 | J16: 7 | K16: 10 | L16: Cotización Pradecon (plazo del fleje; para hojas no lo informa) | M16: =G16*(J16+K16)/2 -> 13.123699 | N16: =MAX(0,I16*K16-M16) -> 3.551101 | O16: =M16+N16 -> 16.6748 | P16: Paquete de 20 hojas | Q16: 20 | R16: 20 | S16: =MAX(1,CEILING(I16*R16/Q16,1)) -> 2 | T16: =F16/(S16*Q16) -> 9.2637875 | U16: =N16+S16*Q16 -> 43.551101 | V16: Calle de chapa (carros) | W16: 40 | X16: =U16/W16 -> 1.0887775
... A119: P115 | B119: RV-CLASED_9l | C119: Matafuego Clase D 9 l (reventa) | D119: u | E119: Fabricante nacional | F119: 277.4296 | G119: =F119/DiasAnio -> 1.1559567 | H119: 30.5173 | I119: =H119/DiasMes -> 1.525865 | J119: 20 | K119: 20 | L119: Sin cotización: planilla de MP | M119: =G119*(J119+K119)/2 -> 23.119133 | N119: =MAX(0,I119*K119-M119) -> 7.3981667 | O119: =M119+N119 -> 30.5173 | P119: Unidad | Q119: 1 | R119: 20 | S119: =MAX(1,CEILING(I119*R119/Q119,1)) -> 31 | T119: =F119/(S119*Q119) -> 8.9493419 | U119: =N119+S119*Q119 -> 38.398167 | V119: Almacén de producto terminado | W119: 180 | X119: =U119/W119 -> 0.21332315

Sheet Dimensionamiento
A1: Dimensionamiento del almacenamiento por material (stock máximo de la política)
A2: ="Circulación × "&CoefCirc&" solo en el área bruta · puesto de trabajo si ocupa ≤ "&UmbCajon&" m² · amarillo = editable" -> Circulación × 1,5 solo en el área bruta · puesto de trabajo si ocupa ≤ 0,1 m² · amarillo = editable
A4: Ref. | B4: Código | C4: Material | D4: UM | E4: Proveedor | F4: Sección de almacén | G4: Consumo por día, promedio | H4: Stock de seguridad | I4: Stock máximo | J4: Días de producción que dura el stock máximo | K4: Plazo máximo (días hábiles) | L4: Nivel de plazo | M4: Percentil de volumen (en su UM) | N4: Nivel de volumen | O4: Criticidad | P4: Lugares que ocupa el stock máximo | Q4: Huella por lugar (m²) | R4: Niveles | S4: Superficie sin redondear (m²) | T4: Forzar ubicación | U4: Ubicación | V4: Lugares en almacén | W4: Área neta (m²) | X4: Área bruta (m²) | Y4: Nota | Z4: Clave de orden | AA4: Clave de días
A5: ='Política de stock'!A5 -> P01 | B5: ='Política de stock'!B5 -> MP-01 | C5: ='Política de stock'!C5 -> Caño c/costura Ø76,2 × 1,25 × 6 m (cuerpo 1 kg) | D5: ='Política de stock'!D5 -> barra | E5: ='Política de stock'!E5 -> Metalpri / Prilux | F5: ='Política de stock'!V5 -> Cantilever de caños y barras | G5: ='Política de stock'!G5 -> 36.706637 | H5: ='Política de stock'!N5 -> 16.150923 | I5: ='Política de stock'!U5 -> 288.15092 | J5: =IF(G5>0,I5/G5,0) -> 7.850104 | K5: ='Política de stock'!K5 -> 1 | L5: =IF(K5>=UmbLT,"Alto","Bajo") -> Bajo | M5: =IF('Política de stock'!F5>0,COUNTIFS('Política de stock'!$D$5:$D$119,D5,'Política de stock'!$F$5:$F$119,"<"&'Política de stock'!F5)/COUNTIF('Política de stock'!$D$5:$D$119,D5),0) -> 0.8 | N5: =IF(M5>=UmbVol,"Alto","Bajo") -> Alto | O5: =IF(AND(L5="Alto",N5="Alto"),"Alta",IF(OR(L5="Alto",N5="Alto"),"Media","Baja")) -> Media | P5: ='Política de stock'!X5 -> 4.7237856 | Q5: 5 | R5: 3 | S5: =P5/R5*Q5 -> 7.872976 | U5: =IF(T5<>"",T5,IF(S5<=UmbCajon,"Puesto de trabajo","Almacén")) -> Almacén | V5: =IF(U5="Almacén",ROUNDUP(P5,0),0) -> 5 | W5: =ROUNDUP(V5/R5,0)*Q5 -> 10 | X5: =W5*CoefCirc -> 15 | Z5: =X5+ROW()/1000000 -> 15.000005 | AA5: =F5&"|"&U5&"|"&ROUND(J5,6) -> Cantilever de caños y barras|Almacén|7,850104
A6: ='Política de stock'!A6 -> P02 | B6: ='Política de stock'!B6 -> MP-02 | C6: ='Política de stock'!C6 -> Hoja LAF 1,25 × 1220 × 2440 mm | D6: ='Política de stock'!D6 -> hoja | E6: ='Política de stock'!E6 -> Pradecon | F6: ='Política de stock'!V6 -> Chapa y fleje (manuales) | G6: ='Política de stock'!G6 -> 2.1749783 | H6: ='Política de stock'!N6 -> 10.222384 | I6: ='Política de stock'!U6 -> 110.22238 | J6: =IF(G6>0,I6/G6,0) -> 50.677463 | K6: ='Política de stock'!K6 -> 10 | L6: =IF(K6>=UmbLT,"Alto","Bajo") -> Alto | M6: =IF('Política de stock'!F6>0,COUNTIFS('Política de stock'!$D$5:$D$119,D6,'Política de stock'!$F$5:$F$119,"<"&'Política de stock'!F6)/COUNTIF('Política de stock'!$D$5:$D$119,D6),0) -> 0.6 | N6: =IF(M6>=UmbVol,"Alto","Bajo") -> Alto | O6: =IF(AND(L6="Alto",N6="Alto"),"Alta",IF(OR(L6="Alto",N6="Alto"),"Media","Baja")) -> Alta | P6: ='Política de stock'!X6 -> 0.81045871 | Q6: 2.9768 | R6: 2 | S6: =P6/R6*Q6 -> 1.2062867 | U6: =IF(T6<>"",T6,IF(S6<=UmbCajon,"Puesto de trabajo","Almacén")) -> Almacén | V6: =IF(U6="Almacén",ROUNDUP(P6,0),0) -> 1 | W6: =ROUNDUP(V6/R6,0)*Q6 -> 2.9768 | X6: =W6*CoefCirc -> 4.4652 | Z6: =X6+ROW()/1000000 -> 4.465206 | AA6: =F6&"|"&U6&"|"&ROUND(J6,6) -> Chapa y fleje (manuales)|Almacén|50,677463
A7: ='Política de stock'!A7 -> P03 | B7: ='Política de stock'!B7 -> MP-03 | C7: ='Política de stock'!C7 -> Hoja LAF 1,6 × 1000 × 2000 mm | D7: ='Política de stock'!D7 -> hoja | E7: ='Política de stock'!E7 -> Pradecon | F7: ='Política de stock'!V7 -> Chapa y fleje (manuales) | G7: ='Política de stock'!G7 -> 22.696056 | H7: ='Política de stock'!N7 -> 106.67148 | I7: ='Política de stock'!U7 -> 746.67148 | J7: =IF(G7>0,I7/G7,0) -> 32.898733 | K7: ='Política de stock'!K7 -> 10 | L7: =IF(K7>=UmbLT,"Alto","Bajo") -> Alto | M7: =IF('Política de stock'!F7>0,COUNTIFS('Política de stock'!$D$5:$D$119,D7,'Política de stock'!$F$5:$F$119,"<"&'Política de stock'!F7)/COUNTIF('Política de stock'!$D$5:$D$119,D7),0) -> 0.8 | N7: =IF(M7>=UmbVol,"Alto","Bajo") -> Alto | O7: =IF(AND(L7="Alto",N7="Alto"),"Alta",IF(OR(L7="Alto",N7="Alto"),"Media","Baja")) -> Alta | P7: ='Política de stock'!X7 -> 4.7257688 | Q7: 2 | R7: 2 | S7: =P7/R7*Q7 -> 4.7257688 | U7: =IF(T7<>"",T7,IF(S7<=UmbCajon,"Puesto de trabajo","Almacén")) -> Almacén | V7: =IF(U7="Almacén",ROUNDUP(P7,0),0) -> 5 | W7: =ROUNDUP(V7/R7,0)*Q7 -> 6 | X7: =W7*CoefCirc -> 9 | Z7: =X7+ROW()/1000000 -> 9.000007 | AA7: =F7&"|"&U7&"|"&ROUND(J7,6) -> Chapa y fleje (manuales)|Almacén|32,898733
A8: ='Política de stock'!A8 -> P04 | B8: ='Política de stock'!B8 -> MP-04 | C8: ='Política de stock'!C8 -> Hoja LAF 2,0 × 1500 × 3000 mm | D8: ='Política de stock'!D8 -> hoja | E8: ='Política de stock'!E8 -> Pradecon | F8: ='Política de stock'!V8 -> Chapa y fleje (manuales) | G8: ='Política de stock'!G8 -> 1.0706283 | H8: ='Política de stock'!N8 -> 5.0319592 | I8: ='Política de stock'!U8 -> 45.031959 | J8: =IF(G8>0,I8/G8,0) -> 42.061244 | K8: ='Política de stock'!K8 -> 10 | L8: =IF(K8>=UmbLT,"Alto","Bajo") -> Alto | M8: =IF('Política de stock'!F8>0,COUNTIFS('Política de stock'!$D$5:$D$119,D8,'Política de stock'!$F$5:$F$119,"<"&'Política de stock'!F8)/COUNTIF('Política de stock'!$D$5:$D$119,D8),0) -> 0.2 | N8: =IF(M8>=UmbVol,"Alto","Bajo") -> Bajo | O8: =IF(AND(L8="Alto",N8="Alto"),"Alta",IF(OR(L8="Alto",N8="Alto"),"Media","Baja")) -> Media | P8: ='Política de stock'!X8 -> 0.80414213 | Q8: 4.5 | R8: 2 | S8: =P8/R8*Q8 -> 1.8093198 | U8: =IF(T8<>"",T8,IF(S8<=UmbCajon,"Puesto de trabajo","Almacén")) -> Almacén | V8: =IF(U8="Almacén",ROUNDUP(P8,0),0) -> 1 | W8: =ROUNDUP(V8/R8,0)*Q8 -> 4.5 | X8: =W8*CoefCirc -> 6.75 | Z8: =X8+ROW()/1000000 -> 6.750008 | AA8: =F8&"|"&U8&"|"&ROUND(J8,6) -> Chapa y fleje (manuales)|Almacén|42,061244
A9: ='Política de stock'!A9 -> P05 | B9: ='Política de stock'!B9 -> MP-05 | C9: ='Política de stock'!C9 -> Fleje LAF 0,9 × 114 mm (cúpula 1 kg) | D9: ='Política de stock'!D9 -> kg | E9: ='Política de stock'!E9 -> Pradecon | F9: ='Política de stock'!V9 -> Chapa y fleje (manuales) | G9: ='Política de stock'!G9 -> 66.637015 | H9: ='Política de stock'!N9 -> 393.15838 | I9: ='Política de stock'!U9 -> 2293.1584 | J9: =IF(G9>0,I9/G9,0) -> 34.412682 | K9: ='Política de stock'!K9 -> 10 | L9: =IF(K9>=UmbLT,"Alto","Bajo") -> Alto | M9: =IF('Política de stock'!F9>0,COUNTIFS('Política de stock'!$D$5:$D$119,D9,'Política de stock'!$F$5:$F$119,"<"&'Política de stock'!F9)/COUNTIF('Política de stock'!$D$5:$D$119,D9),0) -> 0.58823529 | N9: =IF(M9>=UmbVol,"Alto","Bajo") -> Alto | O9: =IF(AND(L9="Alto",N9="Alto"),"Alta",IF(OR(L9="Alto",N9="Alto"),"Media","Baja")) -> Alta | P9: ='Política de stock'!X9 -> 2.2931584 | Q9: =HuellaPallet -> 1.2 | R9: 1 | S9: =P9/R9*Q9 -> 2.7517901 | U9: =IF(T9<>"",T9,IF(S9<=UmbCajon,"Puesto de trabajo","Almacén")) -> Almacén | V9: =IF(U9="Almacén",ROUNDUP(P9,0),0) -> 3 | W9: =ROUNDUP(V9/R9,0)*Q9 -> 3.6 | X9: =W9*CoefCirc -> 5.4 | Z9: =X9+ROW()/1000000 -> 5.400009 | AA9: =F9&"|"&U9&"|"&ROUND(J9,6) -> Chapa y fleje (manuales)|Almacén|34,412682
A10: ='Política de stock'!A10 -> P06 | B10: ='Política de stock'!B10 -> MP-13 | C10: ='Política de stock'!C10 -> Fleje LAF 1,25 × 135 mm (fondo 1 kg) | D10: ='Política de stock'!D10 -> kg | E10: ='Política de stock'!E10 -> Pradecon | F10: ='Política de stock'!V10 -> Chapa y fleje (manuales) | G10: ='Política de stock'!G10 -> 128.61266 | H10: ='Política de stock'!N10 -> 758.8147 | I10: ='Política de stock'!U10 -> 2658.8147 | J10: =IF(G10>0,I10/G10,0) -> 20.67304 | K10: ='Política de stock'!K10 -> 10 | L10: =IF(K10>=UmbLT,"Alto","Bajo") -> Alto | M10: =IF('Política de stock'!F10>0,COUNTIFS('Política de stock'!$D$5:$D$119,D10,'Política de stock'!$F$5:$F$119,"<"&'Política de stock'!F10)/COUNTIF('Política de stock'!$D$5:$D$119,D10),0) -> 0.76470588 | N10: =IF(M10>=UmbVol,"Alto","Bajo") -> Alto | O10: =IF(AND(L10="Alto",N10="Alto"),"Alta",IF(OR(L10="Alto",N10="Alto"),"Media","Baja")) -> Alta | P10: ='Política de stock'!X10 -> 2.6588147 | Q10: =HuellaPallet -> 1.2 | R10: 1 | S10: =P10/R10*Q10 -> 3.1905776 | U10: =IF(T10<>"",T10,IF(S10<=UmbCajon,"Puesto de trabajo","Almacén")) -> Almacén | V10: =IF(U10="Almacén",ROUNDUP(P10,0),0) -> 3 | W10: =ROUNDUP(V10/R10,0)*Q10 -> 3.6 | X10: =W10*CoefCirc -> 5.4 | Z10: =X10+ROW()/1000000 -> 5.40001 | AA10: =F10&"|"&U10&"|"&ROUND(J10,6) -> Chapa y fleje (manuales)|Almacén|20,67304
A11: ='Política de stock'!A11 -> P07 | B11: ='Política de stock'!B11 -> MP-06 | C11: ='Política de stock'!C11 -> Fleje LAF 1,25 × 200 mm (cúpula y fondo 2,5 kg) | D11: ='Política de stock'!D11 -> kg | E11: ='Política de stock'!E11 -> Pacheco Chapas | F11: ='Política de stock'!V11 -> Chapa y fleje (manuales) | G11: ='Política de stock'!G11 -> 38.377136 | H11: ='Política de stock'!N11 -> 180.37254 | I11: ='Política de stock'!U11 -> 1164.3725 | J11: =IF(G11>0,I11/G11,0) -> 30.340267 | K11: ='Política de stock'!K11 -> 10 | L11: =IF(K11>=UmbLT,"Alto","Bajo") -> Alto | M11: =IF('Política de stock'!F11>0,COUNTIFS('Política de stock'!$D$5:$D$119,D11,'Política de stock'!$F$5:$F$119,"<"&'Política de stock'!F11)/COUNTIF('Política de stock'!$D$5:$D$119,D11),0) -> 0.52941176 | N11: =IF(M11>=UmbVol,"Alto","Bajo") -> Alto | O11: =IF(AND(L11="Alto",N11="Alto"),"Alta",IF(OR(L11="Alto",N11="Alto"),"Media","Baja")) -> Alta | P11: ='Política de stock'!X11 -> 2.3666109 | Q11: =HuellaPallet -> 1.2 | R11: 1 | S11: =P11/R11*Q11 -> 2.839933 | U11: =IF(T11<>"",T11,IF(S11<=UmbCajon,"Puesto de trabajo","Almacén")) -> Almacén | V11: =IF(U11="Almacén",ROUNDUP(P11,0),0) -> 3 | W11: =ROUNDUP(V11/R11,0)*Q11 -> 3.6 | X11: =W11*CoefCirc -> 5.4 | Z11: =X11+ROW()/1000000 -> 5.400011 | AA11: =F11&"|"&U11&"|"&ROUND(J11,6) -> Chapa y fleje (manuales)|Almacén|30,340267
A12: ='Política de stock'!A12 -> P08 | B12: ='Política de stock'!B12 -> MP-07 | C12: ='Política de stock'!C12 -> Fleje LAF 1,6 × 250 mm (cúpula 5 kg) | D12: ='Política de stock'!D12 -> kg | E12: ='Política de stock'!E12 -> Pacheco Chapas | F12: ='Política de stock'!V12 -> Chapa y fleje (manuales) | G12: ='Política de stock'!G12 -> 191.56197 | H12: ='Política de stock'!N12 -> 900.34126 | I12: ='Política de stock'!U12 -> 2745.3413 | J12: =IF(G12>0,I12/G12,0) -> 14.331348 | K12: ='Política de stock'!K12 -> 10 | L12: =IF(K12>=UmbLT,"Alto","Bajo") -> Alto | M12: =IF('Política de stock'!F12>0,COUNTIFS('Política de stock'!$D$5:$D$119,D12,'Política de stock'!$F$5:$F$119,"<"&'Política de stock'!F12)/COUNTIF('Política de stock'!$D$5:$D$119,D12),0) -> 0.82352941 | N12: =IF(M12>=UmbVol,"Alto","Bajo") -> Alto | O12: =IF(AND(L12="Alto",N12="Alto"),"Alta",IF(OR(L12="Alto",N12="Alto"),"Media","Baja")) -> Alta | P12: ='Política de stock'!X12 -> 4.4639695 | Q12: =HuellaPallet -> 1.2 | R12: 1 | S12: =P12/R12*Q12 -> 5.3567634 | U12: =IF(T12<>"",T12,IF(S12<=UmbCajon,"Puesto de trabajo","Almacén")) -> Almacén | V12: =IF(U12="Almacén",ROUNDUP(P12,0),0) -> 5 | W12: =ROUNDUP(V12/R12,0)*Q12 -> 6 | X12: =W12*CoefCirc -> 9 | Z12: =X12+ROW()/1000000 -> 9.000012 | AA12: =F12&"|"&U12&"|"&ROUND(J12,6) -> Chapa y fleje (manuales)|Almacén|14,331348
A13: ='Política de stock'!A13 -> P09 | B13: ='Política de stock'!B13 -> MP-08 | C13: ='Política de stock'!C13 -> Fleje LAF 1,6 × 200 mm (fondo 5 kg) | D13: ='Política de stock'!D13 -> kg | E13: ='Política de stock'!E13 -> Pacheco Chapas | F13: ='Política de stock'!V13 -> Chapa y fleje (manuales) | G13: ='Política de stock'!G13 -> 123.14698 | H13: ='Política de stock'!N13 -> 578.79083 | I13: ='Política de stock'!U13 -> 1562.7908 | J13: =IF(G13>0,I13/G13,0) -> 12.690452 | K13: ='Política de stock'!K13 -> 10 | L13: =IF(K13>=UmbLT,"Alto","Bajo") -> Alto | M13: =IF('Política de stock'!F13>0,COUNTIFS('Política de stock'!$D$5:$D$119,D13,'Política de stock'!$F$5:$F$119,"<"&'Política de stock'!F13)/COUNTIF('Política de stock'!$D$5:$D$119,D13),0) -> 0.70588235 | N13: =IF(M13>=UmbVol,"Alto","Bajo") -> Alto | O13: =IF(AND(L13="Alto",N13="Alto"),"Alta",IF(OR(L13="Alto",N13="Alto"),"Media","Baja")) -> Alta | P13: ='Política de stock'!X13 -> 3.1764041 | Q13: =HuellaPallet -> 1.2 | R13: 1 | S13: =P13/R13*Q13 -> 3.811685 | U13: =IF(T13<>"",T13,IF(S13<=UmbCajon,"Puesto de trabajo","Almacén")) -> Almacén | V13: =IF(U13="Almacén",ROUNDUP(P13,0),0) -> 4 | W13: =ROUNDUP(V13/R13,0)*Q13 -> 4.8 | X13: =W13*CoefCirc -> 7.2 | Z13: =X13+ROW()/1000000 -> 7.200013 | AA13: =F13&"|"&U13&"|"&ROUND(J13,6) -> Chapa y fleje (manuales)|Almacén|12,690452
A14: ='Política de stock'!A14 -> P10 | B14: ='Política de stock'!B14 -> MP-09 | C14: ='Política de stock'!C14 -> Fleje LAF 1,6 × 300 mm (cúpula 10 kg) | D14: ='Política de stock'!D14 -> kg | E14: ='Política de stock'!E14 -> Pacheco Chapas | F14: ='Política de stock'!V14 -> Chapa y fleje (manuales) | G14: ='Política de stock'!G14 -> 15.793609 | H14: ='Política de stock'!N14 -> 74.229972 | I14: ='Política de stock'!U14 -> 664.22997 | J14: =IF(G14>0,I14/G14,0) -> 42.056883 | K14: ='Política de stock'!K14 -> 10 | L14: =IF(K14>=UmbLT,"Alto","Bajo") -> Alto | M14: =IF('Política de stock'!F14>0,COUNTIFS('Política de stock'!$D$5:$D$119,D14,'Política de stock'!$F$5:$F$119,"<"&'Política de stock'!F14)/COUNTIF('Política de stock'!$D$5:$D$119,D14),0) -> 0.41176471 | N14: =IF(M14>=UmbVol,"Alto","Bajo") -> Bajo | O14: =IF(AND(L14="Alto",N14="Alto"),"Alta",IF(OR(L14="Alto",N14="Alto"),"Media","Baja")) -> Media | P14: ='Política de stock'!X14 -> 0.90004061 | Q14: =HuellaPallet -> 1.2 | R14: 1 | S14: =P14/R14*Q14 -> 1.0800487 | U14: =IF(T14<>"",T14,IF(S14<=UmbCajon,"Puesto de trabajo","Almacén")) -> Almacén | V14: =IF(U14="Almacén",ROUNDUP(P14,0),0) -> 1 | W14: =ROUNDUP(V14/R14,0)*Q14 -> 1.2 | X14: =W14*CoefCirc -> 1.8 | Z14: =X14+ROW()/1000000 -> 1.800014 | AA14: =F14&"|"&U14&"|"&ROUND(J14,6) -> Chapa y fleje (manuales)|Almacén|42,056883
A15: ='Política de stock'!A15 -> P11 | B15: ='Política de stock'!B15 -> MP-10 | C15: ='Política de stock'!C15 -> Fleje LAF 2,0 × 249 mm (fondo 10 kg) | D15: ='Política de stock'!D15 -> kg | E15: ='Política de stock'!E15 -> Pacheco Chapas | F15: ='Política de stock'!V15 -> Chapa y fleje (manuales) | G15: ='Política de stock'!G15 -> 13.058471 | H15: ='Política de stock'!N15 -> 61.374798 | I15: ='Política de stock'!U15 -> 559.3748 | J15: =IF(G15>0,I15/G15,0) -> 42.836164 | K15: ='Política de stock'!K15 -> 10 | L15: =IF(K15>=UmbLT,"Alto","Bajo") -> Alto | M15: =IF('Política de stock'!F15>0,COUNTIFS('Política de stock'!$D$5:$D$119,D15,'Política de stock'!$F$5:$F$119,"<"&'Política de stock'!F15)/COUNTIF('Política de stock'!$D$5:$D$119,D15),0) -> 0.29411765 | N15: =IF(M15>=UmbVol,"Alto","Bajo") -> Bajo | O15: =IF(AND(L15="Alto",N15="Alto"),"Alta",IF(OR(L15="Alto",N15="Alto"),"Media","Baja")) -> Media | P15: ='Política de stock'!X15 -> 1.1232426 | Q15: =HuellaPallet -> 1.2 | R15: 1 | S15: =P15/R15*Q15 -> 1.3478911 | U15: =IF(T15<>"",T15,IF(S15<=UmbCajon,"Puesto de trabajo","Almacén")) -> Almacén | V15: =IF(U15="Almacén",ROUNDUP(P15,0),0) -> 2 | W15: =ROUNDUP(V15/R15,0)*Q15 -> 2.4 | X15: =W15*CoefCirc -> 3.6 | Z15: =X15+ROW()/1000000 -> 3.600015 | AA15: =F15&"|"&U15&"|"&ROUND(J15,6) -> Chapa y fleje (manuales)|Almacén|42,836164
A16: ='Política de stock'!A16 -> P12 | B16: ='Política de stock'!B16 -> MP-11 | C16: ='Política de stock'!C16 -> Hoja LAC 3,2 × 1500 × 3000 mm | D16: ='Política de stock'!D16 -> hoja | E16: ='Política de stock'!E16 -> Pradecon | F16: ='Política de stock'!V16 -> Calle de chapa (carros) | G16: ='Política de stock'!G16 -> 1.5439646 | H16: ='Política de stock'!N16 -> 3.551101 | I16: ='Política de stock'!U16 -> 43.551101 | J16: =IF(G16>0,I16/G16,0) -> 28.207319 | K16: ='Política de stock'!K16 -> 10 | L16: =IF(K16>=UmbLT,"Alto","Bajo") -> Alto | M16: =IF('Política de stock'!F16>0,COUNTIFS('Política de stock'!$D$5:$D$119,D16,'Política de stock'!$F$5:$F$119,"<"&'Política de stock'!F16)/COUNTIF('Política de stock'!$D$5:$D$119,D16),0) -> 0.4 | N16: =IF(M16>=UmbVol,"Alto","Bajo") -> Bajo | O16: =IF(AND(L16="Alto",N16="Alto"),"Alta",IF(OR(L16="Alto",N16="Alto"),"Media","Baja")) -> Media | P16: ='Política de stock'!X16 -> 1.0887775 | Q16: 4.5 | R16: 2 | S16: =P16/R16*Q16 -> 2.4497494 | U16: =IF(T16<>"",T16,IF(S16<=UmbCajon,"Puesto de trabajo","Almacén")) -> Almacén | V16: =IF(U16="Almacén",ROUNDUP(P16,0),0) -> 2 | W16: =ROUNDUP(V16/R16,0)*Q16 -> 4.5 | X16: =W16*CoefCirc -> 6.75 | Z16: =X16+ROW()/1000000 -> 6.750016 | AA16: =F16&"|"&U16&"|"&ROUND(J16,6) -> Calle de chapa (carros)|Almacén|28,207319
A17: ='Política de stock'!A17 -> P13 | B17: ='Política de stock'!B17 -> MP-12 | C17: ='Política de stock'!C17 -> Hoja LAC 4,75 × 1500 × 3000 mm | D17: ='Política de stock'!D17 -> hoja | E17: ='Política de stock'!E17 -> Pradecon | F17: ='Política de stock'!V17 -> Calle de chapa (carros) | G17: ='Política de stock'!G17 -> 0.68830625 | H17: ='Política de stock'!N17 -> 1.5830969 | I17: ='Política de stock'!U17 -> 16.583097 | J17: =IF(G17>0,I17/G17,0) -> 24.092614 | K17: ='Política de stock'!K17 -> 10 | L17: =IF(K17>=UmbLT,"Alto","Bajo") -> Alto | M17: =IF('Política de stock'!F17>0,COUNTIFS('Política de stock'!$D$5:$D$119,D17,'Política de stock'!$F$5:$F$119,"<"&'Política de stock'!F17)/COUNTIF('Política de stock'!$D$5:$D$119,D17),0) -> 0 | N17: =IF(M17>=UmbVol,"Alto","Bajo") -> Bajo | O17: =IF(AND(L17="Alto",N17="Alto"),"Alta",IF(OR(L17="Alto",N17="Alto"),"Media","Baja")) -> Media | P17: ='Política de stock'!X17 -> 0.5527699 | Q17: 4.5 | R17: 2 | S17: =P17/R17*Q17 -> 1.2437323 | U17: =IF(T17<>"",T17,IF(S17<=UmbCajon,"Puesto de trabajo","Almacén")) -> Almacén | V17: =IF(U17="Almacén",ROUNDUP(P17,0),0) -> 1 | W17: =ROUNDUP(V17/R17,0)*Q17 -> 4.5 | X17: =W17*CoefCirc -> 6.75 | Z17: =X17+ROW()/1000000 -> 6.750017 | AA17: =F17&"|"&U17&"|"&ROUND(J17,6) -> Calle de chapa (carros)|Almacén|24,092614
