Workbook

Sheet Indice
A1: ÍNDICE
A3: Hoja | B3: Contenido
A4: Resumen | B4: Resultados principales 2035, conclusiones y recomendaciones
A5: Volumenes | B5: Producción y recargas 2026–2035 (Drive)
A6: Geometria Acero | B6: Medidas, masas de acero, soldadura y pintura por formato
A7: Coef Fabricacion | B7: Consumo de cada MP por unidad fabricada
A8: Coef Recargas | B8: Consumo de cada MP por recarga
A9: Consumo Anual | B9: Consumo por año de cada MP (2026–2035)
A10: MP Abastecimiento | B10: TABLA PRINCIPAL: cómo viene cada MP, cada cuánto llega, stock, almacenamiento, descarga y zona
A11: Almacen MP | B11: m² por zona vs. layout, ubicación recomendada, recepciones y scrap
A12: Manipulacion | B12: Cómo se descarga y se mueve cada unidad de carga; equipos
A13: Pallets PT | B13: Unidades por pallet de cilindros y matafuegos; stock de PT
A14: Corte Opcion D | B14: Opción elegida: hojas estándar + guillotina CENA + flejes a medida. Acero por SKU, nesting y cortes, guillotina, equipos y manejo en el puesto
... A16: Fuentes | B16: Documentos del Drive y fuentes web
A18: Referencias
A19: Dato | B19: Dato editable (número en azul; en las tablas de parámetros va en negrita)
A20: Fórmula | B20: Cálculo o vínculo a otra hoja (negro): no editar
B21: Total o resultado principal
B22: Sección de la hoja
A23: A | B23: Duda de prioridad A (hoja Dudas): cambia decisiones o superficies
A25: Confianza del dato
A26: DRIVE | B26: Dato tomado de un archivo del Drive del proyecto
A27: COTIZ | B27: Cotización o mail recibido de un proveedor
A28: WEB | B28: Fuente web (ver hoja Fuentes)
A29: EST | B29: Estimación de ingeniería: validar antes de cerrar

Sheet Resumen
A1: FLAMA S.A. — MATERIAS PRIMAS, ABASTECIMIENTO Y ALMACENAMIENTO (año de diseño 2035)
A2: Armado el 27/09/2026 a partir del Drive del proyecto (INVESTIGACION PROVEEDORES + Dimensionamiento (13)) y fuentes web. Todo lo calculado es fórmula: cambiar los datos azules recalcula el libro.
A5: ALCANCE
A6: • Fabricación de matafuegos ABC 1–100 kg (terminados) y de cilindros vendidos vacíos, más las recargas de la PLANTA INDUSTRIAL.
A7: • No incluye las recargas de la planta comercial (otro sitio), ni servicios, EPP ni repuestos de máquinas (están en 'Investigación mercado').
A8: • Año de diseño de stock y superficies: 2035 (el máximo del horizonte). El consumo 2026–2035 está en Consumo Anual.
A10: RESULTADOS PRINCIPALES 2035
A11: Indicador | B11: Valor | C11: Unidad | D11: Dónde se calcula
A12: Acero total (hojas, flejes, caño y casquetes) | B12: ='Corte Opcion D'!F22 -> 506.2327 | C12: t/año | D12: Corte Opcion D A
A13: Polvo ABC (fabricación + recargas) | B13: ='MP Abastecimiento'!$L$36/1000 -> 403.50998 | C13: t/año | D13: Consumo Anual MP-33
A14: Gas Ar/CO₂ para soldadura | B14: ='MP Abastecimiento'!$L$28/12 -> 602.46182 | C14: m³/mes promedio | D14: Consumo Anual MP-25
A15: Nitrógeno | B15: ='MP Abastecimiento'!$L$37/12 -> 394.19828 | C15: m³/mes promedio | D15: Consumo Anual MP-34
A16: Alambre MIG (0,9 + 1,2 mm) | B16: =('MP Abastecimiento'!$L$26+'MP Abastecimiento'!$L$27)/1000 -> 7.2907419 | C16: t/año | D16: Consumo Anual
A17: Stock máximo de MP | B17: ='MP Abastecimiento'!X69 -> 187.64379 | C17: t | D17: MP Abastecimiento
A18: Superficie de almacenamiento de MP requerida (incl. pasillos) | B18: ='Almacen MP'!C28 -> 377.01864 | C18: m² | D18: Almacen MP 2
A19: · AL-1 acero (requerido) | B19: ='Almacen MP'!C21 -> 148.3061 | C19: m² | D19: vs ≈116 m² netos para acero en AL-1 (layout v3)
A20: · Pañol de insumos pesados (requerido) | B20: ='Almacen MP'!C22 -> 35.207333 | C20: m² | D20: No existe junto a P1 en el layout v3
A21: · Polvo químico (requerido) | B21: ='Almacen MP'!C23 -> 23.120917 | C21: m²
A22: · Insumos de terminación y embalaje (requerido) | B22: ='Almacen MP'!C24 -> 97.523375 | C22: m² | D22: No existe en el layout v3
A23: · Jaula de gases (requerido) | B23: ='Almacen MP'!C25 -> 48.78 | C23: m² | D23: vs 16 m² dibujados
A24: Recepciones de MP | B24: ='Almacen MP'!C73 -> 5.039729 | C24: camiones/semana | D24: Almacen MP 5
A25: Pallets de PT despachados | B25: ='Pallets PT'!C67 -> 1201.5258 | C25: pallets/año | D25: Pallets PT D
A26: Posiciones de PT requeridas vs layout (122) | B26: ='Pallets PT'!C75 -> 88 | C26: posiciones | D26: Pallets PT D
A27: Cilindros de 1 kg por pallet (a granel) | B27: ='Pallets PT'!C29 -> 780 | C27: u/pallet | D27: Pallets PT A
A28: Cilindros de 5 kg por pallet (a granel) | B28: ='Pallets PT'!E29 -> 126 | C28: u/pallet | D28: Pallets PT A
A29: Scrap ferroso | B29: ='Almacen MP'!B80 -> 68.847833 | C29: t/año | D29: Almacen MP 6
A30: Inversión en corte y manejo de chapa (opción D, guillotina CENA) | B30: ='Corte Opcion D'!D61 -> 82300 | C30: USD/año | D30: Corte Opcion D D
A32: CONCLUSIONES Y RECOMENDACIONES (para debatir)
A33: Chapa | B33: Opción D: cuerpos desde hojas estándar (1220×2440, 1000×2000, 1500×3000) cortadas en guillotina propia CENA 8×3200 con tope de 1.000 mm; cúpulas y fondos desde flejes a medida (Pacheco / Pradecon). La comparación de alternativas está en Comparacion_corte.xlsx.
A34: Chapa | B34: Especificar en la orden de compra: paquetes de hojas ≤2 t, un formato por paquete, sobre tacos; rollos de fleje de 0,5–1 t parados sobre cama de madera, zunchos radiales.
A35: Manipulación | B35: Sin puente grúa: autoelevador 2,5 t con prolongaciones y espolón. En la guillotina, mesa elevadora de tijera 3 t + mesa de bolas: las hojas de 25–168 kg se deslizan, no se levantan (ver Corte Opcion D).
A36: Autoelevador | B36: Autoelevador eléctrico de 2,0–2,5 t (no 1,5 t) para big bags de polvo, pallets de 1 t en rack y rollos con espolón; transpaletas y carros para la línea (cátedra).
A37: Pañol | B37: Separar un pañol de INSUMOS PESADOS junto a AL-1 y al portón P1 (alambre, granalla, cuplas, asientos, consumibles): hoy el pañol está en la esquina opuesta.
A38: Terminación | B38: Falta un depósito de insumos de terminación y embalaje junto a S3a/AL-3 (válvulas, cajas, etiquetas, film, pallets).
A39: Polvo | B39: Big bag de 1 t con estación de descarga sobre la tolva de carga: en 2035 se consumen ≈2 t/día de polvo.
A40: Cilindros | B40: Cilindros vendidos a granel, parados, con separador de cartón por capa, tapón de rosca y film (ver Pallets PT).
A41: Validar | B41: Antes de cerrar: ver hoja Dudas (prioridad A). En especial, % de polvo nuevo en recargas, medidas de caja y los mails a proveedores con volúmenes equivocados.

Sheet Volumenes
A1: VOLÚMENES DE PRODUCCIÓN Y RECARGAS 2026–2035
A2: Fuente: Dimensionamiento_Tecnico_con_Recargas (13).xlsx › hoja datos_base (Drive, subido 27/09/2026). Recargas = PLANTA INDUSTRIAL sin la fila 'TOTAL CARROS' (es subtotal de 25–100 kg y duplicaba 1.427 u en 2035).
A4: A. MATAFUEGOS TERMINADOS (fabricados + cargados) — unidades/año
A5: Año | B5: 1 kg | C5: 2,5 kg | D5: 5 kg | E5: 10 kg | F5: 25 kg | G5: 50 kg | H5: 70 kg | I5: 100 kg | J5: Total
A6: 2026 | B6: 4179 | C6: 295 | D6: 2256 | E6: 92 | F6: 34 | G6: 75 | H6: 16 | I6: 11 | J6: =SUM(B6:I6) -> 6958
A7: 2027 | B7: 5997 | C7: 709 | D7: 3847 | E7: 177 | F7: 58 | G7: 128 | H7: 29 | I7: 18 | J7: =SUM(B7:I7) -> 10963
A8: 2028 | B8: 6852 | C8: 987 | D8: 5094 | E8: 253 | F8: 76 | G8: 166 | H8: 36 | I8: 24 | J8: =SUM(B8:I8) -> 13488
A9: 2029 | B9: 8467 | C9: 1501 | D9: 6823 | E9: 358 | F9: 100 | G9: 221 | H9: 48 | I9: 33 | J9: =SUM(B9:I9) -> 17551
A10: 2030 | B10: 12681 | C10: 2312 | D10: 10819 | E10: 603 | F10: 156 | G10: 343 | H10: 74 | I10: 50 | J10: =SUM(B10:I10) -> 27038
A11: 2031 | B11: 15620 | C11: 3252 | D11: 14606 | E11: 872 | F11: 212 | G11: 466 | H11: 101 | I11: 67 | J11: =SUM(B11:I11) -> 35196
A12: 2032 | B12: 20333 | C12: 4103 | D12: 18878 | E12: 1127 | F12: 273 | G12: 599 | H12: 131 | I12: 87 | J12: =SUM(B12:I12) -> 45531
A13: 2033 | B13: 25132 | C13: 5105 | D13: 23368 | E13: 1395 | F13: 338 | G13: 743 | H13: 163 | I13: 108 | J13: =SUM(B13:I13) -> 56352
A14: 2034 | B14: 28573 | C14: 6195 | D14: 26968 | E14: 1612 | F14: 393 | G14: 866 | H14: 189 | I14: 126 | J14: =SUM(B14:I14) -> 64922
A15: 2035 | B15: 32073 | C15: 7425 | D15: 30751 | E15: 1841 | F15: 453 | G15: 997 | H15: 218 | I15: 145 | J15: =SUM(B15:I15) -> 73903
A17: B. CILINDROS VENDIDOS VACÍOS (pintados y probados, sin válvula) — unidades/año
A18: Año | B18: 1 kg | C18: 2,5 kg | D18: 5 kg | E18: 10 kg | F18: 25 kg | G18: 50 kg | H18: 70 kg | I18: 100 kg | J18: Total
A19: 2026 | B19: 0 | C19: 0 | D19: 0 | E19: 0 | F19: 0 | G19: 0 | H19: 0 | I19: 0 | J19: =SUM(B19:I19) -> 0
A20: 2027 | B20: 0 | C20: 0 | D20: 0 | E20: 0 | F20: 0 | G20: 0 | H20: 0 | I20: 0 | J20: =SUM(B20:I20) -> 0
A21: 2028 | B21: 7662 | C21: 300 | D21: 1479 | E21: 90 | F21: 14 | G21: 32 | H21: 7 | I21: 5 | J21: =SUM(B21:I21) -> 9589
A22: 2029 | B22: 26695 | C22: 1044 | D22: 5152 | E22: 315 | F22: 50 | G22: 111 | H22: 24 | I22: 16 | J22: =SUM(B22:I22) -> 33407
A23: 2030 | B23: 49435 | C23: 1933 | D23: 9541 | E23: 583 | F23: 93 | G23: 205 | H23: 45 | I23: 30 | J23: =SUM(B23:I23) -> 61865
A24: 2031 | B24: 71680 | C24: 2803 | D24: 13834 | E24: 846 | F24: 135 | G24: 298 | H24: 65 | I24: 43 | J24: =SUM(B24:I24) -> 89704
A25: 2032 | B25: 101341 | C25: 3963 | D25: 19559 | E25: 1195 | F25: 191 | G25: 421 | H25: 92 | I25: 60 | J25: =SUM(B25:I25) -> 126822
A26: 2033 | B26: 131001 | C26: 5123 | D26: 25283 | E26: 1545 | F26: 247 | G26: 544 | H26: 119 | I26: 78 | J26: =SUM(B26:I26) -> 163940
A27: 2034 | B27: 146820 | C27: 5741 | D27: 28336 | E27: 1731 | F27: 277 | G27: 610 | H27: 133 | I27: 88 | J27: =SUM(B27:I27) -> 183736
A28: 2035 | B28: 170548 | C28: 6669 | D28: 32915 | E28: 2011 | F28: 322 | G28: 708 | H28: 155 | I28: 102 | J28: =SUM(B28:I28) -> 213430
A30: C. RECIPIENTES FABRICADOS = TERMINADOS + CILINDROS — unidades/año
A31: Año | B31: 1 kg | C31: 2,5 kg | D31: 5 kg | E31: 10 kg | F31: 25 kg | G31: 50 kg | H31: 70 kg | I31: 100 kg | J31: Total
A32: 2026 | B32: =B6+B19 -> 4179 | C32: =C6+C19 -> 295 | D32: =D6+D19 -> 2256 | E32: =E6+E19 -> 92 | F32: =F6+F19 -> 34 | G32: =G6+G19 -> 75 | H32: =H6+H19 -> 16 | I32: =I6+I19 -> 11 | J32: =SUM(B32:I32) -> 6958
A33: 2027 | B33: =B7+B20 -> 5997 | C33: =C7+C20 -> 709 | D33: =D7+D20 -> 3847 | E33: =E7+E20 -> 177 | F33: =F7+F20 -> 58 | G33: =G7+G20 -> 128 | H33: =H7+H20 -> 29 | I33: =I7+I20 -> 18 | J33: =SUM(B33:I33) -> 10963
A34: 2028 | B34: =B8+B21 -> 14514 | C34: =C8+C21 -> 1287 | D34: =D8+D21 -> 6573 | E34: =E8+E21 -> 343 | F34: =F8+F21 -> 90 | G34: =G8+G21 -> 198 | H34: =H8+H21 -> 43 | I34: =I8+I21 -> 29 | J34: =SUM(B34:I34) -> 23077
A35: 2029 | B35: =B9+B22 -> 35162 | C35: =C9+C22 -> 2545 | D35: =D9+D22 -> 11975 | E35: =E9+E22 -> 673 | F35: =F9+F22 -> 150 | G35: =G9+G22 -> 332 | H35: =H9+H22 -> 72 | I35: =I9+I22 -> 49 | J35: =SUM(B35:I35) -> 50958
A36: 2030 | B36: =B10+B23 -> 62116 | C36: =C10+C23 -> 4245 | D36: =D10+D23 -> 20360 | E36: =E10+E23 -> 1186 | F36: =F10+F23 -> 249 | G36: =G10+G23 -> 548 | H36: =H10+H23 -> 119 | I36: =I10+I23 -> 80 | J36: =SUM(B36:I36) -> 88903
A37: 2031 | B37: =B11+B24 -> 87300 | C37: =C11+C24 -> 6055 | D37: =D11+D24 -> 28440 | E37: =E11+E24 -> 1718 | F37: =F11+F24 -> 347 | G37: =G11+G24 -> 764 | H37: =H11+H24 -> 166 | I37: =I11+I24 -> 110 | J37: =SUM(B37:I37) -> 124900
A38: 2032 | B38: =B12+B25 -> 121674 | C38: =C12+C25 -> 8066 | D38: =D12+D25 -> 38437 | E38: =E12+E25 -> 2322 | F38: =F12+F25 -> 464 | G38: =G12+G25 -> 1020 | H38: =H12+H25 -> 223 | I38: =I12+I25 -> 147 | J38: =SUM(B38:I38) -> 172353
A39: 2033 | B39: =B13+B26 -> 156133 | C39: =C13+C26 -> 10228 | D39: =D13+D26 -> 48651 | E39: =E13+E26 -> 2940 | F39: =F13+F26 -> 585 | G39: =G13+G26 -> 1287 | H39: =H13+H26 -> 282 | I39: =I13+I26 -> 186 | J39: =SUM(B39:I39) -> 220292
A40: 2034 | B40: =B14+B27 -> 175393 | C40: =C14+C27 -> 11936 | D40: =D14+D27 -> 55304 | E40: =E14+E27 -> 3343 | F40: =F14+F27 -> 670 | G40: =G14+G27 -> 1476 | H40: =H14+H27 -> 322 | I40: =I14+I27 -> 214 | J40: =SUM(B40:I40) -> 248658
A41: 2035 | B41: =B15+B28 -> 202621 | C41: =C15+C28 -> 14094 | D41: =D15+D28 -> 63666 | E41: =E15+E28 -> 3852 | F41: =F15+F28 -> 775 | G41: =G15+G28 -> 1705 | H41: =H15+H28 -> 373 | I41: =I15+I28 -> 247 | J41: =SUM(B41:I41) -> 287333
A43: D. RECARGAS PLANTA INDUSTRIAL (se hacen en esta planta) — unidades/año
A44: Año | B44: ABC 1 kg | C44: ABC 2,5 kg | D44: ABC 5 kg | E44: ABC 10 kg | F44: Agua 10 l | G44: AFFF 10 l | H44: AFFF 50 l s/r | I44: BC 5 kg | J44: Sales K 6 l | K44: CO₂ 2 kg | L44: CO₂ 5 kg | M44: HCFC/HFC 5 kg | N44: Clase D 9 l | O44: ABC 25 kg s/r | P44: ABC 50 kg s/r | Q44: ABC 70 kg s/r | R44: ABC 100 kg s/r | S44: Total
...

Sheet Geometria Acero
A1: GEOMETRÍA, ACERO Y CONSUMIBLES DE PROCESO POR RECIPIENTE
A2: Medidas: registro FADESA (Dimensiones de chapa), ET's Matafuegos, Materias Primas › Lineamientos, cotizaciones Pacheco N°42021 / Pradecon 173170-173195 y Comparacion_corte.xlsx (opción D elegida: hojas estándar en guillotina propia + fleje a medida). Cuando los archivos se contradicen se anotó en 'Dudas'.
A4: PARÁMETROS GENERALES
A5: Parámetro | B5: Unidad | C5: Valor | D5: Fuente / criterio
A6: Densidad del acero | B6: kg/m³ | C6: 7850 | D6: Valor estándar acero al carbono (Corte_chapa.docx)
A7: Caño cuerpo 1 kg — Ø exterior | B7: mm | C7: 76.2 | D7: Metalprisa: caño c/c LF Ø76,2 (mail 09/09/2026)
A8: Caño cuerpo 1 kg — espesor | B8: mm | C8: 1.25 | D8: Metalprisa Ø76,2 × 1,25 = $37.044 + IVA la barra de 6 m
A9: Largo de barra de caño | B9: mm | C9: 6000 | D9: Metalprisa (caño de 6 m); Ternium: largo estándar 6.000 mm
A10: Merma de corte por cuerpo (ranura + despunte) | B10: mm | C10: 3 | D10: EST
A11: Masa por metro de caño | B11: kg/m | C11: =PI()*($C$7-$C$8)*$C$8*$C$6/1000000 -> 2.3104745 | D11: Fórmula
A12: Masa por barra de caño | B12: kg | C12: =$C$11*$C$9/1000 -> 13.862847 | D12: Fórmula
A13: Puente entre discos en el fleje | B13: mm | C13: 3 | D13: Comparacion_corte (opción D): puente s = 3 mm (≈1,5–3 × e); paso = D₀ + s
A14: Pintura en polvo — peso específico | B14: g/cm³ | C14: 1.5 | D14: EST (poliéster 1,4–1,7). Rendimiento teórico = 1000/(ρ·e) (pinturaenpolvo.org)
A15: Pintura — espesor de película | B15: µm | C15: 70 | D15: Mail a Sinteplast: 60–80 µm en manuales (Drive)
A16: Pintura — pérdidas de aplicación | B16: % | C16: 0.25 | D16: Rendimiento práctico 25–30 % menor que el teórico (pinturaenpolvo.org)
A17: Pintura — consumo práctico | B17: kg/m² | C17: =$C$14*$C$15/1000/(1-$C$16) -> 0.14 | D17: Fórmula
A18: Factor de área de cúpula/fondo embutidos vs. círculo plano | B18: - | C18: 1.15 | D18: EST
A19: Rendimiento de depósito del alambre | B19: % | C19: 0.9 | D19: EST (salpicaduras + despuntes)
A20: Caudal de gas — manuales | B20: L/min | C20: 14 | D20: EST (12–15 L/min según BOM del Drive)
A21: Caudal de gas — rodantes | B21: L/min | C21: 16 | D21: EST
A22: Factor pre/post-flujo y purgas de gas | B22: - | C22: 1.25 | D22: EST
A23: Granalla — consumo por hora de granallado | B23: kg/h | C23: 6 | D23: EST; referencia web ≈9 kg/h en una granalladora comercial (metalmecanica.com)
A24: Granalladora — capacidad real | B24: u/h | C24: 81.2 | D24: Dimensionamiento (13) › Parametros › Granallado = 81,2 u/h
A25: Desengrasante concentrado por m² pintado | B25: L/m² | C25: 0.01 | D25: EST — pedir dato al proveedor del túnel (SP Ingeniería/Electricolor)
A26: Fosfatizante concentrado por m² pintado | B26: L/m² | C26: 0.01 | D26: EST — ídem
A27: Recorrido del tope trasero de la guillotina (CENA 8×3200) | B27: mm | C27: 1000 | D27: Cotización CENA (Drive): versión con tope trasero 20–1.000 mm, USD 36.800 + IVA
A28: Peso máximo por paquete de hojas (orden de compra) | B28: kg | C28: 2000 | D28: Opción D: paquetes ≤2 t (autoelevador 2,5 t y mesa elevadora de 3 t)
A29: DATOS POR FORMATO (una columna por formato)
A30: Concepto | B30: Unidad | C30: 1 kg | D30: 2,5 kg | E30: 5 kg | F30: 10 kg | G30: 25 kg | H30: 50 kg | I30: 70 kg | J30: 100 kg | K30: Fuente / criterio
A31: Tipo de cuerpo | B31: - | C31: Caño | D31: Hoja LAF (guillotina) | E31: Hoja LAF (guillotina) | F31: Hoja LAF (guillotina) | G31: Hoja LAC (guillotina) | H31: Hoja LAC (guillotina) | I31: Hoja LAC (guillotina) | J31: Hoja LAC (guillotina) | K31: Opción D: cuerpos desde hoja estándar cortada en guillotina propia; 1 kg desde caño
A32: Espesor del cuerpo | B32: mm | C32: 1.25 | D32: 1.25 | E32: 1.6 | F32: 2 | G32: 3.2 | H32: 3.2 | I32: 4.75 | J32: 4.75 | K32: FADESA / cotizaciones Pacheco
A33: Ø exterior del recipiente | B33: mm | C33: 76.2 | D33: 124 | E33: 153 | F33: 181.5 | G33: 276.5 | H33: 320 | I33: 390 | J33: 390 | K33: ET's Matafuegos. 70 kg corregido a Ø390: desarrollo 1.212 mm ⇒ Ø≈390 (ET's dice 216,5 → ver Dudas)
A34: Desarrollo de la plancha (= perímetro) | B34: mm | C34: 0 | D34: 385.5 | E34: 474.5 | F34: 563 | G34: 858 | H34: 994 | I34: 1212 | J34: 1212 | K34: FADESA / Lineamientos (Materias Primas)
A35: Alto del cuerpo (1 kg: largo de corte del caño) | B35: mm | C35: 255 | D35: 269.5 | E35: 330 | F35: 495 | G35: 490 | H35: 640 | I35: 680 | J35: 900 | K35: FADESA: caño cortado a 255 mm; planchas L × H
A36: Masa neta del cuerpo | B36: kg | C36: =$C$11*C35/1000 -> 0.589171 | D36: =D34*D35*D32*$C$6/1000000000 -> 1.0194427 | E36: =E34*E35*E32*$C$6/1000000000 -> 1.9667076 | F36: =F34*F35*F32*$C$6/1000000000 -> 4.3753545 | G36: =G34*G35*G32*$C$6/1000000000 -> 10.56095 | H36: =H34*H35*H32*$C$6/1000000000 -> 15.980339 | I36: =I34*I35*I32*$C$6/1000000000 -> 30.730866 | J36: =J34*J35*J32*$C$6/1000000000 -> 40.673205 | K36: Fórmula (1 kg: kg/m de caño × largo)
A37: Espesor de la cúpula | B37: mm | C37: 0.9 | D37: 1.25 | E37: 1.6 | F37: 2 | G37: 0 | H37: 0 | I37: 0 | J37: 0 | K37: FADESA / ET's: 1,6 mm en el 10 kg; la opción D toma 2,0 mm (tabla FLAMA y fleje cotizado por Pacheco) → Dudas
A38: Ø del disco de cúpula (D₀) | B38: mm | C38: 108 | D38: 179 | E38: 221 | F38: 258 | G38: 0 | H38: 0 | I38: 0 | J38: 0 | K38: FADESA 2,5–10 kg; 1 kg = ESTIMADO 108 mm (Comparacion_corte: masa de pieza 0,0461 kg / 0,71) — medir
A39: Ancho del fleje de cúpula | B39: mm | C39: 114 | D39: 200 | E39: 250 | F39: 300 | G39: 0 | H39: 0 | I39: 0 | J39: 0 | K39: Opción D: 1 kg fleje 114 mm (Pradecon, corte a medida sin cargo); 2,5–10 kg Pacheco N°42021
A40: Discos a lo ancho del fleje (cúpula) | B40: u | C40: 1 | D40: 1 | E40: 1 | F40: 1 | G40: 0 | H40: 0 | I40: 0 | J40: 0 | K40: 1 disco por ancho de fleje (troquel simple)
A41: Masa bruta de fleje por cúpula | B41: kg | C41: =IF(C40=0,0,C39/C40*(C38+$C$13)*C37*$C$6/1000000000) -> 0.08940051 | D41: =IF(D40=0,0,D39/D40*(D38+$C$13)*D37*$C$6/1000000000) -> 0.357175 | E41: =IF(E40=0,0,E39/E40*(E38+$C$13)*E37*$C$6/1000000000) -> 0.70336 | F41: =IF(F40=0,0,F39/F40*(F38+$C$13)*F37*$C$6/1000000000) -> 1.22931 | G41: =IF(G40=0,0,G39/G40*(G38+$C$13)*G37*$C$6/1000000000) -> 0 | H41: =IF(H40=0,0,H39/H40*(H38+$C$13)*H37*$C$6/1000000000) -> 0 | I41: =IF(I40=0,0,I39/I40*(I38+$C$13)*I37*$C$6/1000000000) -> 0 | J41: =IF(J40=0,0,J39/J40*(J38+$C$13)*J37*$C$6/1000000000) -> 0 | K41: Fórmula: (ancho/n) × (D₀+puente) × e × ρ
...

Sheet Coef Fabricacion
A1: COEFICIENTES DE CONSUMO POR UNIDAD — FABRICACIÓN
A2: Cada fila es una MP. Consumo anual = Σ coef × volumen (hoja Consumo Anual). R = por recipiente fabricado (terminado + cilindro) · T = por matafuego terminado · C = por cilindro vendido vacío.
A4: PARÁMETROS
A5: Parámetro | B5: Unidad | C5: Valor | D5: Fuente / criterio
A6: Densidad aparente del polvo ABC | B6: kg/L | C6: 0.95 | D6: EST (0,9–1,1)
A7: Volumen libre para el gas (fracción del volumen interior) | B7: % | C7: 0.25 | D7: EST
A8: Presión de carga absoluta (1,4 MPa + 1 bar) | B8: bar | C8: 15 | D8: IRAM 3523: servicio 1,4 MPa (mails del Drive)
A9: Factor de pérdidas de N₂ en la carga (purga, mangueras) | B9: - | C9: 1.3 | D9: EST
A10: Merma de polvo en el llenado | B10: % | C10: 0.01 | D10: EST
A11: Matafuegos de 1 kg por caja | B11: u | C11: 6 | D11: ET's Matafuegos (caja × 6)
A12: Tapones de enmascarado — ciclos de vida | B12: ciclos | C12: 50 | D12: EST
A13: Alambre por punta de contacto | B13: kg | C13: 4 | D13: EST
A14: Recipientes por disco de amolado | B14: u | C14: 150 | D14: EST
A15: Film stretch por pallet | B15: kg | C15: 0.35 | D15: EST (con pre-estirado, recubridor EDOS PS5)
A16: Esquineros por pallet | B16: u | C16: 4 | D16: EST
A17: Masa válvula 1 kg (M22) | B17: kg | C17: 0.2 | D17: EST
A18: Masa válvula M30 + manómetro | B18: kg | C18: 0.35 | D18: EST
A20: Carga nominal de polvo por formato (kg) | B20: kg | L20: 1 | M20: 2.5 | N20: 5 | O20: 10 | P20: 25 | Q20: 50 | R20: 70 | S20: 100
D22: R — por RECIPIENTE fabricado | L22: T — por matafuego TERMINADO | T22: C — por CILINDRO vendido vacío
A23: Código | B23: Materia prima / insumo | C23: Unidad | D23: 1 kg | E23: 2,5 kg | F23: 5 kg | G23: 10 kg | H23: 25 kg | I23: 50 kg | J23: 70 kg | K23: 100 kg | L23: 1 kg | M23: 2,5 kg | N23: 5 kg | O23: 10 kg | P23: 25 kg | Q23: 50 kg | R23: 70 kg | S23: 100 kg | T23: 1 kg | U23: 2,5 kg | V23: 5 kg | W23: 10 kg | X23: 25 kg | Y23: 50 kg | Z23: 70 kg | AA23: 100 kg | AB23: Criterio / fuente | AC23: Confianza
A24: MP-01 | B24: Caño SAE 1010 c/costura Ø76,2 × 1,25 mm × 6 m (cuerpo 1 kg) | C24: barra | D24: ='Geometria Acero'!$C$82 -> 0.043478261 | E24: 0 | F24: 0 | G24: 0 | H24: 0 | I24: 0 | J24: 0 | K24: 0 | L24: 0 | M24: 0 | N24: 0 | O24: 0 | P24: 0 | Q24: 0 | R24: 0 | S24: 0 | T24: 0 | U24: 0 | V24: 0 | W24: 0 | X24: 0 | Y24: 0 | Z24: 0 | AA24: 0 | AB24: Barras por cuerpo = 1 / cuerpos por barra (Geometria) | AC24: COTIZ + EST
A25: MP-02 | B25: Hoja LAF 1,25 × 1220 × 2440 mm (cuerpos 2,5 kg; 27 por hoja) | C25: hoja | D25: 0 | E25: ='Geometria Acero'!$D$87 -> 0.037037037 | F25: 0 | G25: 0 | H25: 0 | I25: 0 | J25: 0 | K25: 0 | L25: 0 | M25: 0 | N25: 0 | O25: 0 | P25: 0 | Q25: 0 | R25: 0 | S25: 0 | T25: 0 | U25: 0 | V25: 0 | W25: 0 | X25: 0 | Y25: 0 | Z25: 0 | AA25: 0 | AB25: Hojas por cuerpo (Geometria, opción D) | AC25: COTIZ + nesting
A26: MP-03 | B26: Hoja LAF 1,6 × 1000 × 2000 mm (cuerpos 5 kg; 12 por hoja) | C26: hoja | D26: 0 | E26: 0 | F26: ='Geometria Acero'!$E$87 -> 0.083333333 | G26: 0 | H26: 0 | I26: 0 | J26: 0 | K26: 0 | L26: 0 | M26: 0 | N26: 0 | O26: 0 | P26: 0 | Q26: 0 | R26: 0 | S26: 0 | T26: 0 | U26: 0 | V26: 0 | W26: 0 | X26: 0 | Y26: 0 | Z26: 0 | AA26: 0 | AB26: Hojas por cuerpo (Geometria, opción D) | AC26: COTIZ + nesting
A27: MP-04 | B27: Hoja LAF 2,0 × 1500 × 3000 mm (cuerpos 10 kg; 15 por hoja) | C27: hoja | D27: 0 | E27: 0 | F27: 0 | G27: ='Geometria Acero'!$F$87 -> 0.066666667 | H27: 0 | I27: 0 | J27: 0 | K27: 0 | L27: 0 | M27: 0 | N27: 0 | O27: 0 | P27: 0 | Q27: 0 | R27: 0 | S27: 0 | T27: 0 | U27: 0 | V27: 0 | W27: 0 | X27: 0 | Y27: 0 | Z27: 0 | AA27: 0 | AB27: Hojas por cuerpo (Geometria, opción D) | AC27: COTIZ + nesting
A28: MP-05 | B28: Fleje LAF 0,9 × 114 mm (cúpula 1 kg) | C28: kg | D28: ='Geometria Acero'!$C$41 -> 0.08940051 | E28: 0 | F28: 0 | G28: 0 | H28: 0 | I28: 0 | J28: 0 | K28: 0 | L28: 0 | M28: 0 | N28: 0 | O28: 0 | P28: 0 | Q28: 0 | R28: 0 | S28: 0 | T28: 0 | U28: 0 | V28: 0 | W28: 0 | X28: 0 | Y28: 0 | Z28: 0 | AA28: 0 | AB28: Masa bruta de fleje por cúpula (Geometria) | AC28: COTIZ + EST
A29: MP-06 | B29: Fleje LAF 1,25 × 200 mm (cúpula Ø179 + fondo Ø148, 2,5 kg) | C29: kg | D29: 0 | E29: ='Geometria Acero'!$D$41+'Geometria Acero'!$D$47 -> 0.6535125 | F29: 0 | G29: 0 | H29: 0 | I29: 0 | J29: 0 | K29: 0 | L29: 0 | M29: 0 | N29: 0 | O29: 0 | P29: 0 | Q29: 0 | R29: 0 | S29: 0 | T29: 0 | U29: 0 | V29: 0 | W29: 0 | X29: 0 | Y29: 0 | Z29: 0 | AA29: 0 | AB29: Masa bruta de fleje cúpula + fondo | AC29: COTIZ
A30: MP-07 | B30: Fleje LAF 1,6 × 250 mm (cúpula Ø221, 5 kg) | C30: kg | D30: 0 | E30: 0 | F30: ='Geometria Acero'!$E$41 -> 0.70336 | G30: 0 | H30: 0 | I30: 0 | J30: 0 | K30: 0 | L30: 0 | M30: 0 | N30: 0 | O30: 0 | P30: 0 | Q30: 0 | R30: 0 | S30: 0 | T30: 0 | U30: 0 | V30: 0 | W30: 0 | X30: 0 | Y30: 0 | Z30: 0 | AA30: 0 | AB30: Masa bruta de fleje por cúpula | AC30: COTIZ
A31: MP-08 | B31: Fleje LAF 1,6 × 200 mm (fondo Ø177, 5 kg) | C31: kg | D31: 0 | E31: 0 | F31: ='Geometria Acero'!$E$47 -> 0.45216 | G31: 0 | H31: 0 | I31: 0 | J31: 0 | K31: 0 | L31: 0 | M31: 0 | N31: 0 | O31: 0 | P31: 0 | Q31: 0 | R31: 0 | S31: 0 | T31: 0 | U31: 0 | V31: 0 | W31: 0 | X31: 0 | Y31: 0 | Z31: 0 | AA31: 0 | AB31: Masa bruta de fleje por fondo | AC31: COTIZ
A32: MP-09 | B32: Fleje LAF 2,0 × 300 mm (cúpula Ø258, 10 kg) | C32: kg | D32: 0 | E32: 0 | F32: 0 | G32: ='Geometria Acero'!$F$41 -> 1.22931 | H32: 0 | I32: 0 | J32: 0 | K32: 0 | L32: 0 | M32: 0 | N32: 0 | O32: 0 | P32: 0 | Q32: 0 | R32: 0 | S32: 0 | T32: 0 | U32: 0 | V32: 0 | W32: 0 | X32: 0 | Y32: 0 | Z32: 0 | AA32: 0 | AB32: Masa bruta de fleje por cúpula | AC32: COTIZ
A33: MP-10 | B33: Fleje LAF 2,0 × 249 mm (fondo Ø205, 10 kg) | C33: kg | D33: 0 | E33: 0 | F33: 0 | G33: ='Geometria Acero'!$F$47 -> 0.8131344 | H33: 0 | I33: 0 | J33: 0 | K33: 0 | L33: 0 | M33: 0 | N33: 0 | O33: 0 | P33: 0 | Q33: 0 | R33: 0 | S33: 0 | T33: 0 | U33: 0 | V33: 0 | W33: 0 | X33: 0 | Y33: 0 | Z33: 0 | AA33: 0 | AB33: Masa bruta de fleje por fondo | AC33: COTIZ
A34: MP-11 | B34: Hoja LAC 3,2 × 1500 × 3000 mm (cuerpos 25 kg: 9 por hoja; 50 kg: 6 por hoja) | C34: hoja | D34: 0 | E34: 0 | F34: 0 | G34: 0 | H34: ='Geometria Acero'!$G$87 -> 0.11111111 | I34: ='Geometria Acero'!$H$87 -> 0.16666667 | J34: 0 | K34: 0 | L34: 0 | M34: 0 | N34: 0 | O34: 0 | P34: 0 | Q34: 0 | R34: 0 | S34: 0 | T34: 0 | U34: 0 | V34: 0 | W34: 0 | X34: 0 | Y34: 0 | Z34: 0 | AA34: 0 | AB34: Hojas por cuerpo (Geometria, opción D) | AC34: COTIZ + nesting
A35: MP-12 | B35: Hoja LAC 4,75 × 1500 × 3000 mm (cuerpos 70 y 100 kg; hoja mixta 3 × 70 + 1 × 100) | C35: hoja | D35: 0 | E35: 0 | F35: 0 | G35: 0 | H35: 0 | I35: 0 | J35: ='Geometria Acero'!$I$87 -> 0.22222222 | K35: ='Geometria Acero'!$J$87 -> 0.33333333 | L35: 0 | M35: 0 | N35: 0 | O35: 0 | P35: 0 | Q35: 0 | R35: 0 | S35: 0 | T35: 0 | U35: 0 | V35: 0 | W35: 0 | X35: 0 | Y35: 0 | Z35: 0 | AA35: 0 | AB35: Hojas por cuerpo; el 70 kg descuenta el 100 kg que sale de la hoja mixta (Geometria) | AC35: COTIZ + nesting
A36: MP-13 | B36: Fleje LAF 0,9 × 106 mm (fondo 1 kg) | C36: kg | D36: ='Geometria Acero'!$C$47 -> 0.07713567 | E36: 0 | F36: 0 | G36: 0 | H36: 0 | I36: 0 | J36: 0 | K36: 0 | L36: 0 | M36: 0 | N36: 0 | O36: 0 | P36: 0 | Q36: 0 | R36: 0 | S36: 0 | T36: 0 | U36: 0 | V36: 0 | W36: 0 | X36: 0 | Y36: 0 | Z36: 0 | AA36: 0 | AB36: Masa bruta de fleje por fondo (Geometria) | AC36: COTIZ + EST
A37: MP-15 | B37: Casquete embutido 10" × 3,2 mm (carro 25 kg) | C37: u | D37: 0 | E37: 0 | F37: 0 | G37: 0 | H37: 2 | I37: 0 | J37: 0 | K37: 0 | L37: 0 | M37: 0 | N37: 0 | O37: 0 | P37: 0 | Q37: 0 | R37: 0 | S37: 0 | T37: 0 | U37: 0 | V37: 0 | W37: 0 | X37: 0 | Y37: 0 | Z37: 0 | AA37: 0 | AB37: 2 casquetes (fondo = cúpula) por recipiente | AC37: DRIVE + EST
A38: MP-16 | B38: Casquete embutido 12" × 3,2 mm (carro 50 kg) | C38: u | D38: 0 | E38: 0 | F38: 0 | G38: 0 | H38: 0 | I38: 2 | J38: 0 | K38: 0 | L38: 0 | M38: 0 | N38: 0 | O38: 0 | P38: 0 | Q38: 0 | R38: 0 | S38: 0 | T38: 0 | U38: 0 | V38: 0 | W38: 0 | X38: 0 | Y38: 0 | Z38: 0 | AA38: 0 | AB38: 2 por recipiente | AC38: DRIVE + EST
A39: MP-17 | B39: Casquete embutido 15" × 4,75 mm (carros 70 y 100 kg) | C39: u | D39: 0 | E39: 0 | F39: 0 | G39: 0 | H39: 0 | I39: 0 | J39: 2 | K39: 2 | L39: 0 | M39: 0 | N39: 0 | O39: 0 | P39: 0 | Q39: 0 | R39: 0 | S39: 0 | T39: 0 | U39: 0 | V39: 0 | W39: 0 | X39: 0 | Y39: 0 | Z39: 0 | AA39: 0 | AB39: 2 por recipiente | AC39: DRIVE + EST
A40: MP-18 | B40: Asiento de válvula roscado M22 (cúpula 1 kg) | C40: u | D40: 1 | E40: 0 | F40: 0 | G40: 0 | H40: 0 | I40: 0 | J40: 0 | K40: 0 | L40: 0 | M40: 0 | N40: 0 | O40: 0 | P40: 0 | Q40: 0 | R40: 0 | S40: 0 | T40: 0 | U40: 0 | V40: 0 | W40: 0 | X40: 0 | Y40: 0 | Z40: 0 | AA40: 0 | AB40: 1 por recipiente | AC40: EST
A41: MP-19 | B41: Asiento de válvula roscado M30 × 1,5 (cúpula 2,5–10 kg) | C41: u | D41: 0 | E41: 1 | F41: 1 | G41: 1 | H41: 0 | I41: 0 | J41: 0 | K41: 0 | L41: 0 | M41: 0 | N41: 0 | O41: 0 | P41: 0 | Q41: 0 | R41: 0 | S41: 0 | T41: 0 | U41: 0 | V41: 0 | W41: 0 | X41: 0 | Y41: 0 | Z41: 0 | AA41: 0 | AB41: 1 por recipiente | AC41: EST
A42: MP-20 | B42: Cupla soldable M30 × 1,5 (carros 25 y 50 kg) | C42: u | D42: 0 | E42: 0 | F42: 0 | G42: 0 | H42: 1 | I42: 1 | J42: 0 | K42: 0 | L42: 0 | M42: 0 | N42: 0 | O42: 0 | P42: 0 | Q42: 0 | R42: 0 | S42: 0 | T42: 0 | U42: 0 | V42: 0 | W42: 0 | X42: 0 | Y42: 0 | Z42: 0 | AA42: 0 | AB42: 1 por recipiente | AC42: COTIZ
A43: MP-21 | B43: Cupla soldable 2½" BSP (carros 70 y 100 kg) | C43: u | D43: 0 | E43: 0 | F43: 0 | G43: 0 | H43: 0 | I43: 0 | J43: 1 | K43: 1 | L43: 0 | M43: 0 | N43: 0 | O43: 0 | P43: 0 | Q43: 0 | R43: 0 | S43: 0 | T43: 0 | U43: 0 | V43: 0 | W43: 0 | X43: 0 | Y43: 0 | Z43: 0 | AA43: 0 | AB43: 1 por recipiente | AC43: COTIZ
...

Sheet Coef Recargas
A1: COEFICIENTES DE CONSUMO POR UNIDAD — RECARGAS (planta industrial)
A2: Por recarga, según tipo de equipo. Se usan los % del Dimensionamiento (13) › Parametros Recargas cuando existen.
A4: PARÁMETROS
A5: Parámetro | B5: Unidad | C5: Valor | D5: Fuente / criterio
A6: Polvo ABC/BC nuevo por recarga (reposición + rechazos) | B6: % | C6: 0.25 | D6: EST: ≈15 % de reposición + 10 % de rechazo en el ensayo Puffer (IRAM 3672, muestreo 10 %)
A7: Polvo clase D nuevo por recarga | B7: % | C7: 0.3 | D7: EST
A8: % CO₂ / agente limpio que se vacían y recargan | B8: % | C8: 0.35 | D8: Dimensionamiento (13) › Parametros Recargas
A9: Pérdidas de trasvase de CO₂ | B9: % | C9: 0.1 | D9: EST
A10: Pérdidas de agente limpio | B10: % | C10: 0.05 | D10: EST
A11: Concentración de AFFF en la premezcla | B11: % | C11: 0.06 | D11: EST conservador (AFFF 3 % o 6 %; lista de precios Drive)
A12: N₂ por recarga agua / AFFF 10 l | B12: m³ | C12: 0.036 | D12: EST: 2,5 L libres × 11 bar × 1,3
A13: N₂ por recarga AFFF 50 l | B13: m³ | C13: 0.18 | D13: EST
A14: N₂ por recarga clase K 6 l | B14: m³ | C14: 0.022 | D14: EST
A15: Argón por recarga de agente limpio vaciado | B15: m³ | C15: 0.02 | D15: EST
A16: Reposición de manómetros | B16: % | C16: 0.08 | D16: EST
A17: Reposición de válvulas | B17: % | C17: 0.03 | D17: EST
... A22: Carga de un equipo clase D 9 l | B22: kg | C22: 10 | D22: EST (BOM Drive: CLD-10)
A24: Carga nominal (kg o litros) | D24: 1 | E24: 2.5 | F24: 5 | G24: 10 | H24: 10 | I24: 10 | J24: 50 | K24: 5 | L24: 6 | M24: 2 | N24: 5 | O24: 5 | P24: =$C$22 -> 10 | Q24: 25 | R24: 50 | S24: 70 | T24: 100
A25: Familia | D25: ABC | E25: ABC | F25: ABC | G25: ABC | H25: LIQ | I25: LIQ | J25: LIQ | K25: BC | L25: LIQ | M25: CO2 | N25: CO2 | O25: LIM | P25: D | Q25: ABC | R25: ABC | S25: ABC | T25: ABC
A26: % de equipos que se desarman (cambio de O-ring) | D26: 1 | E26: 1 | F26: 1 | G26: 1 | H26: 1 | I26: 1 | J26: 1 | K26: 1 | L26: 1 | M26: =$C$8 -> 0.35 | N26: =$C$8 -> 0.35 | O26: =$C$8 -> 0.35 | P26: 1 | Q26: 1 | R26: 1 | S26: 1 | T26: 1
A28: Código | B28: Materia prima / insumo | C28: Unidad | D28: ABC 1 kg | E28: ABC 2,5 kg | F28: ABC 5 kg | G28: ABC 10 kg | H28: Agua 10 l | I28: AFFF 10 l | J28: AFFF 50 l s/r | K28: BC 5 kg | L28: Sales K 6 l | M28: CO₂ 2 kg | N28: CO₂ 5 kg | O28: HCFC/HFC 5 kg | P28: Clase D 9 l | Q28: ABC 25 kg s/r | R28: ABC 50 kg s/r | S28: ABC 70 kg s/r | T28: ABC 100 kg s/r | U28: Criterio / fuente | V28: Confianza
A29: MP-33 | B29: Polvo químico ABC (MAP ≥55 %, IRAM 3569) | C29: kg | D29: =D$24*$C$6 -> 0.25 | E29: =E$24*$C$6 -> 0.625 | F29: =F$24*$C$6 -> 1.25 | G29: =G$24*$C$6 -> 2.5 | H29: 0 | I29: 0 | J29: 0 | K29: 0 | L29: 0 | M29: 0 | N29: 0 | O29: 0 | P29: 0 | Q29: =Q$24*$C$6 -> 6.25 | R29: =R$24*$C$6 -> 12.5 | S29: =S$24*$C$6 -> 17.5 | T29: =T$24*$C$6 -> 25 | U29: Carga nominal + 1 % de merma; recargas: % de polvo nuevo | V29: COTIZ + WEB + EST
A30: MP-34 | B30: Nitrógeno seco (≥99,8 %, rocío ≤ −40 °C) | C30: m³ | D30: =D$24/'Coef Fabricacion'!$C$6*'Coef Fabricacion'!$C$7/(1-'Coef Fabricacion'!$C$7)*'Coef Fabricacion'!$C$8*'Coef Fabricacion'!$C$9/1000 -> 0.0068421053 | E30: =E$24/'Coef Fabricacion'!$C$6*'Coef Fabricacion'!$C$7/(1-'Coef Fabricacion'!$C$7)*'Coef Fabricacion'!$C$8*'Coef Fabricacion'!$C$9/1000 -> 0.017105263 | F30: =F$24/'Coef Fabricacion'!$C$6*'Coef Fabricacion'!$C$7/(1-'Coef Fabricacion'!$C$7)*'Coef Fabricacion'!$C$8*'Coef Fabricacion'!$C$9/1000 -> 0.034210526 | G30: =G$24/'Coef Fabricacion'!$C$6*'Coef Fabricacion'!$C$7/(1-'Coef Fabricacion'!$C$7)*'Coef Fabricacion'!$C$8*'Coef Fabricacion'!$C$9/1000 -> 0.068421053 | H30: =$C$12 -> 0.036 | I30: =$C$12 -> 0.036 | J30: =$C$13 -> 0.18 | K30: =K$24/'Coef Fabricacion'!$C$6*'Coef Fabricacion'!$C$7/(1-'Coef Fabricacion'!$C$7)*'Coef Fabricacion'!$C$8*'Coef Fabricacion'!$C$9/1000 -> 0.034210526 | L30: =$C$14 -> 0.022 | M30: 0 | N30: 0 | O30: 0 | P30: 0 | Q30: =Q$24/'Coef Fabricacion'!$C$6*'Coef Fabricacion'!$C$7/(1-'Coef Fabricacion'!$C$7)*'Coef Fabricacion'!$C$8*'Coef Fabricacion'!$C$9/1000 -> 0.17105263 | R30: =R$24/'Coef Fabricacion'!$C$6*'Coef Fabricacion'!$C$7/(1-'Coef Fabricacion'!$C$7)*'Coef Fabricacion'!$C$8*'Coef Fabricacion'!$C$9/1000 -> 0.34210526 | S30: =S$24/'Coef Fabricacion'!$C$6*'Coef Fabricacion'!$C$7/(1-'Coef Fabricacion'!$C$7)*'Coef Fabricacion'!$C$8*'Coef Fabricacion'!$C$9/1000 -> 0.47894737 | T30: =T$24/'Coef Fabricacion'!$C$6*'Coef Fabricacion'!$C$7/(1-'Coef Fabricacion'!$C$7)*'Coef Fabricacion'!$C$8*'Coef Fabricacion'!$C$9/1000 -> 0.68421053 | U30: Volumen libre × 15 bar × pérdidas | V30: DRIVE + EST
A31: MP-35 | B31: Polvo químico BC (recargas) | C31: kg | D31: 0 | E31: 0 | F31: 0 | G31: 0 | H31: 0 | I31: 0 | J31: 0 | K31: =K$24*$C$6 -> 1.25 | L31: 0 | M31: 0 | N31: 0 | O31: 0 | P31: 0 | Q31: 0 | R31: 0 | S31: 0 | T31: 0 | U31: % de polvo nuevo | V31: COTIZ
A32: MP-36 | B32: Polvo clase D (recargas) | C32: kg | D32: 0 | E32: 0 | F32: 0 | G32: 0 | H32: 0 | I32: 0 | J32: 0 | K32: 0 | L32: 0 | M32: 0 | N32: 0 | O32: 0 | P32: =P$24*$C$7 -> 3 | Q32: 0 | R32: 0 | S32: 0 | T32: 0 | U32: % de polvo nuevo | V32: EST
A33: MP-37 | B33: CO₂ líquido (recargas) | C33: kg | D33: 0 | E33: 0 | F33: 0 | G33: 0 | H33: 0 | I33: 0 | J33: 0 | K33: 0 | L33: 0 | M33: =M$24*$C$8*(1+$C$9) -> 0.77 | N33: =N$24*$C$8*(1+$C$9) -> 1.925 | O33: 0 | P33: 0 | Q33: 0 | R33: 0 | S33: 0 | T33: 0 | U33: Carga × % vaciados × pérdidas de trasvase | V33: DRIVE + EST
A34: MP-38 | B34: Agente limpio HCFC/HFC (recargas) | C34: kg | D34: 0 | E34: 0 | F34: 0 | G34: 0 | H34: 0 | I34: 0 | J34: 0 | K34: 0 | L34: 0 | M34: 0 | N34: 0 | O34: =O$24*$C$8*(1+$C$10) -> 1.8375 | P34: 0 | Q34: 0 | R34: 0 | S34: 0 | T34: 0 | U34: Carga × % vaciados × pérdidas | V34: EST
A35: MP-39 | B35: Argón (presurización de agente limpio) | C35: m³ | D35: 0 | E35: 0 | F35: 0 | G35: 0 | H35: 0 | I35: 0 | J35: 0 | K35: 0 | L35: 0 | M35: 0 | N35: 0 | O35: =$C$8*$C$15 -> 0.007 | P35: 0 | Q35: 0 | R35: 0 | S35: 0 | T35: 0 | U35: % vaciados × m³ por carga | V35: EST
A36: MP-40 | B36: Concentrado AFFF (recargas) | C36: L | D36: 0 | E36: 0 | F36: 0 | G36: 0 | H36: 0 | I36: =I$24*$C$11 -> 0.6 | J36: =J$24*$C$11 -> 3 | K36: 0 | L36: 0 | M36: 0 | N36: 0 | O36: 0 | P36: 0 | Q36: 0 | R36: 0 | S36: 0 | T36: 0 | U36: Volumen × concentración (la premezcla se reemplaza) | V36: COTIZ + WEB
A37: MP-41 | B37: Solución clase K — acetato de potasio (recargas) | C37: L | D37: 0 | E37: 0 | F37: 0 | G37: 0 | H37: 0 | I37: 0 | J37: 0 | K37: 0 | L37: =L$24 -> 6 | M37: 0 | N37: 0 | O37: 0 | P37: 0 | Q37: 0 | R37: 0 | S37: 0 | T37: 0 | U37: Se reemplaza la carga completa | V37: COTIZ + EST
A38: MP-42 | B38: Válvula M-22 para 1 kg con tubo de pesca | C38: u | D38: =$C$17 -> 0.03 | E38: 0 | F38: 0 | G38: 0 | H38: 0 | I38: 0 | J38: 0 | K38: 0 | L38: 0 | M38: 0 | N38: 0 | O38: 0 | P38: 0 | Q38: 0 | R38: 0 | S38: 0 | T38: 0 | U38: 1 por terminado; 3 % de reposición en recargas | V38: COTIZ
A39: MP-43 | B39: Válvula M-30 con resorte para 2,5–10 kg | C39: u | D39: 0 | E39: =$C$17 -> 0.03 | F39: =$C$17 -> 0.03 | G39: =$C$17 -> 0.03 | H39: =$C$17 -> 0.03 | I39: =$C$17 -> 0.03 | J39: 0 | K39: =$C$17 -> 0.03 | L39: =$C$17 -> 0.03 | M39: 0 | N39: 0 | O39: =$C$17 -> 0.03 | P39: 0 | Q39: 0 | R39: 0 | S39: 0 | T39: 0 | U39: 1 por terminado; 3 % de reposición | V39: COTIZ
A40: MP-44 | B40: Válvula para carro 25–100 kg (con traba, manija y resorte) | C40: u | D40: 0 | E40: 0 | F40: 0 | G40: 0 | H40: 0 | I40: 0 | J40: =$C$17 -> 0.03 | K40: 0 | L40: 0 | M40: 0 | N40: 0 | O40: 0 | P40: 0 | Q40: =$C$17 -> 0.03 | R40: =$C$17 -> 0.03 | S40: =$C$17 -> 0.03 | T40: =$C$17 -> 0.03 | U40: 1 por carro terminado | V40: COTIZ
A41: MP-45 | B41: Manómetro IRAM 3533 (1,4 MPa) | C41: u | D41: =$C$16 -> 0.08 | E41: =$C$16 -> 0.08 | F41: =$C$16 -> 0.08 | G41: =$C$16 -> 0.08 | H41: =$C$16 -> 0.08 | I41: =$C$16 -> 0.08 | J41: =$C$16 -> 0.08 | K41: =$C$16 -> 0.08 | L41: =$C$16 -> 0.08 | M41: 0 | N41: 0 | O41: =$C$16 -> 0.08 | P41: 0 | Q41: =$C$16 -> 0.08 | R41: =$C$16 -> 0.08 | S41: =$C$16 -> 0.08 | T41: =$C$16 -> 0.08 | U41: 1 por terminado; 8 % de reposición | V41: EST
A42: MP-46 | B42: Tubo pescante PP/PEAD (2,5–10 kg) | C42: u | D42: 0 | E42: =$C$19 -> 0.03 | F42: =$C$19 -> 0.03 | G42: =$C$19 -> 0.03 | H42: =$C$19 -> 0.03 | I42: =$C$19 -> 0.03 | J42: 0 | K42: =$C$19 -> 0.03 | L42: =$C$19 -> 0.03 | M42: 0 | N42: 0 | O42: =$C$19 -> 0.03 | P42: 0 | Q42: 0 | R42: 0 | S42: 0 | T42: 0 | U42: 1 por terminado (en 1 kg viene con la válvula) | V42: EST
A43: MP-47 | B43: Tubo pescante de acero (carros) | C43: u | D43: 0 | E43: 0 | F43: 0 | G43: 0 | H43: 0 | I43: 0 | J43: =$C$19 -> 0.03 | K43: 0 | L43: 0 | M43: 0 | N43: 0 | O43: 0 | P43: 0 | Q43: =$C$19 -> 0.03 | R43: =$C$19 -> 0.03 | S43: =$C$19 -> 0.03 | T43: =$C$19 -> 0.03 | U43: 1 por carro | V43: EST
A44: MP-48 | B44: Manguera + tobera (2,5–10 kg) | C44: u | D44: 0 | E44: =$C$18 -> 0.05 | F44: =$C$18 -> 0.05 | G44: =$C$18 -> 0.05 | H44: =$C$18 -> 0.05 | I44: =$C$18 -> 0.05 | J44: 0 | K44: =$C$18 -> 0.05 | L44: =$C$18 -> 0.05 | M44: =$C$18 -> 0.05 | N44: =$C$18 -> 0.05 | O44: =$C$18 -> 0.05 | P44: =$C$18 -> 0.05 | Q44: 0 | R44: 0 | S44: 0 | T44: 0 | U44: 1 por terminado (el 1 kg no lleva) | V44: EST
A45: MP-49 | B45: Manguera + lanza/pistola para carro | C45: u | D45: 0 | E45: 0 | F45: 0 | G45: 0 | H45: 0 | I45: 0 | J45: =$C$18 -> 0.05 | K45: 0 | L45: 0 | M45: 0 | N45: 0 | O45: 0 | P45: 0 | Q45: =$C$18 -> 0.05 | R45: =$C$18 -> 0.05 | S45: =$C$18 -> 0.05 | T45: =$C$18 -> 0.05 | U45: 1 por carro | V45: EST
A46: MP-50 | B46: O-ring NBR 70 | C46: u | D46: =2*D$26 -> 2 | E46: =2*E$26 -> 2 | F46: =2*F$26 -> 2 | G46: =2*G$26 -> 2 | H46: =2*H$26 -> 2 | I46: =2*I$26 -> 2 | J46: =2*J$26 -> 2 | K46: =2*K$26 -> 2 | ... T46: =2*T$26 -> 2 | U46: 2 por válvula; en recargas solo si se desarma | V46: EST
A47: MP-51 | B47: Pasador + precinto de seguridad numerado | C47: u | D47: 1 | E47: 1 | F47: 1 | G47: 1 | H47: 1 | I47: 1 | J47: 1 | K47: 1 | L47: 1 | M47: 1 | N47: 1 | O47: 1 | P47: 1 | Q47: 1 | R47: 1 | S47: 1 | T47: 1 | U47: 1 por terminado y por recarga | V47: EST
...

Sheet Consumo Anual
A1: CONSUMO ANUAL DE MATERIAS PRIMAS E INSUMOS 2026–2035
A2: Fórmula por celda: Σ(coef R × recipientes) + Σ(coef T × terminados) + Σ(coef C × cilindros) + Σ(coef recarga × recargas).
A5: Código | B5: Materia prima / insumo | C5: Unidad | D5: 2026 | E5: 2027 | F5: 2028 | G5: 2029 | H5: 2030 | I5: 2031 | J5: 2032 | K5: 2033 | L5: 2034 | M5: 2035 | N5: Crecimiento 2035/2028
A6: MP-01 | B6: Caño SAE 1010 c/costura Ø76,2 × 1,25 mm × 6 m (cuerpo 1 kg) | C6: barra | D6: =SUMPRODUCT('Coef Fabricacion'!$D$24:$K$24,Volumenes!$B$32:$I$32)+SUMPRODUCT('Coef Fabricacion'!$L$24:$S$24,Volumenes!$B$6:$I$6)+SUMPRODUCT('Coef Fabricacion'!$T$24:$AA$24,Volumenes!$B$19:$I$19) -> 181.69565 | E6: =SUMPRODUCT('Coef Fabricacion'!$D$24:$K$24,Volumenes!$B$33:$I$33)+SUMPRODUCT('Coef Fabricacion'!$L$24:$S$24,Volumenes!$B$7:$I$7)+SUMPRODUCT('Coef Fabricacion'!$T$24:$AA$24,Volumenes!$B$20:$I$20) -> 260.73913 | F6: =SUMPRODUCT('Coef Fabricacion'!$D$24:$K$24,Volumenes!$B$34:$I$34)+SUMPRODUCT('Coef Fabricacion'!$L$24:$S$24,Volumenes!$B$8:$I$8)+SUMPRODUCT('Coef Fabricacion'!$T$24:$AA$24,Volumenes!$B$21:$I$21) -> 631.04348 | G6: =SUMPRODUCT('Coef Fabricacion'!$D$24:$K$24,Volumenes!$B$35:$I$35)+SUMPRODUCT('Coef Fabricacion'!$L$24:$S$24,Volumenes!$B$9:$I$9)+SUMPRODUCT('Coef Fabricacion'!$T$24:$AA$24,Volumenes!$B$22:$I$22) -> 1528.7826 | H6: =SUMPRODUCT('Coef Fabricacion'!$D$24:$K$24,Volumenes!$B$36:$I$36)+SUMPRODUCT('Coef Fabricacion'!$L$24:$S$24,Volumenes!$B$10:$I$10)+SUMPRODUCT('Coef Fabricacion'!$T$24:$AA$24,Volumenes!$B$23:$I$23) -> 2700.6957 | I6: =SUMPRODUCT('Coef Fabricacion'!$D$24:$K$24,Volumenes!$B$37:$I$37)+SUMPRODUCT('Coef Fabricacion'!$L$24:$S$24,Volumenes!$B$11:$I$11)+SUMPRODUCT('Coef Fabricacion'!$T$24:$AA$24,Volumenes!$B$24:$I$24) -> 3795.6522 | J6: =SUMPRODUCT('Coef Fabricacion'!$D$24:$K$24,Volumenes!$B$38:$I$38)+SUMPRODUCT('Coef Fabricacion'!$L$24:$S$24,Volumenes!$B$12:$I$12)+SUMPRODUCT('Coef Fabricacion'!$T$24:$AA$24,Volumenes!$B$25:$I$25) -> 5290.1739 | K6: =SUMPRODUCT('Coef Fabricacion'!$D$24:$K$24,Volumenes!$B$39:$I$39)+SUMPRODUCT('Coef Fabricacion'!$L$24:$S$24,Volumenes!$B$13:$I$13)+SUMPRODUCT('Coef Fabricacion'!$T$24:$AA$24,Volumenes!$B$26:$I$26) -> 6788.3913 | L6: =SUMPRODUCT('Coef Fabricacion'!$D$24:$K$24,Volumenes!$B$40:$I$40)+SUMPRODUCT('Coef Fabricacion'!$L$24:$S$24,Volumenes!$B$14:$I$14)+SUMPRODUCT('Coef Fabricacion'!$T$24:$AA$24,Volumenes!$B$27:$I$27) -> 7625.7826 | M6: =SUMPRODUCT('Coef Fabricacion'!$D$24:$K$24,Volumenes!$B$41:$I$41)+SUMPRODUCT('Coef Fabricacion'!$L$24:$S$24,Volumenes!$B$15:$I$15)+SUMPRODUCT('Coef Fabricacion'!$T$24:$AA$24,Volumenes!$B$28:$I$28) -> 8809.6087 | N6: =IF(F6=0,"—",M6/F6) -> 13.960383
A7: MP-02 | B7: Hoja LAF 1,25 × 1220 × 2440 mm (cuerpos 2,5 kg; 27 por hoja) | C7: hoja | D7: =SUMPRODUCT('Coef Fabricacion'!$D$25:$K$25,Volumenes!$B$32:$I$32)+SUMPRODUCT('Coef Fabricacion'!$L$25:$S$25,Volumenes!$B$6:$I$6)+SUMPRODUCT('Coef Fabricacion'!$T$25:$AA$25,Volumenes!$B$19:$I$19) -> 10.925926 | E7: =SUMPRODUCT('Coef Fabricacion'!$D$25:$K$25,Volumenes!$B$33:$I$33)+SUMPRODUCT('Coef Fabricacion'!$L$25:$S$25,Volumenes!$B$7:$I$7)+SUMPRODUCT('Coef Fabricacion'!$T$25:$AA$25,Volumenes!$B$20:$I$20) -> 26.259259 | F7: =SUMPRODUCT('Coef Fabricacion'!$D$25:$K$25,Volumenes!$B$34:$I$34)+SUMPRODUCT('Coef Fabricacion'!$L$25:$S$25,Volumenes!$B$8:$I$8)+SUMPRODUCT('Coef Fabricacion'!$T$25:$AA$25,Volumenes!$B$21:$I$21) -> 47.666667 | G7: =SUMPRODUCT('Coef Fabricacion'!$D$25:$K$25,Volumenes!$B$35:$I$35)+SUMPRODUCT('Coef Fabricacion'!$L$25:$S$25,Volumenes!$B$9:$I$9)+SUMPRODUCT('Coef Fabricacion'!$T$25:$AA$25,Volumenes!$B$22:$I$22) -> 94.259259 | H7: =SUMPRODUCT('Coef Fabricacion'!$D$25:$K$25,Volumenes!$B$36:$I$36)+SUMPRODUCT('Coef Fabricacion'!$L$25:$S$25,Volumenes!$B$10:$I$10)+SUMPRODUCT('Coef Fabricacion'!$T$25:$AA$25,Volumenes!$B$23:$I$23) -> 157.22222 | I7: =SUMPRODUCT('Coef Fabricacion'!$D$25:$K$25,Volumenes!$B$37:$I$37)+SUMPRODUCT('Coef Fabricacion'!$L$25:$S$25,Volumenes!$B$11:$I$11)+SUMPRODUCT('Coef Fabricacion'!$T$25:$AA$25,Volumenes!$B$24:$I$24) -> 224.25926 | J7: =SUMPRODUCT('Coef Fabricacion'!$D$25:$K$25,Volumenes!$B$38:$I$38)+SUMPRODUCT('Coef Fabricacion'!$L$25:$S$25,Volumenes!$B$12:$I$12)+SUMPRODUCT('Coef Fabricacion'!$T$25:$AA$25,Volumenes!$B$25:$I$25) -> 298.74074 | K7: =SUMPRODUCT('Coef Fabricacion'!$D$25:$K$25,Volumenes!$B$39:$I$39)+SUMPRODUCT('Coef Fabricacion'!$L$25:$S$25,Volumenes!$B$13:$I$13)+SUMPRODUCT('Coef Fabricacion'!$T$25:$AA$25,Volumenes!$B$26:$I$26) -> 378.81481 | L7: =SUMPRODUCT('Coef Fabricacion'!$D$25:$K$25,Volumenes!$B$40:$I$40)+SUMPRODUCT('Coef Fabricacion'!$L$25:$S$25,Volumenes!$B$14:$I$14)+SUMPRODUCT('Coef Fabricacion'!$T$25:$AA$25,Volumenes!$B$27:$I$27) -> 442.07407 | M7: =SUMPRODUCT('Coef Fabricacion'!$D$25:$K$25,Volumenes!$B$41:$I$41)+SUMPRODUCT('Coef Fabricacion'!$L$25:$S$25,Volumenes!$B$15:$I$15)+SUMPRODUCT('Coef Fabricacion'!$T$25:$AA$25,Volumenes!$B$28:$I$28) -> 522 | N7: =IF(F7=0,"—",M7/F7) -> 10.951049
A8: MP-03 | B8: Hoja LAF 1,6 × 1000 × 2000 mm (cuerpos 5 kg; 12 por hoja) | C8: hoja | D8: =SUMPRODUCT('Coef Fabricacion'!$D$26:$K$26,Volumenes!$B$32:$I$32)+SUMPRODUCT('Coef Fabricacion'!$L$26:$S$26,Volumenes!$B$6:$I$6)+SUMPRODUCT('Coef Fabricacion'!$T$26:$AA$26,Volumenes!$B$19:$I$19) -> 188 | E8: =SUMPRODUCT('Coef Fabricacion'!$D$26:$K$26,Volumenes!$B$33:$I$33)+SUMPRODUCT('Coef Fabricacion'!$L$26:$S$26,Volumenes!$B$7:$I$7)+SUMPRODUCT('Coef Fabricacion'!$T$26:$AA$26,Volumenes!$B$20:$I$20) -> 320.58333 | F8: =SUMPRODUCT('Coef Fabricacion'!$D$26:$K$26,Volumenes!$B$34:$I$34)+SUMPRODUCT('Coef Fabricacion'!$L$26:$S$26,Volumenes!$B$8:$I$8)+SUMPRODUCT('Coef Fabricacion'!$T$26:$AA$26,Volumenes!$B$21:$I$21) -> 547.75 | G8: =SUMPRODUCT('Coef Fabricacion'!$D$26:$K$26,Volumenes!$B$35:$I$35)+SUMPRODUCT('Coef Fabricacion'!$L$26:$S$26,Volumenes!$B$9:$I$9)+SUMPRODUCT('Coef Fabricacion'!$T$26:$AA$26,Volumenes!$B$22:$I$22) -> 997.91667 | H8: =SUMPRODUCT('Coef Fabricacion'!$D$26:$K$26,Volumenes!$B$36:$I$36)+SUMPRODUCT('Coef Fabricacion'!$L$26:$S$26,Volumenes!$B$10:$I$10)+SUMPRODUCT('Coef Fabricacion'!$T$26:$AA$26,Volumenes!$B$23:$I$23) -> 1696.6667 | I8: =SUMPRODUCT('Coef Fabricacion'!$D$26:$K$26,Volumenes!$B$37:$I$37)+SUMPRODUCT('Coef Fabricacion'!$L$26:$S$26,Volumenes!$B$11:$I$11)+SUMPRODUCT('Coef Fabricacion'!$T$26:$AA$26,Volumenes!$B$24:$I$24) -> 2370 | J8: =SUMPRODUCT('Coef Fabricacion'!$D$26:$K$26,Volumenes!$B$38:$I$38)+SUMPRODUCT('Coef Fabricacion'!$L$26:$S$26,Volumenes!$B$12:$I$12)+SUMPRODUCT('Coef Fabricacion'!$T$26:$AA$26,Volumenes!$B$25:$I$25) -> 3203.0833 | K8: =SUMPRODUCT('Coef Fabricacion'!$D$26:$K$26,Volumenes!$B$39:$I$39)+SUMPRODUCT('Coef Fabricacion'!$L$26:$S$26,Volumenes!$B$13:$I$13)+SUMPRODUCT('Coef Fabricacion'!$T$26:$AA$26,Volumenes!$B$26:$I$26) -> 4054.25 | L8: =SUMPRODUCT('Coef Fabricacion'!$D$26:$K$26,Volumenes!$B$40:$I$40)+SUMPRODUCT('Coef Fabricacion'!$L$26:$S$26,Volumenes!$B$14:$I$14)+SUMPRODUCT('Coef Fabricacion'!$T$26:$AA$26,Volumenes!$B$27:$I$27) -> 4608.6667 | M8: =SUMPRODUCT('Coef Fabricacion'!$D$26:$K$26,Volumenes!$B$41:$I$41)+SUMPRODUCT('Coef Fabricacion'!$L$26:$S$26,Volumenes!$B$15:$I$15)+SUMPRODUCT('Coef Fabricacion'!$T$26:$AA$26,Volumenes!$B$28:$I$28) -> 5305.5 | N8: =IF(F8=0,"—",M8/F8) -> 9.6859881
A9: MP-04 | B9: Hoja LAF 2,0 × 1500 × 3000 mm (cuerpos 10 kg; 15 por hoja) | C9: hoja | D9: =SUMPRODUCT('Coef Fabricacion'!$D$27:$K$27,Volumenes!$B$32:$I$32)+SUMPRODUCT('Coef Fabricacion'!$L$27:$S$27,Volumenes!$B$6:$I$6)+SUMPRODUCT('Coef Fabricacion'!$T$27:$AA$27,Volumenes!$B$19:$I$19) -> 6.1333333 | E9: =SUMPRODUCT('Coef Fabricacion'!$D$27:$K$27,Volumenes!$B$33:$I$33)+SUMPRODUCT('Coef Fabricacion'!$L$27:$S$27,Volumenes!$B$7:$I$7)+SUMPRODUCT('Coef Fabricacion'!$T$27:$AA$27,Volumenes!$B$20:$I$20) -> 11.8 | F9: =SUMPRODUCT('Coef Fabricacion'!$D$27:$K$27,Volumenes!$B$34:$I$34)+SUMPRODUCT('Coef Fabricacion'!$L$27:$S$27,Volumenes!$B$8:$I$8)+SUMPRODUCT('Coef Fabricacion'!$T$27:$AA$27,Volumenes!$B$21:$I$21) -> 22.866667 | G9: =SUMPRODUCT('Coef Fabricacion'!$D$27:$K$27,Volumenes!$B$35:$I$35)+SUMPRODUCT('Coef Fabricacion'!$L$27:$S$27,Volumenes!$B$9:$I$9)+SUMPRODUCT('Coef Fabricacion'!$T$27:$AA$27,Volumenes!$B$22:$I$22) -> 44.866667 | H9: =SUMPRODUCT('Coef Fabricacion'!$D$27:$K$27,Volumenes!$B$36:$I$36)+SUMPRODUCT('Coef Fabricacion'!$L$27:$S$27,Volumenes!$B$10:$I$10)+SUMPRODUCT('Coef Fabricacion'!$T$27:$AA$27,Volumenes!$B$23:$I$23) -> 79.066667 | I9: =SUMPRODUCT('Coef Fabricacion'!$D$27:$K$27,Volumenes!$B$37:$I$37)+SUMPRODUCT('Coef Fabricacion'!$L$27:$S$27,Volumenes!$B$11:$I$11)+SUMPRODUCT('Coef Fabricacion'!$T$27:$AA$27,Volumenes!$B$24:$I$24) -> 114.53333 | J9: =SUMPRODUCT('Coef Fabricacion'!$D$27:$K$27,Volumenes!$B$38:$I$38)+SUMPRODUCT('Coef Fabricacion'!$L$27:$S$27,Volumenes!$B$12:$I$12)+SUMPRODUCT('Coef Fabricacion'!$T$27:$AA$27,Volumenes!$B$25:$I$25) -> 154.8 | K9: =SUMPRODUCT('Coef Fabricacion'!$D$27:$K$27,Volumenes!$B$39:$I$39)+SUMPRODUCT('Coef Fabricacion'!$L$27:$S$27,Volumenes!$B$13:$I$13)+SUMPRODUCT('Coef Fabricacion'!$T$27:$AA$27,Volumenes!$B$26:$I$26) -> 196 | L9: =SUMPRODUCT('Coef Fabricacion'!$D$27:$K$27,Volumenes!$B$40:$I$40)+SUMPRODUCT('Coef Fabricacion'!$L$27:$S$27,Volumenes!$B$14:$I$14)+SUMPRODUCT('Coef Fabricacion'!$T$27:$AA$27,Volumenes!$B$27:$I$27) -> 222.86667 | M9: =SUMPRODUCT('Coef Fabricacion'!$D$27:$K$27,Volumenes!$B$41:$I$41)+SUMPRODUCT('Coef Fabricacion'!$L$27:$S$27,Volumenes!$B$15:$I$15)+SUMPRODUCT('Coef Fabricacion'!$T$27:$AA$27,Volumenes!$B$28:$I$28) -> 256.8 | N9: =IF(F9=0,"—",M9/F9) -> 11.230321
A10: MP-05 | B10: Fleje LAF 0,9 × 114 mm (cúpula 1 kg) | C10: kg | D10: =SUMPRODUCT('Coef Fabricacion'!$D$28:$K$28,Volumenes!$B$32:$I$32)+SUMPRODUCT('Coef Fabricacion'!$L$28:$S$28,Volumenes!$B$6:$I$6)+SUMPRODUCT('Coef Fabricacion'!$T$28:$AA$28,Volumenes!$B$19:$I$19) -> 373.60473 | E10: =SUMPRODUCT('Coef Fabricacion'!$D$28:$K$28,Volumenes!$B$33:$I$33)+SUMPRODUCT('Coef Fabricacion'!$L$28:$S$28,Volumenes!$B$7:$I$7)+SUMPRODUCT('Coef Fabricacion'!$T$28:$AA$28,Volumenes!$B$20:$I$20) -> 536.13486 | F10: =SUMPRODUCT('Coef Fabricacion'!$D$28:$K$28,Volumenes!$B$34:$I$34)+SUMPRODUCT('Coef Fabricacion'!$L$28:$S$28,Volumenes!$B$8:$I$8)+SUMPRODUCT('Coef Fabricacion'!$T$28:$AA$28,Volumenes!$B$21:$I$21) -> 1297.559 | G10: =SUMPRODUCT('Coef Fabricacion'!$D$28:$K$28,Volumenes!$B$35:$I$35)+SUMPRODUCT('Coef Fabricacion'!$L$28:$S$28,Volumenes!$B$9:$I$9)+SUMPRODUCT('Coef Fabricacion'!$T$28:$AA$28,Volumenes!$B$22:$I$22) -> 3143.5007 | H10: =SUMPRODUCT('Coef Fabricacion'!$D$28:$K$28,Volumenes!$B$36:$I$36)+SUMPRODUCT('Coef Fabricacion'!$L$28:$S$28,Volumenes!$B$10:$I$10)+SUMPRODUCT('Coef Fabricacion'!$T$28:$AA$28,Volumenes!$B$23:$I$23) -> 5553.2021 | I10: =SUMPRODUCT('Coef Fabricacion'!$D$28:$K$28,Volumenes!$B$37:$I$37)+SUMPRODUCT('Coef Fabricacion'!$L$28:$S$28,Volumenes!$B$11:$I$11)+SUMPRODUCT('Coef Fabricacion'!$T$28:$AA$28,Volumenes!$B$24:$I$24) -> 7804.6645 | J10: =SUMPRODUCT('Coef Fabricacion'!$D$28:$K$28,Volumenes!$B$38:$I$38)+SUMPRODUCT('Coef Fabricacion'!$L$28:$S$28,Volumenes!$B$12:$I$12)+SUMPRODUCT('Coef Fabricacion'!$T$28:$AA$28,Volumenes!$B$25:$I$25) -> 10877.718 | K10: =SUMPRODUCT('Coef Fabricacion'!$D$28:$K$28,Volumenes!$B$39:$I$39)+SUMPRODUCT('Coef Fabricacion'!$L$28:$S$28,Volumenes!$B$13:$I$13)+SUMPRODUCT('Coef Fabricacion'!$T$28:$AA$28,Volumenes!$B$26:$I$26) -> 13958.37 | L10: =SUMPRODUCT('Coef Fabricacion'!$D$28:$K$28,Volumenes!$B$40:$I$40)+SUMPRODUCT('Coef Fabricacion'!$L$28:$S$28,Volumenes!$B$14:$I$14)+SUMPRODUCT('Coef Fabricacion'!$T$28:$AA$28,Volumenes!$B$27:$I$27) -> 15680.224 | M10: =SUMPRODUCT('Coef Fabricacion'!$D$28:$K$28,Volumenes!$B$41:$I$41)+SUMPRODUCT('Coef Fabricacion'!$L$28:$S$28,Volumenes!$B$15:$I$15)+SUMPRODUCT('Coef Fabricacion'!$T$28:$AA$28,Volumenes!$B$28:$I$28) -> 18114.421 | N10: =IF(F10=0,"—",M10/F10) -> 13.960383
A11: MP-06 | B11: Fleje LAF 1,25 × 200 mm (cúpula Ø179 + fondo Ø148, 2,5 kg) | C11: kg | D11: =SUMPRODUCT('Coef Fabricacion'!$D$29:$K$29,Volumenes!$B$32:$I$32)+SUMPRODUCT('Coef Fabricacion'!$L$29:$S$29,Volumenes!$B$6:$I$6)+SUMPRODUCT('Coef Fabricacion'!$T$29:$AA$29,Volumenes!$B$19:$I$19) -> 192.78619 | E11: =SUMPRODUCT('Coef Fabricacion'!$D$29:$K$29,Volumenes!$B$33:$I$33)+SUMPRODUCT('Coef Fabricacion'!$L$29:$S$29,Volumenes!$B$7:$I$7)+SUMPRODUCT('Coef Fabricacion'!$T$29:$AA$29,Volumenes!$B$20:$I$20) -> 463.34036 | F11: =SUMPRODUCT('Coef Fabricacion'!$D$29:$K$29,Volumenes!$B$34:$I$34)+SUMPRODUCT('Coef Fabricacion'!$L$29:$S$29,Volumenes!$B$8:$I$8)+SUMPRODUCT('Coef Fabricacion'!$T$29:$AA$29,Volumenes!$B$21:$I$21) -> 841.07059 | G11: =SUMPRODUCT('Coef Fabricacion'!$D$29:$K$29,Volumenes!$B$35:$I$35)+SUMPRODUCT('Coef Fabricacion'!$L$29:$S$29,Volumenes!$B$9:$I$9)+SUMPRODUCT('Coef Fabricacion'!$T$29:$AA$29,Volumenes!$B$22:$I$22) -> 1663.1893 | H11: =SUMPRODUCT('Coef Fabricacion'!$D$29:$K$29,Volumenes!$B$36:$I$36)+SUMPRODUCT('Coef Fabricacion'!$L$29:$S$29,Volumenes!$B$10:$I$10)+SUMPRODUCT('Coef Fabricacion'!$T$29:$AA$29,Volumenes!$B$23:$I$23) -> 2774.1606 | I11: =SUMPRODUCT('Coef Fabricacion'!$D$29:$K$29,Volumenes!$B$37:$I$37)+SUMPRODUCT('Coef Fabricacion'!$L$29:$S$29,Volumenes!$B$11:$I$11)+SUMPRODUCT('Coef Fabricacion'!$T$29:$AA$29,Volumenes!$B$24:$I$24) -> 3957.0182 | J11: =SUMPRODUCT('Coef Fabricacion'!$D$29:$K$29,Volumenes!$B$38:$I$38)+SUMPRODUCT('Coef Fabricacion'!$L$29:$S$29,Volumenes!$B$12:$I$12)+SUMPRODUCT('Coef Fabricacion'!$T$29:$AA$29,Volumenes!$B$25:$I$25) -> 5271.2318 | K11: =SUMPRODUCT('Coef Fabricacion'!$D$29:$K$29,Volumenes!$B$39:$I$39)+SUMPRODUCT('Coef Fabricacion'!$L$29:$S$29,Volumenes!$B$13:$I$13)+SUMPRODUCT('Coef Fabricacion'!$T$29:$AA$29,Volumenes!$B$26:$I$26) -> 6684.1259 | L11: =SUMPRODUCT('Coef Fabricacion'!$D$29:$K$29,Volumenes!$B$40:$I$40)+SUMPRODUCT('Coef Fabricacion'!$L$29:$S$29,Volumenes!$B$14:$I$14)+SUMPRODUCT('Coef Fabricacion'!$T$29:$AA$29,Volumenes!$B$27:$I$27) -> 7800.3252 | M11: =SUMPRODUCT('Coef Fabricacion'!$D$29:$K$29,Volumenes!$B$41:$I$41)+SUMPRODUCT('Coef Fabricacion'!$L$29:$S$29,Volumenes!$B$15:$I$15)+SUMPRODUCT('Coef Fabricacion'!$T$29:$AA$29,Volumenes!$B$28:$I$28) -> 9210.6052 | N11: =IF(F11=0,"—",M11/F11) -> 10.951049
A12: MP-07 | B12: Fleje LAF 1,6 × 250 mm (cúpula Ø221, 5 kg) | C12: kg | D12: =SUMPRODUCT('Coef Fabricacion'!$D$30:$K$30,Volumenes!$B$32:$I$32)+SUMPRODUCT('Coef Fabricacion'!$L$30:$S$30,Volumenes!$B$6:$I$6)+SUMPRODUCT('Coef Fabricacion'!$T$30:$AA$30,Volumenes!$B$19:$I$19) -> 1586.7802 | E12: =SUMPRODUCT('Coef Fabricacion'!$D$30:$K$30,Volumenes!$B$33:$I$33)+SUMPRODUCT('Coef Fabricacion'!$L$30:$S$30,Volumenes!$B$7:$I$7)+SUMPRODUCT('Coef Fabricacion'!$T$30:$AA$30,Volumenes!$B$20:$I$20) -> 2705.8259 | F12: =SUMPRODUCT('Coef Fabricacion'!$D$30:$K$30,Volumenes!$B$34:$I$34)+SUMPRODUCT('Coef Fabricacion'!$L$30:$S$30,Volumenes!$B$8:$I$8)+SUMPRODUCT('Coef Fabricacion'!$T$30:$AA$30,Volumenes!$B$21:$I$21) -> 4623.1853 | G12: =SUMPRODUCT('Coef Fabricacion'!$D$30:$K$30,Volumenes!$B$35:$I$35)+SUMPRODUCT('Coef Fabricacion'!$L$30:$S$30,Volumenes!$B$9:$I$9)+SUMPRODUCT('Coef Fabricacion'!$T$30:$AA$30,Volumenes!$B$22:$I$22) -> 8422.736 | H12: =SUMPRODUCT('Coef Fabricacion'!$D$30:$K$30,Volumenes!$B$36:$I$36)+SUMPRODUCT('Coef Fabricacion'!$L$30:$S$30,Volumenes!$B$10:$I$10)+SUMPRODUCT('Coef Fabricacion'!$T$30:$AA$30,Volumenes!$B$23:$I$23) -> 14320.41 | I12: =SUMPRODUCT('Coef Fabricacion'!$D$30:$K$30,Volumenes!$B$37:$I$37)+SUMPRODUCT('Coef Fabricacion'!$L$30:$S$30,Volumenes!$B$11:$I$11)+SUMPRODUCT('Coef Fabricacion'!$T$30:$AA$30,Volumenes!$B$24:$I$24) -> 20003.558 | J12: =SUMPRODUCT('Coef Fabricacion'!$D$30:$K$30,Volumenes!$B$38:$I$38)+SUMPRODUCT('Coef Fabricacion'!$L$30:$S$30,Volumenes!$B$12:$I$12)+SUMPRODUCT('Coef Fabricacion'!$T$30:$AA$30,Volumenes!$B$25:$I$25) -> 27035.048 | K12: =SUMPRODUCT('Coef Fabricacion'!$D$30:$K$30,Volumenes!$B$39:$I$39)+SUMPRODUCT('Coef Fabricacion'!$L$30:$S$30,Volumenes!$B$13:$I$13)+SUMPRODUCT('Coef Fabricacion'!$T$30:$AA$30,Volumenes!$B$26:$I$26) -> 34219.167 | L12: =SUMPRODUCT('Coef Fabricacion'!$D$30:$K$30,Volumenes!$B$40:$I$40)+SUMPRODUCT('Coef Fabricacion'!$L$30:$S$30,Volumenes!$B$14:$I$14)+SUMPRODUCT('Coef Fabricacion'!$T$30:$AA$30,Volumenes!$B$27:$I$27) -> 38898.621 | M12: =SUMPRODUCT('Coef Fabricacion'!$D$30:$K$30,Volumenes!$B$41:$I$41)+SUMPRODUCT('Coef Fabricacion'!$L$30:$S$30,Volumenes!$B$15:$I$15)+SUMPRODUCT('Coef Fabricacion'!$T$30:$AA$30,Volumenes!$B$28:$I$28) -> 44780.118 | N12: =IF(F12=0,"—",M12/F12) -> 9.6859881
A13: MP-08 | B13: Fleje LAF 1,6 × 200 mm (fondo Ø177, 5 kg) | C13: kg | D13: =SUMPRODUCT('Coef Fabricacion'!$D$31:$K$31,Volumenes!$B$32:$I$32)+SUMPRODUCT('Coef Fabricacion'!$L$31:$S$31,Volumenes!$B$6:$I$6)+SUMPRODUCT('Coef Fabricacion'!$T$31:$AA$31,Volumenes!$B$19:$I$19) -> 1020.073 | E13: =SUMPRODUCT('Coef Fabricacion'!$D$31:$K$31,Volumenes!$B$33:$I$33)+SUMPRODUCT('Coef Fabricacion'!$L$31:$S$31,Volumenes!$B$7:$I$7)+SUMPRODUCT('Coef Fabricacion'!$T$31:$AA$31,Volumenes!$B$20:$I$20) -> 1739.4595 | F13: =SUMPRODUCT('Coef Fabricacion'!$D$31:$K$31,Volumenes!$B$34:$I$34)+SUMPRODUCT('Coef Fabricacion'!$L$31:$S$31,Volumenes!$B$8:$I$8)+SUMPRODUCT('Coef Fabricacion'!$T$31:$AA$31,Volumenes!$B$21:$I$21) -> 2972.0477 | G13: =SUMPRODUCT('Coef Fabricacion'!$D$31:$K$31,Volumenes!$B$35:$I$35)+SUMPRODUCT('Coef Fabricacion'!$L$31:$S$31,Volumenes!$B$9:$I$9)+SUMPRODUCT('Coef Fabricacion'!$T$31:$AA$31,Volumenes!$B$22:$I$22) -> 5414.616 | H13: =SUMPRODUCT('Coef Fabricacion'!$D$31:$K$31,Volumenes!$B$36:$I$36)+SUMPRODUCT('Coef Fabricacion'!$L$31:$S$31,Volumenes!$B$10:$I$10)+SUMPRODUCT('Coef Fabricacion'!$T$31:$AA$31,Volumenes!$B$23:$I$23) -> 9205.9776 | I13: =SUMPRODUCT('Coef Fabricacion'!$D$31:$K$31,Volumenes!$B$37:$I$37)+SUMPRODUCT('Coef Fabricacion'!$L$31:$S$31,Volumenes!$B$11:$I$11)+SUMPRODUCT('Coef Fabricacion'!$T$31:$AA$31,Volumenes!$B$24:$I$24) -> 12859.43 | J13: =SUMPRODUCT('Coef Fabricacion'!$D$31:$K$31,Volumenes!$B$38:$I$38)+SUMPRODUCT('Coef Fabricacion'!$L$31:$S$31,Volumenes!$B$12:$I$12)+SUMPRODUCT('Coef Fabricacion'!$T$31:$AA$31,Volumenes!$B$25:$I$25) -> 17379.674 | K13: =SUMPRODUCT('Coef Fabricacion'!$D$31:$K$31,Volumenes!$B$39:$I$39)+SUMPRODUCT('Coef Fabricacion'!$L$31:$S$31,Volumenes!$B$13:$I$13)+SUMPRODUCT('Coef Fabricacion'!$T$31:$AA$31,Volumenes!$B$26:$I$26) -> 21998.036 | L13: =SUMPRODUCT('Coef Fabricacion'!$D$31:$K$31,Volumenes!$B$40:$I$40)+SUMPRODUCT('Coef Fabricacion'!$L$31:$S$31,Volumenes!$B$14:$I$14)+SUMPRODUCT('Coef Fabricacion'!$T$31:$AA$31,Volumenes!$B$27:$I$27) -> 25006.257 | M13: =SUMPRODUCT('Coef Fabricacion'!$D$31:$K$31,Volumenes!$B$41:$I$41)+SUMPRODUCT('Coef Fabricacion'!$L$31:$S$31,Volumenes!$B$15:$I$15)+SUMPRODUCT('Coef Fabricacion'!$T$31:$AA$31,Volumenes!$B$28:$I$28) -> 28787.219 | N13: =IF(F13=0,"—",M13/F13) -> 9.6859881
A14: MP-09 | B14: Fleje LAF 2,0 × 300 mm (cúpula Ø258, 10 kg) | C14: kg | D14: =SUMPRODUCT('Coef Fabricacion'!$D$32:$K$32,Volumenes!$B$32:$I$32)+SUMPRODUCT('Coef Fabricacion'!$L$32:$S$32,Volumenes!$B$6:$I$6)+SUMPRODUCT('Coef Fabricacion'!$T$32:$AA$32,Volumenes!$B$19:$I$19) -> 113.09652 | E14: =SUMPRODUCT('Coef Fabricacion'!$D$32:$K$32,Volumenes!$B$33:$I$33)+SUMPRODUCT('Coef Fabricacion'!$L$32:$S$32,Volumenes!$B$7:$I$7)+SUMPRODUCT('Coef Fabricacion'!$T$32:$AA$32,Volumenes!$B$20:$I$20) -> 217.58787 | F14: =SUMPRODUCT('Coef Fabricacion'!$D$32:$K$32,Volumenes!$B$34:$I$34)+SUMPRODUCT('Coef Fabricacion'!$L$32:$S$32,Volumenes!$B$8:$I$8)+SUMPRODUCT('Coef Fabricacion'!$T$32:$AA$32,Volumenes!$B$21:$I$21) -> 421.65333 | G14: =SUMPRODUCT('Coef Fabricacion'!$D$32:$K$32,Volumenes!$B$35:$I$35)+SUMPRODUCT('Coef Fabricacion'!$L$32:$S$32,Volumenes!$B$9:$I$9)+SUMPRODUCT('Coef Fabricacion'!$T$32:$AA$32,Volumenes!$B$22:$I$22) -> 827.32563 | H14: =SUMPRODUCT('Coef Fabricacion'!$D$32:$K$32,Volumenes!$B$36:$I$36)+SUMPRODUCT('Coef Fabricacion'!$L$32:$S$32,Volumenes!$B$10:$I$10)+SUMPRODUCT('Coef Fabricacion'!$T$32:$AA$32,Volumenes!$B$23:$I$23) -> 1457.9617 | I14: =SUMPRODUCT('Coef Fabricacion'!$D$32:$K$32,Volumenes!$B$37:$I$37)+SUMPRODUCT('Coef Fabricacion'!$L$32:$S$32,Volumenes!$B$11:$I$11)+SUMPRODUCT('Coef Fabricacion'!$T$32:$AA$32,Volumenes!$B$24:$I$24) -> 2111.9546 | J14: =SUMPRODUCT('Coef Fabricacion'!$D$32:$K$32,Volumenes!$B$38:$I$38)+SUMPRODUCT('Coef Fabricacion'!$L$32:$S$32,Volumenes!$B$12:$I$12)+SUMPRODUCT('Coef Fabricacion'!$T$32:$AA$32,Volumenes!$B$25:$I$25) -> 2854.4578 | K14: =SUMPRODUCT('Coef Fabricacion'!$D$32:$K$32,Volumenes!$B$39:$I$39)+SUMPRODUCT('Coef Fabricacion'!$L$32:$S$32,Volumenes!$B$13:$I$13)+SUMPRODUCT('Coef Fabricacion'!$T$32:$AA$32,Volumenes!$B$26:$I$26) -> 3614.1714 | L14: =SUMPRODUCT('Coef Fabricacion'!$D$32:$K$32,Volumenes!$B$40:$I$40)+SUMPRODUCT('Coef Fabricacion'!$L$32:$S$32,Volumenes!$B$14:$I$14)+SUMPRODUCT('Coef Fabricacion'!$T$32:$AA$32,Volumenes!$B$27:$I$27) -> 4109.5833 | M14: =SUMPRODUCT('Coef Fabricacion'!$D$32:$K$32,Volumenes!$B$41:$I$41)+SUMPRODUCT('Coef Fabricacion'!$L$32:$S$32,Volumenes!$B$15:$I$15)+SUMPRODUCT('Coef Fabricacion'!$T$32:$AA$32,Volumenes!$B$28:$I$28) -> 4735.3021 | N14: =IF(F14=0,"—",M14/F14) -> 11.230321
