Workbook

Sheet Resumen
A1: Recargas 2035 — pulmón, vehículos y transitorios
A2: FLAMA S.A. · Proyecto Final UTN-FRBA. Todo se calcula con los datos de Supuestos (celdas amarillas).
A4: 1. ¿Cuántos llegan?
A5: Recargas 2035 (u/año) | B5: ='Demanda y mix'!D23 -> 127340 | C5: Dimensionamiento_Recargas, datos_base
A6: Llegan por día — mes promedio (u/día) | B6: ='Demanda y mix'!O57 -> 530.58333 | C6: año ÷ 12 meses ÷ 20 días hábiles
A7: Llegan por día — mes pico (u/día) | B7: ='Demanda y mix'!P57 -> 594.89565
A8: Mes pico | B8: ='Demanda y mix'!B59 -> Dic
A9: Llegan en el día pico (u/día) | B9: ='Demanda y mix'!Q57 -> 684.13 | C9: mes pico × factor del día pico
A10: Llegan por turno en el día pico (u/turno) | B10: =B9/Supuestos!$B$8 -> 342.065
A12: 2. Mix entrante
A13: Familia | B13: % del total | C13: u/día promedio | D13: u/día mes pico
A14: ='Demanda y mix'!A64 -> ABC 1 kg | B14: ='Demanda y mix'!C64 -> 0.52776818 | C14: ='Demanda y mix'!D64 -> 280.025 | D14: ='Demanda y mix'!E64 -> 336.02267
A15: ='Demanda y mix'!A65 -> Manual 2,5 a 6 kg/l | B15: ='Demanda y mix'!C65 -> 0.3935684 | C15: ='Demanda y mix'!D65 -> 208.82083 | D15: ='Demanda y mix'!E65 -> 216.7124
A16: ='Demanda y mix'!A66 -> Manual 9 a 10 kg/l | B16: ='Demanda y mix'!C66 -> 0.065203392 | C16: ='Demanda y mix'!D66 -> 34.595833 | D16: ='Demanda y mix'!E66 -> 35.001636
A17: ='Demanda y mix'!A67 -> Rodante | B17: ='Demanda y mix'!C67 -> 0.013460028 | C17: ='Demanda y mix'!D67 -> 7.1416667 | D17: ='Demanda y mix'!E67 -> 7.1589454
A19: Rubro | B19: % del total | C19: u/día promedio | D19: u/día mes pico | E19: Vehículo
A20: ='Demanda y mix'!A50 -> Automotriz | B20: ='Demanda y mix'!B50/'Demanda y mix'!B57 -> 0.54949806 | C20: ='Demanda y mix'!O50 -> 291.55451 | D20: ='Demanda y mix'!P50 -> 349.86542 | E20: ='Vehículos y viajes'!B14 -> Kangoo
A21: ='Demanda y mix'!A51 -> Edificios | B21: ='Demanda y mix'!B51/'Demanda y mix'!B57 -> 0.24891499 | C21: ='Demanda y mix'!O51 -> 132.07015 | D21: ='Demanda y mix'!P51 -> 142.63576 | E21: ='Vehículos y viajes'!B15 -> Master
A22: ='Demanda y mix'!A52 -> Salud | B22: ='Demanda y mix'!B52/'Demanda y mix'!B57 -> 0.038744495 | C22: ='Demanda y mix'!O52 -> 20.557183 | D22: ='Demanda y mix'!P52 -> 19.734896 | E22: ='Vehículos y viajes'!B16 -> Master
A23: ='Demanda y mix'!A53 -> Educación | B23: ='Demanda y mix'!B53/'Demanda y mix'!B57 -> 0.073301449 | C23: ='Demanda y mix'!O53 -> 38.892527 | D23: ='Demanda y mix'!P53 -> 32.669723 | E23: ='Vehículos y viajes'!B17 -> Master
A24: ='Demanda y mix'!A54 -> Hoteles | B24: ='Demanda y mix'!B54/'Demanda y mix'!B57 -> 0.032356722 | C24: ='Demanda y mix'!O54 -> 17.167937 | D24: ='Demanda y mix'!P54 -> 20.601525 | E24: ='Vehículos y viajes'!B18 -> Master
A25: ='Demanda y mix'!A55 -> Industrias | B25: ='Demanda y mix'!B55/'Demanda y mix'!B57 -> 0.053085814 | C25: ='Demanda y mix'!O55 -> 28.166448 | D25: ='Demanda y mix'!P55 -> 27.03979 | E25: ='Vehículos y viajes'!B19 -> Master
A26: ='Demanda y mix'!A56 -> Supermercados | B26: ='Demanda y mix'!B56/'Demanda y mix'!B57 -> 0.004098464 | C26: ='Demanda y mix'!O56 -> 2.1745767 | D26: ='Demanda y mix'!P56 -> 2.3485428 | E26: ='Vehículos y viajes'!B20 -> Kangoo
A28: 3. Vehículos y viajes (dimensionado para el día pico)
A29: Kangoo Express furgón (cantidad) | B29: ='Vehículos y viajes'!E65 -> 3 | C29: autos (puntos de acopio) y supermercados
A30: Master que conviene | B30: ='Vehículos y viajes'!B50 -> Master L1H1 | C30: menos vehículos y, si empatan, la más barata
A31: Master (cantidad) | B31: ='Vehículos y viajes'!E66 -> 4 | C31: edificios, salud, educación, hoteles e industrias
A32: Viajes por día en el día pico | B32: ='Vehículos y viajes'!G67 -> 11.667618 | C32: cada viaje entrega, retira y cambia transitorios
A33: Paradas por día en el día pico | B33: ='Vehículos y viajes'!I61 -> 65.180777
A34: Inversión en vehículos (ARS, oct-2026) | B34: ='Vehículos y viajes'!H67 -> 371999455
A36: 4. Transitorios
A37: Stock recomendado (u) | B37: ='Transitorios y pulmón'!H23 -> 2646 | C37: mes pico, ciclo base, con margen
A38: Punto mínimo (u) | B38: ='Transitorios y pulmón'!I23 -> 1066 | C38: día promedio con el ciclo más corto
A39: Días que tarda en volver (base) | B39: ='Transitorios y pulmón'!B30 -> 4.0173952 | C39: proceso + espera + revisión del transitorio
A40: Revisiones y recargas extra por año (u) | B40: ='Transitorios y pulmón'!B36 -> 3436.3333
A41: … como % de las recargas 2035 | B41: ='Transitorios y pulmón'!C36 -> 0.026985498
A43: 5. Pulmón de recargas (día pico)
A44: Zona | B44: Posiciones necesarias | C44: En el plano | D44: Faltan (−) / sobran (+)
A45: ='Transitorios y pulmón'!A40 -> Recepción (R0) | B45: ='Transitorios y pulmón'!E40 -> 14 | C45: ='Transitorios y pulmón'!F40 -> 16 | D45: ='Transitorios y pulmón'!G40 -> 2
A46: ='Transitorios y pulmón'!A41 -> Despacho | B46: ='Transitorios y pulmón'!E41 -> 14 | C46: ='Transitorios y pulmón'!F41 -> 7 | D46: ='Transitorios y pulmón'!G41 -> -7
...

Sheet Supuestos
A1: Supuestos — pulmón de recargas, vehículos y transitorios (FLAMA S.A., año 2035)
A2: Celdas con fondo amarillo y texto azul: datos o supuestos que se pueden cambiar. Todo lo demás del libro se calcula solo con fórmulas.
A4: 1. Generales
A5: Dato | B5: Valor | C5: Unidad | D5: Fuente / criterio
A6: Días hábiles por mes | B6: 20 | C6: días | D6: Dimensionamiento_Recargas (parametros_recargas). Pedido: dividir por 12 y por 20.
A7: Meses por año | B7: 12 | C7: meses
A8: Turnos de logística por día | B8: 2 | C8: turnos | D8: Dos turnos: los vehículos salen a la mañana y a la tarde.
A9: Horas productivas por turno | B9: 7.5 | C9: h | D9: Dimensionamiento_Recargas: 8 h − 30 min de refrigerio.
A10: Factor del día pico dentro del mes pico | B10: 1.15 | C10: × | D10: Supuesto: variación de un día a otro (+15 %).
A12: 2. Recorrido de los vehículos
A13: Dato | B13: Valor | C13: Unidad | D13: Fuente / criterio
A14: Ida y vuelta planta ↔ zona de clientes | B14: 1.5 | C14: h por viaje | D14: Supuesto: clientes en AMBA, ~25 km promedio por tramo.
A15: Tiempo fijo por parada | B15: 20 | C15: min | D15: Supuesto: estacionar, presentarse, remito y firma.
A16: Tiempo de manejo entre paradas | B16: 15 | C16: min | D16: Supuesto.
A17: Personas en el vehículo (chofer + ayudante) | B17: 2 | C17: personas | D17: Se descuentan de la carga útil.
A18: Peso por persona | B18: 80 | C18: kg
A19: Tara de estantería, cinchas y cajones | B19: 0.1 | C19: de la carga útil | D19: Supuesto.
A20: Aprovechamiento del piso de carga | B20: 0.75 | C20: del piso | D20: Descuenta pasarruedas, pasillo de carga y ataduras.
A21: Niveles de carga (estantería con celdas) | B21: 2 | C21: niveles | D21: Manuales en 2 niveles; los rodantes ocupan toda la altura.
A23: 3. Ciclo del transitorio (días hábiles)
A24: Dato | B24: Base | C24: Mínimo | D24: Fuente / criterio
A25: Proceso en planta sin prueba hidráulica | B25: 2 | C25: 1 | D25: Supuesto: entra un día y sale al siguiente.
A26: Proceso en planta con prueba hidráulica (PH + secado) | B26: 4 | C26: 3 | D26: Supuesto.
A27: Espera en despacho hasta el recorrido | B27: 0.5 | C27: 0 | D27: Con 2 turnos sale en el turno siguiente.
A28: Revisión del transitorio cuando vuelve | B28: 1 | C28: 0.5 | D28: Control de peso, presión y precinto antes de volver a salir.
A29: Dato | B29: Valor | C29: Unidad | D29: Fuente / criterio
A30: Margen de seguridad del stock de transitorios | B30: 0.1 | C30: del stock | D30: Supuesto.
A31: Revisión o recarga anual de cada transitorio | B31: 1 | C31: veces por año | D31: Pedido: todos los años se les hace recarga o revisión.
A32: Días fuera de servicio por revisión o recarga | B32: 3 | C32: días | D32: Supuesto: pasa por el proceso como cualquier recarga.
A33: Salidas en que el cliente usa el transitorio | B33: 0.005 | C33: de las salidas | D33: Supuesto: si lo usa, vuelve para recarga.
A35: 4. Pulmón de recargas
A36: Dato | B36: Valor | C36: Unidad | D36: Fuente / criterio
A37: Días de llegada que se guardan en recepción | B37: 0.5 | C37: días | D37: Con 2 turnos en la planta, lo que trae un turno entra al proceso en el turno siguiente.
A38: Días de recargados esperando el recorrido | B38: 0.5 | C38: días | D38: Con 2 turnos salen en el turno siguiente.
A39: Factor de jaulas a medio llenar | B39: 1.15 | C39: × | D39: Las jaulas se separan por cliente y familia de agente.
A40: Jaulas vacías de reserva | B40: 0.15 | C40: de las ocupadas | D40: Supuesto.
A41: Niveles de la estantería de transitorios | B41: 3 | C41: niveles | D41: Los transitorios son stock: van en estantería (los rodantes, en el piso).
A42: Jaulas vacías apiladas por posición | B42: 2 | C42: jaulas | D42: Vacías se apilan con transpaleta manual de a 2 (o con el apilador).
A43: Posiciones de recepción en el plano actual (R0) | B43: 16 | C43: posic. 1,2 × 1,0 | D43: Plano rev 50: 9 contra el muro norte + 7 contra el muro viejo.
A44: Posiciones de despacho en el plano actual | B44: 7 | C44: posic. 1,2 × 1,0 | D44: Plano rev 50.
...

Sheet Demanda y mix
A1: Demanda 2035 y mix entrante
A2: Cuántos matafuegos llegan por año, mes y día, de qué tipo y de qué rubro.
A4: 1. Recargas 2035 por tipo y por rubro (u/año)
A5: Tipo | B5: Código | C5: Familia | D5: Recargas 2035 (u/año) | E5: % del total | F5: Automotriz | G5: Edificios | H5: Salud | I5: Educación | J5: Hoteles | K5: Industrias | L5: Supermercados | M5: Control | N5: u/día promedio | O5: u/día mes pico | P5: u/día día pico
A6: =Supuestos!A62 -> ABC 1 kg | B6: =Supuestos!B62 -> ABC-1 | C6: =Supuestos!D62 -> ABC 1 kg | D6: 67206 | E6: =D6/$D$23 -> 0.52776818 | F6: =IFERROR($D6*INDEX($B$31:$B$44,MATCH($B6,$A$31:$A$44,0))/INDEX($I$31:$I$44,MATCH($B6,$A$31:$A$44,0)),0) -> 67173.077 | G6: =IFERROR($D6*INDEX($C$31:$C$44,MATCH($B6,$A$31:$A$44,0))/INDEX($I$31:$I$44,MATCH($B6,$A$31:$A$44,0)),0) -> 0 | H6: =IFERROR($D6*INDEX($D$31:$D$44,MATCH($B6,$A$31:$A$44,0))/INDEX($I$31:$I$44,MATCH($B6,$A$31:$A$44,0)),0) -> 0 | I6: =IFERROR($D6*INDEX($E$31:$E$44,MATCH($B6,$A$31:$A$44,0))/INDEX($I$31:$I$44,MATCH($B6,$A$31:$A$44,0)),0) -> 0 | J6: =IFERROR($D6*INDEX($F$31:$F$44,MATCH($B6,$A$31:$A$44,0))/INDEX($I$31:$I$44,MATCH($B6,$A$31:$A$44,0)),0) -> 18.260158 | K6: =IFERROR($D6*INDEX($G$31:$G$44,MATCH($B6,$A$31:$A$44,0))/INDEX($I$31:$I$44,MATCH($B6,$A$31:$A$44,0)),0) -> 0 | L6: =IFERROR($D6*INDEX($H$31:$H$44,MATCH($B6,$A$31:$A$44,0))/INDEX($I$31:$I$44,MATCH($B6,$A$31:$A$44,0)),0) -> 14.662722 | M6: =SUM(F6:L6)-D6 -> 0 | N6: =D6/(Supuestos!$B$7*Supuestos!$B$6) -> 280.025 | O6: =SUMPRODUCT(F6:L6,$F$24:$L$24)/Supuestos!$B$6 -> 336.02267 | P6: =O6*Supuestos!$B$10 -> 386.42607 | Q6: ← Recargas 2035: Dimensionamiento_Recargas, hoja datos_base (127.340 u).
A7: =Supuestos!A63 -> ABC 2,5 kg | B7: =Supuestos!B63 -> ABC-2.5 | C7: =Supuestos!D63 -> Manual 2,5 a 6 kg/l | D7: 5691 | E7: =D7/$D$23 -> 0.044691377 | F7: =IFERROR($D7*INDEX($B$31:$B$44,MATCH($B7,$A$31:$A$44,0))/INDEX($I$31:$I$44,MATCH($B7,$A$31:$A$44,0)),0) -> 0 | G7: =IFERROR($D7*INDEX($C$31:$C$44,MATCH($B7,$A$31:$A$44,0))/INDEX($I$31:$I$44,MATCH($B7,$A$31:$A$44,0)),0) -> 2409.8333 | H7: =IFERROR($D7*INDEX($D$31:$D$44,MATCH($B7,$A$31:$A$44,0))/INDEX($I$31:$I$44,MATCH($B7,$A$31:$A$44,0)),0) -> 313.40556 | I7: =IFERROR($D7*INDEX($E$31:$E$44,MATCH($B7,$A$31:$A$44,0))/INDEX($I$31:$I$44,MATCH($B7,$A$31:$A$44,0)),0) -> 1171.1417 | J7: =IFERROR($D7*INDEX($F$31:$F$44,MATCH($B7,$A$31:$A$44,0))/INDEX($I$31:$I$44,MATCH($B7,$A$31:$A$44,0)),0) -> 1597.5787 | K7: =IFERROR($D7*INDEX($G$31:$G$44,MATCH($B7,$A$31:$A$44,0))/INDEX($I$31:$I$44,MATCH($B7,$A$31:$A$44,0)),0) -> 0 | L7: =IFERROR($D7*INDEX($H$31:$H$44,MATCH($B7,$A$31:$A$44,0))/INDEX($I$31:$I$44,MATCH($B7,$A$31:$A$44,0)),0) -> 199.04075 | M7: =SUM(F7:L7)-D7 -> 0 | N7: =D7/(Supuestos!$B$7*Supuestos!$B$6) -> 23.7125 | O7: =SUMPRODUCT(F7:L7,$F$24:$L$24)/Supuestos!$B$6 -> 25.080445 | P7: =O7*Supuestos!$B$10 -> 28.842512 | Q7: La tabla de la captura suma además "TOTAL CARROS" (1.427) y da 128.766: cuenta los rodantes dos veces.
A8: =Supuestos!A64 -> ABC 5 kg | B8: =Supuestos!B64 -> ABC-5 | C8: =Supuestos!D64 -> Manual 2,5 a 6 kg/l | D8: 34614 | E8: =D8/$D$23 -> 0.27182346 | F8: =IFERROR($D8*INDEX($B$31:$B$44,MATCH($B8,$A$31:$A$44,0))/INDEX($I$31:$I$44,MATCH($B8,$A$31:$A$44,0)),0) -> 2800.0062 | G8: =IFERROR($D8*INDEX($C$31:$C$44,MATCH($B8,$A$31:$A$44,0))/INDEX($I$31:$I$44,MATCH($B8,$A$31:$A$44,0)),0) -> 20119.458 | H8: =IFERROR($D8*INDEX($D$31:$D$44,MATCH($B8,$A$31:$A$44,0))/INDEX($I$31:$I$44,MATCH($B8,$A$31:$A$44,0)),0) -> 2293.2739 | I8: =IFERROR($D8*INDEX($E$31:$E$44,MATCH($B8,$A$31:$A$44,0))/INDEX($I$31:$I$44,MATCH($B8,$A$31:$A$44,0)),0) -> 4992.3336 | J8: =IFERROR($D8*INDEX($F$31:$F$44,MATCH($B8,$A$31:$A$44,0))/INDEX($I$31:$I$44,MATCH($B8,$A$31:$A$44,0)),0) -> 1057.1033 | K8: =IFERROR($D8*INDEX($G$31:$G$44,MATCH($B8,$A$31:$A$44,0))/INDEX($I$31:$I$44,MATCH($B8,$A$31:$A$44,0)),0) -> 3154.3123 | L8: =IFERROR($D8*INDEX($H$31:$H$44,MATCH($B8,$A$31:$A$44,0))/INDEX($I$31:$I$44,MATCH($B8,$A$31:$A$44,0)),0) -> 197.51207 | M8: =SUM(F8:L8)-D8 -> 0 | N8: =D8/(Supuestos!$B$7*Supuestos!$B$6) -> 144.225 | O8: =SUMPRODUCT(F8:L8,$F$24:$L$24)/Supuestos!$B$6 -> 149.97543 | P8: =O8*Supuestos!$B$10 -> 172.47174 | Q8: Reparto por rubro: cada tipo se reparte como se reparten las recargas de ese tipo en el mercado (tabla 2).
A9: =Supuestos!A65 -> ABC 10 kg | B9: =Supuestos!B65 -> ABC-10P | C9: =Supuestos!D65 -> Manual 9 a 10 kg/l | D9: 2050 | E9: =D9/$D$23 -> 0.016098634 | F9: =IFERROR($D9*INDEX($B$31:$B$44,MATCH($B9,$A$31:$A$44,0))/INDEX($I$31:$I$44,MATCH($B9,$A$31:$A$44,0)),0) -> 0 | G9: =IFERROR($D9*INDEX($C$31:$C$44,MATCH($B9,$A$31:$A$44,0))/INDEX($I$31:$I$44,MATCH($B9,$A$31:$A$44,0)),0) -> 1084.9537 | H9: =IFERROR($D9*INDEX($D$31:$D$44,MATCH($B9,$A$31:$A$44,0))/INDEX($I$31:$I$44,MATCH($B9,$A$31:$A$44,0)),0) -> 269.74811 | I9: =IFERROR($D9*INDEX($E$31:$E$44,MATCH($B9,$A$31:$A$44,0))/INDEX($I$31:$I$44,MATCH($B9,$A$31:$A$44,0)),0) -> 472.08235 | J9: =IFERROR($D9*INDEX($F$31:$F$44,MATCH($B9,$A$31:$A$44,0))/INDEX($I$31:$I$44,MATCH($B9,$A$31:$A$44,0)),0) -> 223.21587 | K9: =IFERROR($D9*INDEX($G$31:$G$44,MATCH($B9,$A$31:$A$44,0))/INDEX($I$31:$I$44,MATCH($B9,$A$31:$A$44,0)),0) -> 0 | L9: =IFERROR($D9*INDEX($H$31:$H$44,MATCH($B9,$A$31:$A$44,0))/INDEX($I$31:$I$44,MATCH($B9,$A$31:$A$44,0)),0) -> 0 | M9: =SUM(F9:L9)-D9 -> 0 | N9: =D9/(Supuestos!$B$7*Supuestos!$B$6) -> 8.5416667 | O9: =SUMPRODUCT(F9:L9,$F$24:$L$24)/Supuestos!$B$6 -> 8.7296515 | P9: =O9*Supuestos!$B$10 -> 10.039099
A10: =Supuestos!A66 -> Agua 10 l | B10: =Supuestos!B66 -> AGUA-10 | C10: =Supuestos!D66 -> Manual 9 a 10 kg/l | D10: 2893 | E10: =D10/$D$23 -> 0.022718706 | F10: =IFERROR($D10*INDEX($B$31:$B$44,MATCH($B10,$A$31:$A$44,0))/INDEX($I$31:$I$44,MATCH($B10,$A$31:$A$44,0)),0) -> 0 | G10: =IFERROR($D10*INDEX($C$31:$C$44,MATCH($B10,$A$31:$A$44,0))/INDEX($I$31:$I$44,MATCH($B10,$A$31:$A$44,0)),0) -> 1516.9691 | H10: =IFERROR($D10*INDEX($D$31:$D$44,MATCH($B10,$A$31:$A$44,0))/INDEX($I$31:$I$44,MATCH($B10,$A$31:$A$44,0)),0) -> 426.59431 | I10: =IFERROR($D10*INDEX($E$31:$E$44,MATCH($B10,$A$31:$A$44,0))/INDEX($I$31:$I$44,MATCH($B10,$A$31:$A$44,0)),0) -> 449.14442 | J10: =IFERROR($D10*INDEX($F$31:$F$44,MATCH($B10,$A$31:$A$44,0))/INDEX($I$31:$I$44,MATCH($B10,$A$31:$A$44,0)),0) -> 164.71832 | K10: =IFERROR($D10*INDEX($G$31:$G$44,MATCH($B10,$A$31:$A$44,0))/INDEX($I$31:$I$44,MATCH($B10,$A$31:$A$44,0)),0) -> 315.36844 | L10: =IFERROR($D10*INDEX($H$31:$H$44,MATCH($B10,$A$31:$A$44,0))/INDEX($I$31:$I$44,MATCH($B10,$A$31:$A$44,0)),0) -> 20.205413 | M10: =SUM(F10:L10)-D10 -> 0 | N10: =D10/(Supuestos!$B$7*Supuestos!$B$6) -> 12.054167 | O10: =SUMPRODUCT(F10:L10,$F$24:$L$24)/Supuestos!$B$6 -> 12.280733 | P10: =O10*Supuestos!$B$10 -> 14.122843
A11: =Supuestos!A67 -> AFFF 10 l | B11: =Supuestos!B67 -> AFFF-9 | C11: =Supuestos!D67 -> Manual 9 a 10 kg/l | D11: 550 | E11: =D11/$D$23 -> 0.0043191456 | F11: =IFERROR($D11*INDEX($B$31:$B$44,MATCH($B11,$A$31:$A$44,0))/INDEX($I$31:$I$44,MATCH($B11,$A$31:$A$44,0)),0) -> 0 | G11: =IFERROR($D11*INDEX($C$31:$C$44,MATCH($B11,$A$31:$A$44,0))/INDEX($I$31:$I$44,MATCH($B11,$A$31:$A$44,0)),0) -> 0 | H11: =IFERROR($D11*INDEX($D$31:$D$44,MATCH($B11,$A$31:$A$44,0))/INDEX($I$31:$I$44,MATCH($B11,$A$31:$A$44,0)),0) -> 0 | I11: =IFERROR($D11*INDEX($E$31:$E$44,MATCH($B11,$A$31:$A$44,0))/INDEX($I$31:$I$44,MATCH($B11,$A$31:$A$44,0)),0) -> 0 | J11: =IFERROR($D11*INDEX($F$31:$F$44,MATCH($B11,$A$31:$A$44,0))/INDEX($I$31:$I$44,MATCH($B11,$A$31:$A$44,0)),0) -> 0 | K11: =IFERROR($D11*INDEX($G$31:$G$44,MATCH($B11,$A$31:$A$44,0))/INDEX($I$31:$I$44,MATCH($B11,$A$31:$A$44,0)),0) -> 550 | L11: =IFERROR($D11*INDEX($H$31:$H$44,MATCH($B11,$A$31:$A$44,0))/INDEX($I$31:$I$44,MATCH($B11,$A$31:$A$44,0)),0) -> 0 | M11: =SUM(F11:L11)-D11 -> 0 | N11: =D11/(Supuestos!$B$7*Supuestos!$B$6) -> 2.2916667 | O11: =SUMPRODUCT(F11:L11,$F$24:$L$24)/Supuestos!$B$6 -> 2.2 | P11: =O11*Supuestos!$B$10 -> 2.53
A12: =Supuestos!A68 -> AFFF 50 l s/ruedas | B12: =Supuestos!B68 -> AFFF-50R | C12: =Supuestos!D68 -> Rodante | D12: 287 | E12: =D12/$D$23 -> 0.0022538087 | F12: =IFERROR($D12*INDEX($B$31:$B$44,MATCH($B12,$A$31:$A$44,0))/INDEX($I$31:$I$44,MATCH($B12,$A$31:$A$44,0)),0) -> 0 | G12: =IFERROR($D12*INDEX($C$31:$C$44,MATCH($B12,$A$31:$A$44,0))/INDEX($I$31:$I$44,MATCH($B12,$A$31:$A$44,0)),0) -> 0 | H12: =IFERROR($D12*INDEX($D$31:$D$44,MATCH($B12,$A$31:$A$44,0))/INDEX($I$31:$I$44,MATCH($B12,$A$31:$A$44,0)),0) -> 0 | I12: =IFERROR($D12*INDEX($E$31:$E$44,MATCH($B12,$A$31:$A$44,0))/INDEX($I$31:$I$44,MATCH($B12,$A$31:$A$44,0)),0) -> 0 | J12: =IFERROR($D12*INDEX($F$31:$F$44,MATCH($B12,$A$31:$A$44,0))/INDEX($I$31:$I$44,MATCH($B12,$A$31:$A$44,0)),0) -> 0 | K12: =IFERROR($D12*INDEX($G$31:$G$44,MATCH($B12,$A$31:$A$44,0))/INDEX($I$31:$I$44,MATCH($B12,$A$31:$A$44,0)),0) -> 287 | L12: =IFERROR($D12*INDEX($H$31:$H$44,MATCH($B12,$A$31:$A$44,0))/INDEX($I$31:$I$44,MATCH($B12,$A$31:$A$44,0)),0) -> 0 | M12: =SUM(F12:L12)-D12 -> 0 | N12: =D12/(Supuestos!$B$7*Supuestos!$B$6) -> 1.1958333 | O12: =SUMPRODUCT(F12:L12,$F$24:$L$24)/Supuestos!$B$6 -> 1.148 | P12: =O12*Supuestos!$B$10 -> 1.3202
A13: =Supuestos!A69 -> BC 5 kg | B13: =Supuestos!B69 -> BC-5 | C13: =Supuestos!D69 -> Manual 2,5 a 6 kg/l | D13: 165 | E13: =D13/$D$23 -> 0.0012957437 | F13: =IFERROR($D13*INDEX($B$31:$B$44,MATCH($B13,$A$31:$A$44,0))/INDEX($I$31:$I$44,MATCH($B13,$A$31:$A$44,0)),0) -> 0 | G13: =IFERROR($D13*INDEX($C$31:$C$44,MATCH($B13,$A$31:$A$44,0))/INDEX($I$31:$I$44,MATCH($B13,$A$31:$A$44,0)),0) -> 0 | H13: =IFERROR($D13*INDEX($D$31:$D$44,MATCH($B13,$A$31:$A$44,0))/INDEX($I$31:$I$44,MATCH($B13,$A$31:$A$44,0)),0) -> 0 | I13: =IFERROR($D13*INDEX($E$31:$E$44,MATCH($B13,$A$31:$A$44,0))/INDEX($I$31:$I$44,MATCH($B13,$A$31:$A$44,0)),0) -> 0 | J13: =IFERROR($D13*INDEX($F$31:$F$44,MATCH($B13,$A$31:$A$44,0))/INDEX($I$31:$I$44,MATCH($B13,$A$31:$A$44,0)),0) -> 0 | K13: =IFERROR($D13*INDEX($G$31:$G$44,MATCH($B13,$A$31:$A$44,0))/INDEX($I$31:$I$44,MATCH($B13,$A$31:$A$44,0)),0) -> 165 | L13: =IFERROR($D13*INDEX($H$31:$H$44,MATCH($B13,$A$31:$A$44,0))/INDEX($I$31:$I$44,MATCH($B13,$A$31:$A$44,0)),0) -> 0 | M13: =SUM(F13:L13)-D13 -> 0 | N13: =D13/(Supuestos!$B$7*Supuestos!$B$6) -> 0.6875 | O13: =SUMPRODUCT(F13:L13,$F$24:$L$24)/Supuestos!$B$6 -> 0.66 | P13: =O13*Supuestos!$B$10 -> 0.759
A14: =Supuestos!A70 -> Sales K 6 l | B14: =Supuestos!B70 -> SALK-6 | C14: =Supuestos!D70 -> Manual 2,5 a 6 kg/l | D14: 1427 | E14: =D14/$D$23 -> 0.01120622 | F14: =IFERROR($D14*INDEX($B$31:$B$44,MATCH($B14,$A$31:$A$44,0))/INDEX($I$31:$I$44,MATCH($B14,$A$31:$A$44,0)),0) -> 0 | G14: =IFERROR($D14*INDEX($C$31:$C$44,MATCH($B14,$A$31:$A$44,0))/INDEX($I$31:$I$44,MATCH($B14,$A$31:$A$44,0)),0) -> 444.48792 | H14: =IFERROR($D14*INDEX($D$31:$D$44,MATCH($B14,$A$31:$A$44,0))/INDEX($I$31:$I$44,MATCH($B14,$A$31:$A$44,0)),0) -> 110.47537 | I14: =IFERROR($D14*INDEX($E$31:$E$44,MATCH($B14,$A$31:$A$44,0))/INDEX($I$31:$I$44,MATCH($B14,$A$31:$A$44,0)),0) -> 339.77907 | J14: =IFERROR($D14*INDEX($F$31:$F$44,MATCH($B14,$A$31:$A$44,0))/INDEX($I$31:$I$44,MATCH($B14,$A$31:$A$44,0)),0) -> 340.69068 | K14: =IFERROR($D14*INDEX($G$31:$G$44,MATCH($B14,$A$31:$A$44,0))/INDEX($I$31:$I$44,MATCH($B14,$A$31:$A$44,0)),0) -> 191.56696 | L14: =IFERROR($D14*INDEX($H$31:$H$44,MATCH($B14,$A$31:$A$44,0))/INDEX($I$31:$I$44,MATCH($B14,$A$31:$A$44,0)),0) -> 0 | M14: =SUM(F14:L14)-D14 -> 0 | N14: =D14/(Supuestos!$B$7*Supuestos!$B$6) -> 5.9458333 | O14: =SUMPRODUCT(F14:L14,$F$24:$L$24)/Supuestos!$B$6 -> 6.1010451 | P14: =O14*Supuestos!$B$10 -> 7.0162019
A15: =Supuestos!A71 -> CO₂ 2 kg | B15: =Supuestos!B71 -> CO2-2 | C15: =Supuestos!D71 -> Manual 2,5 a 6 kg/l | D15: 7784 | E15: =D15/$D$23 -> 0.06112769 | F15: =IFERROR($D15*INDEX($B$31:$B$44,MATCH($B15,$A$31:$A$44,0))/INDEX($I$31:$I$44,MATCH($B15,$A$31:$A$44,0)),0) -> 0 | G15: =IFERROR($D15*INDEX($C$31:$C$44,MATCH($B15,$A$31:$A$44,0))/INDEX($I$31:$I$44,MATCH($B15,$A$31:$A$44,0)),0) -> 4865.2052 | H15: =IFERROR($D15*INDEX($D$31:$D$44,MATCH($B15,$A$31:$A$44,0))/INDEX($I$31:$I$44,MATCH($B15,$A$31:$A$44,0)),0) -> 498.93667 | I15: =IFERROR($D15*INDEX($E$31:$E$44,MATCH($B15,$A$31:$A$44,0))/INDEX($I$31:$I$44,MATCH($B15,$A$31:$A$44,0)),0) -> 1742.7025 | J15: =IFERROR($D15*INDEX($F$31:$F$44,MATCH($B15,$A$31:$A$44,0))/INDEX($I$31:$I$44,MATCH($B15,$A$31:$A$44,0)),0) -> 408.99369 | K15: =IFERROR($D15*INDEX($G$31:$G$44,MATCH($B15,$A$31:$A$44,0))/INDEX($I$31:$I$44,MATCH($B15,$A$31:$A$44,0)),0) -> 177.68447 | L15: =IFERROR($D15*INDEX($H$31:$H$44,MATCH($B15,$A$31:$A$44,0))/INDEX($I$31:$I$44,MATCH($B15,$A$31:$A$44,0)),0) -> 90.477447 | M15: =SUM(F15:L15)-D15 -> 0 | N15: =D15/(Supuestos!$B$7*Supuestos!$B$6) -> 32.433333 | O15: =SUMPRODUCT(F15:L15,$F$24:$L$24)/Supuestos!$B$6 -> 33.151484 | P15: =O15*Supuestos!$B$10 -> 38.124206
A16: =Supuestos!A72 -> CO₂ 5 kg | B16: =Supuestos!B72 -> CO2-5 | C16: =Supuestos!D72 -> Manual 9 a 10 kg/l | D16: 2660 | E16: =D16/$D$23 -> 0.020888959 | F16: =IFERROR($D16*INDEX($B$31:$B$44,MATCH($B16,$A$31:$A$44,0))/INDEX($I$31:$I$44,MATCH($B16,$A$31:$A$44,0)),0) -> 0 | G16: =IFERROR($D16*INDEX($C$31:$C$44,MATCH($B16,$A$31:$A$44,0))/INDEX($I$31:$I$44,MATCH($B16,$A$31:$A$44,0)),0) -> 747.89716 | H16: =IFERROR($D16*INDEX($D$31:$D$44,MATCH($B16,$A$31:$A$44,0))/INDEX($I$31:$I$44,MATCH($B16,$A$31:$A$44,0)),0) -> 605.96691 | I16: =IFERROR($D16*INDEX($E$31:$E$44,MATCH($B16,$A$31:$A$44,0))/INDEX($I$31:$I$44,MATCH($B16,$A$31:$A$44,0)),0) -> 88.358402 | J16: =IFERROR($D16*INDEX($F$31:$F$44,MATCH($B16,$A$31:$A$44,0))/INDEX($I$31:$I$44,MATCH($B16,$A$31:$A$44,0)),0) -> 221.48175 | K16: =IFERROR($D16*INDEX($G$31:$G$44,MATCH($B16,$A$31:$A$44,0))/INDEX($I$31:$I$44,MATCH($B16,$A$31:$A$44,0)),0) -> 996.29577 | L16: =IFERROR($D16*INDEX($H$31:$H$44,MATCH($B16,$A$31:$A$44,0))/INDEX($I$31:$I$44,MATCH($B16,$A$31:$A$44,0)),0) -> 0 | M16: =SUM(F16:L16)-D16 -> 0 | N16: =D16/(Supuestos!$B$7*Supuestos!$B$6) -> 11.083333 | O16: =SUMPRODUCT(F16:L16,$F$24:$L$24)/Supuestos!$B$6 -> 11.191251 | P16: =O16*Supuestos!$B$10 -> 12.869939
A17: =Supuestos!A73 -> HCFC/HFC 5 kg | B17: =Supuestos!B73 -> HCFC | C17: =Supuestos!D73 -> Manual 2,5 a 6 kg/l | D17: 436 | E17: =D17/$D$23 -> 0.0034239045 | F17: =IFERROR($D17*INDEX($B$31:$B$44,MATCH($B17,$A$31:$A$44,0))/INDEX($I$31:$I$44,MATCH($B17,$A$31:$A$44,0)),0) -> 0 | G17: =IFERROR($D17*INDEX($C$31:$C$44,MATCH($B17,$A$31:$A$44,0))/INDEX($I$31:$I$44,MATCH($B17,$A$31:$A$44,0)),0) -> 0 | H17: =IFERROR($D17*INDEX($D$31:$D$44,MATCH($B17,$A$31:$A$44,0))/INDEX($I$31:$I$44,MATCH($B17,$A$31:$A$44,0)),0) -> 136.83253 | I17: =IFERROR($D17*INDEX($E$31:$E$44,MATCH($B17,$A$31:$A$44,0))/INDEX($I$31:$I$44,MATCH($B17,$A$31:$A$44,0)),0) -> 0 | J17: =IFERROR($D17*INDEX($F$31:$F$44,MATCH($B17,$A$31:$A$44,0))/INDEX($I$31:$I$44,MATCH($B17,$A$31:$A$44,0)),0) -> 0 | K17: =IFERROR($D17*INDEX($G$31:$G$44,MATCH($B17,$A$31:$A$44,0))/INDEX($I$31:$I$44,MATCH($B17,$A$31:$A$44,0)),0) -> 299.16747 | L17: =IFERROR($D17*INDEX($H$31:$H$44,MATCH($B17,$A$31:$A$44,0))/INDEX($I$31:$I$44,MATCH($B17,$A$31:$A$44,0)),0) -> 0 | M17: =SUM(F17:L17)-D17 -> 0 | N17: =D17/(Supuestos!$B$7*Supuestos!$B$6) -> 1.8166667 | O17: =SUMPRODUCT(F17:L17,$F$24:$L$24)/Supuestos!$B$6 -> 1.744 | P17: =O17*Supuestos!$B$10 -> 2.0056
A18: =Supuestos!A74 -> Clase D 9 l | B18: =Supuestos!B74 -> CLD-10 | C18: =Supuestos!D74 -> Manual 9 a 10 kg/l | D18: 150 | E18: =D18/$D$23 -> 0.0011779488 | F18: =IFERROR($D18*INDEX($B$31:$B$44,MATCH($B18,$A$31:$A$44,0))/INDEX($I$31:$I$44,MATCH($B18,$A$31:$A$44,0)),0) -> 0 | G18: =IFERROR($D18*INDEX($C$31:$C$44,MATCH($B18,$A$31:$A$44,0))/INDEX($I$31:$I$44,MATCH($B18,$A$31:$A$44,0)),0) -> 0 | H18: =IFERROR($D18*INDEX($D$31:$D$44,MATCH($B18,$A$31:$A$44,0))/INDEX($I$31:$I$44,MATCH($B18,$A$31:$A$44,0)),0) -> 0 | I18: =IFERROR($D18*INDEX($E$31:$E$44,MATCH($B18,$A$31:$A$44,0))/INDEX($I$31:$I$44,MATCH($B18,$A$31:$A$44,0)),0) -> 0 | J18: =IFERROR($D18*INDEX($F$31:$F$44,MATCH($B18,$A$31:$A$44,0))/INDEX($I$31:$I$44,MATCH($B18,$A$31:$A$44,0)),0) -> 0 | K18: =IFERROR($D18*INDEX($G$31:$G$44,MATCH($B18,$A$31:$A$44,0))/INDEX($I$31:$I$44,MATCH($B18,$A$31:$A$44,0)),0) -> 150 | L18: =IFERROR($D18*INDEX($H$31:$H$44,MATCH($B18,$A$31:$A$44,0))/INDEX($I$31:$I$44,MATCH($B18,$A$31:$A$44,0)),0) -> 0 | M18: =SUM(F18:L18)-D18 -> 0 | N18: =D18/(Supuestos!$B$7*Supuestos!$B$6) -> 0.625 | O18: =SUMPRODUCT(F18:L18,$F$24:$L$24)/Supuestos!$B$6 -> 0.6 | P18: =O18*Supuestos!$B$10 -> 0.69
A19: =Supuestos!A75 -> ABC 25 kg s/ruedas | B19: =Supuestos!B75 -> ABC-50R | C19: =Supuestos!D75 -> Rodante | D19: 357 | E19: =D19/$D$23 -> 0.0028035181 | F19: =IFERROR($D19*INDEX($B$31:$B$44,MATCH($B19,$A$31:$A$44,0))/INDEX($I$31:$I$44,MATCH($B19,$A$31:$A$44,0)),0) -> 0 | G19: =IFERROR($D19*INDEX($C$31:$C$44,MATCH($B19,$A$31:$A$44,0))/INDEX($I$31:$I$44,MATCH($B19,$A$31:$A$44,0)),0) -> 127.09662 | H19: =IFERROR($D19*INDEX($D$31:$D$44,MATCH($B19,$A$31:$A$44,0))/INDEX($I$31:$I$44,MATCH($B19,$A$31:$A$44,0)),0) -> 69.671439 | I19: =IFERROR($D19*INDEX($E$31:$E$44,MATCH($B19,$A$31:$A$44,0))/INDEX($I$31:$I$44,MATCH($B19,$A$31:$A$44,0)),0) -> 19.679897 | J19: =IFERROR($D19*INDEX($F$31:$F$44,MATCH($B19,$A$31:$A$44,0))/INDEX($I$31:$I$44,MATCH($B19,$A$31:$A$44,0)),0) -> 22.081058 | K19: =IFERROR($D19*INDEX($G$31:$G$44,MATCH($B19,$A$31:$A$44,0))/INDEX($I$31:$I$44,MATCH($B19,$A$31:$A$44,0)),0) -> 118.47099 | L19: =IFERROR($D19*INDEX($H$31:$H$44,MATCH($B19,$A$31:$A$44,0))/INDEX($I$31:$I$44,MATCH($B19,$A$31:$A$44,0)),0) -> 0 | M19: =SUM(F19:L19)-D19 -> 0 | N19: =D19/(Supuestos!$B$7*Supuestos!$B$6) -> 1.4875 | O19: =SUMPRODUCT(F19:L19,$F$24:$L$24)/Supuestos!$B$6 -> 1.5037894 | P19: =O19*Supuestos!$B$10 -> 1.7293578
A20: =Supuestos!A76 -> ABC 50 kg s/ruedas | B20: =Supuestos!B76 -> ABC-50R | C20: =Supuestos!D76 -> Rodante | D20: 785 | E20: =D20/$D$23 -> 0.0061645987 | F20: =IFERROR($D20*INDEX($B$31:$B$44,MATCH($B20,$A$31:$A$44,0))/INDEX($I$31:$I$44,MATCH($B20,$A$31:$A$44,0)),0) -> 0 | G20: =IFERROR($D20*INDEX($C$31:$C$44,MATCH($B20,$A$31:$A$44,0))/INDEX($I$31:$I$44,MATCH($B20,$A$31:$A$44,0)),0) -> 279.47015 | H20: =IFERROR($D20*INDEX($D$31:$D$44,MATCH($B20,$A$31:$A$44,0))/INDEX($I$31:$I$44,MATCH($B20,$A$31:$A$44,0)),0) -> 153.1991 | I20: =IFERROR($D20*INDEX($E$31:$E$44,MATCH($B20,$A$31:$A$44,0))/INDEX($I$31:$I$44,MATCH($B20,$A$31:$A$44,0)),0) -> 43.273724 | J20: =IFERROR($D20*INDEX($F$31:$F$44,MATCH($B20,$A$31:$A$44,0))/INDEX($I$31:$I$44,MATCH($B20,$A$31:$A$44,0)),0) -> 48.553586 | K20: =IFERROR($D20*INDEX($G$31:$G$44,MATCH($B20,$A$31:$A$44,0))/INDEX($I$31:$I$44,MATCH($B20,$A$31:$A$44,0)),0) -> 260.50344 | L20: =IFERROR($D20*INDEX($H$31:$H$44,MATCH($B20,$A$31:$A$44,0))/INDEX($I$31:$I$44,MATCH($B20,$A$31:$A$44,0)),0) -> 0 | M20: =SUM(F20:L20)-D20 -> 0 | N20: =D20/(Supuestos!$B$7*Supuestos!$B$6) -> 3.2708333 | O20: =SUMPRODUCT(F20:L20,$F$24:$L$24)/Supuestos!$B$6 -> 3.3066518 | P20: =O20*Supuestos!$B$10 -> 3.8026496
... A22: =Supuestos!A78 -> ABC 100 kg s/ruedas | B22: =Supuestos!B78 -> ABC-50R | C22: =Supuestos!D78 -> Rodante | D22: 114 | E22: =D22/$D$23 -> 0.00089524109 | F22: =IFERROR($D22*INDEX($B$31:$B$44,MATCH($B22,$A$31:$A$44,0))/INDEX($I$31:$I$44,MATCH($B22,$A$31:$A$44,0)),0) -> 0 | G22: =IFERROR($D22*INDEX($C$31:$C$44,MATCH($B22,$A$31:$A$44,0))/INDEX($I$31:$I$44,MATCH($B22,$A$31:$A$44,0)),0) -> 40.585474 | H22: =IFERROR($D22*INDEX($D$31:$D$44,MATCH($B22,$A$31:$A$44,0))/INDEX($I$31:$I$44,MATCH($B22,$A$31:$A$44,0)),0) -> 22.248023 | I22: =IFERROR($D22*INDEX($E$31:$E$44,MATCH($B22,$A$31:$A$44,0))/INDEX($I$31:$I$44,MATCH($B22,$A$31:$A$44,0)),0) -> 6.2843369 | J22: =IFERROR($D22*INDEX($F$31:$F$44,MATCH($B22,$A$31:$A$44,0))/INDEX($I$31:$I$44,MATCH($B22,$A$31:$A$44,0)),0) -> 7.051094 | K22: =IFERROR($D22*INDEX($G$31:$G$44,MATCH($B22,$A$31:$A$44,0))/INDEX($I$31:$I$44,MATCH($B22,$A$31:$A$44,0)),0) -> 37.831072 | L22: =IFERROR($D22*INDEX($H$31:$H$44,MATCH($B22,$A$31:$A$44,0))/INDEX($I$31:$I$44,MATCH($B22,$A$31:$A$44,0)),0) -> 0 | M22: =SUM(F22:L22)-D22 -> 0 | N22: =D22/(Supuestos!$B$7*Supuestos!$B$6) -> 0.475 | O22: =SUMPRODUCT(F22:L22,$F$24:$L$24)/Supuestos!$B$6 -> 0.48020166 | P22: =O22*Supuestos!$B$10 -> 0.55223191
A23: Total | D23: =SUM(D6:D22) -> 127340 | E23: =SUM(E6:E22) -> 1 | F23: =SUM(F6:F22) -> 69973.083 | G23: =SUM(G6:G22) -> 31696.835 | H23: =SUM(H6:H22) -> 4933.724 | I23: =SUM(I6:I22) -> 9334.2065 | J23: =SUM(J6:J22) -> 4120.3049 | K23: =SUM(K6:K22) -> 6759.9476 | ... P23: =SUM(P6:P22) -> 684.13
A24: Estacionalidad del mes pico | F24: =INDEX(Supuestos!$B$96:$M$102,MATCH(F$5,Supuestos!$A$96:$A$102,0),$C$59) -> 0.1 | G24: =INDEX(Supuestos!$B$96:$M$102,MATCH(G$5,Supuestos!$A$96:$A$102,0),$C$59) -> 0.09 | H24: =INDEX(Supuestos!$B$96:$M$102,MATCH(H$5,Supuestos!$A$96:$A$102,0),$C$59) -> 0.08 | I24: =INDEX(Supuestos!$B$96:$M$102,MATCH(I$5,Supuestos!$A$96:$A$102,0),$C$59) -> 0.07 | J24: =INDEX(Supuestos!$B$96:$M$102,MATCH(J$5,Supuestos!$A$96:$A$102,0),$C$59) -> 0.1 | K24: =INDEX(Supuestos!$B$96:$M$102,MATCH(K$5,Supuestos!$A$96:$A$102,0),$C$59) -> 0.08 | L24: =INDEX(Supuestos!$B$96:$M$102,MATCH(L$5,Supuestos!$A$96:$A$102,0),$C$59) -> 0.09
A25: % con transitorio | F25: =INDEX(Supuestos!$D$84:$D$90,MATCH(F$5,Supuestos!$A$84:$A$90,0)) -> 1 | G25: =INDEX(Supuestos!$D$84:$D$90,MATCH(G$5,Supuestos!$A$84:$A$90,0)) -> 1 | H25: =INDEX(Supuestos!$D$84:$D$90,MATCH(H$5,Supuestos!$A$84:$A$90,0)) -> 0.9 | I25: =INDEX(Supuestos!$D$84:$D$90,MATCH(I$5,Supuestos!$A$84:$A$90,0)) -> 1 | J25: =INDEX(Supuestos!$D$84:$D$90,MATCH(J$5,Supuestos!$A$84:$A$90,0)) -> 1 | K25: =INDEX(Supuestos!$D$84:$D$90,MATCH(K$5,Supuestos!$A$84:$A$90,0)) -> 0.8 | L25: =INDEX(Supuestos!$D$84:$D$90,MATCH(L$5,Supuestos!$A$84:$A$90,0)) -> 1
A29: 2. Mercado argentino de recargas por rubro y tipo (u/año) — CONSOLIDADO_24
A30: Código | B30: Automotriz | C30: Edificios | D30: Salud | E30: Educación | F30: Hoteles | G30: Industrias | H30: Supermercados | I30: Total
A31: ABC-1 | B31: 6890147 | C31: 0 | D31: 0 | E31: 0 | F31: 1873 | G31: 0 | H31: 1504 | I31: =SUM(B31:H31) -> 6893524 | J31: ← Suma de la columna RECARGAS de cada hoja de rubro de CONSOLIDADO_24 (industrias incluye almacenes;
A32: ABC-2.5 | B32: 0 | C32: 209661 | D32: 27267 | E32: 101892 | F32: 138993 | G32: 0 | H32: 17317 | I32: =SUM(B32:H32) -> 495130 | J32: supermercados incluye góndola; hoteles incluye alquiler temporario). Los rodantes del mercado vienen
A33: ABC-5 | B33: 212830 | C33: 1529291 | D33: 174313 | E33: 379470 | F33: 80351 | G33: 239761 | H33: 15013 | I33: =SUM(B33:H33) -> 2631029 | J33: todos como ABC 50 kg: los de 25, 70 y 100 kg se reparten igual.
A34: ABC-10P | B34: 0 | C34: 93731 | D34: 23304 | E34: 40784 | F34: 19284 | G34: 0 | H34: 0 | I34: =SUM(B34:H34) -> 177103
A35: AGUA-10 | B35: 0 | C35: 118397 | D35: 33295 | E35: 35055 | F35: 12856 | G35: 24614 | H35: 1577 | I35: =SUM(B35:H35) -> 225794
A36: AFFF-9 | B36: 0 | C36: 0 | D36: 0 | E36: 0 | F36: 0 | G36: 33670 | H36: 0 | I36: =SUM(B36:H36) -> 33670
A37: AFFF-50R | B37: 0 | C37: 0 | D37: 0 | E37: 0 | F37: 0 | G37: 18051 | H37: 0 | I37: =SUM(B37:H37) -> 18051
A38: BC-5 | B38: 0 | C38: 0 | D38: 0 | E38: 0 | F38: 0 | G38: 9854 | H38: 0 | I38: =SUM(B38:H38) -> 9854
A39: SALK-6 | B39: 0 | C39: 41932 | D39: 10422 | E39: 32054 | F39: 32140 | G39: 18072 | H39: 0 | I39: =SUM(B39:H39) -> 134620
A40: CO2-2 | B40: 0 | C40: 382323 | D40: 39208 | E40: 136947 | F40: 32140 | G40: 13963 | H40: 7110 | I40: =SUM(B40:H40) -> 611691
A41: CO2-5 | B41: 0 | C41: 54265 | D41: 43967 | E41: 6411 | F41: 16070 | G41: 72288 | H41: 0 | I41: =SUM(B41:H41) -> 193001
A42: HCFC | B42: 0 | C42: 0 | D42: 9014 | E42: 0 | F42: 0 | G42: 19708 | H42: 0 | I42: =SUM(B42:H42) -> 28722
A43: CLD-10 | B43: 0 | C43: 0 | D43: 0 | E43: 0 | F43: 0 | G43: 8218 | H43: 0 | I43: =SUM(B43:H43) -> 8218
A44: ABC-50R | B44: 0 | C44: 36999 | D44: 20282 | E44: 5729 | F44: 6428 | G44: 34488 | H44: 0 | I44: =SUM(B44:H44) -> 103926
A45: Total | B45: =SUM(B31:B44) -> 7102977 | C45: =SUM(C31:C44) -> 2466599 | D45: =SUM(D31:D44) -> 381072 | E45: =SUM(E31:E44) -> 738342 | F45: =SUM(F31:F44) -> 340135 | G45: =SUM(G31:G44) -> 492687 | H45: =SUM(H31:H44) -> 42521 | I45: =SUM(I31:I44) -> 11564333
...

Sheet Vehículos y viajes
A1: Vehículos y viajes
A2: Cada viaje sale con recargados + transitorios para dejar y vuelve con los del cliente + los transitorios que retira. En cada turno el vehículo hace su recorrido y vuelve cargado.
A4: 1. Capacidad de cada vehículo
A5: Dato | B5: Kangoo Express | C5: Master L1H1 | D5: Master L2H2 | E5: Master L3H2 | F5: Cómo se calcula
A6: Piso útil (m²) | B6: =Supuestos!$B$50*Supuestos!$B$51*Supuestos!$B$20 -> 1.6206 | C6: =Supuestos!$C$50*Supuestos!$C$51*Supuestos!$B$20 -> 3.4192463 | D6: =Supuestos!$D$50*Supuestos!$D$51*Supuestos!$B$20 -> 4.0811212 | E6: =Supuestos!$E$50*Supuestos!$E$51*Supuestos!$B$20 -> 4.9415588 | F6: largo × ancho × aprovechamiento
A7: Carga neta disponible (kg) | B7: =(Supuestos!$B$54-Supuestos!$B$17*Supuestos!$B$18)*(1-Supuestos!$B$19) -> 531 | C7: =(Supuestos!$C$54-Supuestos!$B$17*Supuestos!$B$18)*(1-Supuestos!$B$19) -> 1225.8 | D7: =(Supuestos!$D$54-Supuestos!$B$17*Supuestos!$B$18)*(1-Supuestos!$B$19) -> 1161.9 | E7: =(Supuestos!$E$54-Supuestos!$B$17*Supuestos!$B$18)*(1-Supuestos!$B$19) -> 1093.5 | F7: (carga útil − personas) × (1 − tara)
A8: Volumen nominal (m³) | B8: =Supuestos!$B$53 -> 3.3 | C8: =Supuestos!$C$53 -> 8 | D8: =Supuestos!$D$53 -> 10.8 | E8: =Supuestos!$E$53 -> 13 | F8: dato de Renault
A9: Precio actual (ARS) | B9: =Supuestos!$B$57 -> 33626485 | C9: =Supuestos!$C$57 -> 67780000 | D9: =Supuestos!$D$57 -> 73883676 | E9: =Supuestos!$E$57 -> 78322536 | F9: ver Supuestos
A10: Lleva rodantes | B10: =IF(Supuestos!$B$55=1,"Sí","No") -> No | C10: =IF(Supuestos!$C$55=1,"Sí","No") -> Sí | D10: =IF(Supuestos!$D$55=1,"Sí","No") -> Sí | E10: =IF(Supuestos!$E$55=1,"Sí","No") -> Sí
A12: 2. Datos de cada rubro para el recorrido
A13: Rubro | B13: Vehículo | C13: u/día promedio | D13: u/día pico | E13: % con transitorio | F13: u. por cliente | G13: min por u. | H13: Peso medio (kg/u) | I13: m² de piso por u. | J13: h por u. del cliente | K13: u. del cliente por turno (límite de tiempo)
A14: Automotriz | B14: =INDEX(Supuestos!$B$84:$B$90,MATCH($A14,Supuestos!$A$84:$A$90,0)) -> Kangoo | C14: ='Demanda y mix'!O50 -> 291.55451 | D14: ='Demanda y mix'!Q50 -> 402.34523 | E14: =INDEX(Supuestos!$D$84:$D$90,MATCH($A14,Supuestos!$A$84:$A$90,0)) -> 1 | F14: =INDEX(Supuestos!$C$84:$C$90,MATCH($A14,Supuestos!$A$84:$A$90,0)) -> 25 | G14: =INDEX(Supuestos!$E$84:$E$90,MATCH($A14,Supuestos!$A$84:$A$90,0)) -> 0.5 | H14: ='Demanda y mix'!R50 -> 2.2601006 | I14: ='Demanda y mix'!S50 -> 0.0090002579 | J14: =2/F14*(Supuestos!$B$15+Supuestos!$B$16)/60+2*G14/60 -> 0.063333333 | K14: =(Supuestos!$B$9-Supuestos!$B$14)/J14 -> 94.736842
A15: Edificios | B15: =INDEX(Supuestos!$B$84:$B$90,MATCH($A15,Supuestos!$A$84:$A$90,0)) -> Master | C15: ='Demanda y mix'!O51 -> 132.07015 | D15: ='Demanda y mix'!Q51 -> 164.03112 | E15: =INDEX(Supuestos!$D$84:$D$90,MATCH($A15,Supuestos!$A$84:$A$90,0)) -> 1 | F15: =INDEX(Supuestos!$C$84:$C$90,MATCH($A15,Supuestos!$A$84:$A$90,0)) -> 14 | G15: =INDEX(Supuestos!$E$84:$E$90,MATCH($A15,Supuestos!$A$84:$A$90,0)) -> 1.5 | H15: ='Demanda y mix'!R51 -> 9.9521135 | I15: ='Demanda y mix'!S51 -> 0.03424888 | J15: =2/F15*(Supuestos!$B$15+Supuestos!$B$16)/60+2*G15/60 -> 0.13333333 | K15: =(Supuestos!$B$9-Supuestos!$B$14)/J15 -> 45
A16: Salud | B16: =INDEX(Supuestos!$B$84:$B$90,MATCH($A16,Supuestos!$A$84:$A$90,0)) -> Master | C16: ='Demanda y mix'!O52 -> 20.557183 | D16: ='Demanda y mix'!Q52 -> 22.69513 | E16: =INDEX(Supuestos!$D$84:$D$90,MATCH($A16,Supuestos!$A$84:$A$90,0)) -> 0.9 | F16: =INDEX(Supuestos!$C$84:$C$90,MATCH($A16,Supuestos!$A$84:$A$90,0)) -> 35 | G16: =INDEX(Supuestos!$E$84:$E$90,MATCH($A16,Supuestos!$A$84:$A$90,0)) -> 1.5 | H16: ='Demanda y mix'!R52 -> 14.390407 | I16: ='Demanda y mix'!S52 -> 0.059005024 | J16: =2/F16*(Supuestos!$B$15+Supuestos!$B$16)/60+2*G16/60 -> 0.083333333 | K16: =(Supuestos!$B$9-Supuestos!$B$14)/J16 -> 72
A17: Educación | B17: =INDEX(Supuestos!$B$84:$B$90,MATCH($A17,Supuestos!$A$84:$A$90,0)) -> Master | C17: ='Demanda y mix'!O53 -> 38.892527 | D17: ='Demanda y mix'!Q53 -> 37.570181 | E17: =INDEX(Supuestos!$D$84:$D$90,MATCH($A17,Supuestos!$A$84:$A$90,0)) -> 1 | F17: =INDEX(Supuestos!$C$84:$C$90,MATCH($A17,Supuestos!$A$84:$A$90,0)) -> 18 | G17: =INDEX(Supuestos!$E$84:$E$90,MATCH($A17,Supuestos!$A$84:$A$90,0)) -> 1.5 | H17: ='Demanda y mix'!R53 -> 9.1720953 | I17: ='Demanda y mix'!S53 -> 0.029730289 | J17: =2/F17*(Supuestos!$B$15+Supuestos!$B$16)/60+2*G17/60 -> 0.11481481 | K17: =(Supuestos!$B$9-Supuestos!$B$14)/J17 -> 52.258065
A18: Hoteles | B18: =INDEX(Supuestos!$B$84:$B$90,MATCH($A18,Supuestos!$A$84:$A$90,0)) -> Master | C18: ='Demanda y mix'!O54 -> 17.167937 | D18: ='Demanda y mix'!Q54 -> 23.691753 | E18: =INDEX(Supuestos!$D$84:$D$90,MATCH($A18,Supuestos!$A$84:$A$90,0)) -> 1 | F18: =INDEX(Supuestos!$C$84:$C$90,MATCH($A18,Supuestos!$A$84:$A$90,0)) -> 20 | G18: =INDEX(Supuestos!$E$84:$E$90,MATCH($A18,Supuestos!$A$84:$A$90,0)) -> 1.5 | H18: ='Demanda y mix'!R54 -> 9.6298779 | I18: ='Demanda y mix'!S54 -> 0.036622478 | J18: =2/F18*(Supuestos!$B$15+Supuestos!$B$16)/60+2*G18/60 -> 0.10833333 | K18: =(Supuestos!$B$9-Supuestos!$B$14)/J18 -> 55.384615
A19: Industrias | B19: =INDEX(Supuestos!$B$84:$B$90,MATCH($A19,Supuestos!$A$84:$A$90,0)) -> Master | C19: ='Demanda y mix'!O55 -> 28.166448 | D19: ='Demanda y mix'!Q55 -> 31.095759 | E19: =INDEX(Supuestos!$D$84:$D$90,MATCH($A19,Supuestos!$A$84:$A$90,0)) -> 0.8 | F19: =INDEX(Supuestos!$C$84:$C$90,MATCH($A19,Supuestos!$A$84:$A$90,0)) -> 45 | G19: =INDEX(Supuestos!$E$84:$E$90,MATCH($A19,Supuestos!$A$84:$A$90,0)) -> 1.5 | H19: ='Demanda y mix'!R55 -> 19.50757 | I19: ='Demanda y mix'!S55 -> 0.092169885 | J19: =2/F19*(Supuestos!$B$15+Supuestos!$B$16)/60+2*G19/60 -> 0.075925926 | K19: =(Supuestos!$B$9-Supuestos!$B$14)/J19 -> 79.02439
A20: Supermercados | B20: =INDEX(Supuestos!$B$84:$B$90,MATCH($A20,Supuestos!$A$84:$A$90,0)) -> Kangoo | C20: ='Demanda y mix'!O56 -> 2.1745767 | D20: ='Demanda y mix'!Q56 -> 2.7008242 | E20: =INDEX(Supuestos!$D$84:$D$90,MATCH($A20,Supuestos!$A$84:$A$90,0)) -> 1 | F20: =INDEX(Supuestos!$C$84:$C$90,MATCH($A20,Supuestos!$A$84:$A$90,0)) -> 16 | G20: =INDEX(Supuestos!$E$84:$E$90,MATCH($A20,Supuestos!$A$84:$A$90,0)) -> 1 | H20: ='Demanda y mix'!R56 -> 6.7447597 | I20: ='Demanda y mix'!S56 -> 0.022241988 | J20: =2/F20*(Supuestos!$B$15+Supuestos!$B$16)/60+2*G20/60 -> 0.10625 | K20: =(Supuestos!$B$9-Supuestos!$B$14)/J20 -> 56.470588
A21: h por u. del cliente = 2 paradas cada "u. por cliente" (una para retirar y otra para entregar) × (parada + manejo) + 2 manipulaciones por u. (retiro con transitorio y entrega).
A23: 3. Carga por viaje (u. en cada sentido, recargados o del cliente + transitorios) — el menor entre espacio y peso
A24: Rubro | B24: Kangoo Express | C24: Master L1H1 | D24: Master L2H2 | E24: Master L3H2
A25: Automotriz | B25: =MIN(B$6/$I14,B$7/$H14) -> 180.06151 | C25: =MIN(C$6/$I14,C$7/$H14) -> 379.90536 | D25: =MIN(D$6/$I14,D$7/$H14) -> 453.44492 | E25: =MIN(E$6/$I14,E$7/$H14) -> 483.82802 | F25: ← espacio: piso útil / m² por u. (2 niveles; los rodantes ocupan toda la altura)
A26: Edificios | B26: =MIN(B$6/$I15,B$7/$H15) -> 47.318335 | C26: =MIN(C$6/$I15,C$7/$H15) -> 99.835271 | D26: =MIN(D$6/$I15,D$7/$H15) -> 116.74907 | E26: =MIN(E$6/$I15,E$7/$H15) -> 109.87616 | F26: peso: carga neta / peso medio del mix del rubro
A27: Salud | B27: =MIN(B$6/$I16,B$7/$H16) -> 27.465458 | C27: =MIN(C$6/$I16,C$7/$H16) -> 57.948392 | D27: =MIN(D$6/$I16,D$7/$H16) -> 69.165657 | E27: =MIN(E$6/$I16,E$7/$H16) -> 75.988121
A28: Educación | B28: =MIN(B$6/$I17,B$7/$H17) -> 54.510066 | C28: =MIN(C$6/$I17,C$7/$H17) -> 115.00885 | D28: =MIN(D$6/$I17,D$7/$H17) -> 126.67771 | E28: =MIN(E$6/$I17,E$7/$H17) -> 119.22031
A29: Hoteles | B29: =MIN(B$6/$I18,B$7/$H18) -> 44.251511 | C29: =MIN(C$6/$I18,C$7/$H18) -> 93.364688 | D29: =MIN(D$6/$I18,D$7/$H18) -> 111.4376 | E29: =MIN(E$6/$I18,E$7/$H18) -> 113.55284
A30: Industrias | B30: =MIN(B$6/$I19,B$7/$H19) -> 17.582749 | C30: =MIN(C$6/$I19,C$7/$H19) -> 37.097217 | D30: =MIN(D$6/$I19,D$7/$H19) -> 44.27825 | E30: =MIN(E$6/$I19,E$7/$H19) -> 53.613593
A31: Supermercados | B31: =MIN(B$6/$I20,B$7/$H20) -> 72.862192 | C31: =MIN(C$6/$I20,C$7/$H20) -> 153.72934 | D31: =MIN(D$6/$I20,D$7/$H20) -> 172.26707 | E31: =MIN(E$6/$I20,E$7/$H20) -> 162.12586
A33: 4. Matafuegos del cliente que mueve un vehículo en un turno
A34: Rubro | B34: Kangoo Express | C34: Master L1H1 | D34: Master L2H2 | E34: Master L3H2 | F34: Viajes por turno (Kangoo) | G34: Viajes por turno (L1H1) | H34: Viajes por turno (L2H2) | I34: Viajes por turno (L3H2)
A35: Automotriz | B35: =IF(B25/(1+$E14)>=$K14,$K14,B25/(1+$E14)*F35) -> 90.030753 | C35: =IF(C25/(1+$E14)>=$K14,$K14,C25/(1+$E14)*G35) -> 94.736842 | D35: =IF(D25/(1+$E14)>=$K14,$K14,D25/(1+$E14)*H35) -> 94.736842 | E35: =IF(E25/(1+$E14)>=$K14,$K14,E25/(1+$E14)*I35) -> 94.736842 | F35: =IF(B25/(1+$E14)>=$K14,1,MAX(1,INT(Supuestos!$B$9/(Supuestos!$B$14+B25/(1+$E14)*$J14)))) -> 1 | G35: =IF(C25/(1+$E14)>=$K14,1,MAX(1,INT(Supuestos!$B$9/(Supuestos!$B$14+C25/(1+$E14)*$J14)))) -> 1 | H35: =IF(D25/(1+$E14)>=$K14,1,MAX(1,INT(Supuestos!$B$9/(Supuestos!$B$14+D25/(1+$E14)*$J14)))) -> 1 | I35: =IF(E25/(1+$E14)>=$K14,1,MAX(1,INT(Supuestos!$B$9/(Supuestos!$B$14+E25/(1+$E14)*$J14)))) -> 1
A36: Edificios | B36: =IF(B26/(1+$E15)>=$K15,$K15,B26/(1+$E15)*F36) -> 23.659168 | C36: =IF(C26/(1+$E15)>=$K15,$K15,C26/(1+$E15)*G36) -> 45 | D36: =IF(D26/(1+$E15)>=$K15,$K15,D26/(1+$E15)*H36) -> 45 | E36: =IF(E26/(1+$E15)>=$K15,$K15,E26/(1+$E15)*I36) -> 45 | F36: =IF(B26/(1+$E15)>=$K15,1,MAX(1,INT(Supuestos!$B$9/(Supuestos!$B$14+B26/(1+$E15)*$J15)))) -> 1 | G36: =IF(C26/(1+$E15)>=$K15,1,MAX(1,INT(Supuestos!$B$9/(Supuestos!$B$14+C26/(1+$E15)*$J15)))) -> 1 | H36: =IF(D26/(1+$E15)>=$K15,1,MAX(1,INT(Supuestos!$B$9/(Supuestos!$B$14+D26/(1+$E15)*$J15)))) -> 1 | I36: =IF(E26/(1+$E15)>=$K15,1,MAX(1,INT(Supuestos!$B$9/(Supuestos!$B$14+E26/(1+$E15)*$J15)))) -> 1
A37: Salud | B37: =IF(B27/(1+$E16)>=$K16,$K16,B27/(1+$E16)*F37) -> 28.911008 | C37: =IF(C27/(1+$E16)>=$K16,$K16,C27/(1+$E16)*G37) -> 30.499154 | D37: =IF(D27/(1+$E16)>=$K16,$K16,D27/(1+$E16)*H37) -> 36.402978 | E37: =IF(E27/(1+$E16)>=$K16,$K16,E27/(1+$E16)*I37) -> 39.993748 | F37: =IF(B27/(1+$E16)>=$K16,1,MAX(1,INT(Supuestos!$B$9/(Supuestos!$B$14+B27/(1+$E16)*$J16)))) -> 2 | G37: =IF(C27/(1+$E16)>=$K16,1,MAX(1,INT(Supuestos!$B$9/(Supuestos!$B$14+C27/(1+$E16)*$J16)))) -> 1 | H37: =IF(D27/(1+$E16)>=$K16,1,MAX(1,INT(Supuestos!$B$9/(Supuestos!$B$14+D27/(1+$E16)*$J16)))) -> 1 | I37: =IF(E27/(1+$E16)>=$K16,1,MAX(1,INT(Supuestos!$B$9/(Supuestos!$B$14+E27/(1+$E16)*$J16)))) -> 1
A38: Educación | B38: =IF(B28/(1+$E17)>=$K17,$K17,B28/(1+$E17)*F38) -> 27.255033 | C38: =IF(C28/(1+$E17)>=$K17,$K17,C28/(1+$E17)*G38) -> 52.258065 | D38: =IF(D28/(1+$E17)>=$K17,$K17,D28/(1+$E17)*H38) -> 52.258065 | E38: =IF(E28/(1+$E17)>=$K17,$K17,E28/(1+$E17)*I38) -> 52.258065 | F38: =IF(B28/(1+$E17)>=$K17,1,MAX(1,INT(Supuestos!$B$9/(Supuestos!$B$14+B28/(1+$E17)*$J17)))) -> 1 | G38: =IF(C28/(1+$E17)>=$K17,1,MAX(1,INT(Supuestos!$B$9/(Supuestos!$B$14+C28/(1+$E17)*$J17)))) -> 1 | H38: =IF(D28/(1+$E17)>=$K17,1,MAX(1,INT(Supuestos!$B$9/(Supuestos!$B$14+D28/(1+$E17)*$J17)))) -> 1 | I38: =IF(E28/(1+$E17)>=$K17,1,MAX(1,INT(Supuestos!$B$9/(Supuestos!$B$14+E28/(1+$E17)*$J17)))) -> 1
A39: Hoteles | B39: =IF(B29/(1+$E18)>=$K18,$K18,B29/(1+$E18)*F39) -> 22.125756 | C39: =IF(C29/(1+$E18)>=$K18,$K18,C29/(1+$E18)*G39) -> 46.682344 | D39: =IF(D29/(1+$E18)>=$K18,$K18,D29/(1+$E18)*H39) -> 55.384615 | E39: =IF(E29/(1+$E18)>=$K18,$K18,E29/(1+$E18)*I39) -> 55.384615 | F39: =IF(B29/(1+$E18)>=$K18,1,MAX(1,INT(Supuestos!$B$9/(Supuestos!$B$14+B29/(1+$E18)*$J18)))) -> 1 | G39: =IF(C29/(1+$E18)>=$K18,1,MAX(1,INT(Supuestos!$B$9/(Supuestos!$B$14+C29/(1+$E18)*$J18)))) -> 1 | H39: =IF(D29/(1+$E18)>=$K18,1,MAX(1,INT(Supuestos!$B$9/(Supuestos!$B$14+D29/(1+$E18)*$J18)))) -> 1 | I39: =IF(E29/(1+$E18)>=$K18,1,MAX(1,INT(Supuestos!$B$9/(Supuestos!$B$14+E29/(1+$E18)*$J18)))) -> 1
A40: Industrias | B40: =IF(B30/(1+$E19)>=$K19,$K19,B30/(1+$E19)*F40) -> 29.304582 | C40: =IF(C30/(1+$E19)>=$K19,$K19,C30/(1+$E19)*G40) -> 41.21913 | D40: =IF(D30/(1+$E19)>=$K19,$K19,D30/(1+$E19)*H40) -> 49.198056 | E40: =IF(E30/(1+$E19)>=$K19,$K19,E30/(1+$E19)*I40) -> 29.78533 | F40: =IF(B30/(1+$E19)>=$K19,1,MAX(1,INT(Supuestos!$B$9/(Supuestos!$B$14+B30/(1+$E19)*$J19)))) -> 3 | G40: =IF(C30/(1+$E19)>=$K19,1,MAX(1,INT(Supuestos!$B$9/(Supuestos!$B$14+C30/(1+$E19)*$J19)))) -> 2 | H40: =IF(D30/(1+$E19)>=$K19,1,MAX(1,INT(Supuestos!$B$9/(Supuestos!$B$14+D30/(1+$E19)*$J19)))) -> 2 | I40: =IF(E30/(1+$E19)>=$K19,1,MAX(1,INT(Supuestos!$B$9/(Supuestos!$B$14+E30/(1+$E19)*$J19)))) -> 1
A41: Supermercados | B41: =IF(B31/(1+$E20)>=$K20,$K20,B31/(1+$E20)*F41) -> 36.431096 | C41: =IF(C31/(1+$E20)>=$K20,$K20,C31/(1+$E20)*G41) -> 56.470588 | D41: =IF(D31/(1+$E20)>=$K20,$K20,D31/(1+$E20)*H41) -> 56.470588 | E41: =IF(E31/(1+$E20)>=$K20,$K20,E31/(1+$E20)*I41) -> 56.470588 | F41: =IF(B31/(1+$E20)>=$K20,1,MAX(1,INT(Supuestos!$B$9/(Supuestos!$B$14+B31/(1+$E20)*$J20)))) -> 1 | G41: =IF(C31/(1+$E20)>=$K20,1,MAX(1,INT(Supuestos!$B$9/(Supuestos!$B$14+C31/(1+$E20)*$J20)))) -> 1 | H41: =IF(D31/(1+$E20)>=$K20,1,MAX(1,INT(Supuestos!$B$9/(Supuestos!$B$14+D31/(1+$E20)*$J20)))) -> 1 | I41: =IF(E31/(1+$E20)>=$K20,1,MAX(1,INT(Supuestos!$B$9/(Supuestos!$B$14+E31/(1+$E20)*$J20)))) -> 1
A42: Si el vehículo se llena antes de que se termine el turno, puede hacer más de un viaje; si no, el límite es el tiempo (un solo recorrido por turno).
A44: 5. ¿Qué Master conviene? (rubros asignados a Master, en el mes pico)
A45: Dato | B45: Kangoo Express | C45: Master L1H1 | D45: Master L2H2 | E45: Master L3H2
...

Sheet Transitorios y pulmón
A1: Transitorios y pulmón de recargas
A2: Transitorio = matafuego de FLAMA que se le deja al cliente mientras el suyo está en la planta. Pulmón = lugar en la planta para lo que llega, lo que sale y los transitorios.
A4: 1. Transitorios por tipo
A5: Tipo | B5: Salen por día (prom.) | C5: Salen por día (mes pico) | D5: % con PH | E5: Días afuera + revisión (base) | F5: Días (mínimo) | G5: Fuera de servicio por su revisión | H5: Stock recomendado (u) | I5: Punto mínimo (u) | J5: En la planta (u) | K5: Jaulas en la planta | L5: Rodante
A6: =Supuestos!A62 -> ABC 1 kg | B6: =SUMPRODUCT('Demanda y mix'!F6:L6,'Demanda y mix'!$F$25:$L$25)/(Supuestos!$B$7*Supuestos!$B$6) -> 280.025 | C6: =SUMPRODUCT('Demanda y mix'!F6:L6,'Demanda y mix'!$F$24:$L$24,'Demanda y mix'!$F$25:$L$25)/Supuestos!$B$6 -> 336.02267 | D6: =Supuestos!H62 -> 0.25 | E6: =Supuestos!$B$25*(1-D6)+Supuestos!$B$26*D6+Supuestos!$B$27+Supuestos!$B$28 -> 4 | F6: =Supuestos!$C$25*(1-D6)+Supuestos!$C$26*D6+Supuestos!$C$27+Supuestos!$C$28 -> 2 | G6: =(Supuestos!$B$31*Supuestos!$B$32+(Supuestos!$B$7*Supuestos!$B$6/E6)*Supuestos!$B$33*Supuestos!$B$32)/(Supuestos!$B$7*Supuestos!$B$6) -> 0.01625 | H6: =ROUNDUP(C6*E6*(1+Supuestos!$B$30)/(1-G6),0) -> 1503 | I6: =ROUNDUP(B6*F6,0) -> 561 | J6: =MAX(0,H6-C6*(E6-Supuestos!$B$28)) -> 494.93199 | K6: =J6/Supuestos!F62 -> 6.8740555 | L6: =Supuestos!G62 -> 0
A7: =Supuestos!A63 -> ABC 2,5 kg | B7: =SUMPRODUCT('Demanda y mix'!F7:L7,'Demanda y mix'!$F$25:$L$25)/(Supuestos!$B$7*Supuestos!$B$6) -> 23.581914 | C7: =SUMPRODUCT('Demanda y mix'!F7:L7,'Demanda y mix'!$F$24:$L$24,'Demanda y mix'!$F$25:$L$25)/Supuestos!$B$6 -> 24.955083 | D7: =Supuestos!H63 -> 0.25 | E7: =Supuestos!$B$25*(1-D7)+Supuestos!$B$26*D7+Supuestos!$B$27+Supuestos!$B$28 -> 4 | F7: =Supuestos!$C$25*(1-D7)+Supuestos!$C$26*D7+Supuestos!$C$27+Supuestos!$C$28 -> 2 | G7: =(Supuestos!$B$31*Supuestos!$B$32+(Supuestos!$B$7*Supuestos!$B$6/E7)*Supuestos!$B$33*Supuestos!$B$32)/(Supuestos!$B$7*Supuestos!$B$6) -> 0.01625 | H7: =ROUNDUP(C7*E7*(1+Supuestos!$B$30)/(1-G7),0) -> 112 | I7: =ROUNDUP(B7*F7,0) -> 48 | J7: =MAX(0,H7-C7*(E7-Supuestos!$B$28)) -> 37.134752 | K7: =J7/Supuestos!F63 -> 1.2378251 | L7: =Supuestos!G63 -> 0
A8: =Supuestos!A64 -> ABC 5 kg | B8: =SUMPRODUCT('Demanda y mix'!F8:L8,'Demanda y mix'!$F$25:$L$25)/(Supuestos!$B$7*Supuestos!$B$6) -> 140.64088 | C8: =SUMPRODUCT('Demanda y mix'!F8:L8,'Demanda y mix'!$F$24:$L$24,'Demanda y mix'!$F$25:$L$25)/Supuestos!$B$6 -> 146.53467 | D8: =Supuestos!H64 -> 0.25 | E8: =Supuestos!$B$25*(1-D8)+Supuestos!$B$26*D8+Supuestos!$B$27+Supuestos!$B$28 -> 4 | F8: =Supuestos!$C$25*(1-D8)+Supuestos!$C$26*D8+Supuestos!$C$27+Supuestos!$C$28 -> 2 | G8: =(Supuestos!$B$31*Supuestos!$B$32+(Supuestos!$B$7*Supuestos!$B$6/E8)*Supuestos!$B$33*Supuestos!$B$32)/(Supuestos!$B$7*Supuestos!$B$6) -> 0.01625 | H8: =ROUNDUP(C8*E8*(1+Supuestos!$B$30)/(1-G8),0) -> 656 | I8: =ROUNDUP(B8*F8,0) -> 282 | J8: =MAX(0,H8-C8*(E8-Supuestos!$B$28)) -> 216.39599 | K8: =J8/Supuestos!F64 -> 9.0164998 | L8: =Supuestos!G64 -> 0
A9: =Supuestos!A65 -> ABC 10 kg | B9: =SUMPRODUCT('Demanda y mix'!F9:L9,'Demanda y mix'!$F$25:$L$25)/(Supuestos!$B$7*Supuestos!$B$6) -> 8.4292716 | C9: =SUMPRODUCT('Demanda y mix'!F9:L9,'Demanda y mix'!$F$24:$L$24,'Demanda y mix'!$F$25:$L$25)/Supuestos!$B$6 -> 8.6217523 | D9: =Supuestos!H65 -> 0.25 | E9: =Supuestos!$B$25*(1-D9)+Supuestos!$B$26*D9+Supuestos!$B$27+Supuestos!$B$28 -> 4 | F9: =Supuestos!$C$25*(1-D9)+Supuestos!$C$26*D9+Supuestos!$C$27+Supuestos!$C$28 -> 2 | G9: =(Supuestos!$B$31*Supuestos!$B$32+(Supuestos!$B$7*Supuestos!$B$6/E9)*Supuestos!$B$33*Supuestos!$B$32)/(Supuestos!$B$7*Supuestos!$B$6) -> 0.01625 | H9: =ROUNDUP(C9*E9*(1+Supuestos!$B$30)/(1-G9),0) -> 39 | I9: =ROUNDUP(B9*F9,0) -> 17 | J9: =MAX(0,H9-C9*(E9-Supuestos!$B$28)) -> 13.134743 | K9: =J9/Supuestos!F65 -> 0.82092145 | L9: =Supuestos!G65 -> 0
A10: =Supuestos!A66 -> Agua 10 l | B10: =SUMPRODUCT('Demanda y mix'!F10:L10,'Demanda y mix'!$F$25:$L$25)/(Supuestos!$B$7*Supuestos!$B$6) -> 11.613612 | C10: =SUMPRODUCT('Demanda y mix'!F10:L10,'Demanda y mix'!$F$24:$L$24,'Demanda y mix'!$F$25:$L$25)/Supuestos!$B$6 -> 11.857801 | D10: =Supuestos!H66 -> 0.5 | E10: =Supuestos!$B$25*(1-D10)+Supuestos!$B$26*D10+Supuestos!$B$27+Supuestos!$B$28 -> 4.5 | F10: =Supuestos!$C$25*(1-D10)+Supuestos!$C$26*D10+Supuestos!$C$27+Supuestos!$C$28 -> 2.5 | G10: =(Supuestos!$B$31*Supuestos!$B$32+(Supuestos!$B$7*Supuestos!$B$6/E10)*Supuestos!$B$33*Supuestos!$B$32)/(Supuestos!$B$7*Supuestos!$B$6) -> 0.015833333 | H10: =ROUNDUP(C10*E10*(1+Supuestos!$B$30)/(1-G10),0) -> 60 | I10: =ROUNDUP(B10*F10,0) -> 30 | J10: =MAX(0,H10-C10*(E10-Supuestos!$B$28)) -> 18.497697 | K10: =J10/Supuestos!F66 -> 1.1561061 | L10: =Supuestos!G66 -> 0
A11: =Supuestos!A67 -> AFFF 10 l | B11: =SUMPRODUCT('Demanda y mix'!F11:L11,'Demanda y mix'!$F$25:$L$25)/(Supuestos!$B$7*Supuestos!$B$6) -> 1.8333333 | C11: =SUMPRODUCT('Demanda y mix'!F11:L11,'Demanda y mix'!$F$24:$L$24,'Demanda y mix'!$F$25:$L$25)/Supuestos!$B$6 -> 1.76 | D11: =Supuestos!H67 -> 0.5 | E11: =Supuestos!$B$25*(1-D11)+Supuestos!$B$26*D11+Supuestos!$B$27+Supuestos!$B$28 -> 4.5 | F11: =Supuestos!$C$25*(1-D11)+Supuestos!$C$26*D11+Supuestos!$C$27+Supuestos!$C$28 -> 2.5 | G11: =(Supuestos!$B$31*Supuestos!$B$32+(Supuestos!$B$7*Supuestos!$B$6/E11)*Supuestos!$B$33*Supuestos!$B$32)/(Supuestos!$B$7*Supuestos!$B$6) -> 0.015833333 | H11: =ROUNDUP(C11*E11*(1+Supuestos!$B$30)/(1-G11),0) -> 9 | I11: =ROUNDUP(B11*F11,0) -> 5 | J11: =MAX(0,H11-C11*(E11-Supuestos!$B$28)) -> 2.84 | K11: =J11/Supuestos!F67 -> 0.1775 | L11: =Supuestos!G67 -> 0
A12: =Supuestos!A68 -> AFFF 50 l s/ruedas | B12: =SUMPRODUCT('Demanda y mix'!F12:L12,'Demanda y mix'!$F$25:$L$25)/(Supuestos!$B$7*Supuestos!$B$6) -> 0.95666667 | C12: =SUMPRODUCT('Demanda y mix'!F12:L12,'Demanda y mix'!$F$24:$L$24,'Demanda y mix'!$F$25:$L$25)/Supuestos!$B$6 -> 0.9184 | D12: =Supuestos!H68 -> 0.5 | E12: =Supuestos!$B$25*(1-D12)+Supuestos!$B$26*D12+Supuestos!$B$27+Supuestos!$B$28 -> 4.5 | F12: =Supuestos!$C$25*(1-D12)+Supuestos!$C$26*D12+Supuestos!$C$27+Supuestos!$C$28 -> 2.5 | G12: =(Supuestos!$B$31*Supuestos!$B$32+(Supuestos!$B$7*Supuestos!$B$6/E12)*Supuestos!$B$33*Supuestos!$B$32)/(Supuestos!$B$7*Supuestos!$B$6) -> 0.015833333 | H12: =ROUNDUP(C12*E12*(1+Supuestos!$B$30)/(1-G12),0) -> 5 | I12: =ROUNDUP(B12*F12,0) -> 3 | J12: =MAX(0,H12-C12*(E12-Supuestos!$B$28)) -> 1.7856 | K12: =J12/Supuestos!F68 -> 0.8928 | L12: =Supuestos!G68 -> 1
A13: =Supuestos!A69 -> BC 5 kg | B13: =SUMPRODUCT('Demanda y mix'!F13:L13,'Demanda y mix'!$F$25:$L$25)/(Supuestos!$B$7*Supuestos!$B$6) -> 0.55 | C13: =SUMPRODUCT('Demanda y mix'!F13:L13,'Demanda y mix'!$F$24:$L$24,'Demanda y mix'!$F$25:$L$25)/Supuestos!$B$6 -> 0.528 | D13: =Supuestos!H69 -> 0.25 | E13: =Supuestos!$B$25*(1-D13)+Supuestos!$B$26*D13+Supuestos!$B$27+Supuestos!$B$28 -> 4 | F13: =Supuestos!$C$25*(1-D13)+Supuestos!$C$26*D13+Supuestos!$C$27+Supuestos!$C$28 -> 2 | G13: =(Supuestos!$B$31*Supuestos!$B$32+(Supuestos!$B$7*Supuestos!$B$6/E13)*Supuestos!$B$33*Supuestos!$B$32)/(Supuestos!$B$7*Supuestos!$B$6) -> 0.01625 | H13: =ROUNDUP(C13*E13*(1+Supuestos!$B$30)/(1-G13),0) -> 3 | I13: =ROUNDUP(B13*F13,0) -> 2 | J13: =MAX(0,H13-C13*(E13-Supuestos!$B$28)) -> 1.416 | K13: =J13/Supuestos!F69 -> 0.059 | L13: =Supuestos!G69 -> 0
A14: =Supuestos!A70 -> Sales K 6 l | B14: =SUMPRODUCT('Demanda y mix'!F14:L14,'Demanda y mix'!$F$25:$L$25)/(Supuestos!$B$7*Supuestos!$B$6) -> 5.7401628 | C14: =SUMPRODUCT('Demanda y mix'!F14:L14,'Demanda y mix'!$F$24:$L$24,'Demanda y mix'!$F$25:$L$25)/Supuestos!$B$6 -> 5.9036014 | D14: =Supuestos!H70 -> 0.5 | E14: =Supuestos!$B$25*(1-D14)+Supuestos!$B$26*D14+Supuestos!$B$27+Supuestos!$B$28 -> 4.5 | F14: =Supuestos!$C$25*(1-D14)+Supuestos!$C$26*D14+Supuestos!$C$27+Supuestos!$C$28 -> 2.5 | G14: =(Supuestos!$B$31*Supuestos!$B$32+(Supuestos!$B$7*Supuestos!$B$6/E14)*Supuestos!$B$33*Supuestos!$B$32)/(Supuestos!$B$7*Supuestos!$B$6) -> 0.015833333 | H14: =ROUNDUP(C14*E14*(1+Supuestos!$B$30)/(1-G14),0) -> 30 | I14: =ROUNDUP(B14*F14,0) -> 15 | J14: =MAX(0,H14-C14*(E14-Supuestos!$B$28)) -> 9.3373951 | K14: =J14/Supuestos!F70 -> 0.46686976 | L14: =Supuestos!G70 -> 0
A15: =Supuestos!A71 -> CO₂ 2 kg | B15: =SUMPRODUCT('Demanda y mix'!F15:L15,'Demanda y mix'!$F$25:$L$25)/(Supuestos!$B$7*Supuestos!$B$6) -> 32.077373 | C15: =SUMPRODUCT('Demanda y mix'!F15:L15,'Demanda y mix'!$F$24:$L$24,'Demanda y mix'!$F$25:$L$25)/Supuestos!$B$6 -> 32.809762 | D15: =Supuestos!H71 -> 0.25 | E15: =Supuestos!$B$25*(1-D15)+Supuestos!$B$26*D15+Supuestos!$B$27+Supuestos!$B$28 -> 4 | F15: =Supuestos!$C$25*(1-D15)+Supuestos!$C$26*D15+Supuestos!$C$27+Supuestos!$C$28 -> 2 | G15: =(Supuestos!$B$31*Supuestos!$B$32+(Supuestos!$B$7*Supuestos!$B$6/E15)*Supuestos!$B$33*Supuestos!$B$32)/(Supuestos!$B$7*Supuestos!$B$6) -> 0.01625 | H15: =ROUNDUP(C15*E15*(1+Supuestos!$B$30)/(1-G15),0) -> 147 | I15: =ROUNDUP(B15*F15,0) -> 65 | J15: =MAX(0,H15-C15*(E15-Supuestos!$B$28)) -> 48.570715 | K15: =J15/Supuestos!F71 -> 1.6190238 | L15: =Supuestos!G71 -> 0
A16: =Supuestos!A72 -> CO₂ 5 kg | B16: =SUMPRODUCT('Demanda y mix'!F16:L16,'Demanda y mix'!$F$25:$L$25)/(Supuestos!$B$7*Supuestos!$B$6) -> 10.000601 | C16: =SUMPRODUCT('Demanda y mix'!F16:L16,'Demanda y mix'!$F$24:$L$24,'Demanda y mix'!$F$25:$L$25)/Supuestos!$B$6 -> 10.151828 | D16: =Supuestos!H72 -> 0.25 | E16: =Supuestos!$B$25*(1-D16)+Supuestos!$B$26*D16+Supuestos!$B$27+Supuestos!$B$28 -> 4 | F16: =Supuestos!$C$25*(1-D16)+Supuestos!$C$26*D16+Supuestos!$C$27+Supuestos!$C$28 -> 2 | G16: =(Supuestos!$B$31*Supuestos!$B$32+(Supuestos!$B$7*Supuestos!$B$6/E16)*Supuestos!$B$33*Supuestos!$B$32)/(Supuestos!$B$7*Supuestos!$B$6) -> 0.01625 | H16: =ROUNDUP(C16*E16*(1+Supuestos!$B$30)/(1-G16),0) -> 46 | I16: =ROUNDUP(B16*F16,0) -> 21 | J16: =MAX(0,H16-C16*(E16-Supuestos!$B$28)) -> 15.544517 | K16: =J16/Supuestos!F72 -> 0.77722584 | L16: =Supuestos!G72 -> 0
A17: =Supuestos!A73 -> HCFC/HFC 5 kg | B17: =SUMPRODUCT('Demanda y mix'!F17:L17,'Demanda y mix'!$F$25:$L$25)/(Supuestos!$B$7*Supuestos!$B$6) -> 1.5103469 | C17: =SUMPRODUCT('Demanda y mix'!F17:L17,'Demanda y mix'!$F$24:$L$24,'Demanda y mix'!$F$25:$L$25)/Supuestos!$B$6 -> 1.449933 | D17: =Supuestos!H73 -> 0.25 | E17: =Supuestos!$B$25*(1-D17)+Supuestos!$B$26*D17+Supuestos!$B$27+Supuestos!$B$28 -> 4 | F17: =Supuestos!$C$25*(1-D17)+Supuestos!$C$26*D17+Supuestos!$C$27+Supuestos!$C$28 -> 2 | G17: =(Supuestos!$B$31*Supuestos!$B$32+(Supuestos!$B$7*Supuestos!$B$6/E17)*Supuestos!$B$33*Supuestos!$B$32)/(Supuestos!$B$7*Supuestos!$B$6) -> 0.01625 | H17: =ROUNDUP(C17*E17*(1+Supuestos!$B$30)/(1-G17),0) -> 7 | I17: =ROUNDUP(B17*F17,0) -> 4 | J17: =MAX(0,H17-C17*(E17-Supuestos!$B$28)) -> 2.650201 | K17: =J17/Supuestos!F73 -> 0.11042504 | L17: =Supuestos!G73 -> 0
... A22: =Supuestos!A78 -> ABC 100 kg s/ruedas | B22: =SUMPRODUCT('Demanda y mix'!F22:L22,'Demanda y mix'!$F$25:$L$25)/(Supuestos!$B$7*Supuestos!$B$6) -> 0.4342041 | C22: =SUMPRODUCT('Demanda y mix'!F22:L22,'Demanda y mix'!$F$24:$L$24,'Demanda y mix'!$F$25:$L$25)/Supuestos!$B$6 -> 0.4410376 | D22: =Supuestos!H78 -> 0.25 | E22: =Supuestos!$B$25*(1-D22)+Supuestos!$B$26*D22+Supuestos!$B$27+Supuestos!$B$28 -> 4 | F22: =Supuestos!$C$25*(1-D22)+Supuestos!$C$26*D22+Supuestos!$C$27+Supuestos!$C$28 -> 2 | G22: =(Supuestos!$B$31*Supuestos!$B$32+(Supuestos!$B$7*Supuestos!$B$6/E22)*Supuestos!$B$33*Supuestos!$B$32)/(Supuestos!$B$7*Supuestos!$B$6) -> 0.01625 | H22: =ROUNDUP(C22*E22*(1+Supuestos!$B$30)/(1-G22),0) -> 2 | I22: =ROUNDUP(B22*F22,0) -> 1 | J22: =MAX(0,H22-C22*(E22-Supuestos!$B$28)) -> 0.67688721 | K22: =J22/Supuestos!F78 -> 0.67688721 | L22: =Supuestos!G78 -> 1
A23: Total | B23: =SUM(B6:B22) -> 522.89433 | C23: =SUM(C6:C22) -> 587.5142 | H23: =SUM(H6:H22) -> 2646 | I23: =SUM(I6:I22) -> 1066 | J23: =SUM(J6:J22) -> 873.23749 | K23: =SUM(K6:K22) -> 27.88704
A24: Stock recomendado = salen por día en el mes pico × días afuera (+ revisión) × (1 + margen) / (1 − fuera de servicio). Es la ley de Little: lo que hay afuera = lo que sale por día × los días que tarda en volver.
A25: Punto mínimo = salidas de un día promedio × el ciclo más corto posible (proceso en 1 día, PH en 3, sin espera). Por debajo de eso falta transitorio aunque todo salga perfecto. Salen de la propia línea de manuales y carros.
A27: 2. ¿Cuántos transitorios hacen falta según los días que tarda en volver el matafuego del cliente?
A28: Días afuera + revisión | B28: 1 | C28: 2 | D28: 3 | E28: 4 | F28: 5 | G28: 6 | H28: 7
A29: Transitorios (u) | B29: =ROUNDUP(SUM($C$6:$C$22)*1*(1+Supuestos!$B$30),0) -> 647 | C29: =ROUNDUP(SUM($C$6:$C$22)*2*(1+Supuestos!$B$30),0) -> 1293 | D29: =ROUNDUP(SUM($C$6:$C$22)*3*(1+Supuestos!$B$30),0) -> 1939 | E29: =ROUNDUP(SUM($C$6:$C$22)*4*(1+Supuestos!$B$30),0) -> 2586 | F29: =ROUNDUP(SUM($C$6:$C$22)*5*(1+Supuestos!$B$30),0) -> 3232 | G29: =ROUNDUP(SUM($C$6:$C$22)*6*(1+Supuestos!$B$30),0) -> 3878 | H29: =ROUNDUP(SUM($C$6:$C$22)*7*(1+Supuestos!$B$30),0) -> 4524
A30: Días del caso base (promedio) | B30: =SUMPRODUCT(C6:C22,E6:E22)/C23 -> 4.0173952 | C30: ← cada día que se acorta el ciclo ahorra una fila de transitorios: es la palanca más fuerte.
A32: 3. Trabajo extra en la planta por los transitorios (por año)
A33: Concepto | B33: u/año | C33: % de las recargas 2035
A34: Revisión o recarga anual | B34: =H23*Supuestos!$B$31 -> 2646 | C34: =B34/'Demanda y mix'!$D$23 -> 0.020779017
A35: Recarga porque el cliente lo usó | B35: =SUMPRODUCT(H6:H22,1/E6:E22)*Supuestos!$B$7*Supuestos!$B$6*Supuestos!$B$33 -> 790.33333 | C35: =B35/'Demanda y mix'!$D$23 -> 0.0062064813
